Workbook

Sheet 1.7
A1: 45474 | C1: Stock
A2: TÊN SẢN PHẨM VR | B2: ĐVT | C2: TỒN TRƯỚC | D2: GIÁ NHẬP | E2: THÀNH TIỀN
A4: BẮP CẢI TÍM | B4: Kg
A5: BẮP CẢI TÍM (BẮP) | B5: BẮP
A6: BẮP CẢI TÍM SUSHI | B6: Kg
A7: BẮP CẢI TRẮNG | B7: Kg
A8: BẮP CẢI TRẮNG (BẮP) | B8: BẮP
A9: BẮP CẢI TRẮNG MỘC CHÂU | B9: Kg
A10: BẮP CẢI TRẮNG SÓI BIỂN | B10: Kg
A11: BẮP CẢI TRẮNG SUSHI | B11: Kg
A12: BẮP MỸ CẶP | B12: CẶP
A13: BẦU | B13: Kg
A14: BÍ ĐAO XANH | B14: Kg
A15: BÍ ĐAO XANH 400G | B15: TRÁI
A16: BÍ ĐỎ HỒ LÔ | B16: Kg | C16: 7 | D16: 18000 | E16: =+D16*C16 -> 126000
A17: BÍ ĐỎ MINI | B17: Kg
A18: BÍ ĐỎ NON (KG)KQ | B18: Kg
A19: BÍ ĐỎ NON TRÁI VR | B19: TRÁI
A20: BÍ ĐỎ NON( KG) VR | B20: Kg
A21: BÍ ĐỎ TRÒN | B21: Kg | C21: 140 | D21: 13000 | E21: =+D21*C21 -> 1820000
A22: BÍ MINI VÀNG 300GR | B22: TRÁI
A23: BÍ MINI VÀNG KG | B23: Kg
A24: BÍ NGÒI VÀNG | B24: Kg
A25: BÍ NGÒI VÀNG (TRÁI) | B25: TRÁI
A26: BÍ NGÒI XANH | B26: Kg | C26: 70 | D26: 13000 | E26: =+D26*C26 -> 910000
A27: BÍ NGÒI XANH(TRÁI) | B27: TRÁI | C27: 235 | D27: 3900 | E27: =+D27*C27 -> 916500
A28: BÍ NHẬT | B28: Kg
A29: BƠ 034 | B29: Kg | C29: 89 | D29: 12500 | E29: =+D29*C29 -> 1112500
A30: BƠ 034 COOP | B30: Kg
A31: BƠ BOOTH | B31: Kg
A32: BO HOA CHUONG | B32: BÓ
A33: BO HOA CUC TANA | B33: BÓ
A34: BO HOA DONG TIEN HN | B34: BÓ
A35: BO HOA LOA KEN | B35: BÓ
A36: BO HOA PHANG | B36: BÓ
A37: BO HOA SEN QUAN AM | B37: BÓ
A38: BO HOA SEN SUPER | B38: BÓ
A39: BƠ SÁP | B39: Kg | C39: 30 | D39: 11000 | E39: =+D39*C39 -> 330000
A40: BÓ XÔI | B40: Kg
A41: BÓ XÔI 300G VR | B41: TÚI
...

Sheet 2.7
A1: 45475 | C1: Stock
A2: TÊN SẢN PHẨM VR | B2: ĐVT | C2: TỒN TRƯỚC | D2: GIÁ NHẬP | E2: THÀNH TIỀN
A4: BẮP CẢI TÍM | B4: Kg | C4: 4 | D4: 16000 | E4: =+D4*C4 -> 64000
A5: BẮP CẢI TÍM (BẮP) | B5: BẮP
A6: BẮP CẢI TÍM SUSHI | B6: Kg
A7: BẮP CẢI TRẮNG | B7: Kg
A8: BẮP CẢI TRẮNG (BẮP) | B8: BẮP
A9: BẮP CẢI TRẮNG MỘC CHÂU | B9: Kg
A10: BẮP CẢI TRẮNG SÓI BIỂN | B10: Kg
A11: BẮP CẢI TRẮNG SUSHI | B11: Kg
A12: BẮP MỸ CẶP | B12: CẶP
A13: BẦU | B13: Kg
A14: BÍ ĐAO XANH | B14: Kg
A15: BÍ ĐAO XANH 400G | B15: TRÁI
A16: BÍ ĐỎ HỒ LÔ | B16: Kg | C16: 15 | D16: 18000 | E16: =+D16*C16 -> 270000
A17: BÍ ĐỎ MINI | B17: Kg
A18: BÍ ĐỎ NON (KG)KQ | B18: Kg
A19: BÍ ĐỎ NON TRÁI VR | B19: TRÁI
A20: BÍ ĐỎ NON( KG) VR | B20: Kg | C20: 6 | D20: 13000 | E20: =+D20*C20 -> 78000
A21: BÍ ĐỎ TRÒN | B21: Kg | C21: 100 | D21: 13000 | E21: =+D21*C21 -> 1300000
A22: BÍ MINI VÀNG 300GR | B22: TRÁI
A23: BÍ MINI VÀNG KG | B23: Kg
A24: BÍ NGÒI VÀNG | B24: Kg
A25: BÍ NGÒI VÀNG (TRÁI) | B25: TRÁI
A26: BÍ NGÒI XANH | B26: Kg | C26: 120 | D26: 13000 | E26: =+D26*C26 -> 1560000
A27: BÍ NGÒI XANH(TRÁI) | B27: TRÁI | C27: 135 | D27: 3900 | E27: =+D27*C27 -> 526500
A28: BÍ NHẬT | B28: Kg
A29: BƠ 034 | B29: Kg | C29: 69 | D29: 12500 | E29: =+D29*C29 -> 862500
A30: BƠ 034 COOP | B30: Kg
A31: BƠ BOOTH | B31: Kg
A32: BO HOA CHUONG | B32: BÓ
A33: BO HOA CUC TANA | B33: BÓ
A34: BO HOA DONG TIEN HN | B34: BÓ
A35: BO HOA LOA KEN | B35: BÓ
A36: BO HOA PHANG | B36: BÓ
A37: BO HOA SEN QUAN AM | B37: BÓ
A38: BO HOA SEN SUPER | B38: BÓ
A39: BƠ SÁP | B39: Kg | C39: 29 | D39: 11000 | E39: =+D39*C39 -> 319000
A40: BÓ XÔI | B40: Kg
A41: BÓ XÔI 300G VR | B41: TÚI
...

Sheet 3.7
A1: 45476 | C1: Stock
A2: TÊN SẢN PHẨM VR | B2: ĐVT | C2: TỒN TRƯỚC | D2: GIÁ NHẬP | E2: THÀNH TIỀN
A4: BẮP CẢI TÍM | B4: Kg | C4: 5 | D4: =VLOOKUP(A4,'2.7'!A4:D289,4,) -> 16000 | E4: =+D4*C4 -> 80000
A5: BẮP CẢI TÍM (BẮP) | B5: BẮP
A6: BẮP CẢI TÍM SUSHI | B6: Kg
A7: BẮP CẢI TRẮNG | B7: Kg
A8: BẮP CẢI TRẮNG (BẮP) | B8: BẮP
A9: BẮP CẢI TRẮNG MỘC CHÂU | B9: Kg
A10: BẮP CẢI TRẮNG SÓI BIỂN | B10: Kg
A11: BẮP CẢI TRẮNG SUSHI | B11: Kg
A12: BẮP MỸ CẶP | B12: CẶP
A13: BẦU | B13: Kg
A14: BÍ ĐAO XANH | B14: Kg
A15: BÍ ĐAO XANH 400G | B15: TRÁI
A16: BÍ ĐỎ HỒ LÔ | B16: Kg | C16: 20 | D16: =VLOOKUP(A16,'2.7'!A16:D301,4,) -> 18000 | E16: =+D16*C16 -> 360000
A17: BÍ ĐỎ MINI | B17: Kg
A18: BÍ ĐỎ NON (KG)KQ | B18: Kg
A19: BÍ ĐỎ NON TRÁI VR | B19: TRÁI | C19: 107 | D19: =13000*0.3 -> 3900 | E19: =+D19*C19 -> 417300
A20: BÍ ĐỎ NON( KG) VR | B20: Kg
A21: BÍ ĐỎ TRÒN | B21: Kg | C21: 200 | D21: =VLOOKUP(A21,'2.7'!A21:D306,4,) -> 13000 | E21: =+D21*C21 -> 2600000
A22: BÍ MINI VÀNG 300GR | B22: TRÁI
A23: BÍ MINI VÀNG KG | B23: Kg
A24: BÍ NGÒI VÀNG | B24: Kg
A25: BÍ NGÒI VÀNG (TRÁI) | B25: TRÁI
A26: BÍ NGÒI XANH | B26: Kg | C26: 162 | D26: =VLOOKUP(A26,'2.7'!A26:D311,4,) -> 13000 | E26: =+D26*C26 -> 2106000
A27: BÍ NGÒI XANH(TRÁI) | B27: TRÁI
A28: BÍ NHẬT | B28: Kg
A29: BƠ 034 | B29: Kg | C29: 90 | D29: =VLOOKUP(A29,'2.7'!A29:D314,4,) -> 12500 | E29: =+D29*C29 -> 1125000
A30: BƠ 034 COOP | B30: Kg
A31: BƠ BOOTH | B31: Kg
A32: BO HOA CHUONG | B32: BÓ
A33: BO HOA CUC TANA | B33: BÓ
A34: BO HOA DONG TIEN HN | B34: BÓ
A35: BO HOA LOA KEN | B35: BÓ
A36: BO HOA PHANG | B36: BÓ
A37: BO HOA SEN QUAN AM | B37: BÓ
A38: BO HOA SEN SUPER | B38: BÓ
A39: BƠ SÁP | B39: Kg | C39: 25 | D39: =VLOOKUP(A39,'2.7'!A39:D324,4,) -> 11000 | E39: =+D39*C39 -> 275000
A40: BÓ XÔI | B40: Kg
A41: BÓ XÔI 300G VR | B41: TÚI | C41: 6 | D41: 12000 | E41: =+D41*C41 -> 72000
...

Sheet 4.7
A1: 45477 | C1: Stock
A2: TÊN SẢN PHẨM VR | B2: ĐVT | C2: TỒN TRƯỚC | D2: GIÁ NHẬP | E2: THÀNH TIỀN
A4: BẮP CẢI TÍM | B4: Kg
A5: BẮP CẢI TÍM (BẮP) | B5: BẮP
A6: BẮP CẢI TÍM SUSHI | B6: Kg
A7: BẮP CẢI TRẮNG | B7: Kg
A8: BẮP CẢI TRẮNG (BẮP) | B8: BẮP
A9: BẮP CẢI TRẮNG MỘC CHÂU | B9: Kg
A10: BẮP CẢI TRẮNG SÓI BIỂN | B10: Kg
A11: BẮP CẢI TRẮNG SUSHI | B11: Kg
A12: BẮP MỸ CẶP | B12: CẶP
A13: BẦU | B13: Kg
A14: BÍ ĐAO XANH | B14: Kg
A15: BÍ ĐAO XANH 400G | B15: TRÁI
A16: BÍ ĐỎ HỒ LÔ | B16: Kg | C16: 18 | D16: 18000 | E16: =+D16*C16 -> 324000
A17: BÍ ĐỎ MINI | B17: Kg
A18: BÍ ĐỎ NON (KG)KQ | B18: Kg
A19: BÍ ĐỎ NON TRÁI VR | B19: TRÁI | C19: 71 | D19: 3900 | E19: =+D19*C19 -> 276900
A20: BÍ ĐỎ NON( KG) VR | B20: Kg
A21: BÍ ĐỎ TRÒN | B21: Kg | C21: 100 | D21: 13000 | E21: =+D21*C21 -> 1300000
A22: BÍ MINI VÀNG 300GR | B22: TRÁI
A23: BÍ MINI VÀNG KG | B23: Kg
A24: BÍ NGÒI VÀNG | B24: Kg
A25: BÍ NGÒI VÀNG (TRÁI) | B25: TRÁI
A26: BÍ NGÒI XANH | B26: Kg | C26: 120 | D26: 13000 | E26: =+D26*C26 -> 1560000
A27: BÍ NGÒI XANH(TRÁI) | B27: TRÁI
A28: BÍ NHẬT | B28: Kg
A29: BƠ 034 | B29: Kg
A30: BƠ 034 COOP | B30: Kg
A31: BƠ BOOTH | B31: Kg
A32: BO HOA CHUONG | B32: BÓ
A33: BO HOA CUC TANA | B33: BÓ
A34: BO HOA DONG TIEN HN | B34: BÓ
A35: BO HOA LOA KEN | B35: BÓ
A36: BO HOA PHANG | B36: BÓ
A37: BO HOA SEN QUAN AM | B37: BÓ
A38: BO HOA SEN SUPER | B38: BÓ
A39: BƠ SÁP | B39: Kg | C39: 35 | D39: 11000 | E39: =+D39*C39 -> 385000
A40: BÓ XÔI | B40: Kg
A41: BÓ XÔI 300G VR | B41: TÚI
...

Sheet 5.7
A1: hàng tồn cuối ngày 5/7 vr
A2: TÊN SẢN PHẨM | B2: TỒN TRƯỚC | C2: GIÁ NHẬP | D2: THÀNH TIỀN
A3: BẮP CẢI TÍM | D3: =B3*C3 -> 0
A4: BẮP CẢI TÍM (BẮP) | D4: =B4*C4 -> 0
A5: BẮP CẢI TÍM SUSHI | D5: =B5*C5 -> 0
A6: BẮP CẢI TRẮNG | D6: =B6*C6 -> 0
A7: BẮP CẢI TRẮNG (BẮP) | D7: =B7*C7 -> 0
A8: BẮP CẢI TRẮNG MỘC CHÂU | D8: =B8*C8 -> 0
A9: BẮP CẢI TRẮNG SÓI BIỂN | D9: =B9*C9 -> 0
A10: BẮP CẢI TRẮNG SUSHI | D10: =B10*C10 -> 0
A11: BẮP MỸ CẶP | D11: =B11*C11 -> 0
A12: BẦU | D12: =B12*C12 -> 0
A13: BÍ ĐAO XANH | D13: =B13*C13 -> 0
A14: BÍ ĐAO XANH 400G | D14: =B14*C14 -> 0
A15: BÍ ĐỎ HỒ LÔ | B15: 20 | C15: 18000 | D15: =B15*C15 -> 360000
A16: BÍ ĐỎ MINI | D16: =B16*C16 -> 0
A17: BÍ ĐỎ NON (KG)KQ | D17: =B17*C17 -> 0
A18: BÍ ĐỎ NON TRÁI VR | B18: 33 | C18: 4000 | D18: =B18*C18 -> 132000
A19: BÍ ĐỎ NON( KG) VR | D19: =B19*C19 -> 0
A20: BÍ ĐỎ TRÒN | B20: 200 | C20: 13000 | D20: =B20*C20 -> 2600000
A21: BÍ MINI VÀNG 300GR | D21: =B21*C21 -> 0
A22: BÍ MINI VÀNG KG | D22: =B22*C22 -> 0
A23: BÍ NGÒI VÀNG | D23: =B23*C23 -> 0
A24: BÍ NGÒI VÀNG (TRÁI) | D24: =B24*C24 -> 0
A25: BÍ NGÒI XANH | B25: 170 | C25: 12500 | D25: =B25*C25 -> 2125000
A26: BÍ NGÒI XANH(TRÁI) | D26: =B26*C26 -> 0
A27: BÍ NHẬT | D27: =B27*C27 -> 0
A28: BƠ 034 | D28: =B28*C28 -> 0
A29: BƠ 034 COOP | D29: =B29*C29 -> 0
A30: BƠ BOOTH | D30: =B30*C30 -> 0
A31: BO HOA CHUONG | D31: =B31*C31 -> 0
A32: BO HOA CUC TANA | D32: =B32*C32 -> 0
A33: BO HOA DONG TIEN HN | D33: =B33*C33 -> 0
A34: BO HOA LOA KEN | D34: =B34*C34 -> 0
A35: BO HOA PHANG | D35: =B35*C35 -> 0
A36: BO HOA SEN QUAN AM | D36: =B36*C36 -> 0
A37: BO HOA SEN SUPER | D37: =B37*C37 -> 0
A38: BƠ SÁP | B38: 20 | C38: 11000 | D38: =B38*C38 -> 220000
A39: BÓ XÔI | D39: =B39*C39 -> 0
A40: BÓ XÔI 300G VR | D40: =B40*C40 -> 0
...

Sheet 6.7 
A1: hàng tồn cuối ngày 6/7 vr
A2: TÊN SẢN PHẨM | B2: TỒN TRƯỚC | C2: GIÁ NHẬP | D2: THÀNH TIỀN
A3: BẮP CẢI TÍM | B3: 6 | C3: 14000 | D3: =B3*C3 -> 84000
A4: BẮP CẢI TÍM (BẮP) | D4: =B4*C4 -> 0
A5: BẮP CẢI TÍM SUSHI | D5: =B5*C5 -> 0
A6: BẮP CẢI TRẮNG | D6: =B6*C6 -> 0
A7: BẮP CẢI TRẮNG (BẮP) | D7: =B7*C7 -> 0
A8: BẮP CẢI TRẮNG MỘC CHÂU | D8: =B8*C8 -> 0
A9: BẮP CẢI TRẮNG SÓI BIỂN | D9: =B9*C9 -> 0
A10: BẮP CẢI TRẮNG SUSHI | D10: =B10*C10 -> 0
A11: BẮP MỸ CẶP | D11: =B11*C11 -> 0
A12: BẦU | D12: =B12*C12 -> 0
A13: BÍ ĐAO XANH | D13: =B13*C13 -> 0
A14: BÍ ĐAO XANH 400G | D14: =B14*C14 -> 0
A15: BÍ ĐỎ HỒ LÔ | B15: 28 | C15: 18000 | D15: =B15*C15 -> 504000
A16: BÍ ĐỎ MINI | D16: =B16*C16 -> 0
A17: BÍ ĐỎ NON (KG)KQ | D17: =B17*C17 -> 0
A18: BÍ ĐỎ NON TRÁI VR | B18: 5 | C18: 4000 | D18: =B18*C18 -> 20000
A19: BÍ ĐỎ NON( KG) VR | D19: =B19*C19 -> 0
A20: BÍ ĐỎ TRÒN | B20: 75 | C20: 13000 | D20: =B20*C20 -> 975000
A21: BÍ MINI VÀNG 300GR | D21: =B21*C21 -> 0
A22: BÍ MINI VÀNG KG | D22: =B22*C22 -> 0
A23: BÍ NGÒI VÀNG | D23: =B23*C23 -> 0
A24: BÍ NGÒI VÀNG (TRÁI) | D24: =B24*C24 -> 0
A25: BÍ NGÒI XANH | B25: 125 | C25: 13000 | D25: =B25*C25 -> 1625000
A26: BÍ NGÒI XANH(TRÁI) | D26: =B26*C26 -> 0
A27: BÍ NHẬT | D27: =B27*C27 -> 0
A28: BƠ 034 | B28: =34 -> 34 | C28: 12500 | D28: =B28*C28 -> 425000
A29: BƠ 034 COOP | D29: =B29*C29 -> 0
A30: BƠ BOOTH | D30: =B30*C30 -> 0
A31: BO HOA CHUONG | D31: =B31*C31 -> 0
A32: BO HOA CUC TANA | D32: =B32*C32 -> 0
A33: BO HOA DONG TIEN HN | D33: =B33*C33 -> 0
A34: BO HOA LOA KEN | D34: =B34*C34 -> 0
A35: BO HOA PHANG | D35: =B35*C35 -> 0
A36: BO HOA SEN QUAN AM | D36: =B36*C36 -> 0
A37: BO HOA SEN SUPER | D37: =B37*C37 -> 0
A38: BƠ SÁP | B38: 26 | C38: 11000 | D38: =B38*C38 -> 286000
A39: BÓ XÔI | D39: =B39*C39 -> 0
A40: BÓ XÔI 300G VR | D40: =B40*C40 -> 0
...

Sheet 7.7
A1: hàng tồn cuối ngày 7/7 vr
A2: TÊN SẢN PHẨM | B2: TỒN TRƯỚC | C2: GIÁ NHẬP | D2: THÀNH TIỀN
A3: BẮP CẢI TÍM | D3: =B3*C3 -> 0
A4: BẮP CẢI TÍM (BẮP) | D4: =B4*C4 -> 0
A5: BẮP CẢI TÍM SUSHI | D5: =B5*C5 -> 0
A6: BẮP CẢI TRẮNG | D6: =B6*C6 -> 0
A7: BẮP CẢI TRẮNG (BẮP) | D7: =B7*C7 -> 0
A8: BẮP CẢI TRẮNG MỘC CHÂU | D8: =B8*C8 -> 0
A9: BẮP CẢI TRẮNG SÓI BIỂN | D9: =B9*C9 -> 0
A10: BẮP CẢI TRẮNG SUSHI | D10: =B10*C10 -> 0
A11: BẮP MỸ CẶP | D11: =B11*C11 -> 0
A12: BẦU | D12: =B12*C12 -> 0
A13: BÍ ĐAO XANH | D13: =B13*C13 -> 0
A14: BÍ ĐAO XANH 400G | D14: =B14*C14 -> 0
A15: BÍ ĐỎ HỒ LÔ | B15: 15 | C15: 18000 | D15: =B15*C15 -> 270000
A16: BÍ ĐỎ MINI | D16: =B16*C16 -> 0
A17: BÍ ĐỎ NON (KG)KQ | D17: =B17*C17 -> 0
A18: BÍ ĐỎ NON TRÁI VR | B18: 33 | C18: 4000 | D18: =B18*C18 -> 132000
A19: BÍ ĐỎ NON( KG) VR | D19: =B19*C19 -> 0
A20: BÍ ĐỎ TRÒN | B20: 100 | C20: 13000 | D20: =B20*C20 -> 1300000
A21: BÍ MINI VÀNG 300GR | D21: =B21*C21 -> 0
A22: BÍ MINI VÀNG KG | D22: =B22*C22 -> 0
A23: BÍ NGÒI VÀNG | D23: =B23*C23 -> 0
A24: BÍ NGÒI VÀNG (TRÁI) | D24: =B24*C24 -> 0
A25: BÍ NGÒI XANH | B25: 70 | C25: 13000 | D25: =B25*C25 -> 910000
A26: BÍ NGÒI XANH(TRÁI) | D26: =B26*C26 -> 0
A27: BÍ NHẬT | D27: =B27*C27 -> 0
A28: BƠ 034 | B28: 33 | C28: 12000 | D28: =B28*C28 -> 396000
A29: BƠ 034 COOP | D29: =B29*C29 -> 0
A30: BƠ BOOTH | D30: =B30*C30 -> 0
A31: BO HOA CHUONG | D31: =B31*C31 -> 0
A32: BO HOA CUC TANA | D32: =B32*C32 -> 0
A33: BO HOA DONG TIEN HN | D33: =B33*C33 -> 0
A34: BO HOA LOA KEN | D34: =B34*C34 -> 0
A35: BO HOA PHANG | D35: =B35*C35 -> 0
A36: BO HOA SEN QUAN AM | D36: =B36*C36 -> 0
A37: BO HOA SEN SUPER | D37: =B37*C37 -> 0
A38: BƠ SÁP | B38: 25 | C38: 10000 | D38: =B38*C38 -> 250000
A39: BÓ XÔI | D39: =B39*C39 -> 0
A40: BÓ XÔI 300G VR | D40: =B40*C40 -> 0
...

Sheet 8.7
A1: hàng tồn cuối ngày 8/7 vr
A2: TÊN SẢN PHẨM | B2: TỒN TRƯỚC | C2: GIÁ NHẬP | D2: THÀNH TIỀN
A3: BẮP CẢI TÍM | D3: =B3*C3 -> 0
A4: BẮP CẢI TÍM (BẮP) | D4: =B4*C4 -> 0
A5: BẮP CẢI TÍM SUSHI | D5: =B5*C5 -> 0
A6: BẮP CẢI TRẮNG | D6: =B6*C6 -> 0
A7: BẮP CẢI TRẮNG (BẮP) | D7: =B7*C7 -> 0
A8: BẮP CẢI TRẮNG MỘC CHÂU | D8: =B8*C8 -> 0
A9: BẮP CẢI TRẮNG SÓI BIỂN | D9: =B9*C9 -> 0
A10: BẮP CẢI TRẮNG SUSHI | D10: =B10*C10 -> 0
A11: BẮP MỸ CẶP | D11: =B11*C11 -> 0
A12: BẦU | B12: 1 | C12: 10000 | D12: =B12*C12 -> 10000
A13: BÍ ĐAO XANH | D13: =B13*C13 -> 0
A14: BÍ ĐAO XANH 400G | D14: =B14*C14 -> 0
A15: BÍ ĐỎ HỒ LÔ | B15: 9 | C15: 18000 | D15: =B15*C15 -> 162000
A16: BÍ ĐỎ MINI | D16: =B16*C16 -> 0
A17: BÍ ĐỎ NON (KG)KQ | D17: =B17*C17 -> 0
A18: BÍ ĐỎ NON TRÁI VR | B18: 38 | C18: 4000 | D18: =B18*C18 -> 152000
A19: BÍ ĐỎ NON( KG) VR | B19: 50 | C19: 14000 | D19: =B19*C19 -> 700000
A20: BÍ ĐỎ TRÒN | B20: 120 | C20: 13000 | D20: =B20*C20 -> 1560000
A21: BÍ MINI VÀNG 300GR | D21: =B21*C21 -> 0
A22: BÍ MINI VÀNG KG | D22: =B22*C22 -> 0
A23: BÍ NGÒI VÀNG | D23: =B23*C23 -> 0
A24: BÍ NGÒI VÀNG (TRÁI) | D24: =B24*C24 -> 0
A25: BÍ NGÒI XANH | B25: =18+135 -> 153 | C25: 13000 | D25: =B25*C25 -> 1989000
A26: BÍ NGÒI XANH(TRÁI) | D26: =B26*C26 -> 0
A27: BÍ NHẬT | D27: =B27*C27 -> 0
A28: BƠ 034 | B28: 57 | C28: 12000 | D28: =B28*C28 -> 684000
A29: BƠ 034 COOP | D29: =B29*C29 -> 0
A30: BƠ BOOTH | D30: =B30*C30 -> 0
A31: BO HOA CHUONG | D31: =B31*C31 -> 0
A32: BO HOA CUC TANA | D32: =B32*C32 -> 0
A33: BO HOA DONG TIEN HN | D33: =B33*C33 -> 0
A34: BO HOA LOA KEN | D34: =B34*C34 -> 0
A35: BO HOA PHANG | D35: =B35*C35 -> 0
A36: BO HOA SEN QUAN AM | D36: =B36*C36 -> 0
A37: BO HOA SEN SUPER | D37: =B37*C37 -> 0
A38: BƠ SÁP | B38: 17 | C38: 10000 | D38: =B38*C38 -> 170000
A39: BÓ XÔI | D39: =B39*C39 -> 0
A40: BÓ XÔI 300G VR | D40: =B40*C40 -> 0
...

Sheet 9.7
A1: hàng tồn cuối ngày 9/7 vr
A2: TÊN SẢN PHẨM | B2: TỒN TRƯỚC | C2: GIÁ NHẬP | D2: THÀNH TIỀN
A3: CÀ CHUA SÔCOLA 250GR (HỘP) VR | B3: 40 | C3: 10000 | D3: =B3*C3 -> 400000
A4: CÀ CHUA SÔCOLA 250GR (KG) VR | D4: =B4*C4 -> 0
A5: CÀ CHUA SÔCOLA 300GR (HỘP) VR | D5: =B5*C5 -> 0
A6: CÀ RỐT BABY | D6: =B6*C6 -> 0
A7: CÀ RỐT BABY 200GR | D7: =B7*C7 -> 0
A8: CẢI CẦU VỒNG | D8: =B8*C8 -> 0
A9: CẢI CẦU VỒNG 300GR | D9: =B9*C9 -> 0
A10: CẢI KALE | D10: =B10*C10 -> 0
A11: CẢI KALE 150GR | D11: =B11*C11 -> 0
A12: CẢI KALE 300GR | D12: =B12*C12 -> 0
A13: CHANH VÀNG (KG) | D13: =B13*C13 -> 0
A14: CHANH VÀNG TRÁI 180UP | D14: =B14*C14 -> 0
A15: CẦN TÂY (KG) | B15: 75 | C15: 15000 | D15: =B15*C15 -> 1125000
A16: CẦN TÂY(CÂY) | D16: =B16*C16 -> 0
A17: ỚT CHUÔNG 3 MÀU(KG)VR | D17: =B17*C17 -> 0
A18: ỚT CHUÔNG ĐỎ | B18: 40 | C18: 24000 | D18: =B18*C18 -> 960000
A19: ỚT CHUÔNG ĐỎ(TRÁI) | D19: =B19*C19 -> 0
A20: ỚT CHUÔNG 3 MÀU 350G | B20: 5 | C20: 10000 | D20: =B20*C20 -> 50000
A21: ỚT CHUÔNG VÀNG | D21: =B21*C21 -> 0
A22: ỚT CHUÔNG VÀNG(TRÁI) | D22: =B22*C22 -> 0
A23: ỚT CHUÔNG XANH | B23: 40 | C23: 18000 | D23: =B23*C23 -> 720000
A24: ỚT CHUÔNG XANH(TRÁI) | D24: =B24*C24 -> 0
A25: KHOAI TÂY VÀNG ĐL | B25: 100 | C25: 16000 | D25: =B25*C25 -> 1600000
A26: KHOAI TÂY VÀNG LỚN TÚI LƯỚI 500G | D26: =B26*C26 -> 0
A27: KHOAI TÂY VÀNG TRUNG TÚI LƯỚI 500G | D27: =B27*C27 -> 0
A28: CẢI THẢO DL | D28: =B28*C28 -> 0
A29: CỦ DỀN | D29: =B29*C29 -> 0
A30: CỦ DỀN 600G | D30: =B30*C30 -> 0
A31: XÀ LÁCH MỸ | D31: =B31*C31 -> 0
A32: BẦU | D32: =B32*C32 -> 0
A33: BÍ ĐAO XANH | D33: =B33*C33 -> 0
A34: DƯA LEO | D34: =B34*C34 -> 0
A35: DƯA LEO KG (VỈ) | D35: =B35*C35 -> 0
A36: KHỔ QUA KG(VỈ) | D36: =B36*C36 -> 0
A37: BƠ 034 | D37: =B37*C37 -> 0
A38: BƠ 034 COOP | B38: 18 | C38: 11000 | D38: =B38*C38 -> 198000
A39: BƠ SÁP | B39: 35 | C39: 11000 | D39: =B39*C39 -> 385000
A40: KHOAI LANG MẬT (KG) 2-3 CỦ | B40: 545 | C40: 19000 | D40: =B40*C40 -> 10355000
...

Sheet 10.7
A1: hàng tồn cuối ngày 10/7 vr
A2: TÊN SẢN PHẨM | B2: TỒN TRƯỚC | C2: GIÁ NHẬP | D2: THÀNH TIỀN
A3: BẮP CẢI TÍM | B3: 5 | C3: 14000 | D3: =B3*C3 -> 70000
A4: BẮP CẢI TÍM (BẮP) | D4: =B4*C4 -> 0
A5: BẮP CẢI TÍM SUSHI | D5: =B5*C5 -> 0
A6: BẮP CẢI TRẮNG | B6: 120 | C6: 6500 | D6: =B6*C6 -> 780000
A7: BẮP CẢI TRẮNG (BẮP) | D7: =B7*C7 -> 0
A8: BẮP CẢI TRẮNG MỘC CHÂU | D8: =B8*C8 -> 0
A9: BẮP CẢI TRẮNG SÓI BIỂN | D9: =B9*C9 -> 0
A10: BẮP CẢI TRẮNG SUSHI | D10: =B10*C10 -> 0
A11: BẮP MỸ CẶP | D11: =B11*C11 -> 0
A12: BẦU | D12: =B12*C12 -> 0
A13: BÍ ĐAO XANH | D13: =B13*C13 -> 0
A14: BÍ ĐAO XANH 400G | D14: =B14*C14 -> 0
A15: BÍ ĐỎ HỒ LÔ | D15: =B15*C15 -> 0
A16: BÍ ĐỎ MINI | D16: =B16*C16 -> 0
A17: BÍ ĐỎ NON (KG)KQ | D17: =B17*C17 -> 0
A18: BÍ ĐỎ NON TRÁI VR | D18: =B18*C18 -> 0
A19: BÍ ĐỎ NON( KG) VR | B19: 10 | C19: 4000 | D19: =B19*C19 -> 40000
A20: BÍ ĐỎ TRÒN | B20: 300 | C20: 13000 | D20: =B20*C20 -> 3900000
A21: BÍ MINI VÀNG 300GR | D21: =B21*C21 -> 0
A22: BÍ MINI VÀNG KG | D22: =B22*C22 -> 0
A23: BÍ NGÒI VÀNG | D23: =B23*C23 -> 0
A24: BÍ NGÒI VÀNG (TRÁI) | D24: =B24*C24 -> 0
A25: BÍ NGÒI XANH | B25: =35+80 -> 115 | C25: 13000 | D25: =B25*C25 -> 1495000
A26: BÍ NGÒI XANH(TRÁI) | D26: =B26*C26 -> 0
A27: BÍ NHẬT | D27: =B27*C27 -> 0
A28: BƠ 034 | B28: 27 | C28: 12000 | D28: =B28*C28 -> 324000
A29: BƠ 034 COOP | D29: =B29*C29 -> 0
A30: BƠ BOOTH | D30: =B30*C30 -> 0
A31: BO HOA CHUONG | D31: =B31*C31 -> 0
A32: BO HOA CUC TANA | D32: =B32*C32 -> 0
A33: BO HOA DONG TIEN HN | D33: =B33*C33 -> 0
A34: BO HOA LOA KEN | D34: =B34*C34 -> 0
A35: BO HOA PHANG | D35: =B35*C35 -> 0
A36: BO HOA SEN QUAN AM | D36: =B36*C36 -> 0
A37: BO HOA SEN SUPER | D37: =B37*C37 -> 0
A38: BƠ SÁP | B38: 25 | C38: 11000 | D38: =B38*C38 -> 275000
A39: BÓ XÔI | D39: =B39*C39 -> 0
A40: BÓ XÔI 300G VR | D40: =B40*C40 -> 0
...

Sheet 11.7
A1: hàng tồn cuối ngày 11/7 vr
A2: TÊN SẢN PHẨM | B2: TỒN TRƯỚC | C2: GIÁ NHẬP | D2: THÀNH TIỀN
A3: CÀ CHUA SÔCOLA 250GR (HỘP) VR | B3: =5+25+13 -> 43 | C3: 10000 | D3: =B3*C3 -> 430000
A4: CÀ CHUA SÔCOLA 250GR (KG) -NA | D4: =B4*C4 -> 0
A5: CÀ CHUA SÔCOLA 250GR (KG) VR | D5: =B5*C5 -> 0
A6: CÀ CHUA SÔCOLA 250GR(KG) KQ | D6: =B6*C6 -> 0
A7: CÀ CHUA SÔCOLA 300GR (HỘP) VR | D7: =B7*C7 -> 0
A8: CÀ CHUA SOCOLA XÁ | D8: =B8*C8 -> 0
A9: CÀ CHUA SÔCOLA(HỘP) KQ | D9: =B9*C9 -> 0
A10: CÀ RỐT BABY | D10: =B10*C10 -> 0
A11: CÀ RỐT BABY (KG) KQ | D11: =B11*C11 -> 0
A12: CÀ RỐT BABY 200GR | D12: =B12*C12 -> 0
A13: CẢI CẦU VỒNG | D13: =B13*C13 -> 0
A14: CẢI CẦU VỒNG 300GR | D14: =B14*C14 -> 0
A15: CẢI KALE | D15: =B15*C15 -> 0
... A23: ỚT CHUÔNG 3 MÀU(KG)VR | D23: =B23*C23 -> 0
A24: ỚT CHUÔNG ĐỎ | B24: =18+13+13+5+40-20 -> 69 | C24: 24000 | D24: =B24*C24 -> 1656000
A25: ỚT CHUÔNG ĐỎ L1 | D25: =B25*C25 -> 0
A26: ỚT CHUÔNG ĐỎ(TRÁI) | D26: =B26*C26 -> 0
A27: ỚT CHUÔNG 3 MÀU 350G | B27: 2 | C27: 10000 | D27: =B27*C27 -> 20000
A28: ỚT CHUÔNG 3 MÀU KQ(KG) | D28: =B28*C28 -> 0
A29: ỚT CHUÔNG VÀNG | B29: =37+40-20 -> 57 | C29: 29000 | D29: =B29*C29 -> 1653000
A30: ỚT CHUÔNG VÀNG L1 | D30: =B30*C30 -> 0
A31: ỚT CHUÔNG VÀNG(TRÁI) | D31: =B31*C31 -> 0
A32: ỚT CHUÔNG VÀNG+ XANH (VỈ) | D32: =B32*C32 -> 0
A33: ỚT CHUÔNG XANH | B33: =8+6+10-20 -> 4 | C33: 18000 | D33: =B33*C33 -> 72000
A34: ỚT CHUÔNG XANH L1 | D34: =B34*C34 -> 0
A35: ỚT CHUÔNG XANH(TRÁI) | D35: =B35*C35 -> 0
A36: CỦ DỀN | B36: =12+20+28+30-60 -> 30 | C36: 14000 | D36: =B36*C36 -> 420000
A37: CỦ DỀN 600G | D37: =B37*C37 -> 0
A38: GỪNG 250GR | D38: =B38*C38 -> 0
A39: HỒNG GIÒN | D39: =B39*C39 -> 0
A40: XÀ LÁCH MỸ | D40: =B40*C40 -> 0
A41: KHOAI TÂY HỒNG | D41: =B41*C41 -> 0
A42: KHOAI TÂY HỒNG TÚI LƯỚI 500G | D42: =B42*C42 -> 0
A43: KHOAI TÂY VÀNG | D43: =B43*C43 -> 0
A44: KHOAI TÂY VÀNG ĐL | B44: =140+140+80+50-300 -> 110 | C44: 15000 | D44: =B44*C44 -> 1650000
A45: KHOAI TÂY VÀNG LỚN TÚI LƯỚI 500G | D45: =B45*C45 -> 0
A46: KHOAI TÂY VÀNG TRUNG TÚI LƯỚI 500G | D46: =B46*C46 -> 0
A47: CẢI THẢO DL | B47: 250 | C47: 7000 | D47: =B47*C47 -> 1750000
...

Sheet 12.7
A1: hàng tồn cuối ngày 12/7 vr
A2: TÊN SẢN PHẨM | B2: TỒN TRƯỚC | C2: GIÁ NHẬP | D2: THÀNH TIỀN
A3: BẮP CẢI TÍM | B3: 5 | C3: 14000 | D3: =B3*C3 -> 70000
A4: BẮP CẢI TÍM (BẮP) | D4: =B4*C4 -> 0
A5: BẮP CẢI TÍM SUSHI | D5: =B5*C5 -> 0
A6: BẮP CẢI TRẮNG | D6: =B6*C6 -> 0
A7: BẮP CẢI TRẮNG (BẮP) | D7: =B7*C7 -> 0
A8: BẮP CẢI TRẮNG MỘC CHÂU | D8: =B8*C8 -> 0
A9: BẮP CẢI TRẮNG SÓI BIỂN | D9: =B9*C9 -> 0
A10: BẮP CẢI TRẮNG SUSHI | D10: =B10*C10 -> 0
A11: BẮP MỸ CẶP | D11: =B11*C11 -> 0
A12: BẦU | D12: =B12*C12 -> 0
A13: BÍ ĐAO XANH | D13: =B13*C13 -> 0
A14: BÍ ĐAO XANH 400G | D14: =B14*C14 -> 0
A15: BÍ ĐỎ HỒ LÔ | B15: =5+15 -> 20 | C15: 18000 | D15: =B15*C15 -> 360000
A16: BÍ ĐỎ MINI | D16: =B16*C16 -> 0
A17: BÍ ĐỎ NON (KG)KQ | D17: =B17*C17 -> 0
A18: BÍ ĐỎ NON TRÁI VR | B18: =22+60 -> 82 | C18: 4000 | D18: =B18*C18 -> 328000
A19: BÍ ĐỎ NON( KG) VR | D19: =B19*C19 -> 0
A20: BÍ ĐỎ TRÒN | B20: =-1000+1148+280 -> 428 | C20: 13000 | D20: =B20*C20 -> 5564000
A21: BÍ MINI VÀNG 300GR | D21: =B21*C21 -> 0
A22: BÍ MINI VÀNG KG | D22: =B22*C22 -> 0
A23: BÍ NGÒI VÀNG | D23: =B23*C23 -> 0
A24: BÍ NGÒI VÀNG (TRÁI) | D24: =B24*C24 -> 0
A25: BÍ NGÒI XANH | B25: =-30+45+30+40 -> 85 | C25: 9000 | D25: =B25*C25 -> 765000
A26: BÍ NGÒI XANH(TRÁI) | D26: =B26*C26 -> 0
A27: BÍ NHẬT | D27: =B27*C27 -> 0
A28: BƠ 034 | B28: =13+80 -> 93 | C28: 12500 | D28: =B28*C28 -> 1162500
A29: BƠ 034 COOP | D29: =B29*C29 -> 0
A30: BƠ BOOTH | D30: =B30*C30 -> 0
A31: BO HOA CHUONG | D31: =B31*C31 -> 0
A32: BO HOA CUC TANA | D32: =B32*C32 -> 0
A33: BO HOA DONG TIEN HN | D33: =B33*C33 -> 0
A34: BO HOA LOA KEN | D34: =B34*C34 -> 0
A35: BO HOA PHANG | D35: =B35*C35 -> 0
A36: BO HOA SEN QUAN AM | D36: =B36*C36 -> 0
A37: BO HOA SEN SUPER | D37: =B37*C37 -> 0
A38: BƠ SÁP | B38: 12 | C38: 11000 | D38: =B38*C38 -> 132000
A39: BÓ XÔI | D39: =B39*C39 -> 0
A40: BÓ XÔI 300G VR | D40: =B40*C40 -> 0
...

Sheet 13.7
A1: hàng tồn cuối ngày 13/7 vr
A2: TÊN SẢN PHẨM | B2: TỒN TRƯỚC | C2: GIÁ NHẬP | D2: THÀNH TIỀN
A3: BẮP CẢI TÍM | B3: =25+95 -> 120 | C3: 14000 | D3: =B3*C3 -> 1680000
A4: BẮP CẢI TÍM (BẮP) | D4: =B4*C4 -> 0
A5: BẮP CẢI TÍM SUSHI | D5: =B5*C5 -> 0
A6: BẮP CẢI TRẮNG | D6: =B6*C6 -> 0
A7: BẮP CẢI TRẮNG (BẮP) | D7: =B7*C7 -> 0
A8: BẮP CẢI TRẮNG MỘC CHÂU | D8: =B8*C8 -> 0
A9: BẮP CẢI TRẮNG SÓI BIỂN | D9: =B9*C9 -> 0
A10: BẮP CẢI TRẮNG SUSHI | D10: =B10*C10 -> 0
A11: BẮP MỸ CẶP | D11: =B11*C11 -> 0
A12: BẦU | D12: =B12*C12 -> 0
A13: BÍ ĐAO XANH | D13: =B13*C13 -> 0
A14: BÍ ĐAO XANH 400G | D14: =B14*C14 -> 0
A15: BÍ ĐỎ HỒ LÔ | B15: 8 | C15: 18000 | D15: =B15*C15 -> 144000
A16: BÍ ĐỎ MINI | D16: =B16*C16 -> 0
A17: BÍ ĐỎ NON (KG)KQ | D17: =B17*C17 -> 0
A18: BÍ ĐỎ NON TRÁI VR | B18: 25 | C18: 4000 | D18: =B18*C18 -> 100000
A19: BÍ ĐỎ NON( KG) VR | B19: 10 | C19: 14000 | D19: =B19*C19 -> 140000
A20: BÍ ĐỎ TRÒN | B20: =-1000+1262+580+370 -> 1212 | C20: 14000 | D20: =B20*C20 -> 16968000
A21: BÍ MINI VÀNG 300GR | D21: =B21*C21 -> 0
A22: BÍ MINI VÀNG KG | D22: =B22*C22 -> 0
A23: BÍ NGÒI VÀNG | D23: =B23*C23 -> 0
A24: BÍ NGÒI VÀNG (TRÁI) | D24: =B24*C24 -> 0
A25: BÍ NGÒI XANH | B25: =-30+75+23 -> 68 | C25: 9000 | D25: =B25*C25 -> 612000
A26: BÍ NGÒI XANH(TRÁI) | D26: =B26*C26 -> 0
A27: BÍ NHẬT | D27: =B27*C27 -> 0
A28: BƠ 034 | D28: =B28*C28 -> 0
A29: BƠ 034 COOP | D29: =B29*C29 -> 0
A30: BƠ BOOTH | D30: =B30*C30 -> 0
A31: BO HOA CHUONG | D31: =B31*C31 -> 0
A32: BO HOA CUC TANA | D32: =B32*C32 -> 0
A33: BO HOA DONG TIEN HN | D33: =B33*C33 -> 0
A34: BO HOA LOA KEN | D34: =B34*C34 -> 0
A35: BO HOA PHANG | D35: =B35*C35 -> 0
A36: BO HOA SEN QUAN AM | D36: =B36*C36 -> 0
A37: BO HOA SEN SUPER | D37: =B37*C37 -> 0
... A63: CÀ CHUA CHERRY MIX 300G | D63: =B63*C63 -> 0
A64: CÀ CHUA L1 | B64: 40 | C64: 14000 | D64: =B64*C64 -> 560000
A65: CÀ CHUA MỘC CHÂU | D65: =B65*C65 -> 0
...

Sheet 14.7
A1: hàng tồn cuối ngaỳ 14/7 vr
A2: TÊN SẢN PHẨM | B2: TỒN TRƯỚC | C2: GIÁ NHẬP | D2: THÀNH TIỀN
A3: BẮP CẢI TÍM | B3: 17 | C3: 14000 | D3: =B3*C3 -> 238000
A4: BẮP CẢI TÍM (BẮP) | D4: =B4*C4 -> 0
A5: BẮP CẢI TÍM SUSHI | D5: =B5*C5 -> 0
A6: BẮP CẢI TRẮNG | D6: =B6*C6 -> 0
A7: BẮP CẢI TRẮNG (BẮP) | D7: =B7*C7 -> 0
A8: BẮP CẢI TRẮNG MỘC CHÂU | D8: =B8*C8 -> 0
A9: BẮP CẢI TRẮNG SÓI BIỂN | D9: =B9*C9 -> 0
A10: BẮP CẢI TRẮNG SUSHI | D10: =B10*C10 -> 0
A11: BẮP MỸ CẶP | D11: =B11*C11 -> 0
A12: BẦU | D12: =B12*C12 -> 0
A13: BÍ ĐAO XANH | D13: =B13*C13 -> 0
A14: BÍ ĐAO XANH 400G | D14: =B14*C14 -> 0
A15: BÍ ĐỎ HỒ LÔ | B15: =10+15 -> 25 | C15: 18000 | D15: =B15*C15 -> 450000
A16: BÍ ĐỎ MINI | D16: =B16*C16 -> 0
A17: BÍ ĐỎ NON (KG)KQ | D17: =B17*C17 -> 0
A18: BÍ ĐỎ NON TRÁI VR | D18: =B18*C18 -> 0
A19: BÍ ĐỎ NON( KG) VR | D19: =B19*C19 -> 0
A20: BÍ ĐỎ TRÒN | B20: =-1000+1200+450+210+60 -> 920 | C20: 14000 | D20: =B20*C20 -> 12880000
A21: BÍ MINI VÀNG 300GR | D21: =B21*C21 -> 0
A22: BÍ MINI VÀNG KG | D22: =B22*C22 -> 0
A23: BÍ NGÒI VÀNG | D23: =B23*C23 -> 0
A24: BÍ NGÒI VÀNG (TRÁI) | D24: =B24*C24 -> 0
A25: BÍ NGÒI XANH | B25: =-30+25+12+50 -> 57 | C25: 9000 | D25: =B25*C25 -> 513000
A26: BÍ NGÒI XANH(TRÁI) | D26: =B26*C26 -> 0
A27: BÍ NHẬT | D27: =B27*C27 -> 0
A28: BƠ 034 | B28: 24 | C28: 12500 | D28: =B28*C28 -> 300000
A29: BƠ 034 COOP | D29: =B29*C29 -> 0
A30: BƠ BOOTH | D30: =B30*C30 -> 0
A31: BO HOA CHUONG | D31: =B31*C31 -> 0
A32: BO HOA CUC TANA | D32: =B32*C32 -> 0
A33: BO HOA DONG TIEN HN | D33: =B33*C33 -> 0
A34: BO HOA LOA KEN | D34: =B34*C34 -> 0
A35: BO HOA PHANG | D35: =B35*C35 -> 0
A36: BO HOA SEN QUAN AM | D36: =B36*C36 -> 0
A37: BO HOA SEN SUPER | D37: =B37*C37 -> 0
A38: BƠ SÁP | D38: =B38*C38 -> 0
A39: BÓ XÔI | D39: =B39*C39 -> 0
A40: BÓ XÔI 300G VR | D40: =B40*C40 -> 0
...

Sheet 15.7
A1: hàng tồn cuối ngày 15/7 vr
A2: TÊN SẢN PHẨM | B2: TỒN TRƯỚC | C2: GIÁ NHẬP | D2: THÀNH TIỀN
A3: BẮP CẢI TÍM | B3: =5+11 -> 16 | C3: 14000 | D3: =B3*C3 -> 224000
A4: BẮP CẢI TÍM (BẮP) | D4: =B4*C4 -> 0
A5: BẮP CẢI TÍM SUSHI | D5: =B5*C5 -> 0
A6: BẮP CẢI TRẮNG | D6: =B6*C6 -> 0
A7: BẮP CẢI TRẮNG (BẮP) | D7: =B7*C7 -> 0
A8: BẮP CẢI TRẮNG MỘC CHÂU | D8: =B8*C8 -> 0
A9: BẮP CẢI TRẮNG SÓI BIỂN | D9: =B9*C9 -> 0
A10: BẮP CẢI TRẮNG SUSHI | D10: =B10*C10 -> 0
A11: BẮP MỸ CẶP | D11: =B11*C11 -> 0
A12: BẦU | D12: =B12*C12 -> 0
A13: BÍ ĐAO XANH | D13: =B13*C13 -> 0
A14: BÍ ĐAO XANH 400G | D14: =B14*C14 -> 0
A15: BÍ ĐỎ HỒ LÔ | B15: 5 | C15: 18000 | D15: =B15*C15 -> 90000
A16: BÍ ĐỎ MINI | D16: =B16*C16 -> 0
A17: BÍ ĐỎ NON (KG)KQ | D17: =B17*C17 -> 0
A18: BÍ ĐỎ NON TRÁI VR | D18: =B18*C18 -> 0
A19: BÍ ĐỎ NON( KG) VR | B19: 27 | C19: 14000 | D19: =B19*C19 -> 378000
A20: BÍ ĐỎ TRÒN | B20: =-1000+1970 -> 970 | C20: 14000 | D20: =B20*C20 -> 13580000
A21: BÍ MINI VÀNG 300GR | D21: =B21*C21 -> 0
A22: BÍ MINI VÀNG KG | D22: =B22*C22 -> 0
A23: BÍ NGÒI VÀNG | D23: =B23*C23 -> 0
A24: BÍ NGÒI VÀNG (TRÁI) | D24: =B24*C24 -> 0
A25: BÍ NGÒI XANH | B25: =-30+15+10+35+30 -> 60 | C25: 90000 | D25: =B25*C25 -> 5400000
A26: BÍ NGÒI XANH(TRÁI) | D26: =B26*C26 -> 0
A27: BÍ NHẬT | D27: =B27*C27 -> 0
A28: BƠ 034 | B28: =9+17+18 -> 44 | C28: 15500 | D28: =B28*C28 -> 682000
A29: BƠ 034 COOP | B29: 9 | C29: 14500 | D29: =B29*C29 -> 130500
A30: BƠ BOOTH | D30: =B30*C30 -> 0
A31: BO HOA CHUONG | D31: =B31*C31 -> 0
A32: BO HOA CUC TANA | D32: =B32*C32 -> 0
A33: BO HOA DONG TIEN HN | D33: =B33*C33 -> 0
A34: BO HOA LOA KEN | D34: =B34*C34 -> 0
A35: BO HOA PHANG | D35: =B35*C35 -> 0
A36: BO HOA SEN QUAN AM | D36: =B36*C36 -> 0
A37: BO HOA SEN SUPER | D37: =B37*C37 -> 0
A38: BƠ SÁP | B38: =70+15+5-18-30 -> 42 | C38: 11000 | D38: =B38*C38 -> 462000
A39: BÓ XÔI | D39: =B39*C39 -> 0
A40: BÓ XÔI 300G VR | D40: =B40*C40 -> 0
...

Sheet 16.7
A1: hàng tồn cuối ngày 16/7 vr
A2: TÊN SẢN PHẨM | B2: TỒN TRƯỚC | C2: GIÁ NHẬP | D2: THÀNH TIỀN
A3: CÀ CHUA SÔCOLA 250GR (HỘP) VR | B3: 12 | C3: 10000 | D3: =B3*C3 -> 120000
A4: CÀ CHUA SÔCOLA 250GR (KG) -NA | D4: =B4*C4 -> 0
A5: CÀ CHUA SÔCOLA 250GR (KG) VR | D5: =B5*C5 -> 0
A6: CÀ CHUA SÔCOLA 300GR (HỘP) VR | D6: =B6*C6 -> 0
A7: CÀ RỐT BABY | D7: =B7*C7 -> 0
A8: CÀ RỐT BABY 200GR | D8: =B8*C8 -> 0
A9: CẢI CẦU VỒNG | D9: =B9*C9 -> 0
A10: CẢI CẦU VỒNG 300GR | D10: =B10*C10 -> 0
A11: CẢI KALE | D11: =B11*C11 -> 0
A12: CẢI KALE 150GR | D12: =B12*C12 -> 0
A13: CẢI KALE 300GR | D13: =B13*C13 -> 0
A14: CHANH VÀNG (KG) | D14: =B14*C14 -> 0
A15: CHANH VÀNG TRÁI 180UP | D15: =B15*C15 -> 0
... A18: ỚT CHUÔNG 3 MÀU(KG)VR | D18: =B18*C18 -> 0
A19: ỚT CHUÔNG ĐỎ | B19: 116 | C19: 27000 | D19: =B19*C19 -> 3132000
A20: ỚT CHUÔNG ĐỎ L1 | B20: 3 | C20: 24000 | D20: =B20*C20 -> 72000
A21: ỚT CHUÔNG ĐỎ(TRÁI) | D21: =B21*C21 -> 0
A22: ỚT CHUÔNG 3 MÀU 350G | D22: =B22*C22 -> 0
A23: ỚT CHUÔNG VÀNG | B23: 64 | C23: 30000 | D23: =B23*C23 -> 1920000
A24: ỚT CHUÔNG VÀNG L1 | B24: 2 | C24: 24000 | D24: =B24*C24 -> 48000
A25: ỚT CHUÔNG VÀNG(TRÁI) | D25: =B25*C25 -> 0
A26: ỚT CHUÔNG XANH | B26: 7 | C26: 16000 | D26: =B26*C26 -> 112000
A27: ỚT CHUÔNG XANH L1 | B27: 2 | C27: 14000 | D27: =B27*C27 -> 28000
A28: ỚT CHUÔNG XANH(TRÁI) | D28: =B28*C28 -> 0
A29: CỦ DỀN | B29: 60 | C29: 14000 | D29: =B29*C29 -> 840000
A30: CỦ DỀN 600G | D30: =B30*C30 -> 0
A31: XÀ LÁCH MỸ | D31: =B31*C31 -> 0
A32: KHOAI TÂY HỒNG | D32: =B32*C32 -> 0
A33: KHOAI TÂY VÀNG ĐL | B33: 105 | C33: 15000 | D33: =B33*C33 -> 1575000
A34: KHOAI TÂY VÀNG LỚN TÚI LƯỚI 500G | D34: =B34*C34 -> 0
A35: KHOAI TÂY VÀNG TRUNG TÚI LƯỚI 500G | B35: 60 | C35: 13000 | D35: =B35*C35 -> 780000
A36: CẢI THẢO DL | D36: =B36*C36 -> 0
A37: DƯA LEO | D37: =B37*C37 -> 0
A38: DƯA LEO KG (VỈ) | D38: =B38*C38 -> 0
A39: KHỔ QUA KG(VỈ) | B39: 1 | C39: 20000 | D39: =B39*C39 -> 20000
A40: BÍ MINI VÀNG KG | D40: =B40*C40 -> 0
A41: DƯA LEO GIỐNG NHẬT 600GR | D41: =B41*C41 -> 0
A42: DƯA LEO GIỐNG NHẬT KG | D42: =B42*C42 -> 0
...

Sheet 17.7
A1: hàng tồn cuối ngày 17/7 vr
A2: TÊN SẢN PHẨM | B2: TỒN TRƯỚC | C2: GIÁ NHẬP | D2: THÀNH TIỀN
A3: BẮP CẢI TÍM | B3: 15 | C3: 14000 | D3: =B3*C3 -> 210000
A4: BẮP CẢI TÍM (BẮP) | D4: =B4*C4 -> 0
A5: BẮP CẢI TÍM SUSHI | D5: =B5*C5 -> 0
A6: BẮP CẢI TRẮNG | D6: =B6*C6 -> 0
A7: BẮP CẢI TRẮNG (BẮP) | D7: =B7*C7 -> 0
A8: BẮP CẢI TRẮNG MỘC CHÂU | D8: =B8*C8 -> 0
A9: BẮP CẢI TRẮNG SÓI BIỂN | D9: =B9*C9 -> 0
A10: BẮP CẢI TRẮNG SUSHI | D10: =B10*C10 -> 0
A11: BẮP MỸ CẶP | D11: =B11*C11 -> 0
A12: BẦU | D12: =B12*C12 -> 0
A13: BÍ ĐAO XANH | D13: =B13*C13 -> 0
A14: BÍ ĐAO XANH 400G | D14: =B14*C14 -> 0
A15: BÍ ĐỎ HỒ LÔ | D15: =B15*C15 -> 0
... A17: BÍ ĐỎ NON (KG)KQ | D17: =B17*C17 -> 0
A18: BÍ ĐỎ NON TRÁI VR | B18: 14 | C18: 4000 | D18: =B18*C18 -> 56000
A19: BÍ ĐỎ NON( KG) VR | D19: =B19*C19 -> 0
A20: BÍ ĐỎ TRÒN | B20: =-1000+588+1106+120 -> 814 | C20: 14000 | D20: =B20*C20 -> 11396000
A21: BÍ MINI VÀNG 300GR | D21: =B21*C21 -> 0
A22: BÍ MINI VÀNG KG | D22: =B22*C22 -> 0
A23: BÍ NGÒI VÀNG | B23: 4 | C23: 35000 | D23: =B23*C23 -> 140000
A24: BÍ NGÒI VÀNG (TRÁI) | D24: =B24*C24 -> 0
A25: BÍ NGÒI XANH | B25: =-30+5+11+25 -> 11 | C25: 9000 | D25: =B25*C25 -> 99000
A26: BÍ NGÒI XANH(TRÁI) | D26: =B26*C26 -> 0
A27: BÍ NHẬT | D27: =B27*C27 -> 0
A28: BƠ 034 | B28: =55+18+76 -> 149 | C28: 15500 | D28: =B28*C28 -> 2309500
A29: BƠ 034 COOP | D29: =B29*C29 -> 0
A30: BƠ BOOTH | D30: =B30*C30 -> 0
A31: BO HOA CHUONG | D31: =B31*C31 -> 0
A32: BO HOA CUC TANA | D32: =B32*C32 -> 0
A33: BO HOA DONG TIEN HN | D33: =B33*C33 -> 0
A34: BO HOA LOA KEN | D34: =B34*C34 -> 0
A35: BO HOA PHANG | D35: =B35*C35 -> 0
A36: BO HOA SEN QUAN AM | D36: =B36*C36 -> 0
A37: BO HOA SEN SUPER | D37: =B37*C37 -> 0
A38: BƠ SÁP | B38: 10 | C38: 11000 | D38: =B38*C38 -> 110000
A39: BÓ XÔI | D39: =B39*C39 -> 0
A40: BÓ XÔI 300G VR | D40: =B40*C40 -> 0
A41: BÓ XÔI-NA | D41: =B41*C41 -> 0
...

Sheet 18.7
A1: hàng tồn cuối ngày 18/7 vr
A2: TÊN SẢN PHẨM | B2: TỒN TRƯỚC | C2: GIÁ NHẬP | D2: THÀNH TIỀN
A3: BẮP CẢI TÍM | B3: 4 | C3: 14000 | D3: =B3*C3 -> 56000
A4: BẮP CẢI TÍM (BẮP) | D4: =B4*C4 -> 0
A5: BẮP CẢI TÍM SUSHI | D5: =B5*C5 -> 0
A6: BẮP CẢI TRẮNG | D6: =B6*C6 -> 0
A7: BẮP CẢI TRẮNG (BẮP) | D7: =B7*C7 -> 0
A8: BẮP CẢI TRẮNG MỘC CHÂU | D8: =B8*C8 -> 0
A9: BẮP CẢI TRẮNG SÓI BIỂN | D9: =B9*C9 -> 0
A10: BẮP CẢI TRẮNG SUSHI | D10: =B10*C10 -> 0
A11: BẮP MỸ CẶP | D11: =B11*C11 -> 0
A12: BẦU | D12: =B12*C12 -> 0
A13: BÍ ĐAO XANH | D13: =B13*C13 -> 0
A14: BÍ ĐAO XANH 400G | D14: =B14*C14 -> 0
A15: BÍ ĐỎ HỒ LÔ | B15: 8 | C15: 18000 | D15: =B15*C15 -> 144000
A16: BÍ ĐỎ MINI | D16: =B16*C16 -> 0
A17: BÍ ĐỎ NON (KG)KQ | D17: =B17*C17 -> 0
A18: BÍ ĐỎ NON TRÁI VR | D18: =B18*C18 -> 0
A19: BÍ ĐỎ NON( KG) VR | D19: =B19*C19 -> 0
A20: BÍ ĐỎ TRÒN | B20: =-1000+2430 -> 1430 | C20: 14000 | D20: =B20*C20 -> 20020000
A21: BÍ MINI VÀNG 300GR | D21: =B21*C21 -> 0
A22: BÍ MINI VÀNG KG | D22: =B22*C22 -> 0
A23: BÍ NGÒI VÀNG | D23: =B23*C23 -> 0
A24: BÍ NGÒI VÀNG (TRÁI) | D24: =B24*C24 -> 0
A25: BÍ NGÒI XANH | B25: =-30+37+25+30 -> 62 | C25: 9000 | D25: =B25*C25 -> 558000
A26: BÍ NGÒI XANH(TRÁI) | D26: =B26*C26 -> 0
A27: BÍ NHẬT | D27: =B27*C27 -> 0
A28: BƠ 034 | D28: =B28*C28 -> 0
A29: BƠ 034 COOP | D29: =B29*C29 -> 0
A30: BƠ BOOTH | D30: =B30*C30 -> 0
A31: BO HOA CHUONG | D31: =B31*C31 -> 0
A32: BO HOA CUC TANA | D32: =B32*C32 -> 0
A33: BO HOA DONG TIEN HN | D33: =B33*C33 -> 0
A34: BO HOA LOA KEN | D34: =B34*C34 -> 0
A35: BO HOA PHANG | D35: =B35*C35 -> 0
A36: BO HOA SEN QUAN AM | D36: =B36*C36 -> 0
A37: BO HOA SEN SUPER | D37: =B37*C37 -> 0
... A53: BÔNG CẢI XANH CITI | D53: =B53*C53 -> 0
A54: CÀ CHUA | B54: =-300+140+60+40+50+180+60 -> 230 | C54: 18000 | D54: =B54*C54 -> 4140000
A55: CÀ CHUA BI | D55: =B55*C55 -> 0
...

Sheet 19.7
A1: hàng tồn cuối ngày 18/7 vr
A2: TÊN SẢN PHẨM | B2: TỒN TRƯỚC | C2: GIÁ NHẬP | D2: THÀNH TIỀN
A3: BẮP CẢI TÍM | D3: =SUM(B3*C3) -> 0
A4: BẮP CẢI TÍM (BẮP) | D4: =SUM(B4*C4) -> 0
A5: BẮP CẢI TÍM SUSHI | D5: =SUM(B5*C5) -> 0
A6: BẮP CẢI TRẮNG | D6: =SUM(B6*C6) -> 0
A7: BẮP CẢI TRẮNG (BẮP) | D7: =SUM(B7*C7) -> 0
A8: BẮP CẢI TRẮNG MỘC CHÂU | D8: =SUM(B8*C8) -> 0
A9: BẮP CẢI TRẮNG SÓI BIỂN | D9: =SUM(B9*C9) -> 0
A10: BẮP CẢI TRẮNG SUSHI | D10: =SUM(B10*C10) -> 0
A11: BẮP MỸ CẶP | D11: =SUM(B11*C11) -> 0
A12: BẦU | D12: =SUM(B12*C12) -> 0
A13: BÍ ĐAO XANH | D13: =SUM(B13*C13) -> 0
A14: BÍ ĐAO XANH 400G | D14: =SUM(B14*C14) -> 0
A15: BÍ ĐỎ HỒ LÔ | B15: 12 | C15: 18000 | D15: =SUM(B15*C15) -> 216000
A16: BÍ ĐỎ MINI | D16: =SUM(B16*C16) -> 0
A17: BÍ ĐỎ NON (KG)KQ | D17: =SUM(B17*C17) -> 0
A18: BÍ ĐỎ NON TRÁI VR | B18: 15 | C18: 4000 | D18: =SUM(B18*C18) -> 60000
A19: BÍ ĐỎ NON( KG) VR | B19: 10 | C19: 14000 | D19: =SUM(B19*C19) -> 140000
A20: BÍ ĐỎ TRÒN | B20: =-1000+2070 -> 1070 | C20: 14000 | D20: =SUM(B20*C20) -> 14980000
A21: BÍ MINI VÀNG 300GR | D21: =SUM(B21*C21) -> 0
A22: BÍ MINI VÀNG KG | D22: =SUM(B22*C22) -> 0
A23: BÍ NGÒI VÀNG | D23: =SUM(B23*C23) -> 0
A24: BÍ NGÒI VÀNG (TRÁI) | D24: =SUM(B24*C24) -> 0
A25: BÍ NGÒI XANH | B25: =-30+40+30+10 -> 50 | C25: 9000 | D25: =SUM(B25*C25) -> 450000
A26: BÍ NGÒI XANH(TRÁI) | D26: =SUM(B26*C26) -> 0
A27: BÍ NHẬT | D27: =SUM(B27*C27) -> 0
A28: BƠ 034 | B28: 8 | C28: 16500 | D28: =SUM(B28*C28) -> 132000
A29: BƠ 034 COOP | D29: =SUM(B29*C29) -> 0
A30: BƠ BOOTH | D30: =SUM(B30*C30) -> 0
A31: BO HOA CHUONG | D31: =SUM(B31*C31) -> 0
A32: BO HOA CUC TANA | D32: =SUM(B32*C32) -> 0
A33: BO HOA DONG TIEN HN | D33: =SUM(B33*C33) -> 0
A34: BO HOA LOA KEN | D34: =SUM(B34*C34) -> 0
A35: BO HOA PHANG | D35: =SUM(B35*C35) -> 0
A36: BO HOA SEN QUAN AM | D36: =SUM(B36*C36) -> 0
A37: BO HOA SEN SUPER | D37: =SUM(B37*C37) -> 0
A38: BƠ SÁP | D38: =SUM(B38*C38) -> 0
A39: BÓ XÔI | D39: =SUM(B39*C39) -> 0
A40: BÓ XÔI 300G VR | D40: =SUM(B40*C40) -> 0
...

Sheet 20.7
A1: hàng tồn cuối ngày 20/7 vr
A2: TÊN SẢN PHẨM | B2: TỒN TRƯỚC | C2: GIÁ NHẬP | D2: THÀNH TIỀN
A3: CÀ CHUA SÔCOLA 250GR (HỘP) VR | D3: =B3*C3 -> 0
A4: CÀ CHUA SÔCOLA 250GR (KG) VR | D4: =B4*C4 -> 0
A5: CÀ CHUA SÔCOLA 300GR (HỘP) VR | D5: =B5*C5 -> 0
A6: CÀ RỐT BABY 200GR | D6: =B6*C6 -> 0
A7: CẢI CẦU VỒNG | D7: =B7*C7 -> 0
A8: CẢI KALE 150GR | D8: =B8*C8 -> 0
A9: CẢI KALE 300GR | D9: =B9*C9 -> 0
A10: CHANH VÀNG (KG) | D10: =B10*C10 -> 0
A11: CHANH VÀNG TRÁI 180UP | D11: =B11*C11 -> 0
A12: CẦN TÂY (KG) | D12: =B12*C12 -> 0
A13: CẦN TÂY(CÂY) | D13: =B13*C13 -> 0
A14: ỚT CHUÔNG 3 MÀU(KG)VR | D14: =B14*C14 -> 0
A15: ỚT CHUÔNG ĐỎ L1 | B15: 45 | C15: 25000 | D15: =B15*C15 -> 1125000
A16: ỚT CHUÔNG ĐỎ(TRÁI) | D16: =B16*C16 -> 0
A17: ỚT CHUÔNG 3 MÀU 350G | D17: =B17*C17 -> 0
A18: ỚT CHUÔNG VÀNG | B18: 50 | C18: 27000 | D18: =B18*C18 -> 1350000
A19: ỚT CHUÔNG VÀNG(TRÁI) | D19: =B19*C19 -> 0
A20: ỚT CHUÔNG XANH | B20: 20 | C20: 18000 | D20: =B20*C20 -> 360000
A21: ỚT CHUÔNG XANH L1 | B21: 10 | C21: 14000 | D21: =B21*C21 -> 140000
A22: ỚT CHUÔNG XANH(TRÁI) | D22: =B22*C22 -> 0
A23: CỦ DỀN | B23: 60 | C23: 15000 | D23: =B23*C23 -> 900000
A24: CỦ DỀN 600G | D24: =B24*C24 -> 0
A25: XÀ LÁCH MỸ | D25: =B25*C25 -> 0
A26: KHOAI TÂY VÀNG ĐL | D26: =B26*C26 -> 0
A27: KHOAI TÂY VÀNG LỚN TÚI LƯỚI 500G | D27: =B27*C27 -> 0
A28: KHOAI TÂY VÀNG TRUNG TÚI LƯỚI 500G | B28: 22 | C28: 13000 | D28: =B28*C28 -> 286000
A29: CẢI THẢO DL | B29: 98 | C29: 7000 | D29: =B29*C29 -> 686000
A30: DƯA LEO | D30: =B30*C30 -> 0
A31: DƯA LEO KG (VỈ) | D31: =B31*C31 -> 0
A32: KHỔ QUA KG(VỈ) | B32: 5 | C32: 20000 | D32: =B32*C32 -> 100000
A33: DƯA LEO GIỐNG NHẬT 600GR | D33: =B33*C33 -> 0
A34: DƯA LEO GIỐNG NHẬT KG | D34: =B34*C34 -> 0
A35: BƠ 034 | B35: 32 | C35: 16500 | D35: =B35*C35 -> 528000
A36: BƠ SÁP | D36: =B36*C36 -> 0
A37: KHOAI LANG MẬT (KG) 2-3 CỦ | B37: 20 | C37: 19000 | D37: =B37*C37 -> 380000
A38: KHOAI LANG MẬT (KG) 4-6 CỦ | B38: 380 | C38: 20000 | D38: =B38*C38 -> 7600000
A39: KHOAI LANG MẬT 500G VR | D39: =B39*C39 -> 0
A40: PARO | B40: 35 | C40: 14000 | D40: =B40*C40 -> 490000
...

Sheet 21.7
A1: hàng tồn cuối ngày 21/7 vr
A2: TÊN SẢN PHẨM | B2: TỒN TRƯỚC | C2: GIÁ NHẬP | D2: THÀNH TIỀN
A3: BẮP CẢI TÍM | B3: 2 | C3: 14000 | D3: =B3*C3 -> 28000
A4: BẮP CẢI TÍM (BẮP) | D4: =B4*C4 -> 0
A5: BẮP CẢI TÍM SUSHI | D5: =B5*C5 -> 0
A6: BẮP CẢI TRẮNG | D6: =B6*C6 -> 0
A7: BẮP CẢI TRẮNG (BẮP) | D7: =B7*C7 -> 0
A8: BẮP CẢI TRẮNG MỘC CHÂU | D8: =B8*C8 -> 0
A9: BẮP CẢI TRẮNG SÓI BIỂN | D9: =B9*C9 -> 0
A10: BẮP CẢI TRẮNG SUSHI | D10: =B10*C10 -> 0
A11: BẮP MỸ CẶP | D11: =B11*C11 -> 0
A12: BẦU | D12: =B12*C12 -> 0
A13: BÍ ĐAO XANH | D13: =B13*C13 -> 0
A14: BÍ ĐAO XANH 400G | D14: =B14*C14 -> 0
A15: BÍ ĐỎ HỒ LÔ | B15: 22 | C15: 18000 | D15: =B15*C15 -> 396000
A16: BÍ ĐỎ MINI | D16: =B16*C16 -> 0
A17: BÍ ĐỎ NON (KG)KQ | D17: =B17*C17 -> 0
A18: BÍ ĐỎ NON TRÁI VR | D18: =B18*C18 -> 0
A19: BÍ ĐỎ NON( KG) VR | B19: 14 | C19: 14000 | D19: =B19*C19 -> 196000
A20: BÍ ĐỎ TRÒN | B20: =-1000+2700 -> 1700 | C20: 14000 | D20: =B20*C20 -> 23800000
A21: BÍ MINI VÀNG 300GR | D21: =B21*C21 -> 0
A22: BÍ MINI VÀNG KG | D22: =B22*C22 -> 0
A23: BÍ NGÒI VÀNG | D23: =B23*C23 -> 0
A24: BÍ NGÒI VÀNG (TRÁI) | D24: =B24*C24 -> 0
A25: BÍ NGÒI XANH | B25: =-30+44 -> 14 | C25: 11000 | D25: =B25*C25 -> 154000
A26: BÍ NGÒI XANH(TRÁI) | D26: =B26*C26 -> 0
A27: BÍ NHẬT | D27: =B27*C27 -> 0
A28: BƠ 034 | B28: 10 | C28: 17000 | D28: =B28*C28 -> 170000
A29: BƠ 034 COOP | D29: =B29*C29 -> 0
A30: BƠ BOOTH | D30: =B30*C30 -> 0
A31: BO HOA CHUONG | D31: =B31*C31 -> 0
A32: BO HOA CUC TANA | D32: =B32*C32 -> 0
A33: BO HOA DONG TIEN HN | D33: =B33*C33 -> 0
A34: BO HOA LOA KEN | D34: =B34*C34 -> 0
A35: BO HOA PHANG | D35: =B35*C35 -> 0
A36: BO HOA SEN QUAN AM | D36: =B36*C36 -> 0
A37: BO HOA SEN SUPER | D37: =B37*C37 -> 0
A38: BƠ SÁP | D38: =B38*C38 -> 0
A39: BÓ XÔI | D39: =B39*C39 -> 0
A40: BÓ XÔI 300G VR | D40: =B40*C40 -> 0
...

Sheet 22.7
A1: hàng tồn cuối ngày 22/7 vr
A2: TÊN SẢN PHẨM | B2: TỒN TRƯỚC | C2: GIÁ NHẬP | D2: THÀNH TIỀN
A3: BẮP CẢI TÍM | D3: =B3*C3 -> 0
A4: BẮP CẢI TÍM (BẮP) | D4: =B4*C4 -> 0
A5: BẮP CẢI TÍM SUSHI | D5: =B5*C5 -> 0
A6: BẮP CẢI TRẮNG | D6: =B6*C6 -> 0
A7: BẮP CẢI TRẮNG (BẮP) | D7: =B7*C7 -> 0
A8: BẮP CẢI TRẮNG MỘC CHÂU | D8: =B8*C8 -> 0
A9: BẮP CẢI TRẮNG SÓI BIỂN | D9: =B9*C9 -> 0
A10: BẮP CẢI TRẮNG SUSHI | D10: =B10*C10 -> 0
A11: BẮP MỸ CẶP | D11: =B11*C11 -> 0
A12: BẦU | D12: =B12*C12 -> 0
A13: BÍ ĐAO XANH | D13: =B13*C13 -> 0
A14: BÍ ĐAO XANH 400G | D14: =B14*C14 -> 0
A15: BÍ ĐỎ HỒ LÔ | B15: 3 | C15: 18000 | D15: =B15*C15 -> 54000
A16: BÍ ĐỎ MINI | D16: =B16*C16 -> 0
A17: BÍ ĐỎ NON (KG)KQ | D17: =B17*C17 -> 0
A18: BÍ ĐỎ NON TRÁI VR | D18: =B18*C18 -> 0
A19: BÍ ĐỎ NON( KG) VR | B19: 10 | C19: 14000 | D19: =B19*C19 -> 140000
A20: BÍ ĐỎ TRÒN | B20: =-1000+2360 -> 1360 | C20: 14000 | D20: =B20*C20 -> 19040000
A21: BÍ MINI VÀNG 300GR | D21: =B21*C21 -> 0
A22: BÍ MINI VÀNG KG | D22: =B22*C22 -> 0
A23: BÍ NGÒI VÀNG | D23: =B23*C23 -> 0
A24: BÍ NGÒI VÀNG (TRÁI) | D24: =B24*C24 -> 0
A25: BÍ NGÒI XANH | B25: =-30+12+18 -> 0 | C25: 11500 | D25: =B25*C25 -> 0
A26: BÍ NGÒI XANH(TRÁI) | D26: =B26*C26 -> 0
A27: BÍ NHẬT | D27: =B27*C27 -> 0
A28: BƠ 034 | D28: =B28*C28 -> 0
A29: BƠ 034 COOP | D29: =B29*C29 -> 0
A30: BƠ BOOTH | D30: =B30*C30 -> 0
A31: BO HOA CHUONG | D31: =B31*C31 -> 0
A32: BO HOA CUC TANA | D32: =B32*C32 -> 0
A33: BO HOA DONG TIEN HN | D33: =B33*C33 -> 0
A34: BO HOA LOA KEN | D34: =B34*C34 -> 0
A35: BO HOA PHANG | D35: =B35*C35 -> 0
A36: BO HOA SEN QUAN AM | D36: =B36*C36 -> 0
A37: BO HOA SEN SUPER | D37: =B37*C37 -> 0
A38: BƠ SÁP | B38: 18 | C38: 17000 | D38: =B38*C38 -> 306000
A39: BÓ XÔI | D39: =B39*C39 -> 0
A40: BÓ XÔI 300G VR | D40: =B40*C40 -> 0
...

Sheet 23.7
A1: hàng tồn cuối ngày 23/7 vr
A2: TÊN SẢN PHẨM | B2: TỒN TRƯỚC | C2: GIÁ NHẬP | D2: THÀNH TIỀN
A3: BẮP CẢI TÍM | D3: =B3*C3 -> 0
A4: BẮP CẢI TÍM (BẮP) | D4: =B4*C4 -> 0
A5: BẮP CẢI TÍM SUSHI | D5: =B5*C5 -> 0
A6: BẮP CẢI TRẮNG | D6: =B6*C6 -> 0
A7: BẮP CẢI TRẮNG (BẮP) | D7: =B7*C7 -> 0
A8: BẮP CẢI TRẮNG MỘC CHÂU | D8: =B8*C8 -> 0
A9: BẮP CẢI TRẮNG SÓI BIỂN | D9: =B9*C9 -> 0
A10: BẮP CẢI TRẮNG SUSHI | D10: =B10*C10 -> 0
A11: BẮP MỸ CẶP | D11: =B11*C11 -> 0
A12: BẦU | D12: =B12*C12 -> 0
A13: BÍ ĐAO XANH | D13: =B13*C13 -> 0
A14: BÍ ĐAO XANH 400G | D14: =B14*C14 -> 0
... A17: BÍ ĐỎ NON (KG)KQ | D17: =B17*C17 -> 0
A18: BÍ ĐỎ NON TRÁI VR | B18: 6 | C18: 4000 | D18: =B18*C18 -> 24000
A19: BÍ ĐỎ NON( KG) VR | D19: =B19*C19 -> 0
A20: BÍ ĐỎ TRÒN | B20: =-1000+2270+2280+105 -> 3655 | C20: 12500 | D20: =B20*C20 -> 45687500
A21: BÍ MINI VÀNG 300GR | D21: =B21*C21 -> 0
A22: BÍ MINI VÀNG KG | D22: =B22*C22 -> 0
A23: BÍ NGÒI VÀNG | D23: =B23*C23 -> 0
A24: BÍ NGÒI VÀNG (TRÁI) | D24: =B24*C24 -> 0
A25: BÍ NGÒI XANH | B25: =-30+80+95 -> 145 | C25: 11500 | D25: =B25*C25 -> 1667500
A26: BÍ NGÒI XANH(TRÁI) | D26: =B26*C26 -> 0
A27: BÍ NHẬT | D27: =B27*C27 -> 0
A28: BƠ 034 | B28: 35 | C28: 17000 | D28: =B28*C28 -> 595000
A29: BƠ 034 COOP | D29: =B29*C29 -> 0
A30: BƠ BOOTH | D30: =B30*C30 -> 0
A31: BO HOA CHUONG | D31: =B31*C31 -> 0
A32: BO HOA CUC TANA | D32: =B32*C32 -> 0
A33: BO HOA DONG TIEN HN | D33: =B33*C33 -> 0
A34: BO HOA LOA KEN | D34: =B34*C34 -> 0
A35: BO HOA PHANG | D35: =B35*C35 -> 0
A36: BO HOA SEN QUAN AM | D36: =B36*C36 -> 0
A37: BO HOA SEN SUPER | D37: =B37*C37 -> 0
A38: BƠ SÁP | D38: =B38*C38 -> 0
A39: BÓ XÔI | D39: =B39*C39 -> 0
A40: BÓ XÔI 300G VR | D40: =B40*C40 -> 0
... A53: BÔNG CẢI XANH CITI | D53: =B53*C53 -> 0
A54: CÀ CHUA | B54: =-300+140+20+400-80 -> 180 | C54: 23000 | D54: =B54*C54 -> 4140000
...

Sheet 24.7
A1: hàng tồn cuối ngày 24/7 vr
A2: TÊN SẢN PHẨM | B2: TỒN TRƯỚC | C2: GIÁ NHẬP | D2: THÀNH TIỀN
A3: BẮP CẢI TÍM | D3: =B3*C3 -> 0
A4: BẮP CẢI TÍM (BẮP) | D4: =B4*C4 -> 0
A5: BẮP CẢI TÍM SUSHI | D5: =B5*C5 -> 0
A6: BẮP CẢI TRẮNG | D6: =B6*C6 -> 0
A7: BẮP CẢI TRẮNG (BẮP) | D7: =B7*C7 -> 0
A8: BẮP CẢI TRẮNG MỘC CHÂU | D8: =B8*C8 -> 0
A9: BẮP CẢI TRẮNG SÓI BIỂN | D9: =B9*C9 -> 0
A10: BẮP CẢI TRẮNG SUSHI | D10: =B10*C10 -> 0
A11: BẮP MỸ CẶP | D11: =B11*C11 -> 0
A12: BẦU | D12: =B12*C12 -> 0
A13: BÍ ĐAO XANH | D13: =B13*C13 -> 0
A14: BÍ ĐAO XANH 400G | D14: =B14*C14 -> 0
A15: BÍ ĐỎ HỒ LÔ | B15: 9 | C15: 18000 | D15: =B15*C15 -> 162000
A16: BÍ ĐỎ MINI | D16: =B16*C16 -> 0
A17: BÍ ĐỎ NON (KG)KQ | D17: =B17*C17 -> 0
A18: BÍ ĐỎ NON TRÁI VR | B18: 10 | C18: 4000 | D18: =B18*C18 -> 40000
A19: BÍ ĐỎ NON( KG) VR | D19: =B19*C19 -> 0
A20: BÍ ĐỎ TRÒN | B20: 1500 | C20: 11500 | D20: =B20*C20 -> 17250000
A21: BÍ MINI VÀNG 300GR | D21: =B21*C21 -> 0
A22: BÍ MINI VÀNG KG | D22: =B22*C22 -> 0
A23: BÍ NGÒI VÀNG | D23: =B23*C23 -> 0
A24: BÍ NGÒI VÀNG (TRÁI) | D24: =B24*C24 -> 0
A25: BÍ NGÒI XANH | B25: =-30+2+150 -> 122 | C25: 11500 | D25: =B25*C25 -> 1403000
A26: BÍ NGÒI XANH(TRÁI) | D26: =B26*C26 -> 0
A27: BÍ NHẬT | D27: =B27*C27 -> 0
A28: BƠ 034 | D28: =B28*C28 -> 0
A29: BƠ 034 COOP | D29: =B29*C29 -> 0
A30: BƠ BOOTH | D30: =B30*C30 -> 0
A31: BO HOA CHUONG | D31: =B31*C31 -> 0
A32: BO HOA CUC TANA | D32: =B32*C32 -> 0
A33: BO HOA DONG TIEN HN | D33: =B33*C33 -> 0
A34: BO HOA LOA KEN | D34: =B34*C34 -> 0
A35: BO HOA PHANG | D35: =B35*C35 -> 0
A36: BO HOA SEN QUAN AM | D36: =B36*C36 -> 0
A37: BO HOA SEN SUPER | D37: =B37*C37 -> 0
... A44: BÔNG BÍ TÚI 300GR | D44: =B44*C44 -> 0
A45: BÔNG CẢI TRẮNG | B45: 7 | C45: 17000 | D45: =B45*C45 -> 119000
A46: BÔNG CẢI TRẮNG (CÂY) | D46: =B46*C46 -> 0
...

Sheet 25.7
A1: hàng tồn cuối ngày 25/7 vr
A2: TÊN SẢN PHẨM | B2: TỒN TRƯỚC | C2: GIÁ NHẬP | D2: THÀNH TIỀN
A3: BẮP CẢI TÍM | D3: =B3*C3 -> 0
A4: BẮP CẢI TÍM (BẮP) | D4: =B4*C4 -> 0
A5: BẮP CẢI TÍM SUSHI | D5: =B5*C5 -> 0
A6: BẮP CẢI TRẮNG | D6: =B6*C6 -> 0
A7: BẮP CẢI TRẮNG (BẮP) | D7: =B7*C7 -> 0
A8: BẮP CẢI TRẮNG MỘC CHÂU | D8: =B8*C8 -> 0
A9: BẮP CẢI TRẮNG SÓI BIỂN | D9: =B9*C9 -> 0
A10: BẮP CẢI TRẮNG SUSHI | D10: =B10*C10 -> 0
A11: BẮP MỸ CẶP | D11: =B11*C11 -> 0
A12: BẦU | D12: =B12*C12 -> 0
A13: BÍ ĐAO XANH | D13: =B13*C13 -> 0
A14: BÍ ĐAO XANH 400G | D14: =B14*C14 -> 0
... A17: BÍ ĐỎ NON (KG)KQ | D17: =B17*C17 -> 0
A18: BÍ ĐỎ NON TRÁI VR | B18: 34 | C18: 4000 | D18: =B18*C18 -> 136000
A19: BÍ ĐỎ NON( KG) VR | D19: =B19*C19 -> 0
A20: BÍ ĐỎ TRÒN | B20: 1500 | C20: 11500 | D20: =B20*C20 -> 17250000
A21: BÍ MINI VÀNG 300GR | D21: =B21*C21 -> 0
A22: BÍ MINI VÀNG KG | D22: =B22*C22 -> 0
A23: BÍ NGÒI VÀNG | D23: =B23*C23 -> 0
A24: BÍ NGÒI VÀNG (TRÁI) | D24: =B24*C24 -> 0
A25: BÍ NGÒI XANH | D25: =B25*C25 -> 0
A26: BÍ NGÒI XANH(TRÁI) | D26: =B26*C26 -> 0
A27: BÍ NHẬT | D27: =B27*C27 -> 0
A28: BƠ 034 | D28: =B28*C28 -> 0
A29: BƠ 034 COOP | D29: =B29*C29 -> 0
A30: BƠ BOOTH | D30: =B30*C30 -> 0
A31: BO HOA CHUONG | D31: =B31*C31 -> 0
A32: BO HOA CUC TANA | D32: =B32*C32 -> 0
... A53: BÔNG CẢI XANH CITI | D53: =B53*C53 -> 0
A54: CÀ CHUA | B54: =-300+165+320+120+20+20 -> 345 | C54: 23000 | D54: =B54*C54 -> 7935000
A55: CÀ CHUA BI | D55: =B55*C55 -> 0
A56: CÀ CHUA BI (HỘP) 300GR KQ | D56: =B56*C56 -> 0
A57: CÀ CHUA BI (HỘP) 300GR VR | B57: 6 | C57: 6900 | D57: =B57*C57 -> 41400
A58: CÀ CHUA BI 300GR KQ (KG) | D58: =B58*C58 -> 0
A59: CÀ CHUA BI 300GR VR (KG) | D59: =B59*C59 -> 0
A60: CÀ CHUA BI CAM SỮA (KG) VR | D60: =B60*C60 -> 0
A61: CÀ CHUA BI COOP | B61: 8.5 | C61: 11500 | D61: =B61*C61 -> 97750
A62: CÀ CHUA BI-NA | D62: =B62*C62 -> 0
...

Sheet 26.7
A1: hàng tồn cuối ngày 26/7 vr
A2: TÊN SẢN PHẨM | B2: TỒN TRƯỚC | C2: GIÁ NHẬP | D2: THÀNH TIỀN
A3: CÀ CHUA SÔCOLA 250GR (HỘP) VR | D3: =B3*C3 -> 0
A4: CÀ CHUA SÔCOLA 250GR (KG) -NA | D4: =B4*C4 -> 0
A5: CÀ CHUA SÔCOLA 250GR (KG) VR | D5: =B5*C5 -> 0
A6: CÀ CHUA SÔCOLA 250GR(KG) KQ | D6: =B6*C6 -> 0
A7: CÀ CHUA SÔCOLA 300GR (HỘP) VR | D7: =B7*C7 -> 0
A8: CÀ CHUA SOCOLA XÁ | D8: =B8*C8 -> 0
A9: CÀ CHUA SÔCOLA(HỘP) KQ | D9: =B9*C9 -> 0
A10: CÀ RỐT BABY | D10: =B10*C10 -> 0
A11: CÀ RỐT BABY (KG) KQ | D11: =B11*C11 -> 0
A12: CÀ RỐT BABY 200GR | D12: =B12*C12 -> 0
A13: CẢI CẦU VỒNG | D13: =B13*C13 -> 0
A14: CẢI CẦU VỒNG 300GR | D14: =B14*C14 -> 0
... A23: ỚT CHUÔNG 3 MÀU(KG)VR | D23: =B23*C23 -> 0
A24: ỚT CHUÔNG ĐỎ | B24: =-20+20+35+60 -> 95 | C24: 23000 | D24: =B24*C24 -> 2185000
A25: ỚT CHUÔNG ĐỎ L1 | B25: 1 | C25: 16000 | D25: =B25*C25 -> 16000
A26: ỚT CHUÔNG ĐỎ(TRÁI) | D26: =B26*C26 -> 0
A27: ỚT CHUÔNG 3 MÀU 350G | D27: =B27*C27 -> 0
A28: ỚT CHUÔNG 3 MÀU KQ(KG) | D28: =B28*C28 -> 0
A29: ỚT CHUÔNG VÀNG | B29: =-20+78 -> 58 | C29: 21000 | D29: =B29*C29 -> 1218000
A30: ỚT CHUÔNG VÀNG L1 | B30: 22 | C30: 15000 | D30: =B30*C30 -> 330000
A31: ỚT CHUÔNG VÀNG(TRÁI) | D31: =B31*C31 -> 0
A32: ỚT CHUÔNG VÀNG+ XANH (VỈ) | D32: =B32*C32 -> 0
A33: ỚT CHUÔNG XANH | D33: =B33*C33 -> 0
A34: ỚT CHUÔNG XANH L1 | D34: =B34*C34 -> 0
A35: ỚT CHUÔNG XANH(TRÁI) | D35: =B35*C35 -> 0
A36: CỦ DỀN | D36: =B36*C36 -> 0
A37: CỦ DỀN 600G | D37: =B37*C37 -> 0
A38: GỪNG 250GR | D38: =B38*C38 -> 0
A39: HỒNG GIÒN | D39: =B39*C39 -> 0
A40: XÀ LÁCH MỸ | D40: =B40*C40 -> 0
A41: KHOAI TÂY HỒNG | D41: =B41*C41 -> 0
A42: KHOAI TÂY HỒNG TÚI LƯỚI 500G | D42: =B42*C42 -> 0
A43: KHOAI TÂY VÀNG | D43: =B43*C43 -> 0
A44: KHOAI TÂY VÀNG ĐL | B44: =-300+10+140+140+140 -> 130 | C44: 15000 | D44: =B44*C44 -> 1950000
A45: KHOAI TÂY VÀNG LỚN TÚI LƯỚI 500G | D45: =B45*C45 -> 0
A46: KHOAI TÂY VÀNG TRUNG TÚI LƯỚI 500G | B46: 80 | C46: 13000 | D46: =B46*C46 -> 1040000
A47: CẢI THẢO DL | D47: =B47*C47 -> 0
A48: CẢI THẢO DL(BẮP) | D48: =B48*C48 -> 0
...

Sheet 27.7
A1: hàng tồn cuối ngày 27/7 vr
A2: TÊN SẢN PHẨM | B2: TỒN TRƯỚC | C2: GIÁ NHẬP | D2: THÀNH TIỀN
A3: BẮP CẢI TÍM | D3: =B3*C3 -> 0
A4: BẮP CẢI TÍM (BẮP) | D4: =B4*C4 -> 0
A5: BẮP CẢI TÍM SUSHI | D5: =B5*C5 -> 0
A6: BẮP CẢI TRẮNG | D6: =B6*C6 -> 0
A7: BẮP CẢI TRẮNG (BẮP) | D7: =B7*C7 -> 0
A8: BẮP CẢI TRẮNG MỘC CHÂU | D8: =B8*C8 -> 0
A9: BẮP CẢI TRẮNG SÓI BIỂN | D9: =B9*C9 -> 0
A10: BẮP CẢI TRẮNG SUSHI | D10: =B10*C10 -> 0
A11: BẮP MỸ CẶP | D11: =B11*C11 -> 0
A12: BẦU | D12: =B12*C12 -> 0
A13: BÍ ĐAO XANH | D13: =B13*C13 -> 0
A14: BÍ ĐAO XANH 400G | D14: =B14*C14 -> 0
... A17: BÍ ĐỎ NON (KG)KQ | D17: =B17*C17 -> 0
A18: BÍ ĐỎ NON TRÁI VR | B18: 8 | C18: 4000 | D18: =B18*C18 -> 32000
A19: BÍ ĐỎ NON( KG) VR | B19: 14 | C19: 13000 | D19: =B19*C19 -> 182000
A20: BÍ ĐỎ TRÒN | B20: 1500 | C20: 11500 | D20: =B20*C20 -> 17250000
A21: BÍ MINI VÀNG 300GR | D21: =B21*C21 -> 0
A22: BÍ MINI VÀNG KG | D22: =B22*C22 -> 0
A23: BÍ NGÒI VÀNG | D23: =B23*C23 -> 0
A24: BÍ NGÒI VÀNG (TRÁI) | D24: =B24*C24 -> 0
A25: BÍ NGÒI XANH | B25: =-30+45 -> 15 | C25: 12500 | D25: =B25*C25 -> 187500
A26: BÍ NGÒI XANH(TRÁI) | D26: =B26*C26 -> 0
A27: BÍ NHẬT | D27: =B27*C27 -> 0
A28: BƠ 034 | B28: 41 | C28: 17000 | D28: =B28*C28 -> 697000
A29: BƠ 034 COOP | D29: =B29*C29 -> 0
A30: BƠ BOOTH | D30: =B30*C30 -> 0
A31: BO HOA CHUONG | D31: =B31*C31 -> 0
A32: BO HOA CUC TANA | D32: =B32*C32 -> 0
A33: BO HOA DONG TIEN HN | D33: =B33*C33 -> 0
A34: BO HOA LOA KEN | D34: =B34*C34 -> 0
A35: BO HOA PHANG | D35: =B35*C35 -> 0
A36: BO HOA SEN QUAN AM | D36: =B36*C36 -> 0
A37: BO HOA SEN SUPER | D37: =B37*C37 -> 0
A38: BƠ SÁP | B38: 50 | C38: 11000 | D38: =B38*C38 -> 550000
A39: BÓ XÔI | D39: =B39*C39 -> 0
A40: BÓ XÔI 300G VR | D40: =B40*C40 -> 0
A41: BÓ XÔI-NA | D41: =B41*C41 -> 0
A42: BÔNG ATISO | D42: =B42*C42 -> 0
...

Sheet 28.7
A1: hàng tồn cuối ngày 28/7 vr
A2: TÊN SẢN PHẨM | B2: TỒN TRƯỚC | C2: GIÁ NHẬP | D2: THÀNH TIỀN
A3: CÀ CHUA SÔCOLA 250GR (HỘP) VR | B3: 12 | C3: 10000 | D3: =B3*C3 -> 120000
A4: CÀ CHUA SÔCOLA 250GR (KG) -NA | D4: =B4*C4 -> 0
A5: CÀ CHUA SÔCOLA 250GR (KG) VR | D5: =B5*C5 -> 0
A6: CÀ CHUA SÔCOLA 250GR(KG) KQ | D6: =B6*C6 -> 0
A7: CÀ CHUA SÔCOLA 300GR (HỘP) VR | D7: =B7*C7 -> 0
A8: CÀ CHUA SOCOLA XÁ | D8: =B8*C8 -> 0
A9: CÀ CHUA SÔCOLA(HỘP) KQ | D9: =B9*C9 -> 0
A10: CÀ RỐT BABY | D10: =B10*C10 -> 0
A11: CÀ RỐT BABY (KG) KQ | D11: =B11*C11 -> 0
A12: CÀ RỐT BABY 200GR | D12: =B12*C12 -> 0
A13: CẢI CẦU VỒNG | D13: =B13*C13 -> 0
A14: CẢI CẦU VỒNG 300GR | D14: =B14*C14 -> 0
A15: CẢI KALE | D15: =B15*C15 -> 0
... A19: CHANH VÀNG TRÁI 180UP | D19: =B19*C19 -> 0
A20: CẦN TÂY (KG) | B20: 3 | C20: 17000 | D20: =B20*C20 -> 51000
A21: CẦN TÂY THUỶ CANH | D21: =B21*C21 -> 0
A22: CẦN TÂY(CÂY) | D22: =B22*C22 -> 0
A23: ỚT CHUÔNG 3 MÀU(KG)VR | D23: =B23*C23 -> 0
A24: ỚT CHUÔNG ĐỎ | B24: =-20+25+38 -> 43 | C24: 21000 | D24: =B24*C24 -> 903000
A25: ỚT CHUÔNG ĐỎ L1 | D25: =B25*C25 -> 0
A26: ỚT CHUÔNG ĐỎ(TRÁI) | D26: =B26*C26 -> 0
A27: ỚT CHUÔNG 3 MÀU 350G | B27: 8 | C27: 8000 | D27: =B27*C27 -> 64000
A28: ỚT CHUÔNG 3 MÀU KQ(KG) | D28: =B28*C28 -> 0
A29: ỚT CHUÔNG VÀNG | B29: =-20+11+12+3+20 -> 26 | C29: 21000 | D29: =B29*C29 -> 546000
A30: ỚT CHUÔNG VÀNG L1 | B30: 15 | C30: 15000 | D30: =B30*C30 -> 225000
A31: ỚT CHUÔNG VÀNG(TRÁI) | D31: =B31*C31 -> 0
A32: ỚT CHUÔNG VÀNG+ XANH (VỈ) | D32: =B32*C32 -> 0
A33: ỚT CHUÔNG XANH | B33: =-20+25 -> 5 | C33: 28000 | D33: =B33*C33 -> 140000
A34: ỚT CHUÔNG XANH L1 | D34: =B34*C34 -> 0
A35: ỚT CHUÔNG XANH(TRÁI) | D35: =B35*C35 -> 0
A36: CỦ DỀN | D36: =B36*C36 -> 0
A37: CỦ DỀN 600G | D37: =B37*C37 -> 0
A38: GỪNG 250GR | D38: =B38*C38 -> 0
A39: HỒNG GIÒN | D39: =B39*C39 -> 0
A40: XÀ LÁCH MỸ | D40: =B40*C40 -> 0
A41: KHOAI TÂY HỒNG TÚI LƯỚI 500G | D41: =B41*C41 -> 0
A42: KHOAI TÂY VÀNG | D42: =B42*C42 -> 0
A43: KHOAI TÂY VÀNG TRUNG TÚI LƯỚI 500G | B43: 20 | C43: 13000 | D43: =B43*C43 -> 260000
...

Sheet 29.7
A1: hàng tồn cuối ngày 29/7 vr
A2: TÊN SẢN PHẨM | B2: TỒN TRƯỚC | C2: GIÁ NHẬP | D2: THÀNH TIỀN
A3: BẮP CẢI TÍM | D3: =B3*C3 -> 0
A4: BẮP CẢI TÍM (BẮP) | D4: =B4*C4 -> 0
A5: BẮP CẢI TÍM SUSHI | D5: =B5*C5 -> 0
A6: BẮP CẢI TRẮNG | D6: =B6*C6 -> 0
A7: BẮP CẢI TRẮNG (BẮP) | D7: =B7*C7 -> 0
A8: BẮP CẢI TRẮNG MỘC CHÂU | D8: =B8*C8 -> 0
A9: BẮP CẢI TRẮNG SÓI BIỂN | D9: =B9*C9 -> 0
A10: BẮP CẢI TRẮNG SUSHI | D10: =B10*C10 -> 0
A11: BẮP MỸ CẶP | D11: =B11*C11 -> 0
A12: BẦU | D12: =B12*C12 -> 0
A13: BÍ ĐAO XANH | D13: =B13*C13 -> 0
A14: BÍ ĐAO XANH 400G | D14: =B14*C14 -> 0
... A18: BÍ ĐỎ NON TRÁI VR | D18: =B18*C18 -> 0
A19: BÍ ĐỎ NON( KG) VR | B19: 5 | C19: 13000 | D19: =B19*C19 -> 65000
A20: BÍ ĐỎ TRÒN | B20: 1500 | C20: 11500 | D20: =B20*C20 -> 17250000
A21: BÍ MINI VÀNG 300GR | D21: =B21*C21 -> 0
A22: BÍ MINI VÀNG KG | D22: =B22*C22 -> 0
A23: BÍ NGÒI VÀNG | D23: =B23*C23 -> 0
A24: BÍ NGÒI VÀNG (TRÁI) | D24: =B24*C24 -> 0
A25: BÍ NGÒI XANH | D25: =B25*C25 -> 0
A26: BÍ NGÒI XANH(TRÁI) | D26: =B26*C26 -> 0
A27: BÍ NHẬT | D27: =B27*C27 -> 0
A28: BƠ 034 | D28: =B28*C28 -> 0
A29: BƠ 034 COOP | D29: =B29*C29 -> 0
A30: BƠ BOOTH | D30: =B30*C30 -> 0
A31: BO HOA CHUONG | D31: =B31*C31 -> 0
A32: BO HOA CUC TANA | D32: =B32*C32 -> 0
... A37: BO HOA SEN SUPER | D37: =B37*C37 -> 0
A38: BƠ SÁP | B38: =50-30 -> 20 | C38: 12000 | D38: =B38*C38 -> 240000
A39: BÓ XÔI | D39: =B39*C39 -> 0
A40: BÓ XÔI 300G VR | D40: =B40*C40 -> 0
A41: BÓ XÔI-NA | D41: =B41*C41 -> 0
A42: BÔNG ATISO | D42: =B42*C42 -> 0
A43: BÔNG BÍ | D43: =B43*C43 -> 0
A44: BÔNG BÍ TÚI 300GR | D44: =B44*C44 -> 0
A45: BÔNG CẢI TRẮNG | D45: =B45*C45 -> 0
A46: BÔNG CẢI TRẮNG (CÂY) | D46: =B46*C46 -> 0
A47: BÔNG CẢI XANH 10P | D47: =B47*C47 -> 0
...

Sheet 30.7
A1: hàng tồn cuối ngày 30/7 vr
A2: TÊN SẢN PHẨM | B2: TỒN TRƯỚC | C2: GIÁ NHẬP | D2: THÀNH TIỀN
A3: BẮP CẢI TÍM | D3: =B3*C3 -> 0
A4: BẮP CẢI TÍM (BẮP) | D4: =B4*C4 -> 0
A5: BẮP CẢI TÍM SUSHI | D5: =B5*C5 -> 0
A6: BẮP CẢI TRẮNG | D6: =B6*C6 -> 0
A7: BẮP CẢI TRẮNG (BẮP) | D7: =B7*C7 -> 0
A8: BẮP CẢI TRẮNG MỘC CHÂU | D8: =B8*C8 -> 0
A9: BẮP CẢI TRẮNG SÓI BIỂN | D9: =B9*C9 -> 0
A10: BẮP CẢI TRẮNG SUSHI | D10: =B10*C10 -> 0
A11: BẮP MỸ CẶP | D11: =B11*C11 -> 0
A12: BẦU | D12: =B12*C12 -> 0
A13: BÍ ĐAO XANH | D13: =B13*C13 -> 0
A14: BÍ ĐAO XANH 400G | D14: =B14*C14 -> 0
... A17: BÍ ĐỎ NON (KG)KQ | D17: =B17*C17 -> 0
A18: BÍ ĐỎ NON TRÁI VR | B18: 72 | C18: 13000 | D18: =B18*C18 -> 936000
A19: BÍ ĐỎ NON( KG) VR | D19: =B19*C19 -> 0
A20: BÍ ĐỎ TRÒN | B20: 1500 | C20: 12000 | D20: =B20*C20 -> 18000000
A21: BÍ MINI VÀNG 300GR | D21: =B21*C21 -> 0
A22: BÍ MINI VÀNG KG | D22: =B22*C22 -> 0
A23: BÍ NGÒI VÀNG | D23: =B23*C23 -> 0
A24: BÍ NGÒI VÀNG (TRÁI) | D24: =B24*C24 -> 0
A25: BÍ NGÒI XANH | D25: =B25*C25 -> 0
A26: BÍ NGÒI XANH(TRÁI) | D26: =B26*C26 -> 0
A27: BÍ NHẬT | D27: =B27*C27 -> 0
A28: BƠ 034 | D28: =B28*C28 -> 0
A29: BƠ 034 COOP | D29: =B29*C29 -> 0
A30: BƠ BOOTH | D30: =B30*C30 -> 0
A31: BO HOA CHUONG | D31: =B31*C31 -> 0
A32: BO HOA CUC TANA | D32: =B32*C32 -> 0
... A53: BÔNG CẢI XANH CITI | D53: =B53*C53 -> 0
A54: CÀ CHUA | B54: =-300+380+100 -> 180 | C54: 22000 | D54: =B54*C54 -> 3960000
A55: CÀ CHUA BI | B55: 5 | C55: 12500 | D55: =B55*C55 -> 62500
A56: CÀ CHUA BI (HỘP) 300GR KQ | D56: =B56*C56 -> 0
A57: CÀ CHUA BI (HỘP) 300GR VR | B57: 25 | C57: 7500 | D57: =B57*C57 -> 187500
A58: CÀ CHUA BI 300GR KQ (KG) | D58: =B58*C58 -> 0
A59: CÀ CHUA BI 300GR VR (KG) | D59: =B59*C59 -> 0
A60: CÀ CHUA BI CAM SỮA (KG) VR | D60: =B60*C60 -> 0
A61: CÀ CHUA BI COOP | B61: 11 | C61: 12500 | D61: =B61*C61 -> 137500
A62: CÀ CHUA BI-NA | D62: =B62*C62 -> 0
...

Sheet 31.7
A1: hàng tồn cuối ngày 31/7 vr
A2: TÊN SẢN PHẨM | B2: TỒN TRƯỚC | C2: GIÁ NHẬP | D2: THÀNH TIỀN
A3: BẮP CẢI TÍM | D3: =B3*C3 -> 0
A4: BẮP CẢI TÍM (BẮP) | D4: =B4*C4 -> 0
A5: BẮP CẢI TÍM SUSHI | D5: =B5*C5 -> 0
A6: BẮP CẢI TRẮNG | D6: =B6*C6 -> 0
A7: BẮP CẢI TRẮNG (BẮP) | D7: =B7*C7 -> 0
A8: BẮP CẢI TRẮNG MỘC CHÂU | D8: =B8*C8 -> 0
A9: BẮP CẢI TRẮNG SÓI BIỂN | D9: =B9*C9 -> 0
A10: BẮP CẢI TRẮNG SUSHI | D10: =B10*C10 -> 0
A11: BẮP MỸ CẶP | D11: =B11*C11 -> 0
A12: BẦU | D12: =B12*C12 -> 0
A13: BÍ ĐAO XANH | D13: =B13*C13 -> 0
A14: BÍ ĐAO XANH 400G | D14: =B14*C14 -> 0
A15: BÍ ĐỎ HỒ LÔ | B15: 10 | C15: 13500 | D15: =B15*C15 -> 135000
A16: BÍ ĐỎ MINI | D16: =B16*C16 -> 0
A17: BÍ ĐỎ NON (KG)KQ | D17: =B17*C17 -> 0
A18: BÍ ĐỎ NON TRÁI VR | D18: =B18*C18 -> 0
A19: BÍ ĐỎ NON( KG) VR | B19: 13 | C19: 12000 | D19: =B19*C19 -> 156000
A20: BÍ ĐỎ TRÒN | B20: 1500 | C20: 12000 | D20: =B20*C20 -> 18000000
A21: BÍ MINI VÀNG 300GR | D21: =B21*C21 -> 0
A22: BÍ MINI VÀNG KG | D22: =B22*C22 -> 0
A23: BÍ NGÒI VÀNG | D23: =B23*C23 -> 0
A24: BÍ NGÒI VÀNG (TRÁI) | D24: =B24*C24 -> 0
A25: BÍ NGÒI XANH | D25: =B25*C25 -> 0
A26: BÍ NGÒI XANH(TRÁI) | D26: =B26*C26 -> 0
A27: BÍ NHẬT | D27: =B27*C27 -> 0
A28: BƠ 034 | D28: =B28*C28 -> 0
A29: BƠ 034 COOP | D29: =B29*C29 -> 0
A30: BƠ BOOTH | D30: =B30*C30 -> 0
A31: BO HOA CHUONG | D31: =B31*C31 -> 0
A32: BO HOA CUC TANA | D32: =B32*C32 -> 0
... A38: BƠ SÁP | D38: =B38*C38 -> 0
A39: BÓ XÔI | B39: 4 | C39: 28000 | D39: =B39*C39 -> 112000
A40: BÓ XÔI 300G VR | D40: =B40*C40 -> 0
A41: BÓ XÔI-NA | D41: =B41*C41 -> 0
A42: BÔNG ATISO | D42: =B42*C42 -> 0
A43: BÔNG BÍ | D43: =B43*C43 -> 0
A44: BÔNG BÍ TÚI 300GR | D44: =B44*C44 -> 0
A45: BÔNG CẢI TRẮNG | D45: =B45*C45 -> 0
...
