Workbook

Sheet 1.11
A2: hàng tồn cuối ngày 1/11 vr
A3: Tên Sản phẩm | B3: ĐVT | C3: Tồn ĐL | D3: giá | E3: thành tiền
A4: Cà Rốt | B4: Kg | C4: 60 | D4: 19000 | E4: =C4*D4 -> 1140000
A5: Cà Rốt | B5: Túi | C5: 0 | E5: =C5*D5 -> 0
A6: Cà Rốt Baby | B6: Kg | C6: 0 | E6: =C6*D6 -> 0
A7: Cà Rốt Baby | B7: Vỉ | C7: 0 | E7: =C7*D7 -> 0
A8: Củ Cải Đỏ | B8: Kg | C8: 0 | E8: =C8*D8 -> 0
A9: Củ Cải Đỏ 300Gr | B9: Hộp | C9: 0 | E9: =C9*D9 -> 0
A10: Củ Cải Trắng | B10: Kg | C10: 7 | D10: 6500 | E10: =C10*D10 -> 45500
A11: Củ Dền | B11: Kg | C11: 0 | E11: =C11*D11 -> 0
A12: Củ Dền | B12: Túi | C12: 0 | E12: =C12*D12 -> 0
A13: Củ Gừng | B13: Kg | C13: 0 | E13: =C13*D13 -> 0
A14: Củ Hành Tây | B14: Kg | C14: 178 | D14: 30000 | E14: =C14*D14 -> 5340000
A15: Củ Hành Tây Tím | B15: Kg | C15: 9 | D15: 20000 | E15: =C15*D15 -> 180000
A16: Củ Hành Tây Tím | B16: Túi | C16: 0 | E16: =C16*D16 -> 0
A17: Củ Hành Tây Trung | B17: Kg | C17: 0 | E17: =C17*D17 -> 0
A18: Củ Hành Tây Trung | B18: Túi | C18: 567 | D18: 7200 | E18: =C18*D18 -> 4082400
A19: Củ Khoai Lang Mật Size 46 | B19: Kg | C19: 0 | D19: 23000 | E19: =C19*D19 -> 0 | F19: 0
A20: Củ Khoai Lang Mật Size 46 | B20: Túi | C20: 0 | E20: =C20*D20 -> 0
A21: Củ Khoai Lang Nhật | B21: Kg | C21: 230 | D21: 22000 | E21: =C21*D21 -> 5060000
A22: Củ Khoai Lang Nhật | B22: Túi | C22: 0 | E22: =C22*D22 -> 0
A23: Củ Khoai Mỡ | B23: Kg | C23: 0 | E23: =C23*D23 -> 0
A24: Củ Khoai Tây Bi Vàng | B24: Kg | C24: 10 | D24: 12000 | E24: =C24*D24 -> 120000
A25: Củ Khoai Tây Bi Vàng | B25: Túi | C25: 0 | E25: =C25*D25 -> 0
A26: Củ Khoai Tây Vàng | B26: Kg | C26: 310 | D26: 15000 | E26: =C26*D26 -> 4650000
A27: Củ Khoai Tây Vàng | B27: Túi | C27: 44 | D27: 6000 | E27: =C27*D27 -> 264000
A28: Củ Su Hào | B28: Kg | C28: 0 | E28: =C28*D28 -> 0
A29: Bông Cải Xanh 7Cm | B29: Kg | C29: 0 | E29: =C29*D29 -> 0
A30: Bông Cải Xanh Baby | B30: Kg | C30: 0 | E30: =C30*D30 -> 0
A31: Bông Cải Xanh Baby | B31: Vỉ | C31: 0 | E31: =C31*D31 -> 0
A32: Hoa Atiso Đỏ | B32: Vỉ | C32: 0 | E32: =C32*D32 -> 0
A33: Bắp Cải Tím | B33: Kg | C33: 0 | E33: =C33*D33 -> 0
A34: Bắp Cải Trái Tim | B34: Kg | C34: 0 | E34: =C34*D34 -> 0
A35: Bắp Cải Trắng | B35: Kg | C35: 1340 | D35: 13748.5 | E35: =C35*D35 -> 18422990
A36: Cải Bó Xôi | B36: Kg | C36: 0 | E36: =C36*D36 -> 0
A37: Cải Bó Xôi | B37: Túi | C37: 0 | E37: =C37*D37 -> 0
A38: Cải Cầu Vồng | B38: Kg | C38: 0 | E38: =C38*D38 -> 0
A39: Cải Cầu Vồng | B39: Túi | C39: 0 | E39: =C39*D39 -> 0
A40: Cải Kale | B40: Kg | C40: 0 | E40: =C40*D40 -> 0
A41: Cải Kale | B41: Túi | C41: 0 | E41: =C41*D41 -> 0
...

Sheet 2.11
A2: hàng tồn cuối ngày 2/11 vr
A3: Tên Sản phẩm | B3: ĐVT | C3: Tồn ĐL | D3: giá | E3: thành tiền
A4: Cà Rốt | B4: Kg | C4: 0 | E4: =C4*D4 -> 0
A5: Cà Rốt | B5: Túi | C5: 0 | E5: =C5*D5 -> 0
A6: Cà Rốt Baby | B6: Vỉ | C6: 0 | E6: =C6*D6 -> 0
A7: Củ Cải Đỏ 300Gr | B7: Hộp | C7: 0 | E7: =C7*D7 -> 0
A8: Củ Cải Trắng | B8: Kg | C8: 0 | E8: =C8*D8 -> 0
A9: Củ Dền | B9: Kg | C9: 0 | E9: =C9*D9 -> 0
A10: Củ Dền | B10: Túi | C10: 0 | E10: =C10*D10 -> 0
A11: Củ Gừng | B11: Kg | C11: 0 | E11: =C11*D11 -> 0
A12: Củ Hành Tây | B12: Kg | C12: 2125 | D12: 28000 | E12: =C12*D12 -> 59500000
A13: Củ Hành Tây Tím | B13: Kg | C13: 9 | D13: 20000 | E13: =C13*D13 -> 180000
A14: Củ Hành Tây Trung | B14: Túi | C14: 426 | D14: 5400 | E14: =C14*D14 -> 2300400
A15: Củ Khoai Lang Mật Size 46 | B15: Kg | C15: 285 | D15: 22000 | E15: =C15*D15 -> 6270000 | F15: 200
A16: Củ Khoai Lang Nhật | B16: Kg | C16: 160 | D16: 20000 | E16: =C16*D16 -> 3200000
A17: Củ Khoai Mỡ | B17: Kg | C17: 0 | E17: =C17*D17 -> 0
A18: Củ Khoai Tây Bi Vàng | B18: Túi | C18: 0 | E18: =C18*D18 -> 0
A19: Củ Khoai Tây Vàng | B19: Kg | C19: 187 | D19: 15000 | E19: =C19*D19 -> 2805000
A20: Củ Khoai Tây Vàng | B20: Túi | C20: 0 | E20: =C20*D20 -> 0
A21: Củ Su Hào | B21: Kg | C21: 5 | D21: 18000 | E21: =C21*D21 -> 90000
A22: Bông Cải Xanh 7Cm | B22: Kg | C22: 9 | D22: 40000 | E22: =C22*D22 -> 360000
A23: Bông Cải Xanh Baby | B23: Vỉ | C23: 0 | E23: =C23*D23 -> 0
A24: Bắp Cải Tím | B24: Kg | C24: 0 | E24: =C24*D24 -> 0
A25: Bắp Cải Trái Tim | B25: Kg | C25: 35 | D25: 15000 | E25: =C25*D25 -> 525000
A26: Bắp Cải Trắng | B26: Kg | C26: 1920 | D26: 13748.5 | E26: =C26*D26 -> 26397120
A27: Cải Bó Xôi | B27: Kg | C27: 0 | E27: =C27*D27 -> 0
A28: Cải Bó Xôi | B28: Túi | C28: 14 | D28: 10000 | E28: =C28*D28 -> 140000
A29: Cải Cầu Vồng | B29: Túi | C29: 0 | E29: =C29*D29 -> 0
A30: Cải Kale | B30: Túi | C30: 0 | E30: =C30*D30 -> 0
A31: Cải Kale | B31: Túi 150gr | C31: 0 | E31: =C31*D31 -> 0
A32: Cải Thảo | B32: Kg | C32: 250 | D32: 7500 | E32: =C32*D32 -> 1875000
A33: Cần Tây | B33: Cây | C33: 0 | E33: =C33*D33 -> 0
A34: Cần Tây | B34: Kg | C34: 20 | D34: 14000 | E34: =C34*D34 -> 280000
A35: Hành Paro | B35: Cây | C35: 0 | E35: =C35*D35 -> 0
A36: Hành Paro | B36: Kg | C36: 6 | D36: 48000 | E36: =C36*D36 -> 288000
A37: Lá Mè | B37: Túi | C37: 0 | E37: =C37*D37 -> 0
A38: Lá Nha Đam | B38: Kg | C38: 6 | D38: 14000 | E38: =C38*D38 -> 84000
A39: Lá Quế Tây | B39: Túi | C39: 0 | E39: =C39*D39 -> 0
A40: Lá Tía Tô | B40: Kg | C40: 0 | E40: =C40*D40 -> 0
A41: Lá Hương Thảo | B41: Túi | C41: 0 | E41: =C41*D41 -> 0
...

Sheet 3.11
A2: hàng tồn cuối ngày 3/11 vr
A3: Tên Sản phẩm | B3: ĐVT | C3: Tồn ĐL | D3: giá | E3: thành tiền
A4: Cà Rốt | B4: Kg | C4: 0 | E4: =C4*D4 -> 0
A5: Cà Rốt | B5: Túi | C5: 0 | E5: =C5*D5 -> 0
A6: Cà Rốt Baby | B6: Kg | C6: 0 | E6: =C6*D6 -> 0
A7: Cà Rốt Baby | B7: Vỉ | C7: 0 | E7: =C7*D7 -> 0
A8: Củ Cải Đỏ | B8: Hộp | C8: 0 | E8: =C8*D8 -> 0
A9: Củ Cải Đỏ | B9: Kg | C9: 0 | E9: =C9*D9 -> 0
A10: Củ Cải Đỏ 300Gr | B10: Hộp | C10: 0 | E10: =C10*D10 -> 0
A11: Củ Cải Trắng | B11: Kg | C11: 0 | E11: =C11*D11 -> 0
A12: Củ Dền | B12: Kg | C12: 0 | E12: =C12*D12 -> 0
A13: Củ Dền | B13: Túi | C13: 0 | E13: =C13*D13 -> 0
A14: Củ Gừng | B14: Kg | C14: 3 | D14: 45000 | E14: =C14*D14 -> 135000
A15: Củ Hành Tây | B15: Kg | C15: 2178 | D15: 28000 | E15: =C15*D15 -> 60984000
A16: Củ Hành Tây Tím | B16: Kg | C16: 0 | E16: =C16*D16 -> 0
A17: Củ Hành Tây Tím | B17: Túi | C17: 0 | E17: =C17*D17 -> 0
A18: Củ Hành Tây Trung | B18: Kg | C18: 0 | E18: =C18*D18 -> 0
A19: Củ Hành Tây Trung | B19: Túi | C19: 283 | D19: 5400 | E19: =C19*D19 -> 1528200
A20: Củ Khoai Lang Mật Size 46 | B20: Kg | C20: 705 | D20: 22000 | E20: =C20*D20 -> 15510000 | F20: 700
A21: Củ Khoai Lang Mật Size 46 | B21: Túi | C21: 0 | E21: =C21*D21 -> 0
A22: Củ Khoai Lang Nhật | B22: Kg | C22: 140 | D22: 19500 | E22: =C22*D22 -> 2730000
A23: Củ Khoai Lang Nhật | B23: Túi | C23: 0 | E23: =C23*D23 -> 0
A24: Củ Khoai Mỡ | B24: Kg | C24: 0 | E24: =C24*D24 -> 0
A25: Củ Khoai Tây Bi Vàng | B25: Túi | C25: 0 | E25: =C25*D25 -> 0
A26: Củ Khoai Tây Vàng | B26: Kg | C26: 168 | D26: 15000 | E26: =C26*D26 -> 2520000
A27: Củ Khoai Tây Vàng | B27: Túi | C27: 0 | E27: =C27*D27 -> 0
A28: Củ Su Hào | B28: Kg | C28: 0 | E28: =C28*D28 -> 0
A29: Bông Cải Xanh 7Cm | B29: Kg | C29: 0 | E29: =C29*D29 -> 0
A30: Bông Cải Xanh Baby | B30: Kg | C30: 0 | E30: =C30*D30 -> 0
A31: Bông Cải Xanh Baby | B31: Vỉ | C31: 0 | E31: =C31*D31 -> 0
A32: Bắp Cải Tím | B32: Kg | C32: 0 | E32: =C32*D32 -> 0
A33: Bắp Cải Trái Tim | B33: Kg | C33: 180 | D33: 15000 | E33: =C33*D33 -> 2700000
A34: Bắp Cải Trắng | B34: Kg | C34: 1840 | D34: 13748.5 | E34: =C34*D34 -> 25297240
A35: Cải Bó Xôi | B35: Kg | C35: 0 | E35: =C35*D35 -> 0
A36: Cải Bó Xôi | B36: Túi | C36: 0 | E36: =C36*D36 -> 0
A37: Cải Cầu Vồng | B37: Kg | C37: 0 | E37: =C37*D37 -> 0
A38: Cải Cầu Vồng | B38: Túi | C38: 0 | E38: =C38*D38 -> 0
A39: Cải Kale | B39: Kg | C39: 0 | E39: =C39*D39 -> 0
A40: Cải Kale | B40: Túi | C40: 0 | E40: =C40*D40 -> 0
A41: Cải Kale | B41: Túi 150gr | C41: 0 | E41: =C41*D41 -> 0
...

Sheet 4.11
A2: hàng tồn cuối ngày 4/11 vr
A3: Tên Sản phẩm | B3: ĐVT | C3: Tồn ĐL | D3: giá | E3: thành tiền
A4: Cà Rốt | B4: Kg | E4: =C4*D4 -> 0
A5: Cà Rốt | B5: Túi | E5: =C5*D5 -> 0
A6: Cà Rốt Baby | B6: Kg | E6: =C6*D6 -> 0
A7: Cà Rốt Baby | B7: Vỉ | E7: =C7*D7 -> 0
A8: Củ Cải Đỏ | B8: Hộp | E8: =C8*D8 -> 0
A9: Củ Cải Đỏ | B9: Kg | E9: =C9*D9 -> 0
A10: Củ Cải Trắng | B10: Kg | E10: =C10*D10 -> 0
A11: Củ Dền | B11: Kg | C11: 10 | D11: 15000 | E11: =C11*D11 -> 150000
A12: Củ Dền | B12: Túi | E12: =C12*D12 -> 0
A13: Củ Hành Tây | B13: Kg | C13: 2100 | D13: 28000 | E13: =C13*D13 -> 58800000
A14: Củ Hành Tây | B14: Túi 300gr | E14: =C14*D14 -> 0
A15: Củ Hành Tây Tím | B15: Kg | E15: =C15*D15 -> 0
A16: Củ Hành Tây Tím | B16: Túi | E16: =C16*D16 -> 0
A17: Củ Hành Tây Trung | B17: Kg | E17: =C17*D17 -> 0
A18: Củ Hành Tây Trung | B18: Túi | C18: 156 | D18: 5400 | E18: =C18*D18 -> 842400
A19: Củ Khoai Lang Mật Size 46 | B19: Kg | C19: 1175 | D19: 21000 | E19: =C19*D19 -> 24675000 | F19: dung 22, giang 20 | H19: 1170
A20: Củ Khoai Lang Mật Size 46 | B20: Túi | E20: =C20*D20 -> 0
A21: Củ Khoai Lang Nhật | B21: Kg | C21: 140 | D21: 19500 | E21: =C21*D21 -> 2730000
A22: Củ Khoai Lang Nhật | B22: Túi | E22: =C22*D22 -> 0
A23: Củ Khoai Mỡ | B23: Kg | E23: =C23*D23 -> 0
A24: Củ Khoai Tây Vàng | B24: Kg | C24: 130 | D24: 15000 | E24: =C24*D24 -> 1950000
A25: Củ Khoai Tây Vàng | B25: Túi | E25: =C25*D25 -> 0
A26: Củ Su Hào | B26: Kg | E26: =C26*D26 -> 0
A27: Bông Cải Xanh 7Cm | B27: Kg | C27: 8 | D27: 40000 | E27: =C27*D27 -> 320000
A28: Bông Cải Xanh Baby | B28: Kg | E28: =C28*D28 -> 0
A29: Bông Cải Xanh Baby | B29: Vỉ | E29: =C29*D29 -> 0
A30: Bắp Cải Tím | B30: Kg | E30: =C30*D30 -> 0
A31: Bắp Cải Trái Tim | B31: Kg | C31: 280 | D31: 15000 | E31: =C31*D31 -> 4200000
A32: Bắp Cải Trắng | B32: Kg | C32: 2820 | D32: 11000 | E32: =C32*D32 -> 31020000
A33: Bắp Cải Trắng | B33: Bắp | E33: =C33*D33 -> 0
A34: Cải Bó Xôi | B34: Kg | E34: =C34*D34 -> 0
A35: Cải Bó Xôi | B35: Túi | E35: =C35*D35 -> 0
A36: Cải Cầu Vồng | B36: Kg | E36: =C36*D36 -> 0
A37: Cải Cầu Vồng | B37: Túi | E37: =C37*D37 -> 0
A38: Cải Kale | B38: Kg | E38: =C38*D38 -> 0
A39: Cải Kale | B39: Túi | E39: =C39*D39 -> 0
A40: Cải Kale | B40: Túi 150gr | E40: =C40*D40 -> 0
A41: Cải Thảo | B41: Kg | C41: 620 | D41: 7500 | E41: =C41*D41 -> 4650000
...

Sheet 5.11
A1: Tên Sản phẩm | B1: ĐVT | C1: Tồn ĐL | D1: Giá | E1: Thành tiền
A2: Cà Rốt | B2: Kg | C2: 0
A3: Cà Rốt | B3: Túi | C3: 0
A4: Cà Rốt Baby | B4: Kg | C4: 0
A5: Cà Rốt Baby | B5: Vỉ | C5: 0
A6: Củ Cải Đỏ | B6: Hộp | C6: 0
A7: Củ Cải Đỏ | B7: Kg | C7: 2 | D7: 40000 | E7: =+D7*C7 -> 80000
A8: Củ Dền | B8: Kg | C8: 0
A9: Củ Dền | B9: Túi | C9: 0
A10: Củ Hành Tây | B10: Kg | C10: 1895 | D10: 28000 | E10: =+D10*C10 -> 53060000
A11: Củ Hành Tây | B11: Túi 300gr | C11: 0
A12: Củ Hành Tây Trung | B12: Túi | C12: 0
A13: Củ Khoai Lang Mật Size 46 | B13: Kg | C13: 1015 | D13: =VLOOKUP(A13,'4.11'!A17:D226,4,) -> 21000 | E13: =+D13*C13 -> 21315000 | F13: 1010
A14: Củ Khoai Lang Mật Size 46 | B14: Túi | C14: 0
A15: Củ Khoai Lang Nhật | B15: Kg | C15: 120 | D15: =VLOOKUP(A15,'4.11'!A19:D228,4,) -> 19500 | E15: =+D15*C15 -> 2340000
A16: Củ Khoai Lang Nhật | B16: Túi | C16: 0
A17: Củ Khoai Tây Vàng | B17: Kg | C17: 115 | D17: =VLOOKUP(A17,'4.11'!A21:D230,4,) -> 15000 | E17: =+D17*C17 -> 1725000
A18: Củ Khoai Tây Vàng | B18: Túi | C18: 0
A19: Bông Cải Xanh Baby | B19: Kg | C19: 0
A20: Bông Cải Xanh Baby | B20: Vỉ | C20: 0
A21: Bắp Cải Trắng | B21: Kg | C21: 650 | D21: =VLOOKUP(A21,'4.11'!A25:D234,4,) -> 11000 | E21: =+D21*C21 -> 7150000
A22: Cải Bó Xôi | B22: Kg | C22: 0
A23: Cải Bó Xôi | B23: Túi | C23: 55 | D23: 13500 | E23: =+D23*C23 -> 742500
A24: Cải Kale | B24: Kg | C24: 0
A25: Cải Kale | B25: Túi | C25: 0
A26: Cải Kale | B26: Túi 150gr | C26: 0
A27: Cải Thảo | B27: Kg | C27: 1440 | D27: =VLOOKUP(A27,'4.11'!A31:D240,4,) -> 7500 | E27: =+D27*C27 -> 10800000
A28: Cần Tây | B28: Cây | C28: 0
A29: Cần Tây | B29: Kg | C29: 5 | D29: 11000 | E29: =+D29*C29 -> 55000
A30: Cần Tây | B30: Túi | C30: 0
A31: Xà Lách Lolo Xanh T.C | B31: Kg | C31: 3 | D31: 28000 | E31: =+D31*C31 -> 84000
A32: Bí Đỏ Tròn | B32: Kg | C32: 135 | D32: 5200 | E32: =+D32*C32 -> 702000
A33: Bí Ngòi Xanh | B33: Kg | C33: 0
A34: Bí Ngòi Xanh | B34: Trái | C34: 0
A35: Bí Non Nhật | B35: Kg | C35: 60 | D35: 18000 | E35: =+D35*C35 -> 1080000
A36: Bí Non Nhật | B36: Trái | C36: 0
A37: Cà Chua Beef | B37: Kg | C37: 495 | D37: =VLOOKUP(A37,'4.11'!A41:D250,4,) -> 25000 | E37: =+D37*C37 -> 12375000
A38: Cà Chua Beef | B38: Vỉ | C38: 0
A39: Cà Chua Beef | B39: Vỉ 650gr | C39: 0
A40: Cà Chua Thường | B40: Kg | C40: 660 | D40: =VLOOKUP(A40,'4.11'!A44:D253,4,) -> 23000 | E40: =+D40*C40 -> 15180000
...

Sheet 6.11
A1: hàng tồn cuối ngày 6/11 vr
A2: Tên Sản phẩm | B2: ĐVT | C2: Tồn ĐL | D2: giá | E2: thành tiền
A3: Cà Rốt | B3: Kg | C3: 170 | D3: 19000 | E3: =C3*D3 -> 3230000
A4: Cà Rốt | B4: Túi | C4: 0 | E4: =C4*D4 -> 0
A5: Cà Rốt Baby | B5: Vỉ | C5: 0 | E5: =C5*D5 -> 0
A6: Củ Cải Đỏ | B6: Hộp | C6: 0 | E6: =C6*D6 -> 0
A7: Củ Cải Đỏ | B7: Kg | C7: 0 | E7: =C7*D7 -> 0
A8: Củ Dền | B8: Kg | C8: 73 | D8: 15000 | E8: =C8*D8 -> 1095000
A9: Củ Dền | B9: Túi | C9: 0 | E9: =C9*D9 -> 0
A10: Củ Hành Tây | B10: Kg | C10: 1693 | D10: 28000 | E10: =C10*D10 -> 47404000
A11: Củ Hành Tây | B11: Túi 300gr | C11: 0 | E11: =C11*D11 -> 0
A12: Củ Hành Tây Trung | B12: Kg | C12: 0 | E12: =C12*D12 -> 0
A13: Củ Hành Tây Trung | B13: Túi | C13: 0 | E13: =C13*D13 -> 0
A14: Củ Khoai Lang Mật Size 46 | B14: Kg | C14: 1180 | D14: 21000 | E14: =C14*D14 -> 24780000 | F14: 1175
A15: Củ Khoai Lang Mật Size 46 | B15: Túi | C15: 0 | E15: =C15*D15 -> 0
A16: Củ Khoai Lang Nhật | B16: Kg | C16: 200 | D16: 19000 | E16: =C16*D16 -> 3800000
A17: Củ Khoai Lang Nhật | B17: Túi | C17: 0 | E17: =C17*D17 -> 0
A18: Củ Khoai Tây Vàng | B18: Kg | C18: 220 | D18: 15000 | E18: =C18*D18 -> 3300000
A19: Củ Khoai Tây Vàng | B19: Túi | C19: 0 | E19: =C19*D19 -> 0
A20: Bông Cải Xanh Baby | B20: Kg | C20: 0 | E20: =C20*D20 -> 0
A21: Bông Cải Xanh Baby | B21: Vỉ | C21: 0 | E21: =C21*D21 -> 0
A22: Bắp Cải Trắng | B22: Kg | C22: 350 | D22: 11000 | E22: =C22*D22 -> 3850000
A23: Cải Bó Xôi | B23: Kg | C23: 0 | E23: =C23*D23 -> 0
A24: Cải Bó Xôi | B24: Túi | C24: 40 | D24: 12000 | E24: =C24*D24 -> 480000
A25: Cải Kale | B25: Kg | C25: 0 | E25: =C25*D25 -> 0
A26: Cải Kale | B26: Túi | C26: 0 | E26: =C26*D26 -> 0
A27: Cải Kale | B27: Túi 150gr | C27: 0 | E27: =C27*D27 -> 0
A28: Cải Thảo | B28: Kg | C28: 1860 | D28: 7500 | E28: =C28*D28 -> 13950000
A29: Cần Tây | B29: Cây | C29: 0 | E29: =C29*D29 -> 0
A30: Cần Tây | B30: Kg | C30: 126 | D30: 11000 | E30: =C30*D30 -> 1386000
A31: Cần Tây | B31: Túi | C31: 0 | E31: =C31*D31 -> 0
A32: Xà Lách Lolo Xanh T.C | B32: Kg | C32: 3 | D32: 28000 | E32: =C32*D32 -> 84000
A33: Bí Đỏ Tròn | B33: Kg | C33: 2345 | D33: 5200 | E33: =C33*D33 -> 12194000
A34: Bí Ngòi Xanh | B34: Kg | C34: 0 | E34: =C34*D34 -> 0
A35: Bí Ngòi Xanh | B35: Trái | C35: 0 | E35: =C35*D35 -> 0
A36: Bí Non Nhật | B36: Kg | C36: 43 | D36: 13000 | E36: =C36*D36 -> 559000
A37: Bí Non Nhật | B37: Trái | C37: 0 | E37: =C37*D37 -> 0
A38: Cà Chua Beef | B38: Kg | C38: 173 | D38: 25000 | E38: =C38*D38 -> 4325000
A39: Cà Chua Beef | B39: Vỉ | C39: 0 | E39: =C39*D39 -> 0
A40: Cà Chua Beef | B40: Vỉ 650gr | C40: 0 | E40: =C40*D40 -> 0
...

Sheet 7.11
A1: hàng tồn cuối ngày 7/11 vr
A2: Tên Sản phẩm | B2: ĐVT | C2: Tồn ĐL | D2: giá | E2: thành tiền
A3: Bắp Cải Tím | B3: Kg | C3: 0 | E3: =C3*D3 -> 0
A4: Bắp Cải Trái Tim | B4: Kg | C4: 107 | D4: 12000 | E4: =C4*D4 -> 1284000
A5: Bắp Cải Trắng | B5: Kg | C5: 300 | D5: 11000 | E5: =C5*D5 -> 3300000
A6: Bí Đao Xanh | B6: Kg | C6: 0 | E6: =C6*D6 -> 0
A7: Bí Đao Xanh | B7: Trái | C7: 0 | E7: =C7*D7 -> 0
A8: Bí Đỏ Hồ Lô | B8: Kg | C8: 0 | E8: =C8*D8 -> 0
A9: Bí Đỏ Tròn | B9: Kg | C9: 2000 | D9: 5200 | E9: =C9*D9 -> 10400000
A10: Bí Ngòi Vàng | B10: Kg | C10: 0 | E10: =C10*D10 -> 0
A11: Bí Ngòi Xanh | B11: Kg | C11: 0 | E11: =C11*D11 -> 0
A12: Bí Ngòi Xanh | B12: Trái | C12: 0 | E12: =C12*D12 -> 0
A13: Bí Non Nhật | B13: Kg | C13: 41 | D13: 15000 | E13: =C13*D13 -> 615000
A14: Bí Non Nhật | B14: Trái | C14: 0 | E14: =C14*D14 -> 0
A15: Bơ Booth | B15: Kg | C15: 54 | D15: 26000 | E15: =C15*D15 -> 1404000
A16: Bông Cải Trắng | B16: Kg | C16: 0 | E16: =C16*D16 -> 0
A17: Bông Cải Xanh 10Cm | B17: Kg | C17: 9 | D17: 34000 | E17: =C17*D17 -> 306000
A18: Bông Cải Xanh 7Cm | B18: Kg | C18: 54 | D18: 39000 | E18: =C18*D18 -> 2106000
A19: Bông Cải Xanh Baby | B19: Kg | C19: 0 | E19: =C19*D19 -> 0
A20: Bông Cải Xanh Baby | B20: Vỉ | C20: 0 | E20: =C20*D20 -> 0
A21: Cà Chua Beef | B21: Kg | C21: 234 | D21: 25000 | E21: =C21*D21 -> 5850000
A22: Cà Chua Beef | B22: Vỉ | C22: 0 | E22: =C22*D22 -> 0
A23: Cà Chua Beef | B23: Vỉ 650gr | C23: 0 | E23: =C23*D23 -> 0
A24: Cà Chua Beef Trung | B24: Kg | C24: 15 | D24: 17000 | E24: =C24*D24 -> 255000
A25: Cà Chua Beef Trung | B25: Vỉ 500gr | C25: 50 | D25: 11000 | E25: =C25*D25 -> 550000
A26: Cà Chua Bi Đỏ | B26: Kg | C26: 2.5 | D26: 38000 | E26: =C26*D26 -> 95000
A27: Cà Chua Bi Đỏ | B27: Hộp 300gr | C27: 0 | E27: =C27*D27 -> 0
A28: Cà Chua Bi Mix | B28: Hộp | C28: 0 | E28: =C28*D28 -> 0
A29: Cà Chua Socola | B29: Kg | C29: 3 | D29: 36000 | E29: =C29*D29 -> 108000
A30: Cà Chua Socola | B30: Hộp 300gr | C30: 0 | E30: =C30*D30 -> 0
A31: Cà Chua Socola | B31: Hộp 250GR | C31: 0 | E31: =C31*D31 -> 0
A32: Cà Chua Thường | B32: Kg | C32: 190 | D32: 19000 | E32: =C32*D32 -> 3610000
A33: Cà Chua Thường | B33: Vỉ | C33: 0 | E33: =C33*D33 -> 0
A34: Cà Chua Thường Trung | B34: Túi | C34: 208 | D34: 18000 | E34: =C34*D34 -> 3744000
A35: Cà Rốt | B35: Kg | C35: 0 | E35: =C35*D35 -> 0
A36: Cà Rốt | B36: Túi | C36: 0 | E36: =C36*D36 -> 0
A37: Cà Rốt Baby | B37: Kg | C37: 0 | E37: =C37*D37 -> 0
A38: Cà Rốt Baby | B38: Vỉ | C38: 0 | E38: =C38*D38 -> 0
A39: Cà Tím | B39: Kg | C39: 35 | D39: 11000 | E39: =C39*D39 -> 385000
A40: Cà Tím | B40: Cặp | C40: 0 | E40: =C40*D40 -> 0
...

Sheet 8.11
A2: Tên Sản phẩm | B2: ĐVT | C2: tồn | D2: giá | E2: thành tiền
A3: Cà Rốt | B3: Kg | C3: 70 | D3: 18000 | E3: =C3*D3 -> 1260000
A4: Cà Rốt | B4: Túi | C4: 0 | E4: =C4*D4 -> 0
A5: Cà Rốt Baby | B5: Vỉ | C5: 0 | E5: =C5*D5 -> 0
A6: Củ Cải Đỏ | B6: Hộp | C6: 0 | E6: =C6*D6 -> 0
A7: Củ Cải Đỏ | B7: Kg | C7: 0 | E7: =C7*D7 -> 0
A8: Củ Dền | B8: Kg | C8: 50 | D8: 15000 | E8: =C8*D8 -> 750000
A9: Củ Dền | B9: Túi | C9: 0 | E9: =C9*D9 -> 0
A10: Củ Hành Tây | B10: Kg | C10: 1462 | D10: 28000 | E10: =C10*D10 -> 40936000
A11: Củ Hành Tây | B11: Túi 300gr | C11: 0 | E11: =C11*D11 -> 0
A12: Củ Hành Tây Trung | B12: Kg | C12: 0 | E12: =C12*D12 -> 0
A13: Củ Hành Tây Trung | B13: Túi | C13: 750 | D13: 4500 | E13: =C13*D13 -> 3375000
A14: Củ Khoai Lang Mật Size 46 | B14: Kg | C14: 730 | D14: 21000 | E14: =C14*D14 -> 15330000
A15: Củ Khoai Lang Mật Size 46 | B15: Túi | C15: 0 | E15: =C15*D15 -> 0
A16: Củ Khoai Lang Nhật | B16: Kg | C16: 170 | D16: 19000 | E16: =C16*D16 -> 3230000
A17: Củ Khoai Lang Nhật | B17: Túi | C17: 0 | E17: =C17*D17 -> 0
A18: Củ Khoai Tây Vàng | B18: Kg | C18: 185 | D18: 15000 | E18: =C18*D18 -> 2775000
A19: Củ Khoai Tây Vàng | B19: Túi | C19: 0 | E19: =C19*D19 -> 0
A20: Bông Cải Xanh Baby | B20: Kg | C20: 0 | E20: =C20*D20 -> 0
A21: Bông Cải Xanh Baby | B21: Vỉ | C21: 0 | E21: =C21*D21 -> 0
A22: Bắp Cải Trắng | B22: Kg | C22: 45 | D22: 11000 | E22: =C22*D22 -> 495000
A23: Cải Bó Xôi | B23: Kg | C23: 0 | E23: =C23*D23 -> 0
A24: Cải Bó Xôi | B24: Túi | C24: 0 | E24: =C24*D24 -> 0
A25: Cải Kale | B25: Kg | C25: 0 | E25: =C25*D25 -> 0
A26: Cải Kale | B26: Túi | C26: 0 | E26: =C26*D26 -> 0
A27: Cải Kale | B27: Túi 150gr | C27: 0 | E27: =C27*D27 -> 0
A28: Cải Thảo | B28: Kg | C28: 1040 | D28: 7500 | E28: =C28*D28 -> 7800000
A29: Cần Tây | B29: Cây | C29: 0 | E29: =C29*D29 -> 0
A30: Cần Tây | B30: Kg | C30: 208 | D30: 11000 | E30: =C30*D30 -> 2288000
A31: Cần Tây | B31: Túi | C31: 0 | E31: =C31*D31 -> 0
A32: Xà Lách Lolo Xanh T.C | B32: Kg | C32: 0 | E32: =C32*D32 -> 0
A33: Bí Đỏ Tròn | B33: Kg | C33: 520 | D33: 5200 | E33: =C33*D33 -> 2704000
A34: Bí Ngòi Xanh | B34: Kg | C34: 0 | E34: =C34*D34 -> 0
A35: Bí Ngòi Xanh | B35: Trái | C35: 0 | E35: =C35*D35 -> 0
A36: Bí Non Nhật | B36: Kg | C36: 48 | D36: 15000 | E36: =C36*D36 -> 720000
A37: Bí Non Nhật | B37: Trái | C37: 0 | E37: =C37*D37 -> 0
A38: Cà Chua Beef | B38: Kg | C38: 220 | D38: 25000 | E38: =C38*D38 -> 5500000
A39: Cà Chua Beef | B39: Vỉ | C39: 0 | E39: =C39*D39 -> 0
A40: Cà Chua Beef | B40: Vỉ 650gr | C40: 0 | E40: =C40*D40 -> 0
A41: Cà Chua Thường | B41: Kg | C41: 300 | D41: 19000 | E41: =C41*D41 -> 5700000
...

Sheet 9.11
A1: Tên Sản phẩm | B1: ĐVT | C1: Tồn ĐL | D1: Giá | E1: Thành tiền
A2: Cà Rốt | B2: Kg | C2: 0
A3: Cà Rốt | B3: Túi | C3: 0
A4: Cà Rốt Baby | B4: Kg | C4: 0
A5: Cà Rốt Baby | B5: Vỉ | C5: 0
A6: Củ Cải Đỏ | B6: Hộp | C6: 0
A7: Củ Dền | B7: Kg | C7: 37 | D7: 17000 | E7: =+D7*C7 -> 629000
A8: Củ Dền | B8: Túi | C8: 0
A9: Củ Hành Tây | B9: Kg | C9: 1377 | D9: =VLOOKUP(A9,'8.11'!A5:D213,4,) -> 28000 | E9: =+D9*C9 -> 38556000
A10: Củ Hành Tây | B10: Túi 300gr | C10: 0
A11: Củ Hành Tây Trung | B11: Kg | C11: 0
A12: Củ Hành Tây Trung | B12: Túi | C12: 766 | D12: =15000*0.3 -> 4500 | E12: =+D12*C12 -> 3447000
A13: Củ Khoai Lang Mật Size 46 | B13: Kg | C13: 675 | D13: =VLOOKUP(A13,'8.11'!A9:D217,4,) -> 21000 | E13: =+D13*C13 -> 14175000
A14: Củ Khoai Lang Mật Size 46 | B14: Túi | C14: 0
A15: Củ Khoai Lang Nhật | B15: Kg | C15: 140 | D15: =VLOOKUP(A15,'8.11'!A11:D219,4,) -> 19000 | E15: =+D15*C15 -> 2660000
A16: Củ Khoai Lang Nhật | B16: Túi | C16: 0
A17: Củ Khoai Tây Vàng | B17: Kg | C17: 155 | D17: =VLOOKUP(A17,'8.11'!A13:D221,4,) -> 15000 | E17: =+D17*C17 -> 2325000
A18: Củ Khoai Tây Vàng | B18: Túi | C18: 0
A19: Bông Cải Xanh Baby | B19: Kg | C19: 0
A20: Bông Cải Xanh Baby | B20: Vỉ | C20: 0
A21: Bắp Cải Trắng | B21: Kg | C21: 645 | D21: =VLOOKUP(A21,'8.11'!A17:D225,4,) -> 11000 | E21: =+D21*C21 -> 7095000
A22: Cải Bó Xôi | B22: Kg | C22: 0
A23: Cải Bó Xôi | B23: Túi | C23: 17 | D23: =38000*0.3 -> 11400 | E23: =+D23*C23 -> 193800
A24: Cải Kale | B24: Kg | C24: 0
A25: Cải Kale | B25: Túi | C25: 0
A26: Cải Kale | B26: Túi 150gr | C26: 0
A27: Cải Thảo | B27: Kg | C27: 4200 | D27: =VLOOKUP(A27,'8.11'!A23:D231,4,) -> 7500 | E27: =+D27*C27 -> 31500000
A28: Cần Tây | B28: Cây | C28: 0
A29: Cần Tây | B29: Kg | C29: 125 | D29: 10000 | E29: =+D29*C29 -> 1250000
A30: Cần Tây | B30: Túi | C30: 0
A31: Xà Lách Lolo Xanh T.C | B31: Kg | C31: 0
A32: Bí Đỏ Tròn | B32: Kg | C32: 590 | D32: =VLOOKUP(A32,'8.11'!A28:D236,4,) -> 5200 | E32: =+D32*C32 -> 3068000
A33: Bí Ngòi Xanh | B33: Kg | C33: 152 | D33: 23000 | E33: =+D33*C33 -> 3496000
A34: Bí Ngòi Xanh | B34: Trái | C34: 0
A35: Bí Ngòi Xanh | B35: Trái 250gr | C35: 0
A36: Bí Non Nhật | B36: Kg | C36: 48 | D36: =VLOOKUP(A36,'8.11'!A32:D240,4,) -> 15000 | E36: =+D36*C36 -> 720000
A37: Bí Non Nhật | B37: Trái | C37: 0
A38: Cà Chua Beef | B38: Kg | C38: 220 | D38: =VLOOKUP(A38,'8.11'!A34:D242,4,) -> 25000 | E38: =+D38*C38 -> 5500000
A39: Cà Chua Beef | B39: Vỉ | C39: 0
A40: Cà Chua Beef | B40: Vỉ 650gr | C40: 0
...

Sheet 10.11
A1: Tên Sản phẩm | B1: ĐVT | C1: Tồn ĐL | D1: Giá | E1: Thành tiền
A2: Bắp Cải Tím | B2: Kg | C2: 7 | D2: 30000 | E2: =+D2*C2 -> 210000
A3: Bắp Cải Trái Tim | B3: Kg | C3: 0
A4: Bắp Cải Trắng | B4: Kg | C4: 520 | D4: =VLOOKUP(A4,'9.11'!A9:D168,4,) -> 11000 | E4: =+D4*C4 -> 5720000
A5: Bí Đao Xanh | B5: Kg | C5: 0
A6: Bí Đao Xanh | B6: Trái | C6: 0
A7: Bí Đỏ Hồ Lô | B7: Kg | C7: 0
A8: Bí Đỏ Tròn | B8: Kg | C8: 680 | D8: =VLOOKUP(A8,'9.11'!A13:D172,4,) -> 5200 | E8: =+D8*C8 -> 3536000
A9: Bí Ngô Mini | B9: Kg | C9: 0
A10: Bí Ngòi Vàng | B10: Kg | C10: 0
A11: Bí Ngòi Xanh | B11: Kg | C11: 117 | D11: =VLOOKUP(A11,'9.11'!A16:D175,4,) -> 23000 | E11: =+D11*C11 -> 2691000
A12: Bí Ngòi Xanh | B12: Trái | C12: 0
A13: Bí Non Nhật | B13: Kg | C13: 60 | D13: =VLOOKUP(A13,'9.11'!A18:D177,4,) -> 15000 | E13: =+D13*C13 -> 900000
A14: Bí Non Nhật | B14: Trái | C14: 0
A15: Bơ Booth | B15: Kg | C15: 0
A16: Bông Cải Trắng | B16: Kg | C16: 5 | D16: 27000 | E16: =+D16*C16 -> 135000
A17: Bông Cải Xanh 10Cm | B17: Kg | C17: 0
A18: Bông Cải Xanh 7Cm | B18: Kg | C18: 0
A19: Bông Cải Xanh Baby | B19: Kg | C19: 0
A20: Bông Cải Xanh Baby | B20: Vỉ | C20: 0
A21: Cà Chua Beef | B21: Kg | C21: 140 | D21: 24000 | E21: =+D21*C21 -> 3360000
A22: Cà Chua Beef | B22: Vỉ | C22: 0
A23: Cà Chua Beef | B23: Vỉ 650gr | C23: 0
A24: Cà Chua Beef Trung | B24: Kg | C24: 91 | D24: =VLOOKUP(A24,'9.11'!A29:D188,4,) -> 17000 | E24: =+D24*C24 -> 1547000
A25: Cà Chua Beef Trung | B25: Vỉ 500gr | C25: 0
A26: Cà Chua Bi Đỏ | B26: Kg | C26: 0
A27: Cà Chua Bi Đỏ | B27: Hộp 300gr | C27: 0
A28: Cà Chua Bi Mix | B28: Hộp | C28: 0
A29: Cà Chua Bi Mix | B29: Kg | C29: 0
A30: Cà Chua Socola | B30: Kg | C30: 0
A31: Cà Chua Socola | B31: Hộp 300gr | C31: 0
A32: Cà Chua Socola | B32: Hộp 250GR | C32: 0
A33: Cà Chua Thường | B33: Kg | C33: 240 | D33: =VLOOKUP(A33,'9.11'!A38:D197,4,) -> 17000 | E33: =+D33*C33 -> 4080000
A34: Cà Chua Thường | B34: Vỉ | C34: 0
A35: Cà Chua Thường Trung | B35: Túi | C35: 87 | D35: =VLOOKUP(A35,'9.11'!A40:D199,4,) -> 14000 | E35: =+D35*C35 -> 1218000
A36: Cà Rốt | B36: Kg | C36: 65 | D36: 16000 | E36: =+D36*C36 -> 1040000
A37: Cà Rốt | B37: Túi | C37: 0
A38: Cà Rốt Baby | B38: Kg | C38: 0
A39: Cà Rốt Baby | B39: Vỉ | C39: 0
A40: Cà Rốt Trung | B40: Kg | C40: 0
...

Sheet 11.11
A1: Tên Sản phẩm | B1: ĐVT | C1: Tồn ĐL | D1: Giá | E1: Thành tiền
A2: Bắp Cải Tím | B2: Kg | C2: 5 | D2: =VLOOKUP(A2,'10.11'!A2:D169,4,) -> 30000 | E2: =+D2*C2 -> 150000
A3: Bắp Cải Trái Tim | B3: Kg | C3: 25 | D3: 18000 | E3: =+D3*C3 -> 450000
A4: Bắp Cải Trắng | B4: Kg | C4: 390 | D4: =VLOOKUP(A4,'10.11'!A4:D171,4,) -> 11000 | E4: =+D4*C4 -> 4290000
A5: Bí Đao Xanh | B5: Kg | C5: 0
A6: Bí Đao Xanh | B6: Trái | C6: 0
A7: Bí Đỏ Hồ Lô | B7: Kg | C7: 0
A8: Bí Đỏ Tròn | B8: Kg | C8: 2420 | D8: =VLOOKUP(A8,'10.11'!A8:D175,4,) -> 5200 | E8: =+D8*C8 -> 12584000
A9: Bí Ngô Mini | B9: Kg | C9: 0
A10: Bí Ngòi Vàng | B10: Kg | C10: 0
A11: Bí Ngòi Xanh | B11: Kg | C11: 80 | D11: =VLOOKUP(A11,'10.11'!A11:D178,4,) -> 23000 | E11: =+D11*C11 -> 1840000
A12: Bí Ngòi Xanh | B12: Trái | C12: 0
A13: Bí Non Nhật | B13: Kg | C13: 40 | D13: =VLOOKUP(A13,'10.11'!A13:D180,4,) -> 15000 | E13: =+D13*C13 -> 600000
A14: Bí Non Nhật | B14: Trái | C14: 0
A15: Bơ Booth | B15: Kg | C15: 150 | D15: 26000 | E15: =+D15*C15 -> 3900000
A16: Bông Cải Trắng | B16: Kg | C16: 0
A17: Bông Cải Xanh 10Cm | B17: Kg | C17: 0
A18: Bông Cải Xanh 7Cm | B18: Kg | C18: 30 | D18: 39000 | E18: =+D18*C18 -> 1170000
A19: Bông Cải Xanh Baby | B19: Kg | C19: 0
A20: Bông Cải Xanh Baby | B20: Vỉ | C20: 0
A21: Cà Chua Beef | B21: Kg | C21: 0
A22: Cà Chua Beef | B22: Vỉ | C22: 0
A23: Cà Chua Beef | B23: Vỉ 650gr | C23: 0
A24: Cà Chua Beef Trung | B24: Kg | C24: 25 | D24: =VLOOKUP(A24,'10.11'!A24:D191,4,) -> 17000 | E24: =+D24*C24 -> 425000
A25: Cà Chua Beef Trung | B25: Vỉ 500gr | C25: 0
A26: Cà Chua Bi Đỏ | B26: Kg | C26: 10 | D26: 33000 | E26: =+D26*C26 -> 330000
A27: Cà Chua Bi Đỏ | B27: Hộp 300gr | C27: 108 | D27: 9900 | E27: =+D27*C27 -> 1069200
A28: Cà Chua Bi Mix | B28: Hộp | C28: 0
A29: Cà Chua Bi Mix | B29: Kg | C29: 0
A30: Cà Chua Socola | B30: Kg | C30: 4.5 | D30: 40000 | E30: =+D30*C30 -> 180000
A31: Cà Chua Socola | B31: Hộp 300gr | C31: 0
A32: Cà Chua Socola | B32: Hộp 250GR | C32: 0
A33: Cà Chua Thường | B33: Kg | C33: 0
A34: Cà Chua Thường | B34: Vỉ | C34: 0
A35: Cà Chua Thường Trung | B35: Túi | C35: 0
A36: Cà Rốt | B36: Kg | C36: 90 | D36: =VLOOKUP(A36,'10.11'!A36:D203,4,) -> 16000 | E36: =+D36*C36 -> 1440000
A37: Cà Rốt | B37: Túi | C37: 0
A38: Cà Rốt Baby | B38: Kg | C38: 0
A39: Cà Rốt Baby | B39: Vỉ | C39: 0
A40: Cà Rốt Trung | B40: Kg | C40: 0
...

Sheet 12.11
A1: hàng tồn cuối ngày 12/11 vr
A2: Tên Sản phẩm | B2: ĐVT | C2: Tồn ĐL | D2: giá | E2: thành tiền
A3: Cà Rốt | B3: Kg | C3: 25 | D3: 15000 | E3: =C3*D3 -> 375000
A4: Cà Rốt | B4: Túi | C4: 0 | E4: =C4*D4 -> 0
A5: Cà Rốt Baby | B5: Kg | C5: 0 | E5: =C5*D5 -> 0
A6: Cà Rốt Baby | B6: Vỉ | C6: 0 | E6: =C6*D6 -> 0
A7: Củ Cải Đỏ | B7: Hộp | C7: 0 | E7: =C7*D7 -> 0
A8: Củ Cải Đỏ | B8: Kg | C8: 0 | E8: =C8*D8 -> 0
A9: Củ Dền | B9: Kg | C9: 33 | D9: 17000 | E9: =C9*D9 -> 561000
A10: Củ Dền | B10: Túi | C10: 0 | E10: =C10*D10 -> 0
A11: Củ Hành Tây | B11: Kg | C11: 965 | D11: 22000 | E11: =C11*D11 -> 21230000
A12: Củ Hành Tây | B12: Túi 300gr | C12: 0 | E12: =C12*D12 -> 0
A13: Củ Hành Tây Trung | B13: Túi | C13: 1360 | D13: 4500 | E13: =C13*D13 -> 6120000
A14: Củ Khoai Lang Mật Size 46 | B14: Kg | C14: 610 | D14: 21000 | E14: =C14*D14 -> 12810000
A15: Củ Khoai Lang Nhật | B15: Kg | C15: 230 | D15: 19000 | E15: =C15*D15 -> 4370000
A16: Củ Khoai Tây Vàng | B16: Kg | C16: 210 | D16: 15000 | E16: =C16*D16 -> 3150000
A17: Củ Khoai Tây Vàng | B17: Túi | C17: 0 | E17: =C17*D17 -> 0
A18: Bông Cải Xanh Baby | B18: Kg | C18: 0 | E18: =C18*D18 -> 0
A19: Bông Cải Xanh Baby | B19: Vỉ | C19: 0 | E19: =C19*D19 -> 0
A20: Bắp Cải Trắng | B20: Kg | C20: 360 | D20: 11000 | E20: =C20*D20 -> 3960000
A21: Cải Bó Xôi | B21: Kg | C21: 0 | E21: =C21*D21 -> 0
A22: Cải Bó Xôi | B22: Túi | C22: 8 | D22: 10000 | E22: =C22*D22 -> 80000
A23: Cải Kale | B23: Kg | C23: 0 | E23: =C23*D23 -> 0
A24: Cải Kale | B24: Túi | C24: 0 | E24: =C24*D24 -> 0
A25: Cải Kale | B25: Túi 150gr | C25: 0 | E25: =C25*D25 -> 0
A26: Cải Thảo | B26: Kg | C26: 3640 | D26: 7500 | E26: =C26*D26 -> 27300000
A27: Cần Tây | B27: Cây | C27: 0 | E27: =C27*D27 -> 0
A28: Cần Tây | B28: Kg | C28: 23 | D28: 10000 | E28: =C28*D28 -> 230000
A29: Cần Tây | B29: Túi | C29: 0 | E29: =C29*D29 -> 0
A30: Xà Lách Lolo Xanh T.C | B30: Kg | C30: 0 | E30: =C30*D30 -> 0
A31: Bí Đỏ Tròn | B31: Kg | C31: 1970 | D31: 5200 | E31: =C31*D31 -> 10244000
A32: Bí Ngòi Xanh | B32: Kg | C32: 157 | D32: 14000 | E32: =C32*D32 -> 2198000
A33: Bí Ngòi Xanh | B33: Trái | C33: 0 | E33: =C33*D33 -> 0
A34: Bí Non Nhật | B34: Kg | C34: 110 | D34: 14000 | E34: =C34*D34 -> 1540000
A35: Bí Non Nhật | B35: Trái | C35: 0 | E35: =C35*D35 -> 0
A36: Cà Chua Beef | B36: Kg | C36: 322 | D36: 25000 | E36: =C36*D36 -> 8050000
A37: Cà Chua Beef | B37: Vỉ | C37: 0 | E37: =C37*D37 -> 0
A38: Cà Chua Beef | B38: Vỉ 650gr | C38: 0 | E38: =C38*D38 -> 0
A39: Cà Chua Thường | B39: Kg | C39: 190 | D39: 19000 | E39: =C39*D39 -> 3610000
A40: Cà Chua Thường | B40: Vỉ | C40: 0 | E40: =C40*D40 -> 0
...

Sheet 13.11
A2: hàng tồn cuối ngày 13/11 vr
A3: Tên Sản phẩm | B3: ĐVT | C3: Tồn ĐL | D3: giá | E3: thành tiền
A4: Cà Rốt | B4: Kg | C4: 140 | D4: 15000 | E4: =C4*D4 -> 2100000
A5: Cà Rốt | B5: Túi | C5: 0 | E5: =C5*D5 -> 0
A6: Cà Rốt Baby | B6: Vỉ | C6: 0 | E6: =C6*D6 -> 0
A7: Củ Cải Đỏ | B7: Hộp | C7: 0 | E7: =C7*D7 -> 0
A8: Củ Cải Đỏ | B8: Kg | C8: 0 | E8: =C8*D8 -> 0
A9: Củ Dền | B9: Kg | C9: 85 | D9: 17000 | E9: =C9*D9 -> 1445000
A10: Củ Dền | B10: Túi | C10: 0 | E10: =C10*D10 -> 0
A11: Củ Hành Tây | B11: Kg | C11: 665 | D11: 22000 | E11: =C11*D11 -> 14630000
A12: Củ Hành Tây | B12: Túi 300gr | C12: 0 | E12: =C12*D12 -> 0
A13: Củ Hành Tây Trung | B13: Túi | C13: 1433.3333 | D13: 4500 | E13: =C13*D13 -> 6450000
A14: Củ Khoai Lang Mật Size 46 | B14: Kg | C14: 180 | D14: 21000 | E14: =C14*D14 -> 3780000
A15: Củ Khoai Lang Mật Size 46 | B15: Túi | C15: 0 | E15: =C15*D15 -> 0
A16: Củ Khoai Lang Nhật | B16: Kg | C16: 420 | D16: 19000 | E16: =C16*D16 -> 7980000
A17: Củ Khoai Lang Nhật | B17: Túi | C17: 0 | E17: =C17*D17 -> 0
A18: Củ Khoai Tây Vàng | B18: Kg | C18: 365 | D18: 15000 | E18: =C18*D18 -> 5475000
A19: Củ Khoai Tây Vàng | B19: Túi | C19: 0 | E19: =C19*D19 -> 0
A20: Bông Cải Xanh Baby | B20: Kg | C20: 0 | E20: =C20*D20 -> 0
A21: Bông Cải Xanh Baby | B21: Vỉ | C21: 0 | E21: =C21*D21 -> 0
A22: Bắp Cải Trắng | B22: Kg | C22: 488 | D22: 11000 | E22: =C22*D22 -> 5368000
A23: Cải Bó Xôi | B23: Kg | C23: 0 | E23: =C23*D23 -> 0
A24: Cải Bó Xôi | B24: Túi | C24: 25 | D24: 12000 | E24: =C24*D24 -> 300000
A25: Cải Kale | B25: Kg | C25: 0 | E25: =C25*D25 -> 0
A26: Cải Kale | B26: Túi | C26: 0 | E26: =C26*D26 -> 0
A27: Cải Kale | B27: Túi 150gr | C27: 0 | E27: =C27*D27 -> 0
A28: Cải Thảo | B28: Kg | C28: 5475 | D28: 7500 | E28: =C28*D28 -> 41062500
A29: Cần Tây | B29: Cây | C29: 0 | E29: =C29*D29 -> 0
A30: Cần Tây | B30: Kg | C30: 115 | D30: 10000 | E30: =C30*D30 -> 1150000
A31: Cần Tây | B31: Túi | C31: 0 | E31: =C31*D31 -> 0
A32: Xà Lách Lolo Xanh T.C | B32: Kg | C32: 0 | E32: =C32*D32 -> 0
A33: Bí Đỏ Tròn | B33: Kg | C33: 1560 | D33: 5200 | E33: =C33*D33 -> 8112000
A34: Bí Ngòi Xanh | B34: Kg | C34: 245 | D34: 14000 | E34: =C34*D34 -> 3430000
A35: Bí Ngòi Xanh | B35: Trái | C35: 0 | E35: =C35*D35 -> 0
A36: Bí Non Nhật | B36: Kg | C36: 90 | D36: 14000 | E36: =C36*D36 -> 1260000
A37: Bí Non Nhật | B37: Trái | C37: 0 | E37: =C37*D37 -> 0
A38: Cà Chua Beef | B38: Kg | C38: 245 | D38: 24000 | E38: =C38*D38 -> 5880000
A39: Cà Chua Beef | B39: Vỉ | C39: 0 | E39: =C39*D39 -> 0
A40: Cà Chua Beef | B40: Vỉ 650gr | C40: 0 | E40: =C40*D40 -> 0
A41: Cà Chua Thường | B41: Kg | C41: 337 | D41: 18000 | E41: =C41*D41 -> 6066000
...

Sheet 14.11
A2: hàng tồn cuối ngày 14/11 vr
A3: Tên Sản phẩm | B3: ĐVT | C3: Tồn ĐL | D3: giá | E3: thành tiền
A4: Cà Rốt | B4: Kg | C4: 18 | D4: 15000 | E4: =C4*D4 -> 270000
A5: Cà Rốt | B5: Túi | C5: 0 | E5: =C5*D5 -> 0
A6: Cà Rốt Baby | B6: Vỉ | C6: 0 | E6: =C6*D6 -> 0
A7: Củ Cải Đỏ | B7: Hộp | C7: 0 | E7: =C7*D7 -> 0
A8: Củ Cải Đỏ | B8: Kg | C8: 0 | E8: =C8*D8 -> 0
A9: Củ Dền | B9: Kg | C9: 25 | D9: 17000 | E9: =C9*D9 -> 425000
A10: Củ Dền | B10: Túi | C10: 0 | E10: =C10*D10 -> 0
A11: Củ Hành Tây | B11: Kg | C11: 480 | D11: 22000 | E11: =C11*D11 -> 10560000
A12: Củ Hành Tây | B12: Túi 300gr | C12: 0 | E12: =C12*D12 -> 0
A13: Củ Hành Tây Trung | B13: Túi | C13: 1337 | D13: 4500 | E13: =C13*D13 -> 6016500
A14: Củ Khoai Lang Mật Size 46 | B14: Kg | C14: 620 | D14: 23000 | E14: =C14*D14 -> 14260000
A15: Củ Khoai Lang Mật Size 46 | B15: Túi | C15: 0 | E15: =C15*D15 -> 0
A16: Củ Khoai Lang Nhật | B16: Kg | C16: 520 | D16: 19000 | E16: =C16*D16 -> 9880000
A17: Củ Khoai Tây Vàng | B17: Kg | C17: 265 | D17: 15000 | E17: =C17*D17 -> 3975000
A18: Củ Khoai Tây Vàng | B18: Túi | C18: 0 | E18: =C18*D18 -> 0
A19: Bông Cải Xanh Baby | B19: Kg | C19: 0 | E19: =C19*D19 -> 0
A20: Bông Cải Xanh Baby | B20: Vỉ | C20: 0 | E20: =C20*D20 -> 0
A21: Bắp Cải Trắng | B21: Kg | C21: 650 | D21: 11000 | E21: =C21*D21 -> 7150000
A22: Cải Bó Xôi | B22: Kg | C22: 0 | E22: =C22*D22 -> 0
A23: Cải Bó Xôi | B23: Túi | C23: 20 | D23: 12000 | E23: =C23*D23 -> 240000
A24: Cải Kale | B24: Kg | C24: 0 | E24: =C24*D24 -> 0
A25: Cải Kale | B25: Túi | C25: 0 | E25: =C25*D25 -> 0
A26: Cải Thảo | B26: Kg | C26: 3380 | D26: 7500 | E26: =C26*D26 -> 25350000
A27: Cần Tây | B27: Cây | C27: 0 | E27: =C27*D27 -> 0
A28: Cần Tây | B28: Kg | C28: 150 | D28: 10000 | E28: =C28*D28 -> 1500000
A29: Xà Lách Lolo Xanh T.C | B29: Kg | C29: 54 | D29: 28000 | E29: =C29*D29 -> 1512000
A30: Bí Đỏ Tròn | B30: Kg | C30: 900 | D30: 5200 | E30: =C30*D30 -> 4680000
A31: Bí Ngòi Xanh | B31: Kg | C31: 262 | D31: 11000 | E31: =C31*D31 -> 2882000
A32: Bí Ngòi Xanh | B32: Trái | C32: 0 | E32: =C32*D32 -> 0
A33: Bí Non Nhật | B33: Kg | C33: 383 | D33: 11000 | E33: =C33*D33 -> 4213000
A34: Bí Non Nhật | B34: Trái | C34: 0 | E34: =C34*D34 -> 0
A35: Cà Chua Beef | B35: Kg | C35: 230 | D35: 24000 | E35: =C35*D35 -> 5520000
A36: Cà Chua Beef | B36: Vỉ | C36: 0 | E36: =C36*D36 -> 0
A37: Cà Chua Beef | B37: Vỉ 650gr | C37: 0 | E37: =C37*D37 -> 0
A38: Cà Chua Thường | B38: Kg | C38: 750 | D38: 18000 | E38: =C38*D38 -> 13500000
A39: Cà Chua Thường | B39: Vỉ | C39: 0 | E39: =C39*D39 -> 0
A40: Cà Chua Thường Trung | B40: Túi | C40: 0 | E40: =C40*D40 -> 0
A41: Dưa Leo Baby | B41: Kg | C41: 0 | E41: =C41*D41 -> 0
...

Sheet 15.11
A1: Tên Sản phẩm | B1: ĐVT | C1: Tồn ĐL | D1: Giá | E1: Thành tiền
A2: Bắp Cải Tím | B2: Kg | C2: 66 | D2: =VLOOKUP(A2,'14.11'!A4:D129,4,) -> 30000 | E2: =+D2*C2 -> 1980000
A3: Bắp Cải Trái Tim | B3: Kg | C3: 128 | D3: =VLOOKUP(A3,'14.11'!A5:D130,4,) -> 15000 | E3: =+D3*C3 -> 1920000
A4: Bắp Cải Trắng | B4: Kg | C4: 477 | D4: =VLOOKUP(A4,'14.11'!A6:D131,4,) -> 11000 | E4: =+D4*C4 -> 5247000
A5: Bí Đao Xanh | B5: Kg | C5: 0
A6: Bí Đao Xanh | B6: Trái | C6: 0
A7: Bí Đỏ Hồ Lô | B7: Kg | C7: 0
A8: Bí Đỏ Tròn | B8: Kg | C8: 0
A9: Bí Ngô Mini | B9: Kg | C9: 0
A10: Bí Ngòi Vàng | B10: Kg | C10: 0
A11: Bí Ngòi Xanh | B11: Kg | C11: 117 | D11: =VLOOKUP(A11,'14.11'!A13:D138,4,) -> 11000 | E11: =+D11*C11 -> 1287000
A12: Bí Ngòi Xanh | B12: Trái | C12: 0
A13: Bí Non Nhật | B13: Kg | C13: 0
A14: Bí Non Nhật | B14: Trái | C14: 0
A15: Bơ Booth | B15: Kg | C15: 0
A16: Bông Cải Trắng | B16: Kg | C16: 25 | D16: 40000 | E16: =+D16*C16 -> 1000000
A17: Bông Cải Xanh 10Cm | B17: Kg | C17: 0
A18: Bông Cải Xanh 7Cm | B18: Kg | C18: 0
A19: Bông Cải Xanh Baby | B19: Kg | C19: 0
A20: Bông Cải Xanh Baby | B20: Vỉ | C20: 0
A21: Cà Chua Beef | B21: Kg | C21: 46 | D21: =VLOOKUP(A21,'14.11'!A23:D148,4,) -> 24000 | E21: =+D21*C21 -> 1104000
A22: Cà Chua Beef | B22: Vỉ | C22: 0
A23: Cà Chua Beef | B23: Vỉ 650gr | C23: 42 | D23: =VLOOKUP(A23,'14.11'!A25:D150,4,) -> 24000 | E23: =+D23*C23 -> 1008000
A24: Cà Chua Beef Trung | B24: Kg | C24: 0
A25: Cà Chua Beef Trung | B25: Vỉ 500gr | C25: 0
A26: Cà Chua Bi Đỏ | B26: Kg | C26: 30 | D26: =VLOOKUP(A26,'14.11'!A28:D153,4,) -> 33000 | E26: =+D26*C26 -> 990000
A27: Cà Chua Bi Đỏ | B27: Hộp 300gr | C27: 79 | D27: =VLOOKUP(A27,'14.11'!A29:D154,4,) -> 33000 | E27: =+D27*C27 -> 2607000
A28: Cà Chua Bi Mix | B28: Hộp | C28: 9 | D28: =VLOOKUP(A28,'14.11'!A30:D155,4,) -> 17000 | E28: =+D28*C28 -> 153000
A29: Cà Chua Bi Mix | B29: Kg | C29: 0
A30: Cà Chua Socola | B30: Kg | C30: 13.5 | D30: =VLOOKUP(A30,'14.11'!A32:D157,4,) -> 45000 | E30: =+D30*C30 -> 607500
A31: Cà Chua Socola | B31: Hộp 300gr | C31: 0
A32: Cà Chua Socola | B32: Hộp 250GR | C32: 0
A33: Cà Chua Thường | B33: Kg | C33: 342 | D33: =VLOOKUP(A33,'14.11'!A35:D160,4,) -> 18000 | E33: =+D33*C33 -> 6156000
A34: Cà Chua Thường | B34: Vỉ | C34: 0
A35: Cà Chua Thường Trung | B35: Túi | C35: 200 | D35: 16000 | E35: =+D35*C35 -> 3200000
A36: Cà Rốt | B36: Kg | C36: 144 | D36: 15000 | E36: =+D36*C36 -> 2160000
A37: Cà Rốt | B37: Túi | C37: 0
A38: Cà Rốt Baby | B38: Kg | C38: 0
A39: Cà Rốt Baby | B39: Vỉ | C39: 0
A40: Cà Tím | B40: Kg | C40: 60 | D40: =VLOOKUP(A40,'14.11'!A42:D167,4,) -> 9000 | E40: =+D40*C40 -> 540000
...

Sheet 16.11
A1: hàng tồn cuối ngày 16/11
A2: Tên Sản phẩm | B2: ĐVT | C2: Tồn ĐL | D2: giá | E2: thành tiền
A3: Bắp Cải Tím | B3: Kg | C3: 12 | D3: 30000 | E3: =C3*D3 -> 360000
A4: Bắp Cải Trái Tim | B4: Kg | C4: 0 | E4: =C4*D4 -> 0
A5: Bắp Cải Trắng | B5: Kg | C5: 370 | D5: 11000 | E5: =C5*D5 -> 4070000
A6: Bí Đao Xanh | B6: Trái | C6: 0 | E6: =C6*D6 -> 0
A7: Bí Đỏ Hồ Lô | B7: Kg | C7: 0 | E7: =C7*D7 -> 0
A8: Bí Đỏ Tròn | B8: Kg | C8: 960 | D8: 5200 | E8: =C8*D8 -> 4992000
A9: Bí Ngô Mini | B9: Kg | C9: 0 | E9: =C9*D9 -> 0
A10: Bí Ngòi Xanh | B10: Kg | C10: 110 | D10: 11000 | E10: =C10*D10 -> 1210000
A11: Bí Ngòi Xanh | B11: Trái | C11: 0 | E11: =C11*D11 -> 0
A12: Bí Non Nhật | B12: Kg | C12: 50 | D12: 12000 | E12: =C12*D12 -> 600000
A13: Bí Non Nhật | B13: Trái | C13: 0 | E13: =C13*D13 -> 0
A14: Bơ Booth | B14: Kg | C14: 0 | E14: =C14*D14 -> 0
A15: Bông Cải Trắng | B15: Kg | C15: 0 | E15: =C15*D15 -> 0
A16: Bông Cải Xanh 10Cm | B16: Kg | C16: 0 | E16: =C16*D16 -> 0
A17: Bông Cải Xanh 7Cm | B17: Kg | C17: 0 | E17: =C17*D17 -> 0
A18: Bông Cải Xanh Baby | B18: Vỉ | C18: 0 | E18: =C18*D18 -> 0
A19: Cà Chua Beef | B19: Kg | C19: 242 | D19: 24000 | E19: =C19*D19 -> 5808000
A20: Cà Chua Beef | B20: Vỉ | C20: 0 | E20: =C20*D20 -> 0
A21: Cà Chua Beef | B21: Vỉ 650gr | C21: 0 | E21: =C21*D21 -> 0
A22: Cà Chua Beef 500Gr | B22: Vỉ | C22: 0 | E22: =C22*D22 -> 0
A23: Cà Chua Beef Trung | B23: Kg | C23: 0 | E23: =C23*D23 -> 0
A24: Cà Chua Beef Trung | B24: Vỉ 500gr | C24: 80 | D24: 10500 | E24: =C24*D24 -> 840000
A25: Cà Chua Bi Đỏ | B25: Kg | C25: 30 | D25: 33000 | E25: =C25*D25 -> 990000
A26: Cà Chua Bi Đỏ | B26: Hộp 300gr | C26: 110 | D26: 9900 | E26: =C26*D26 -> 1089000
A27: Cà Chua Bi Mix | B27: Hộp | C27: 0 | E27: =C27*D27 -> 0
A28: Cà Chua Socola | B28: Kg | C28: 11 | D28: 44000 | E28: =C28*D28 -> 484000
A29: Cà Chua Socola | B29: Hộp 300gr | C29: 0 | E29: =C29*D29 -> 0
A30: Cà Chua Socola | B30: Hộp 250GR | C30: 0 | E30: =C30*D30 -> 0
A31: Cà Chua Thường | B31: Kg | C31: 280 | D31: 18000 | E31: =C31*D31 -> 5040000
A32: Cà Chua Thường | B32: Vỉ | C32: 0 | E32: =C32*D32 -> 0
A33: Cà Chua Thường Trung | B33: Túi | C33: 60 | D33: 15000 | E33: =C33*D33 -> 900000
A34: Cà Rốt | B34: Kg | C34: 240 | D34: 15000 | E34: =C34*D34 -> 3600000
A35: Cà Rốt | B35: Túi | C35: 0 | E35: =C35*D35 -> 0
A36: Cà Rốt Baby | B36: Vỉ | C36: 0 | E36: =C36*D36 -> 0
A37: Cà Tím | B37: Kg | C37: 130 | D37: 10000 | E37: =C37*D37 -> 1300000
A38: Cà Tím | B38: Cặp | C38: 0 | E38: =C38*D38 -> 0
A39: Cải Bó Xôi | B39: Kg | C39: 0 | E39: =C39*D39 -> 0
A40: Cải Bó Xôi | B40: Túi | C40: 0 | E40: =C40*D40 -> 0
...

Sheet 17.11
A1: hàng tồn cuối ngày 17/11 vr
A2: Tên Sản phẩm | B2: ĐVT | C2: Tồn ĐL | D2: giá | E2: thành tiền
A3: Bắp Cải Tím | B3: Kg | C3: 56 | D3: 30000 | E3: =C3*D3 -> 1680000
A4: Bắp Cải Trái Tim | B4: Kg | C4: 115 | D4: 17000 | E4: =C4*D4 -> 1955000
A5: Bắp Cải Trắng | B5: Kg | C5: 949 | D5: 11000 | E5: =C5*D5 -> 10439000
A6: Bí Đao Xanh | B6: Kg | C6: 0 | E6: =C6*D6 -> 0
A7: Bí Đao Xanh | B7: Trái | C7: 0 | E7: =C7*D7 -> 0
A8: Bí Đỏ Hồ Lô | B8: Kg | C8: 10 | D8: 13000 | E8: =C8*D8 -> 130000
A9: Bí Đỏ Tròn | B9: Kg | C9: 530 | D9: 5300 | E9: =C9*D9 -> 2809000
A10: Bí Ngòi Vàng | B10: Kg | C10: 0 | E10: =C10*D10 -> 0
A11: Bí Ngòi Xanh | B11: Kg | C11: 150 | D11: 10000 | E11: =C11*D11 -> 1500000
A12: Bí Ngòi Xanh | B12: Trái | C12: 0 | E12: =C12*D12 -> 0
A13: Bí Non Nhật | B13: Kg | C13: 143 | D13: 11000 | E13: =C13*D13 -> 1573000
A14: Bí Non Nhật | B14: Trái | C14: 0 | E14: =C14*D14 -> 0
A15: Bơ Booth | B15: Kg | C15: 0 | E15: =C15*D15 -> 0
A16: Bông Cải Trắng | B16: Kg | C16: 0 | E16: =C16*D16 -> 0
A17: Bông Cải Xanh 10Cm | B17: Kg | C17: 12 | D17: 33000 | E17: =C17*D17 -> 396000
A18: Bông Cải Xanh 7Cm | B18: Kg | C18: 0 | E18: =C18*D18 -> 0
A19: Bông Cải Xanh Baby | B19: Kg | C19: 0 | E19: =C19*D19 -> 0
A20: Bông Cải Xanh Baby | B20: Vỉ | C20: 0 | E20: =C20*D20 -> 0
A21: Cà Chua Beef | B21: Kg | C21: 773 | D21: 24000 | E21: =C21*D21 -> 18552000
A22: Cà Chua Beef | B22: Vỉ | C22: 0 | E22: =C22*D22 -> 0
A23: Cà Chua Beef | B23: Vỉ 650gr | C23: 0 | E23: =C23*D23 -> 0
A24: Cà Chua Beef Trung | B24: Kg | C24: 0 | E24: =C24*D24 -> 0
A25: Cà Chua Beef Trung | B25: Vỉ 500gr | C25: 114 | D25: 10500 | E25: =C25*D25 -> 1197000
A26: Cà Chua Bi Đỏ | B26: Hộp 500gr | C26: 19 | D26: 16500 | E26: =C26*D26 -> 313500
A27: Cà Chua Bi Đỏ | B27: Hộp 300gr | C27: 87 | D27: 9900 | E27: =C27*D27 -> 861300
A28: Cà Chua Bi Mix | B28: Hộp | C28: 10 | D28: 15000 | E28: =C28*D28 -> 150000
A29: Cà Chua Socola | B29: Kg | C29: 10.5 | D29: 34000 | E29: =C29*D29 -> 357000
A30: Cà Chua Socola | B30: Hộp 300gr | C30: 0 | E30: =C30*D30 -> 0
A31: Cà Chua Socola | B31: Hộp 250GR | C31: 0 | E31: =C31*D31 -> 0
A32: Cà Chua Thường | B32: Kg | C32: 620 | D32: 15500 | E32: =C32*D32 -> 9610000
A33: Cà Chua Thường | B33: Vỉ | C33: 0 | E33: =C33*D33 -> 0
A34: Cà Chua Thường Trung | B34: Túi | C34: 0 | E34: =C34*D34 -> 0
A35: Cà Rốt | B35: Kg | C35: 20 | D35: 15000 | E35: =C35*D35 -> 300000
A36: Cà Rốt | B36: Túi | C36: 0 | E36: =C36*D36 -> 0
A37: Cà Rốt Baby | B37: Kg | C37: 0 | E37: =C37*D37 -> 0
A38: Cà Rốt Baby | B38: Vỉ | C38: 0 | E38: =C38*D38 -> 0
A39: Cà Rốt Trung | B39: Kg | C39: 0 | E39: =C39*D39 -> 0
A40: Cà Tím | B40: Kg | C40: 118 | D40: 10000 | E40: =C40*D40 -> 1180000
...

Sheet 18.11
A2: hàng tồn cuối ngày 18/11 vr
A3: Tên Sản phẩm | B3: ĐVT | C3: Tồn ĐL | D3: giá | E3: thành tiền
A4: Cà Rốt | B4: Kg | C4: 390 | D4: 14000 | E4: =C4*D4 -> 5460000
A5: Cà Rốt | B5: Túi | C5: 0 | E5: =C5*D5 -> 0
A6: Cà Rốt Baby | B6: Vỉ | C6: 4 | D6: 11000 | E6: =C6*D6 -> 44000
A7: Củ Cải Đỏ | B7: Hộp | C7: 0 | E7: =C7*D7 -> 0
A8: Củ Dền | B8: Kg | C8: 78 | D8: 18000 | E8: =C8*D8 -> 1404000
A9: Củ Dền | B9: Túi | C9: 0 | E9: =C9*D9 -> 0
A10: Củ Hành Tây | B10: Kg | C10: 20 | D10: 21000 | E10: =C10*D10 -> 420000
A11: Củ Hành Tây | B11: Túi 300gr | C11: 0 | E11: =C11*D11 -> 0
A12: Củ Hành Tây Trung | B12: Túi | C12: 1387 | D12: 4500 | E12: =C12*D12 -> 6241500
A13: Củ Khoai Lang Mật Size 46 | B13: Kg | C13: 759 | D13: 25000 | E13: =C13*D13 -> 18975000
A14: Củ Khoai Lang Nhật | B14: Kg | C14: 160 | D14: 19000 | E14: =C14*D14 -> 3040000
A15: Củ Khoai Tây Vàng | B15: Kg | C15: 250 | D15: 15000 | E15: =C15*D15 -> 3750000
A16: Củ Khoai Tây Vàng | B16: Túi | C16: 0 | E16: =C16*D16 -> 0
A17: Bông Cải Xanh Baby | B17: Vỉ | C17: 0 | E17: =C17*D17 -> 0
A18: Bắp Cải Trắng | B18: Kg | C18: 404 | D18: 13500 | E18: =C18*D18 -> 5454000
A19: Cải Bó Xôi | B19: Kg | C19: 0 | E19: =C19*D19 -> 0
A20: Cải Bó Xôi | B20: Túi | C20: 0 | E20: =C20*D20 -> 0
A21: Cải Kale | B21: Túi | C21: 0 | E21: =C21*D21 -> 0
A22: Cải Thảo | B22: Kg | C22: 850 | D22: 7500 | E22: =C22*D22 -> 6375000
A23: Cần Tây | B23: Cây | C23: 0 | E23: =C23*D23 -> 0
A24: Cần Tây | B24: Kg | C24: 188 | D24: 14000 | E24: =C24*D24 -> 2632000
A25: Xà Lách Lolo Xanh T.C | B25: Kg | C25: 70 | D25: 28000 | E25: =C25*D25 -> 1960000
A26: Bí Đỏ Tròn | B26: Kg | C26: 260 | D26: 5300 | E26: =C26*D26 -> 1378000
A27: Bí Ngòi Xanh | B27: Kg | C27: 300 | D27: 10000 | E27: =C27*D27 -> 3000000
A28: Bí Ngòi Xanh | B28: Trái | C28: 0 | E28: =C28*D28 -> 0
A29: Bí Non Nhật | B29: Kg | C29: 51 | D29: 10000 | E29: =C29*D29 -> 510000
A30: Bí Non Nhật | B30: Trái | C30: 0 | E30: =C30*D30 -> 0
A31: Cà Chua Beef | B31: Kg | C31: 127 | D31: 21000 | E31: =C31*D31 -> 2667000
A32: Cà Chua Beef | B32: Vỉ 650gr | C32: 0 | E32: =C32*D32 -> 0
A33: Cà Chua Thường | B33: Kg | C33: 520 | D33: 15500 | E33: =C33*D33 -> 8060000
A34: Cà Chua Thường | B34: Vỉ | C34: 0 | E34: =C34*D34 -> 0
A35: Cà Chua Thường Trung | B35: Túi | C35: 60 | D35: 12000 | E35: =C35*D35 -> 720000
A36: Dưa Leo Baby | B36: Kg | C36: 0 | E36: =C36*D36 -> 0
A37: Dưa Leo Baby | B37: Vỉ | C37: 892 | D37: 5000 | E37: =C37*D37 -> 4460000
A38: Dưa Leo Thường | B38: Kg | C38: 18 | D38: 5000 | E38: =C38*D38 -> 90000
A39: Ớt Chuông Đỏ | B39: Kg | C39: 10 | D39: 37000 | E39: =C39*D39 -> 370000
A40: Ớt Chuông Đỏ | B40: Trái | C40: 0 | E40: =C40*D40 -> 0
A41: Ớt Chuông Vàng | B41: Kg | C41: 83 | D41: 16000 | E41: =C41*D41 -> 1328000
...

Sheet 19.11
A2: hàng tồn cuối ngày 19/11 vr
A3: Tên Sản phẩm | B3: ĐVT | C3: Tồn ĐL | D3: giá nhập | E3: thành tiền
A4: Cà Rốt | B4: Kg | C4: 230 | D4: 14000 | E4: =C4*D4 -> 3220000
A5: Cà Rốt | B5: Túi | C5: 0 | E5: =C5*D5 -> 0
A6: Cà Rốt Baby | B6: Kg | E6: =C6*D6 -> 0
A7: Cà Rốt Baby | B7: Vỉ | C7: 24 | D7: 11000 | E7: =C7*D7 -> 264000
A8: Củ Cải Đỏ | B8: Hộp | C8: 0 | E8: =C8*D8 -> 0
A9: Củ Cải Đỏ | B9: Kg | C9: 0 | E9: =C9*D9 -> 0
A10: Củ Dền | B10: Kg | C10: 30 | D10: 18000 | E10: =C10*D10 -> 540000
A11: Củ Dền | B11: Túi | C11: 0 | E11: =C11*D11 -> 0
A12: Củ Hành Tây | B12: Kg | C12: 1615 | D12: 22000 | E12: =C12*D12 -> 35530000
A13: Củ Hành Tây | B13: Túi 300gr | C13: 0 | E13: =C13*D13 -> 0
A14: Củ Hành Tây Trung | B14: Túi | C14: 1347 | D14: 4500 | E14: =C14*D14 -> 6061500
A15: Củ Khoai Lang Mật Size 46 | B15: Kg | C15: 729 | D15: 25000 | E15: =C15*D15 -> 18225000
A16: Củ Khoai Lang Mật Size 46 | B16: Túi | C16: 0 | E16: =C16*D16 -> 0
A17: Củ Khoai Lang Nhật | B17: Kg | C17: 120 | D17: 18000 | E17: =C17*D17 -> 2160000
A18: Củ Khoai Tây Vàng | B18: Kg | C18: 245 | D18: 15000 | E18: =C18*D18 -> 3675000
A19: Củ Khoai Tây Vàng | B19: Túi | C19: 0 | E19: =C19*D19 -> 0
A20: Bông Cải Xanh Baby | B20: Vỉ | C20: 0 | E20: =C20*D20 -> 0
A21: Bắp Cải Trắng | B21: Kg | C21: 442 | D21: 13500 | E21: =C21*D21 -> 5967000
A22: Cải Bó Xôi | B22: Kg | C22: 0 | E22: =C22*D22 -> 0
A23: Cải Bó Xôi | B23: Túi | C23: 9 | D23: 12000 | E23: =C23*D23 -> 108000
A24: Cải Kale | B24: Kg | C24: 0 | E24: =C24*D24 -> 0
A25: Cải Kale | B25: Túi | C25: 4 | D25: 10000 | E25: =C25*D25 -> 40000
A26: Cải Thảo | B26: Kg | C26: 660 | D26: 5000 | E26: =C26*D26 -> 3300000
A27: Cần Tây | B27: Cây | C27: 0 | E27: =C27*D27 -> 0
A28: Cần Tây | B28: Kg | C28: 0 | E28: =C28*D28 -> 0
A29: Xà Lách Lolo Xanh T.C | B29: Kg | C29: 0 | E29: =C29*D29 -> 0
A30: Bí Đỏ Tròn | B30: Kg | C30: 200 | D30: 5000 | E30: =C30*D30 -> 1000000
A31: Bí Ngòi Xanh | B31: Kg | C31: 22 | D31: 10000 | E31: =C31*D31 -> 220000
A32: Bí Ngòi Xanh | B32: Trái | C32: 0 | E32: =C32*D32 -> 0
A33: Bí Ngòi Xanh | B33: Trái 250gr | C33: 0 | E33: =C33*D33 -> 0
A34: Bí Non Nhật | B34: Kg | C34: 38 | D34: 10000 | E34: =C34*D34 -> 380000
A35: Bí Non Nhật | B35: Trái | C35: 0 | E35: =C35*D35 -> 0
A36: Cà Chua Beef | B36: Kg | C36: 140 | D36: 21000 | E36: =C36*D36 -> 2940000
A37: Cà Chua Beef | B37: Vỉ | C37: 0 | E37: =C37*D37 -> 0
A38: Cà Chua Beef | B38: Vỉ 650gr | C38: 0 | E38: =C38*D38 -> 0
A39: Cà Chua Thường | B39: Kg | C39: 175 | D39: 16000 | E39: =C39*D39 -> 2800000
A40: Cà Chua Thường | B40: Vỉ | C40: 0 | E40: =C40*D40 -> 0
A41: Cà Chua Thường Trung | B41: Túi | C41: 160 | D41: 11000 | E41: =C41*D41 -> 1760000
...

Sheet 20.11
A2: hàng tồn cuối ngày 20/11 vr
A3: Tên Sản phẩm | B3: ĐVT | C3: Tồn ĐL | D3: giá | E3: thành tiền
A4: Cà Rốt | B4: Kg | C4: 225 | D4: 14000 | E4: =C4*D4 -> 3150000
A5: Cà Rốt | B5: Túi | C5: 0 | E5: =C5*D5 -> 0
A6: Cà Rốt Baby | B6: Vỉ | C6: 8 | D6: 11000 | E6: =C6*D6 -> 88000
A7: Củ Cải Đỏ | B7: Hộp | C7: 0 | E7: =C7*D7 -> 0
A8: Củ Cải Đỏ | B8: Kg | C8: 0 | E8: =C8*D8 -> 0
A9: Củ Dền | B9: Kg | C9: 33 | D9: 18000 | E9: =C9*D9 -> 594000
A10: Củ Dền | B10: Túi | C10: 0 | E10: =C10*D10 -> 0
A11: Củ Hành Tây | B11: Kg | C11: 1326 | D11: 22000 | E11: =C11*D11 -> 29172000
A12: Củ Hành Tây | B12: Túi 300gr | C12: 0 | E12: =C12*D12 -> 0
A13: Củ Hành Tây Trung | B13: Túi | C13: 2220 | D13: 4500 | E13: =C13*D13 -> 9990000
A14: Củ Khoai Lang Mật Size 46 | B14: Kg | C14: 671 | D14: 25000 | E14: =C14*D14 -> 16775000
A15: Củ Khoai Lang Mật Size 46 | B15: Túi | C15: 0 | E15: =C15*D15 -> 0
A16: Củ Khoai Lang Nhật | B16: Kg | C16: 50 | D16: 17500 | E16: =C16*D16 -> 875000
A17: Củ Khoai Tây Vàng | B17: Kg | C17: 260 | D17: 15000 | E17: =C17*D17 -> 3900000
A18: Củ Khoai Tây Vàng | B18: Túi | C18: 0 | E18: =C18*D18 -> 0
A19: Bông Cải Xanh Baby | B19: Vỉ | C19: 0 | E19: =C19*D19 -> 0
A20: Bắp Cải Trắng | B20: Kg | C20: 408 | D20: 13500 | E20: =C20*D20 -> 5508000
A21: Cải Bó Xôi | B21: Kg | C21: 0 | E21: =C21*D21 -> 0
A22: Cải Bó Xôi | B22: Túi | C22: 45 | D22: 10000 | E22: =C22*D22 -> 450000
A23: Cải Kale | B23: Túi | C23: 0 | E23: =C23*D23 -> 0
A24: Cải Thảo | B24: Kg | C24: 0 | E24: =C24*D24 -> 0
A25: Cần Tây | B25: Cây | C25: 0 | E25: =C25*D25 -> 0
A26: Cần Tây | B26: Kg | C26: 50 | D26: 14000 | E26: =C26*D26 -> 700000
A27: Xà Lách Lolo Xanh T.C | B27: Kg | C27: 43 | D27: 28000 | E27: =C27*D27 -> 1204000
A28: Bí Đỏ Tròn | B28: Kg | C28: 270 | D28: 5000 | E28: =C28*D28 -> 1350000
A29: Bí Ngòi Xanh | B29: Kg | C29: 0 | E29: =C29*D29 -> 0
A30: Bí Ngòi Xanh | B30: Trái | C30: 0 | E30: =C30*D30 -> 0
A31: Bí Ngòi Xanh | B31: Trái 250gr | C31: 0 | E31: =C31*D31 -> 0
A32: Bí Non Nhật | B32: Kg | C32: 90 | D32: 10000 | E32: =C32*D32 -> 900000
A33: Bí Non Nhật | B33: Trái | C33: 0 | E33: =C33*D33 -> 0
A34: Cà Chua Beef | B34: Kg | C34: 0 | E34: =C34*D34 -> 0
A35: Cà Chua Beef | B35: Vỉ | C35: 0 | E35: =C35*D35 -> 0
A36: Cà Chua Beef | B36: Vỉ 650gr | C36: 0 | E36: =C36*D36 -> 0
A37: Cà Chua Thường | B37: Kg | C37: 0 | E37: =C37*D37 -> 0
A38: Cà Chua Thường | B38: Vỉ | C38: 0 | E38: =C38*D38 -> 0
A39: Cà Chua Thường Trung | B39: Túi | C39: 50 | D39: 11000 | E39: =C39*D39 -> 550000
A40: Dưa Leo Baby | B40: Kg | C40: 55 | D40: 6000 | E40: =C40*D40 -> 330000
A41: Dưa Leo Baby | B41: Vỉ | C41: 85 | D41: 5000 | E41: =C41*D41 -> 425000
...

Sheet 21.11
A2: hàng tồn cuối ngày 21/11 vr
A3: Tên Sản phẩm | B3: ĐVT | C3: Tồn ĐL | D3: giá | E3: thành tiền
A4: Cà Rốt | B4: Kg | C4: 49 | D4: 14000 | E4: =C4*D4 -> 686000
A5: Cà Rốt Baby | B5: Vỉ | C5: 20 | D5: 10000 | E5: =C5*D5 -> 200000
A6: Củ Cải Đỏ | B6: Hộp | C6: 50 | D6: 13000 | E6: =C6*D6 -> 650000
A7: Củ Dền | B7: Kg | C7: 75 | D7: 18000 | E7: =C7*D7 -> 1350000
A8: Củ Hành Tây | B8: Kg | C8: 706 | D8: 22000 | E8: =C8*D8 -> 15532000
A9: Củ Hành Tây Trung | B9: Túi | C9: 2147 | D9: 4500 | E9: =C9*D9 -> 9661500
A10: Củ Khoai Lang Mật Size 46 | B10: Kg | C10: 521 | D10: 25000 | E10: =C10*D10 -> 13025000
A11: Củ Khoai Lang Nhật | B11: Kg | C11: 150 | D11: 25000 | E11: =C11*D11 -> 3750000
A12: Củ Khoai Tây Vàng | B12: Kg | C12: 55 | D12: 15000 | E12: =C12*D12 -> 825000
A13: Bông Cải Xanh Baby | B13: Vỉ | C13: 10 | D13: 11400 | E13: =C13*D13 -> 114000
A14: Bắp Cải Trắng | B14: Kg | C14: 680 | D14: 13500 | E14: =C14*D14 -> 9180000
A15: Cải Bó Xôi | B15: Kg | C15: 15 | D15: 28000 | E15: =C15*D15 -> 420000
... A58: Hồng Treo Gió | B58: Túi | C58: 49 | D58: 100000 | E58: =C58*D58 -> 4900000
A59: Hạt Dẻ Tươi | B59: Kg | C59: =103+1000 -> 1103 | D59: 28600 | E59: =C59*D59 -> 31545800 | F59: đi đường
A60: Ớt Chuông Đỏ Trung | B60: Kg | C60: 20 | D60: 32000 | E60: =C60*D60 -> 640000
A61: Ớt Chuông Vàng Trung | B61: Kg | C61: 20 | D61: 13000 | E61: =C61*D61 -> 260000
A62: Ớt Chuông Xanh Trung | B62: Kg | C62: 10 | D62: 21000 | E62: =C62*D62 -> 210000
E63: =SUM(E4:E62) -> 153470200
A64: kq
A65: Tên Sản phẩm | B65: ĐVT | C65: Tồn ĐL | D65: giá | E65: thành tiền
A66: Củ Cải Trắng | B66: Kg | C66: 200 | D66: 6500 | E66: =C66*D66 -> 1300000
A67: Củ Dền | B67: Kg | C67: 40 | D67: 18000 | E67: =C67*D67 -> 720000
A68: Củ Hành Tây | B68: Kg | C68: 250 | D68: 22000 | E68: =C68*D68 -> 5500000
A69: Củ Khoai Tây Vàng | B69: Kg | C69: 250 | D69: 15000 | E69: =C69*D69 -> 3750000
A70: Bông Cải Xanh Cọng | B70: Kg | C70: 48 | D70: 28000 | E70: =C70*D70 -> 1344000
A71: Bắp Cải Trái Tim | B71: Kg | C71: 150 | D71: 17000 | E71: =C71*D71 -> 2550000
A72: Bắp Cải Trắng | B72: Kg | C72: 256 | D72: 13500 | E72: =C72*D72 -> 3456000
A73: Cần Tây | B73: Kg | C73: 100 | D73: 10000 | E73: =C73*D73 -> 1000000
A74: Bí Đao Xanh | B74: Kg | C74: 70 | D74: 7500 | E74: =C74*D74 -> 525000
A75: Bí Đỏ Tròn | B75: Kg | C75: 600 | D75: 5000 | E75: =C75*D75 -> 3000000
A76: Bí Ngòi Xanh | B76: Kg | C76: 75 | D76: 10000 | E76: =C76*D76 -> 750000
A77: Cà Chua Beef | B77: Kg | C77: 300 | D77: 21000 | E77: =C77*D77 -> 6300000
... A91: cải thảo kim chi | B91: kg | C91: 100 | D91: 5000 | E91: =C91*D91 -> 500000
E92: =SUM(E66:E91) -> 42716000
E93: =E63+E92 -> 196186200

Sheet 22.11
A2: hàng tồn cuối ngày 22/11 vr
A3: Tên Sản phẩm | B3: ĐVT | C3: tồn | D3: giá | E3: thành tiền
A4: Cà Rốt | B4: Kg | C4: 350 | D4: 14000 | E4: =C4*D4 -> 4900000
A5: Cà Rốt | B5: Túi | C5: 0 | E5: =C5*D5 -> 0
A6: Cà Rốt Baby | B6: Vỉ | C6: 7 | D6: 10000 | E6: =C6*D6 -> 70000
A7: Củ Cải Đỏ | B7: Hộp | C7: 0 | E7: =C7*D7 -> 0
A8: Củ Cải Đỏ | B8: Hộp 300gr | C8: 42 | D8: 13000 | E8: =C8*D8 -> 546000
A9: Củ Dền | B9: Kg | C9: 0 | E9: =C9*D9 -> 0
A10: Củ Dền | B10: Túi | C10: 0 | E10: =C10*D10 -> 0
A11: Củ Hành Tây | B11: Kg | C11: 543 | D11: 22000 | E11: =C11*D11 -> 11946000
A12: Củ Hành Tây | B12: Túi 300gr | C12: 0 | E12: =C12*D12 -> 0
A13: Củ Hành Tây Trung | B13: Túi | C13: 2004 | D13: 4500 | E13: =C13*D13 -> 9018000
A14: Củ Khoai Lang Mật Size 46 | B14: Kg | C14: 805 | D14: 25000 | E14: =C14*D14 -> 20125000
A15: Củ Khoai Lang Mật Size 46 | B15: Túi | C15: 0 | E15: =C15*D15 -> 0
A16: Củ Khoai Lang Nhật | B16: Kg | C16: 270 | D16: 17500 | E16: =C16*D16 -> 4725000
A17: Củ Khoai Tây Vàng | B17: Kg | C17: 180 | D17: 15000 | E17: =C17*D17 -> 2700000
A18: Củ Khoai Tây Vàng | B18: Túi | C18: 0 | E18: =C18*D18 -> 0
A19: Bông Cải Xanh Baby | B19: Vỉ | C19: 21 | D19: 11400 | E19: =C19*D19 -> 239400
A20: Bắp Cải Trắng | B20: Kg | C20: 339 | D20: 13500 | E20: =C20*D20 -> 4576500
A21: Cải Bó Xôi | B21: Kg | C21: 32 | D21: 22000 | E21: =C21*D21 -> 704000
A22: Cải Bó Xôi | B22: Túi | C22: 6 | D22: 9000 | E22: =C22*D22 -> 54000
A23: Cải Kale | B23: Túi | C23: 25 | D23: 9000 | E23: =C23*D23 -> 225000
A24: Cải Thảo | B24: Kg | C24: 240 | D24: 7000 | E24: =C24*D24 -> 1680000
A25: Cần Tây | B25: Cây | C25: 0 | E25: =C25*D25 -> 0
A26: Cần Tây | B26: Kg | C26: 135 | D26: 17000 | E26: =C26*D26 -> 2295000
A27: Xà Lách Lolo Xanh T.C | B27: Kg | C27: 0 | E27: =C27*D27 -> 0
A28: Bí Đỏ Tròn | B28: Kg | C28: 0 | E28: =C28*D28 -> 0
A29: Bí Ngòi Xanh | B29: Kg | C29: 90 | D29: 10000 | E29: =C29*D29 -> 900000
A30: Bí Ngòi Xanh | B30: Trái | C30: 0 | E30: =C30*D30 -> 0
A31: Bí Non Nhật | B31: Kg | C31: 0 | E31: =C31*D31 -> 0
A32: Bí Non Nhật | B32: Trái | C32: 0 | E32: =C32*D32 -> 0
A33: Cà Chua Beef | B33: Kg | C33: 300 | D33: 19000 | E33: =C33*D33 -> 5700000
A34: Cà Chua Beef | B34: Vỉ | C34: 0 | E34: =C34*D34 -> 0
A35: Cà Chua Beef | B35: Vỉ 650gr | C35: 0 | E35: =C35*D35 -> 0
A36: Cà Chua Thường | B36: Kg | C36: 200 | D36: 17000 | E36: =C36*D36 -> 3400000
A37: Cà Chua Thường | B37: Vỉ | C37: 0 | E37: =C37*D37 -> 0
A38: Cà Chua Thường Trung | B38: Túi | C38: 80 | D38: 11000 | E38: =C38*D38 -> 880000
A39: Dưa Leo Baby | B39: Kg | C39: 45 | D39: 6000 | E39: =C39*D39 -> 270000
A40: Dưa Leo Baby | B40: Vỉ | C40: 367 | D40: 5000 | E40: =C40*D40 -> 1835000
A41: Dưa Leo Thường | B41: Kg | C41: 18 | D41: 5000 | E41: =C41*D41 -> 90000
...

Sheet 23.11
A2: hàng tồn cuối ngày 23/11 vr
A3: Tên Sản phẩm | B3: ĐVT | C3: tồn | D3: giá | E3: thành tiền
A4: Cà Rốt | B4: Kg | C4: 190 | D4: 14000 | E4: =C4*D4 -> 2660000
A5: Cà Rốt | B5: Túi | C5: 0 | E5: =C5*D5 -> 0
A6: Cà Rốt Baby | B6: Vỉ | C6: 24 | D6: 11000 | E6: =C6*D6 -> 264000
A7: Củ Cải Đỏ | B7: Hộp | C7: 0 | E7: =C7*D7 -> 0
A8: Củ Dền | B8: Kg | C8: 32 | D8: 18000 | E8: =C8*D8 -> 576000
A9: Củ Dền | B9: Túi | C9: 0 | E9: =C9*D9 -> 0
A10: Củ Hành Tây | B10: Kg | C10: 333 | D10: 22000 | E10: =C10*D10 -> 7326000
A11: Củ Hành Tây | B11: Túi 300gr | C11: 0 | E11: =C11*D11 -> 0
A12: Củ Hành Tây Trung | B12: Túi | C12: 1896 | D12: 4500 | E12: =C12*D12 -> 8532000
A13: Củ Khoai Lang Mật Size 46 | B13: Kg | C13: 925 | D13: 25000 | E13: =C13*D13 -> 23125000
A14: Củ Khoai Lang Mật Size 46 | B14: Túi | C14: 0 | E14: =C14*D14 -> 0
A15: Củ Khoai Lang Nhật | B15: Kg | C15: 80 | D15: 17000 | E15: =C15*D15 -> 1360000
A16: Củ Khoai Tây Vàng | B16: Kg | C16: 0 | E16: =C16*D16 -> 0
A17: Củ Khoai Tây Vàng | B17: Túi | C17: 0 | E17: =C17*D17 -> 0
A18: Bắp Cải Trắng | B18: Kg | E18: =C18*D18 -> 0
A19: Cải Bó Xôi | B19: Kg | C19: 23 | D19: 20000 | E19: =C19*D19 -> 460000
A20: Cải Bó Xôi | B20: Túi | C20: 12 | D20: 8000 | E20: =C20*D20 -> 96000
A21: Cải Kale | B21: Túi | C21: 5 | D21: 9000 | E21: =C21*D21 -> 45000
A22: Cải Thảo | B22: Kg | C22: 320 | D22: 7000 | E22: =C22*D22 -> 2240000
A23: Cần Tây | B23: Cây | C23: 0 | E23: =C23*D23 -> 0
A24: Cần Tây | B24: Kg | C24: 100 | D24: 16000 | E24: =C24*D24 -> 1600000
A25: Xà Lách Lolo Xanh T.C | B25: Kg | C25: 15 | D25: 28000 | E25: =C25*D25 -> 420000
A26: Bí Đỏ Tròn | B26: Kg | C26: 1585 | D26: 4300 | E26: =C26*D26 -> 6815500
A27: Bí Ngòi Xanh | B27: Kg | C27: 145 | D27: 10000 | E27: =C27*D27 -> 1450000
A28: Bí Ngòi Xanh | B28: Trái | C28: 0 | E28: =C28*D28 -> 0
A29: Bí Non Nhật | B29: Kg | C29: 217 | D29: 10000 | E29: =C29*D29 -> 2170000
A30: Bí Non Nhật | B30: Trái | C30: 0 | E30: =C30*D30 -> 0
A31: Cà Chua Beef | B31: Kg | C31: 37 | D31: 19000 | E31: =C31*D31 -> 703000
A32: Cà Chua Beef | B32: Vỉ 650gr | C32: 0 | E32: =C32*D32 -> 0
A33: Cà Chua Thường | B33: Kg | C33: 220 | D33: 17000 | E33: =C33*D33 -> 3740000
A34: Cà Chua Thường | B34: Vỉ | C34: 0 | E34: =C34*D34 -> 0
A35: Cà Chua Thường Trung | B35: Túi | C35: 60 | D35: 15000 | E35: =C35*D35 -> 900000
A36: Dưa Leo Baby | B36: Kg | C36: 40 | D36: 6000 | E36: =C36*D36 -> 240000
A37: Dưa Leo Baby | B37: Vỉ | C37: 410 | D37: 5000 | E37: =C37*D37 -> 2050000
A38: Dưa Leo Thường | B38: Kg | C38: 35 | D38: 5000 | E38: =C38*D38 -> 175000
A39: Ớt Chuông Đỏ | B39: Kg | C39: 50 | D39: 35000 | E39: =C39*D39 -> 1750000
A40: Ớt Chuông Đỏ | B40: Trái | C40: 0 | E40: =C40*D40 -> 0
A41: Ớt Chuông Vàng | B41: Kg | C41: 65 | D41: 18000 | E41: =C41*D41 -> 1170000
...

Sheet 24.11
A2: hàng tồn cuối ngày 24/11 vr
A3: Tên Sản phẩm | B3: ĐVT | C3: tồn | D3: giá | E3: thành tiền
A4: Cà Rốt | B4: Kg | C4: 384 | D4: 12000 | E4: =C4*D4 -> 4608000
A5: Cà Rốt | B5: Túi | C5: 0 | E5: =C5*D5 -> 0
A6: Cà Rốt Baby | B6: Kg | C6: 0 | E6: =C6*D6 -> 0
