Workbook

Sheet 1.4
A1: hàng tồn cuối ngày 1/4 vr
A2: TÊN SẢN PHẨM | B2: TỒN TRƯỚC | C2: GIÁ NHẬP | D2: THÀNH TIỀN
A3: BẮP CẢI TÍM | D3: =B3*C3 -> 0
A4: BẮP CẢI TÍM (BẮP) | D4: =B4*C4 -> 0
A5: BẮP CẢI TÍM SUSHI | D5: =B5*C5 -> 0
A6: BẮP CẢI TRẮNG | B6: 300 | C6: 7500 | D6: =B6*C6 -> 2250000
A7: BẮP CẢI TRẮNG (BẮP) | D7: =B7*C7 -> 0
A8: BẮP CẢI TRẮNG MỘC CHÂU | D8: =B8*C8 -> 0
A9: BẮP CẢI TRẮNG SÓI BIỂN | D9: =B9*C9 -> 0
A10: BẮP CẢI TRẮNG SUSHI | D10: =B10*C10 -> 0
A11: BẮP MỸ | D11: =B11*C11 -> 0
A12: BẦU | D12: =B12*C12 -> 0
A13: BÍ ĐAO XANH | D13: =B13*C13 -> 0
A14: BÍ ĐAO XANH 400G | D14: =B14*C14 -> 0
A15: BÍ ĐỎ HỒ LÔ | D15: =B15*C15 -> 0
A16: BÍ ĐỎ MINI | D16: =B16*C16 -> 0
A17: BÍ ĐỎ NON (KG)KQ | D17: =B17*C17 -> 0
A18: BÍ ĐỎ NON TRÁI VR | B18: 30 | C18: 5000 | D18: =B18*C18 -> 150000
A19: BÍ ĐỎ NON( KG) VR | D19: =B19*C19 -> 0
A20: BÍ ĐỎ TRÒN | D20: =B20*C20 -> 0
A21: BÍ MINI VÀNG 300GR | D21: =B21*C21 -> 0
A22: BÍ MINI VÀNG KG | D22: =B22*C22 -> 0
A23: BÍ NGÒI VÀNG | D23: =B23*C23 -> 0
A24: BÍ NGÒI VÀNG (TRÁI) | D24: =B24*C24 -> 0
A25: BÍ NGÒI XANH | B25: 65 | C25: 5000 | D25: =B25*C25 -> 325000
A26: BÍ NGÒI XANH(TRÁI) | D26: =B26*C26 -> 0
A27: BÍ NHẬT | D27: =B27*C27 -> 0
A28: BƠ 034 | D28: =B28*C28 -> 0
A29: BƠ BOOTH | D29: =B29*C29 -> 0
A30: BƠ SÁP | D30: =B30*C30 -> 0
A31: BÓ XÔI | B31: 13 | C31: 22000 | D31: =B31*C31 -> 286000
A32: BÓ XÔI 300G VR | D32: =B32*C32 -> 0
A33: BÓ XÔI-HN KQ | D33: =B33*C33 -> 0
A34: BÓ XÔI-NA | D34: =B34*C34 -> 0
A35: BÔNG ATISO | D35: =B35*C35 -> 0
A36: BÔNG BÍ | D36: =B36*C36 -> 0
A37: BÔNG BÍ TÚI 300GR | D37: =B37*C37 -> 0
A38: BÔNG CẢI TRẮNG | D38: =B38*C38 -> 0
A39: BÔNG CẢI TRẮNG (CÂY) | D39: =B39*C39 -> 0
A40: BÔNG CẢI XANH 10P | D40: =B40*C40 -> 0
...

Sheet 2.4
A1: hàng tồn cuối ngày 2/4 vr
A2: TÊN SẢN PHẨM | B2: TỒN TRƯỚC | C2: GIÁ NHẬP | D2: THÀNH TIỀN
A3: CÀ CHUA SÔCOLA 250GR (KG) VR | B3: 1.5 | C3: 6500 | D3: =B3*C3 -> 9750
A4: CÀ CHUA SÔCOLA 250GR (KG) -NA | D4: =B4*C4 -> 0
A5: CÀ CHUA SÔCOLA 300GR (HỘP) VR | D5: =B5*C5 -> 0
A6: CÀ CHUA SÔCOLA 250GR(KG) KQ | D6: =B6*C6 -> 0
A7: CẢI KALE 300GR | D7: =B7*C7 -> 0
A8: CÀ CHUA SOCOLA XÁ | D8: =B8*C8 -> 0
A9: CÀ CHUA SÔCOLA(HỘP) KQ | D9: =B9*C9 -> 0
A10: CÀ CHUA SÔCOLA 250GR (HỘP) VR | D10: =B10*C10 -> 0
A11: CÀ RỐT BABY (KG) KQ | D11: =B11*C11 -> 0
A12: CÀ RỐT BABY | D12: =B12*C12 -> 0
A13: CẢI CẦU VỒNG | D13: =B13*C13 -> 0
A14: CÀ RỐT BABY 200GR | D14: =B14*C14 -> 0
A15: CẢI CẦU VỒNG 300GR | D15: =B15*C15 -> 0
... A22: ỚT CHUÔNG 3 MÀU(KG)VR | D22: =B22*C22 -> 0
A23: ỚT CHUÔNG ĐỎ | B23: 32 | C23: 36000 | D23: =B23*C23 -> 1152000
A24: ỚT CHUÔNG VÀNG | B24: =8+9+30 -> 47 | C24: 32000 | D24: =B24*C24 -> 1504000
A25: ỚT CHUÔNG ĐỎ L1 | B25: 9 | C25: 29000 | D25: =B25*C25 -> 261000
A26: ỚT CHUÔNG 3 MÀU 350G | D26: =B26*C26 -> 0
A27: ỚT CHUÔNG 3 MÀU KQ(KG) | D27: =B27*C27 -> 0
A28: ỚT CHUÔNG ĐỎ(TRÁI) | B28: 50 | C28: 7200 | D28: =B28*C28 -> 360000
A29: ỚT CHUÔNG VÀNG L1 | B29: 7 | C29: 22000 | D29: =B29*C29 -> 154000
A30: ỚT CHUÔNG VÀNG(TRÁI) | D30: =B30*C30 -> 0
A31: ỚT CHUÔNG VÀNG+ XANH (VỈ) | D31: =B31*C31 -> 0
A32: ỚT CHUÔNG XANH | B32: 14 | C32: 24000 | D32: =B32*C32 -> 336000
A33: ỚT CHUÔNG XANH L1 | D33: =B33*C33 -> 0
A34: ỚT CHUÔNG XANH(TRÁI) | D34: =B34*C34 -> 0
A35: CỦ DỀN | D35: =B35*C35 -> 0
A36: CỦ DỀN 600G | D36: =B36*C36 -> 0
A37: GỪNG 250GR | D37: =B37*C37 -> 0
A38: HỒNG GIÒN | D38: =B38*C38 -> 0
A39: XÀ LÁCH MỸ | D39: =B39*C39 -> 0
A40: KHOAI TÂY HỒNG | D40: =B40*C40 -> 0
A41: KHOAI TÂY HỒNG TÚI LƯỚI 500G | D41: =B41*C41 -> 0
A42: KHOAI TÂY VÀNG | D42: =B42*C42 -> 0
A43: KHOAI TÂY VÀNG ĐL | D43: =B43*C43 -> 0
A44: KHOAI TÂY VÀNG LỚN TÚI LƯỚI 500G | D44: =B44*C44 -> 0
A45: KHOAI TÂY VÀNG RỬA | D45: =B45*C45 -> 0
A46: KHOAI TÂY VÀNG TRUNG TÚI LƯỚI 500G | B46: 30 | C46: 5000 | D46: =B46*C46 -> 150000
...

Sheet 3.4
A1: hàng tồn cuối ngày 3/3 vr
A2: TÊN SẢN PHẨM | B2: TỒN TRƯỚC | C2: GIÁ NHẬP | D2: THÀNH TIỀN
A3: BẮP CẢI TÍM | D3: =B3*C3 -> 0
A4: BẮP CẢI TÍM (BẮP) | D4: =B4*C4 -> 0
A5: BẮP CẢI TÍM SUSHI | D5: =B5*C5 -> 0
A6: BẮP CẢI TRẮNG | D6: =B6*C6 -> 0
A7: BẮP CẢI TRẮNG (BẮP) | D7: =B7*C7 -> 0
A8: BẮP CẢI TRẮNG MỘC CHÂU | D8: =B8*C8 -> 0
A9: BẮP CẢI TRẮNG SÓI BIỂN | D9: =B9*C9 -> 0
A10: BẮP CẢI TRẮNG SUSHI | D10: =B10*C10 -> 0
A11: BẮP MỸ | D11: =B11*C11 -> 0
A12: BẦU | D12: =B12*C12 -> 0
A13: BÍ ĐAO XANH | D13: =B13*C13 -> 0
A14: BÍ ĐAO XANH 400G | D14: =B14*C14 -> 0
... A17: BÍ ĐỎ NON (KG)KQ | D17: =B17*C17 -> 0
A18: BÍ ĐỎ NON TRÁI VR | B18: 36 | C18: 5000 | D18: =B18*C18 -> 180000
A19: BÍ ĐỎ NON( KG) VR | D19: =B19*C19 -> 0
A20: BÍ ĐỎ TRÒN | D20: =B20*C20 -> 0
A21: BÍ MINI VÀNG 300GR | D21: =B21*C21 -> 0
A22: BÍ MINI VÀNG KG | D22: =B22*C22 -> 0
A23: BÍ NGÒI VÀNG | D23: =B23*C23 -> 0
A24: BÍ NGÒI VÀNG (TRÁI) | D24: =B24*C24 -> 0
A25: BÍ NGÒI XANH | B25: =28+15+80 -> 123 | C25: 6000 | D25: =B25*C25 -> 738000
A26: BÍ NGÒI XANH(TRÁI) | D26: =B26*C26 -> 0
A27: BÍ NHẬT | D27: =B27*C27 -> 0
A28: BƠ 034 | D28: =B28*C28 -> 0
A29: BƠ BOOTH | D29: =B29*C29 -> 0
A30: BƠ SÁP | D30: =B30*C30 -> 0
A31: BÓ XÔI | D31: =B31*C31 -> 0
A32: BÓ XÔI 300G VR | D32: =B32*C32 -> 0
A33: BÓ XÔI-HN KQ | D33: =B33*C33 -> 0
A34: BÓ XÔI-NA | D34: =B34*C34 -> 0
A35: BÔNG ATISO | D35: =B35*C35 -> 0
A36: BÔNG BÍ | D36: =B36*C36 -> 0
A37: BÔNG BÍ TÚI 300GR | D37: =B37*C37 -> 0
... A49: CÀ CHUA BI (HỘP) 300GR KQ | D49: =B49*C49 -> 0
A50: CÀ CHUA BI (HỘP) 300GR VR | B50: 3 | C50: 4200 | D50: =B50*C50 -> 12600
A51: CÀ CHUA BI 300GR KQ (KG) | D51: =B51*C51 -> 0
A52: CÀ CHUA BI 300GR VR (KG) | D52: =B52*C52 -> 0
A53: CÀ CHUA BI CAM SỮA (KG) VR | D53: =B53*C53 -> 0
...

Sheet 4.4
A1: hàng tồn cuối ngày 4/4 vr
A2: TÊN SẢN PHẨM | B2: TỒN TRƯỚC | C2: GIÁ NHẬP | D2: THÀNH TIỀN
A3: CÀ CHUA SÔCOLA 250GR (HỘP) VR | B3: =6+24 -> 30 | C3: 7000 | D3: =B3*C3 -> 210000
A4: CÀ CHUA SÔCOLA 250GR (KG) -NA | D4: =B4*C4 -> 0
A5: CÀ CHUA SÔCOLA 250GR (KG) VR | D5: =B5*C5 -> 0
A6: CÀ CHUA SÔCOLA 250GR(KG) KQ | D6: =B6*C6 -> 0
A7: CÀ CHUA SÔCOLA 300GR (HỘP) VR | D7: =B7*C7 -> 0
A8: CÀ CHUA SOCOLA XÁ | D8: =B8*C8 -> 0
A9: CÀ CHUA SÔCOLA(HỘP) KQ | D9: =B9*C9 -> 0
A10: CÀ RỐT BABY | D10: =B10*C10 -> 0
A11: CÀ RỐT BABY (KG) KQ | D11: =B11*C11 -> 0
A12: CÀ RỐT BABY 200GR | D12: =B12*C12 -> 0
A13: CẢI CẦU VỒNG | D13: =B13*C13 -> 0
A14: CẢI CẦU VỒNG 300GR | D14: =B14*C14 -> 0
A15: CẢI KALE | D15: =B15*C15 -> 0
... A22: ỚT CHUÔNG 3 MÀU(KG)VR | D22: =B22*C22 -> 0
A23: ỚT CHUÔNG ĐỎ | B23: =50+25+5 -> 80 | C23: 36000 | D23: =B23*C23 -> 2880000
A24: ỚT CHUÔNG ĐỎ L1 | D24: =B24*C24 -> 0
A25: ỚT CHUÔNG ĐỎ(TRÁI) | D25: =B25*C25 -> 0
A26: ỚT CHUÔNG 3 MÀU 350G | B26: 18 | C26: 12000 | D26: =B26*C26 -> 216000
A27: ỚT CHUÔNG 3 MÀU KQ(KG) | D27: =B27*C27 -> 0
A28: ỚT CHUÔNG VÀNG | B28: 46 | C28: 32000 | D28: =B28*C28 -> 1472000
A29: ỚT CHUÔNG VÀNG L1 | D29: =B29*C29 -> 0
A30: ỚT CHUÔNG VÀNG(TRÁI) | D30: =B30*C30 -> 0
A31: ỚT CHUÔNG VÀNG+ XANH (VỈ) | D31: =B31*C31 -> 0
A32: ỚT CHUÔNG XANH | B32: =10+15 -> 25 | C32: 25000 | D32: =B32*C32 -> 625000
A33: ỚT CHUÔNG XANH L1 | D33: =B33*C33 -> 0
A34: ỚT CHUÔNG XANH(TRÁI) | D34: =B34*C34 -> 0
A35: CỦ DỀN | D35: =B35*C35 -> 0
A36: CỦ DỀN 600G | D36: =B36*C36 -> 0
A37: GỪNG 250GR | D37: =B37*C37 -> 0
A38: HỒNG GIÒN | D38: =B38*C38 -> 0
A39: XÀ LÁCH MỸ | D39: =B39*C39 -> 0
A40: KHOAI TÂY HỒNG | D40: =B40*C40 -> 0
A41: KHOAI TÂY HỒNG TÚI LƯỚI 500G | D41: =B41*C41 -> 0
A42: KHOAI TÂY VÀNG | D42: =B42*C42 -> 0
A43: KHOAI TÂY VÀNG ĐL | D43: =B43*C43 -> 0
A44: KHOAI TÂY VÀNG LỚN TÚI LƯỚI 500G | D44: =B44*C44 -> 0
... A53: BÍ ĐAO XANH 400G | D53: =B53*C53 -> 0
A54: DƯA LEO | B54: 24 | C54: 13000 | D54: =B54*C54 -> 312000
...

Sheet 5.4
A1: hàng tồn cuối ngày 5/4 VR
A2: TÊN SẢN PHẨM | B2: TỒN TRƯỚC | C2: GIÁ NHẬP | D2: THÀNH TIỀN
A3: BẮP CẢI TÍM | D3: =B3*C3 -> 0
A4: BẮP CẢI TÍM (BẮP) | D4: =B4*C4 -> 0
A5: BẮP CẢI TÍM SUSHI | D5: =B5*C5 -> 0
A6: BẮP CẢI TRẮNG | D6: =B6*C6 -> 0
A7: BẮP CẢI TRẮNG (BẮP) | D7: =B7*C7 -> 0
A8: BẮP CẢI TRẮNG MỘC CHÂU | D8: =B8*C8 -> 0
A9: BẮP CẢI TRẮNG SÓI BIỂN | D9: =B9*C9 -> 0
A10: BẮP CẢI TRẮNG SUSHI | D10: =B10*C10 -> 0
A11: BẮP MỸ | D11: =B11*C11 -> 0
A12: BẦU | D12: =B12*C12 -> 0
A13: BÍ ĐAO XANH | D13: =B13*C13 -> 0
A14: BÍ ĐAO XANH 400G | D14: =B14*C14 -> 0
A15: BÍ ĐỎ HỒ LÔ | B15: 6 | C15: 10000 | D15: =B15*C15 -> 60000
A16: BÍ ĐỎ MINI | D16: =B16*C16 -> 0
A17: BÍ ĐỎ NON (KG)KQ | D17: =B17*C17 -> 0
A18: BÍ ĐỎ NON TRÁI VR | B18: 35 | C18: 5000 | D18: =B18*C18 -> 175000
A19: BÍ ĐỎ NON( KG) VR | D19: =B19*C19 -> 0
A20: BÍ ĐỎ TRÒN | D20: =B20*C20 -> 0
A21: BÍ MINI VÀNG 300GR | D21: =B21*C21 -> 0
A22: BÍ MINI VÀNG KG | D22: =B22*C22 -> 0
A23: BÍ NGÒI VÀNG | D23: =B23*C23 -> 0
A24: BÍ NGÒI VÀNG (TRÁI) | D24: =B24*C24 -> 0
A25: BÍ NGÒI XANH | B25: =15+45 -> 60 | C25: 6000 | D25: =B25*C25 -> 360000
A26: BÍ NGÒI XANH(TRÁI) | D26: =B26*C26 -> 0
A27: BÍ NHẬT | D27: =B27*C27 -> 0
A28: BƠ 034 | D28: =B28*C28 -> 0
A29: BƠ BOOTH | D29: =B29*C29 -> 0
A30: BƠ SÁP | D30: =B30*C30 -> 0
A31: BÓ XÔI | D31: =B31*C31 -> 0
A32: BÓ XÔI 300G VR | D32: =B32*C32 -> 0
A33: BÓ XÔI-HN KQ | D33: =B33*C33 -> 0
A34: BÓ XÔI-NA | D34: =B34*C34 -> 0
A35: BÔNG ATISO | D35: =B35*C35 -> 0
A36: BÔNG BÍ | D36: =B36*C36 -> 0
A37: BÔNG BÍ TÚI 300GR | D37: =B37*C37 -> 0
... A56: CÀ CHUA CHERRY MIX 300G | D56: =B56*C56 -> 0
A57: CÀ CHUA L1 | B57: 80 | C57: 6000 | D57: =B57*C57 -> 480000
A58: CÀ CHUA MỘC CHÂU | D58: =B58*C58 -> 0
...

Sheet 6.4
A1: hàng tồn cuối ngày 6/4 vr
A2: TÊN SẢN PHẨM | B2: TỒN TRƯỚC | C2: GIÁ NHẬP | D2: THÀNH TIỀN
A3: BẮP CẢI TÍM | D3: =B3*C3 -> 0
A4: BẮP CẢI TÍM (BẮP) | D4: =B4*C4 -> 0
A5: BẮP CẢI TÍM SUSHI | D5: =B5*C5 -> 0
A6: BẮP CẢI TRẮNG | D6: =B6*C6 -> 0
A7: BẮP CẢI TRẮNG (BẮP) | D7: =B7*C7 -> 0
A8: BẮP CẢI TRẮNG MỘC CHÂU | D8: =B8*C8 -> 0
A9: BẮP CẢI TRẮNG SÓI BIỂN | D9: =B9*C9 -> 0
A10: BẮP CẢI TRẮNG SUSHI | D10: =B10*C10 -> 0
A11: BẮP MỸ | D11: =B11*C11 -> 0
A12: BẦU | D12: =B12*C12 -> 0
A13: BÍ ĐAO XANH | D13: =B13*C13 -> 0
A14: BÍ ĐAO XANH 400G | D14: =B14*C14 -> 0
A15: BÍ ĐỎ HỒ LÔ | B15: 5 | C15: 10000 | D15: =B15*C15 -> 50000
A16: BÍ ĐỎ MINI | D16: =B16*C16 -> 0
A17: BÍ ĐỎ NON (KG)KQ | D17: =B17*C17 -> 0
A18: BÍ ĐỎ NON TRÁI VR | D18: =B18*C18 -> 0
A19: BÍ ĐỎ NON( KG) VR | D19: =B19*C19 -> 0
A20: BÍ ĐỎ TRÒN | D20: =B20*C20 -> 0
A21: BÍ MINI VÀNG 300GR | D21: =B21*C21 -> 0
A22: BÍ MINI VÀNG KG | D22: =B22*C22 -> 0
A23: BÍ NGÒI VÀNG | D23: =B23*C23 -> 0
A24: BÍ NGÒI VÀNG (TRÁI) | D24: =B24*C24 -> 0
A25: BÍ NGÒI XANH | D25: =B25*C25 -> 0
A26: BÍ NGÒI XANH(TRÁI) | D26: =B26*C26 -> 0
A27: BÍ NHẬT | D27: =B27*C27 -> 0
... A49: CÀ CHUA BI (HỘP) 300GR KQ | D49: =B49*C49 -> 0
A50: CÀ CHUA BI (HỘP) 300GR VR | B50: =17 -> 17 | C50: 4200 | D50: =B50*C50 -> 71400
A51: CÀ CHUA BI 300GR KQ (KG) | D51: =B51*C51 -> 0
A52: CÀ CHUA BI 300GR VR (KG) | D52: =B52*C52 -> 0
A53: CÀ CHUA BI CAM SỮA (KG) VR | D53: =B53*C53 -> 0
A54: CÀ CHUA BI COOP | B54: 3.5 | C54: 14000 | D54: =B54*C54 -> 49000
A55: CÀ CHUA BI-NA | D55: =B55*C55 -> 0
A56: CÀ CHUA CHERRY MIX 300G | D56: =B56*C56 -> 0
A57: CÀ CHUA L1 | B57: 30 | C57: 6000 | D57: =B57*C57 -> 180000
A58: CÀ CHUA MỘC CHÂU | D58: =B58*C58 -> 0
A59: CÀ CHUA NGỌT | D59: =B59*C59 -> 0
A60: CÀ CHUA NGỌT 300GR (KG) | D60: =B60*C60 -> 0
A61: CÀ CHUA NGỌT XÁ | D61: =B61*C61 -> 0
...

Sheet 7.4
A1: 45389 | C1: Stock
A2: TÊN SẢN PHẨM | B2: ĐVT | C2: TỒN TRƯỚC | D2: Gía nhập | E2: Thành tiền
A4: BẮP CẢI TÍM | B4: Kg | E4: =+D4*C4 -> 0
A5: BẮP CẢI TÍM (BẮP) | B5: BẮP | E5: =+D5*C5 -> 0
A6: BẮP CẢI TÍM SUSHI | B6: Kg | E6: =+D6*C6 -> 0
A7: BẮP CẢI TRẮNG | B7: Kg | C7: 510 | D7: 8000 | E7: =+D7*C7 -> 4080000
A8: BẮP CẢI TRẮNG (BẮP) | B8: BẮP | E8: =+D8*C8 -> 0
A9: BẮP CẢI TRẮNG MỘC CHÂU | B9: Kg | E9: =+D9*C9 -> 0
A10: BẮP CẢI TRẮNG SÓI BIỂN | B10: Kg | E10: =+D10*C10 -> 0
A11: BẮP CẢI TRẮNG SUSHI | B11: Kg | E11: =+D11*C11 -> 0
A12: BẮP MỸ | B12: Kg | E12: =+D12*C12 -> 0
A13: BẦU | B13: Kg | E13: =+D13*C13 -> 0
A14: BÍ ĐAO XANH | B14: Kg | C14: 60 | D14: 8000 | E14: =+D14*C14 -> 480000
A15: BÍ ĐAO XANH 400G | B15: TRÁI | E15: =+D15*C15 -> 0
A16: BÍ ĐỎ HỒ LÔ | B16: Kg | E16: =+D16*C16 -> 0
A17: BÍ ĐỎ MINI | B17: Kg | E17: =+D17*C17 -> 0
A18: BÍ ĐỎ NON (KG)KQ | B18: Kg | E18: =+D18*C18 -> 0
A19: BÍ ĐỎ NON TRÁI VR | B19: TRÁI | E19: =+D19*C19 -> 0
A20: BÍ ĐỎ NON( KG) VR | B20: Kg | E20: =+D20*C20 -> 0
A21: BÍ ĐỎ TRÒN | B21: Kg | C21: 100 | D21: 4000 | E21: =+D21*C21 -> 400000
A22: BÍ MINI VÀNG 300GR | B22: TRÁI | E22: =+D22*C22 -> 0
A23: BÍ MINI VÀNG KG | B23: Kg | C23: 1 | D23: 45000 | E23: =+D23*C23 -> 45000
A24: BÍ NGÒI VÀNG | B24: Kg | E24: =+D24*C24 -> 0
A25: BÍ NGÒI VÀNG (TRÁI) | B25: TRÁI | E25: =+D25*C25 -> 0
A26: BÍ NGÒI XANH | B26: Kg | E26: =+D26*C26 -> 0
A27: BÍ NGÒI XANH(TRÁI) | B27: TRÁI | E27: =+D27*C27 -> 0
A28: BÍ NHẬT | B28: Kg | E28: =+D28*C28 -> 0
A29: BƠ 034 | B29: Kg | E29: =+D29*C29 -> 0
A30: BƠ BOOTH | B30: Kg | E30: =+D30*C30 -> 0
A31: BƠ SÁP | B31: Kg | E31: =+D31*C31 -> 0
A32: BÓ XÔI | B32: Kg | E32: =+D32*C32 -> 0
A33: BÓ XÔI 300G VR | B33: TÚI | E33: =+D33*C33 -> 0
A34: BÓ XÔI-HN KQ | B34: Kg | E34: =+D34*C34 -> 0
A35: BÓ XÔI-NA | B35: Kg | E35: =+D35*C35 -> 0
... A45: BÔNG CẢI XANH BABY 200G | B45: VỈ | E45: =+D45*C45 -> 0
A46: BÔNG CẢI XANH BIGC | B46: Kg | C46: 8 | D46: 11000 | E46: =+D46*C46 -> 88000
A47: BÔNG CẢI XANH CITI | B47: Kg | E47: =+D47*C47 -> 0
A48: CÀ CHUA | B48: Kg | C48: 470 | D48: 8000 | E48: =+D48*C48 -> 3760000
A49: CÀ CHUA BI | B49: Kg | E49: =+D49*C49 -> 0
A50: CÀ CHUA BI (HỘP) 300GR KQ | B50: HỘP | E50: =+D50*C50 -> 0
...

Sheet 8.4
A1: hàng tồn cuối ngày 9/4 vr
A2: TÊN SẢN PHẨM | B2: TỒN TRƯỚC | C2: GIÁ NHẬP | D2: THÀNH TIỀN
A3: BẮP CẢI TÍM | D3: =B3*C3 -> 0
A4: BẮP CẢI TÍM (BẮP) | D4: =B4*C4 -> 0
A5: BẮP CẢI TÍM SUSHI | D5: =B5*C5 -> 0
A6: BẮP CẢI TRẮNG | D6: =B6*C6 -> 0
A7: BẮP CẢI TRẮNG (BẮP) | D7: =B7*C7 -> 0
A8: BẮP CẢI TRẮNG MỘC CHÂU | D8: =B8*C8 -> 0
A9: BẮP CẢI TRẮNG SÓI BIỂN | D9: =B9*C9 -> 0
A10: BẮP CẢI TRẮNG SUSHI | D10: =B10*C10 -> 0
A11: BẮP MỸ | D11: =B11*C11 -> 0
A12: BẦU | D12: =B12*C12 -> 0
A13: BÍ ĐAO XANH | D13: =B13*C13 -> 0
A14: BÍ ĐAO XANH 400G | D14: =B14*C14 -> 0
... A17: BÍ ĐỎ NON (KG)KQ | D17: =B17*C17 -> 0
A18: BÍ ĐỎ NON TRÁI VR | B18: 25 | C18: 5000 | D18: =B18*C18 -> 125000
A19: BÍ ĐỎ NON( KG) VR | D19: =B19*C19 -> 0
A20: BÍ ĐỎ TRÒN | D20: =B20*C20 -> 0
A21: BÍ MINI VÀNG 300GR | D21: =B21*C21 -> 0
A22: BÍ MINI VÀNG KG | D22: =B22*C22 -> 0
A23: BÍ NGÒI VÀNG | D23: =B23*C23 -> 0
A24: BÍ NGÒI VÀNG (TRÁI) | D24: =B24*C24 -> 0
A25: BÍ NGÒI XANH | B25: 160 | C25: 6000 | D25: =B25*C25 -> 960000
A26: BÍ NGÒI XANH(TRÁI) | D26: =B26*C26 -> 0
A27: BÍ NHẬT | D27: =B27*C27 -> 0
A28: BƠ 034 | D28: =B28*C28 -> 0
A29: BƠ BOOTH | B29: 6 | C29: 38000 | D29: =B29*C29 -> 228000
A30: BƠ SÁP | B30: 35 | C30: 33000 | D30: =B30*C30 -> 1155000
A31: BÓ XÔI | D31: =B31*C31 -> 0
A32: BÓ XÔI 300G VR | D32: =B32*C32 -> 0
A33: BÓ XÔI-HN KQ | D33: =B33*C33 -> 0
A34: BÓ XÔI-NA | D34: =B34*C34 -> 0
A35: BÔNG ATISO | D35: =B35*C35 -> 0
A36: BÔNG BÍ | D36: =B36*C36 -> 0
A37: BÔNG BÍ TÚI 300GR | D37: =B37*C37 -> 0
A38: BÔNG CẢI TRẮNG | B38: 10 | C38: 13000 | D38: =B38*C38 -> 130000
A39: BÔNG CẢI TRẮNG (CÂY) | D39: =B39*C39 -> 0
A40: BÔNG CẢI XANH 10P | D40: =B40*C40 -> 0
A41: BÔNG CẢI XANH AEON | B41: 15 | C41: 20000 | D41: =B41*C41 -> 300000
A42: BÔNG CẢI XANH AEON (CÂY) | D42: =B42*C42 -> 0
...

Sheet 9.4
A1: hàng tồn cuối ngày 9/4 vr
A2: TÊN SẢN PHẨM | B2: TỒN TRƯỚC | C2: GIÁ NHẬP | D2: THÀNH TIỀN
A3: CÀ CHUA SÔCOLA 250GR (HỘP) VR | D3: =B3*C3 -> 0
A4: CÀ CHUA SÔCOLA 250GR (KG) -NA | D4: =B4*C4 -> 0
A5: CÀ CHUA SÔCOLA 250GR (KG) VR | D5: =B5*C5 -> 0
A6: CÀ CHUA SÔCOLA 250GR(KG) KQ | D6: =B6*C6 -> 0
A7: CÀ CHUA SÔCOLA 300GR (HỘP) VR | D7: =B7*C7 -> 0
A8: CÀ CHUA SOCOLA XÁ | D8: =B8*C8 -> 0
A9: CÀ CHUA SÔCOLA(HỘP) KQ | D9: =B9*C9 -> 0
A10: CÀ RỐT BABY | D10: =B10*C10 -> 0
A11: CÀ RỐT BABY (KG) KQ | D11: =B11*C11 -> 0
A12: CÀ RỐT BABY 200GR | D12: =B12*C12 -> 0
A13: CẢI CẦU VỒNG | D13: =B13*C13 -> 0
A14: CẢI CẦU VỒNG 300GR | D14: =B14*C14 -> 0
A15: CẢI KALE | D15: =B15*C15 -> 0
A16: CẢI KALE 300GR | B16: 11 | C16: 4000 | D16: =B16*C16 -> 44000
A17: CHANH VÀNG (KG) | D17: =B17*C17 -> 0
A18: CHANH VÀNG TRÁI 180UP | D18: =B18*C18 -> 0
A19: CẦN TÂY (KG) | B19: =26+36 -> 62 | C19: 10000 | D19: =B19*C19 -> 620000
A20: CẦN TÂY THUỶ CANH | D20: =B20*C20 -> 0
A21: CẦN TÂY(CÂY) | D21: =B21*C21 -> 0
A22: ỚT CHUÔNG 3 MÀU(KG)VR | D22: =B22*C22 -> 0
A23: ỚT CHUÔNG ĐỎ | B23: =5+6+80+8 -> 99 | C23: 40000 | D23: =B23*C23 -> 3960000
A24: ỚT CHUÔNG ĐỎ L1 | D24: =B24*C24 -> 0
A25: ỚT CHUÔNG ĐỎ(TRÁI) | D25: =B25*C25 -> 0
A26: ỚT CHUÔNG 3 MÀU 350G | B26: 8 | C26: 13000 | D26: =B26*C26 -> 104000
A27: ỚT CHUÔNG 3 MÀU KQ(KG) | D27: =B27*C27 -> 0
A28: ỚT CHUÔNG VÀNG | B28: 20 | C28: 38000 | D28: =B28*C28 -> 760000
A29: ỚT CHUÔNG VÀNG L1 | D29: =B29*C29 -> 0
A30: ỚT CHUÔNG VÀNG(TRÁI) | D30: =B30*C30 -> 0
A31: ỚT CHUÔNG VÀNG+ XANH (VỈ) | D31: =B31*C31 -> 0
A32: ỚT CHUÔNG XANH | B32: 128 | C32: 20000 | D32: =B32*C32 -> 2560000
A33: ỚT CHUÔNG XANH L1 | D33: =B33*C33 -> 0
A34: ỚT CHUÔNG XANH(TRÁI) | D34: =B34*C34 -> 0
A35: CỦ DỀN | D35: =B35*C35 -> 0
A36: CỦ DỀN 600G | D36: =B36*C36 -> 0
A37: GỪNG 250GR | D37: =B37*C37 -> 0
A38: HỒNG GIÒN | D38: =B38*C38 -> 0
A39: XÀ LÁCH MỸ | D39: =B39*C39 -> 0
A40: KHOAI TÂY HỒNG | D40: =B40*C40 -> 0
...

Sheet 10.4
A1: 45392 | C1: Stock
A2: TÊN SẢN PHẨM | B2: ĐVT | C2: TỒN TRƯỚC | D2: GIÁ NHẬP | E2: THÀNH TIỀN
A4: BẮP CẢI TÍM | B4: Kg
A5: BẮP CẢI TÍM (BẮP) | B5: BẮP
A6: BẮP CẢI TÍM SUSHI | B6: Kg
A7: BẮP CẢI TRẮNG | B7: Kg
A8: BẮP CẢI TRẮNG (BẮP) | B8: BẮP
A9: BẮP CẢI TRẮNG MỘC CHÂU | B9: Kg
A10: BẮP CẢI TRẮNG SÓI BIỂN | B10: Kg
A11: BẮP CẢI TRẮNG SUSHI | B11: Kg
A12: BẮP MỸ | B12: Kg
A13: BẦU | B13: Kg
A14: BÍ ĐAO XANH | B14: Kg
A15: BÍ ĐAO XANH 400G | B15: TRÁI
... A25: BÍ NGÒI VÀNG (TRÁI) | B25: TRÁI
A26: BÍ NGÒI XANH | B26: Kg | C26: 100 | D26: =VLOOKUP(A26,'8.4'!A25:C618,3,) -> 6000 | E26: =+D26*C26 -> 600000
A27: BÍ NGÒI XANH(TRÁI) | B27: TRÁI
A28: BÍ NHẬT | B28: Kg
A29: BƠ 034 | B29: Kg
A30: BƠ BOOTH | B30: Kg | C30: 14 | D30: =VLOOKUP(A30,'8.4'!A29:C622,3,) -> 38000 | E30: =+D30*C30 -> 532000
A31: BƠ SÁP | B31: Kg | C31: 13 | D31: =VLOOKUP(A31,'8.4'!A30:C623,3,) -> 33000 | E31: =+D31*C31 -> 429000
A32: BÓ XÔI | B32: Kg
A33: BÓ XÔI 300G VR | B33: TÚI
A34: BÓ XÔI-HN KQ | B34: Kg
A35: BÓ XÔI-NA | B35: Kg
A36: BÔNG ATISO | B36: Kg
A37: BÔNG BÍ | B37: Kg
A38: BÔNG BÍ TÚI 300GR | B38: VỈ
A39: BÔNG CẢI TRẮNG | B39: Kg
A40: BÔNG CẢI TRẮNG (CÂY) | B40: CÂY
A41: BÔNG CẢI XANH 10P | B41: Kg
A42: BÔNG CẢI XANH AEON | B42: Kg | C42: 3 | D42: =VLOOKUP(A42,'8.4'!A41:C634,3,) -> 20000 | E42: =+D42*C42 -> 60000
A43: BÔNG CẢI XANH AEON (CÂY) | B43: CÂY
A44: BÔNG CẢI XANH BABY (KG) | B44: Kg
A45: BÔNG CẢI XANH BABY 200G | B45: VỈ
A46: BÔNG CẢI XANH BIGC | B46: Kg
A47: BÔNG CẢI XANH CITI | B47: Kg
A48: CÀ CHUA | B48: Kg
A49: CÀ CHUA BI | B49: Kg
A50: CÀ CHUA BI (HỘP) 300GR KQ | B50: HỘP
...

Sheet 11.4
A1: hàng tồn cuối ngày 11/4
A2: TÊN SẢN PHẨM | B2: TỒN TRƯỚC | C2: GIÁ NHẬP | D2: THÀNH TIỀN
A3: BẮP CẢI TÍM | B3: 5 | C3: 7000 | D3: =B3*C3 -> 35000
A4: BẮP CẢI TÍM (BẮP) | D4: =B4*C4 -> 0
A5: BẮP CẢI TÍM SUSHI | D5: =B5*C5 -> 0
A6: BẮP CẢI TRẮNG | D6: =B6*C6 -> 0
A7: BẮP CẢI TRẮNG (BẮP) | D7: =B7*C7 -> 0
A8: BẮP CẢI TRẮNG MỘC CHÂU | D8: =B8*C8 -> 0
A9: BẮP CẢI TRẮNG SÓI BIỂN | D9: =B9*C9 -> 0
A10: BẮP CẢI TRẮNG SUSHI | D10: =B10*C10 -> 0
A11: BẮP MỸ | D11: =B11*C11 -> 0
A12: BẦU | D12: =B12*C12 -> 0
A13: BÍ ĐAO XANH | D13: =B13*C13 -> 0
A14: BÍ ĐAO XANH 400G | D14: =B14*C14 -> 0
A15: BÍ ĐỎ HỒ LÔ | B15: 20 | C15: 10000 | D15: =B15*C15 -> 200000
A16: BÍ ĐỎ MINI | D16: =B16*C16 -> 0
A17: BÍ ĐỎ NON (KG)KQ | D17: =B17*C17 -> 0
A18: BÍ ĐỎ NON TRÁI VR | B18: 19 | C18: 5000 | D18: =B18*C18 -> 95000
A19: BÍ ĐỎ NON( KG) VR | D19: =B19*C19 -> 0
A20: BÍ ĐỎ TRÒN | D20: =B20*C20 -> 0
A21: BÍ MINI VÀNG 300GR | D21: =B21*C21 -> 0
A22: BÍ MINI VÀNG KG | D22: =B22*C22 -> 0
A23: BÍ NGÒI VÀNG | D23: =B23*C23 -> 0
A24: BÍ NGÒI VÀNG (TRÁI) | D24: =B24*C24 -> 0
A25: BÍ NGÒI XANH | B25: =16+20+15+10+45 -> 106 | C25: 6500 | D25: =B25*C25 -> 689000
A26: BÍ NGÒI XANH(TRÁI) | D26: =B26*C26 -> 0
A27: BÍ NHẬT | D27: =B27*C27 -> 0
A28: BƠ 034 | D28: =B28*C28 -> 0
A29: BƠ BOOTH | D29: =B29*C29 -> 0
A30: BƠ SÁP | D30: =B30*C30 -> 0
A31: BÓ XÔI | D31: =B31*C31 -> 0
A32: BÓ XÔI 300G VR | D32: =B32*C32 -> 0
A33: BÓ XÔI-HN KQ | D33: =B33*C33 -> 0
A34: BÓ XÔI-NA | D34: =B34*C34 -> 0
A35: BÔNG ATISO | D35: =B35*C35 -> 0
A36: BÔNG BÍ | D36: =B36*C36 -> 0
A37: BÔNG BÍ TÚI 300GR | D37: =B37*C37 -> 0
... A62: CÀ CHUA ROSEBERRY 300G | D62: =B62*C62 -> 0
A63: CÀ CHUA SÔCOLA 250GR (HỘP) VR | B63: 11 | C63: 5500 | D63: =B63*C63 -> 60500
A64: CÀ CHUA SÔCOLA 250GR (KG) -NA | D64: =B64*C64 -> 0
...

Sheet 12.4
A1: hàng tồn cuối ngày 12/3 vr
A2: TÊN SẢN PHẨM | B2: TỒN TRƯỚC | C2: GIÁ NHẬP | D2: THÀNH TIỀN
A3: BẮP CẢI TÍM | B3: 4 | C3: 13000 | D3: =B3*C3 -> 52000
A4: BẮP CẢI TÍM (BẮP) | D4: =B4*C4 -> 0
A5: BẮP CẢI TÍM SUSHI | D5: =B5*C5 -> 0
A6: BẮP CẢI TRẮNG | D6: =B6*C6 -> 0
A7: BẮP CẢI TRẮNG (BẮP) | D7: =B7*C7 -> 0
A8: BẮP CẢI TRẮNG MỘC CHÂU | D8: =B8*C8 -> 0
A9: BẮP CẢI TRẮNG SÓI BIỂN | D9: =B9*C9 -> 0
A10: BẮP CẢI TRẮNG SUSHI | D10: =B10*C10 -> 0
A11: BẮP MỸ | D11: =B11*C11 -> 0
A12: BẦU | D12: =B12*C12 -> 0
A13: BÍ ĐAO XANH | D13: =B13*C13 -> 0
A14: BÍ ĐAO XANH 400G | D14: =B14*C14 -> 0
A15: BÍ ĐỎ HỒ LÔ | B15: 16 | C15: 10000 | D15: =B15*C15 -> 160000
A16: BÍ ĐỎ MINI | D16: =B16*C16 -> 0
A17: BÍ ĐỎ NON (KG)KQ | D17: =B17*C17 -> 0
A18: BÍ ĐỎ NON TRÁI VR | B18: =18+40+25 -> 83 | C18: 4000 | D18: =B18*C18 -> 332000
A19: BÍ ĐỎ NON( KG) VR | D19: =B19*C19 -> 0
A20: BÍ ĐỎ TRÒN | D20: =B20*C20 -> 0
A21: BÍ MINI VÀNG 300GR | D21: =B21*C21 -> 0
A22: BÍ MINI VÀNG KG | D22: =B22*C22 -> 0
A23: BÍ NGÒI VÀNG | D23: =B23*C23 -> 0
A24: BÍ NGÒI VÀNG (TRÁI) | D24: =B24*C24 -> 0
A25: BÍ NGÒI XANH | B25: =10+12+50 -> 72 | C25: 7000 | D25: =B25*C25 -> 504000
A26: BÍ NGÒI XANH(TRÁI) | D26: =B26*C26 -> 0
A27: BÍ NHẬT | D27: =B27*C27 -> 0
A28: BƠ 034 | D28: =B28*C28 -> 0
A29: BƠ BOOTH | D29: =B29*C29 -> 0
A30: BƠ SÁP | D30: =B30*C30 -> 0
A31: BÓ XÔI | D31: =B31*C31 -> 0
A32: BÓ XÔI 300G VR | B32: 13 | C32: 9500 | D32: =B32*C32 -> 123500
A33: BÓ XÔI-HN KQ | D33: =B33*C33 -> 0
A34: BÓ XÔI-NA | D34: =B34*C34 -> 0
A35: BÔNG ATISO | D35: =B35*C35 -> 0
A36: BÔNG BÍ | D36: =B36*C36 -> 0
A37: BÔNG BÍ TÚI 300GR | D37: =B37*C37 -> 0
A38: BÔNG CẢI TRẮNG | D38: =B38*C38 -> 0
A39: BÔNG CẢI TRẮNG (CÂY) | D39: =B39*C39 -> 0
A40: BÔNG CẢI XANH 10P | B40: 10 | C40: 14000 | D40: =B40*C40 -> 140000
...

Sheet 13.4
A2: TÊN SẢN PHẨM | B2: TỒN TRƯỚC | C2: GIÁ NHẬP | D2: THÀNH TIỀN
A3: BẮP CẢI TÍM | B3: =25+17 -> 42 | C3: 13000 | D3: =B3*C3 -> 546000
A4: BẮP CẢI TÍM (BẮP) | D4: =B4*C4 -> 0
A5: BẮP CẢI TÍM SUSHI | D5: =B5*C5 -> 0
A6: BẮP CẢI TRẮNG | D6: =B6*C6 -> 0
A7: BẮP CẢI TRẮNG (BẮP) | D7: =B7*C7 -> 0
A8: BẮP CẢI TRẮNG MỘC CHÂU | D8: =B8*C8 -> 0
A9: BẮP CẢI TRẮNG SÓI BIỂN | D9: =B9*C9 -> 0
A10: BẮP CẢI TRẮNG SUSHI | D10: =B10*C10 -> 0
A11: BẮP MỸ | D11: =B11*C11 -> 0
A12: BẦU | D12: =B12*C12 -> 0
A13: BÍ ĐAO XANH | D13: =B13*C13 -> 0
A14: BÍ ĐAO XANH 400G | D14: =B14*C14 -> 0
A15: BÍ ĐỎ HỒ LÔ | B15: 15 | C15: 10000 | D15: =B15*C15 -> 150000
A16: BÍ ĐỎ MINI | D16: =B16*C16 -> 0
A17: BÍ ĐỎ NON (KG)KQ | D17: =B17*C17 -> 0
A18: BÍ ĐỎ NON TRÁI VR | D18: =B18*C18 -> 0
A19: BÍ ĐỎ NON( KG) VR | D19: =B19*C19 -> 0
A20: BÍ ĐỎ TRÒN | D20: =B20*C20 -> 0
A21: BÍ MINI VÀNG 300GR | D21: =B21*C21 -> 0
A22: BÍ MINI VÀNG KG | D22: =B22*C22 -> 0
A23: BÍ NGÒI VÀNG | D23: =B23*C23 -> 0
A24: BÍ NGÒI VÀNG (TRÁI) | D24: =B24*C24 -> 0
A25: BÍ NGÒI XANH | B25: =7+20+15 -> 42 | C25: 7000 | D25: =B25*C25 -> 294000
A26: BÍ NGÒI XANH(TRÁI) | D26: =B26*C26 -> 0
A27: BÍ NHẬT | D27: =B27*C27 -> 0
A28: BƠ 034 | D28: =B28*C28 -> 0
A29: BƠ BOOTH | B29: 18 | C29: 50000 | D29: =B29*C29 -> 900000
A30: BƠ SÁP | D30: =B30*C30 -> 0
A31: BÓ XÔI | D31: =B31*C31 -> 0
A32: BÓ XÔI 300G VR | B32: 6 | C32: 11500 | D32: =B32*C32 -> 69000
A33: BÓ XÔI-HN KQ | D33: =B33*C33 -> 0
A34: BÓ XÔI-NA | D34: =B34*C34 -> 0
A35: BÔNG ATISO | D35: =B35*C35 -> 0
A36: BÔNG BÍ | D36: =B36*C36 -> 0
A37: BÔNG BÍ TÚI 300GR | D37: =B37*C37 -> 0
A38: BÔNG CẢI TRẮNG | D38: =B38*C38 -> 0
A39: BÔNG CẢI TRẮNG (CÂY) | D39: =B39*C39 -> 0
A40: BÔNG CẢI XANH 10P | B40: 11 | C40: 16000 | D40: =B40*C40 -> 176000
A41: BÔNG CẢI XANH AEON | D41: =B41*C41 -> 0
...

Sheet 14.4
A1: hàng tồn cuối ngày 14/4 vr
A2: TÊN SẢN PHẨM | B2: TỒN TRƯỚC | C2: GIÁ NHẬP | D2: THÀNH TIỀN
A3: BẮP CẢI TÍM | B3: 13 | C3: 13000 | D3: =B3*C3 -> 169000
A4: BẮP CẢI TÍM (BẮP) | D4: =B4*C4 -> 0
A5: BẮP CẢI TÍM SUSHI | D5: =B5*C5 -> 0
A6: BẮP CẢI TRẮNG | D6: =B6*C6 -> 0
A7: BẮP CẢI TRẮNG (BẮP) | D7: =B7*C7 -> 0
A8: BẮP CẢI TRẮNG MỘC CHÂU | D8: =B8*C8 -> 0
A9: BẮP CẢI TRẮNG SÓI BIỂN | D9: =B9*C9 -> 0
A10: BẮP CẢI TRẮNG SUSHI | D10: =B10*C10 -> 0
A11: BẮP MỸ | D11: =B11*C11 -> 0
A12: BẦU | D12: =B12*C12 -> 0
A13: BÍ ĐAO XANH | D13: =B13*C13 -> 0
A14: BÍ ĐAO XANH 400G | D14: =B14*C14 -> 0
A15: BÍ ĐỎ HỒ LÔ | B15: 30 | C15: 10000 | D15: =B15*C15 -> 300000
A16: BÍ ĐỎ MINI | D16: =B16*C16 -> 0
A17: BÍ ĐỎ NON (KG)KQ | D17: =B17*C17 -> 0
A18: BÍ ĐỎ NON TRÁI VR | D18: =B18*C18 -> 0
A19: BÍ ĐỎ NON( KG) VR | D19: =B19*C19 -> 0
A20: BÍ ĐỎ TRÒN | D20: =B20*C20 -> 0
A21: BÍ MINI VÀNG 300GR | D21: =B21*C21 -> 0
A22: BÍ MINI VÀNG KG | D22: =B22*C22 -> 0
A23: BÍ NGÒI VÀNG | D23: =B23*C23 -> 0
A24: BÍ NGÒI VÀNG (TRÁI) | D24: =B24*C24 -> 0
A25: BÍ NGÒI XANH | B25: =45+30+15+20 -> 110 | C25: 7000 | D25: =B25*C25 -> 770000
A26: BÍ NGÒI XANH(TRÁI) | D26: =B26*C26 -> 0
A27: BÍ NHẬT | D27: =B27*C27 -> 0
A28: BƠ 034 | B28: 18 | C28: 50000 | D28: =B28*C28 -> 900000
A29: BƠ BOOTH | D29: =B29*C29 -> 0
A30: BƠ SÁP | D30: =B30*C30 -> 0
A31: BÓ XÔI | D31: =B31*C31 -> 0
A32: BÓ XÔI 300G VR | B32: 9 | C32: 11500 | D32: =B32*C32 -> 103500
A33: BÓ XÔI-HN KQ | D33: =B33*C33 -> 0
A34: BÓ XÔI-NA | D34: =B34*C34 -> 0
A35: BÔNG ATISO | D35: =B35*C35 -> 0
A36: BÔNG BÍ | B36: 0.5 | C36: 45000 | D36: =B36*C36 -> 22500
A37: BÔNG BÍ TÚI 300GR | D37: =B37*C37 -> 0
A38: BÔNG CẢI TRẮNG | D38: =B38*C38 -> 0
A39: BÔNG CẢI TRẮNG (CÂY) | D39: =B39*C39 -> 0
A40: BÔNG CẢI XANH 10P | D40: =B40*C40 -> 0
...

Sheet 15.4
A1: hàng tồn cuối ngày 15/4 vr
A2: TÊN SẢN PHẨM | B2: TỒN TRƯỚC | C2: GIÁ NHẬP | D2: THÀNH TIỀN
A3: BẮP CẢI TÍM | D3: =B3*C3 -> 0
A4: BẮP CẢI TÍM (BẮP) | D4: =B4*C4 -> 0
A5: BẮP CẢI TÍM SUSHI | D5: =B5*C5 -> 0
A6: BẮP CẢI TRẮNG | D6: =B6*C6 -> 0
A7: BẮP CẢI TRẮNG (BẮP) | D7: =B7*C7 -> 0
A8: BẮP CẢI TRẮNG MỘC CHÂU | D8: =B8*C8 -> 0
A9: BẮP CẢI TRẮNG SÓI BIỂN | D9: =B9*C9 -> 0
A10: BẮP CẢI TRẮNG SUSHI | D10: =B10*C10 -> 0
A11: BẮP MỸ | D11: =B11*C11 -> 0
A12: BẦU | D12: =B12*C12 -> 0
A13: BÍ ĐAO XANH | D13: =B13*C13 -> 0
A14: BÍ ĐAO XANH 400G | D14: =B14*C14 -> 0
... A17: BÍ ĐỎ NON (KG)KQ | D17: =B17*C17 -> 0
A18: BÍ ĐỎ NON TRÁI VR | B18: =20+35 -> 55 | C18: 4000 | D18: =B18*C18 -> 220000
A19: BÍ ĐỎ NON( KG) VR | D19: =B19*C19 -> 0
A20: BÍ ĐỎ TRÒN | D20: =B20*C20 -> 0
A21: BÍ MINI VÀNG 300GR | D21: =B21*C21 -> 0
A22: BÍ MINI VÀNG KG | D22: =B22*C22 -> 0
A23: BÍ NGÒI VÀNG | D23: =B23*C23 -> 0
A24: BÍ NGÒI VÀNG (TRÁI) | D24: =B24*C24 -> 0
A25: BÍ NGÒI XANH | D25: =B25*C25 -> 0
A26: BÍ NGÒI XANH(TRÁI) | D26: =B26*C26 -> 0
A27: BÍ NHẬT | D27: =B27*C27 -> 0
A28: BƠ 034 | D28: =B28*C28 -> 0
A29: BƠ BOOTH | D29: =B29*C29 -> 0
A30: BƠ SÁP | D30: =B30*C30 -> 0
... A55: CÀ CHUA BI-NA | D55: =B55*C55 -> 0
A56: CÀ CHUA CHERRY MIX 300G | B56: 8 | C56: 10000 | D56: =B56*C56 -> 80000
A57: CÀ CHUA L1 | D57: =B57*C57 -> 0
A58: CÀ CHUA MỘC CHÂU | D58: =B58*C58 -> 0
A59: CÀ CHUA NGỌT | D59: =B59*C59 -> 0
A60: CÀ CHUA NGỌT 300GR (KG) | D60: =B60*C60 -> 0
A61: CÀ CHUA NGỌT XÁ | D61: =B61*C61 -> 0
A62: CÀ CHUA ROSEBERRY 300G | D62: =B62*C62 -> 0
A63: CÀ CHUA SÔCOLA 250GR (HỘP) VR | B63: 32 | C63: 5500 | D63: =B63*C63 -> 176000
A64: CÀ CHUA SÔCOLA 250GR (KG) -NA | D64: =B64*C64 -> 0
A65: CÀ CHUA SÔCOLA 250GR (KG) VR | D65: =B65*C65 -> 0
A66: CÀ CHUA SÔCOLA 250GR(KG) KQ | D66: =B66*C66 -> 0
...

Sheet 16.4
A1: hàng tồn cuối ngày 16/4 VR
A2: TÊN SẢN PHẨM | B2: TỒN TRƯỚC | C2: GIÁ NHẬP | D2: THÀNH TIỀN
A3: BẮP CẢI TÍM | D3: =B3*C3 -> 0
A4: BẮP CẢI TÍM (BẮP) | D4: =B4*C4 -> 0
A5: BẮP CẢI TÍM SUSHI | D5: =B5*C5 -> 0
A6: BẮP CẢI TRẮNG | D6: =B6*C6 -> 0
A7: BẮP CẢI TRẮNG (BẮP) | D7: =B7*C7 -> 0
A8: BẮP CẢI TRẮNG MỘC CHÂU | D8: =B8*C8 -> 0
A9: BẮP CẢI TRẮNG SÓI BIỂN | D9: =B9*C9 -> 0
A10: BẮP CẢI TRẮNG SUSHI | D10: =B10*C10 -> 0
A11: BẮP MỸ | D11: =B11*C11 -> 0
A12: BẦU | D12: =B12*C12 -> 0
A13: BÍ ĐAO XANH | D13: =B13*C13 -> 0
A14: BÍ ĐAO XANH 400G | D14: =B14*C14 -> 0
... A24: BÍ NGÒI VÀNG (TRÁI) | D24: =B24*C24 -> 0
A25: BÍ NGÒI XANH | B25: =12+13+46+12+50+15 -> 148 | C25: 7000 | D25: =B25*C25 -> 1036000
A26: BÍ NGÒI XANH(TRÁI) | D26: =B26*C26 -> 0
A27: BÍ NHẬT | D27: =B27*C27 -> 0
A28: BƠ 034 | B28: 72 | C28: 48000 | D28: =B28*C28 -> 3456000
A29: BƠ BOOTH | D29: =B29*C29 -> 0
A30: BƠ SÁP | D30: =B30*C30 -> 0
A31: BÓ XÔI | D31: =B31*C31 -> 0
A32: BÓ XÔI 300G VR | D32: =B32*C32 -> 0
A33: BÓ XÔI-HN KQ | D33: =B33*C33 -> 0
A34: BÓ XÔI-NA | D34: =B34*C34 -> 0
A35: BÔNG ATISO | D35: =B35*C35 -> 0
A36: BÔNG BÍ | D36: =B36*C36 -> 0
A37: BÔNG BÍ TÚI 300GR | D37: =B37*C37 -> 0
A38: BÔNG CẢI TRẮNG | D38: =B38*C38 -> 0
A39: BÔNG CẢI TRẮNG (CÂY) | D39: =B39*C39 -> 0
A40: BÔNG CẢI XANH 10P | D40: =B40*C40 -> 0
A41: BÔNG CẢI XANH AEON | B41: 28 | C41: 24000 | D41: =B41*C41 -> 672000
A42: BÔNG CẢI XANH AEON (CÂY) | D42: =B42*C42 -> 0
A43: BÔNG CẢI XANH BABY (KG) | D43: =B43*C43 -> 0
A44: BÔNG CẢI XANH BABY 200G | D44: =B44*C44 -> 0
A45: BÔNG CẢI XANH BIGC | D45: =B45*C45 -> 0
A46: BÔNG CẢI XANH CITI | D46: =B46*C46 -> 0
A47: CÀ CHUA | D47: =B47*C47 -> 0
A48: CÀ CHUA BI | D48: =B48*C48 -> 0
A49: CÀ CHUA BI (HỘP) 300GR KQ | D49: =B49*C49 -> 0
...

Sheet 17.4
A1: 45399 | C1: Stock
A2: TÊN SẢN PHẨM VR | B2: ĐVT | C2: TỒN TRƯỚC | D2: GIÁ NHẬP | E2: THÀNH TIỀN
A4: BẮP CẢI TÍM | B4: Kg
A5: BẮP CẢI TÍM (BẮP) | B5: BẮP
A6: BẮP CẢI TÍM SUSHI | B6: Kg
A7: BẮP CẢI TRẮNG | B7: Kg
A8: BẮP CẢI TRẮNG (BẮP) | B8: BẮP
A9: BẮP CẢI TRẮNG MỘC CHÂU | B9: Kg
A10: BẮP CẢI TRẮNG SÓI BIỂN | B10: Kg
A11: BẮP CẢI TRẮNG SUSHI | B11: Kg
A12: BẮP MỸ | B12: Kg
A13: BẦU | B13: Kg
A14: BÍ ĐAO XANH | B14: Kg
A15: BÍ ĐAO XANH 400G | B15: TRÁI
A16: BÍ ĐỎ HỒ LÔ | B16: Kg | C16: 40 | D16: 11000 | E16: =+D16*C16 -> 440000
A17: BÍ ĐỎ MINI | B17: Kg
A18: BÍ ĐỎ NON (KG)KQ | B18: Kg
A19: BÍ ĐỎ NON TRÁI VR | B19: TRÁI | C19: 40 | D19: =13000*0.3 -> 3900 | E19: =+D19*C19 -> 156000
A20: BÍ ĐỎ NON( KG) VR | B20: Kg
A21: BÍ ĐỎ TRÒN | B21: Kg
A22: BÍ MINI VÀNG 300GR | B22: TRÁI
A23: BÍ MINI VÀNG KG | B23: Kg
A24: BÍ NGÒI VÀNG | B24: Kg
A25: BÍ NGÒI VÀNG (TRÁI) | B25: TRÁI
A26: BÍ NGÒI XANH | B26: Kg | C26: 83 | D26: 7500 | E26: =+D26*C26 -> 622500
A27: BÍ NGÒI XANH(TRÁI) | B27: TRÁI
A28: BÍ NHẬT | B28: Kg
A29: BƠ 034 | B29: Kg | C29: 9 | D29: 45000 | E29: =+D29*C29 -> 405000
A30: BƠ BOOTH | B30: Kg
A31: BƠ SÁP | B31: Kg | E31: =+D31*C31 -> 0
A32: BÓ XÔI | B32: Kg | C32: 8 | D32: 29000 | E32: =+D32*C32 -> 232000
A33: BÓ XÔI 300G VR | B33: TÚI | C33: 30 | D33: =33000*0.3 -> 9900 | E33: =+D33*C33 -> 297000
A34: BÓ XÔI-HN KQ | B34: Kg
A35: BÓ XÔI-NA | B35: Kg
A36: BÔNG ATISO | B36: Kg
A37: BÔNG BÍ | B37: Kg | C37: 0.5 | D37: 45000 | E37: =+D37*C37 -> 22500
A38: BÔNG BÍ TÚI 300GR | B38: VỈ
A39: BÔNG CẢI TRẮNG | B39: Kg
A40: BÔNG CẢI TRẮNG (CÂY) | B40: CÂY
A41: BÔNG CẢI XANH 10P | B41: Kg | C41: 6 | D41: 21000 | E41: =+D41*C41 -> 126000
...

Sheet 18.4
A1: 45400 | C1: Stock
A2: TÊN SẢN PHẨM VR | B2: ĐVT | C2: TỒN TRƯỚC | D2: GIÁ NHẬP | E2: THÀNH TIỀN
A4: BẮP CẢI TÍM | B4: Kg
A5: BẮP CẢI TÍM (BẮP) | B5: BẮP
A6: BẮP CẢI TÍM SUSHI | B6: Kg
A7: BẮP CẢI TRẮNG | B7: Kg
A8: BẮP CẢI TRẮNG (BẮP) | B8: BẮP
A9: BẮP CẢI TRẮNG MỘC CHÂU | B9: Kg
A10: BẮP CẢI TRẮNG SÓI BIỂN | B10: Kg
A11: BẮP CẢI TRẮNG SUSHI | B11: Kg
A12: BẮP MỸ | B12: Kg
A13: BẦU | B13: Kg
A14: BÍ ĐAO XANH | B14: Kg
A15: BÍ ĐAO XANH 400G | B15: TRÁI
... A19: BÍ ĐỎ NON TRÁI VR | B19: TRÁI
A20: BÍ ĐỎ NON( KG) VR | B20: Kg | C20: 25 | D20: 13000 | E20: 325000
A21: BÍ ĐỎ TRÒN | B21: Kg
A22: BÍ MINI VÀNG 300GR | B22: TRÁI
A23: BÍ MINI VÀNG KG | B23: Kg
A24: BÍ NGÒI VÀNG | B24: Kg
A25: BÍ NGÒI VÀNG (TRÁI) | B25: TRÁI
A26: BÍ NGÒI XANH | B26: Kg | C26: 106 | D26: 7500 | E26: 795000
A27: BÍ NGÒI XANH(TRÁI) | B27: TRÁI
A28: BÍ NHẬT | B28: Kg
A29: BƠ 034 | B29: Kg | C29: 70 | D29: 45000 | E29: 3150000
A30: BƠ BOOTH | B30: Kg
A31: BƠ SÁP | B31: Kg
A32: BÓ XÔI | B32: Kg
A33: BÓ XÔI 300G VR | B33: TÚI | C33: 30 | D33: 9900 | E33: 297000
A34: BÓ XÔI-HN KQ | B34: Kg
A35: BÓ XÔI-NA | B35: Kg
A36: BÔNG ATISO | B36: Kg
A37: BÔNG BÍ | B37: Kg | C37: 0.5 | D37: 45000 | E37: 22500
A38: BÔNG BÍ TÚI 300GR | B38: VỈ
A39: BÔNG CẢI TRẮNG | B39: Kg
A40: BÔNG CẢI TRẮNG (CÂY) | B40: CÂY
A41: BÔNG CẢI XANH 10P | B41: Kg
A42: BÔNG CẢI XANH AEON | B42: Kg
A43: BÔNG CẢI XANH AEON (CÂY) | B43: CÂY
A44: BÔNG CẢI XANH BABY (KG) | B44: Kg
...

Sheet 19.4
A1: hàng tồn cuối ngày 19/4 vr
A2: TÊN SẢN PHẨM | B2: TỒN TRƯỚC | C2: GIÁ NHẬP | D2: THÀNH TIỀN
A3: BẮP CẢI TÍM | D3: =B3*C3 -> 0
A4: BẮP CẢI TÍM (BẮP) | D4: =B4*C4 -> 0
A5: BẮP CẢI TÍM SUSHI | D5: =B5*C5 -> 0
A6: BẮP CẢI TRẮNG | D6: =B6*C6 -> 0
A7: BẮP CẢI TRẮNG (BẮP) | D7: =B7*C7 -> 0
A8: BẮP CẢI TRẮNG MỘC CHÂU | D8: =B8*C8 -> 0
A9: BẮP CẢI TRẮNG SÓI BIỂN | D9: =B9*C9 -> 0
A10: BẮP CẢI TRẮNG SUSHI | D10: =B10*C10 -> 0
A11: BẮP MỸ | D11: =B11*C11 -> 0
A12: BẦU | D12: =B12*C12 -> 0
A13: BÍ ĐAO XANH | D13: =B13*C13 -> 0
A14: BÍ ĐAO XANH 400G | D14: =B14*C14 -> 0
A15: BÍ ĐỎ HỒ LÔ | B15: 9 | C15: 10000 | D15: =B15*C15 -> 90000
A16: BÍ ĐỎ MINI | D16: =B16*C16 -> 0
A17: BÍ ĐỎ NON (KG)KQ | D17: =B17*C17 -> 0
A18: BÍ ĐỎ NON TRÁI VR | D18: =B18*C18 -> 0
A19: BÍ ĐỎ NON( KG) VR | D19: =B19*C19 -> 0
A20: BÍ ĐỎ TRÒN | D20: =B20*C20 -> 0
A21: BÍ MINI VÀNG 300GR | D21: =B21*C21 -> 0
A22: BÍ MINI VÀNG KG | D22: =B22*C22 -> 0
A23: BÍ NGÒI VÀNG | D23: =B23*C23 -> 0
A24: BÍ NGÒI VÀNG (TRÁI) | D24: =B24*C24 -> 0
A25: BÍ NGÒI XANH | B25: =10+37+40 -> 87 | C25: 7000 | D25: =B25*C25 -> 609000
A26: BÍ NGÒI XANH(TRÁI) | D26: =B26*C26 -> 0
A27: BÍ NHẬT | D27: =B27*C27 -> 0
A28: BƠ 034 | D28: =B28*C28 -> 0
A29: BƠ BOOTH | D29: =B29*C29 -> 0
A30: BƠ SÁP | D30: =B30*C30 -> 0
A31: BÓ XÔI | D31: =B31*C31 -> 0
A32: BÓ XÔI 300G VR | D32: =B32*C32 -> 0
A33: BÓ XÔI-HN KQ | D33: =B33*C33 -> 0
A34: BÓ XÔI-NA | D34: =B34*C34 -> 0
A35: BÔNG ATISO | D35: =B35*C35 -> 0
A36: BÔNG BÍ | D36: =B36*C36 -> 0
A37: BÔNG BÍ TÚI 300GR | D37: =B37*C37 -> 0
... A39: BÔNG CẢI TRẮNG (CÂY) | D39: =B39*C39 -> 0
A40: BÔNG CẢI XANH 10P | B40: 3 | C40: 21000 | D40: =B40*C40 -> 63000
A41: BÔNG CẢI XANH AEON | B41: =35+24-20 -> 39 | C41: 27000 | D41: =B41*C41 -> 1053000
...

Sheet 20.4
A1: hàng tồn cuối ngày 20/4 vr
A2: TÊN SẢN PHẨM | B2: TỒN TRƯỚC | C2: GIÁ NHẬP | D2: THÀNH TIỀN
A3: BẮP CẢI TÍM | D3: =B3*C3 -> 0
A4: BẮP CẢI TÍM (BẮP) | D4: =B4*C4 -> 0
A5: BẮP CẢI TÍM SUSHI | D5: =B5*C5 -> 0
A6: BẮP CẢI TRẮNG | D6: =B6*C6 -> 0
A7: BẮP CẢI TRẮNG (BẮP) | D7: =B7*C7 -> 0
A8: BẮP CẢI TRẮNG MỘC CHÂU | D8: =B8*C8 -> 0
A9: BẮP CẢI TRẮNG SÓI BIỂN | D9: =B9*C9 -> 0
A10: BẮP CẢI TRẮNG SUSHI | D10: =B10*C10 -> 0
A11: BẮP MỸ | D11: =B11*C11 -> 0
A12: BẦU | D12: =B12*C12 -> 0
A13: BÍ ĐAO XANH | D13: =B13*C13 -> 0
A14: BÍ ĐAO XANH 400G | D14: =B14*C14 -> 0
A15: BÍ ĐỎ HỒ LÔ | B15: 47 | C15: 10000 | D15: =B15*C15 -> 470000
A16: BÍ ĐỎ MINI | D16: =B16*C16 -> 0
A17: BÍ ĐỎ NON (KG)KQ | D17: =B17*C17 -> 0
A18: BÍ ĐỎ NON TRÁI VR | D18: =B18*C18 -> 0
A19: BÍ ĐỎ NON( KG) VR | B19: =18+19 -> 37 | C19: 10000 | D19: =B19*C19 -> 370000
A20: BÍ ĐỎ TRÒN | D20: =B20*C20 -> 0
A21: BÍ MINI VÀNG 300GR | D21: =B21*C21 -> 0
A22: BÍ MINI VÀNG KG | D22: =B22*C22 -> 0
A23: BÍ NGÒI VÀNG | D23: =B23*C23 -> 0
A24: BÍ NGÒI VÀNG (TRÁI) | D24: =B24*C24 -> 0
A25: BÍ NGÒI XANH | B25: =75+60 -> 135 | C25: 7000 | D25: =B25*C25 -> 945000
A26: BÍ NGÒI XANH(TRÁI) | D26: =B26*C26 -> 0
A27: BÍ NHẬT | D27: =B27*C27 -> 0
A28: BƠ 034 | D28: =B28*C28 -> 0
A29: BƠ BOOTH | D29: =B29*C29 -> 0
A30: BƠ SÁP | D30: =B30*C30 -> 0
A31: BÓ XÔI | D31: =B31*C31 -> 0
A32: BÓ XÔI 300G VR | D32: =B32*C32 -> 0
A33: BÓ XÔI-HN KQ | D33: =B33*C33 -> 0
A34: BÓ XÔI-NA | D34: =B34*C34 -> 0
A35: BÔNG ATISO | D35: =B35*C35 -> 0
A36: BÔNG BÍ | D36: =B36*C36 -> 0
A37: BÔNG BÍ TÚI 300GR | D37: =B37*C37 -> 0
A38: BÔNG CẢI TRẮNG | B38: 8 | C38: 13000 | D38: =B38*C38 -> 104000
A39: BÔNG CẢI TRẮNG (CÂY) | D39: =B39*C39 -> 0
A40: BÔNG CẢI XANH 10P | D40: =B40*C40 -> 0
...

Sheet 21.4
A1: hàng tồn cuối ngày 21/4 vr
A2: TÊN SẢN PHẨM | B2: TỒN TRƯỚC | C2: GIÁ NHẬP | D2: THÀNH TIỀN
A3: BẮP CẢI TÍM | B3: 5 | C3: 13000 | D3: =B3*C3 -> 65000
A4: BẮP CẢI TÍM (BẮP) | D4: =B4*C4 -> 0
A5: BẮP CẢI TÍM SUSHI | D5: =B5*C5 -> 0
A6: BẮP CẢI TRẮNG | D6: =B6*C6 -> 0
A7: BẮP CẢI TRẮNG (BẮP) | D7: =B7*C7 -> 0
A8: BẮP CẢI TRẮNG MỘC CHÂU | D8: =B8*C8 -> 0
A9: BẮP CẢI TRẮNG SÓI BIỂN | D9: =B9*C9 -> 0
A10: BẮP CẢI TRẮNG SUSHI | D10: =B10*C10 -> 0
A11: BẮP MỸ | D11: =B11*C11 -> 0
A12: BẦU | D12: =B12*C12 -> 0
A13: BÍ ĐAO XANH | D13: =B13*C13 -> 0
A14: BÍ ĐAO XANH 400G | D14: =B14*C14 -> 0
A15: BÍ ĐỎ HỒ LÔ | B15: 27 | C15: 10000 | D15: =B15*C15 -> 270000
A16: BÍ ĐỎ MINI | D16: =B16*C16 -> 0
A17: BÍ ĐỎ NON (KG)KQ | D17: =B17*C17 -> 0
A18: BÍ ĐỎ NON TRÁI VR | B18: =60+8+18 -> 86 | C18: 4000 | D18: =B18*C18 -> 344000
A19: BÍ ĐỎ NON( KG) VR | B19: 31 | C19: 12000 | D19: =B19*C19 -> 372000
A20: BÍ ĐỎ TRÒN | D20: =B20*C20 -> 0
A21: BÍ MINI VÀNG 300GR | D21: =B21*C21 -> 0
A22: BÍ MINI VÀNG KG | D22: =B22*C22 -> 0
A23: BÍ NGÒI VÀNG | D23: =B23*C23 -> 0
A24: BÍ NGÒI VÀNG (TRÁI) | D24: =B24*C24 -> 0
A25: BÍ NGÒI XANH | B25: 90 | C25: 7000 | D25: =B25*C25 -> 630000
A26: BÍ NGÒI XANH(TRÁI) | D26: =B26*C26 -> 0
A27: BÍ NHẬT | D27: =B27*C27 -> 0
A28: BƠ 034 | B28: 18 | C28: 44000 | D28: =B28*C28 -> 792000
A29: BƠ BOOTH | D29: =B29*C29 -> 0
A30: BƠ SÁP | B30: 40 | C30: 28000 | D30: =B30*C30 -> 1120000
A31: BÓ XÔI | D31: =B31*C31 -> 0
A32: BÓ XÔI 300G VR | B32: 3 | C32: 9500 | D32: =B32*C32 -> 28500
A33: BÓ XÔI-HN KQ | D33: =B33*C33 -> 0
A34: BÓ XÔI-NA | D34: =B34*C34 -> 0
A35: BÔNG ATISO | D35: =B35*C35 -> 0
A36: BÔNG BÍ | D36: =B36*C36 -> 0
A37: BÔNG BÍ TÚI 300GR | D37: =B37*C37 -> 0
A38: BÔNG CẢI TRẮNG | B38: 3 | C38: 13000 | D38: =B38*C38 -> 39000
A39: BÔNG CẢI TRẮNG (CÂY) | D39: =B39*C39 -> 0
A40: BÔNG CẢI XANH 10P | B40: 20 | C40: 21000 | D40: =B40*C40 -> 420000
...

Sheet 22.4
A1: hàng tồn cuối ngày 22/4 vr
A2: TÊN SẢN PHẨM | B2: TỒN TRƯỚC | C2: GIÁ NHẬP | D2: THÀNH TIỀN
A3: BẮP CẢI TÍM | B3: 10 | C3: 13000 | D3: =B3*C3 -> 130000
A4: BẮP CẢI TÍM (BẮP) | D4: =B4*C4 -> 0
A5: BẮP CẢI TÍM SUSHI | D5: =B5*C5 -> 0
A6: BẮP CẢI TRẮNG | D6: =B6*C6 -> 0
A7: BẮP CẢI TRẮNG (BẮP) | D7: =B7*C7 -> 0
A8: BẮP CẢI TRẮNG MỘC CHÂU | D8: =B8*C8 -> 0
A9: BẮP CẢI TRẮNG SÓI BIỂN | D9: =B9*C9 -> 0
A10: BẮP CẢI TRẮNG SUSHI | D10: =B10*C10 -> 0
A11: BẮP MỸ | D11: =B11*C11 -> 0
A12: BẦU | D12: =B12*C12 -> 0
A13: BÍ ĐAO XANH | D13: =B13*C13 -> 0
A14: BÍ ĐAO XANH 400G | D14: =B14*C14 -> 0
A15: BÍ ĐỎ HỒ LÔ | B15: 12 | C15: 10000 | D15: =B15*C15 -> 120000
A16: BÍ ĐỎ MINI | D16: =B16*C16 -> 0
A17: BÍ ĐỎ NON (KG)KQ | D17: =B17*C17 -> 0
A18: BÍ ĐỎ NON TRÁI VR | B18: 33 | C18: 4000 | D18: =B18*C18 -> 132000
A19: BÍ ĐỎ NON( KG) VR | B19: 31 | C19: 12000 | D19: =B19*C19 -> 372000
A20: BÍ ĐỎ TRÒN | D20: =B20*C20 -> 0
A21: BÍ MINI VÀNG 300GR | D21: =B21*C21 -> 0
A22: BÍ MINI VÀNG KG | D22: =B22*C22 -> 0
A23: BÍ NGÒI VÀNG | D23: =B23*C23 -> 0
A24: BÍ NGÒI VÀNG (TRÁI) | D24: =B24*C24 -> 0
A25: BÍ NGÒI XANH | B25: =45+10+25+21 -> 101 | C25: 7000 | D25: =B25*C25 -> 707000
A26: BÍ NGÒI XANH(TRÁI) | D26: =B26*C26 -> 0
A27: BÍ NHẬT | D27: =B27*C27 -> 0
A28: BƠ 034 | D28: =B28*C28 -> 0
A29: BƠ BOOTH | D29: =B29*C29 -> 0
A30: BƠ SÁP | B30: 26 | C30: 30000 | D30: =B30*C30 -> 780000
A31: BÓ XÔI | D31: =B31*C31 -> 0
A32: BÓ XÔI 300G VR | D32: =B32*C32 -> 0
A33: BÓ XÔI-HN KQ | D33: =B33*C33 -> 0
A34: BÓ XÔI-NA | D34: =B34*C34 -> 0
A35: BÔNG ATISO | D35: =B35*C35 -> 0
A36: BÔNG BÍ | D36: =B36*C36 -> 0
A37: BÔNG BÍ TÚI 300GR | D37: =B37*C37 -> 0
A38: BÔNG CẢI TRẮNG | D38: =B38*C38 -> 0
A39: BÔNG CẢI TRẮNG (CÂY) | D39: =B39*C39 -> 0
A40: BÔNG CẢI XANH 10P | B40: 4 | C40: 21000 | D40: =B40*C40 -> 84000
...

Sheet 23.4
A1: 45406 | C1: Stock
A2: TÊN SẢN PHẨM VR | B2: ĐVT | C2: TỒN TRƯỚC | D2: GIÁ NHẬP | E2: THÀNH TIỀN
A4: BẮP CẢI TÍM | B4: Kg
A5: BẮP CẢI TÍM (BẮP) | B5: BẮP
A6: BẮP CẢI TÍM SUSHI | B6: Kg
A7: BẮP CẢI TRẮNG | B7: Kg
A8: BẮP CẢI TRẮNG (BẮP) | B8: BẮP
A9: BẮP CẢI TRẮNG MỘC CHÂU | B9: Kg
A10: BẮP CẢI TRẮNG SÓI BIỂN | B10: Kg
A11: BẮP CẢI TRẮNG SUSHI | B11: Kg
A12: BẮP MỸ | B12: Kg
A13: BẦU | B13: Kg
A14: BÍ ĐAO XANH | B14: Kg
A15: BÍ ĐAO XANH 400G | B15: TRÁI
... A19: BÍ ĐỎ NON TRÁI VR | B19: TRÁI
A20: BÍ ĐỎ NON( KG) VR | B20: Kg | C20: 43 | D20: 12000 | E20: 516000
A21: BÍ ĐỎ TRÒN | B21: Kg
A22: BÍ MINI VÀNG 300GR | B22: TRÁI
A23: BÍ MINI VÀNG KG | B23: Kg
A24: BÍ NGÒI VÀNG | B24: Kg
A25: BÍ NGÒI VÀNG (TRÁI) | B25: TRÁI
A26: BÍ NGÒI XANH | B26: Kg | C26: 105 | D26: 7000 | E26: 735000
A27: BÍ NGÒI XANH(TRÁI) | B27: TRÁI
A28: BÍ NHẬT | B28: Kg
A29: BƠ 034 | B29: Kg | C29: 5 | D29: 45000 | E29: 225000
A30: BƠ BOOTH | B30: Kg
A31: BƠ SÁP | B31: Kg
A32: BÓ XÔI | B32: Kg
A33: BÓ XÔI 300G VR | B33: TÚI
A34: BÓ XÔI-HN KQ | B34: Kg
A35: BÓ XÔI-NA | B35: Kg
A36: BÔNG ATISO | B36: Kg
A37: BÔNG BÍ | B37: Kg
A38: BÔNG BÍ TÚI 300GR | B38: VỈ
A39: BÔNG CẢI TRẮNG | B39: Kg
A40: BÔNG CẢI TRẮNG (CÂY) | B40: CÂY
A41: BÔNG CẢI XANH 10P | B41: Kg
... A50: CÀ CHUA BI (HỘP) 300GR KQ | B50: HỘP
A51: CÀ CHUA BI (HỘP) 300GR VR | B51: HỘP | C51: 10 | D51: 5400 | E51: 54000
A52: CÀ CHUA BI 300GR KQ (KG) | B52: Kg
...

Sheet 24.4
A1: hàng tồn cuối ngày 24/4 vr
A2: TÊN SẢN PHẨM | B2: TỒN TRƯỚC | C2: GIÁ NHẬP | D2: THÀNH TIỀN
A3: BẮP CẢI TÍM | D3: =B3*C3 -> 0
A4: BẮP CẢI TÍM (BẮP) | D4: =B4*C4 -> 0
A5: BẮP CẢI TÍM SUSHI | D5: =B5*C5 -> 0
A6: BẮP CẢI TRẮNG | D6: =B6*C6 -> 0
A7: BẮP CẢI TRẮNG (BẮP) | D7: =B7*C7 -> 0
A8: BẮP CẢI TRẮNG MỘC CHÂU | D8: =B8*C8 -> 0
A9: BẮP CẢI TRẮNG SÓI BIỂN | D9: =B9*C9 -> 0
A10: BẮP CẢI TRẮNG SUSHI | D10: =B10*C10 -> 0
A11: BẮP MỸ | D11: =B11*C11 -> 0
A12: BẦU | D12: =B12*C12 -> 0
A13: BÍ ĐAO XANH | D13: =B13*C13 -> 0
A14: BÍ ĐAO XANH 400G | D14: =B14*C14 -> 0
... A17: BÍ ĐỎ NON (KG)KQ | D17: =B17*C17 -> 0
A18: BÍ ĐỎ NON TRÁI VR | B18: =38+18+24+35 -> 115 | C18: 4000 | D18: =B18*C18 -> 460000
A19: BÍ ĐỎ NON( KG) VR | B19: 16 | C19: 12000 | D19: =B19*C19 -> 192000
A20: BÍ ĐỎ TRÒN | D20: =B20*C20 -> 0
A21: BÍ MINI VÀNG 300GR | D21: =B21*C21 -> 0
A22: BÍ MINI VÀNG KG | D22: =B22*C22 -> 0
A23: BÍ NGÒI VÀNG | D23: =B23*C23 -> 0
A24: BÍ NGÒI VÀNG (TRÁI) | D24: =B24*C24 -> 0
A25: BÍ NGÒI XANH | B25: =25+95 -> 120 | C25: 7000 | D25: =B25*C25 -> 840000
A26: BÍ NGÒI XANH(TRÁI) | D26: =B26*C26 -> 0
A27: BÍ NHẬT | D27: =B27*C27 -> 0
A28: BÓ XÔI | D28: =B28*C28 -> 0
A29: BÓ XÔI 300G VR | D29: =B29*C29 -> 0
A30: BÓ XÔI-HN KQ | D30: =B30*C30 -> 0
A31: BÓ XÔI-NA | D31: =B31*C31 -> 0
A32: BÔNG ATISO | D32: =B32*C32 -> 0
A33: BÔNG BÍ | D33: =B33*C33 -> 0
A34: BÔNG BÍ TÚI 300GR | D34: =B34*C34 -> 0
A35: BÔNG CẢI TRẮNG | D35: =B35*C35 -> 0
A36: BÔNG CẢI TRẮNG (CÂY) | D36: =B36*C36 -> 0
A37: BÔNG CẢI XANH 10P | D37: =B37*C37 -> 0
... A43: BÔNG CẢI XANH CITI | D43: =B43*C43 -> 0
A44: BƠ 034 | B44: =90+24+30+45-50 -> 139 | C44: 42000 | D44: =B44*C44 -> 5838000
A45: BƠ BOOTH | D45: =B45*C45 -> 0
A46: BƠ SÁP | B46: 40 | C46: 23000 | D46: =B46*C46 -> 920000
A47: CÀ CHUA | D47: =B47*C47 -> 0
...

Sheet 25.4
A1: hàng tồn cuối ngày 25/4 vr
A2: TÊN SẢN PHẨM | B2: TỒN TRƯỚC | C2: GIÁ NHẬP | D2: THÀNH TIỀN
A3: CÀ CHUA SÔCOLA 250GR (HỘP) VR | B3: 12 | C3: 5000 | D3: =B3*C3 -> 60000
A4: CÀ CHUA SÔCOLA 250GR (KG) -NA | D4: =B4*C4 -> 0
A5: CÀ CHUA SÔCOLA 250GR (KG) VR | D5: =B5*C5 -> 0
A6: CÀ CHUA SÔCOLA 250GR(KG) KQ | D6: =B6*C6 -> 0
A7: CÀ CHUA SÔCOLA 300GR (HỘP) VR | D7: =B7*C7 -> 0
A8: CÀ CHUA SOCOLA XÁ | D8: =B8*C8 -> 0
A9: CÀ CHUA SÔCOLA(HỘP) KQ | D9: =B9*C9 -> 0
A10: CÀ RỐT BABY | D10: =B10*C10 -> 0
A11: CÀ RỐT BABY (KG) KQ | D11: =B11*C11 -> 0
A12: CÀ RỐT BABY 200GR | D12: =B12*C12 -> 0
A13: CẢI CẦU VỒNG | D13: =B13*C13 -> 0
A14: CẢI CẦU VỒNG 300GR | D14: =B14*C14 -> 0
A15: CẢI KALE | D15: =B15*C15 -> 0
A16: CẢI KALE 150GR | D16: =B16*C16 -> 0
A17: CẢI KALE 300GR | B17: 3 | C17: 6000 | D17: =B17*C17 -> 18000
A18: CHANH VÀNG (KG) | D18: =B18*C18 -> 0
A19: CHANH VÀNG TRÁI 180UP | D19: =B19*C19 -> 0
A20: CẦN TÂY (KG) | D20: =B20*C20 -> 0
A21: CẦN TÂY THUỶ CANH | D21: =B21*C21 -> 0
A22: CẦN TÂY(CÂY) | D22: =B22*C22 -> 0
A23: ỚT CHUÔNG 3 MÀU(KG)VR | D23: =B23*C23 -> 0
A24: ỚT CHUÔNG ĐỎ | B24: =170+74 -> 244 | C24: 39000 | D24: =B24*C24 -> 9516000
A25: ỚT CHUÔNG ĐỎ L1 | B25: 20 | C25: 25000 | D25: =B25*C25 -> 500000
A26: ỚT CHUÔNG ĐỎ(TRÁI) | D26: =B26*C26 -> 0
A27: ỚT CHUÔNG 3 MÀU 350G | B27: 6 | C27: 11000 | D27: =B27*C27 -> 66000
A28: ỚT CHUÔNG 3 MÀU KQ(KG) | D28: =B28*C28 -> 0
A29: ỚT CHUÔNG VÀNG | B29: =25+26+7+10 -> 68 | C29: 39000 | D29: =B29*C29 -> 2652000
A30: ỚT CHUÔNG VÀNG L1 | D30: =B30*C30 -> 0
A31: ỚT CHUÔNG VÀNG(TRÁI) | D31: =B31*C31 -> 0
A32: ỚT CHUÔNG VÀNG+ XANH (VỈ) | D32: =B32*C32 -> 0
A33: ỚT CHUÔNG XANH | B33: =6+10+21+10+40 -> 87 | C33: 18000 | D33: =B33*C33 -> 1566000
A34: ỚT CHUÔNG XANH L1 | D34: =B34*C34 -> 0
A35: ỚT CHUÔNG XANH(TRÁI) | D35: =B35*C35 -> 0
A36: CỦ DỀN | D36: =B36*C36 -> 0
A37: CỦ DỀN 600G | D37: =B37*C37 -> 0
A38: GỪNG 250GR | D38: =B38*C38 -> 0
A39: HỒNG GIÒN | D39: =B39*C39 -> 0
A40: XÀ LÁCH MỸ | D40: =B40*C40 -> 0
...

Sheet 26.4
A1: hàng tồn cuối ngày 26/4 vr
A2: TÊN SẢN PHẨM | B2: TỒN TRƯỚC | C2: GIÁ NHẬP | D2: THÀNH TIỀN
A3: CÀ CHUA SÔCOLA 250GR (HỘP) VR | B3: 22 | C3: 5000 | D3: =B3*C3 -> 110000
A4: CÀ CHUA SÔCOLA 250GR (KG) VR | D4: =B4*C4 -> 0
A5: CÀ CHUA SÔCOLA 300GR (HỘP) VR | D5: =B5*C5 -> 0
A6: CÀ RỐT BABY 200GR | D6: =B6*C6 -> 0
A7: CẢI CẦU VỒNG | D7: =B7*C7 -> 0
A8: CẢI CẦU VỒNG 300GR | D8: =B8*C8 -> 0
A9: CẢI KALE 150GR | D9: =B9*C9 -> 0
A10: CẢI KALE 300GR | B10: 3 | C10: 6000 | D10: =B10*C10 -> 18000
A11: CHANH VÀNG TRÁI 180UP | D11: =B11*C11 -> 0
A12: CẦN TÂY (KG) | D12: =B12*C12 -> 0
A13: CẦN TÂY(CÂY) | D13: =B13*C13 -> 0
A14: ỚT CHUÔNG 3 MÀU(KG)VR | D14: =B14*C14 -> 0
A15: ỚT CHUÔNG ĐỎ | B15: 175 | C15: 39000 | D15: =B15*C15 -> 6825000
A16: ỚT CHUÔNG ĐỎ(TRÁI) | D16: =B16*C16 -> 0
A17: ỚT CHUÔNG 3 MÀU 350G | B17: 10 | C17: 13000 | D17: =B17*C17 -> 130000
A18: ỚT CHUÔNG VÀNG | B18: 100 | C18: 40000 | D18: =B18*C18 -> 4000000
A19: ỚT CHUÔNG VÀNG(TRÁI) | D19: =B19*C19 -> 0
A20: ỚT CHUÔNG XANH | B20: 85 | C20: 20000 | D20: =B20*C20 -> 1700000
A21: ỚT CHUÔNG XANH(TRÁI) | D21: =B21*C21 -> 0
A22: CỦ DỀN | D22: =B22*C22 -> 0
A23: CỦ DỀN 600G | D23: =B23*C23 -> 0
A24: HỒNG GIÒN | D24: =B24*C24 -> 0
A25: XÀ LÁCH MỸ | D25: =B25*C25 -> 0
A26: KHOAI TÂY VÀNG | D26: =B26*C26 -> 0
A27: KHOAI TÂY VÀNG ĐL | D27: =B27*C27 -> 0
A28: KHOAI TÂY VÀNG LỚN TÚI LƯỚI 500G | D28: =B28*C28 -> 0
A29: KHOAI TÂY VÀNG TRUNG TÚI LƯỚI 500G | D29: =B29*C29 -> 0
A30: CẢI THẢO DL | D30: =B30*C30 -> 0
A31: CẢI THẢO DL(BẮP) | D31: =B31*C31 -> 0
A32: DƯA LEO | B32: 3 | C32: 5000 | D32: =B32*C32 -> 15000
A33: MƯỚP HƯƠNG | B33: 2 | C33: 10000 | D33: =B33*C33 -> 20000
A34: DƯA LEO GIỐNG NHẬT 600GR | D34: =B34*C34 -> 0
A35: DƯA LEO GIỐNG NHẬT KG | B35: 48 | C35: 9000 | D35: =B35*C35 -> 432000
A36: BƠ 034 | D36: =B36*C36 -> 0
A37: BƠ BOOTH | D37: =B37*C37 -> 0
A38: BƠ SÁP | B38: 10 | C38: 23000 | D38: =B38*C38 -> 230000
A39: KHOAI LANG MẬT (KG) 2-3 CỦ | B39: 390 | C39: 21000 | D39: =B39*C39 -> 8190000
A40: KHOAI LANG MẬT (KG) 4-6 CỦ | B40: 595 | C40: 20000 | D40: =B40*C40 -> 11900000
...

Sheet 27.4
A1: hàng tồn cuối ngày 27/9 vr
A2: TÊN SẢN PHẨM | B2: TỒN TRƯỚC | C2: GIÁ NHẬP | D2: THÀNH TIỀN
A3: BẮP CẢI TÍM | D3: =B3*C3 -> 0
A4: BẮP CẢI TÍM (BẮP) | D4: =B4*C4 -> 0
A5: BẮP CẢI TÍM SUSHI | D5: =B5*C5 -> 0
A6: BẮP CẢI TRẮNG | D6: =B6*C6 -> 0
A7: BẮP CẢI TRẮNG (BẮP) | D7: =B7*C7 -> 0
A8: BẮP CẢI TRẮNG MỘC CHÂU | D8: =B8*C8 -> 0
A9: BẮP CẢI TRẮNG SÓI BIỂN | D9: =B9*C9 -> 0
A10: BẮP CẢI TRẮNG SUSHI | D10: =B10*C10 -> 0
A11: BẮP MỸ | D11: =B11*C11 -> 0
A12: BẦU | D12: =B12*C12 -> 0
A13: BÍ ĐAO XANH | D13: =B13*C13 -> 0
A14: BÍ ĐAO XANH 400G | D14: =B14*C14 -> 0
A15: BÍ ĐỎ HỒ LÔ | B15: 18 | C15: 10000 | D15: =B15*C15 -> 180000
A16: BÍ ĐỎ MINI | D16: =B16*C16 -> 0
A17: BÍ ĐỎ NON (KG)KQ | D17: =B17*C17 -> 0
A18: BÍ ĐỎ NON TRÁI VR | B18: =46+40 -> 86 | C18: 4000 | D18: =B18*C18 -> 344000
A19: BÍ ĐỎ NON( KG) VR | D19: =B19*C19 -> 0
A20: BÍ ĐỎ TRÒN | D20: =B20*C20 -> 0
A21: BÍ MINI VÀNG 300GR | D21: =B21*C21 -> 0
A22: BÍ MINI VÀNG KG | D22: =B22*C22 -> 0
A23: BÍ NGÒI VÀNG | D23: =B23*C23 -> 0
A24: BÍ NGÒI VÀNG (TRÁI) | D24: =B24*C24 -> 0
A25: BÍ NGÒI XANH | B25: =45+10+8+60+88 -> 211 | C25: 7000 | D25: =B25*C25 -> 1477000
A26: BÍ NGÒI XANH(TRÁI) | D26: =B26*C26 -> 0
A27: BÍ NHẬT | D27: =B27*C27 -> 0
A28: BƠ 034 | D28: =B28*C28 -> 0
A29: BƠ BOOTH | D29: =B29*C29 -> 0
A30: BƠ SÁP | D30: =B30*C30 -> 0
A31: BÓ XÔI | D31: =B31*C31 -> 0
A32: BÓ XÔI 300G VR | D32: =B32*C32 -> 0
A33: BÓ XÔI-HN KQ | D33: =B33*C33 -> 0
A34: BÓ XÔI-NA | D34: =B34*C34 -> 0
A35: BÔNG ATISO | D35: =B35*C35 -> 0
A36: BÔNG BÍ | D36: =B36*C36 -> 0
A37: BÔNG BÍ TÚI 300GR | D37: =B37*C37 -> 0
... A56: CÀ CHUA CHERRY MIX 300G | D56: =B56*C56 -> 0
A57: CÀ CHUA L1 | B57: 50 | C57: 18000 | D57: =B57*C57 -> 900000
A58: CÀ CHUA MỘC CHÂU | D58: =B58*C58 -> 0
...

Sheet 28.4
A1: hàng tồn cuối ngày 28/4 vr
A2: TÊN SẢN PHẨM | B2: TỒN TRƯỚC | C2: GIÁ NHẬP | D2: THÀNH TIỀN
A3: BẮP CẢI TÍM | D3: =B3*C3 -> 0
A4: BẮP CẢI TÍM (BẮP) | D4: =B4*C4 -> 0
A5: BẮP CẢI TÍM SUSHI | D5: =B5*C5 -> 0
A6: BẮP CẢI TRẮNG | D6: =B6*C6 -> 0
A7: BẮP CẢI TRẮNG (BẮP) | D7: =B7*C7 -> 0
A8: BẮP CẢI TRẮNG MỘC CHÂU | D8: =B8*C8 -> 0
A9: BẮP CẢI TRẮNG SÓI BIỂN | D9: =B9*C9 -> 0
A10: BẮP CẢI TRẮNG SUSHI | D10: =B10*C10 -> 0
A11: BẮP MỸ | D11: =B11*C11 -> 0
A12: BẦU | D12: =B12*C12 -> 0
A13: BÍ ĐAO XANH | D13: =B13*C13 -> 0
A14: BÍ ĐAO XANH 400G | D14: =B14*C14 -> 0
A15: BÍ ĐỎ HỒ LÔ | B15: 15 | C15: 11000 | D15: =B15*C15 -> 165000
A16: BÍ ĐỎ MINI | D16: =B16*C16 -> 0
A17: BÍ ĐỎ NON (KG)KQ | D17: =B17*C17 -> 0
A18: BÍ ĐỎ NON TRÁI VR | D18: =B18*C18 -> 0
A19: BÍ ĐỎ NON( KG) VR | D19: =B19*C19 -> 0
A20: BÍ ĐỎ TRÒN | D20: =B20*C20 -> 0
A21: BÍ MINI VÀNG 300GR | D21: =B21*C21 -> 0
A22: BÍ MINI VÀNG KG | D22: =B22*C22 -> 0
A23: BÍ NGÒI VÀNG | D23: =B23*C23 -> 0
A24: BÍ NGÒI VÀNG (TRÁI) | D24: =B24*C24 -> 0
A25: BÍ NGÒI XANH | B25: =70+45 -> 115 | C25: 7000 | D25: =B25*C25 -> 805000
A26: BÍ NGÒI XANH(TRÁI) | D26: =B26*C26 -> 0
A27: BÍ NHẬT | D27: =B27*C27 -> 0
A28: BƠ 034 | D28: =B28*C28 -> 0
A29: BƠ BOOTH | D29: =B29*C29 -> 0
A30: BƠ SÁP | B30: 5 | C30: 23000 | D30: =B30*C30 -> 115000
A31: BÓ XÔI | D31: =B31*C31 -> 0
A32: BÓ XÔI 300G VR | D32: =B32*C32 -> 0
A33: BÓ XÔI-HN KQ | D33: =B33*C33 -> 0
A34: BÓ XÔI-NA | D34: =B34*C34 -> 0
A35: BÔNG ATISO | D35: =B35*C35 -> 0
A36: BÔNG BÍ | D36: =B36*C36 -> 0
A37: BÔNG BÍ TÚI 300GR | D37: =B37*C37 -> 0
A38: BÔNG CẢI TRẮNG | D38: =B38*C38 -> 0
A39: BÔNG CẢI TRẮNG (CÂY) | D39: =B39*C39 -> 0
A40: BÔNG CẢI XANH 10P | B40: 40 | C40: 26000 | D40: =B40*C40 -> 1040000
...

Sheet 29.4
A1: hàng tồn cuối ngày 29/4 vr
A2: TÊN SẢN PHẨM | B2: TỒN TRƯỚC | C2: GIÁ NHẬP | D2: THÀNH TIỀN
A3: CÀ CHUA SOCOLA XÁ | D3: =B3*C3 -> 0
A4: CÀ CHUA SÔCOLA 250GR (HỘP) VR | D4: =B4*C4 -> 0
A5: CÀ CHUA SÔCOLA 250GR (KG) -NA | D5: =B5*C5 -> 0
A6: CÀ CHUA SÔCOLA 250GR (KG) VR | D6: =B6*C6 -> 0
A7: CÀ CHUA SÔCOLA 250GR(KG) KQ | D7: =B7*C7 -> 0
A8: CÀ CHUA SÔCOLA 300GR (HỘP) VR | D8: =B8*C8 -> 0
A9: CÀ CHUA SÔCOLA(HỘP) KQ | D9: =B9*C9 -> 0
A10: CÀ RỐT BABY | D10: =B10*C10 -> 0
A11: CÀ RỐT BABY (KG) KQ | D11: =B11*C11 -> 0
A12: CÀ RỐT BABY 200GR | D12: =B12*C12 -> 0
A13: CẢI CẦU VỒNG | D13: =B13*C13 -> 0
A14: CẢI CẦU VỒNG 300GR | D14: =B14*C14 -> 0
... A23: ỚT CHUÔNG 3 MÀU(KG)VR | D23: =B23*C23 -> 0
A24: ỚT CHUÔNG ĐỎ | B24: =4+120+50 -> 174 | C24: 31000 | D24: =B24*C24 -> 5394000
A25: ỚT CHUÔNG ĐỎ L1 | D25: =B25*C25 -> 0
A26: ỚT CHUÔNG ĐỎ(TRÁI) | D26: =B26*C26 -> 0
A27: ỚT CHUÔNG 3 MÀU 350G | B27: 15 | C27: 12000 | D27: =B27*C27 -> 180000
A28: ỚT CHUÔNG 3 MÀU KQ(KG) | D28: =B28*C28 -> 0
A29: ỚT CHUÔNG VÀNG | D29: =B29*C29 -> 0
A30: ỚT CHUÔNG VÀNG L1 | D30: =B30*C30 -> 0
A31: ỚT CHUÔNG VÀNG(TRÁI) | D31: =B31*C31 -> 0
A32: ỚT CHUÔNG VÀNG+ XANH (VỈ) | D32: =B32*C32 -> 0
A33: ỚT CHUÔNG XANH | B33: =5+10+10 -> 25 | C33: 20000 | D33: =B33*C33 -> 500000
A34: ỚT CHUÔNG XANH L1 | D34: =B34*C34 -> 0
A35: ỚT CHUÔNG XANH(TRÁI) | D35: =B35*C35 -> 0
A36: KHOAI TÂY HỒNG | D36: =B36*C36 -> 0
A37: KHOAI TÂY HỒNG TÚI LƯỚI 500G | D37: =B37*C37 -> 0
A38: KHOAI TÂY VÀNG | D38: =B38*C38 -> 0
A39: KHOAI TÂY VÀNG ĐL | D39: =B39*C39 -> 0
A40: KHOAI TÂY VÀNG LỚN TÚI LƯỚI 500G | D40: =B40*C40 -> 0
A41: KHOAI TÂY VÀNG TRUNG TÚI LƯỚI 500G | B41: =5/0.5 -> 10 | C41: 5000 | D41: =B41*C41 -> 50000
A42: CẢI THẢO DL | D42: =B42*C42 -> 0
A43: CẢI THẢO DL(BẮP) | D43: =B43*C43 -> 0
A44: CẢI THẢO KIM CHI | D44: =B44*C44 -> 0
A45: CẢI THẢO VR | D45: =B45*C45 -> 0
A46: GỪNG 250GR | D46: =B46*C46 -> 0
A47: CỦ DỀN | D47: =B47*C47 -> 0
A48: CỦ DỀN 600G | D48: =B48*C48 -> 0
...

Sheet 30.4
A1: hàng tồn cuối ngày 30/4
A2: TÊN SẢN PHẨM | B2: TỒN TRƯỚC | C2: GIÁ NHẬP | D2: THÀNH TIỀN
A3: BẮP CẢI TÍM | D3: =B3*C3 -> 0
A4: BẮP CẢI TÍM (BẮP) | D4: =B4*C4 -> 0
A5: BẮP CẢI TÍM SUSHI | D5: =B5*C5 -> 0
A6: BẮP CẢI TRẮNG | D6: =B6*C6 -> 0
A7: BẮP CẢI TRẮNG (BẮP) | D7: =B7*C7 -> 0
A8: BẮP CẢI TRẮNG MỘC CHÂU | D8: =B8*C8 -> 0
A9: BẮP CẢI TRẮNG SÓI BIỂN | D9: =B9*C9 -> 0
A10: BẮP CẢI TRẮNG SUSHI | D10: =B10*C10 -> 0
A11: BẮP MỸ | D11: =B11*C11 -> 0
A12: BẦU | D12: =B12*C12 -> 0
A13: BÍ ĐAO XANH | D13: =B13*C13 -> 0
A14: BÍ ĐAO XANH 400G | D14: =B14*C14 -> 0
A15: BÍ ĐỎ HỒ LÔ | B15: 16 | C15: 11000 | D15: =B15*C15 -> 176000
A16: BÍ ĐỎ MINI | D16: =B16*C16 -> 0
A17: BÍ ĐỎ NON (KG)KQ | D17: =B17*C17 -> 0
A18: BÍ ĐỎ NON TRÁI VR | B18: =22+28 -> 50 | C18: 4000 | D18: =B18*C18 -> 200000
A19: BÍ ĐỎ NON( KG) VR | B19: 3 | C19: 12000 | D19: =B19*C19 -> 36000
A20: BÍ ĐỎ TRÒN | D20: =B20*C20 -> 0
A21: BÍ MINI VÀNG 300GR | D21: =B21*C21 -> 0
A22: BÍ NGÒI VÀNG | B22: 2.5 | C22: 15000 | D22: =B22*C22 -> 37500
A23: BÍ NGÒI VÀNG | D23: =B23*C23 -> 0
A24: BÍ NGÒI VÀNG (TRÁI) | D24: =B24*C24 -> 0
A25: BÍ NGÒI XANH | B25: =11+15+15+15+48 -> 104 | C25: 7000 | D25: =B25*C25 -> 728000
A26: BÍ NGÒI XANH(TRÁI) | D26: =B26*C26 -> 0
A27: BÍ NHẬT | D27: =B27*C27 -> 0
A28: BƠ 034 | B28: 39 | C28: 35000 | D28: =B28*C28 -> 1365000
A29: BƠ BOOTH | D29: =B29*C29 -> 0
A30: BƠ SÁP | B30: 6 | C30: 23000 | D30: =B30*C30 -> 138000
A31: BÓ XÔI | D31: =B31*C31 -> 0
A32: BÓ XÔI 300G VR | D32: =B32*C32 -> 0
A33: BÓ XÔI-HN KQ | D33: =B33*C33 -> 0
A34: BÓ XÔI-NA | D34: =B34*C34 -> 0
A35: BÔNG ATISO | D35: =B35*C35 -> 0
A36: BÔNG BÍ | D36: =B36*C36 -> 0
A37: BÔNG BÍ TÚI 300GR | D37: =B37*C37 -> 0
A38: BÔNG CẢI TRẮNG | B38: 7 | C38: 11000 | D38: =B38*C38 -> 77000
A39: BÔNG CẢI TRẮNG (CÂY) | D39: =B39*C39 -> 0
A40: BÔNG CẢI XANH 10P | B40: 5 | C40: 24000 | D40: =B40*C40 -> 120000
...
