Workbook

Sheet 1.1
A1: hàng tồn cuối ngày 1/1
A2: TÊN SẢN PHẨM | B2: TỒN TRƯỚC | C2: GIÁ NHẬP | D2: THÀNH TIỀN
A3: CÀ CHUA SÔCOLA 250GR (HỘP) VR | B3: 10 | C3: 8000 | D3: =B3*C3 -> 80000
A4: CÀ CHUA SÔCOLA 250GR (KG) -NA | D4: =B4*C4 -> 0
A5: CÀ CHUA SÔCOLA 250GR (KG) VR | D5: =B5*C5 -> 0
A6: CÀ CHUA SÔCOLA 250GR(KG) KQ | D6: =B6*C6 -> 0
A7: CÀ CHUA SÔCOLA 300GR (HỘP) VR | D7: =B7*C7 -> 0
A8: CÀ CHUA SOCOLA XÁ | D8: =B8*C8 -> 0
A9: CÀ CHUA SÔCOLA(HỘP) KQ | D9: =B9*C9 -> 0
A10: CÀ RỐT BABY | D10: =B10*C10 -> 0
A11: CÀ RỐT BABY (KG) KQ | D11: =B11*C11 -> 0
A12: CÀ RỐT BABY 200GR | D12: =B12*C12 -> 0
A13: CẢI CẦU VỒNG | D13: =B13*C13 -> 0
A14: CẢI CẦU VỒNG 300GR | B14: 6 | C14: 6000 | D14: =B14*C14 -> 36000
A15: CẢI KALE | D15: =B15*C15 -> 0
A16: CẢI KALE 300GR | D16: =B16*C16 -> 0
A17: CHANH VÀNG (KG) | D17: =B17*C17 -> 0
A18: CHANH VÀNG TRÁI 180UP | D18: =B18*C18 -> 0
A19: CẦN TÂY (KG) | D19: =B19*C19 -> 0
A20: CẦN TÂY THUỶ CANH | D20: =B20*C20 -> 0
A21: CẦN TÂY(CÂY) | D21: =B21*C21 -> 0
A22: ỚT CHUÔNG 3 MÀU(KG)VR | D22: =B22*C22 -> 0
A23: ỚT CHUÔNG ĐỎ | B23: 140 | C23: 30000 | D23: =B23*C23 -> 4200000
A24: ỚT CHUÔNG ĐỎ L1 | D24: =B24*C24 -> 0
A25: ỚT CHUÔNG ĐỎ(TRÁI) | D25: =B25*C25 -> 0
A26: ỚT CHUÔNG 3 MÀU 350G | D26: =B26*C26 -> 0
A27: ỚT CHUÔNG 3 MÀU KQ(KG) | D27: =B27*C27 -> 0
A28: ỚT CHUÔNG VÀNG | B28: 4 | C28: 38000 | D28: =B28*C28 -> 152000
A29: ỚT CHUÔNG VÀNG L1 | D29: =B29*C29 -> 0
A30: ỚT CHUÔNG VÀNG(TRÁI) | D30: =B30*C30 -> 0
A31: ỚT CHUÔNG VÀNG+ XANH (VỈ) | D31: =B31*C31 -> 0
A32: ỚT CHUÔNG XANH | B32: 45 | C32: 27000 | D32: =B32*C32 -> 1215000
A33: ỚT CHUÔNG XANH L1 | D33: =B33*C33 -> 0
A34: ỚT CHUÔNG XANH(TRÁI) | D34: =B34*C34 -> 0
A35: CỦ DỀN | B35: =40+40+15+12 -> 107 | C35: 12000 | D35: =B35*C35 -> 1284000
A36: CỦ DỀN 600G | D36: =B36*C36 -> 0
A37: GỪNG 250GR | D37: =B37*C37 -> 0
A38: HỒNG GIÒN | D38: =B38*C38 -> 0
A39: XÀ LÁCH MỸ | D39: =B39*C39 -> 0
A40: KHOAI TÂY HỒNG | B40: 10 | C40: 24000 | D40: =B40*C40 -> 240000
...

Sheet 2.1
A1: hàng tồn cuối ngày 2/1
A2: TÊN SẢN PHẨM | B2: TỒN TRƯỚC | C2: GIÁ NHẬP | D2: THÀNH TIỀN
A3: CÀ CHUA SÔCOLA 250GR (HỘP) VR | D3: =B3*C3 -> 0
A4: CÀ CHUA SÔCOLA 250GR (KG) -NA | D4: =B4*C4 -> 0
A5: CÀ CHUA SÔCOLA 250GR (KG) VR | D5: =B5*C5 -> 0
A6: CÀ CHUA SÔCOLA 250GR(KG) KQ | D6: =B6*C6 -> 0
A7: CÀ CHUA SÔCOLA 300GR (HỘP) VR | D7: =B7*C7 -> 0
A8: CÀ CHUA SOCOLA XÁ | D8: =B8*C8 -> 0
A9: CÀ CHUA SÔCOLA(HỘP) KQ | D9: =B9*C9 -> 0
A10: CÀ RỐT BABY | D10: =B10*C10 -> 0
A11: CÀ RỐT BABY (KG) KQ | D11: =B11*C11 -> 0
A12: CÀ RỐT BABY 200GR | D12: =B12*C12 -> 0
A13: CẢI CẦU VỒNG | D13: =B13*C13 -> 0
A14: CẢI CẦU VỒNG 300GR | D14: =B14*C14 -> 0
... A22: ỚT CHUÔNG 3 MÀU(KG)VR | D22: =B22*C22 -> 0
A23: ỚT CHUÔNG ĐỎ | B23: =7+25+40+40 -> 112 | C23: 30000 | D23: =B23*C23 -> 3360000
A24: ỚT CHUÔNG ĐỎ L1 | B24: 20 | C24: 23000 | D24: =B24*C24 -> 460000
A25: ỚT CHUÔNG ĐỎ(TRÁI) | D25: =B25*C25 -> 0
A26: ỚT CHUÔNG 3 MÀU 350G | D26: =B26*C26 -> 0
A27: ỚT CHUÔNG 3 MÀU KQ(KG) | D27: =B27*C27 -> 0
A28: ỚT CHUÔNG VÀNG | B28: 60 | C28: 38000 | D28: =B28*C28 -> 2280000
A29: ỚT CHUÔNG VÀNG L1 | B29: 50 | C29: 25000 | D29: =B29*C29 -> 1250000
A30: ỚT CHUÔNG VÀNG(TRÁI) | D30: =B30*C30 -> 0
A31: ỚT CHUÔNG VÀNG+ XANH (VỈ) | D31: =B31*C31 -> 0
A32: ỚT CHUÔNG XANH | B32: =13+12+17 -> 42 | C32: 30000 | D32: =B32*C32 -> 1260000
A33: ỚT CHUÔNG XANH L1 | D33: =B33*C33 -> 0
A34: ỚT CHUÔNG XANH(TRÁI) | D34: =B34*C34 -> 0
A35: CỦ DỀN | B35: =5+40+10 -> 55 | C35: 12000 | D35: =B35*C35 -> 660000
A36: CỦ DỀN 600G | D36: =B36*C36 -> 0
A37: GỪNG 250GR | D37: =B37*C37 -> 0
A38: HỒNG GIÒN | D38: =B38*C38 -> 0
A39: XÀ LÁCH MỸ | D39: =B39*C39 -> 0
A40: KHOAI TÂY HỒNG | D40: =B40*C40 -> 0
A41: KHOAI TÂY HỒNG TÚI LƯỚI 500G | D41: =B41*C41 -> 0
A42: KHOAI TÂY VÀNG | B42: 80 | C42: 12000 | D42: =B42*C42 -> 960000
A43: KHOAI TÂY VÀNG ĐL | B43: 130 | C43: 15000 | D43: =B43*C43 -> 1950000
A44: KHOAI TÂY VÀNG LỚN TÚI LƯỚI 500G | D44: =B44*C44 -> 0
A45: KHOAI TÂY VÀNG RỬA | D45: =B45*C45 -> 0
A46: KHOAI TÂY VÀNG TRUNG TÚI LƯỚI 500G | D46: =B46*C46 -> 0
A47: CẢI THẢO DL | D47: =B47*C47 -> 0
...

Sheet 3.1
A1: hàng tồn cuối ngày 3/1
A2: TÊN SẢN PHẨM | B2: TỒN TRƯỚC | C2: GIÁ NHẬP | D2: THÀNH TIỀN
A3: CÀ CHUA SÔCOLA 250GR (HỘP) VR | D3: =B3*C3 -> 0
A4: CÀ CHUA SÔCOLA 250GR (KG) -NA | D4: =B4*C4 -> 0
A5: CÀ CHUA SÔCOLA 250GR (KG) VR | D5: =B5*C5 -> 0
A6: CÀ CHUA SÔCOLA 250GR(KG) KQ | D6: =B6*C6 -> 0
A7: CÀ CHUA SÔCOLA 300GR (HỘP) VR | D7: =B7*C7 -> 0
A8: CÀ CHUA SOCOLA XÁ | D8: =B8*C8 -> 0
A9: CÀ CHUA SÔCOLA(HỘP) KQ | D9: =B9*C9 -> 0
A10: CÀ RỐT BABY | D10: =B10*C10 -> 0
A11: CÀ RỐT BABY (KG) KQ | D11: =B11*C11 -> 0
A12: CÀ RỐT BABY 200GR | D12: =B12*C12 -> 0
A13: CẢI CẦU VỒNG | D13: =B13*C13 -> 0
A14: CẢI CẦU VỒNG 300GR | D14: =B14*C14 -> 0
... A22: ỚT CHUÔNG 3 MÀU(KG)VR | D22: =B22*C22 -> 0
A23: ỚT CHUÔNG ĐỎ | B23: 75 | C23: 33000 | D23: =B23*C23 -> 2475000
A24: ỚT CHUÔNG ĐỎ L1 | B24: 50 | C24: 23000 | D24: =B24*C24 -> 1150000
A25: ỚT CHUÔNG ĐỎ(TRÁI) | D25: =B25*C25 -> 0
A26: ỚT CHUÔNG 3 MÀU 350G | B26: 30 | C26: 10000 | D26: =B26*C26 -> 300000
A27: ỚT CHUÔNG 3 MÀU KQ(KG) | D27: =B27*C27 -> 0
A28: ỚT CHUÔNG VÀNG | B28: =20+5+15 -> 40 | C28: 38000 | D28: =B28*C28 -> 1520000
A29: ỚT CHUÔNG VÀNG L1 | B29: =4+7+15 -> 26 | C29: 25000 | D29: =B29*C29 -> 650000
A30: ỚT CHUÔNG VÀNG(TRÁI) | D30: =B30*C30 -> 0
A31: ỚT CHUÔNG VÀNG+ XANH (VỈ) | D31: =B31*C31 -> 0
A32: ỚT CHUÔNG XANH | D32: =B32*C32 -> 0
A33: ỚT CHUÔNG XANH L1 | D33: =B33*C33 -> 0
A34: ỚT CHUÔNG XANH(TRÁI) | D34: =B34*C34 -> 0
A35: CỦ DỀN | B35: =20+6+7 -> 33 | C35: 12000 | D35: =B35*C35 -> 396000
A36: CỦ DỀN 600G | D36: =B36*C36 -> 0
A37: GỪNG 250GR | D37: =B37*C37 -> 0
A38: HỒNG GIÒN | D38: =B38*C38 -> 0
A39: XÀ LÁCH MỸ | D39: =B39*C39 -> 0
A40: KHOAI TÂY HỒNG | D40: =B40*C40 -> 0
A41: KHOAI TÂY HỒNG TÚI LƯỚI 500G | D41: =B41*C41 -> 0
A42: KHOAI TÂY VÀNG | B42: 18 | C42: 12000 | D42: =B42*C42 -> 216000
A43: KHOAI TÂY VÀNG ĐL | B43: =20+150+105+53 -> 328 | C43: 15000 | D43: =B43*C43 -> 4920000
A44: KHOAI TÂY VÀNG LỚN TÚI LƯỚI 500G | D44: =B44*C44 -> 0
A45: KHOAI TÂY VÀNG RỬA | D45: =B45*C45 -> 0
A46: KHOAI TÂY VÀNG TRUNG TÚI LƯỚI 500G | D46: =B46*C46 -> 0
A47: CẢI THẢO DL | D47: =B47*C47 -> 0
...

Sheet 4.1
A1: hàng tồn cuối ngày 4/12
A2: TÊN SẢN PHẨM | B2: TỒN TRƯỚC | C2: GHI CHÚ | D2: Tồn kho an toàn tại ĐL
A3: CÀ CHUA SÔCOLA 250GR (HỘP) VR | D3: =B3*C3 -> 0
A4: CÀ CHUA SÔCOLA 250GR (KG) -NA | D4: =B4*C4 -> 0
A5: CÀ CHUA SÔCOLA 250GR (KG) VR | D5: =B5*C5 -> 0
A6: CÀ CHUA SÔCOLA 250GR(KG) KQ | D6: =B6*C6 -> 0
A7: CÀ CHUA SÔCOLA 300GR (HỘP) VR | D7: =B7*C7 -> 0
A8: CÀ CHUA SOCOLA XÁ | D8: =B8*C8 -> 0
A9: CÀ CHUA SÔCOLA(HỘP) KQ | D9: =B9*C9 -> 0
A10: CÀ RỐT BABY | D10: =B10*C10 -> 0
A11: CÀ RỐT BABY (KG) KQ | D11: =B11*C11 -> 0
A12: CÀ RỐT BABY 200GR | D12: =B12*C12 -> 0
A13: CẢI CẦU VỒNG | D13: =B13*C13 -> 0
A14: CẢI CẦU VỒNG 300GR | D14: =B14*C14 -> 0
... A22: ỚT CHUÔNG 3 MÀU(KG)VR | D22: =B22*C22 -> 0
A23: BẮP CẢI TÍM | B23: 10 | C23: 26000 | D23: =B23*C23 -> 260000
A24: BÍ ĐỎ HỒ LÔ | B24: 12 | C24: 10500 | D24: =B24*C24 -> 126000
A25: ỚT CHUÔNG ĐỎ(TRÁI) | D25: =B25*C25 -> 0
A26: ỚT CHUÔNG 3 MÀU 350G | D26: =B26*C26 -> 0
A27: ỚT CHUÔNG 3 MÀU KQ(KG) | D27: =B27*C27 -> 0
A28: BÍ ĐỎ NON( KG) VR | B28: 15 | C28: 10000 | D28: =B28*C28 -> 150000
A29: BÍ ĐỎ TRÒN | B29: =2000+650 -> 2650 | C29: 5000 | D29: =B29*C29 -> 13250000
A30: ỚT CHUÔNG VÀNG(TRÁI) | D30: =B30*C30 -> 0
A31: ỚT CHUÔNG VÀNG+ XANH (VỈ) | D31: =B31*C31 -> 0
A32: BÍ NGÒI VÀNG | B32: 1 | C32: 28000 | D32: =B32*C32 -> 28000
A33: ỚT CHUÔNG XANH L1 | D33: =B33*C33 -> 0
A34: ỚT CHUÔNG XANH(TRÁI) | D34: =B34*C34 -> 0
A35: BÍ NGÒI XANH | B35: =30+50+33+75+10+47 -> 245 | C35: 10000 | D35: =B35*C35 -> 2450000
A36: CỦ DỀN 600G | D36: =B36*C36 -> 0
A37: GỪNG 250GR | D37: =B37*C37 -> 0
A38: HỒNG GIÒN | D38: =B38*C38 -> 0
A39: XÀ LÁCH MỸ | D39: =B39*C39 -> 0
A40: BÓ XÔI | B40: 2 | C40: 15000 | D40: =B40*C40 -> 30000
A41: KHOAI TÂY HỒNG TÚI LƯỚI 500G | D41: =B41*C41 -> 0
A42: KHOAI TÂY VÀNG | D42: =B42*C42 -> 0
A43: BÔNG BÍ | B43: 0.5 | C43: 50000 | D43: =B43*C43 -> 25000
A44: BÔNG CẢI TRẮNG | B44: 14 | C44: 15000 | D44: =B44*C44 -> 210000
A45: KHOAI TÂY VÀNG RỬA | D45: =B45*C45 -> 0
A46: KHOAI TÂY VÀNG TRUNG TÚI LƯỚI 500G | D46: =B46*C46 -> 0
A47: CẢI THẢO DL | D47: =B47*C47 -> 0
...

Sheet 5.1
A1: 45296
A2: TÊN SẢN PHẨM | B2: ĐVT | C2: TỒN TRƯỚC | D2: GIÁ NHẬP | E2: THÀNH TIỀN
A4: CÀ CHUA SÔCOLA 250GR (HỘP) VR | B4: HỘP | C4: 2 | D4: 10000 | E4: =+D4*C4 -> 20000
A5: CÀ CHUA SÔCOLA 250GR (KG) -NA | B5: Kg | D5: =IFERROR(VLOOKUP(A5,'4.1'!A24:C306,3,0),) -> 0 | E5: =+D5*C5 -> 0
A6: CÀ CHUA SÔCOLA 250GR (KG) VR | B6: Kg | D6: =IFERROR(VLOOKUP(A6,'4.1'!A25:C307,3,0),) -> 0 | E6: =+D6*C6 -> 0
A7: CÀ CHUA SÔCOLA 250GR(KG) KQ | B7: Kg | D7: =IFERROR(VLOOKUP(A7,'4.1'!A26:C308,3,0),) -> 0 | E7: =+D7*C7 -> 0
A8: CÀ CHUA SÔCOLA 300GR (HỘP) VR | B8: HỘP | D8: =IFERROR(VLOOKUP(A8,'4.1'!A27:C309,3,0),) -> 0 | E8: =+D8*C8 -> 0
A9: CÀ CHUA SOCOLA XÁ | B9: Kg | D9: =IFERROR(VLOOKUP(A9,'4.1'!A28:C310,3,0),) -> 0 | E9: =+D9*C9 -> 0
A10: CÀ CHUA SÔCOLA(HỘP) KQ | B10: HỘP | D10: =IFERROR(VLOOKUP(A10,'4.1'!A29:C311,3,0),) -> 0 | E10: =+D10*C10 -> 0
A11: CÀ RỐT BABY | B11: Kg | D11: =IFERROR(VLOOKUP(A11,'4.1'!A30:C312,3,0),) -> 0 | E11: =+D11*C11 -> 0
A12: CÀ RỐT BABY (KG) KQ | B12: Kg | D12: =IFERROR(VLOOKUP(A12,'4.1'!A31:C313,3,0),) -> 0 | E12: =+D12*C12 -> 0
A13: CÀ RỐT BABY 200GR | B13: VỈ | D13: =IFERROR(VLOOKUP(A13,'4.1'!A32:C314,3,0),) -> 0 | E13: =+D13*C13 -> 0
A14: CẢI CẦU VỒNG | B14: Kg | D14: =IFERROR(VLOOKUP(A14,'4.1'!A33:C315,3,0),) -> 0 | E14: =+D14*C14 -> 0
A15: CẢI CẦU VỒNG 300GR | B15: TÚI | D15: =IFERROR(VLOOKUP(A15,'4.1'!A34:C316,3,0),) -> 0 | E15: =+D15*C15 -> 0
A16: CẢI KALE | B16: Kg | D16: =IFERROR(VLOOKUP(A16,'4.1'!A35:C317,3,0),) -> 0 | E16: =+D16*C16 -> 0
... A23: ỚT CHUÔNG 3 MÀU(KG)VR | B23: VỈ | D23: =IFERROR(VLOOKUP(A23,'4.1'!A42:C324,3,0),) -> 0 | E23: =+D23*C23 -> 0
A24: ỚT CHUÔNG ĐỎ | B24: Kg | C24: 155 | D24: =IFERROR(VLOOKUP(A24,'4.1'!A43:C325,3,0),) -> 33000 | E24: =+D24*C24 -> 5115000
A25: ỚT CHUÔNG ĐỎ L1 | B25: Kg | C25: 10 | D25: =IFERROR(VLOOKUP(A25,'4.1'!A44:C326,3,0),) -> 23000 | E25: =+D25*C25 -> 230000
A26: ỚT CHUÔNG ĐỎ(TRÁI) | B26: TRÁI | D26: =IFERROR(VLOOKUP(A26,'4.1'!A45:C327,3,0),) -> 0 | E26: =+D26*C26 -> 0
A27: ỚT CHUÔNG 3 MÀU 350G | B27: VỈ | D27: =IFERROR(VLOOKUP(A27,'4.1'!A46:C328,3,0),) -> 0 | E27: =+D27*C27 -> 0
A28: ỚT CHUÔNG 3 MÀU KQ(KG) | B28: Kg | D28: =IFERROR(VLOOKUP(A28,'4.1'!A47:C329,3,0),) -> 0 | E28: =+D28*C28 -> 0
A29: ỚT CHUÔNG VÀNG | B29: Kg | C29: 21 | D29: =IFERROR(VLOOKUP(A29,'4.1'!A48:C330,3,0),) -> 42000 | E29: =+D29*C29 -> 882000
A30: ỚT CHUÔNG VÀNG L1 | B30: Kg | D30: =IFERROR(VLOOKUP(A30,'4.1'!A49:C331,3,0),) -> 25000 | E30: =+D30*C30 -> 0
A31: ỚT CHUÔNG VÀNG(TRÁI) | B31: TRÁI | D31: =IFERROR(VLOOKUP(A31,'4.1'!A50:C332,3,0),) -> 0 | E31: =+D31*C31 -> 0
A32: ỚT CHUÔNG VÀNG+ XANH (VỈ) | B32: VỈ | D32: =IFERROR(VLOOKUP(A32,'4.1'!A51:C333,3,0),) -> 0 | E32: =+D32*C32 -> 0
A33: ỚT CHUÔNG XANH | B33: Kg | C33: 66 | D33: =IFERROR(VLOOKUP(A33,'4.1'!A52:C334,3,0),) -> 27000 | E33: =+D33*C33 -> 1782000
A34: ỚT CHUÔNG XANH L1 | B34: Kg | D34: =IFERROR(VLOOKUP(A34,'4.1'!A53:C335,3,0),) -> 0 | E34: =+D34*C34 -> 0
A35: ỚT CHUÔNG XANH(TRÁI) | B35: TRÁI | D35: =IFERROR(VLOOKUP(A35,'4.1'!A54:C336,3,0),) -> 0 | E35: =+D35*C35 -> 0
A36: CỦ DỀN | B36: Kg | C36: 47 | D36: =IFERROR(VLOOKUP(A36,'4.1'!A55:C337,3,0),) -> 12000 | E36: =+D36*C36 -> 564000
A37: CỦ DỀN 600G | B37: TÚI | D37: =IFERROR(VLOOKUP(A37,'4.1'!A56:C338,3,0),) -> 0 | E37: =+D37*C37 -> 0
A38: GỪNG 250GR | B38: Kg | D38: =IFERROR(VLOOKUP(A38,'4.1'!A57:C339,3,0),) -> 0 | E38: =+D38*C38 -> 0
A39: HỒNG GIÒN | B39: Kg | D39: =IFERROR(VLOOKUP(A39,'4.1'!A58:C340,3,0),) -> 0 | E39: =+D39*C39 -> 0
A40: XÀ LÁCH MỸ | B40: Kg | D40: =IFERROR(VLOOKUP(A40,'4.1'!A59:C341,3,0),) -> 0 | E40: =+D40*C40 -> 0
A41: KHOAI TÂY HỒNG | B41: Kg | D41: =IFERROR(VLOOKUP(A41,'4.1'!A60:C342,3,0),) -> 24000 | E41: =+D41*C41 -> 0
A42: KHOAI TÂY HỒNG TÚI LƯỚI 500G | B42: TÚI | D42: =IFERROR(VLOOKUP(A42,'4.1'!A61:C343,3,0),) -> 0 | E42: =+D42*C42 -> 0
A43: KHOAI TÂY VÀNG | B43: Kg | C43: 8 | D43: 15000 | E43: =+D43*C43 -> 120000
A44: KHOAI TÂY VÀNG ĐL | B44: Kg | C44: 150 | D44: =IFERROR(VLOOKUP(A44,'4.1'!A63:C345,3,0),) -> 15000 | E44: =+D44*C44 -> 2250000
A45: KHOAI TÂY VÀNG LỚN TÚI LƯỚI 500G | B45: TÚI | C45: 50 | D45: =IFERROR(VLOOKUP(A45,'4.1'!A64:C346,3,0),) -> 15000 | E45: =+D45*C45 -> 750000
A46: KHOAI TÂY VÀNG RỬA | B46: Kg | D46: =IFERROR(VLOOKUP(A46,'4.1'!A65:C347,3,0),) -> 0 | E46: =+D46*C46 -> 0
A47: KHOAI TÂY VÀNG TRUNG TÚI LƯỚI 500G | B47: TÚI | D47: =IFERROR(VLOOKUP(A47,'4.1'!A66:C348,3,0),) -> 0 | E47: =+D47*C47 -> 0
...

Sheet 6.1
A1: hàng tồn cuối ngày 6/1
A2: TÊN SẢN PHẨM | B2: TỒN TRƯỚC | C2: GIÁ NHẬP | D2: THÀNH TIỀN
A3: CÀ CHUA SÔCOLA 250GR (HỘP) VR | D3: =B3*C3 -> 0
A4: CÀ CHUA SÔCOLA 250GR (KG) -NA | D4: =B4*C4 -> 0
A5: CÀ CHUA SÔCOLA 250GR (KG) VR | B5: 1.5 | C5: 40000 | D5: =B5*C5 -> 60000
A6: CÀ CHUA SÔCOLA 250GR(KG) KQ | D6: =B6*C6 -> 0
A7: CÀ CHUA SÔCOLA 300GR (HỘP) VR | D7: =B7*C7 -> 0
A8: CÀ CHUA SOCOLA XÁ | D8: =B8*C8 -> 0
A9: CÀ CHUA SÔCOLA(HỘP) KQ | D9: =B9*C9 -> 0
A10: CÀ RỐT BABY | D10: =B10*C10 -> 0
A11: CÀ RỐT BABY (KG) KQ | D11: =B11*C11 -> 0
A12: CÀ RỐT BABY 200GR | D12: =B12*C12 -> 0
A13: CẢI CẦU VỒNG | D13: =B13*C13 -> 0
A14: CẢI CẦU VỒNG 300GR | B14: 6 | C14: 5300 | D14: =B14*C14 -> 31800
A15: CẢI KALE | D15: =B15*C15 -> 0
A16: CẢI KALE 300GR | D16: =B16*C16 -> 0
A17: CHANH VÀNG (KG) | D17: =B17*C17 -> 0
A18: CHANH VÀNG TRÁI 180UP | D18: =B18*C18 -> 0
A19: CẦN TÂY (KG) | D19: =B19*C19 -> 0
A20: CẦN TÂY THUỶ CANH | D20: =B20*C20 -> 0
A21: CẦN TÂY(CÂY) | D21: =B21*C21 -> 0
A22: ỚT CHUÔNG 3 MÀU(KG)VR | D22: =B22*C22 -> 0
A23: ỚT CHUÔNG ĐỎ | B23: =70+35+30 -> 135 | C23: 33000 | D23: =B23*C23 -> 4455000
A24: ỚT CHUÔNG ĐỎ L1 | B24: 15 | C24: 33000 | D24: =B24*C24 -> 495000
A25: ỚT CHUÔNG ĐỎ(TRÁI) | D25: =B25*C25 -> 0
A26: ỚT CHUÔNG 3 MÀU 350G | D26: =B26*C26 -> 0
A27: ỚT CHUÔNG 3 MÀU KQ(KG) | D27: =B27*C27 -> 0
A28: ỚT CHUÔNG VÀNG | B28: 20 | C28: 43000 | D28: =B28*C28 -> 860000
A29: ỚT CHUÔNG VÀNG L1 | B29: 33 | C29: 40000 | D29: =B29*C29 -> 1320000
A30: ỚT CHUÔNG VÀNG(TRÁI) | D30: =B30*C30 -> 0
A31: ỚT CHUÔNG VÀNG+ XANH (VỈ) | D31: =B31*C31 -> 0
A32: ỚT CHUÔNG XANH | B32: =5+13+6+10+20+10 -> 64 | C32: 27000 | D32: =B32*C32 -> 1728000
A33: ỚT CHUÔNG XANH L1 | D33: =B33*C33 -> 0
A34: ỚT CHUÔNG XANH(TRÁI) | D34: =B34*C34 -> 0
A35: CỦ DỀN | B35: =10+20+15 -> 45 | C35: 12000 | D35: =B35*C35 -> 540000
A36: CỦ DỀN 600G | D36: =B36*C36 -> 0
A37: GỪNG 250GR | D37: =B37*C37 -> 0
A38: HỒNG GIÒN | D38: =B38*C38 -> 0
A39: XÀ LÁCH MỸ | D39: =B39*C39 -> 0
A40: KHOAI TÂY HỒNG | B40: 12 | C40: 24000 | D40: =B40*C40 -> 288000
...

Sheet 7.1
A1: hàng tồn cuối ngày 7/1
A2: TÊN SẢN PHẨM | B2: TỒN TRƯỚC | C2: GIÁ NHẬP | D2: THÀNH TIỀN
A3: CÀ CHUA SÔCOLA 250GR (HỘP) VR | D3: =B3*C3 -> 0
A4: CÀ CHUA SÔCOLA 250GR (KG) -NA | D4: =B4*C4 -> 0
A5: CÀ CHUA SÔCOLA 250GR (KG) VR | D5: =B5*C5 -> 0
A6: CÀ CHUA SÔCOLA 250GR(KG) KQ | D6: =B6*C6 -> 0
A7: CÀ CHUA SÔCOLA 300GR (HỘP) VR | D7: =B7*C7 -> 0
A8: CÀ CHUA SOCOLA XÁ | D8: =B8*C8 -> 0
A9: CÀ CHUA SÔCOLA(HỘP) KQ | D9: =B9*C9 -> 0
A10: CÀ RỐT BABY | D10: =B10*C10 -> 0
A11: CÀ RỐT BABY (KG) KQ | D11: =B11*C11 -> 0
A12: CÀ RỐT BABY 200GR | D12: =B12*C12 -> 0
A13: CẢI CẦU VỒNG | D13: =B13*C13 -> 0
A14: BÍ ĐỎ NON TRÁI VR | B14: =25+18+33 -> 76 | C14: 4000 | D14: =B14*C14 -> 304000
A15: CẢI KALE | D15: =B15*C15 -> 0
A16: CẢI KALE 300GR | D16: =B16*C16 -> 0
A17: CHANH VÀNG (KG) | D17: =B17*C17 -> 0
A18: CHANH VÀNG TRÁI 180UP | D18: =B18*C18 -> 0
A19: CẦN TÂY (KG) | D19: =B19*C19 -> 0
A20: CẦN TÂY THUỶ CANH | D20: =B20*C20 -> 0
A21: CẦN TÂY(CÂY) | D21: =B21*C21 -> 0
A22: ỚT CHUÔNG 3 MÀU(KG)VR | D22: =B22*C22 -> 0
A23: BÍ ĐỎ TRÒN | B23: =1835+150+90+45 -> 2120 | C23: 5000 | D23: =B23*C23 -> 10600000
A24: BÍ NGÒI VÀNG | B24: 3 | C24: 26000 | D24: =B24*C24 -> 78000
A25: ỚT CHUÔNG ĐỎ(TRÁI) | D25: =B25*C25 -> 0
A26: ỚT CHUÔNG 3 MÀU 350G | D26: =B26*C26 -> 0
A27: ỚT CHUÔNG 3 MÀU KQ(KG) | D27: =B27*C27 -> 0
A28: ỚT CHUÔNG VÀNG | D28: =B28*C28 -> 0
A29: ỚT CHUÔNG VÀNG L1 | D29: =B29*C29 -> 0
A30: ỚT CHUÔNG VÀNG(TRÁI) | D30: =B30*C30 -> 0
A31: ỚT CHUÔNG VÀNG+ XANH (VỈ) | D31: =B31*C31 -> 0
A32: BÍ NGÒI XANH | B32: 72 | C32: 8000 | D32: =B32*C32 -> 576000
A33: BÓ XÔI | B33: 5 | C33: 15000 | D33: =B33*C33 -> 75000
A34: ỚT CHUÔNG XANH(TRÁI) | D34: =B34*C34 -> 0
A35: BÔNG BÍ | B35: 0.75 | C35: 50000 | D35: =B35*C35 -> 37500
A36: CỦ DỀN 600G | D36: =B36*C36 -> 0
A37: GỪNG 250GR | D37: =B37*C37 -> 0
A38: HỒNG GIÒN | D38: =B38*C38 -> 0
A39: XÀ LÁCH MỸ | D39: =B39*C39 -> 0
A40: BÔNG CẢI TRẮNG | B40: 23 | C40: 18000 | D40: =B40*C40 -> 414000
...

Sheet 8.1
A1: 45299
A2: TÊN SẢN PHẨM | B2: ĐVT | C2: TỒN TRƯỚC | D2: GIÁ NHẬP | E2: THÀNH TIỀN
E3: =+D3*C3 -> 0
A4: BÍ ĐỎ HỒ LÔ | B4: Kg | C4: 5 | D4: 10000 | E4: =+D4*C4 -> 50000
A5: CÀ CHUA SÔCOLA 250GR (KG) -NA | B5: Kg | D5: =IFERROR(VLOOKUP(A5,'7.1'!A15:C306,3,),) -> 0 | E5: =+D5*C5 -> 0
A6: CÀ CHUA SÔCOLA 250GR (KG) VR | B6: Kg | D6: =IFERROR(VLOOKUP(A6,'7.1'!A16:C307,3,),) -> 0 | E6: =+D6*C6 -> 0
A7: CÀ CHUA SÔCOLA 250GR(KG) KQ | B7: Kg | D7: =IFERROR(VLOOKUP(A7,'7.1'!A17:C308,3,),) -> 0 | E7: =+D7*C7 -> 0
A8: CÀ CHUA SÔCOLA 300GR (HỘP) VR | B8: HỘP | D8: =IFERROR(VLOOKUP(A8,'7.1'!A18:C309,3,),) -> 0 | E8: =+D8*C8 -> 0
A9: CÀ CHUA SOCOLA XÁ | B9: Kg | D9: =IFERROR(VLOOKUP(A9,'7.1'!A19:C310,3,),) -> 0 | E9: =+D9*C9 -> 0
A10: CÀ CHUA SÔCOLA(HỘP) KQ | B10: HỘP | D10: =IFERROR(VLOOKUP(A10,'7.1'!A20:C311,3,),) -> 0 | E10: =+D10*C10 -> 0
A11: CÀ RỐT BABY | B11: Kg | D11: =IFERROR(VLOOKUP(A11,'7.1'!A21:C312,3,),) -> 0 | E11: =+D11*C11 -> 0
A12: CÀ RỐT BABY (KG) KQ | B12: Kg | D12: =IFERROR(VLOOKUP(A12,'7.1'!A22:C313,3,),) -> 0 | E12: =+D12*C12 -> 0
A13: CÀ RỐT BABY 200GR | B13: VỈ | D13: =IFERROR(VLOOKUP(A13,'7.1'!A23:C314,3,),) -> 0 | E13: =+D13*C13 -> 0
A14: CẢI CẦU VỒNG | B14: Kg | D14: =IFERROR(VLOOKUP(A14,'7.1'!A24:C315,3,),) -> 0 | E14: =+D14*C14 -> 0
A15: BÍ ĐỎ NON TRÁI VR | B15: TRÁI | C15: 43 | D15: 4000 | E15: =+D15*C15 -> 172000
A16: CẢI KALE | B16: Kg | D16: =IFERROR(VLOOKUP(A16,'7.1'!A26:C317,3,),) -> 0 | E16: =+D16*C16 -> 0
A17: BÍ ĐỎ TRÒN | B17: Kg | C17: 1620 | D17: 5000 | E17: =+D17*C17 -> 8100000
A18: CHANH VÀNG (KG) | B18: Kg | D18: =IFERROR(VLOOKUP(A18,'7.1'!A28:C319,3,),) -> 0 | E18: =+D18*C18 -> 0
A19: CHANH VÀNG TRÁI 180UP | B19: TRÁI | D19: =IFERROR(VLOOKUP(A19,'7.1'!A29:C320,3,),) -> 0 | E19: =+D19*C19 -> 0
A20: CẦN TÂY (KG) | B20: Kg | D20: =IFERROR(VLOOKUP(A20,'7.1'!A30:C321,3,),) -> 0 | E20: =+D20*C20 -> 0
A21: CẦN TÂY THUỶ CANH | B21: Kg | D21: =IFERROR(VLOOKUP(A21,'7.1'!A31:C322,3,),) -> 0 | E21: =+D21*C21 -> 0
A22: CẦN TÂY(CÂY) | B22: CÂY | D22: =IFERROR(VLOOKUP(A22,'7.1'!A32:C323,3,),) -> 0 | E22: =+D22*C22 -> 0
A23: ỚT CHUÔNG 3 MÀU(KG)VR | B23: VỈ | D23: =IFERROR(VLOOKUP(A23,'7.1'!A33:C324,3,),) -> 0 | E23: =+D23*C23 -> 0
A24: BÍ NGÒI VÀNG | B24: Kg | C24: 1 | D24: 26000 | E24: =+D24*C24 -> 26000
A25: BÍ NGÒI XANH | B25: Kg | C25: 90 | D25: 8000 | E25: =+D25*C25 -> 720000
A26: ỚT CHUÔNG ĐỎ(TRÁI) | B26: TRÁI | D26: =IFERROR(VLOOKUP(A26,'7.1'!A36:C327,3,),) -> 0 | E26: =+D26*C26 -> 0
A27: ỚT CHUÔNG 3 MÀU 350G | B27: VỈ | D27: =IFERROR(VLOOKUP(A27,'7.1'!A37:C328,3,),) -> 0 | E27: =+D27*C27 -> 0
A28: ỚT CHUÔNG 3 MÀU KQ(KG) | B28: Kg | D28: =IFERROR(VLOOKUP(A28,'7.1'!A38:C329,3,),) -> 0 | E28: =+D28*C28 -> 0
A29: ỚT CHUÔNG VÀNG | B29: Kg | D29: =IFERROR(VLOOKUP(A29,'7.1'!A39:C330,3,),) -> 0 | E29: =+D29*C29 -> 0
A30: ỚT CHUÔNG VÀNG L1 | B30: Kg | D30: =IFERROR(VLOOKUP(A30,'7.1'!A40:C331,3,),) -> 0 | E30: =+D30*C30 -> 0
A31: ỚT CHUÔNG VÀNG(TRÁI) | B31: TRÁI | D31: =IFERROR(VLOOKUP(A31,'7.1'!A41:C332,3,),) -> 0 | E31: =+D31*C31 -> 0
A32: ỚT CHUÔNG VÀNG+ XANH (VỈ) | B32: VỈ | D32: =IFERROR(VLOOKUP(A32,'7.1'!A42:C333,3,),) -> 0 | E32: =+D32*C32 -> 0
A33: CÀ CHUA | B33: Kg | C33: 530 | D33: 8000 | E33: =+D33*C33 -> 4240000
A34: CÀ CHUA L1 | B34: TÚI | C34: 40 | D34: 6000 | E34: =+D34*C34 -> 240000
A35: ỚT CHUÔNG XANH(TRÁI) | B35: TRÁI | D35: =IFERROR(VLOOKUP(A35,'7.1'!A45:C336,3,),) -> 0 | E35: =+D35*C35 -> 0
A36: CÀ CHUA SÔCOLA 250GR (HỘP) VR | B36: HỘP | C36: 92 | D36: 9000 | E36: =+D36*C36 -> 828000
A37: CỦ DỀN 600G | B37: TÚI | D37: =IFERROR(VLOOKUP(A37,'7.1'!A47:C338,3,),) -> 0 | E37: =+D37*C37 -> 0
A38: GỪNG 250GR | B38: Kg | D38: =IFERROR(VLOOKUP(A38,'7.1'!A48:C339,3,),) -> 0 | E38: =+D38*C38 -> 0
A39: HỒNG GIÒN | B39: Kg | D39: =IFERROR(VLOOKUP(A39,'7.1'!A49:C340,3,),) -> 0 | E39: =+D39*C39 -> 0
A40: XÀ LÁCH MỸ | B40: Kg | D40: =IFERROR(VLOOKUP(A40,'7.1'!A50:C341,3,),) -> 0 | E40: =+D40*C40 -> 0
...

Sheet 9.1
A1: 45300 | C1: Stock
A2: TÊN SẢN PHẨM | B2: ĐVT | C2: TỒN TRƯỚC | D2: GIÁ NHẬP | E2: THÀNH TIỀN
A4: BẮP CẢI TÍM | B4: Kg | C4: 5 | D4: 28000 | E4: =+D4*C4 -> 140000
A5: CÀ CHUA SÔCOLA 250GR (KG) -NA | B5: Kg | E5: =+D5*C5 -> 0
A6: CÀ CHUA SÔCOLA 250GR (KG) VR | B6: Kg | E6: =+D6*C6 -> 0
A7: CÀ CHUA SÔCOLA 250GR(KG) KQ | B7: Kg | E7: =+D7*C7 -> 0
A8: CÀ CHUA SÔCOLA 300GR (HỘP) VR | B8: HỘP | E8: =+D8*C8 -> 0
A9: CÀ CHUA SOCOLA XÁ | B9: Kg | E9: =+D9*C9 -> 0
A10: CÀ CHUA SÔCOLA(HỘP) KQ | B10: HỘP | E10: =+D10*C10 -> 0
A11: CÀ RỐT BABY | B11: Kg | E11: =+D11*C11 -> 0
A12: CÀ RỐT BABY (KG) KQ | B12: Kg | E12: =+D12*C12 -> 0
A13: CÀ RỐT BABY 200GR | B13: VỈ | E13: =+D13*C13 -> 0
A14: CẢI CẦU VỒNG | B14: Kg | E14: =+D14*C14 -> 0
A15: BẦU | B15: Kg | C15: 2 | D15: 10000 | E15: =+D15*C15 -> 20000
A16: CẢI KALE | B16: Kg | E16: =+D16*C16 -> 0
A17: BÍ ĐỎ NON TRÁI VR | B17: TRÁI | C17: 68 | D17: =11000*0.3 -> 3300 | E17: =+D17*C17 -> 224400
A18: CHANH VÀNG (KG) | B18: Kg | E18: =+D18*C18 -> 0
A19: CHANH VÀNG TRÁI 180UP | B19: TRÁI | E19: =+D19*C19 -> 0
A20: BÍ ĐỎ TRÒN | B20: Kg | C20: 1875 | D20: 6000 | E20: =+D20*C20 -> 11250000
A21: CẦN TÂY THUỶ CANH | B21: Kg | E21: =+D21*C21 -> 0
A22: CẦN TÂY(CÂY) | B22: CÂY | E22: =+D22*C22 -> 0
A23: ỚT CHUÔNG 3 MÀU(KG)VR | B23: VỈ | E23: =+D23*C23 -> 0
A24: BÍ NGÒI XANH | B24: Kg | C24: 235 | D24: 8000 | E24: =+D24*C24 -> 1880000
A25: BÓ XÔI | B25: Kg | C25: 6 | D25: 15000 | E25: =+D25*C25 -> 90000
A26: ỚT CHUÔNG ĐỎ(TRÁI) | B26: TRÁI | E26: =+D26*C26 -> 0
A27: BÔNG CẢI XANH BIGC | B27: Kg | C27: 25 | D27: 14000 | E27: =+D27*C27 -> 350000
A28: ỚT CHUÔNG 3 MÀU KQ(KG) | B28: Kg | E28: =+D28*C28 -> 0
A29: CÀ CHUA | B29: Kg | C29: 920 | D29: 8000 | E29: =+D29*C29 -> 7360000
A30: CÀ CHUA BI COOP | B30: Kg | C30: 9.5 | D30: 14000 | E30: =+D30*C30 -> 133000
A31: ỚT CHUÔNG VÀNG(TRÁI) | B31: TRÁI | E31: =+D31*C31 -> 0
A32: ỚT CHUÔNG VÀNG+ XANH (VỈ) | B32: VỈ | E32: =+D32*C32 -> 0
A33: CÀ CHUA L1 | B33: TÚI | C33: 164 | D33: 5000 | E33: =+D33*C33 -> 820000
A34: CÀ CHUA SÔCOLA 250GR (HỘP) VR | B34: HỘP | C34: 22 | D34: 7500 | E34: =+D34*C34 -> 165000
A35: ỚT CHUÔNG XANH(TRÁI) | B35: TRÁI | E35: =+D35*C35 -> 0
A36: CÀ CHUA Ý | B36: Kg | C36: 660 | D36: 17000 | E36: =+D36*C36 -> 11220000
A37: CỦ DỀN 600G | B37: TÚI | E37: =+D37*C37 -> 0
A38: GỪNG 250GR | B38: Kg | E38: =+D38*C38 -> 0
A39: HỒNG GIÒN | B39: Kg | E39: =+D39*C39 -> 0
A40: XÀ LÁCH MỸ | B40: Kg | E40: =+D40*C40 -> 0
A41: CÀ CHUA Ý CHÙM | B41: KG | C41: 220 | D41: 19000 | E41: =+D41*C41 -> 4180000
...

Sheet 10.1
A1: hàng tồn cuối ngày 10.1
A2: TÊN SẢN PHẨM | B2: TỒN TRƯỚC | C2: GIÁ NHẬP | D2: THÀNH TIỀN
A3: CÀ CHUA SÔCOLA 250GR (HỘP) VR | B3: 71 | C3: 6500 | D3: =B3*C3 -> 461500
A4: CÀ CHUA SÔCOLA 250GR (KG) -NA | D4: =B4*C4 -> 0
A5: CÀ CHUA SÔCOLA 250GR (KG) VR | D5: =B5*C5 -> 0
A6: CÀ CHUA SÔCOLA 250GR(KG) KQ | B6: 9 | C6: 36000 | D6: =B6*C6 -> 324000
A7: CÀ CHUA SÔCOLA 300GR (HỘP) VR | D7: =B7*C7 -> 0
A8: CÀ CHUA SOCOLA XÁ | D8: =B8*C8 -> 0
A9: CÀ CHUA SÔCOLA(HỘP) KQ | D9: =B9*C9 -> 0
A10: CÀ RỐT BABY | D10: =B10*C10 -> 0
A11: CÀ RỐT BABY (KG) KQ | D11: =B11*C11 -> 0
A12: CÀ RỐT BABY 200GR | D12: =B12*C12 -> 0
A13: CẢI CẦU VỒNG | D13: =B13*C13 -> 0
A14: CẢI CẦU VỒNG 300GR | D14: =B14*C14 -> 0
A15: CẢI KALE | D15: =B15*C15 -> 0
A16: CẢI KALE 300GR | D16: =B16*C16 -> 0
A17: CHANH VÀNG (KG) | B17: 6 | C17: 55000 | D17: =B17*C17 -> 330000
A18: CHANH VÀNG TRÁI 180UP | D18: =B18*C18 -> 0
A19: CẦN TÂY (KG) | D19: =B19*C19 -> 0
A20: CẦN TÂY THUỶ CANH | D20: =B20*C20 -> 0
A21: CẦN TÂY(CÂY) | D21: =B21*C21 -> 0
A22: ỚT CHUÔNG 3 MÀU(KG)VR | D22: =B22*C22 -> 0
A23: ỚT CHUÔNG ĐỎ | D23: =B23*C23 -> 0
A24: ỚT CHUÔNG ĐỎ L1 | B24: 30 | C24: 28000 | D24: =B24*C24 -> 840000
A25: ỚT CHUÔNG ĐỎ(TRÁI) | D25: =B25*C25 -> 0
A26: ỚT CHUÔNG 3 MÀU 350G | B26: 100 | C26: 13000 | D26: =B26*C26 -> 1300000
A27: ỚT CHUÔNG 3 MÀU KQ(KG) | D27: =B27*C27 -> 0
A28: ỚT CHUÔNG VÀNG | B28: 20 | C28: 45000 | D28: =B28*C28 -> 900000
A29: ỚT CHUÔNG VÀNG L1 | B29: 15 | C29: 40000 | D29: =B29*C29 -> 600000
A30: ỚT CHUÔNG VÀNG(TRÁI) | D30: =B30*C30 -> 0
A31: ỚT CHUÔNG VÀNG+ XANH (VỈ) | D31: =B31*C31 -> 0
A32: ỚT CHUÔNG XANH | D32: =B32*C32 -> 0
A33: ỚT CHUÔNG XANH L1 | B33: 15 | C33: 21000 | D33: =B33*C33 -> 315000
A34: ỚT CHUÔNG XANH(TRÁI) | D34: =B34*C34 -> 0
A35: CỦ DỀN | B35: =10+5+17+5+20 -> 57 | C35: 10000 | D35: =B35*C35 -> 570000
A36: CỦ DỀN 600G | D36: =B36*C36 -> 0
A37: GỪNG 250GR | D37: =B37*C37 -> 0
A38: HỒNG GIÒN | D38: =B38*C38 -> 0
A39: XÀ LÁCH MỸ | D39: =B39*C39 -> 0
A40: KHOAI TÂY HỒNG | B40: 25 | C40: 25000 | D40: =B40*C40 -> 625000
...

Sheet 11.1
A1: hàng tồn cuối ngày 11/1
A2: TÊN SẢN PHẨM | B2: TỒN TRƯỚC | C2: GIÁ NHẬP | D2: THÀNH TIỀN
A3: CÀ CHUA SÔCOLA 250GR (HỘP) VR | B3: 34 | C3: 6000 | D3: =B3*C3 -> 204000
A4: CÀ CHUA SÔCOLA 250GR (KG) -NA | D4: =B4*C4 -> 0
A5: CÀ CHUA SÔCOLA 250GR (KG) VR | D5: =B5*C5 -> 0
A6: CÀ CHUA SÔCOLA 250GR(KG) KQ | D6: =B6*C6 -> 0
A7: CÀ CHUA SÔCOLA 300GR (HỘP) VR | D7: =B7*C7 -> 0
A8: CÀ CHUA SOCOLA XÁ | D8: =B8*C8 -> 0
A9: CÀ CHUA SÔCOLA(HỘP) KQ | D9: =B9*C9 -> 0
A10: CÀ RỐT BABY | D10: =B10*C10 -> 0
A11: CÀ RỐT BABY (KG) KQ | D11: =B11*C11 -> 0
A12: CÀ RỐT BABY 200GR | B12: 10 | C12: 9000 | D12: =B12*C12 -> 90000
A13: CẢI CẦU VỒNG | D13: =B13*C13 -> 0
A14: CẢI CẦU VỒNG 300GR | B14: 8 | C14: 4800 | D14: =B14*C14 -> 38400
A15: CẢI KALE | D15: =B15*C15 -> 0
A16: CẢI KALE 300GR | D16: =B16*C16 -> 0
A17: CHANH VÀNG (KG) | D17: =B17*C17 -> 0
A18: CHANH VÀNG TRÁI 180UP | D18: =B18*C18 -> 0
A19: CẦN TÂY (KG) | D19: =B19*C19 -> 0
A20: CẦN TÂY THUỶ CANH | D20: =B20*C20 -> 0
A21: CẦN TÂY(CÂY) | D21: =B21*C21 -> 0
A22: ỚT CHUÔNG 3 MÀU(KG)VR | D22: =B22*C22 -> 0
A23: ỚT CHUÔNG ĐỎ | B23: =20+25+10+5 -> 60 | C23: 35000 | D23: =B23*C23 -> 2100000
A24: ỚT CHUÔNG ĐỎ L1 | B24: 13 | C24: 28000 | D24: =B24*C24 -> 364000
A25: ỚT CHUÔNG ĐỎ(TRÁI) | D25: =B25*C25 -> 0
A26: ỚT CHUÔNG 3 MÀU 350G | B26: 100 | C26: 15000 | D26: =B26*C26 -> 1500000
A27: ỚT CHUÔNG 3 MÀU KQ(KG) | D27: =B27*C27 -> 0
A28: ỚT CHUÔNG VÀNG | B28: 35 | C28: 50000 | D28: =B28*C28 -> 1750000
A29: ỚT CHUÔNG VÀNG L1 | B29: 13 | C29: 40000 | D29: =B29*C29 -> 520000
A30: ỚT CHUÔNG VÀNG(TRÁI) | D30: =B30*C30 -> 0
A31: ỚT CHUÔNG VÀNG+ XANH (VỈ) | D31: =B31*C31 -> 0
A32: ỚT CHUÔNG XANH | B32: 80 | C32: 28000 | D32: =B32*C32 -> 2240000
A33: ỚT CHUÔNG XANH L1 | B33: 10 | C33: 21000 | D33: =B33*C33 -> 210000
A34: ỚT CHUÔNG XANH(TRÁI) | D34: =B34*C34 -> 0
A35: CỦ DỀN | B35: =40+48+10+25 -> 123 | C35: 11000 | D35: =B35*C35 -> 1353000
A36: CỦ DỀN 600G | D36: =B36*C36 -> 0
A37: GỪNG 250GR | D37: =B37*C37 -> 0
A38: HỒNG GIÒN | D38: =B38*C38 -> 0
A39: XÀ LÁCH MỸ | D39: =B39*C39 -> 0
A40: KHOAI TÂY HỒNG | B40: 3 | C40: 24000 | D40: =B40*C40 -> 72000
...

Sheet 12.1
A1: hàng tồn cuối ngày 12/1
A2: TÊN SẢN PHẨM | B2: TỒN TRƯỚC | C2: GIÁ NHẬP | D2: THÀNH TIỀN
A3: CÀ CHUA SÔCOLA 250GR (HỘP) VR | D3: =B3*C3 -> 0
A4: CÀ CHUA SÔCOLA 250GR (KG) -NA | D4: =B4*C4 -> 0
A5: CÀ CHUA SÔCOLA 250GR (KG) VR | D5: =B5*C5 -> 0
A6: CÀ CHUA SÔCOLA 250GR(KG) KQ | D6: =B6*C6 -> 0
A7: CÀ CHUA SÔCOLA 300GR (HỘP) VR | D7: =B7*C7 -> 0
A8: CÀ CHUA SOCOLA XÁ | D8: =B8*C8 -> 0
A9: CÀ CHUA SÔCOLA(HỘP) KQ | B9: 8 | C9: 6000 | D9: =B9*C9 -> 48000
A10: CÀ RỐT BABY | D10: =B10*C10 -> 0
A11: CÀ RỐT BABY (KG) KQ | D11: =B11*C11 -> 0
A12: CÀ RỐT BABY 200GR | D12: =B12*C12 -> 0
A13: CẢI CẦU VỒNG | D13: =B13*C13 -> 0
A14: CẢI CẦU VỒNG 300GR | D14: =B14*C14 -> 0
A15: CẢI KALE | D15: =B15*C15 -> 0
A16: CẢI KALE 300GR | B16: 13 | C16: 4000 | D16: =B16*C16 -> 52000
A17: CHANH VÀNG (KG) | D17: =B17*C17 -> 0
A18: CHANH VÀNG TRÁI 180UP | D18: =B18*C18 -> 0
A19: CẦN TÂY (KG) | D19: =B19*C19 -> 0
A20: CẦN TÂY THUỶ CANH | D20: =B20*C20 -> 0
A21: CẦN TÂY(CÂY) | D21: =B21*C21 -> 0
A22: ỚT CHUÔNG 3 MÀU(KG)VR | D22: =B22*C22 -> 0
A23: ỚT CHUÔNG ĐỎ | B23: 75 | C23: 35000 | D23: =B23*C23 -> 2625000
A24: ỚT CHUÔNG ĐỎ L1 | B24: 30 | C24: 28000 | D24: =B24*C24 -> 840000
A25: ỚT CHUÔNG ĐỎ(TRÁI) | D25: =B25*C25 -> 0
A26: ỚT CHUÔNG 3 MÀU 350G | B26: 100 | C26: 15000 | D26: =B26*C26 -> 1500000
A27: ỚT CHUÔNG 3 MÀU KQ(KG) | D27: =B27*C27 -> 0
A28: ỚT CHUÔNG VÀNG | B28: 15 | C28: 50000 | D28: =B28*C28 -> 750000
A29: ỚT CHUÔNG VÀNG L1 | B29: 14 | C29: 40000 | D29: =B29*C29 -> 560000
A30: ỚT CHUÔNG VÀNG(TRÁI) | D30: =B30*C30 -> 0
A31: ỚT CHUÔNG VÀNG+ XANH (VỈ) | D31: =B31*C31 -> 0
A32: ỚT CHUÔNG XANH | B32: =18+40 -> 58 | C32: 28000 | D32: =B32*C32 -> 1624000
A33: ỚT CHUÔNG XANH L1 | B33: 15 | C33: 21000 | D33: =B33*C33 -> 315000
A34: ỚT CHUÔNG XANH(TRÁI) | D34: =B34*C34 -> 0
A35: CỦ DỀN | B35: =20+20+40 -> 80 | C35: 10000 | D35: =B35*C35 -> 800000
A36: CỦ DỀN 600G | D36: =B36*C36 -> 0
A37: GỪNG 250GR | D37: =B37*C37 -> 0
A38: HỒNG GIÒN | D38: =B38*C38 -> 0
A39: XÀ LÁCH MỸ | D39: =B39*C39 -> 0
A40: KHOAI TÂY HỒNG | B40: 20 | C40: 24000 | D40: =B40*C40 -> 480000
...

Sheet 13.1
A1: hàng tồn cuối ngày 13/1
A2: TÊN SẢN PHẨM | B2: TỒN TRƯỚC | C2: GIÁ NHẬP | D2: THÀNH TIỀN
A3: CÀ CHUA SÔCOLA 250GR (HỘP) VR | B3: 12 | C3: 6000 | D3: =B3*C3 -> 72000
A4: CÀ CHUA SÔCOLA 250GR (KG) -NA | D4: =B4*C4 -> 0
A5: CÀ CHUA SÔCOLA 250GR (KG) VR | D5: =B5*C5 -> 0
A6: CÀ CHUA SÔCOLA 250GR(KG) KQ | D6: =B6*C6 -> 0
A7: CÀ CHUA SÔCOLA 300GR (HỘP) VR | D7: =B7*C7 -> 0
A8: CÀ CHUA SOCOLA XÁ | D8: =B8*C8 -> 0
A9: CÀ CHUA SÔCOLA(HỘP) KQ | D9: =B9*C9 -> 0
A10: CÀ RỐT BABY | D10: =B10*C10 -> 0
A11: CÀ RỐT BABY (KG) KQ | D11: =B11*C11 -> 0
A12: CÀ RỐT BABY 200GR | B12: 10 | C12: 8000 | D12: =B12*C12 -> 80000
A13: CẢI CẦU VỒNG | D13: =B13*C13 -> 0
A14: CẢI CẦU VỒNG 300GR | D14: =B14*C14 -> 0
A15: CẢI KALE | D15: =B15*C15 -> 0
A16: CẢI KALE 300GR | B16: 16 | C16: 3000 | D16: =B16*C16 -> 48000
A17: CHANH VÀNG (KG) | D17: =B17*C17 -> 0
A18: CHANH VÀNG TRÁI 180UP | D18: =B18*C18 -> 0
A19: CẦN TÂY (KG) | B19: 5 | C19: 15000 | D19: =B19*C19 -> 75000
A20: CẦN TÂY THUỶ CANH | D20: =B20*C20 -> 0
A21: CẦN TÂY(CÂY) | D21: =B21*C21 -> 0
A22: ỚT CHUÔNG 3 MÀU(KG)VR | D22: =B22*C22 -> 0
A23: ỚT CHUÔNG ĐỎ | B23: =20+14+50+15+10 -> 109 | C23: 35000 | D23: =B23*C23 -> 3815000
A24: ỚT CHUÔNG ĐỎ L1 | B24: 18 | C24: 28000 | D24: =B24*C24 -> 504000
A25: ỚT CHUÔNG ĐỎ(TRÁI) | D25: =B25*C25 -> 0
A26: ỚT CHUÔNG 3 MÀU 350G | D26: =B26*C26 -> 0
A27: ỚT CHUÔNG 3 MÀU KQ(KG) | D27: =B27*C27 -> 0
A28: ỚT CHUÔNG VÀNG | B28: =30+15 -> 45 | C28: 50000 | D28: =B28*C28 -> 2250000
A29: ỚT CHUÔNG VÀNG L1 | B29: 10 | C29: 40000 | D29: =B29*C29 -> 400000
A30: ỚT CHUÔNG VÀNG(TRÁI) | D30: =B30*C30 -> 0
A31: ỚT CHUÔNG VÀNG+ XANH (VỈ) | D31: =B31*C31 -> 0
A32: ỚT CHUÔNG XANH | B32: =20+10+9+10+18 -> 67 | C32: 28000 | D32: =B32*C32 -> 1876000
A33: ỚT CHUÔNG XANH L1 | B33: 10 | C33: 21000 | D33: =B33*C33 -> 210000
A34: ỚT CHUÔNG XANH(TRÁI) | D34: =B34*C34 -> 0
A35: CỦ DỀN | B35: =10+20+18 -> 48 | C35: 10000 | D35: =B35*C35 -> 480000
A36: CỦ DỀN 600G | D36: =B36*C36 -> 0
A37: GỪNG 250GR | D37: =B37*C37 -> 0
A38: HỒNG GIÒN | D38: =B38*C38 -> 0
A39: XÀ LÁCH MỸ | D39: =B39*C39 -> 0
A40: KHOAI TÂY HỒNG | D40: =B40*C40 -> 0
...

Sheet 14.1
A1: hàng tồn cuối ngày 14/1
A2: TÊN SẢN PHẨM | B2: TỒN TRƯỚC | C2: GIÁ NHẬP | D2: THÀNH TIỀN
A3: CÀ CHUA SÔCOLA 250GR (HỘP) VR | B3: 5 | C3: 6000 | D3: =B3*C3 -> 30000
A4: CÀ CHUA SÔCOLA 250GR (KG) -NA | D4: =B4*C4 -> 0
A5: CÀ CHUA SÔCOLA 250GR (KG) VR | D5: =B5*C5 -> 0
A6: CÀ CHUA SÔCOLA 250GR(KG) KQ | D6: =B6*C6 -> 0
A7: CÀ CHUA SÔCOLA 300GR (HỘP) VR | D7: =B7*C7 -> 0
A8: CÀ CHUA SOCOLA XÁ | D8: =B8*C8 -> 0
A9: CÀ CHUA SÔCOLA(HỘP) KQ | D9: =B9*C9 -> 0
A10: CÀ RỐT BABY | D10: =B10*C10 -> 0
A11: CÀ RỐT BABY (KG) KQ | D11: =B11*C11 -> 0
A12: CÀ RỐT BABY 200GR | D12: =B12*C12 -> 0
A13: CẢI CẦU VỒNG | D13: =B13*C13 -> 0
A14: CẢI CẦU VỒNG 300GR | D14: =B14*C14 -> 0
A15: CẢI KALE | D15: =B15*C15 -> 0
A16: CẢI KALE 300GR | B16: 20 | C16: 3000 | D16: =B16*C16 -> 60000
A17: CHANH VÀNG (KG) | D17: =B17*C17 -> 0
A18: CHANH VÀNG TRÁI 180UP | D18: =B18*C18 -> 0
A19: CẦN TÂY (KG) | B19: 3 | C19: 12000 | D19: =B19*C19 -> 36000
A20: CẦN TÂY THUỶ CANH | D20: =B20*C20 -> 0
A21: CẦN TÂY(CÂY) | D21: =B21*C21 -> 0
A22: ỚT CHUÔNG 3 MÀU(KG)VR | D22: =B22*C22 -> 0
A23: ỚT CHUÔNG ĐỎ | B23: =35+30+20 -> 85 | C23: 36000 | D23: =B23*C23 -> 3060000
A24: ỚT CHUÔNG ĐỎ L1 | B24: 27 | C24: 28000 | D24: =B24*C24 -> 756000
A25: ỚT CHUÔNG ĐỎ(TRÁI) | D25: =B25*C25 -> 0
A26: ỚT CHUÔNG 3 MÀU 350G | D26: =B26*C26 -> 0
A27: ỚT CHUÔNG 3 MÀU KQ(KG) | D27: =B27*C27 -> 0
A28: ỚT CHUÔNG VÀNG | B28: =25+20 -> 45 | C28: 50000 | D28: =B28*C28 -> 2250000
A29: ỚT CHUÔNG VÀNG L1 | D29: =B29*C29 -> 0
A30: ỚT CHUÔNG VÀNG(TRÁI) | D30: =B30*C30 -> 0
A31: ỚT CHUÔNG VÀNG+ XANH (VỈ) | D31: =B31*C31 -> 0
A32: ỚT CHUÔNG XANH | B32: 29 | C32: 28000 | D32: =B32*C32 -> 812000
A33: ỚT CHUÔNG XANH L1 | B33: 7 | C33: 21000 | D33: =B33*C33 -> 147000
A34: ỚT CHUÔNG XANH(TRÁI) | D34: =B34*C34 -> 0
A35: CỦ DỀN | B35: =67+5 -> 72 | C35: 10000 | D35: =B35*C35 -> 720000
A36: CỦ DỀN 600G | D36: =B36*C36 -> 0
A37: GỪNG 250GR | D37: =B37*C37 -> 0
A38: HỒNG GIÒN | D38: =B38*C38 -> 0
A39: XÀ LÁCH MỸ | D39: =B39*C39 -> 0
A40: KHOAI TÂY HỒNG | D40: =B40*C40 -> 0
...

Sheet 15.1
A1: hàng tồn cuối ngày 15/1
A2: TÊN SẢN PHẨM | B2: TỒN TRƯỚC | C2: GIÁ NHẬP | D2: THÀNH TIỀN
A3: CÀ CHUA SÔCOLA 250GR (HỘP) VR | D3: =B3*C3 -> 0
A4: CÀ CHUA SÔCOLA 250GR (KG) -NA | D4: =B4*C4 -> 0
A5: CÀ CHUA SÔCOLA 250GR (KG) VR | D5: =B5*C5 -> 0
A6: CÀ CHUA SÔCOLA 250GR(KG) KQ | D6: =B6*C6 -> 0
A7: CÀ CHUA SÔCOLA 300GR (HỘP) VR | D7: =B7*C7 -> 0
A8: CÀ CHUA SOCOLA XÁ | D8: =B8*C8 -> 0
A9: CÀ CHUA SÔCOLA(HỘP) KQ | D9: =B9*C9 -> 0
A10: CÀ RỐT BABY | D10: =B10*C10 -> 0
A11: CÀ RỐT BABY (KG) KQ | D11: =B11*C11 -> 0
A12: CÀ RỐT BABY 200GR | D12: =B12*C12 -> 0
A13: CẢI CẦU VỒNG | D13: =B13*C13 -> 0
A14: CẢI CẦU VỒNG 300GR | B14: 2 | C14: 4800 | D14: =B14*C14 -> 9600
A15: CẢI KALE | D15: =B15*C15 -> 0
A16: CẢI KALE 300GR | B16: 35 | C16: 3000 | D16: =B16*C16 -> 105000
A17: CHANH VÀNG (KG) | D17: =B17*C17 -> 0
A18: CHANH VÀNG TRÁI 180UP | D18: =B18*C18 -> 0
A19: CẦN TÂY (KG) | D19: =B19*C19 -> 0
A20: CẦN TÂY THUỶ CANH | D20: =B20*C20 -> 0
A21: CẦN TÂY(CÂY) | D21: =B21*C21 -> 0
A22: ỚT CHUÔNG 3 MÀU(KG)VR | D22: =B22*C22 -> 0
A23: ỚT CHUÔNG ĐỎ | B23: =6+60+45+20 -> 131 | C23: 36000 | D23: =B23*C23 -> 4716000
A24: ỚT CHUÔNG ĐỎ L1 | D24: =B24*C24 -> 0
A25: ỚT CHUÔNG ĐỎ(TRÁI) | D25: =B25*C25 -> 0
A26: ỚT CHUÔNG 3 MÀU 350G | D26: =B26*C26 -> 0
A27: ỚT CHUÔNG 3 MÀU KQ(KG) | D27: =B27*C27 -> 0
A28: ỚT CHUÔNG VÀNG | B28: 18 | C28: 50000 | D28: =B28*C28 -> 900000
A29: ỚT CHUÔNG VÀNG L1 | D29: =B29*C29 -> 0
A30: ỚT CHUÔNG VÀNG(TRÁI) | D30: =B30*C30 -> 0
A31: ỚT CHUÔNG VÀNG+ XANH (VỈ) | D31: =B31*C31 -> 0
A32: ỚT CHUÔNG XANH | B32: =9+11+15+75 -> 110 | C32: 28000 | D32: =B32*C32 -> 3080000
A33: ỚT CHUÔNG XANH L1 | D33: =B33*C33 -> 0
A34: ỚT CHUÔNG XANH(TRÁI) | D34: =B34*C34 -> 0
A35: CỦ DỀN | B35: =8+10+15+55 -> 88 | C35: 10000 | D35: =B35*C35 -> 880000
A36: CỦ DỀN 600G | D36: =B36*C36 -> 0
A37: GỪNG 250GR | D37: =B37*C37 -> 0
A38: HỒNG GIÒN | D38: =B38*C38 -> 0
A39: XÀ LÁCH MỸ | D39: =B39*C39 -> 0
A40: KHOAI TÂY HỒNG | D40: =B40*C40 -> 0
...

Sheet 16.1
A1: hàng tồn cuối ngày 16/1
A2: TÊN SẢN PHẨM | B2: TỒN TRƯỚC | C2: GIÁ NHẬP | D2: THÀNH TIỀN
A3: CÀ CHUA SÔCOLA 250GR (HỘP) VR | B3: 8 | C3: 6000 | D3: =B3*C3 -> 48000
A4: CÀ CHUA SÔCOLA 250GR (KG) -NA | D4: =B4*C4 -> 0
A5: CÀ CHUA SÔCOLA 250GR (KG) VR | D5: =B5*C5 -> 0
A6: CÀ CHUA SÔCOLA 250GR(KG) KQ | D6: =B6*C6 -> 0
A7: CÀ CHUA SÔCOLA 300GR (HỘP) VR | D7: =B7*C7 -> 0
A8: CÀ CHUA SOCOLA XÁ | D8: =B8*C8 -> 0
A9: CÀ CHUA SÔCOLA(HỘP) KQ | D9: =B9*C9 -> 0
A10: CÀ RỐT BABY | D10: =B10*C10 -> 0
A11: CÀ RỐT BABY (KG) KQ | D11: =B11*C11 -> 0
A12: CÀ RỐT BABY 200GR | D12: =B12*C12 -> 0
A13: CẢI CẦU VỒNG | D13: =B13*C13 -> 0
A14: CẢI CẦU VỒNG 300GR | B14: 1 | C14: 4800 | D14: =B14*C14 -> 4800
A15: CẢI KALE | D15: =B15*C15 -> 0
A16: CẢI KALE 300GR | D16: =B16*C16 -> 0
A17: CHANH VÀNG (KG) | D17: =B17*C17 -> 0
A18: CHANH VÀNG TRÁI 180UP | D18: =B18*C18 -> 0
A19: CẦN TÂY (KG) | D19: =B19*C19 -> 0
A20: CẦN TÂY THUỶ CANH | D20: =B20*C20 -> 0
A21: CẦN TÂY(CÂY) | D21: =B21*C21 -> 0
A22: ỚT CHUÔNG 3 MÀU(KG)VR | D22: =B22*C22 -> 0
A23: ỚT CHUÔNG ĐỎ | B23: =80+85+20+50 -> 235 | C23: 36000 | D23: =B23*C23 -> 8460000
A24: ỚT CHUÔNG ĐỎ L1 | D24: =B24*C24 -> 0
A25: ỚT CHUÔNG ĐỎ(TRÁI) | D25: =B25*C25 -> 0
A26: ỚT CHUÔNG 3 MÀU 350G | B26: 40 | C26: 15000 | D26: =B26*C26 -> 600000
A27: ỚT CHUÔNG 3 MÀU KQ(KG) | D27: =B27*C27 -> 0
A28: ỚT CHUÔNG VÀNG | B28: =40+10+8+99 -> 157 | C28: 50000 | D28: =B28*C28 -> 7850000
A29: ỚT CHUÔNG VÀNG L1 | B29: 10 | C29: 40000 | D29: =B29*C29 -> 400000
A30: ỚT CHUÔNG VÀNG(TRÁI) | D30: =B30*C30 -> 0
A31: ỚT CHUÔNG VÀNG+ XANH (VỈ) | D31: =B31*C31 -> 0
A32: ỚT CHUÔNG XANH | B32: =10+25+20 -> 55 | C32: 28000 | D32: =B32*C32 -> 1540000
A33: ỚT CHUÔNG XANH L1 | D33: =B33*C33 -> 0
A34: ỚT CHUÔNG XANH(TRÁI) | D34: =B34*C34 -> 0
A35: CỦ DỀN | B35: =50+10+7+50 -> 117 | C35: 10000 | D35: =B35*C35 -> 1170000
A36: CỦ DỀN 600G | D36: =B36*C36 -> 0
A37: GỪNG 250GR | D37: =B37*C37 -> 0
A38: HỒNG GIÒN | D38: =B38*C38 -> 0
A39: XÀ LÁCH MỸ | D39: =B39*C39 -> 0
A40: KHOAI TÂY HỒNG | B40: 25 | C40: 24000 | D40: =B40*C40 -> 600000
...

Sheet 17.1
A1: hàng tồn cuối ngày 17/1
A2: TÊN SẢN PHẨM | B2: TỒN TRƯỚC | C2: GIÁ NHẬP | D2: THÀNH TIỀN
A3: CÀ CHUA SÔCOLA 250GR (HỘP) VR | D3: =B3*C3 -> 0
A4: CÀ CHUA SÔCOLA 250GR (KG) -NA | D4: =B4*C4 -> 0
A5: CÀ CHUA SÔCOLA 250GR (KG) VR | D5: =B5*C5 -> 0
A6: CÀ CHUA SÔCOLA 250GR(KG) KQ | D6: =B6*C6 -> 0
A7: CÀ CHUA SÔCOLA 300GR (HỘP) VR | D7: =B7*C7 -> 0
A8: CÀ CHUA SOCOLA XÁ | D8: =B8*C8 -> 0
A9: CÀ CHUA SÔCOLA(HỘP) KQ | D9: =B9*C9 -> 0
A10: CÀ RỐT BABY | D10: =B10*C10 -> 0
A11: CÀ RỐT BABY (KG) KQ | D11: =B11*C11 -> 0
A12: CÀ RỐT BABY 200GR | D12: =B12*C12 -> 0
A13: CẢI CẦU VỒNG | D13: =B13*C13 -> 0
A14: CẢI CẦU VỒNG 300GR | D14: =B14*C14 -> 0
A15: CẢI KALE | D15: =B15*C15 -> 0
A16: CẢI KALE 300GR | B16: 8 | C16: 3000 | D16: =B16*C16 -> 24000
A17: CHANH VÀNG (KG) | D17: =B17*C17 -> 0
A18: CHANH VÀNG TRÁI 180UP | D18: =B18*C18 -> 0
A19: CẦN TÂY (KG) | D19: =B19*C19 -> 0
A20: CẦN TÂY THUỶ CANH | D20: =B20*C20 -> 0
A21: CẦN TÂY(CÂY) | D21: =B21*C21 -> 0
A22: ỚT CHUÔNG 3 MÀU(KG)VR | D22: =B22*C22 -> 0
A23: ỚT CHUÔNG ĐỎ | B23: 107 | C23: 36000 | D23: =B23*C23 -> 3852000
A24: ỚT CHUÔNG ĐỎ L1 | D24: =B24*C24 -> 0
A25: ỚT CHUÔNG ĐỎ(TRÁI) | D25: =B25*C25 -> 0
A26: ỚT CHUÔNG 3 MÀU 350G | D26: =B26*C26 -> 0
A27: ỚT CHUÔNG 3 MÀU KQ(KG) | D27: =B27*C27 -> 0
A28: ỚT CHUÔNG VÀNG | B28: 100 | C28: 50000 | D28: =B28*C28 -> 5000000
A29: ỚT CHUÔNG VÀNG L1 | B29: 10 | C29: 40000 | D29: =B29*C29 -> 400000
A30: ỚT CHUÔNG VÀNG(TRÁI) | D30: =B30*C30 -> 0
A31: ỚT CHUÔNG VÀNG+ XANH (VỈ) | D31: =B31*C31 -> 0
A32: ỚT CHUÔNG XANH | B32: =3+30+8+10 -> 51 | C32: 28000 | D32: =B32*C32 -> 1428000
A33: ỚT CHUÔNG XANH L1 | D33: =B33*C33 -> 0
A34: ỚT CHUÔNG XANH(TRÁI) | D34: =B34*C34 -> 0
A35: CỦ DỀN | B35: 60 | C35: 10000 | D35: =B35*C35 -> 600000
A36: CỦ DỀN 600G | D36: =B36*C36 -> 0
A37: GỪNG 250GR | D37: =B37*C37 -> 0
A38: HỒNG GIÒN | D38: =B38*C38 -> 0
A39: XÀ LÁCH MỸ | D39: =B39*C39 -> 0
A40: KHOAI TÂY HỒNG | B40: 3 | C40: 20000 | D40: =B40*C40 -> 60000
...

Sheet 18.1
A1: hàng tồn cuối ngày 18/1
A2: TÊN SẢN PHẨM | B2: TỒN TRƯỚC | C2: GIÁ NHẬP | D2: THÀNH TIỀN
A3: CÀ CHUA SÔCOLA 250GR (HỘP) VR | D3: =B3*C3 -> 0
A4: CÀ CHUA SÔCOLA 250GR (KG) -NA | D4: =B4*C4 -> 0
A5: CÀ CHUA SÔCOLA 250GR (KG) VR | D5: =B5*C5 -> 0
A6: CÀ CHUA SÔCOLA 250GR(KG) KQ | D6: =B6*C6 -> 0
A7: CÀ CHUA SÔCOLA 300GR (HỘP) VR | D7: =B7*C7 -> 0
A8: CÀ CHUA SOCOLA XÁ | D8: =B8*C8 -> 0
A9: CÀ CHUA SÔCOLA(HỘP) KQ | D9: =B9*C9 -> 0
A10: CÀ RỐT BABY | D10: =B10*C10 -> 0
A11: CÀ RỐT BABY (KG) KQ | D11: =B11*C11 -> 0
A12: CÀ RỐT BABY 200GR | D12: =B12*C12 -> 0
A13: CẢI CẦU VỒNG | D13: =B13*C13 -> 0
A14: CẢI CẦU VỒNG 300GR | D14: =B14*C14 -> 0
... A22: ỚT CHUÔNG 3 MÀU(KG)VR | D22: =B22*C22 -> 0
A23: ỚT CHUÔNG ĐỎ | B23: =40+68+15 -> 123 | C23: 36000 | D23: =B23*C23 -> 4428000
A24: ỚT CHUÔNG ĐỎ L1 | D24: =B24*C24 -> 0
A25: ỚT CHUÔNG ĐỎ(TRÁI) | D25: =B25*C25 -> 0
A26: ỚT CHUÔNG 3 MÀU 350G | D26: =B26*C26 -> 0
A27: ỚT CHUÔNG 3 MÀU KQ(KG) | D27: =B27*C27 -> 0
A28: ỚT CHUÔNG VÀNG | D28: =B28*C28 -> 0
A29: ỚT CHUÔNG VÀNG L1 | B29: 6 | C29: 40000 | D29: =B29*C29 -> 240000
A30: ỚT CHUÔNG VÀNG(TRÁI) | D30: =B30*C30 -> 0
A31: ỚT CHUÔNG VÀNG+ XANH (VỈ) | D31: =B31*C31 -> 0
A32: ỚT CHUÔNG XANH | B32: =5+20+5+30 -> 60 | C32: 28000 | D32: =B32*C32 -> 1680000
A33: ỚT CHUÔNG XANH L1 | D33: =B33*C33 -> 0
A34: ỚT CHUÔNG XANH(TRÁI) | D34: =B34*C34 -> 0
A35: CỦ DỀN | B35: =10+80+10 -> 100 | C35: 10000 | D35: =B35*C35 -> 1000000
A36: CỦ DỀN 600G | D36: =B36*C36 -> 0
A37: GỪNG 250GR | D37: =B37*C37 -> 0
A38: HỒNG GIÒN | D38: =B38*C38 -> 0
A39: XÀ LÁCH MỸ | D39: =B39*C39 -> 0
A40: KHOAI TÂY HỒNG | B40: 5 | C40: 20000 | D40: =B40*C40 -> 100000
A41: KHOAI TÂY HỒNG TÚI LƯỚI 500G | D41: =B41*C41 -> 0
A42: KHOAI TÂY VÀNG | D42: =B42*C42 -> 0
A43: KHOAI TÂY VÀNG ĐL | B43: =140+20 -> 160 | C43: 14000 | D43: =B43*C43 -> 2240000
A44: KHOAI TÂY VÀNG LỚN TÚI LƯỚI 500G | D44: =B44*C44 -> 0
A45: KHOAI TÂY VÀNG RỬA | D45: =B45*C45 -> 0
A46: KHOAI TÂY VÀNG TRUNG TÚI LƯỚI 500G | D46: =B46*C46 -> 0
A47: CẢI THẢO DL | D47: =B47*C47 -> 0
...

Sheet 19.1
A1: hàng tồn cuối ngày 19/1
A2: TÊN SẢN PHẨM | B2: TỒN TRƯỚC | C2: GIÁ NHẬP | D2: THÀNH TIỀN
A3: CÀ CHUA SÔCOLA 250GR (HỘP) VR | D3: =B3*C3 -> 0
A4: CÀ CHUA SÔCOLA 250GR (KG) -NA | D4: =B4*C4 -> 0
A5: CÀ CHUA SÔCOLA 250GR (KG) VR | D5: =B5*C5 -> 0
A6: CÀ CHUA SÔCOLA 250GR(KG) KQ | D6: =B6*C6 -> 0
A7: CÀ CHUA SÔCOLA 300GR (HỘP) VR | D7: =B7*C7 -> 0
A8: CÀ CHUA SOCOLA XÁ | D8: =B8*C8 -> 0
A9: CÀ CHUA SÔCOLA(HỘP) KQ | D9: =B9*C9 -> 0
A10: CÀ RỐT BABY | D10: =B10*C10 -> 0
A11: CÀ RỐT BABY (KG) KQ | D11: =B11*C11 -> 0
A12: CÀ RỐT BABY 200GR | D12: =B12*C12 -> 0
A13: CẢI CẦU VỒNG | D13: =B13*C13 -> 0
A14: CẢI CẦU VỒNG 300GR | D14: =B14*C14 -> 0
... A22: ỚT CHUÔNG 3 MÀU(KG)VR | D22: =B22*C22 -> 0
A23: ỚT CHUÔNG ĐỎ | B23: =60+8+40+5+45 -> 158 | C23: 34000 | D23: =B23*C23 -> 5372000
A24: ỚT CHUÔNG ĐỎ L1 | D24: =B24*C24 -> 0
A25: ỚT CHUÔNG ĐỎ(TRÁI) | D25: =B25*C25 -> 0
A26: ỚT CHUÔNG 3 MÀU 350G | D26: =B26*C26 -> 0
A27: ỚT CHUÔNG 3 MÀU KQ(KG) | D27: =B27*C27 -> 0
A28: ỚT CHUÔNG VÀNG | B28: =70+5+15 -> 90 | C28: 48000 | D28: =B28*C28 -> 4320000
A29: ỚT CHUÔNG VÀNG L1 | D29: =B29*C29 -> 0
A30: ỚT CHUÔNG VÀNG(TRÁI) | D30: =B30*C30 -> 0
A31: ỚT CHUÔNG VÀNG+ XANH (VỈ) | D31: =B31*C31 -> 0
A32: ỚT CHUÔNG XANH | B32: =5+18+26+7 -> 56 | C32: 25000 | D32: =B32*C32 -> 1400000
A33: ỚT CHUÔNG XANH L1 | D33: =B33*C33 -> 0
A34: ỚT CHUÔNG XANH(TRÁI) | D34: =B34*C34 -> 0
A35: CỦ DỀN | B35: =35+10 -> 45 | C35: 10000 | D35: =B35*C35 -> 450000
A36: CỦ DỀN 600G | D36: =B36*C36 -> 0
A37: GỪNG 250GR | D37: =B37*C37 -> 0
A38: HỒNG GIÒN | D38: =B38*C38 -> 0
A39: XÀ LÁCH MỸ | D39: =B39*C39 -> 0
A40: KHOAI TÂY HỒNG | B40: 20 | C40: 20000 | D40: =B40*C40 -> 400000
A41: KHOAI TÂY HỒNG TÚI LƯỚI 500G | D41: =B41*C41 -> 0
A42: KHOAI TÂY VÀNG | D42: =B42*C42 -> 0
A43: KHOAI TÂY VÀNG ĐL | B43: =12+20 -> 32 | C43: 14000 | D43: =B43*C43 -> 448000
A44: KHOAI TÂY VÀNG LỚN TÚI LƯỚI 500G | D44: =B44*C44 -> 0
A45: KHOAI TÂY VÀNG RỬA | D45: =B45*C45 -> 0
A46: KHOAI TÂY VÀNG TRUNG TÚI LƯỚI 500G | D46: =B46*C46 -> 0
A47: CẢI THẢO DL | D47: =B47*C47 -> 0
...

Sheet 20.1
A1: hàng tồn cuối ngày 20/1
A2: TÊN SẢN PHẨM | B2: TỒN TRƯỚC | C2: GIÁ NHẬP | D2: THÀNH TIỀN
A3: CÀ CHUA SÔCOLA 250GR (HỘP) VR | D3: =B3*C3 -> 0
A4: CÀ CHUA SÔCOLA 250GR (KG) -NA | D4: =B4*C4 -> 0
A5: CÀ CHUA SÔCOLA 250GR (KG) VR | D5: =B5*C5 -> 0
A6: CÀ CHUA SÔCOLA 250GR(KG) KQ | D6: =B6*C6 -> 0
A7: CÀ CHUA SÔCOLA 300GR (HỘP) VR | D7: =B7*C7 -> 0
A8: CÀ CHUA SOCOLA XÁ | D8: =B8*C8 -> 0
A9: CÀ CHUA SÔCOLA(HỘP) KQ | D9: =B9*C9 -> 0
A10: CÀ RỐT BABY | D10: =B10*C10 -> 0
A11: CÀ RỐT BABY (KG) KQ | D11: =B11*C11 -> 0
A12: CÀ RỐT BABY 200GR | D12: =B12*C12 -> 0
A13: CẢI CẦU VỒNG | D13: =B13*C13 -> 0
A14: CẢI CẦU VỒNG 300GR | D14: =B14*C14 -> 0
... A22: ỚT CHUÔNG 3 MÀU(KG)VR | D22: =B22*C22 -> 0
A23: ỚT CHUÔNG ĐỎ | B23: =130+8 -> 138 | C23: 34000 | D23: =B23*C23 -> 4692000
A24: ỚT CHUÔNG ĐỎ L1 | D24: =B24*C24 -> 0
A25: ỚT CHUÔNG ĐỎ(TRÁI) | D25: =B25*C25 -> 0
A26: ỚT CHUÔNG 3 MÀU 350G | B26: 20 | C26: 13000 | D26: =B26*C26 -> 260000
A27: ỚT CHUÔNG 3 MÀU KQ(KG) | D27: =B27*C27 -> 0
A28: ỚT CHUÔNG VÀNG | B28: 60 | C28: 48000 | D28: =B28*C28 -> 2880000
A29: ỚT CHUÔNG VÀNG L1 | D29: =B29*C29 -> 0
A30: ỚT CHUÔNG VÀNG(TRÁI) | D30: =B30*C30 -> 0
A31: ỚT CHUÔNG VÀNG+ XANH (VỈ) | D31: =B31*C31 -> 0
A32: ỚT CHUÔNG XANH | B32: 45 | C32: 25000 | D32: =B32*C32 -> 1125000
A33: ỚT CHUÔNG XANH L1 | D33: =B33*C33 -> 0
A34: ỚT CHUÔNG XANH(TRÁI) | D34: =B34*C34 -> 0
A35: CỦ DỀN | B35: =15+40 -> 55 | C35: 10000 | D35: =B35*C35 -> 550000
A36: CỦ DỀN 600G | D36: =B36*C36 -> 0
A37: GỪNG 250GR | D37: =B37*C37 -> 0
A38: HỒNG GIÒN | D38: =B38*C38 -> 0
A39: XÀ LÁCH MỸ | D39: =B39*C39 -> 0
A40: KHOAI TÂY HỒNG | B40: 3 | C40: 20000 | D40: =B40*C40 -> 60000
A41: KHOAI TÂY HỒNG TÚI LƯỚI 500G | D41: =B41*C41 -> 0
A42: KHOAI TÂY VÀNG | D42: =B42*C42 -> 0
A43: KHOAI TÂY VÀNG ĐL | D43: =B43*C43 -> 0
A44: KHOAI TÂY VÀNG LỚN TÚI LƯỚI 500G | D44: =B44*C44 -> 0
A45: KHOAI TÂY VÀNG RỬA | D45: =B45*C45 -> 0
A46: KHOAI TÂY VÀNG TRUNG TÚI LƯỚI 500G | D46: =B46*C46 -> 0
A47: CẢI THẢO DL | D47: =B47*C47 -> 0
...

Sheet 21.1
A1: hàng tồn cuối ngày 21/11
A2: TÊN SẢN PHẨM | B2: TỒN TRƯỚC | C2: GIÁ NHẬP | D2: THÀNH TIỀN
A3: CÀ CHUA SÔCOLA 250GR (HỘP) VR | D3: =B3*C3 -> 0
A4: CÀ CHUA SÔCOLA 250GR (KG) -NA | D4: =B4*C4 -> 0
A5: CÀ CHUA SÔCOLA 250GR (KG) VR | D5: =B5*C5 -> 0
A6: CÀ CHUA SÔCOLA 250GR(KG) KQ | D6: =B6*C6 -> 0
A7: CÀ CHUA SÔCOLA 300GR (HỘP) VR | D7: =B7*C7 -> 0
A8: CÀ CHUA SOCOLA XÁ | D8: =B8*C8 -> 0
A9: CÀ CHUA SÔCOLA(HỘP) KQ | D9: =B9*C9 -> 0
A10: CÀ RỐT BABY | D10: =B10*C10 -> 0
A11: CÀ RỐT BABY (KG) KQ | D11: =B11*C11 -> 0
A12: CÀ RỐT BABY 200GR | D12: =B12*C12 -> 0
A13: CẢI CẦU VỒNG | D13: =B13*C13 -> 0
A14: CẢI CẦU VỒNG 300GR | D14: =B14*C14 -> 0
... A22: ỚT CHUÔNG 3 MÀU(KG)VR | D22: =B22*C22 -> 0
A23: ỚT CHUÔNG ĐỎ | B23: 80 | C23: 32000 | D23: =B23*C23 -> 2560000
A24: ỚT CHUÔNG ĐỎ L1 | D24: =B24*C24 -> 0
A25: ỚT CHUÔNG ĐỎ(TRÁI) | D25: =B25*C25 -> 0
A26: ỚT CHUÔNG 3 MÀU 350G | D26: =B26*C26 -> 0
A27: ỚT CHUÔNG 3 MÀU KQ(KG) | D27: =B27*C27 -> 0
A28: ỚT CHUÔNG VÀNG | B28: 8 | C28: 42000 | D28: =B28*C28 -> 336000
A29: ỚT CHUÔNG VÀNG L1 | D29: =B29*C29 -> 0
A30: ỚT CHUÔNG VÀNG(TRÁI) | D30: =B30*C30 -> 0
A31: ỚT CHUÔNG VÀNG+ XANH (VỈ) | D31: =B31*C31 -> 0
A32: ỚT CHUÔNG XANH | B32: =25+3+5 -> 33 | C32: 22000 | D32: =B32*C32 -> 726000
A33: ỚT CHUÔNG XANH L1 | D33: =B33*C33 -> 0
A34: ỚT CHUÔNG XANH(TRÁI) | D34: =B34*C34 -> 0
A35: CỦ DỀN | B35: =68+8 -> 76 | C35: 10000 | D35: =B35*C35 -> 760000
A36: CỦ DỀN 600G | D36: =B36*C36 -> 0
A37: GỪNG 250GR | D37: =B37*C37 -> 0
A38: HỒNG GIÒN | D38: =B38*C38 -> 0
A39: XÀ LÁCH MỸ | D39: =B39*C39 -> 0
A40: KHOAI TÂY HỒNG | B40: 20 | C40: 20000 | D40: =B40*C40 -> 400000
A41: KHOAI TÂY HỒNG TÚI LƯỚI 500G | D41: =B41*C41 -> 0
A42: KHOAI TÂY VÀNG | D42: =B42*C42 -> 0
A43: KHOAI TÂY VÀNG ĐL | B43: =15+215 -> 230 | C43: 14000 | D43: =B43*C43 -> 3220000
A44: KHOAI TÂY VÀNG LỚN TÚI LƯỚI 500G | D44: =B44*C44 -> 0
A45: KHOAI TÂY VÀNG RỬA | D45: =B45*C45 -> 0
A46: KHOAI TÂY VÀNG TRUNG TÚI LƯỚI 500G | B46: 16 | C46: 6000 | D46: =B46*C46 -> 96000
A47: CẢI THẢO DL | B47: 10 | C47: 6000 | D47: =B47*C47 -> 60000
...

Sheet 22.1
A1: hàng tồn cuối ngày 22/1
A2: TÊN SẢN PHẨM | B2: TỒN TRƯỚC | C2: GIÁ NHẬP | D2: THÀNH TIỀN
A3: CÀ CHUA SÔCOLA 250GR (HỘP) VR | D3: =B3*C3 -> 0
A4: CÀ CHUA SÔCOLA 250GR (KG) -NA | D4: =B4*C4 -> 0
A5: CÀ CHUA SÔCOLA 250GR (KG) VR | D5: =B5*C5 -> 0
A6: CÀ CHUA SÔCOLA 250GR(KG) KQ | D6: =B6*C6 -> 0
A7: CÀ CHUA SÔCOLA 300GR (HỘP) VR | D7: =B7*C7 -> 0
A8: CÀ CHUA SOCOLA XÁ | D8: =B8*C8 -> 0
A9: CÀ CHUA SÔCOLA(HỘP) KQ | D9: =B9*C9 -> 0
A10: CÀ RỐT BABY | D10: =B10*C10 -> 0
A11: CÀ RỐT BABY (KG) KQ | D11: =B11*C11 -> 0
A12: CÀ RỐT BABY 200GR | D12: =B12*C12 -> 0
A13: CẢI CẦU VỒNG | D13: =B13*C13 -> 0
A14: CẢI CẦU VỒNG 300GR | D14: =B14*C14 -> 0
A15: CẢI KALE | D15: =B15*C15 -> 0
A16: CẢI KALE 300GR | B16: 11 | C16: 3000 | D16: =B16*C16 -> 33000
A17: CHANH VÀNG (KG) | D17: =B17*C17 -> 0
A18: CHANH VÀNG TRÁI 180UP | D18: =B18*C18 -> 0
A19: CẦN TÂY (KG) | D19: =B19*C19 -> 0
A20: CẦN TÂY THUỶ CANH | D20: =B20*C20 -> 0
A21: CẦN TÂY(CÂY) | D21: =B21*C21 -> 0
A22: ỚT CHUÔNG 3 MÀU(KG)VR | D22: =B22*C22 -> 0
A23: ỚT CHUÔNG ĐỎ | B23: =20+60+20 -> 100 | C23: 32000 | D23: =B23*C23 -> 3200000
A24: ỚT CHUÔNG ĐỎ L1 | D24: =B24*C24 -> 0
A25: ỚT CHUÔNG ĐỎ(TRÁI) | D25: =B25*C25 -> 0
A26: ỚT CHUÔNG 3 MÀU 350G | D26: =B26*C26 -> 0
A27: ỚT CHUÔNG 3 MÀU KQ(KG) | D27: =B27*C27 -> 0
A28: ỚT CHUÔNG VÀNG | B28: =17+67 -> 84 | C28: 42000 | D28: =B28*C28 -> 3528000
A29: ỚT CHUÔNG VÀNG L1 | D29: =B29*C29 -> 0
A30: ỚT CHUÔNG VÀNG(TRÁI) | D30: =B30*C30 -> 0
A31: ỚT CHUÔNG VÀNG+ XANH (VỈ) | D31: =B31*C31 -> 0
A32: ỚT CHUÔNG XANH | B32: =30+28 -> 58 | C32: 22000 | D32: =B32*C32 -> 1276000
A33: ỚT CHUÔNG XANH L1 | D33: =B33*C33 -> 0
A34: ỚT CHUÔNG XANH(TRÁI) | D34: =B34*C34 -> 0
A35: CỦ DỀN | B35: 130 | C35: 10000 | D35: =B35*C35 -> 1300000
A36: CỦ DỀN 600G | D36: =B36*C36 -> 0
A37: GỪNG 250GR | D37: =B37*C37 -> 0
A38: HỒNG GIÒN | D38: =B38*C38 -> 0
A39: XÀ LÁCH MỸ | D39: =B39*C39 -> 0
A40: KHOAI TÂY HỒNG | B40: 18 | C40: 20000 | D40: =B40*C40 -> 360000
...

Sheet 23.1
A1: hàng tồn cuối ngày 23/1 | B1: Stock | D1: Safety stock
A2: TÊN SẢN PHẨM | B2: TỒN TRƯỚC | C2: GIÁ NHẬP | D2: THÀNH TIỀN
A3: BẮP CẢI TÍM | B3: 20 | C3: 21000 | D3: =B3*C3 -> 420000
A4: BẮP CẢI TÍM (BẮP) | D4: =B4*C4 -> 0
A5: BẮP CẢI TÍM SUSHI | D5: =B5*C5 -> 0
A6: BẮP CẢI TRẮNG | B6: 50 | C6: 6500 | D6: =B6*C6 -> 325000
A7: BẮP CẢI TRẮNG (BẮP) | D7: =B7*C7 -> 0
A8: BẮP CẢI TRẮNG MỘC CHÂU | D8: =B8*C8 -> 0
A9: BẮP CẢI TRẮNG SUSHI | D9: =B9*C9 -> 0
A10: BẮP MỸ | D10: =B10*C10 -> 0
A11: BẦU | D11: =B11*C11 -> 0
A12: BÍ ĐAO XANH | D12: =B12*C12 -> 0
A13: BÍ ĐAO XANH 400G | D13: =B13*C13 -> 0
A14: BÍ ĐỎ HỒ LÔ | B14: 24 | C14: 10000 | D14: =B14*C14 -> 240000
A15: BÍ ĐỎ MINI | D15: =B15*C15 -> 0
A16: BÍ ĐỎ NON (KG)KQ | D16: =B16*C16 -> 0
A17: BÍ ĐỎ NON TRÁI VR | B17: 14 | C17: 4000 | D17: =B17*C17 -> 56000
A18: BÍ ĐỎ NON( KG) VR | D18: =B18*C18 -> 0
A19: BÍ ĐỎ TRÒN | B19: =700+466 -> 1166 | C19: 6000 | D19: =B19*C19 -> 6996000
A20: BÍ MINI VÀNG 300GR | D20: =B20*C20 -> 0
A21: BÍ MINI VÀNG KG | D21: =B21*C21 -> 0
A22: BÍ NGÒI VÀNG | D22: =B22*C22 -> 0
A23: BÍ NGÒI VÀNG (TRÁI) | D23: =B23*C23 -> 0
A24: BÍ NGÒI XANH | B24: 26 | C24: 11000 | D24: =B24*C24 -> 286000
A25: BÍ NGÒI XANH(TRÁI) | D25: =B25*C25 -> 0
A26: BÍ NHẬT | D26: =B26*C26 -> 0
A27: BƠ 034 | D27: =B27*C27 -> 0
A28: BƠ BOOTH | D28: =B28*C28 -> 0
A29: BƠ SÁP | D29: =B29*C29 -> 0
A30: BÓ XÔI | D30: =B30*C30 -> 0
A31: BÓ XÔI 300G VR | B31: 6 | C31: 5700 | D31: =B31*C31 -> 34200
A32: BÓ XÔI-HN KQ | D32: =B32*C32 -> 0
A33: BÓ XÔI-NA | D33: =B33*C33 -> 0
A34: BÔNG ATISO | D34: =B34*C34 -> 0
A35: BÔNG BÍ | B35: 1 | C35: 45000 | D35: =B35*C35 -> 45000
A36: BÔNG BÍ TÚI 300GR | D36: =B36*C36 -> 0
A37: BÔNG CẢI TRẮNG | B37: 10 | C37: 12000 | D37: =B37*C37 -> 120000
A38: BÔNG CẢI TRẮNG (CÂY) | D38: =B38*C38 -> 0
A39: BÔNG CẢI XANH 10P | D39: =B39*C39 -> 0
A40: BÔNG CẢI XANH AEON | D40: =B40*C40 -> 0
...

Sheet 24.1
A1: hàng tồn cuối ngày 24/1 | B1: Stock | D1: Safety stock
A2: TÊN SẢN PHẨM | B2: TỒN TRƯỚC | C2: GIÁ NHẬP | D2: THÀNH TIỀN
A3: BẮP CẢI TÍM | B3: 6 | C3: 21000 | D3: =B3*C3 -> 126000
A4: CÀ CHUA SÔCOLA 250GR (KG) -NA | D4: =B4*C4 -> 0
A5: CÀ CHUA SÔCOLA 250GR (KG) VR | D5: =B5*C5 -> 0
A6: CÀ CHUA SÔCOLA 250GR(KG) KQ | D6: =B6*C6 -> 0
A7: CÀ CHUA SÔCOLA 300GR (HỘP) VR | D7: =B7*C7 -> 0
A8: CÀ CHUA SOCOLA XÁ | D8: =B8*C8 -> 0
A9: CÀ CHUA SÔCOLA(HỘP) KQ | D9: =B9*C9 -> 0
A10: CÀ RỐT BABY | D10: =B10*C10 -> 0
A11: CÀ RỐT BABY (KG) KQ | D11: =B11*C11 -> 0
A12: CÀ RỐT BABY 200GR | D12: =B12*C12 -> 0
A13: CẢI CẦU VỒNG | D13: =B13*C13 -> 0
A14: CẢI CẦU VỒNG 300GR | D14: =B14*C14 -> 0
A15: CẢI KALE | D15: =B15*C15 -> 0
... A22: ỚT CHUÔNG 3 MÀU(KG)VR | D22: =B22*C22 -> 0
A23: BÍ ĐỎ HỒ LÔ | B23: 15 | C23: 10000 | D23: =B23*C23 -> 150000
A24: BÍ ĐỎ TRÒN | B24: =2700+690 -> 3390 | C24: 6000 | D24: =B24*C24 -> 20340000
A25: ỚT CHUÔNG ĐỎ(TRÁI) | D25: =B25*C25 -> 0
A26: ỚT CHUÔNG 3 MÀU 350G | D26: =B26*C26 -> 0
A27: ỚT CHUÔNG 3 MÀU KQ(KG) | D27: =B27*C27 -> 0
A28: BÍ NGÒI XANH | B28: 50 | C28: 10000 | D28: =B28*C28 -> 500000
A29: BÔNG CẢI TRẮNG | B29: =18+22 -> 40 | C29: 11000 | D29: =B29*C29 -> 440000
A30: ỚT CHUÔNG VÀNG(TRÁI) | D30: =B30*C30 -> 0
A31: ỚT CHUÔNG VÀNG+ XANH (VỈ) | D31: =B31*C31 -> 0
A32: BÔNG CẢI XANH AEON | B32: 8 | C32: 23000 | D32: =B32*C32 -> 184000
A33: ỚT CHUÔNG XANH L1 | D33: =B33*C33 -> 0
A34: ỚT CHUÔNG XANH(TRÁI) | D34: =B34*C34 -> 0
A35: BÔNG CẢI XANH BIGC | B35: 40 | C35: 14000 | D35: =B35*C35 -> 560000
A36: CỦ DỀN 600G | D36: =B36*C36 -> 0
A37: GỪNG 250GR | D37: =B37*C37 -> 0
A38: HỒNG GIÒN | D38: =B38*C38 -> 0
A39: CÀ CHUA | B39: =230+120+20+20 -> 390 | C39: 8000 | D39: =B39*C39 -> 3120000
A40: CÀ CHUA BI (HỘP) 300GR VR | B40: 4 | C40: 4200 | D40: =B40*C40 -> 16800
A41: KHOAI TÂY HỒNG TÚI LƯỚI 500G | D41: =B41*C41 -> 0
A42: KHOAI TÂY VÀNG | D42: =B42*C42 -> 0
A43: CÀ CHUA BI COOP | B43: 9 | C43: 7000 | D43: =B43*C43 -> 63000
A44: KHOAI TÂY VÀNG LỚN TÚI LƯỚI 500G | D44: =B44*C44 -> 0
A45: KHOAI TÂY VÀNG RỬA | D45: =B45*C45 -> 0
A46: KHOAI TÂY VÀNG TRUNG TÚI LƯỚI 500G | D46: =B46*C46 -> 0
...

Sheet 25.1
A1: 45316 | C1: Stock
A2: TÊN SẢN PHẨM | B2: ĐVT | C2: TỒN TRƯỚC | D2: GIÁ NHẬP | E2: THÀNH TIỀN
A4: BẮP CẢI TÍM | B4: Kg
A5: BẮP CẢI TÍM (BẮP) | B5: BẮP
A6: BẮP CẢI TÍM SUSHI | B6: Kg
A7: BẮP CẢI TRẮNG | B7: Kg | C7: 150 | D7: 6500 | E7: =+D7*C7 -> 975000
A8: BẮP CẢI TRẮNG (BẮP) | B8: BẮP
A9: BẮP CẢI TRẮNG MỘC CHÂU | B9: Kg
A10: BẮP CẢI TRẮNG SUSHI | B10: Kg
A11: BẮP MỸ | B11: Kg
A12: BẦU | B12: Kg
A13: BÍ ĐAO XANH | B13: Kg
A14: BÍ ĐAO XANH 400G | B14: TRÁI
A15: BÍ ĐỎ HỒ LÔ | B15: Kg | C15: 13 | D15: 10000 | E15: =+D15*C15 -> 130000
A16: BÍ ĐỎ MINI | B16: Kg
A17: BÍ ĐỎ NON (KG)KQ | B17: Kg
A18: BÍ ĐỎ NON TRÁI VR | B18: TRÁI
A19: BÍ ĐỎ NON( KG) VR | B19: Kg
A20: BÍ ĐỎ TRÒN | B20: Kg | C20: 2545 | D20: 6000 | E20: =+D20*C20 -> 15270000
A21: BÍ MINI VÀNG 300GR | B21: TRÁI
A22: BÍ MINI VÀNG KG | B22: Kg
A23: BÍ NGÒI VÀNG | B23: Kg
A24: BÍ NGÒI VÀNG (TRÁI) | B24: TRÁI
A25: BÍ NGÒI XANH | B25: Kg | C25: 80 | D25: 10000 | E25: =+D25*C25 -> 800000
A26: BÍ NGÒI XANH(TRÁI) | B26: TRÁI
A27: BÍ NHẬT | B27: Kg
A28: BƠ 034 | B28: Kg
A29: BƠ BOOTH | B29: Kg
A30: BƠ SÁP | B30: Kg
A31: BÓ XÔI | B31: Kg
A32: BÓ XÔI 300G VR | B32: TÚI
A33: BÓ XÔI-HN KQ | B33: Kg
A34: BÓ XÔI-NA | B34: Kg
A35: BÔNG ATISO | B35: Kg
A36: BÔNG BÍ | B36: Kg
A37: BÔNG BÍ TÚI 300GR | B37: VỈ
A38: BÔNG CẢI TRẮNG | B38: Kg | C38: 23 | D38: 11000 | E38: =+D38*C38 -> 253000
A39: BÔNG CẢI TRẮNG (CÂY) | B39: CÂY
A40: BÔNG CẢI XANH 10P | B40: Kg
A41: BÔNG CẢI XANH AEON | B41: Kg
...

Sheet 26.1
A1: 45317 | C1: Stock
A2: TÊN SẢN PHẨM | B2: ĐVT | C2: TỒN TRƯỚC | D2: GIÁ NHẬP | E2: THÀNH TIỀN
A4: CÀ CHUA SÔCOLA 250GR (HỘP) VR | B4: HỘP
A5: CÀ CHUA SÔCOLA 250GR (KG) -NA | B5: Kg
A6: BẮP CẢI TÍM | B6: Kg | C6: 3 | D6: 21000 | E6: =+D6*C6 -> 63000
A7: CÀ CHUA SÔCOLA 250GR(KG) KQ | B7: Kg
A8: CÀ CHUA SÔCOLA 300GR (HỘP) VR | B8: HỘP
A9: CÀ CHUA SOCOLA XÁ | B9: Kg
A10: CÀ CHUA SÔCOLA(HỘP) KQ | B10: HỘP
A11: CÀ RỐT BABY | B11: Kg
A12: CÀ RỐT BABY (KG) KQ | B12: Kg
A13: CÀ RỐT BABY 200GR | B13: VỈ
A14: CẢI CẦU VỒNG | B14: Kg
A15: BẮP CẢI TRẮNG | B15: Kg | C15: 119 | D15: 6500 | E15: =+D15*C15 -> 773500
A16: CẢI KALE | B16: Kg
A17: BÍ ĐỎ HỒ LÔ | B17: Kg | C17: 20 | D17: 10000 | E17: =+D17*C17 -> 200000
A18: CHANH VÀNG (KG) | B18: Kg
A19: CHANH VÀNG TRÁI 180UP | B19: TRÁI
A20: CẦN TÂY (KG) | B20: Kg
A21: CẦN TÂY THUỶ CANH | B21: Kg
A22: CẦN TÂY(CÂY) | B22: CÂY
A23: ỚT CHUÔNG 3 MÀU(KG)VR | B23: VỈ
A24: BÍ ĐỎ TRÒN | B24: Kg | C24: 1881 | D24: 6000 | E24: =+D24*C24 -> 11286000
A25: ỚT CHUÔNG ĐỎ L1 | B25: Kg
A26: ỚT CHUÔNG ĐỎ(TRÁI) | B26: TRÁI
A27: BÍ NGÒI XANH | B27: Kg | C27: 70 | D27: 10000 | E27: =+D27*C27 -> 700000
A28: ỚT CHUÔNG 3 MÀU KQ(KG) | B28: Kg
A29: BÔNG CẢI TRẮNG | B29: Kg | C29: 20 | D29: 11000 | E29: =+D29*C29 -> 220000
A30: ỚT CHUÔNG VÀNG L1 | B30: Kg
A31: ỚT CHUÔNG VÀNG(TRÁI) | B31: TRÁI
A32: ỚT CHUÔNG VÀNG+ XANH (VỈ) | B32: VỈ
A33: BÔNG CẢI XANH 10P | B33: Kg | C33: 22 | D33: 17000 | E33: =+D33*C33 -> 374000
A34: ỚT CHUÔNG XANH L1 | B34: Kg
A35: ỚT CHUÔNG XANH(TRÁI) | B35: TRÁI
A36: BÔNG CẢI XANH BIGC | B36: Kg | C36: 18 | D36: 14000 | E36: =+D36*C36 -> 252000
A37: CỦ DỀN 600G | B37: TÚI
A38: GỪNG 250GR | B38: Kg
A39: HỒNG GIÒN | B39: Kg
A40: XÀ LÁCH MỸ | B40: Kg
A41: CÀ CHUA | B41: Kg | C41: 760 | D41: 8000 | E41: =+D41*C41 -> 6080000
...

Sheet 27.1
A1: 27/1 | C1: Stock
A2: TÊN SẢN PHẨM | B2: ĐVT | C2: TỒN TRƯỚC | D2: GIÁ NHẬP | E2: THÀNH TIỀN
A4: BẮP CẢI TÍM | B4: Kg | C4: 11 | D4: 21000 | E4: =+D4*C4 -> 231000
A5: BẮP CẢI TÍM (BẮP) | B5: BẮP | D5: 0
A6: BẮP CẢI TÍM SUSHI | B6: Kg | D6: 0
A7: BẮP CẢI TRẮNG | B7: Kg | C7: 168 | D7: 6500 | E7: =+D7*C7 -> 1092000
A8: BẮP CẢI TRẮNG (BẮP) | B8: BẮP | D8: 0
A9: BẮP CẢI TRẮNG MỘC CHÂU | B9: Kg | D9: 0
A10: BẮP CẢI TRẮNG SUSHI | B10: Kg | D10: 0
A11: BẮP MỸ | B11: Kg | D11: 0
A12: BẦU | B12: Kg | D12: 0
A13: BÍ ĐAO XANH | B13: Kg | D13: 0
A14: BÍ ĐAO XANH 400G | B14: TRÁI | D14: 0
A15: BÍ ĐỎ HỒ LÔ | B15: Kg | C15: 22 | D15: 10000 | E15: =+D15*C15 -> 220000
A16: BÍ ĐỎ MINI | B16: Kg | D16: 0
A17: BÍ ĐỎ NON (KG)KQ | B17: Kg | D17: 0
A18: BÍ ĐỎ NON TRÁI VR | B18: TRÁI | C18: 31 | D18: 3300 | E18: =+D18*C18 -> 102300
A19: BÍ ĐỎ NON( KG) VR | B19: Kg | D19: 0
A20: BÍ ĐỎ TRÒN | B20: Kg | C20: 1016 | D20: 6000 | E20: =+D20*C20 -> 6096000
A21: BÍ MINI VÀNG 300GR | B21: TRÁI | D21: 0
A22: BÍ MINI VÀNG KG | B22: Kg | D22: 0
A23: BÍ NGÒI VÀNG | B23: Kg | D23: 0
A24: BÍ NGÒI VÀNG (TRÁI) | B24: TRÁI | D24: 0
A25: BÍ NGÒI XANH | B25: Kg | C25: 227 | D25: 10000 | E25: =+D25*C25 -> 2270000
A26: BÍ NGÒI XANH(TRÁI) | B26: TRÁI | D26: 0
A27: BÍ NHẬT | B27: Kg | D27: 0
A28: BƠ 034 | B28: Kg | D28: 0
A29: BƠ BOOTH | B29: Kg | D29: 0
A30: BƠ SÁP | B30: Kg | D30: 0
A31: BÓ XÔI | B31: Kg | D31: 0
A32: BÓ XÔI 300G VR | B32: TÚI | D32: 0
A33: BÓ XÔI-HN KQ | B33: Kg | D33: 0
A34: BÓ XÔI-NA | B34: Kg | D34: 0
A35: BÔNG ATISO | B35: Kg | D35: 0
A36: BÔNG BÍ | B36: Kg | D36: 0
A37: BÔNG BÍ TÚI 300GR | B37: VỈ | D37: 0
A38: BÔNG CẢI TRẮNG | B38: Kg | C38: 27 | D38: 11000 | E38: =+D38*C38 -> 297000
A39: BÔNG CẢI TRẮNG (CÂY) | B39: CÂY | D39: 0
A40: BÔNG CẢI XANH 10P | B40: Kg | D40: 0
A41: BÔNG CẢI XANH AEON | B41: Kg | D41: 0
...

Sheet 28.1
A1: 45319 | C1: Stock
A2: TÊN SẢN PHẨM | B2: ĐVT | C2: TỒN TRƯỚC | D2: GIÁ NHẬP | E2: THÀNH TIỀN
A4: BẮP CẢI TÍM | B4: Kg | C4: 15 | D4: 21000 | E4: =+D4*C4 -> 315000
A5: BẮP CẢI TÍM (BẮP) | B5: BẮP | D5: 0
A6: BẮP CẢI TÍM SUSHI | B6: Kg | D6: 0
A7: BẮP CẢI TRẮNG | B7: Kg | C7: 45 | D7: 6500 | E7: =+D7*C7 -> 292500
A8: BẮP CẢI TRẮNG (BẮP) | B8: BẮP | D8: 0
A9: BẮP CẢI TRẮNG MỘC CHÂU | B9: Kg | D9: 0
A10: BẮP CẢI TRẮNG SUSHI | B10: Kg | D10: 0
A11: BẮP MỸ | B11: Kg | D11: 0
A12: BẦU | B12: Kg | D12: 0
A13: BÍ ĐAO XANH | B13: Kg | D13: 0
A14: BÍ ĐAO XANH 400G | B14: TRÁI | D14: 0
A15: BÍ ĐỎ HỒ LÔ | B15: Kg | C15: 13 | D15: 10000 | E15: =+D15*C15 -> 130000
A16: BÍ ĐỎ MINI | B16: Kg | D16: 0
A17: BÍ ĐỎ NON (KG)KQ | B17: Kg | D17: 0
A18: BÍ ĐỎ NON TRÁI VR | B18: TRÁI | C18: 23 | D18: 3300 | E18: =+D18*C18 -> 75900
A19: BÍ ĐỎ NON( KG) VR | B19: Kg | D19: 0
A20: BÍ ĐỎ TRÒN | B20: Kg | C20: 340 | D20: 6000 | E20: =+D20*C20 -> 2040000
A21: BÍ MINI VÀNG 300GR | B21: TRÁI | D21: 0
A22: BÍ MINI VÀNG KG | B22: Kg | D22: 0
A23: BÍ NGÒI VÀNG | B23: Kg | D23: 0
A24: BÍ NGÒI VÀNG (TRÁI) | B24: TRÁI | D24: 0
