Workbook

Sheet 1.6
A1: hàng tồn cuối ngày 1/6 vr
A2: TÊN SẢN PHẨM | B2: TỒN TRƯỚC | C2: GIÁ NHẬP | D2: THÀNH TIỀN
A3: BẮP CẢI TÍM | B3: 20 | C3: 12000 | D3: =B3*C3 -> 240000
A4: BẮP CẢI TÍM (BẮP) | D4: =B4*C4 -> 0
A5: BẮP CẢI TÍM SUSHI | D5: =B5*C5 -> 0
A6: BẮP CẢI TRẮNG | D6: =B6*C6 -> 0
A7: BẮP CẢI TRẮNG (BẮP) | D7: =B7*C7 -> 0
A8: BẮP CẢI TRẮNG MỘC CHÂU | D8: =B8*C8 -> 0
A9: BẮP CẢI TRẮNG SÓI BIỂN | D9: =B9*C9 -> 0
A10: BẮP CẢI TRẮNG SUSHI | D10: =B10*C10 -> 0
A11: BẮP MỸ CẶP | D11: =B11*C11 -> 0
A12: BẦU | D12: =B12*C12 -> 0
A13: BÍ ĐAO XANH | D13: =B13*C13 -> 0
A14: BÍ ĐAO XANH 400G | D14: =B14*C14 -> 0
A15: BÍ ĐỎ HỒ LÔ | B15: 13 | C15: 20000 | D15: =B15*C15 -> 260000
A16: BÍ ĐỎ MINI | D16: =B16*C16 -> 0
A17: BÍ ĐỎ NON (KG)KQ | D17: =B17*C17 -> 0
A18: BÍ ĐỎ NON TRÁI VR | D18: =B18*C18 -> 0
A19: BÍ ĐỎ NON( KG) VR | D19: =B19*C19 -> 0
A20: BÍ ĐỎ TRÒN | D20: =B20*C20 -> 0
A21: BÍ MINI VÀNG 300GR | D21: =B21*C21 -> 0
A22: BÍ MINI VÀNG KG | D22: =B22*C22 -> 0
A23: BÍ NGÒI VÀNG | D23: =B23*C23 -> 0
A24: BÍ NGÒI VÀNG (TRÁI) | D24: =B24*C24 -> 0
A25: BÍ NGÒI XANH | B25: =20+13+30+50 -> 113 | C25: 15000 | D25: =B25*C25 -> 1695000
A26: BÍ NGÒI XANH(TRÁI) | D26: =B26*C26 -> 0
A27: BÍ NHẬT | D27: =B27*C27 -> 0
A28: BƠ 034 | B28: =7+69+15 -> 91 | C28: 18000 | D28: =B28*C28 -> 1638000
A29: BƠ BOOTH | D29: =B29*C29 -> 0
A30: BO HOA CHUONG | D30: =B30*C30 -> 0
A31: BO HOA CUC TANA | D31: =B31*C31 -> 0
A32: BO HOA DONG TIEN HN | D32: =B32*C32 -> 0
A33: BO HOA PHANG | D33: =B33*C33 -> 0
A34: BO HOA SEN QUAN AM | D34: =B34*C34 -> 0
A35: BO HOA SEN SUPER | D35: =B35*C35 -> 0
A36: BƠ SÁP | B36: 23 | C36: 14000 | D36: =B36*C36 -> 322000
A37: BÓ XÔI | B37: 4 | C37: 43000 | D37: =B37*C37 -> 172000
A38: BÓ XÔI 300G VR | D38: =B38*C38 -> 0
A39: BÓ XÔI-HN KQ | D39: =B39*C39 -> 0
A40: BÓ XÔI-NA | D40: =B40*C40 -> 0
...

Sheet 2.6
A1: hàng tồn cuối ngày 2/6 vr
A2: TÊN SẢN PHẨM | B2: TỒN TRƯỚC | C2: GIÁ NHẬP | D2: THÀNH TIỀN
A3: BẮP CẢI TÍM | D3: =B3*C3 -> 0
A4: BẮP CẢI TÍM (BẮP) | D4: =B4*C4 -> 0
A5: BẮP CẢI TÍM SUSHI | D5: =B5*C5 -> 0
A6: BẮP CẢI TRẮNG | D6: =B6*C6 -> 0
A7: BẮP CẢI TRẮNG (BẮP) | D7: =B7*C7 -> 0
A8: BẮP CẢI TRẮNG MỘC CHÂU | D8: =B8*C8 -> 0
A9: BẮP CẢI TRẮNG SÓI BIỂN | D9: =B9*C9 -> 0
A10: BẮP CẢI TRẮNG SUSHI | D10: =B10*C10 -> 0
A11: BẮP MỸ CẶP | D11: =B11*C11 -> 0
A12: BẦU | D12: =B12*C12 -> 0
A13: BÍ ĐAO XANH | D13: =B13*C13 -> 0
A14: BÍ ĐAO XANH 400G | D14: =B14*C14 -> 0
... A17: BÍ ĐỎ NON (KG)KQ | D17: =B17*C17 -> 0
A18: BÍ ĐỎ NON TRÁI VR | B18: 5 | C18: 3500 | D18: =B18*C18 -> 17500
A19: BÍ ĐỎ NON( KG) VR | D19: =B19*C19 -> 0
A20: BÍ ĐỎ TRÒN | B20: 300 | C20: 12000 | D20: =B20*C20 -> 3600000
A21: BÍ MINI VÀNG 300GR | D21: =B21*C21 -> 0
A22: BÍ MINI VÀNG KG | D22: =B22*C22 -> 0
A23: BÍ NGÒI VÀNG | D23: =B23*C23 -> 0
A24: BÍ NGÒI VÀNG (TRÁI) | D24: =B24*C24 -> 0
A25: BÍ NGÒI XANH | B25: =45+90+10 -> 145 | C25: 16000 | D25: =B25*C25 -> 2320000
A26: BÍ NGÒI XANH(TRÁI) | D26: =B26*C26 -> 0
A27: BÍ NHẬT | D27: =B27*C27 -> 0
A28: BƠ 034 | B28: 45 | C28: 18000 | D28: =B28*C28 -> 810000
A29: BƠ BOOTH | D29: =B29*C29 -> 0
A30: BO HOA CHUONG | D30: =B30*C30 -> 0
A31: BO HOA CUC TANA | D31: =B31*C31 -> 0
A32: BO HOA DONG TIEN HN | D32: =B32*C32 -> 0
A33: BO HOA PHANG | D33: =B33*C33 -> 0
A34: BO HOA SEN QUAN AM | D34: =B34*C34 -> 0
A35: BO HOA SEN SUPER | D35: =B35*C35 -> 0
A36: BƠ SÁP | B36: =45+18 -> 63 | C36: 14000 | D36: =B36*C36 -> 882000
A37: BÓ XÔI | B37: 3 | C37: 43000 | D37: =B37*C37 -> 129000
A38: BÓ XÔI 300G VR | D38: =B38*C38 -> 0
A39: BÓ XÔI-HN KQ | D39: =B39*C39 -> 0
A40: BÓ XÔI-NA | D40: =B40*C40 -> 0
A41: BÔNG ATISO | D41: =B41*C41 -> 0
A42: BÔNG BÍ | D42: =B42*C42 -> 0
...

Sheet 3.6
A1: hàng tồn cuối ngày 3/6 vr
A2: TÊN SẢN PHẨM | B2: TỒN TRƯỚC | C2: GIÁ NHẬP | D2: THÀNH TIỀN
A3: BẮP CẢI TÍM | D3: =B3*C3 -> 0
A4: BẮP CẢI TÍM (BẮP) | D4: =B4*C4 -> 0
A5: BẮP CẢI TÍM SUSHI | D5: =B5*C5 -> 0
A6: BẮP CẢI TRẮNG | D6: =B6*C6 -> 0
A7: BẮP CẢI TRẮNG (BẮP) | D7: =B7*C7 -> 0
A8: BẮP CẢI TRẮNG MỘC CHÂU | D8: =B8*C8 -> 0
A9: BẮP CẢI TRẮNG SÓI BIỂN | D9: =B9*C9 -> 0
A10: BẮP CẢI TRẮNG SUSHI | D10: =B10*C10 -> 0
A11: BẮP MỸ CẶP | D11: =B11*C11 -> 0
A12: BẦU | B12: 9 | C12: 10000 | D12: =B12*C12 -> 90000
A13: BÍ ĐAO XANH | D13: =B13*C13 -> 0
A14: BÍ ĐAO XANH 400G | D14: =B14*C14 -> 0
A15: BÍ ĐỎ HỒ LÔ | D15: =B15*C15 -> 0
A16: BÍ ĐỎ MINI | D16: =B16*C16 -> 0
A17: BÍ ĐỎ NON (KG)KQ | D17: =B17*C17 -> 0
A18: BÍ ĐỎ NON TRÁI VR | D18: =B18*C18 -> 0
A19: BÍ ĐỎ NON( KG) VR | B19: 15 | C19: 12000 | D19: =B19*C19 -> 180000
A20: BÍ ĐỎ TRÒN | B20: 300 | C20: 12000 | D20: =B20*C20 -> 3600000
A21: BÍ MINI VÀNG 300GR | D21: =B21*C21 -> 0
A22: BÍ MINI VÀNG KG | D22: =B22*C22 -> 0
A23: BÍ NGÒI VÀNG | D23: =B23*C23 -> 0
A24: BÍ NGÒI VÀNG (TRÁI) | D24: =B24*C24 -> 0
A25: BÍ NGÒI XANH | B25: 105 | C25: 12000 | D25: =B25*C25 -> 1260000
A26: BÍ NGÒI XANH(TRÁI) | D26: =B26*C26 -> 0
A27: BÍ NHẬT | D27: =B27*C27 -> 0
A28: BƠ 034 | B28: =15+54+15+70 -> 154 | C28: 18000 | D28: =B28*C28 -> 2772000
A29: BƠ BOOTH | D29: =B29*C29 -> 0
A30: BO HOA CHUONG | D30: =B30*C30 -> 0
A31: BO HOA CUC TANA | D31: =B31*C31 -> 0
A32: BO HOA DONG TIEN HN | D32: =B32*C32 -> 0
A33: BO HOA PHANG | D33: =B33*C33 -> 0
A34: BO HOA SEN QUAN AM | D34: =B34*C34 -> 0
A35: BO HOA SEN SUPER | D35: =B35*C35 -> 0
A36: BƠ SÁP | B36: =12+15+35 -> 62 | C36: 14000 | D36: =B36*C36 -> 868000
A37: BÓ XÔI | D37: =B37*C37 -> 0
A38: BÓ XÔI 300G VR | D38: =B38*C38 -> 0
A39: BÓ XÔI-HN KQ | D39: =B39*C39 -> 0
A40: BÓ XÔI-NA | D40: =B40*C40 -> 0
...

Sheet 4.6
A1: hàng tồn cuối ngày 4/6 vr
A2: TÊN SẢN PHẨM | B2: TỒN TRƯỚC | C2: GIÁ NHẬP | D2: THÀNH TIỀN
A3: BẮP CẢI TÍM | B3: 18 | C3: 11000 | D3: =B3*C3 -> 198000
A4: BẮP CẢI TÍM (BẮP) | D4: =B4*C4 -> 0
A5: BẮP CẢI TÍM SUSHI | D5: =B5*C5 -> 0
A6: BẮP CẢI TRẮNG | D6: =B6*C6 -> 0
A7: BẮP CẢI TRẮNG (BẮP) | D7: =B7*C7 -> 0
A8: BẮP CẢI TRẮNG MỘC CHÂU | D8: =B8*C8 -> 0
A9: BẮP CẢI TRẮNG SÓI BIỂN | D9: =B9*C9 -> 0
A10: BẮP CẢI TRẮNG SUSHI | D10: =B10*C10 -> 0
A11: BẮP MỸ CẶP | D11: =B11*C11 -> 0
A12: BẦU | B12: 8 | C12: 10000 | D12: =B12*C12 -> 80000
A13: BÍ ĐAO XANH | D13: =B13*C13 -> 0
A14: BÍ ĐAO XANH 400G | D14: =B14*C14 -> 0
A15: BÍ ĐỎ HỒ LÔ | D15: =B15*C15 -> 0
A16: BÍ ĐỎ MINI | D16: =B16*C16 -> 0
A17: BÍ ĐỎ NON (KG)KQ | D17: =B17*C17 -> 0
A18: BÍ ĐỎ NON TRÁI VR | B18: 25 | C18: 3500 | D18: =B18*C18 -> 87500
A19: BÍ ĐỎ NON( KG) VR | D19: =B19*C19 -> 0
A20: BÍ ĐỎ TRÒN | B20: 300 | C20: 12000 | D20: =B20*C20 -> 3600000
A21: BÍ MINI VÀNG 300GR | D21: =B21*C21 -> 0
A22: BÍ MINI VÀNG KG | D22: =B22*C22 -> 0
A23: BÍ NGÒI VÀNG | D23: =B23*C23 -> 0
A24: BÍ NGÒI VÀNG (TRÁI) | D24: =B24*C24 -> 0
A25: BÍ NGÒI XANH | B25: =30+15+35+51 -> 131 | C25: 10000 | D25: =B25*C25 -> 1310000
A26: BÍ NGÒI XANH(TRÁI) | D26: =B26*C26 -> 0
A27: BÍ NHẬT | D27: =B27*C27 -> 0
A28: BƠ 034 | B28: =38+46 -> 84 | C28: 17000 | D28: =B28*C28 -> 1428000
A29: BƠ BOOTH | D29: =B29*C29 -> 0
A30: BO HOA CHUONG | D30: =B30*C30 -> 0
A31: BO HOA CUC TANA | D31: =B31*C31 -> 0
A32: BO HOA DONG TIEN HN | D32: =B32*C32 -> 0
A33: BO HOA LOA KEN | D33: =B33*C33 -> 0
A34: BO HOA PHANG | D34: =B34*C34 -> 0
A35: BO HOA SEN QUAN AM | D35: =B35*C35 -> 0
A36: BO HOA SEN SUPER | D36: =B36*C36 -> 0
A37: BƠ SÁP | B37: 6 | C37: 14000 | D37: =B37*C37 -> 84000
A38: BÓ XÔI | D38: =B38*C38 -> 0
A39: BÓ XÔI 300G VR | D39: =B39*C39 -> 0
A40: BÓ XÔI-HN KQ | D40: =B40*C40 -> 0
...

Sheet 5.6
A1: hàng tồn cuối ngày 5/6 vr
A2: TÊN SẢN PHẨM | B2: TỒN TRƯỚC | C2: GIÁ NHẬP | D2: THÀNH TIỀN
A3: BẮP CẢI TÍM | D3: =B3*C3 -> 0
A4: BẮP CẢI TÍM (BẮP) | D4: =B4*C4 -> 0
A5: BẮP CẢI TÍM SUSHI | D5: =B5*C5 -> 0
A6: BẮP CẢI TRẮNG | D6: =B6*C6 -> 0
A7: BẮP CẢI TRẮNG (BẮP) | D7: =B7*C7 -> 0
A8: BẮP CẢI TRẮNG MỘC CHÂU | D8: =B8*C8 -> 0
A9: BẮP CẢI TRẮNG SÓI BIỂN | D9: =B9*C9 -> 0
A10: BẮP CẢI TRẮNG SUSHI | D10: =B10*C10 -> 0
A11: BẮP MỸ CẶP | D11: =B11*C11 -> 0
A12: BẦU | B12: 2 | C12: 10000 | D12: =B12*C12 -> 20000
A13: BÍ ĐAO XANH | D13: =B13*C13 -> 0
A14: BÍ ĐAO XANH 400G | D14: =B14*C14 -> 0
A15: BÍ ĐỎ HỒ LÔ | B15: 5 | C15: 20000 | D15: =B15*C15 -> 100000
A16: BÍ ĐỎ MINI | D16: =B16*C16 -> 0
A17: BÍ ĐỎ NON (KG)KQ | D17: =B17*C17 -> 0
A18: BÍ ĐỎ NON TRÁI VR | B18: =60+100+5 -> 165 | C18: 4000 | D18: =B18*C18 -> 660000
A19: BÍ ĐỎ NON( KG) VR | B19: 25 | C19: 13000 | D19: =B19*C19 -> 325000
A20: BÍ ĐỎ TRÒN | B20: 300 | C20: 14000 | D20: =B20*C20 -> 4200000
A21: BÍ MINI VÀNG 300GR | D21: =B21*C21 -> 0
A22: BÍ MINI VÀNG KG | D22: =B22*C22 -> 0
A23: BÍ NGÒI VÀNG | D23: =B23*C23 -> 0
A24: BÍ NGÒI VÀNG (TRÁI) | D24: =B24*C24 -> 0
A25: BÍ NGÒI XANH | B25: 100 | C25: 8000 | D25: =B25*C25 -> 800000
A26: BÍ NGÒI XANH(TRÁI) | D26: =B26*C26 -> 0
A27: BÍ NHẬT | D27: =B27*C27 -> 0
A28: BƠ 034 | B28: =75+25+30 -> 130 | C28: 17000 | D28: =B28*C28 -> 2210000
A29: BƠ BOOTH | B29: 14 | C29: 24000 | D29: =B29*C29 -> 336000
A30: BO HOA CHUONG | D30: =B30*C30 -> 0
A31: BO HOA CUC TANA | D31: =B31*C31 -> 0
A32: BO HOA DONG TIEN HN | D32: =B32*C32 -> 0
A33: BO HOA LOA KEN | D33: =B33*C33 -> 0
A34: BO HOA PHANG | D34: =B34*C34 -> 0
A35: BO HOA SEN QUAN AM | D35: =B35*C35 -> 0
A36: BO HOA SEN SUPER | D36: =B36*C36 -> 0
A37: BƠ SÁP | D37: =B37*C37 -> 0
A38: BÓ XÔI | D38: =B38*C38 -> 0
A39: BÓ XÔI 300G VR | D39: =B39*C39 -> 0
A40: BÓ XÔI-HN KQ | D40: =B40*C40 -> 0
...

Sheet 6.6
A1: hàng tồn cuối ngày 6/6 vr
A2: TÊN SẢN PHẨM | B2: TỒN TRƯỚC | C2: GIÁ NHẬP | D2: THÀNH TIỀN
A3: BẮP CẢI TÍM | D3: =B3*C3 -> 0
A4: BẮP CẢI TÍM (BẮP) | D4: =B4*C4 -> 0
A5: BẮP CẢI TÍM SUSHI | D5: =B5*C5 -> 0
A6: BẮP CẢI TRẮNG | D6: =B6*C6 -> 0
A7: BẮP CẢI TRẮNG (BẮP) | D7: =B7*C7 -> 0
A8: BẮP CẢI TRẮNG MỘC CHÂU | D8: =B8*C8 -> 0
A9: BẮP CẢI TRẮNG SÓI BIỂN | D9: =B9*C9 -> 0
A10: BẮP CẢI TRẮNG SUSHI | D10: =B10*C10 -> 0
A11: BẮP MỸ CẶP | D11: =B11*C11 -> 0
A12: BẦU | B12: 2 | C12: 10000 | D12: =B12*C12 -> 20000
A13: BÍ ĐAO XANH | D13: =B13*C13 -> 0
A14: BÍ ĐAO XANH 400G | D14: =B14*C14 -> 0
A15: BÍ ĐỎ HỒ LÔ | B15: 4 | C15: 20000 | D15: =B15*C15 -> 80000
A16: BÍ ĐỎ MINI | D16: =B16*C16 -> 0
A17: BÍ ĐỎ NON (KG)KQ | D17: =B17*C17 -> 0
A18: BÍ ĐỎ NON TRÁI VR | B18: =125+18+18 -> 161 | C18: 4000 | D18: =B18*C18 -> 644000
A19: BÍ ĐỎ NON( KG) VR | D19: =B19*C19 -> 0
A20: BÍ ĐỎ TRÒN | B20: 300 | C20: 14000 | D20: =B20*C20 -> 4200000
A21: BÍ MINI VÀNG 300GR | D21: =B21*C21 -> 0
A22: BÍ MINI VÀNG KG | D22: =B22*C22 -> 0
A23: BÍ NGÒI VÀNG | D23: =B23*C23 -> 0
A24: BÍ NGÒI VÀNG (TRÁI) | D24: =B24*C24 -> 0
A25: BÍ NGÒI XANH | B25: 103 | C25: 8000 | D25: =B25*C25 -> 824000
A26: BÍ NGÒI XANH(TRÁI) | D26: =B26*C26 -> 0
A27: BÍ NHẬT | D27: =B27*C27 -> 0
A28: BƠ 034 | B28: =104+140+5+6 -> 255 | C28: 17000 | D28: =B28*C28 -> 4335000
A29: BƠ BOOTH | D29: =B29*C29 -> 0
A30: BO HOA CHUONG | D30: =B30*C30 -> 0
A31: BO HOA CUC TANA | D31: =B31*C31 -> 0
A32: BO HOA DONG TIEN HN | D32: =B32*C32 -> 0
A33: BO HOA LOA KEN | D33: =B33*C33 -> 0
A34: BO HOA PHANG | D34: =B34*C34 -> 0
A35: BO HOA SEN QUAN AM | D35: =B35*C35 -> 0
A36: BO HOA SEN SUPER | D36: =B36*C36 -> 0
A37: BƠ SÁP | B37: =21+43+27+13 -> 104 | C37: 10000 | D37: =B37*C37 -> 1040000
A38: BÓ XÔI | D38: =B38*C38 -> 0
A39: BÓ XÔI 300G VR | D39: =B39*C39 -> 0
A40: BÓ XÔI-HN KQ | D40: =B40*C40 -> 0
...

Sheet 7.6
A1: hàng tồn cuối ngày 7/6 vr
A2: TÊN SẢN PHẨM | B2: TỒN TRƯỚC | C2: GIÁ NHẬP | D2: THÀNH TIỀN
A3: BẮP CẢI TÍM | B3: 25 | C3: 11000 | D3: =B3*C3 -> 275000
A4: BẮP CẢI TÍM (BẮP) | D4: =B4*C4 -> 0
A5: BẮP CẢI TÍM SUSHI | D5: =B5*C5 -> 0
A6: BẮP CẢI TRẮNG | D6: =B6*C6 -> 0
A7: BẮP CẢI TRẮNG (BẮP) | D7: =B7*C7 -> 0
A8: BẮP CẢI TRẮNG MỘC CHÂU | D8: =B8*C8 -> 0
A9: BẮP CẢI TRẮNG SÓI BIỂN | D9: =B9*C9 -> 0
A10: BẮP CẢI TRẮNG SUSHI | D10: =B10*C10 -> 0
A11: BẮP MỸ CẶP | D11: =B11*C11 -> 0
A12: BẦU | D12: =B12*C12 -> 0
A13: BÍ ĐAO XANH | D13: =B13*C13 -> 0
A14: BÍ ĐAO XANH 400G | D14: =B14*C14 -> 0
A15: BÍ ĐỎ HỒ LÔ | D15: =B15*C15 -> 0
... A18: BÍ ĐỎ NON TRÁI VR | D18: =B18*C18 -> 0
A19: BÍ ĐỎ NON( KG) VR | B19: 60 | C19: 4000 | D19: =B19*C19 -> 240000
A20: BÍ ĐỎ TRÒN | D20: =B20*C20 -> 0
A21: BÍ MINI VÀNG 300GR | D21: =B21*C21 -> 0
A22: BÍ MINI VÀNG KG | D22: =B22*C22 -> 0
A23: BÍ NGÒI VÀNG | D23: =B23*C23 -> 0
A24: BÍ NGÒI VÀNG (TRÁI) | D24: =B24*C24 -> 0
A25: BÍ NGÒI XANH | B25: 20 | C25: 8000 | D25: =B25*C25 -> 160000
A26: BÍ NGÒI XANH(TRÁI) | D26: =B26*C26 -> 0
A27: BÍ NHẬT | D27: =B27*C27 -> 0
A28: BƠ 034 | B28: =180+40+65 -> 285 | C28: 17000 | D28: =B28*C28 -> 4845000
A29: BƠ BOOTH | D29: =B29*C29 -> 0
A30: BO HOA CHUONG | D30: =B30*C30 -> 0
A31: BO HOA CUC TANA | D31: =B31*C31 -> 0
A32: BO HOA DONG TIEN HN | D32: =B32*C32 -> 0
A33: BO HOA LOA KEN | D33: =B33*C33 -> 0
A34: BO HOA PHANG | D34: =B34*C34 -> 0
A35: BO HOA SEN QUAN AM | D35: =B35*C35 -> 0
A36: BO HOA SEN SUPER | D36: =B36*C36 -> 0
A37: BƠ SÁP | B37: 45 | C37: 10000 | D37: =B37*C37 -> 450000
A38: BÓ XÔI | D38: =B38*C38 -> 0
A39: BÓ XÔI 300G VR | D39: =B39*C39 -> 0
A40: BÓ XÔI-HN KQ | D40: =B40*C40 -> 0
A41: BÓ XÔI-NA | D41: =B41*C41 -> 0
A42: BÔNG ATISO | D42: =B42*C42 -> 0
...

Sheet 8.6
A1: hàng tồn cuối ngày 8/6 vr
A2: TÊN SẢN PHẨM | B2: TỒN TRƯỚC | C2: GIÁ NHẬP | D2: THÀNH TIỀN
A3: BẮP CẢI TÍM | B3: 18 | C3: 11000 | D3: =B3*C3 -> 198000
A4: BẮP CẢI TÍM (BẮP) | D4: =B4*C4 -> 0
A5: BẮP CẢI TÍM SUSHI | D5: =B5*C5 -> 0
A6: BẮP CẢI TRẮNG | D6: =B6*C6 -> 0
A7: BẮP CẢI TRẮNG (BẮP) | D7: =B7*C7 -> 0
A8: BẮP CẢI TRẮNG MỘC CHÂU | D8: =B8*C8 -> 0
A9: BẮP CẢI TRẮNG SÓI BIỂN | D9: =B9*C9 -> 0
A10: BẮP CẢI TRẮNG SUSHI | D10: =B10*C10 -> 0
A11: BẮP MỸ CẶP | D11: =B11*C11 -> 0
A12: BẦU | D12: =B12*C12 -> 0
A13: BÍ ĐAO XANH | D13: =B13*C13 -> 0
A14: BÍ ĐAO XANH 400G | D14: =B14*C14 -> 0
A15: BÍ ĐỎ HỒ LÔ | D15: =B15*C15 -> 0
... A17: BÍ ĐỎ NON (KG)KQ | D17: =B17*C17 -> 0
A18: BÍ ĐỎ NON TRÁI VR | B18: 25 | C18: 4000 | D18: =B18*C18 -> 100000
A19: BÍ ĐỎ NON( KG) VR | B19: =70+42 -> 112 | C19: 13000 | D19: =B19*C19 -> 1456000
A20: BÍ ĐỎ TRÒN | D20: =B20*C20 -> 0
A21: BÍ MINI VÀNG 300GR | D21: =B21*C21 -> 0
A22: BÍ MINI VÀNG KG | D22: =B22*C22 -> 0
A23: BÍ NGÒI VÀNG | D23: =B23*C23 -> 0
A24: BÍ NGÒI VÀNG (TRÁI) | D24: =B24*C24 -> 0
A25: BÍ NGÒI XANH | B25: 58 | C25: 8000 | D25: =B25*C25 -> 464000
A26: BÍ NGÒI XANH(TRÁI) | D26: =B26*C26 -> 0
A27: BÍ NHẬT | D27: =B27*C27 -> 0
A28: BƠ 034 | B28: =75+19 -> 94 | C28: 17000 | D28: =B28*C28 -> 1598000
A29: BƠ BOOTH | B29: 16 | C29: 26000 | D29: =B29*C29 -> 416000
A30: BO HOA CHUONG | D30: =B30*C30 -> 0
A31: BO HOA CUC TANA | D31: =B31*C31 -> 0
A32: BO HOA DONG TIEN HN | D32: =B32*C32 -> 0
A33: BO HOA LOA KEN | D33: =B33*C33 -> 0
A34: BO HOA PHANG | D34: =B34*C34 -> 0
A35: BO HOA SEN QUAN AM | D35: =B35*C35 -> 0
A36: BO HOA SEN SUPER | D36: =B36*C36 -> 0
A37: BƠ SÁP | B37: 100 | C37: 10000 | D37: =B37*C37 -> 1000000
A38: BÓ XÔI | D38: =B38*C38 -> 0
A39: BÓ XÔI 300G VR | D39: =B39*C39 -> 0
A40: BÓ XÔI-HN KQ | D40: =B40*C40 -> 0
A41: BÓ XÔI-NA | D41: =B41*C41 -> 0
...

Sheet 9.6
A1: hàng tồn cuối ngày 9/6 vr
A2: TÊN SẢN PHẨM | B2: TỒN TRƯỚC | C2: GIÁ NHẬP | D2: THÀNH TIỀN
A3: BẮP CẢI TÍM | D3: =B3*C3 -> 0
A4: BẮP CẢI TÍM (BẮP) | D4: =B4*C4 -> 0
A5: BẮP CẢI TÍM SUSHI | D5: =B5*C5 -> 0
A6: BẮP CẢI TRẮNG | D6: =B6*C6 -> 0
A7: BẮP CẢI TRẮNG (BẮP) | D7: =B7*C7 -> 0
A8: BẮP CẢI TRẮNG MỘC CHÂU | D8: =B8*C8 -> 0
A9: BẮP CẢI TRẮNG SÓI BIỂN | D9: =B9*C9 -> 0
A10: BẮP CẢI TRẮNG SUSHI | D10: =B10*C10 -> 0
A11: BẮP MỸ CẶP | D11: =B11*C11 -> 0
A12: BẦU | D12: =B12*C12 -> 0
A13: BÍ ĐAO XANH | D13: =B13*C13 -> 0
A14: BÍ ĐAO XANH 400G | D14: =B14*C14 -> 0
... A17: BÍ ĐỎ NON (KG)KQ | D17: =B17*C17 -> 0
A18: BÍ ĐỎ NON TRÁI VR | B18: 106 | C18: 4000 | D18: =B18*C18 -> 424000
A19: BÍ ĐỎ NON( KG) VR | D19: =B19*C19 -> 0
A20: BÍ ĐỎ TRÒN | D20: =B20*C20 -> 0
A21: BÍ MINI VÀNG 300GR | D21: =B21*C21 -> 0
A22: BÍ MINI VÀNG KG | D22: =B22*C22 -> 0
A23: BÍ NGÒI VÀNG | D23: =B23*C23 -> 0
A24: BÍ NGÒI VÀNG (TRÁI) | D24: =B24*C24 -> 0
A25: BÍ NGÒI XANH | B25: 120 | C25: 8000 | D25: =B25*C25 -> 960000
A26: BÍ NGÒI XANH(TRÁI) | D26: =B26*C26 -> 0
A27: BÍ NHẬT | D27: =B27*C27 -> 0
A28: BƠ 034 | B28: =34+12+13 -> 59 | C28: 17000 | D28: =B28*C28 -> 1003000
A29: BƠ BOOTH | D29: =B29*C29 -> 0
A30: BO HOA CHUONG | D30: =B30*C30 -> 0
A31: BO HOA CUC TANA | D31: =B31*C31 -> 0
A32: BO HOA DONG TIEN HN | D32: =B32*C32 -> 0
A33: BO HOA LOA KEN | D33: =B33*C33 -> 0
A34: BO HOA PHANG | D34: =B34*C34 -> 0
A35: BO HOA SEN QUAN AM | D35: =B35*C35 -> 0
A36: BO HOA SEN SUPER | D36: =B36*C36 -> 0
A37: BƠ SÁP | B37: =210+56 -> 266 | C37: 11463 | D37: =B37*C37 -> 3049158
A38: BÓ XÔI | D38: =B38*C38 -> 0
A39: BÓ XÔI 300G VR | D39: =B39*C39 -> 0
A40: BÓ XÔI-HN KQ | D40: =B40*C40 -> 0
A41: BÓ XÔI-NA | D41: =B41*C41 -> 0
A42: BÔNG ATISO | D42: =B42*C42 -> 0
...

Sheet 10.6
A1: hàng tồn cuối ngày 10/6 vr
A2: TÊN SẢN PHẨM | B2: TỒN TRƯỚC | C2: GIÁ NHẬP | D2: THÀNH TIỀN
A3: BẮP CẢI TÍM | B3: 10 | C3: 11000 | D3: =B3*C3 -> 110000
A4: BẮP CẢI TÍM (BẮP) | D4: =B4*C4 -> 0
A5: BẮP CẢI TÍM SUSHI | D5: =B5*C5 -> 0
A6: BẮP CẢI TRẮNG | D6: =B6*C6 -> 0
A7: BẮP CẢI TRẮNG (BẮP) | D7: =B7*C7 -> 0
A8: BẮP CẢI TRẮNG MỘC CHÂU | D8: =B8*C8 -> 0
A9: BẮP CẢI TRẮNG SÓI BIỂN | D9: =B9*C9 -> 0
A10: BẮP CẢI TRẮNG SUSHI | D10: =B10*C10 -> 0
A11: BẮP MỸ CẶP | D11: =B11*C11 -> 0
A12: BẦU | D12: =B12*C12 -> 0
A13: BÍ ĐAO XANH | D13: =B13*C13 -> 0
A14: BÍ ĐAO XANH 400G | D14: =B14*C14 -> 0
A15: BÍ ĐỎ HỒ LÔ | D15: =B15*C15 -> 0
... A18: BÍ ĐỎ NON TRÁI VR | D18: =B18*C18 -> 0
A19: BÍ ĐỎ NON( KG) VR | B19: 8 | C19: 14000 | D19: =B19*C19 -> 112000
A20: BÍ ĐỎ TRÒN | B20: 300 | C20: 17000 | D20: =B20*C20 -> 5100000
A21: BÍ MINI VÀNG 300GR | D21: =B21*C21 -> 0
A22: BÍ MINI VÀNG KG | D22: =B22*C22 -> 0
A23: BÍ NGÒI VÀNG | D23: =B23*C23 -> 0
A24: BÍ NGÒI VÀNG (TRÁI) | D24: =B24*C24 -> 0
A25: BÍ NGÒI XANH | B25: =35+30+90+50+60 -> 265 | C25: 12000 | D25: =B25*C25 -> 3180000
A26: BÍ NGÒI XANH(TRÁI) | D26: =B26*C26 -> 0
A27: BÍ NHẬT | D27: =B27*C27 -> 0
A28: BƠ 034 | B28: =18+250+120+60 -> 448 | C28: 13480 | D28: =B28*C28 -> 6039040
A29: BƠ BOOTH | D29: =B29*C29 -> 0
A30: BO HOA CHUONG | D30: =B30*C30 -> 0
A31: BO HOA CUC TANA | D31: =B31*C31 -> 0
A32: BO HOA DONG TIEN HN | D32: =B32*C32 -> 0
A33: BO HOA LOA KEN | D33: =B33*C33 -> 0
A34: BO HOA PHANG | D34: =B34*C34 -> 0
A35: BO HOA SEN QUAN AM | D35: =B35*C35 -> 0
A36: BO HOA SEN SUPER | D36: =B36*C36 -> 0
A37: BƠ SÁP | B37: =105+65+80+10 -> 260 | C37: 11463 | D37: =B37*C37 -> 2980380
A38: BÓ XÔI | D38: =B38*C38 -> 0
A39: BÓ XÔI 300G VR | D39: =B39*C39 -> 0
A40: BÓ XÔI-HN KQ | D40: =B40*C40 -> 0
A41: BÓ XÔI-NA | D41: =B41*C41 -> 0
A42: BÔNG ATISO | D42: =B42*C42 -> 0
...

Sheet 11.6
A1: hàng tồn cuối ngày 11/6 vr
A2: TÊN SẢN PHẨM | B2: TỒN TRƯỚC | C2: GIÁ NHẬP | D2: THÀNH TIỀN
A3: BẮP CẢI TÍM | B3: 12 | C3: 11000 | D3: =B3*C3 -> 132000
A4: BẮP CẢI TÍM (BẮP) | D4: =B4*C4 -> 0
A5: BẮP CẢI TÍM SUSHI | D5: =B5*C5 -> 0
A6: BẮP CẢI TRẮNG | D6: =B6*C6 -> 0
A7: BẮP CẢI TRẮNG (BẮP) | D7: =B7*C7 -> 0
A8: BẮP CẢI TRẮNG MỘC CHÂU | D8: =B8*C8 -> 0
A9: BẮP CẢI TRẮNG SÓI BIỂN | D9: =B9*C9 -> 0
A10: BẮP CẢI TRẮNG SUSHI | D10: =B10*C10 -> 0
A11: BẮP MỸ CẶP | D11: =B11*C11 -> 0
A12: BẦU | D12: =B12*C12 -> 0
A13: BÍ ĐAO XANH | D13: =B13*C13 -> 0
A14: BÍ ĐAO XANH 400G | D14: =B14*C14 -> 0
A15: BÍ ĐỎ HỒ LÔ | D15: =B15*C15 -> 0
... A17: BÍ ĐỎ NON (KG)KQ | D17: =B17*C17 -> 0
A18: BÍ ĐỎ NON TRÁI VR | B18: =52+37+50+20+46+53+50 -> 308 | C18: 4000 | D18: =B18*C18 -> 1232000
A19: BÍ ĐỎ NON( KG) VR | B19: 16 | C19: 14000 | D19: =B19*C19 -> 224000
A20: BÍ ĐỎ TRÒN | D20: =B20*C20 -> 0
A21: BÍ MINI VÀNG 300GR | D21: =B21*C21 -> 0
A22: BÍ MINI VÀNG KG | D22: =B22*C22 -> 0
A23: BÍ NGÒI VÀNG | D23: =B23*C23 -> 0
A24: BÍ NGÒI VÀNG (TRÁI) | D24: =B24*C24 -> 0
A25: BÍ NGÒI XANH | B25: 50 | C25: 8000 | D25: =B25*C25 -> 400000
A26: BÍ NGÒI XANH(TRÁI) | D26: =B26*C26 -> 0
A27: BÍ NHẬT | D27: =B27*C27 -> 0
A28: BƠ 034 | B28: =18+15 -> 33 | C28: 13000 | D28: =B28*C28 -> 429000
A29: BƠ BOOTH | D29: =B29*C29 -> 0
A30: BO HOA CHUONG | D30: =B30*C30 -> 0
A31: BO HOA CUC TANA | D31: =B31*C31 -> 0
A32: BO HOA DONG TIEN HN | D32: =B32*C32 -> 0
A33: BO HOA LOA KEN | D33: =B33*C33 -> 0
A34: BO HOA PHANG | D34: =B34*C34 -> 0
A35: BO HOA SEN QUAN AM | D35: =B35*C35 -> 0
A36: BO HOA SEN SUPER | D36: =B36*C36 -> 0
A37: BƠ SÁP | B37: =35+62+27+65+12 -> 201 | C37: 11500 | D37: =B37*C37 -> 2311500
A38: BÓ XÔI | D38: =B38*C38 -> 0
A39: BÓ XÔI 300G VR | D39: =B39*C39 -> 0
A40: BÓ XÔI-HN KQ | D40: =B40*C40 -> 0
A41: BÓ XÔI-NA | D41: =B41*C41 -> 0
...

Sheet 12.6
A1: hàng tồn cuối ngày 12/6 vr
A2: TÊN SẢN PHẨM | B2: TỒN TRƯỚC | C2: GIÁ NHẬP | D2: THÀNH TIỀN
A3: BẮP CẢI TÍM | B3: 20 | C3: 11000 | D3: =B3*C3 -> 220000
A4: BẮP CẢI TÍM (BẮP) | D4: =B4*C4 -> 0
A5: BẮP CẢI TÍM SUSHI | D5: =B5*C5 -> 0
A6: BẮP CẢI TRẮNG | D6: =B6*C6 -> 0
A7: BẮP CẢI TRẮNG (BẮP) | D7: =B7*C7 -> 0
A8: BẮP CẢI TRẮNG MỘC CHÂU | D8: =B8*C8 -> 0
A9: BẮP CẢI TRẮNG SÓI BIỂN | D9: =B9*C9 -> 0
A10: BẮP CẢI TRẮNG SUSHI | D10: =B10*C10 -> 0
A11: BẮP MỸ CẶP | D11: =B11*C11 -> 0
A12: BẦU | D12: =B12*C12 -> 0
A13: BÍ ĐAO XANH | D13: =B13*C13 -> 0
A14: BÍ ĐAO XANH 400G | D14: =B14*C14 -> 0
A15: BÍ ĐỎ HỒ LÔ | D15: =B15*C15 -> 0
... A17: BÍ ĐỎ NON (KG)KQ | D17: =B17*C17 -> 0
A18: BÍ ĐỎ NON TRÁI VR | B18: =14+26+30+85+50 -> 205 | C18: 3500 | D18: =B18*C18 -> 717500
A19: BÍ ĐỎ NON( KG) VR | D19: =B19*C19 -> 0
A20: BÍ ĐỎ TRÒN | D20: =B20*C20 -> 0
A21: BÍ MINI VÀNG 300GR | D21: =B21*C21 -> 0
A22: BÍ MINI VÀNG KG | D22: =B22*C22 -> 0
A23: BÍ NGÒI VÀNG | D23: =B23*C23 -> 0
A24: BÍ NGÒI VÀNG (TRÁI) | D24: =B24*C24 -> 0
A25: BÍ NGÒI XANH | D25: =B25*C25 -> 0
A26: BÍ NGÒI XANH(TRÁI) | D26: =B26*C26 -> 0
A27: BÍ NHẬT | D27: =B27*C27 -> 0
A28: BƠ 034 | B28: 160 | C28: 13000 | D28: =B28*C28 -> 2080000
A29: BƠ BOOTH | D29: =B29*C29 -> 0
A30: BO HOA CHUONG | D30: =B30*C30 -> 0
A31: BO HOA CUC TANA | D31: =B31*C31 -> 0
A32: BO HOA DONG TIEN HN | D32: =B32*C32 -> 0
A33: BO HOA LOA KEN | D33: =B33*C33 -> 0
A34: BO HOA PHANG | D34: =B34*C34 -> 0
A35: BO HOA SEN QUAN AM | D35: =B35*C35 -> 0
A36: BO HOA SEN SUPER | D36: =B36*C36 -> 0
A37: BƠ SÁP | B37: 63 | C37: 11500 | D37: =B37*C37 -> 724500
A38: BÓ XÔI | D38: =B38*C38 -> 0
A39: BÓ XÔI 300G VR | D39: =B39*C39 -> 0
A40: BÓ XÔI-HN KQ | D40: =B40*C40 -> 0
A41: BÓ XÔI-NA | D41: =B41*C41 -> 0
...

Sheet 13.6
A1: 45425 | C1: Stock
A2: TÊN SẢN PHẨM KQ | B2: ĐVT | C2: TỒN TRƯỚC | D2: GIÁ NHẬP | E2: THÀNH TIỀN
A4: BẮP CẢI TÍM | B4: Kg
A5: BẮP CẢI TÍM (BẮP) | B5: BẮP
A6: BẮP CẢI TÍM SUSHI | B6: Kg
A7: BẮP CẢI TRẮNG | B7: Kg | C7: 160 | D7: 5000 | E7: =+D7*C7 -> 800000
A8: BẮP CẢI TRẮNG (BẮP) | B8: BẮP
A9: BẮP CẢI TRẮNG MỘC CHÂU | B9: Kg
A10: BẮP CẢI TRẮNG SÓI BIỂN | B10: Kg
A11: BẮP CẢI TRẮNG SUSHI | B11: Kg
A12: BẮP MỸ | B12: Kg
A13: BẦU | B13: Kg
A14: BÍ ĐAO XANH | B14: Kg | C14: 18 | D14: 7000 | E14: =+D14*C14 -> 126000
A15: BÍ ĐAO XANH 400G | B15: TRÁI
A16: BÍ ĐỎ HỒ LÔ | B16: Kg
A17: BÍ ĐỎ MINI | B17: Kg
A18: BÍ ĐỎ NON (KG)KQ | B18: Kg
A19: BÍ ĐỎ NON TRÁI VR | B19: TRÁI
A20: BÍ ĐỎ NON( KG) VR | B20: Kg
A21: BÍ ĐỎ TRÒN | B21: Kg | C21: 1100 | D21: 17000 | E21: =+D21*C21 -> 18700000
A22: BÍ MINI VÀNG 300GR | B22: TRÁI
A23: BÍ MINI VÀNG KG | B23: Kg
A24: BÍ NGÒI VÀNG | B24: Kg
A25: BÍ NGÒI VÀNG (TRÁI) | B25: TRÁI
A26: BÍ NGÒI XANH | B26: Kg
A27: BÍ NGÒI XANH(TRÁI) | B27: TRÁI
A28: BÍ NHẬT | B28: Kg
A29: BƠ 034 | B29: Kg
A30: BƠ BOOTH | B30: Kg
A31: BƠ SÁP | B31: Kg
A32: BÓ XÔI | B32: Kg
A33: BÓ XÔI 300G VR | B33: TÚI
... A47: BÔNG CẢI XANH CITI | B47: Kg
A48: CÀ CHUA | B48: Kg | C48: 480 | D48: 17000 | E48: =+D48*C48 -> 8160000
A49: CÀ CHUA BI | B49: Kg
A50: CÀ CHUA BI (HỘP) 300GR KQ | B50: HỘP
A51: CÀ CHUA BI (HỘP) 300GR VR | B51: HỘP
A52: CÀ CHUA BI 300GR KQ (KG) | B52: Kg
A53: CÀ CHUA BI 300GR VR (KG) | B53: Kg
A54: CÀ CHUA BI CAM SỮA (KG) VR | B54: Kg
...

Sheet 14.6
A1: NGÀY 16/06/2024 | C1: Stock
A2: TÊN SẢN PHẨM KQ | B2: ĐVT | C2: TỒN TRƯỚC | D2: GIÁ NHẬP | E2: THÀNH TIỀN
A4: BẮP CẢI TÍM | B4: Kg
A5: BẮP CẢI TÍM (BẮP) | B5: BẮP
A6: BẮP CẢI TÍM SUSHI | B6: Kg
A7: BẮP CẢI TRẮNG | B7: Kg | C7: 148 | D7: 5000 | E7: =+D7*C7 -> 740000
A8: BẮP CẢI TRẮNG (BẮP) | B8: BẮP
A9: BẮP CẢI TRẮNG MỘC CHÂU | B9: Kg
A10: BẮP CẢI TRẮNG SÓI BIỂN | B10: Kg
A11: BẮP CẢI TRẮNG SUSHI | B11: Kg
A12: BẮP MỸ | B12: Kg
A13: BẦU | B13: Kg
A14: BÍ ĐAO XANH | B14: Kg | C14: 30 | D14: 7000 | E14: =+D14*C14 -> 210000
A15: BÍ ĐAO XANH 400G | B15: TRÁI
A16: BÍ ĐỎ HỒ LÔ | B16: Kg
A17: BÍ ĐỎ MINI | B17: Kg
A18: BÍ ĐỎ NON (KG)KQ | B18: Kg
A19: BÍ ĐỎ NON TRÁI VR | B19: TRÁI
A20: BÍ ĐỎ NON( KG) VR | B20: Kg
A21: BÍ ĐỎ TRÒN | B21: Kg | C21: 1065 | D21: 17000 | E21: =+D21*C21 -> 18105000
A22: BÍ MINI VÀNG 300GR | B22: TRÁI
A23: BÍ MINI VÀNG KG | B23: Kg
A24: BÍ NGÒI VÀNG | B24: Kg | C24: 2 | D24: 10000 | E24: =+D24*C24 -> 20000
A25: BÍ NGÒI VÀNG (TRÁI) | B25: TRÁI
A26: BÍ NGÒI XANH | B26: Kg
A27: BÍ NGÒI XANH(TRÁI) | B27: TRÁI
A28: BÍ NHẬT | B28: Kg
A29: BƠ 034 | B29: Kg
A30: BƠ BOOTH | B30: Kg
A31: BƠ SÁP | B31: Kg
A32: BÓ XÔI | B32: Kg
A33: BÓ XÔI 300G VR | B33: TÚI
A34: BÓ XÔI-HN KQ | B34: Kg
A35: BÓ XÔI-NA | B35: Kg
A36: BÔNG ATISO | B36: Kg
... A47: BÔNG CẢI XANH CITI | B47: Kg
A48: CÀ CHUA | B48: Kg | C48: 316 | D48: 18000 | E48: =+D48*C48 -> 5688000
A49: CÀ CHUA BI | B49: Kg
A50: CÀ CHUA BI (HỘP) 300GR KQ | B50: HỘP
A51: CÀ CHUA BI (HỘP) 300GR VR | B51: HỘP
...

Sheet 15.6
A1: hàng tồn cuối ngày 15/6 vr
A2: TÊN SẢN PHẨM | B2: TỒN TRƯỚC | C2: GIÁ NHẬP | D2: THÀNH TIỀN
A3: BẮP CẢI TÍM | B3: 10 | C3: 10000 | D3: =B3*C3 -> 100000
A4: BẮP CẢI TÍM (BẮP) | D4: =B4*C4 -> 0
A5: BẮP CẢI TÍM SUSHI | D5: =B5*C5 -> 0
A6: BẮP CẢI TRẮNG | D6: =B6*C6 -> 0
A7: BẮP CẢI TRẮNG (BẮP) | D7: =B7*C7 -> 0
A8: BẮP CẢI TRẮNG MỘC CHÂU | D8: =B8*C8 -> 0
A9: BẮP CẢI TRẮNG SÓI BIỂN | D9: =B9*C9 -> 0
A10: BẮP CẢI TRẮNG SUSHI | D10: =B10*C10 -> 0
A11: BẮP MỸ CẶP | D11: =B11*C11 -> 0
A12: BẦU | D12: =B12*C12 -> 0
A13: BÍ ĐAO XANH | D13: =B13*C13 -> 0
A14: BÍ ĐAO XANH 400G | D14: =B14*C14 -> 0
A15: BÍ ĐỎ HỒ LÔ | D15: =B15*C15 -> 0
... A17: BÍ ĐỎ NON (KG)KQ | D17: =B17*C17 -> 0
A18: BÍ ĐỎ NON TRÁI VR | B18: 23 | C18: 4000 | D18: =B18*C18 -> 92000
A19: BÍ ĐỎ NON( KG) VR | B19: 8 | C19: 12000 | D19: =B19*C19 -> 96000
A20: BÍ ĐỎ TRÒN | B20: 100 | C20: 18000 | D20: =B20*C20 -> 1800000
A21: BÍ MINI VÀNG 300GR | D21: =B21*C21 -> 0
A22: BÍ MINI VÀNG KG | D22: =B22*C22 -> 0
A23: BÍ NGÒI VÀNG | D23: =B23*C23 -> 0
A24: BÍ NGÒI VÀNG (TRÁI) | D24: =B24*C24 -> 0
A25: BÍ NGÒI XANH | B25: 114 | C25: 8000 | D25: =B25*C25 -> 912000
A26: BÍ NGÒI XANH(TRÁI) | D26: =B26*C26 -> 0
A27: BÍ NHẬT | D27: =B27*C27 -> 0
A28: BO HOA CUC TANA | D28: =B28*C28 -> 0
A29: BO HOA CHUONG | D29: =B29*C29 -> 0
A30: BO HOA DONG TIEN HN | D30: =B30*C30 -> 0
A31: BO HOA LOA KEN | D31: =B31*C31 -> 0
A32: BO HOA PHANG | D32: =B32*C32 -> 0
A33: BO HOA SEN QUAN AM | D33: =B33*C33 -> 0
A34: BO HOA SEN SUPER | D34: =B34*C34 -> 0
A35: BÓ XÔI | D35: =B35*C35 -> 0
A36: BÓ XÔI 300G VR | B36: 11 | C36: 12000 | D36: =B36*C36 -> 132000
A37: BÓ XÔI-HN KQ | D37: =B37*C37 -> 0
A38: BÓ XÔI-NA | D38: =B38*C38 -> 0
A39: BÔNG ATISO | D39: =B39*C39 -> 0
A40: BÔNG BÍ | D40: =B40*C40 -> 0
A41: BÔNG BÍ TÚI 300GR | D41: =B41*C41 -> 0
...

Sheet 16.6
A1: hàng tồn cuối ngày 16/6 vr
A2: TÊN SẢN PHẨM | B2: TỒN TRƯỚC | C2: GIÁ NHẬP | D2: THÀNH TIỀN
A3: BẮP CẢI TÍM | B3: 15 | C3: 10000 | D3: =B3*C3 -> 150000
A4: BẮP CẢI TÍM (BẮP) | D4: =B4*C4 -> 0
A5: BẮP CẢI TÍM SUSHI | D5: =B5*C5 -> 0
A6: BẮP CẢI TRẮNG | D6: =B6*C6 -> 0
A7: BẮP CẢI TRẮNG (BẮP) | D7: =B7*C7 -> 0
A8: BẮP CẢI TRẮNG MỘC CHÂU | D8: =B8*C8 -> 0
A9: BẮP CẢI TRẮNG SÓI BIỂN | D9: =B9*C9 -> 0
A10: BẮP CẢI TRẮNG SUSHI | D10: =B10*C10 -> 0
A11: BẮP MỸ CẶP | D11: =B11*C11 -> 0
A12: BẦU | D12: =B12*C12 -> 0
A13: BÍ ĐAO XANH | D13: =B13*C13 -> 0
A14: BÍ ĐAO XANH 400G | D14: =B14*C14 -> 0
A15: BÍ ĐỎ HỒ LÔ | B15: 19 | C15: 19000 | D15: =B15*C15 -> 361000
A16: BÍ ĐỎ MINI | D16: =B16*C16 -> 0
A17: BÍ ĐỎ NON (KG)KQ | D17: =B17*C17 -> 0
A18: BÍ ĐỎ NON TRÁI VR | D18: =B18*C18 -> 0
A19: BÍ ĐỎ NON( KG) VR | D19: =B19*C19 -> 0
A20: BÍ ĐỎ TRÒN | B20: 100 | C20: 18000 | D20: =B20*C20 -> 1800000
A21: BÍ MINI VÀNG 300GR | D21: =B21*C21 -> 0
A22: BÍ MINI VÀNG KG | D22: =B22*C22 -> 0
A23: BÍ NGÒI VÀNG | D23: =B23*C23 -> 0
A24: BÍ NGÒI VÀNG (TRÁI) | D24: =B24*C24 -> 0
A25: BÍ NGÒI XANH | B25: 52 | C25: 8000 | D25: =B25*C25 -> 416000
A26: BÍ NGÒI XANH(TRÁI) | D26: =B26*C26 -> 0
A27: BÍ NHẬT | D27: =B27*C27 -> 0
A28: BƠ 034 | B28: =35+15 -> 50 | C28: 12500 | D28: =B28*C28 -> 625000
A29: BƠ BOOTH | B29: 15 | C29: 20000 | D29: =B29*C29 -> 300000
A30: BO HOA CHUONG | D30: =B30*C30 -> 0
A31: BO HOA CUC TANA | D31: =B31*C31 -> 0
A32: BO HOA DONG TIEN HN | D32: =B32*C32 -> 0
A33: BO HOA LOA KEN | D33: =B33*C33 -> 0
A34: BO HOA PHANG | D34: =B34*C34 -> 0
A35: BO HOA SEN QUAN AM | D35: =B35*C35 -> 0
A36: BO HOA SEN SUPER | D36: =B36*C36 -> 0
A37: BƠ SÁP | B37: =74+22-40+38 -> 94 | C37: 11500 | D37: =B37*C37 -> 1081000
A38: BÓ XÔI | D38: =B38*C38 -> 0
A39: BÓ XÔI 300G VR | B39: 12 | C39: 12000 | D39: =B39*C39 -> 144000
A40: BÓ XÔI-HN KQ | D40: =B40*C40 -> 0
...

Sheet 17.6
A1: hàng tồn cuối ngày 17/6 vr
A2: TÊN SẢN PHẨM | B2: TỒN TRƯỚC | C2: GIÁ NHẬP | D2: THÀNH TIỀN
A3: CÀ CHUA SÔCOLA 250GR (HỘP) VR | B3: 62 | C3: 12000 | D3: =B3*C3 -> 744000
A4: CÀ CHUA SÔCOLA 300GR (HỘP) VR | D4: =B4*C4 -> 0
A5: CÀ RỐT BABY 200GR | D5: =B5*C5 -> 0
A6: CẢI KALE | D6: =B6*C6 -> 0
A7: CẢI KALE 300GR | D7: =B7*C7 -> 0
A8: CHANH VÀNG TRÁI 180UP | D8: =B8*C8 -> 0
A9: CẦN TÂY (KG) | B9: 30 | C9: 22000 | D9: =B9*C9 -> 660000
A10: CẦN TÂY(CÂY) | D10: =B10*C10 -> 0
A11: ỚT CHUÔNG 3 MÀU(KG)VR | D11: =B11*C11 -> 0
A12: ỚT CHUÔNG ĐỎ | B12: 7 | C12: 26000 | D12: =B12*C12 -> 182000
A13: ỚT CHUÔNG ĐỎ(TRÁI) | D13: =B13*C13 -> 0
A14: ỚT CHUÔNG VÀNG | B14: 30 | C14: 38000 | D14: =B14*C14 -> 1140000
A15: ỚT CHUÔNG VÀNG L1 | B15: 5 | C15: 30000 | D15: =B15*C15 -> 150000
A16: ỚT CHUÔNG VÀNG(TRÁI) | D16: =B16*C16 -> 0
A17: ỚT CHUÔNG XANH | B17: 65 | C17: 18000 | D17: =B17*C17 -> 1170000
A18: ỚT CHUÔNG XANH L1 | B18: 5 | C18: 10000 | D18: =B18*C18 -> 50000
A19: ỚT CHUÔNG XANH(TRÁI) | D19: =B19*C19 -> 0
A20: CỦ DỀN | D20: =B20*C20 -> 0
A21: CỦ DỀN 600G | D21: =B21*C21 -> 0
A22: XÀ LÁCH MỸ | D22: =B22*C22 -> 0
A23: KHOAI TÂY VÀNG ĐL | B23: 250 | C23: 16000 | D23: =B23*C23 -> 4000000
A24: KHOAI TÂY VÀNG LỚN TÚI LƯỚI 500G | B24: 230 | C24: 11000 | D24: =B24*C24 -> 2530000
A25: CẢI THẢO DL | D25: =B25*C25 -> 0
A26: BÍ ĐAO XANH | D26: =B26*C26 -> 0
A27: DƯA LEO | D27: =B27*C27 -> 0
A28: DƯA LEO GIỐNG NHẬT 600GR | D28: =B28*C28 -> 0
A29: DƯA LEO GIỐNG NHẬT KG | D29: =B29*C29 -> 0
A30: BƠ 034 | B30: 30 | C30: 12500 | D30: =B30*C30 -> 375000
A31: BƠ SÁP | B31: 70 | C31: 11500 | D31: =B31*C31 -> 805000
A32: KHOAI LANG MẬT (KG) 2-3 CỦ | B32: 400 | C32: 20000 | D32: =B32*C32 -> 8000000
A33: KHOAI LANG MẬT (KG) 4-6 CỦ | B33: 350 | C33: 19000 | D33: =B33*C33 -> 6650000
A34: KHOAI LANG MẬT 500G VR | D34: =B34*C34 -> 0
A35: PARO | D35: =B35*C35 -> 0
A36: PARO (CÂY) | D36: =B36*C36 -> 0
A37: BẮP CẢI TÍM | B37: 10 | C37: 10000 | D37: =B37*C37 -> 100000
A38: CÀ CHUA CHERRY MIX 300G | D38: =B38*C38 -> 0
A39: TÍA TÔ 50G | D39: =B39*C39 -> 0
A40: XÀ LÁCH LOLO XANH | D40: =B40*C40 -> 0
...

Sheet 18.6
A1: hàng tồn cuối ngày 18/6 vr
A2: TÊN SẢN PHẨM | B2: TỒN TRƯỚC | C2: GIÁ NHẬP | D2: THÀNH TIỀN
A3: BẮP CẢI TÍM | B3: 24 | C3: 10000 | D3: =B3*C3 -> 240000
A4: BẮP CẢI TÍM (BẮP) | D4: =B4*C4 -> 0
A5: BẮP CẢI TÍM SUSHI | D5: =B5*C5 -> 0
A6: BẮP CẢI TRẮNG | D6: =B6*C6 -> 0
A7: BẮP CẢI TRẮNG (BẮP) | D7: =B7*C7 -> 0
A8: BẮP CẢI TRẮNG MỘC CHÂU | D8: =B8*C8 -> 0
A9: BẮP CẢI TRẮNG SÓI BIỂN | D9: =B9*C9 -> 0
A10: BẮP CẢI TRẮNG SUSHI | D10: =B10*C10 -> 0
A11: BẮP MỸ CẶP | D11: =B11*C11 -> 0
A12: BẦU | B12: 1 | C12: 10000 | D12: =B12*C12 -> 10000
A13: BÍ ĐAO XANH | D13: =B13*C13 -> 0
A14: BÍ ĐAO XANH 400G | D14: =B14*C14 -> 0
A15: BÍ ĐỎ HỒ LÔ | B15: 20 | C15: 19000 | D15: =B15*C15 -> 380000
A16: BÍ ĐỎ MINI | D16: =B16*C16 -> 0
A17: BÍ ĐỎ NON (KG)KQ | D17: =B17*C17 -> 0
A18: BÍ ĐỎ NON TRÁI VR | D18: =B18*C18 -> 0
A19: BÍ ĐỎ NON( KG) VR | D19: =B19*C19 -> 0
A20: BÍ ĐỎ TRÒN | B20: 270 | C20: 18000 | D20: =B20*C20 -> 4860000
A21: BÍ MINI VÀNG 300GR | D21: =B21*C21 -> 0
A22: BÍ MINI VÀNG KG | D22: =B22*C22 -> 0
A23: BÍ NGÒI VÀNG | D23: =B23*C23 -> 0
A24: BÍ NGÒI VÀNG (TRÁI) | D24: =B24*C24 -> 0
A25: BÍ NGÒI XANH | B25: =10+30+18+30+30 -> 118 | C25: 11000 | D25: =B25*C25 -> 1298000
A26: BÍ NGÒI XANH(TRÁI) | D26: =B26*C26 -> 0
A27: BÍ NHẬT | D27: =B27*C27 -> 0
A28: BƠ 034 | B28: 68 | C28: 12500 | D28: =B28*C28 -> 850000
A29: BƠ 034 COOP | D29: =B29*C29 -> 0
A30: BƠ BOOTH | B30: 8 | C30: 20000 | D30: =B30*C30 -> 160000
A31: BO HOA CHUONG | D31: =B31*C31 -> 0
A32: BO HOA CUC TANA | D32: =B32*C32 -> 0
A33: BO HOA DONG TIEN HN | D33: =B33*C33 -> 0
A34: BO HOA LOA KEN | D34: =B34*C34 -> 0
A35: BO HOA PHANG | D35: =B35*C35 -> 0
A36: BO HOA SEN QUAN AM | D36: =B36*C36 -> 0
A37: BO HOA SEN SUPER | D37: =B37*C37 -> 0
A38: BƠ SÁP | B38: =17+17+22+110 -> 166 | C38: 11500 | D38: =B38*C38 -> 1909000
A39: BÓ XÔI | D39: =B39*C39 -> 0
A40: BÓ XÔI 300G VR | B40: 4 | C40: 13000 | D40: =B40*C40 -> 52000
...

Sheet 19.6
A1: hàng tồn cuối ngày 19/6 vr
A2: TÊN SẢN PHẨM | B2: TỒN TRƯỚC | C2: GIÁ NHẬP | D2: THÀNH TIỀN
A3: BẮP CẢI TÍM | B3: 4 | C3: 10000 | D3: =B3*C3 -> 40000
A4: BẮP CẢI TÍM (BẮP) | D4: =B4*C4 -> 0
A5: BẮP CẢI TÍM SUSHI | D5: =B5*C5 -> 0
A6: BẮP CẢI TRẮNG | D6: =B6*C6 -> 0
A7: BẮP CẢI TRẮNG (BẮP) | D7: =B7*C7 -> 0
A8: BẮP CẢI TRẮNG MỘC CHÂU | D8: =B8*C8 -> 0
A9: BẮP CẢI TRẮNG SÓI BIỂN | D9: =B9*C9 -> 0
A10: BẮP CẢI TRẮNG SUSHI | D10: =B10*C10 -> 0
A11: BẮP MỸ CẶP | D11: =B11*C11 -> 0
A12: BẦU | D12: =B12*C12 -> 0
A13: BÍ ĐAO XANH | D13: =B13*C13 -> 0
A14: BÍ ĐAO XANH 400G | D14: =B14*C14 -> 0
A15: BÍ ĐỎ HỒ LÔ | B15: 8 | C15: 19000 | D15: =B15*C15 -> 152000
A16: BÍ ĐỎ MINI | D16: =B16*C16 -> 0
A17: BÍ ĐỎ NON (KG)KQ | D17: =B17*C17 -> 0
A18: BÍ ĐỎ NON TRÁI VR | D18: =B18*C18 -> 0
A19: BÍ ĐỎ NON( KG) VR | D19: =B19*C19 -> 0
A20: BÍ ĐỎ TRÒN | B20: 160 | C20: 18000 | D20: =B20*C20 -> 2880000
A21: BÍ MINI VÀNG 300GR | D21: =B21*C21 -> 0
A22: BÍ MINI VÀNG KG | D22: =B22*C22 -> 0
A23: BÍ NGÒI VÀNG | D23: =B23*C23 -> 0
A24: BÍ NGÒI VÀNG (TRÁI) | D24: =B24*C24 -> 0
A25: BÍ NGÒI XANH | B25: =25+12 -> 37 | C25: 11000 | D25: =B25*C25 -> 407000
A26: BÍ NGÒI XANH(TRÁI) | D26: =B26*C26 -> 0
A27: BÍ NHẬT | D27: =B27*C27 -> 0
A28: BƠ 034 | B28: =3+20 -> 23 | C28: 12500 | D28: =B28*C28 -> 287500
A29: BƠ 034 COOP | B29: 12 | C29: 11000 | D29: =B29*C29 -> 132000
A30: BƠ BOOTH | B30: 30 | C30: 20000 | D30: =B30*C30 -> 600000
A31: BO HOA CHUONG | D31: =B31*C31 -> 0
A32: BO HOA CUC TANA | D32: =B32*C32 -> 0
A33: BO HOA DONG TIEN HN | D33: =B33*C33 -> 0
A34: BO HOA LOA KEN | D34: =B34*C34 -> 0
A35: BO HOA PHANG | D35: =B35*C35 -> 0
A36: BO HOA SEN QUAN AM | D36: =B36*C36 -> 0
A37: BO HOA SEN SUPER | D37: =B37*C37 -> 0
A38: BƠ SÁP | B38: 20 | C38: 11500 | D38: =B38*C38 -> 230000
A39: BÓ XÔI | D39: =B39*C39 -> 0
A40: BÓ XÔI 300G VR | D40: =B40*C40 -> 0
...

Sheet 20.6
A1: hàng tồn cuối ngày 20/6 vr | B1: Stock | D1: Safety stock
A2: TÊN SẢN PHẨM | B2: TỒN TRƯỚC | C2: GIÁ NHẬP | D2: THÀNH TIỀN
A3: CÀ CHUA SÔCOLA 250GR (HỘP) VR | B3: 39 | C3: 10000 | D3: =B3*C3 -> 390000
A4: CÀ CHUA SÔCOLA 250GR (KG) VR | D4: =B4*C4 -> 0
A5: CÀ CHUA SÔCOLA 300GR (HỘP) VR | D5: =B5*C5 -> 0
A6: CÀ RỐT BABY | D6: =B6*C6 -> 0
A7: CÀ RỐT BABY 200GR | D7: =B7*C7 -> 0
A8: CẢI CẦU VỒNG | D8: =B8*C8 -> 0
A9: CẢI CẦU VỒNG 300GR | D9: =B9*C9 -> 0
A10: CẢI KALE 300GR | D10: =B10*C10 -> 0
A11: CHANH VÀNG TRÁI 180UP | D11: =B11*C11 -> 0
A12: CẦN TÂY (KG) | B12: 18 | C12: 21000 | D12: =B12*C12 -> 378000
A13: CẦN TÂY(CÂY) | D13: =B13*C13 -> 0
A14: ỚT CHUÔNG ĐỎ | B14: 75 | C14: 24000 | D14: =B14*C14 -> 1800000
A15: ỚT CHUÔNG ĐỎ(TRÁI) | D15: =B15*C15 -> 0
A16: ỚT CHUÔNG 3 MÀU 350G | B16: 45 | C16: 11000 | D16: =B16*C16 -> 495000
A17: ỚT CHUÔNG VÀNG | B17: 44 | C17: 36000 | D17: =B17*C17 -> 1584000
A18: ỚT CHUÔNG VÀNG(TRÁI) | D18: =B18*C18 -> 0
A19: ỚT CHUÔNG XANH | B19: 105 | C19: 20000 | D19: =B19*C19 -> 2100000
A20: ỚT CHUÔNG XANH(TRÁI) | D20: =B20*C20 -> 0
A21: CỦ DỀN | D21: =B21*C21 -> 0
A22: CỦ DỀN 600G | D22: =B22*C22 -> 0
A23: XÀ LÁCH MỸ | D23: =B23*C23 -> 0
A24: KHOAI TÂY HỒNG | D24: =B24*C24 -> 0
A25: KHOAI TÂY VÀNG ĐL | B25: 245 | C25: 16000 | D25: =B25*C25 -> 3920000
A26: KHOAI TÂY VÀNG LỚN TÚI LƯỚI 500G | D26: =B26*C26 -> 0
A27: KHOAI TÂY VÀNG TRUNG TÚI LƯỚI 500G | B27: 30 | C27: 11000 | D27: =B27*C27 -> 330000
A28: CẢI THẢO DL | D28: =B28*C28 -> 0
A29: BẦU | D29: =B29*C29 -> 0
A30: BÍ ĐAO XANH | D30: =B30*C30 -> 0
A31: DƯA LEO | D31: =B31*C31 -> 0
A32: DƯA LEO GIỐNG NHẬT 600GR | D32: =B32*C32 -> 0
A33: DƯA LEO GIỐNG NHẬT KG | D33: =B33*C33 -> 0
A34: BƠ 034 | B34: 5 | C34: 12500 | D34: =B34*C34 -> 62500
A35: BƠ SÁP | B35: 98 | C35: 11000 | D35: =B35*C35 -> 1078000
A36: KHOAI LANG MẬT (KG) 2-3 CỦ | B36: 210 | C36: 20000 | D36: =B36*C36 -> 4200000
A37: KHOAI LANG MẬT (KG) 4-6 CỦ | B37: 600 | C37: 19000 | D37: =B37*C37 -> 11400000
A38: KHOAI LANG MẬT 500G VR | D38: =B38*C38 -> 0
A39: PARO | B39: 25 | C39: 16000 | D39: =B39*C39 -> 400000
A40: PARO (CÂY) | D40: =B40*C40 -> 0
...

Sheet 21.6
A1: hàng tồn cuối ngày 21/6 vr
A2: TÊN SẢN PHẨM | B2: TỒN TRƯỚC | C2: GIÁ NHẬP | D2: THÀNH TIỀN
A3: BẮP CẢI TÍM | D3: =B3*C3 -> 0
A4: BẮP CẢI TÍM (BẮP) | D4: =B4*C4 -> 0
A5: BẮP CẢI TÍM SUSHI | D5: =B5*C5 -> 0
A6: BẮP CẢI TRẮNG | D6: =B6*C6 -> 0
A7: BẮP CẢI TRẮNG (BẮP) | D7: =B7*C7 -> 0
A8: BẮP CẢI TRẮNG MỘC CHÂU | D8: =B8*C8 -> 0
A9: BẮP CẢI TRẮNG SÓI BIỂN | D9: =B9*C9 -> 0
A10: BẮP CẢI TRẮNG SUSHI | D10: =B10*C10 -> 0
A11: BẮP MỸ CẶP | D11: =B11*C11 -> 0
A12: BẦU | D12: =B12*C12 -> 0
A13: BÍ ĐAO XANH | D13: =B13*C13 -> 0
A14: BÍ ĐAO XANH 400G | D14: =B14*C14 -> 0
A15: BÍ ĐỎ HỒ LÔ | B15: =5+33+55 -> 93 | C15: 19000 | D15: =B15*C15 -> 1767000
A16: BÍ ĐỎ MINI | D16: =B16*C16 -> 0
A17: BÍ ĐỎ NON (KG)KQ | D17: =B17*C17 -> 0
A18: BÍ ĐỎ NON TRÁI VR | B18: =50+120+15 -> 185 | C18: 4000 | D18: =B18*C18 -> 740000
A19: BÍ ĐỎ NON( KG) VR | D19: =B19*C19 -> 0
A20: BÍ ĐỎ TRÒN | B20: 160 | C20: 18000 | D20: =B20*C20 -> 2880000
A21: BÍ MINI VÀNG 300GR | D21: =B21*C21 -> 0
A22: BÍ MINI VÀNG KG | D22: =B22*C22 -> 0
A23: BÍ NGÒI VÀNG | D23: =B23*C23 -> 0
A24: BÍ NGÒI VÀNG (TRÁI) | D24: =B24*C24 -> 0
A25: BÍ NGÒI XANH | B25: =18+30+23 -> 71 | C25: 11000 | D25: =B25*C25 -> 781000
A26: BÍ NGÒI XANH(TRÁI) | D26: =B26*C26 -> 0
A27: BÍ NHẬT | D27: =B27*C27 -> 0
A28: BƠ 034 | B28: =35+6+18 -> 59 | C28: 12500 | D28: =B28*C28 -> 737500
A29: BƠ 034 COOP | D29: =B29*C29 -> 0
A30: BƠ BOOTH | B30: 8 | C30: 20000 | D30: =B30*C30 -> 160000
A31: BO HOA CHUONG | D31: =B31*C31 -> 0
A32: BO HOA CUC TANA | D32: =B32*C32 -> 0
A33: BO HOA DONG TIEN HN | D33: =B33*C33 -> 0
A34: BO HOA LOA KEN | D34: =B34*C34 -> 0
A35: BO HOA PHANG | D35: =B35*C35 -> 0
A36: BO HOA SEN QUAN AM | D36: =B36*C36 -> 0
A37: BO HOA SEN SUPER | D37: =B37*C37 -> 0
A38: BƠ SÁP | B38: =5+15+3 -> 23 | C38: 11500 | D38: =B38*C38 -> 264500
A39: BÓ XÔI | D39: =B39*C39 -> 0
A40: BÓ XÔI 300G VR | D40: =B40*C40 -> 0
...

Sheet 22.6
A1: hàng tồn cuối ngày 22/6 vr
A2: TÊN SẢN PHẨM | B2: TỒN TRƯỚC | C2: GIÁ NHẬP | D2: THÀNH TIỀN
A3: BẮP CẢI TÍM | B3: 10 | C3: 10000 | D3: =B3*C3 -> 100000
A4: BẮP CẢI TÍM (BẮP) | D4: =B4*C4 -> 0
A5: BẮP CẢI TÍM SUSHI | D5: =B5*C5 -> 0
A6: BẮP CẢI TRẮNG | D6: =B6*C6 -> 0
A7: BẮP CẢI TRẮNG (BẮP) | D7: =B7*C7 -> 0
A8: BẮP CẢI TRẮNG MỘC CHÂU | D8: =B8*C8 -> 0
A9: BẮP CẢI TRẮNG SÓI BIỂN | D9: =B9*C9 -> 0
A10: BẮP CẢI TRẮNG SUSHI | D10: =B10*C10 -> 0
A11: BẮP MỸ CẶP | D11: =B11*C11 -> 0
A12: BẦU | D12: =B12*C12 -> 0
A13: BÍ ĐAO XANH | D13: =B13*C13 -> 0
A14: BÍ ĐAO XANH 400G | D14: =B14*C14 -> 0
A15: BÍ ĐỎ HỒ LÔ | D15: =B15*C15 -> 0
... A19: BÍ ĐỎ NON( KG) VR | D19: =B19*C19 -> 0
A20: BÍ ĐỎ TRÒN | B20: 175 | C20: 14500 | D20: =B20*C20 -> 2537500
A21: BÍ MINI VÀNG 300GR | D21: =B21*C21 -> 0
A22: BÍ MINI VÀNG KG | D22: =B22*C22 -> 0
A23: BÍ NGÒI VÀNG | B23: 1.5 | C23: 12000 | D23: =B23*C23 -> 18000
A24: BÍ NGÒI VÀNG (TRÁI) | D24: =B24*C24 -> 0
A25: BÍ NGÒI XANH | B25: =13+28+37+38+16+5+10 -> 147 | C25: 11000 | D25: =B25*C25 -> 1617000
A26: BÍ NGÒI XANH(TRÁI) | D26: =B26*C26 -> 0
A27: BÍ NHẬT | D27: =B27*C27 -> 0
A28: BƠ 034 | B28: 90 | C28: 12500 | D28: =B28*C28 -> 1125000
A29: BƠ 034 COOP | D29: =B29*C29 -> 0
A30: BƠ BOOTH | B30: 8 | C30: 20000 | D30: =B30*C30 -> 160000
A31: BO HOA CHUONG | D31: =B31*C31 -> 0
A32: BO HOA CUC TANA | D32: =B32*C32 -> 0
A33: BO HOA DONG TIEN HN | D33: =B33*C33 -> 0
A34: BO HOA LOA KEN | D34: =B34*C34 -> 0
A35: BO HOA PHANG | D35: =B35*C35 -> 0
A36: BO HOA SEN QUAN AM | D36: =B36*C36 -> 0
A37: BO HOA SEN SUPER | D37: =B37*C37 -> 0
A38: BƠ SÁP | D38: =B38*C38 -> 0
A39: BÓ XÔI | D39: =B39*C39 -> 0
A40: BÓ XÔI 300G VR | D40: =B40*C40 -> 0
A41: BÓ XÔI-NA | D41: =B41*C41 -> 0
A42: BÔNG ATISO | D42: =B42*C42 -> 0
... A54: CÀ CHUA | D54: =B54*C54 -> 0
...

Sheet 23.6
A1: hàng tồn cuối ngày 23/6 vr
A2: TÊN SẢN PHẨM | B2: TỒN TRƯỚC | C2: GIÁ NHẬP | D2: THÀNH TIỀN
A3: CÀ CHUA SÔCOLA 250GR (HỘP) VR | D3: =B3*C3 -> 0
A4: CÀ CHUA SÔCOLA 250GR (KG) -NA | D4: =B4*C4 -> 0
A5: CÀ CHUA SÔCOLA 250GR (KG) VR | D5: =B5*C5 -> 0
A6: CÀ CHUA SÔCOLA 250GR(KG) KQ | D6: =B6*C6 -> 0
A7: CÀ CHUA SÔCOLA 300GR (HỘP) VR | D7: =B7*C7 -> 0
A8: CÀ CHUA SOCOLA XÁ | D8: =B8*C8 -> 0
A9: CÀ CHUA SÔCOLA(HỘP) KQ | D9: =B9*C9 -> 0
A10: CÀ RỐT BABY | D10: =B10*C10 -> 0
A11: CÀ RỐT BABY (KG) KQ | D11: =B11*C11 -> 0
A12: CÀ RỐT BABY 200GR | D12: =B12*C12 -> 0
A13: CẢI CẦU VỒNG | D13: =B13*C13 -> 0
A14: CẢI CẦU VỒNG 300GR | D14: =B14*C14 -> 0
... A19: CHANH VÀNG TRÁI 180UP | D19: =B19*C19 -> 0
A20: CẦN TÂY (KG) | B20: 42 | C20: 21000 | D20: =B20*C20 -> 882000
A21: CẦN TÂY THUỶ CANH | D21: =B21*C21 -> 0
A22: CẦN TÂY(CÂY) | D22: =B22*C22 -> 0
A23: ỚT CHUÔNG 3 MÀU(KG)VR | D23: =B23*C23 -> 0
A24: ỚT CHUÔNG ĐỎ | B24: =30+60+50+20 -> 160 | C24: 32000 | D24: =B24*C24 -> 5120000
A25: ỚT CHUÔNG ĐỎ L1 | D25: =B25*C25 -> 0
A26: ỚT CHUÔNG ĐỎ(TRÁI) | D26: =B26*C26 -> 0
A27: ỚT CHUÔNG 3 MÀU 350G | D27: =B27*C27 -> 0
A28: ỚT CHUÔNG 3 MÀU KQ(KG) | D28: =B28*C28 -> 0
A29: ỚT CHUÔNG VÀNG | B29: =50+10+8+60+6+20 -> 154 | C29: 38000 | D29: =B29*C29 -> 5852000
A30: ỚT CHUÔNG VÀNG L1 | D30: =B30*C30 -> 0
A31: ỚT CHUÔNG VÀNG(TRÁI) | D31: =B31*C31 -> 0
A32: ỚT CHUÔNG VÀNG+ XANH (VỈ) | D32: =B32*C32 -> 0
A33: ỚT CHUÔNG XANH | B33: =60+5 -> 65 | C33: 20000 | D33: =B33*C33 -> 1300000
A34: ỚT CHUÔNG XANH L1 | D34: =B34*C34 -> 0
A35: ỚT CHUÔNG XANH(TRÁI) | D35: =B35*C35 -> 0
A36: KHOAI TÂY HỒNG | D36: =B36*C36 -> 0
A37: KHOAI TÂY HỒNG TÚI LƯỚI 500G | D37: =B37*C37 -> 0
A38: KHOAI TÂY VÀNG | D38: =B38*C38 -> 0
A39: KHOAI TÂY VÀNG ĐL | B39: 200 | C39: 16000 | D39: =B39*C39 -> 3200000
A40: KHOAI TÂY VÀNG LỚN TÚI LƯỚI 500G | D40: =B40*C40 -> 0
A41: KHOAI TÂY VÀNG TRUNG TÚI LƯỚI 500G | D41: =B41*C41 -> 0
A42: CẢI THẢO DL | D42: =B42*C42 -> 0
A43: CẢI THẢO DL(BẮP) | D43: =B43*C43 -> 0
A44: CẢI THẢO KIM CHI | D44: =B44*C44 -> 0
...

Sheet 24.6
A1: NGÀY 26/06/2024
A2: TÊN SẢN PHẨM | B2: TỒN TRƯỚC | C2: GIÁ NHẬP | D2: THÀNH TIỀN
A3: BẮP CẢI TÍM | B3: 10 | C3: 12000 | D3: =B3*C3 -> 120000
A4: BẮP CẢI TÍM (BẮP) | D4: =B4*C4 -> 0
A5: BẮP CẢI TÍM SUSHI | D5: =B5*C5 -> 0
A6: BẮP CẢI TRẮNG | D6: =B6*C6 -> 0
A7: BẮP CẢI TRẮNG (BẮP) | D7: =B7*C7 -> 0
A8: BẮP CẢI TRẮNG MỘC CHÂU | D8: =B8*C8 -> 0
A9: BẮP CẢI TRẮNG SÓI BIỂN | D9: =B9*C9 -> 0
A10: BẮP CẢI TRẮNG SUSHI | D10: =B10*C10 -> 0
A11: BẮP MỸ CẶP | D11: =B11*C11 -> 0
A12: BẦU | D12: =B12*C12 -> 0
A13: BÍ ĐAO XANH | D13: =B13*C13 -> 0
A14: BÍ ĐAO XANH 400G | D14: =B14*C14 -> 0
A15: BÍ ĐỎ HỒ LÔ | B15: 15 | C15: 18000 | D15: =B15*C15 -> 270000
A16: BÍ ĐỎ MINI | D16: =B16*C16 -> 0
A17: BÍ ĐỎ NON (KG)KQ | D17: =B17*C17 -> 0
A18: BÍ ĐỎ NON TRÁI VR | B18: =57+27+10 -> 94 | C18: 4000 | D18: =B18*C18 -> 376000
A19: BÍ ĐỎ NON( KG) VR | D19: =B19*C19 -> 0
A20: BÍ ĐỎ TRÒN | B20: 140 | C20: 14500 | D20: =B20*C20 -> 2030000
A21: BÍ MINI VÀNG 300GR | D21: =B21*C21 -> 0
A22: BÍ MINI VÀNG KG | D22: =B22*C22 -> 0
A23: BÍ NGÒI VÀNG | D23: =B23*C23 -> 0
A24: BÍ NGÒI VÀNG (TRÁI) | D24: =B24*C24 -> 0
A25: BÍ NGÒI XANH | B25: =13+25+15+23+45+38 -> 159 | C25: 11500 | D25: =B25*C25 -> 1828500
A26: BÍ NGÒI XANH(TRÁI) | D26: =B26*C26 -> 0
A27: BÍ NHẬT | D27: =B27*C27 -> 0
A28: BƠ 034 | B28: =15+15 -> 30 | C28: 12500 | D28: =B28*C28 -> 375000
A29: BƠ 034 COOP | D29: =B29*C29 -> 0
A30: BƠ BOOTH | D30: =B30*C30 -> 0
A31: BO HOA CHUONG | D31: =B31*C31 -> 0
A32: BO HOA CUC TANA | D32: =B32*C32 -> 0
A33: BO HOA DONG TIEN HN | D33: =B33*C33 -> 0
A34: BO HOA LOA KEN | D34: =B34*C34 -> 0
A35: BO HOA PHANG | D35: =B35*C35 -> 0
A36: BO HOA SEN QUAN AM | D36: =B36*C36 -> 0
A37: BO HOA SEN SUPER | D37: =B37*C37 -> 0
A38: BƠ SÁP | B38: 110 | C38: 11000 | D38: =B38*C38 -> 1210000
A39: BÓ XÔI | D39: =B39*C39 -> 0
A40: BÓ XÔI 300G VR | D40: =B40*C40 -> 0
...

Sheet 25.6
A1: hàng tồn cuối ngày 25/6 vr
A2: TÊN SẢN PHẨM | B2: TỒN TRƯỚC | C2: GIÁ NHẬP | D2: THÀNH TIỀN
A3: BẮP CẢI TÍM | D3: =B3*C3 -> 0
A4: BẮP CẢI TÍM (BẮP) | D4: =B4*C4 -> 0
A5: BẮP CẢI TÍM SUSHI | D5: =B5*C5 -> 0
A6: BẮP CẢI TRẮNG | D6: =B6*C6 -> 0
A7: BẮP CẢI TRẮNG (BẮP) | D7: =B7*C7 -> 0
A8: BẮP CẢI TRẮNG MỘC CHÂU | D8: =B8*C8 -> 0
A9: BẮP CẢI TRẮNG SÓI BIỂN | D9: =B9*C9 -> 0
A10: BẮP CẢI TRẮNG SUSHI | D10: =B10*C10 -> 0
A11: BẮP MỸ CẶP | D11: =B11*C11 -> 0
A12: BẦU | D12: =B12*C12 -> 0
A13: BÍ ĐAO XANH | D13: =B13*C13 -> 0
A14: BÍ ĐAO XANH 400G | D14: =B14*C14 -> 0
A15: BÍ ĐỎ HỒ LÔ | B15: 18 | C15: 18000 | D15: =B15*C15 -> 324000
A16: BÍ ĐỎ MINI | D16: =B16*C16 -> 0
A17: BÍ ĐỎ NON (KG)KQ | D17: =B17*C17 -> 0
A18: BÍ ĐỎ NON TRÁI VR | B18: =13+15 -> 28 | C18: 4000 | D18: =B18*C18 -> 112000
A19: BÍ ĐỎ NON( KG) VR | D19: =B19*C19 -> 0
A20: BÍ ĐỎ TRÒN | B20: 150 | C20: 13000 | D20: =B20*C20 -> 1950000
A21: BÍ MINI VÀNG 300GR | D21: =B21*C21 -> 0
A22: BÍ MINI VÀNG KG | D22: =B22*C22 -> 0
A23: BÍ NGÒI VÀNG | D23: =B23*C23 -> 0
A24: BÍ NGÒI VÀNG (TRÁI) | D24: =B24*C24 -> 0
A25: BÍ NGÒI XANH | B25: =65+12+40+45 -> 162 | C25: 11000 | D25: =B25*C25 -> 1782000
A26: BÍ NGÒI XANH(TRÁI) | D26: =B26*C26 -> 0
A27: BÍ NHẬT | D27: =B27*C27 -> 0
A28: BƠ 034 | B28: =32+32 -> 64 | C28: 12500 | D28: =B28*C28 -> 800000
A29: BƠ 034 COOP | D29: =B29*C29 -> 0
A30: BƠ BOOTH | D30: =B30*C30 -> 0
A31: BO HOA CHUONG | D31: =B31*C31 -> 0
A32: BO HOA CUC TANA | D32: =B32*C32 -> 0
A33: BO HOA DONG TIEN HN | D33: =B33*C33 -> 0
A34: BO HOA LOA KEN | D34: =B34*C34 -> 0
A35: BO HOA PHANG | D35: =B35*C35 -> 0
A36: BO HOA SEN QUAN AM | D36: =B36*C36 -> 0
A37: BO HOA SEN SUPER | D37: =B37*C37 -> 0
A38: BƠ SÁP | B38: 9 | C38: 11000 | D38: =B38*C38 -> 99000
A39: BÓ XÔI | D39: =B39*C39 -> 0
A40: BÓ XÔI 300G VR | D40: =B40*C40 -> 0
...

Sheet 26.6
A1: hàng tồn cuối ngày 26/6 vr
A2: TÊN SẢN PHẨM | B2: TỒN TRƯỚC | C2: GIÁ NHẬP | D2: THÀNH TIỀN
A3: BẮP CẢI TÍM | B3: 10 | C3: 13000 | D3: =B3*C3 -> 130000
A4: BẮP CẢI TÍM (BẮP) | D4: =B4*C4 -> 0
A5: BẮP CẢI TÍM SUSHI | D5: =B5*C5 -> 0
A6: BẮP CẢI TRẮNG | D6: =B6*C6 -> 0
A7: BẮP CẢI TRẮNG (BẮP) | D7: =B7*C7 -> 0
A8: BẮP CẢI TRẮNG MỘC CHÂU | D8: =B8*C8 -> 0
A9: BẮP CẢI TRẮNG SÓI BIỂN | D9: =B9*C9 -> 0
A10: BẮP CẢI TRẮNG SUSHI | D10: =B10*C10 -> 0
A11: BẮP MỸ CẶP | D11: =B11*C11 -> 0
A12: BẦU | D12: =B12*C12 -> 0
A13: BÍ ĐAO XANH | D13: =B13*C13 -> 0
A14: BÍ ĐAO XANH 400G | D14: =B14*C14 -> 0
A15: BÍ ĐỎ HỒ LÔ | D15: =B15*C15 -> 0
... A17: BÍ ĐỎ NON (KG)KQ | D17: =B17*C17 -> 0
A18: BÍ ĐỎ NON TRÁI VR | B18: =21+148 -> 169 | C18: 4000 | D18: =B18*C18 -> 676000
A19: BÍ ĐỎ NON( KG) VR | D19: =B19*C19 -> 0
A20: BÍ ĐỎ TRÒN | B20: 120 | C20: 13000 | D20: =B20*C20 -> 1560000
A21: BÍ MINI VÀNG 300GR | D21: =B21*C21 -> 0
A22: BÍ MINI VÀNG KG | D22: =B22*C22 -> 0
A23: BÍ NGÒI VÀNG | B23: 3 | C23: 14000 | D23: =B23*C23 -> 42000
A24: BÍ NGÒI VÀNG (TRÁI) | D24: =B24*C24 -> 0
A25: BÍ NGÒI XANH | B25: =125+8 -> 133 | C25: 12000 | D25: =B25*C25 -> 1596000
A26: BÍ NGÒI XANH(TRÁI) | D26: =B26*C26 -> 0
A27: BÍ NHẬT | D27: =B27*C27 -> 0
A28: BƠ 034 | B28: 9 | C28: 12500 | D28: =B28*C28 -> 112500
A29: BƠ 034 COOP | D29: =B29*C29 -> 0
A30: BƠ BOOTH | D30: =B30*C30 -> 0
A31: BO HOA CHUONG | D31: =B31*C31 -> 0
A32: BO HOA CUC TANA | D32: =B32*C32 -> 0
A33: BO HOA DONG TIEN HN | D33: =B33*C33 -> 0
A34: BO HOA LOA KEN | D34: =B34*C34 -> 0
A35: BO HOA PHANG | D35: =B35*C35 -> 0
A36: BO HOA SEN QUAN AM | D36: =B36*C36 -> 0
A37: BO HOA SEN SUPER | D37: =B37*C37 -> 0
A38: BƠ SÁP | B38: =116+8+15 -> 139 | C38: 11000 | D38: =B38*C38 -> 1529000
A39: BÓ XÔI | D39: =B39*C39 -> 0
A40: BÓ XÔI 300G VR | D40: =B40*C40 -> 0
A41: BÓ XÔI-NA | D41: =B41*C41 -> 0
...

Sheet 27.6
A1: hàng tồn cuối ngày 27/6 vr
A2: TÊN SẢN PHẨM | B2: TỒN TRƯỚC | C2: GIÁ NHẬP | D2: THÀNH TIỀN
A3: CÀ CHUA SÔCOLA 250GR (HỘP) VR | D3: =B3*C3 -> 0
A4: CÀ CHUA SÔCOLA 250GR (KG) -NA | D4: =B4*C4 -> 0
A5: CÀ CHUA SÔCOLA 250GR (KG) VR | D5: =B5*C5 -> 0
A6: CÀ CHUA SÔCOLA 250GR(KG) KQ | D6: =B6*C6 -> 0
A7: CÀ CHUA SÔCOLA 300GR (HỘP) VR | D7: =B7*C7 -> 0
A8: CÀ CHUA SOCOLA XÁ | D8: =B8*C8 -> 0
A9: CÀ CHUA SÔCOLA(HỘP) KQ | D9: =B9*C9 -> 0
A10: CÀ RỐT BABY | D10: =B10*C10 -> 0
A11: CÀ RỐT BABY (KG) KQ | D11: =B11*C11 -> 0
A12: CÀ RỐT BABY 200GR | D12: =B12*C12 -> 0
A13: CẢI CẦU VỒNG | D13: =B13*C13 -> 0
A14: CẢI CẦU VỒNG 300GR | D14: =B14*C14 -> 0
... A23: ỚT CHUÔNG 3 MÀU(KG)VR | D23: =B23*C23 -> 0
A24: ỚT CHUÔNG ĐỎ | B24: =20+40+25+20 -> 105 | C24: 26000 | D24: =B24*C24 -> 2730000
A25: ỚT CHUÔNG ĐỎ L1 | D25: =B25*C25 -> 0
A26: ỚT CHUÔNG ĐỎ(TRÁI) | D26: =B26*C26 -> 0
A27: ỚT CHUÔNG 3 MÀU 350G | D27: =B27*C27 -> 0
A28: ỚT CHUÔNG 3 MÀU KQ(KG) | D28: =B28*C28 -> 0
A29: ỚT CHUÔNG VÀNG | B29: =120+5+40+38+20 -> 223 | C29: 36000 | D29: =B29*C29 -> 8028000
A30: ỚT CHUÔNG VÀNG L1 | D30: =B30*C30 -> 0
A31: ỚT CHUÔNG VÀNG(TRÁI) | D31: =B31*C31 -> 0
A32: ỚT CHUÔNG VÀNG+ XANH (VỈ) | D32: =B32*C32 -> 0
A33: ỚT CHUÔNG XANH | B33: 26 | C33: 22000 | D33: =B33*C33 -> 572000
A34: ỚT CHUÔNG XANH L1 | D34: =B34*C34 -> 0
A35: ỚT CHUÔNG XANH(TRÁI) | D35: =B35*C35 -> 0
A36: CỦ DỀN | D36: =B36*C36 -> 0
A37: CỦ DỀN 600G | D37: =B37*C37 -> 0
A38: GỪNG 250GR | D38: =B38*C38 -> 0
A39: HỒNG GIÒN | D39: =B39*C39 -> 0
A40: XÀ LÁCH MỸ | D40: =B40*C40 -> 0
A41: KHOAI TÂY HỒNG | D41: =B41*C41 -> 0
A42: KHOAI TÂY HỒNG TÚI LƯỚI 500G | D42: =B42*C42 -> 0
A43: KHOAI TÂY VÀNG | D43: =B43*C43 -> 0
A44: KHOAI TÂY VÀNG ĐL | D44: =B44*C44 -> 0
A45: KHOAI TÂY VÀNG LỚN TÚI LƯỚI 500G | D45: =B45*C45 -> 0
A46: KHOAI TÂY VÀNG TRUNG TÚI LƯỚI 500G | B46: 180 | C46: 16000 | D46: =B46*C46 -> 2880000
A47: CẢI THẢO DL | D47: =B47*C47 -> 0
A48: CẢI THẢO DL(BẮP) | D48: =B48*C48 -> 0
...

Sheet 28.6
A1: hàng tồn cuối ngày 28/6 vr
A2: TÊN SẢN PHẨM | B2: TỒN TRƯỚC | C2: GIÁ NHẬP | D2: THÀNH TIỀN
A3: BẮP CẢI TÍM | D3: =B3*C3 -> 0
A4: BẮP CẢI TÍM (BẮP) | D4: =B4*C4 -> 0
A5: BẮP CẢI TÍM SUSHI | D5: =B5*C5 -> 0
A6: BẮP CẢI TRẮNG | D6: =B6*C6 -> 0
A7: BẮP CẢI TRẮNG (BẮP) | D7: =B7*C7 -> 0
A8: BẮP CẢI TRẮNG MỘC CHÂU | D8: =B8*C8 -> 0
A9: BẮP CẢI TRẮNG SÓI BIỂN | D9: =B9*C9 -> 0
A10: BẮP CẢI TRẮNG SUSHI | D10: =B10*C10 -> 0
A11: BẮP MỸ CẶP | D11: =B11*C11 -> 0
A12: BẦU | D12: =B12*C12 -> 0
A13: BÍ ĐAO XANH | D13: =B13*C13 -> 0
A14: BÍ ĐAO XANH 400G | D14: =B14*C14 -> 0
A15: BÍ ĐỎ HỒ LÔ | B15: =15+17 -> 32 | C15: 18000 | D15: =B15*C15 -> 576000
A16: BÍ ĐỎ MINI | D16: =B16*C16 -> 0
A17: BÍ ĐỎ NON (KG)KQ | D17: =B17*C17 -> 0
A18: BÍ ĐỎ NON TRÁI VR | B18: =16+28+50+22 -> 116 | C18: 4000 | D18: =B18*C18 -> 464000
A19: BÍ ĐỎ NON( KG) VR | D19: =B19*C19 -> 0
A20: BÍ ĐỎ TRÒN | B20: 160 | C20: 13000 | D20: =B20*C20 -> 2080000
A21: BÍ MINI VÀNG 300GR | D21: =B21*C21 -> 0
A22: BÍ MINI VÀNG KG | D22: =B22*C22 -> 0
A23: BÍ NGÒI VÀNG | D23: =B23*C23 -> 0
A24: BÍ NGÒI VÀNG (TRÁI) | D24: =B24*C24 -> 0
A25: BÍ NGÒI XANH | B25: =22+55+60+35+30 -> 202 | C25: 12500 | D25: =B25*C25 -> 2525000
A26: BÍ NGÒI XANH(TRÁI) | D26: =B26*C26 -> 0
A27: BÍ NHẬT | D27: =B27*C27 -> 0
A28: BƠ 034 | D28: =B28*C28 -> 0
A29: BƠ 034 COOP | B29: 40 | C29: 12500 | D29: =B29*C29 -> 500000
A30: BƠ BOOTH | D30: =B30*C30 -> 0
A31: BO HOA CHUONG | D31: =B31*C31 -> 0
A32: BO HOA CUC TANA | D32: =B32*C32 -> 0
A33: BO HOA DONG TIEN HN | D33: =B33*C33 -> 0
A34: BO HOA LOA KEN | D34: =B34*C34 -> 0
A35: BO HOA PHANG | D35: =B35*C35 -> 0
A36: BO HOA SEN QUAN AM | D36: =B36*C36 -> 0
A37: BO HOA SEN SUPER | D37: =B37*C37 -> 0
A38: BƠ SÁP | B38: 22 | C38: 11000 | D38: =B38*C38 -> 242000
A39: BÓ XÔI | D39: =B39*C39 -> 0
A40: BÓ XÔI 300G VR | D40: =B40*C40 -> 0
...

Sheet 29.6
A1: hàng tồn cuối ngày 29/6 vr
A2: TÊN SẢN PHẨM | B2: TỒN TRƯỚC | C2: GIÁ NHẬP | D2: Tồn kho an toàn tại ĐL
A4: BẮP CẢI TÍM | D4: =B4*C4 -> 0
A5: BẮP CẢI TÍM (BẮP) | D5: =B5*C5 -> 0
A6: BẮP CẢI TÍM SUSHI | D6: =B6*C6 -> 0
A7: BẮP CẢI TRẮNG | D7: =B7*C7 -> 0
A8: BẮP CẢI TRẮNG (BẮP) | D8: =B8*C8 -> 0
A9: BẮP CẢI TRẮNG MỘC CHÂU | D9: =B9*C9 -> 0
A10: BẮP CẢI TRẮNG SÓI BIỂN | D10: =B10*C10 -> 0
A11: BẮP CẢI TRẮNG SUSHI | D11: =B11*C11 -> 0
A12: BẮP MỸ CẶP | D12: =B12*C12 -> 0
A13: BẦU | D13: =B13*C13 -> 0
A14: BÍ ĐAO XANH | D14: =B14*C14 -> 0
A15: BÍ ĐAO XANH 400G | D15: =B15*C15 -> 0
A16: BÍ ĐỎ HỒ LÔ | B16: 15 | C16: 18000 | D16: =B16*C16 -> 270000
A17: BÍ ĐỎ MINI | D17: =B17*C17 -> 0
A18: BÍ ĐỎ NON (KG)KQ | D18: =B18*C18 -> 0
A19: BÍ ĐỎ NON TRÁI VR | D19: =B19*C19 -> 0
A20: BÍ ĐỎ NON( KG) VR | D20: =B20*C20 -> 0
A21: BÍ ĐỎ TRÒN | B21: 100 | C21: 13000 | D21: =B21*C21 -> 1300000
A22: BÍ MINI VÀNG 300GR | D22: =B22*C22 -> 0
A23: BÍ MINI VÀNG KG | D23: =B23*C23 -> 0
A24: BÍ NGÒI VÀNG | D24: =B24*C24 -> 0
A25: BÍ NGÒI VÀNG (TRÁI) | D25: =B25*C25 -> 0
A26: BÍ NGÒI XANH | B26: 200 | C26: 13000 | D26: =B26*C26 -> 2600000
A27: BÍ NGÒI XANH(TRÁI) | D27: =B27*C27 -> 0
A28: BÍ NHẬT | D28: =B28*C28 -> 0
A29: BƠ 034 | D29: =B29*C29 -> 0
A30: BƠ 034 COOP | D30: =B30*C30 -> 0
A31: BƠ BOOTH | D31: =B31*C31 -> 0
A32: BO HOA CHUONG | D32: =B32*C32 -> 0
A33: BO HOA CUC TANA | D33: =B33*C33 -> 0
A34: BO HOA DONG TIEN HN | D34: =B34*C34 -> 0
A35: BO HOA LOA KEN | D35: =B35*C35 -> 0
A36: BO HOA PHANG | D36: =B36*C36 -> 0
A37: BO HOA SEN QUAN AM | D37: =B37*C37 -> 0
A38: BO HOA SEN SUPER | D38: =B38*C38 -> 0
A39: BƠ SÁP | B39: 20 | C39: 11000 | D39: =B39*C39 -> 220000
A40: BÓ XÔI | D40: =B40*C40 -> 0
A41: BÓ XÔI 300G VR | D41: =B41*C41 -> 0
...

Sheet 30.6
A1: 45473
A2: TÊN SẢN PHẨM VR | B2: ĐVT | C2: TỒN TRƯỚC | D2: GIÁ NHẬP | E2: THÀNH TIỀN
A4: BẮP CẢI TÍM | B4: Kg | C4: 22 | D4: 16000 | E4: =+D4*C4 -> 352000
A5: BẮP CẢI TÍM (BẮP) | B5: BẮP
A6: BẮP CẢI TÍM SUSHI | B6: Kg
A7: BẮP CẢI TRẮNG | B7: Kg
A8: BẮP CẢI TRẮNG (BẮP) | B8: BẮP
A9: BẮP CẢI TRẮNG MỘC CHÂU | B9: Kg
A10: BẮP CẢI TRẮNG SÓI BIỂN | B10: Kg
A11: BẮP CẢI TRẮNG SUSHI | B11: Kg
A12: BẮP MỸ CẶP | B12: CẶP
A13: BẦU | B13: Kg
A14: BÍ ĐAO XANH | B14: Kg
A15: BÍ ĐAO XANH 400G | B15: TRÁI
A16: BÍ ĐỎ HỒ LÔ | B16: Kg | C16: 3 | D16: 18000 | E16: =+D16*C16 -> 54000
A17: BÍ ĐỎ MINI | B17: Kg
A18: BÍ ĐỎ NON (KG)KQ | B18: Kg
A19: BÍ ĐỎ NON TRÁI VR | B19: TRÁI | C19: 74 | D19: 4000 | E19: =+D19*C19 -> 296000
A20: BÍ ĐỎ NON( KG) VR | B20: Kg
A21: BÍ ĐỎ TRÒN | B21: Kg | C21: 100 | D21: 13000 | E21: =+D21*C21 -> 1300000
A22: BÍ MINI VÀNG 300GR | B22: TRÁI
A23: BÍ MINI VÀNG KG | B23: Kg
A24: BÍ NGÒI VÀNG | B24: Kg
A25: BÍ NGÒI VÀNG (TRÁI) | B25: TRÁI
A26: BÍ NGÒI XANH | B26: Kg | C26: 122 | D26: 13000 | E26: =+D26*C26 -> 1586000
A27: BÍ NGÒI XANH(TRÁI) | B27: TRÁI
A28: BÍ NHẬT | B28: Kg
A29: BƠ 034 | B29: Kg | C29: 39 | D29: 12500 | E29: =+D29*C29 -> 487500
A30: BƠ 034 COOP | B30: Kg
A31: BƠ BOOTH | B31: Kg
A32: BO HOA CHUONG | B32: BÓ
A33: BO HOA CUC TANA | B33: BÓ
A34: BO HOA DONG TIEN HN | B34: BÓ
A35: BO HOA LOA KEN | B35: BÓ
A36: BO HOA PHANG | B36: BÓ
A37: BO HOA SEN QUAN AM | B37: BÓ
A38: BO HOA SEN SUPER | B38: BÓ
A39: BƠ SÁP | B39: Kg | C39: 47 | D39: 11000 | E39: =+D39*C39 -> 517000
A40: BÓ XÔI | B40: Kg
A41: BÓ XÔI 300G VR | B41: TÚI
...
