Workbook

Sheet 1.2
A1: hàng tồn cuối ngày 1/2
A2: TÊN HÀNG | B2: TỒN TRƯỚC | C2: GIÁ NHẬP | D2: THÀNH TIỀN
A3: CÀ CHUA SÔCOLA 250GR (HỘP) VR | D3: =B3*C3 -> 0
A4: CÀ CHUA SÔCOLA 250GR (KG) -NA | D4: =B4*C4 -> 0
A5: BẮP CẢI TÍM | B5: =18+18+5 -> 41 | C5: 17000 | D5: =B5*C5 -> 697000
A6: CÀ CHUA SÔCOLA 250GR(KG) KQ | D6: =B6*C6 -> 0
A7: CÀ CHUA SÔCOLA 300GR (HỘP) VR | D7: =B7*C7 -> 0
A8: CÀ CHUA SOCOLA XÁ | D8: =B8*C8 -> 0
A9: CÀ CHUA SÔCOLA(HỘP) KQ | D9: =B9*C9 -> 0
A10: CÀ RỐT BABY | D10: =B10*C10 -> 0
A11: CÀ RỐT BABY (KG) KQ | D11: =B11*C11 -> 0
A12: BẮP CẢI TRẮNG | B12: 90 | C12: 6500 | D12: =B12*C12 -> 585000
A13: CẢI CẦU VỒNG | D13: =B13*C13 -> 0
A14: BẦU | D14: =B14*C14 -> 0
A15: CẢI KALE | D15: =B15*C15 -> 0
A16: BÍ ĐAO XANH | B16: 4 | C16: 18000 | D16: =B16*C16 -> 72000
A17: CHANH VÀNG (KG) | D17: =B17*C17 -> 0
A18: CHANH VÀNG TRÁI 180UP | D18: =B18*C18 -> 0
A19: BÍ ĐỎ HỒ LÔ | B19: 12 | C19: 10000 | D19: =B19*C19 -> 120000
A20: CẦN TÂY THUỶ CANH | D20: =B20*C20 -> 0
A21: CẦN TÂY(CÂY) | D21: =B21*C21 -> 0
A22: ỚT CHUÔNG 3 MÀU(KG)VR | D22: =B22*C22 -> 0
A23: BÍ ĐỎ NON( KG) VR | D23: =B23*C23 -> 0
A24: ỚT CHUÔNG ĐỎ L1 | D24: =B24*C24 -> 0
A25: ỚT CHUÔNG ĐỎ(TRÁI) | D25: =B25*C25 -> 0
A26: ỚT CHUÔNG 3 MÀU 350G | B26: =15+55 -> 70 | C26: 15000 | D26: =B26*C26 -> 1050000
A27: ỚT CHUÔNG 3 MÀU KQ(KG) | D27: =B27*C27 -> 0
A28: BÍ ĐỎ TRÒN | B28: =650+60+30+690 -> 1430 | C28: 6000 | D28: =B28*C28 -> 8580000
A29: ỚT CHUÔNG VÀNG L1 | D29: =B29*C29 -> 0
A30: ỚT CHUÔNG VÀNG(TRÁI) | D30: =B30*C30 -> 0
A31: ỚT CHUÔNG VÀNG+ XANH (VỈ) | D31: =B31*C31 -> 0
A32: BÍ NGÒI XANH | B32: =15+20+50 -> 85 | C32: 10000 | D32: =B32*C32 -> 850000
A33: ỚT CHUÔNG XANH L1 | D33: =B33*C33 -> 0
A34: ỚT CHUÔNG XANH(TRÁI) | D34: =B34*C34 -> 0
A35: BƠ BOOTH | D35: =B35*C35 -> 0
A36: CỦ DỀN 600G | D36: =B36*C36 -> 0
A37: GỪNG 250GR | D37: =B37*C37 -> 0
A38: BÓ XÔI | D38: =B38*C38 -> 0
A39: XÀ LÁCH MỸ | B39: 15 | C39: 10000 | D39: =B39*C39 -> 150000
A40: KHOAI TÂY HỒNG | B40: 6 | C40: 19000 | D40: =B40*C40 -> 114000
...

Sheet 2.2
A1: hàng tồn cuối ngày 2/2
A2: TÊN SẢN PHẨM | B2: TỒN TRƯỚC | C2: GIÁ NHẬP | D2: THÀNH TIỀN
A3: CÀ CHUA SÔCOLA 250GR (HỘP) VR | D3: =B3*C3 -> 0
A4: CÀ CHUA SÔCOLA 250GR (KG) -NA | D4: =B4*C4 -> 0
A5: CÀ CHUA SÔCOLA 250GR (KG) VR | D5: =B5*C5 -> 0
A6: CÀ CHUA SÔCOLA 250GR(KG) KQ | D6: =B6*C6 -> 0
A7: CÀ CHUA SÔCOLA 300GR (HỘP) VR | D7: =B7*C7 -> 0
A8: CÀ CHUA SOCOLA XÁ | D8: =B8*C8 -> 0
A9: CÀ CHUA SÔCOLA(HỘP) KQ | D9: =B9*C9 -> 0
A10: CÀ RỐT BABY | D10: =B10*C10 -> 0
A11: CÀ RỐT BABY (KG) KQ | D11: =B11*C11 -> 0
A12: CÀ RỐT BABY 200GR | D12: =B12*C12 -> 0
A13: CẢI CẦU VỒNG | D13: =B13*C13 -> 0
A14: CẢI CẦU VỒNG 300GR | D14: =B14*C14 -> 0
A15: CẢI KALE | D15: =B15*C15 -> 0
A16: BẮP CẢI TÍM | B16: 7 | C16: 17000 | D16: =B16*C16 -> 119000
A17: CHANH VÀNG (KG) | D17: =B17*C17 -> 0
A18: CHANH VÀNG TRÁI 180UP | D18: =B18*C18 -> 0
A19: CẦN TÂY (KG) | D19: =B19*C19 -> 0
A20: CẦN TÂY THUỶ CANH | D20: =B20*C20 -> 0
A21: CẦN TÂY(CÂY) | D21: =B21*C21 -> 0
A22: ỚT CHUÔNG 3 MÀU(KG)VR | D22: =B22*C22 -> 0
A23: BẮP CẢI TRẮNG | B23: 36 | C23: 6500 | D23: =B23*C23 -> 234000
A24: ỚT CHUÔNG ĐỎ L1 | D24: =B24*C24 -> 0
A25: ỚT CHUÔNG ĐỎ(TRÁI) | D25: =B25*C25 -> 0
A26: BÍ ĐAO XANH | B26: 5 | C26: 18000 | D26: =B26*C26 -> 90000
A27: ỚT CHUÔNG 3 MÀU KQ(KG) | D27: =B27*C27 -> 0
A28: BÍ ĐỎ HỒ LÔ | B28: 9 | C28: 10000 | D28: =B28*C28 -> 90000
A29: ỚT CHUÔNG VÀNG L1 | D29: =B29*C29 -> 0
A30: ỚT CHUÔNG VÀNG(TRÁI) | D30: =B30*C30 -> 0
A31: ỚT CHUÔNG VÀNG+ XANH (VỈ) | D31: =B31*C31 -> 0
A32: BÍ ĐỎ NON TRÁI VR | B32: =20+17 -> 37 | C32: 4000 | D32: =B32*C32 -> 148000
A33: ỚT CHUÔNG XANH L1 | D33: =B33*C33 -> 0
A34: ỚT CHUÔNG XANH(TRÁI) | D34: =B34*C34 -> 0
A35: BÍ ĐỎ TRÒN | B35: =2220+1260 -> 3480 | C35: 6000 | D35: =B35*C35 -> 20880000
A36: CỦ DỀN 600G | D36: =B36*C36 -> 0
A37: GỪNG 250GR | D37: =B37*C37 -> 0
A38: HỒNG GIÒN | D38: =B38*C38 -> 0
A39: XÀ LÁCH MỸ | D39: =B39*C39 -> 0
A40: BÍ NGÒI VÀNG | B40: 1 | C40: 28000 | D40: =B40*C40 -> 28000
...

Sheet 3.2
A2: TÊN SẢN PHẨM | B2: ĐVT | C2: TỒN TRƯỚC | D2: GIÁ NHẬP | E2: THÀNH TIỀN | F2: TEM KQ KHO | G2: LÁ KQ KHO | H2: DATE | I2: KG/ KHAY
A4: BẮP CẢI TÍM | B4: Kg | H4: 0 | I4: 10
A5: BẮP CẢI TÍM (BẮP) | B5: BẮP | H5: 0 | I5: 10
A6: BẮP CẢI TÍM SUSHI | B6: Kg | H6: 0 | I6: 10
A7: BẮP CẢI TRẮNG | B7: Kg | C7: 100 | D7: =_xlfn.IFNA(VLOOKUP(A7,'2.2'!A16:C308,3,),) -> 6500 | E7: =+D7*C7 -> 650000 | H7: 0 | I7: 12
A8: BẮP CẢI TRẮNG (BẮP) | B8: BẮP | D8: =_xlfn.IFNA(VLOOKUP(A8,'2.2'!A17:C309,3,),) -> 0 | H8: 0 | I8: 12
A9: BẮP CẢI TRẮNG MỘC CHÂU | B9: Kg | D9: =_xlfn.IFNA(VLOOKUP(A9,'2.2'!A18:C310,3,),) -> 0 | H9: 0 | I9: 20
A10: BẮP CẢI TRẮNG SUSHI | B10: Kg | D10: =_xlfn.IFNA(VLOOKUP(A10,'2.2'!A19:C311,3,),) -> 0 | H10: 0 | I10: 12
A11: BẮP MỸ | B11: Kg | D11: =_xlfn.IFNA(VLOOKUP(A11,'2.2'!A20:C312,3,),) -> 0 | H11: 0 | I11: 20
A12: BẦU | B12: Kg | D12: =_xlfn.IFNA(VLOOKUP(A12,'2.2'!A21:C313,3,),) -> 0 | H12: 0 | I12: 20
A13: BÍ ĐAO XANH | B13: Kg | C13: 5 | D13: =_xlfn.IFNA(VLOOKUP(A13,'2.2'!A22:C314,3,),) -> 18000 | E13: =+D13*C13 -> 90000 | H13: 0 | I13: 20
A14: BÍ ĐAO XANH 400G | B14: TRÁI | D14: =_xlfn.IFNA(VLOOKUP(A14,'2.2'!A23:C315,3,),) -> 0 | H14: 0 | I14: 15
A15: BÍ ĐỎ HỒ LÔ | B15: Kg | C15: 36 | D15: =_xlfn.IFNA(VLOOKUP(A15,'2.2'!A24:C316,3,),) -> 10000 | E15: =+D15*C15 -> 360000 | H15: 0 | I15: 15
A16: BÍ ĐỎ MINI | B16: Kg | D16: =_xlfn.IFNA(VLOOKUP(A16,'2.2'!A25:C317,3,),) -> 0 | H16: 0
A17: BÍ ĐỎ NON (KG)KQ | B17: Kg | D17: =_xlfn.IFNA(VLOOKUP(A17,'2.2'!A26:C318,3,),) -> 0 | H17: 0 | I17: 20
A18: BÍ ĐỎ NON TRÁI VR | B18: TRÁI | C18: 13 | D18: =_xlfn.IFNA(VLOOKUP(A18,'2.2'!A27:C319,3,),) -> 4000 | E18: =+D18*C18 -> 52000 | H18: 170 | I18: 20
A19: BÍ ĐỎ NON( KG) VR | B19: Kg | D19: =_xlfn.IFNA(VLOOKUP(A19,'2.2'!A28:C320,3,),) -> 0 | H19: 0 | I19: 20
A20: BÍ ĐỎ TRÒN | B20: Kg | C20: 2640 | D20: =_xlfn.IFNA(VLOOKUP(A20,'2.2'!A29:C321,3,),) -> 6000 | E20: =+D20*C20 -> 15840000 | H20: 0 | I20: 15
A21: BÍ MINI VÀNG 300GR | B21: TRÁI | D21: =_xlfn.IFNA(VLOOKUP(A21,'2.2'!A30:C322,3,),) -> 0 | H21: 0 | I21: 5
A22: BÍ MINI VÀNG KG | B22: Kg | D22: =_xlfn.IFNA(VLOOKUP(A22,'2.2'!A31:C323,3,),) -> 0 | H22: 0 | I22: 5
A23: BÍ NGÒI VÀNG | B23: Kg | D23: =_xlfn.IFNA(VLOOKUP(A23,'2.2'!A32:C324,3,),) -> 28000 | H23: 0 | I23: 20
A24: BÍ NGÒI VÀNG (TRÁI) | B24: TRÁI | D24: =_xlfn.IFNA(VLOOKUP(A24,'2.2'!A33:C325,3,),) -> 0 | H24: 0 | I24: 20
A25: BÍ NGÒI XANH | B25: Kg | C25: 125 | D25: =_xlfn.IFNA(VLOOKUP(A25,'2.2'!A34:C326,3,),) -> 10000 | E25: =+D25*C25 -> 1250000 | H25: 0 | I25: 20
A26: BÍ NGÒI XANH(TRÁI) | B26: TRÁI | D26: =_xlfn.IFNA(VLOOKUP(A26,'2.2'!A35:C327,3,),) -> 0 | H26: 253 | I26: 40
A27: BÍ NHẬT | B27: Kg | D27: =_xlfn.IFNA(VLOOKUP(A27,'2.2'!A36:C328,3,),) -> 0 | H27: 0 | I27: 15
A28: BƠ 034 | B28: Kg | D28: =_xlfn.IFNA(VLOOKUP(A28,'2.2'!A37:C329,3,),) -> 0 | H28: 0 | I28: 20
A29: BƠ BOOTH | B29: Kg | D29: =_xlfn.IFNA(VLOOKUP(A29,'2.2'!A38:C330,3,),) -> 0 | H29: 0 | I29: 20
A30: BƠ SÁP | B30: Kg | D30: =_xlfn.IFNA(VLOOKUP(A30,'2.2'!A39:C331,3,),) -> 0 | H30: 0 | I30: 20
A31: BÓ XÔI | B31: Kg | D31: =_xlfn.IFNA(VLOOKUP(A31,'2.2'!A40:C332,3,),) -> 0 | I31: 5
A32: BÓ XÔI 300G VR | B32: TÚI | D32: =_xlfn.IFNA(VLOOKUP(A32,'2.2'!A41:C333,3,),) -> 0 | H32: 190 | I32: 20
A33: BÓ XÔI-HN KQ | B33: Kg | D33: =_xlfn.IFNA(VLOOKUP(A33,'2.2'!A42:C334,3,),) -> 0 | I33: 5
A34: BÓ XÔI-NA | B34: Kg | D34: =_xlfn.IFNA(VLOOKUP(A34,'2.2'!A43:C335,3,),) -> 0 | I34: 5
A35: BÔNG ATISO | B35: Kg | D35: =_xlfn.IFNA(VLOOKUP(A35,'2.2'!A44:C336,3,),) -> 0 | H35: 0 | I35: 10
A36: BÔNG BÍ | B36: Kg | D36: =_xlfn.IFNA(VLOOKUP(A36,'2.2'!A45:C337,3,),) -> 0 | H36: 0
A37: BÔNG BÍ TÚI 300GR | B37: VỈ | C37: 2 | D37: =35000*0.3 -> 10500 | E37: =+D37*C37 -> 21000 | H37: 0
A38: BÔNG CẢI TRẮNG | B38: Kg | C38: 2 | D38: =_xlfn.IFNA(VLOOKUP(A38,'2.2'!A47:C339,3,),) -> 11000 | E38: =+D38*C38 -> 22000 | F38: 84 | I38: 8
A39: BÔNG CẢI TRẮNG (CÂY) | B39: CÂY | D39: =_xlfn.IFNA(VLOOKUP(A39,'2.2'!A48:C340,3,),) -> 0 | H39: 0 | I39: 10
A40: BÔNG CẢI XANH 10P | B40: Kg | D40: =_xlfn.IFNA(VLOOKUP(A40,'2.2'!A49:C341,3,),) -> 0 | H40: 0
A41: BÔNG CẢI XANH AEON | B41: Kg | D41: =_xlfn.IFNA(VLOOKUP(A41,'2.2'!A50:C342,3,),) -> 0 | I41: 8
A42: BÔNG CẢI XANH AEON (CÂY) | B42: CÂY | D42: =_xlfn.IFNA(VLOOKUP(A42,'2.2'!A51:C343,3,),) -> 0 | H42: 133 | I42: 15
...

Sheet 4.2
A1: hàng tồn cuối ngày 4/2
A2: TÊN SẢN PHẨM | B2: TỒN TRƯỚC | C2: GIÁ NHẬP | D2: THÀNH TIỀN
A3: CÀ CHUA SÔCOLA 250GR (HỘP) VR | D3: =B3*C3 -> 0
A4: CÀ CHUA SÔCOLA 250GR (KG) -NA | D4: =B4*C4 -> 0
A5: CÀ CHUA SÔCOLA 250GR (KG) VR | D5: =B5*C5 -> 0
A6: CÀ CHUA SÔCOLA 250GR(KG) KQ | D6: =B6*C6 -> 0
A7: CÀ CHUA SÔCOLA 300GR (HỘP) VR | D7: =B7*C7 -> 0
A8: CÀ CHUA SOCOLA XÁ | D8: =B8*C8 -> 0
A9: CÀ CHUA SÔCOLA(HỘP) KQ | D9: =B9*C9 -> 0
A10: CÀ RỐT BABY | D10: =B10*C10 -> 0
A11: CÀ RỐT BABY (KG) KQ | D11: =B11*C11 -> 0
A12: CÀ RỐT BABY 200GR | B12: 5 | C12: 6000 | D12: =B12*C12 -> 30000
A13: CẢI CẦU VỒNG | D13: =B13*C13 -> 0
A14: CẢI CẦU VỒNG 300GR | B14: 3 | C14: 6000 | D14: =B14*C14 -> 18000
A15: CẢI KALE | D15: =B15*C15 -> 0
A16: CẢI KALE 300GR | B16: 10 | C16: 3000 | D16: =B16*C16 -> 30000
A17: CHANH VÀNG (KG) | B17: 15 | C17: 50000 | D17: =B17*C17 -> 750000
A18: CHANH VÀNG TRÁI 180UP | D18: =B18*C18 -> 0
A19: CẦN TÂY (KG) | B19: 42 | C19: 9000 | D19: =B19*C19 -> 378000
A20: CẦN TÂY THUỶ CANH | D20: =B20*C20 -> 0
A21: CẦN TÂY(CÂY) | D21: =B21*C21 -> 0
A22: ỚT CHUÔNG 3 MÀU(KG)VR | D22: =B22*C22 -> 0
A23: ỚT CHUÔNG ĐỎ | B23: =80+50+20+45+16 -> 211 | C23: 40000 | D23: =B23*C23 -> 8440000
A24: ỚT CHUÔNG ĐỎ L1 | B24: 20 | C24: 32000 | D24: =B24*C24 -> 640000
A25: ỚT CHUÔNG ĐỎ(TRÁI) | D25: =B25*C25 -> 0
A26: ỚT CHUÔNG 3 MÀU 350G | B26: 4 | C26: 16000 | D26: =B26*C26 -> 64000
A27: ỚT CHUÔNG 3 MÀU KQ(KG) | D27: =B27*C27 -> 0
A28: ỚT CHUÔNG VÀNG | B28: 60 | C28: 40000 | D28: =B28*C28 -> 2400000
A29: ỚT CHUÔNG VÀNG L1 | B29: 10 | C29: 32000 | D29: =B29*C29 -> 320000
A30: ỚT CHUÔNG VÀNG(TRÁI) | D30: =B30*C30 -> 0
A31: ỚT CHUÔNG VÀNG+ XANH (VỈ) | D31: =B31*C31 -> 0
A32: ỚT CHUÔNG XANH | B32: =5+6+16 -> 27 | C32: 30000 | D32: =B32*C32 -> 810000
A33: ỚT CHUÔNG XANH L1 | B33: 10 | C33: 23000 | D33: =B33*C33 -> 230000
A34: ỚT CHUÔNG XANH(TRÁI) | D34: =B34*C34 -> 0
A35: CỦ DỀN | B35: =12+70 -> 82 | C35: 10000 | D35: =B35*C35 -> 820000
A36: CỦ DỀN 600G | D36: =B36*C36 -> 0
A37: GỪNG 250GR | D37: =B37*C37 -> 0
A38: HỒNG GIÒN | D38: =B38*C38 -> 0
A39: XÀ LÁCH MỸ | D39: =B39*C39 -> 0
A40: KHOAI TÂY HỒNG | B40: 6 | C40: 19000 | D40: =B40*C40 -> 114000
...

Sheet 5.2
A1: hàng tồn cuối ngày 5/2
A2: TÊN SẢN PHẨM | B2: TỒN TRƯỚC | C2: GIÁ NHẬP | D2: THÀNH TIỀN
A3: CÀ CHUA SÔCOLA 250GR (HỘP) VR | B3: 4 | C3: 5000 | D3: =B3*C3 -> 20000
A4: CÀ CHUA SÔCOLA 250GR (KG) -NA | D4: =B4*C4 -> 0
A5: CÀ CHUA SÔCOLA 250GR (KG) VR | D5: =B5*C5 -> 0
A6: CÀ CHUA SÔCOLA 250GR(KG) KQ | D6: =B6*C6 -> 0
A7: CÀ CHUA SÔCOLA 300GR (HỘP) VR | D7: =B7*C7 -> 0
A8: CÀ CHUA SOCOLA XÁ | D8: =B8*C8 -> 0
A9: CÀ CHUA SÔCOLA(HỘP) KQ | D9: =B9*C9 -> 0
A10: CÀ RỐT BABY | D10: =B10*C10 -> 0
A11: CÀ RỐT BABY (KG) KQ | D11: =B11*C11 -> 0
A12: CÀ RỐT BABY 200GR | D12: =B12*C12 -> 0
A13: CẢI CẦU VỒNG | D13: =B13*C13 -> 0
A14: CẢI CẦU VỒNG 300GR | D14: =B14*C14 -> 0
A15: CẢI KALE | D15: =B15*C15 -> 0
A16: CẢI KALE 300GR | B16: =10+3 -> 13 | C16: 3000 | D16: =B16*C16 -> 39000
A17: CHANH VÀNG (KG) | D17: =B17*C17 -> 0
A18: CHANH VÀNG TRÁI 180UP | D18: =B18*C18 -> 0
A19: CẦN TÂY (KG) | B19: 36 | C19: 9000 | D19: =B19*C19 -> 324000
A20: CẦN TÂY THUỶ CANH | D20: =B20*C20 -> 0
A21: CẦN TÂY(CÂY) | D21: =B21*C21 -> 0
A22: ỚT CHUÔNG 3 MÀU(KG)VR | D22: =B22*C22 -> 0
A23: ỚT CHUÔNG ĐỎ | B23: =12+20+140 -> 172 | C23: 40000 | D23: =B23*C23 -> 6880000
A24: ỚT CHUÔNG ĐỎ L1 | B24: 10 | C24: 34000 | D24: =B24*C24 -> 340000
A25: ỚT CHUÔNG ĐỎ(TRÁI) | D25: =B25*C25 -> 0
A26: ỚT CHUÔNG 3 MÀU 350G | B26: =25+15 -> 40 | C26: 13000 | D26: =B26*C26 -> 520000
A27: ỚT CHUÔNG 3 MÀU KQ(KG) | D27: =B27*C27 -> 0
A28: ỚT CHUÔNG VÀNG | B28: =10+40+50 -> 100 | C28: 40000 | D28: =B28*C28 -> 4000000
A29: ỚT CHUÔNG VÀNG L1 | B29: 20 | C29: 34000 | D29: =B29*C29 -> 680000
A30: ỚT CHUÔNG VÀNG(TRÁI) | D30: =B30*C30 -> 0
A31: ỚT CHUÔNG VÀNG+ XANH (VỈ) | D31: =B31*C31 -> 0
A32: ỚT CHUÔNG XANH | B32: =6+15+125 -> 146 | C32: 30000 | D32: =B32*C32 -> 4380000
A33: ỚT CHUÔNG XANH L1 | B33: 20 | C33: 23000 | D33: =B33*C33 -> 460000
A34: ỚT CHUÔNG XANH(TRÁI) | D34: =B34*C34 -> 0
A35: CỦ DỀN | B35: =55+20+50 -> 125 | C35: 10000 | D35: =B35*C35 -> 1250000
A36: CỦ DỀN 600G | D36: =B36*C36 -> 0
A37: GỪNG 250GR | D37: =B37*C37 -> 0
A38: HỒNG GIÒN | D38: =B38*C38 -> 0
A39: XÀ LÁCH MỸ | D39: =B39*C39 -> 0
A40: KHOAI TÂY HỒNG | D40: =B40*C40 -> 0
...

Sheet 6.2
A1: hàng tồn cuối ngày 6/2
A2: TÊN SẢN PHẨM | B2: TỒN TRƯỚC | C2: GIÁ NHẬP | D2: THÀNH TIỀN
A3: CÀ CHUA SÔCOLA 250GR (HỘP) VR | D3: =B3*C3 -> 0
A4: CÀ CHUA SÔCOLA 250GR (KG) -NA | D4: =B4*C4 -> 0
A5: CÀ CHUA SÔCOLA 250GR (KG) VR | D5: =B5*C5 -> 0
A6: CÀ CHUA SÔCOLA 250GR(KG) KQ | D6: =B6*C6 -> 0
A7: CÀ CHUA SÔCOLA 300GR (HỘP) VR | D7: =B7*C7 -> 0
A8: CÀ CHUA SOCOLA XÁ | D8: =B8*C8 -> 0
A9: CÀ CHUA SÔCOLA(HỘP) KQ | D9: =B9*C9 -> 0
A10: CÀ RỐT BABY | D10: =B10*C10 -> 0
A11: CÀ RỐT BABY (KG) KQ | D11: =B11*C11 -> 0
A12: CÀ RỐT BABY 200GR | D12: =B12*C12 -> 0
A13: CẢI CẦU VỒNG | D13: =B13*C13 -> 0
A14: CẢI CẦU VỒNG 300GR | D14: =B14*C14 -> 0
... A18: CHANH VÀNG TRÁI 180UP | D18: =B18*C18 -> 0
A19: CẦN TÂY (KG) | B19: 57 | C19: 9000 | D19: =B19*C19 -> 513000
A20: CẦN TÂY THUỶ CANH | D20: =B20*C20 -> 0
A21: CẦN TÂY(CÂY) | D21: =B21*C21 -> 0
A22: ỚT CHUÔNG 3 MÀU(KG)VR | D22: =B22*C22 -> 0
A23: ỚT CHUÔNG ĐỎ | B23: =35+30+10+130+35+30+10+15+200+80+80 -> 655 | C23: 42000 | D23: =B23*C23 -> 27510000
A24: ỚT CHUÔNG ĐỎ L1 | D24: =B24*C24 -> 0
A25: ỚT CHUÔNG ĐỎ(TRÁI) | D25: =B25*C25 -> 0
A26: ỚT CHUÔNG 3 MÀU 350G | B26: 34 | C26: 15000 | D26: =B26*C26 -> 510000
A27: ỚT CHUÔNG 3 MÀU KQ(KG) | D27: =B27*C27 -> 0
A28: ỚT CHUÔNG VÀNG | B28: =30+20+40+8+40+10+15 -> 163 | C28: 40000 | D28: =B28*C28 -> 6520000
A29: ỚT CHUÔNG VÀNG L1 | D29: =B29*C29 -> 0
A30: ỚT CHUÔNG VÀNG(TRÁI) | D30: =B30*C30 -> 0
A31: ỚT CHUÔNG VÀNG+ XANH (VỈ) | D31: =B31*C31 -> 0
A32: ỚT CHUÔNG XANH | B32: =310+90 -> 400 | C32: 30000 | D32: =B32*C32 -> 12000000
A33: ỚT CHUÔNG XANH L1 | D33: =B33*C33 -> 0
A34: ỚT CHUÔNG XANH(TRÁI) | D34: =B34*C34 -> 0
A35: CỦ DỀN | B35: =78+10+20+20 -> 128 | C35: 10000 | D35: =B35*C35 -> 1280000
A36: CỦ DỀN 600G | D36: =B36*C36 -> 0
A37: GỪNG 250GR | D37: =B37*C37 -> 0
A38: HỒNG GIÒN | D38: =B38*C38 -> 0
A39: XÀ LÁCH MỸ | D39: =B39*C39 -> 0
A40: KHOAI TÂY HỒNG | B40: 20 | C40: 19000 | D40: =B40*C40 -> 380000
A41: KHOAI TÂY HỒNG TÚI LƯỚI 500G | D41: =B41*C41 -> 0
A42: KHOAI TÂY VÀNG | D42: =B42*C42 -> 0
A43: KHOAI TÂY VÀNG ĐL | D43: =B43*C43 -> 0
...

Sheet 7.2
A1: hàng tồn cuối ngày 7/2
A2: TÊN SẢN PHẨM | B2: TỒN TRƯỚC | C2: GIÁ NHẬP | D2: THÀNH TIỀN
A3: CÀ CHUA SÔCOLA 250GR (HỘP) VR | B3: 0 | D3: =B3*C3 -> 0
A4: CÀ CHUA SÔCOLA 250GR (KG) -NA | D4: =B4*C4 -> 0
A5: CÀ CHUA SÔCOLA 250GR (KG) VR | D5: =B5*C5 -> 0
A6: CÀ CHUA SÔCOLA 250GR(KG) KQ | D6: =B6*C6 -> 0
A7: CÀ CHUA SÔCOLA 300GR (HỘP) VR | D7: =B7*C7 -> 0
A8: CÀ CHUA SOCOLA XÁ | D8: =B8*C8 -> 0
A9: CÀ CHUA SÔCOLA(HỘP) KQ | D9: =B9*C9 -> 0
A10: CÀ RỐT BABY | D10: =B10*C10 -> 0
A11: CÀ RỐT BABY (KG) KQ | D11: =B11*C11 -> 0
A12: CÀ RỐT BABY 200GR | D12: =B12*C12 -> 0
A13: CẢI CẦU VỒNG | D13: =B13*C13 -> 0
A14: CẢI CẦU VỒNG 300GR | D14: =B14*C14 -> 0
A15: CẢI KALE | D15: =B15*C15 -> 0
... A18: CHANH VÀNG TRÁI 180UP | D18: =B18*C18 -> 0
A19: CẦN TÂY (KG) | B19: 105 | C19: 9000 | D19: =B19*C19 -> 945000
A20: CẦN TÂY THUỶ CANH | D20: =B20*C20 -> 0
A21: CẦN TÂY(CÂY) | B21: 0 | D21: =B21*C21 -> 0
A22: ỚT CHUÔNG 3 MÀU(KG)VR | D22: =B22*C22 -> 0
A23: ỚT CHUÔNG ĐỎ | B23: =60+65+85+150 -> 360 | C23: 40000 | D23: =B23*C23 -> 14400000
A24: ỚT CHUÔNG ĐỎ L1 | B24: 32 | C24: 24000 | D24: =B24*C24 -> 768000
A25: ỚT CHUÔNG ĐỎ(TRÁI) | B25: 0 | D25: =B25*C25 -> 0
A26: ỚT CHUÔNG 3 MÀU 350G | B26: 45 | C26: 15000 | D26: =B26*C26 -> 675000
A27: ỚT CHUÔNG 3 MÀU KQ(KG) | D27: =B27*C27 -> 0
A28: ỚT CHUÔNG VÀNG | B28: =45+40+55+65+45+60 -> 310 | C28: 40000 | D28: =B28*C28 -> 12400000
A29: ỚT CHUÔNG VÀNG L1 | B29: 31 | C29: 24000 | D29: =B29*C29 -> 744000
A30: ỚT CHUÔNG VÀNG(TRÁI) | D30: =B30*C30 -> 0
A31: ỚT CHUÔNG VÀNG+ XANH (VỈ) | D31: =B31*C31 -> 0
A32: ỚT CHUÔNG XANH | B32: =20+20+100+120+30 -> 290 | C32: 30000 | D32: =B32*C32 -> 8700000
A33: ỚT CHUÔNG XANH L1 | D33: =B33*C33 -> 0
A34: ỚT CHUÔNG XANH(TRÁI) | D34: =B34*C34 -> 0
A35: CỦ DỀN | B35: 123 | C35: 10000 | D35: =B35*C35 -> 1230000
A36: CỦ DỀN 600G | D36: =B36*C36 -> 0
A37: GỪNG 250GR | D37: =B37*C37 -> 0
A38: HỒNG GIÒN | D38: =B38*C38 -> 0
A39: XÀ LÁCH MỸ | D39: =B39*C39 -> 0
A40: KHOAI TÂY HỒNG | D40: =B40*C40 -> 0
A41: KHOAI TÂY HỒNG TÚI LƯỚI 500G | D41: =B41*C41 -> 0
A42: KHOAI TÂY VÀNG | D42: =B42*C42 -> 0
...

Sheet 9.2
A1: hàng tồn cuối ngày 9/2
A2: TÊN SẢN PHẨM | B2: TỒN TRƯỚC | C2: GIÁ NHẬP | D2: THÀNH TIỀN
A3: CÀ CHUA SÔCOLA 250GR (HỘP) VR | D3: =B3*C3 -> 0
A4: CÀ CHUA SÔCOLA 250GR (KG) VR | D4: =B4*C4 -> 0
A5: BẮP CẢI TÍM SUSHI | D5: =B5*C5 -> 0
A6: CÀ CHUA SÔCOLA 300GR (HỘP) VR | D6: =B6*C6 -> 0
A7: CẢI KALE 300GR | D7: =B7*C7 -> 0
A8: BẮP CẢI TRẮNG MỘC CHÂU | D8: =B8*C8 -> 0
A9: BẮP CẢI TRẮNG SUSHI | D9: =B9*C9 -> 0
A10: BẮP MỸ | D10: =B10*C10 -> 0
A11: BẦU | D11: =B11*C11 -> 0
A12: CHANH VÀNG TRÁI 180UP | D12: =B12*C12 -> 0
A13: CẦN TÂY (KG) | D13: =B13*C13 -> 0
A14: BÍ ĐỎ HỒ LÔ | B14: 13 | C14: 10000 | D14: =B14*C14 -> 130000
A15: BÍ ĐỎ MINI | D15: =B15*C15 -> 0
A16: BÍ ĐỎ NON (KG)KQ | D16: =B16*C16 -> 0
A17: CẦN TÂY(CÂY) | D17: =B17*C17 -> 0
A18: BÍ ĐỎ NON( KG) VR | D18: =B18*C18 -> 0
A19: ỚT CHUÔNG ĐỎ | B19: =240+65 -> 305 | C19: 35000 | D19: =B19*C19 -> 10675000
A20: ỚT CHUÔNG ĐỎ(TRÁI) | D20: =B20*C20 -> 0
A21: BÍ MINI VÀNG KG | B21: 9 | C21: 70000 | D21: =B21*C21 -> 630000
A22: BÍ NGÒI VÀNG | D22: =B22*C22 -> 0
A23: BÍ NGÒI VÀNG (TRÁI) | D23: =B23*C23 -> 0
A24: ỚT CHUÔNG 3 MÀU 350G | D24: =B24*C24 -> 0
A25: ỚT CHUÔNG VÀNG | B25: =20+60+55+60 -> 195 | C25: 40000 | D25: =B25*C25 -> 7800000
A26: BÍ NHẬT | D26: =B26*C26 -> 0
A27: BƠ 034 | D27: =B27*C27 -> 0
A28: BƠ BOOTH | D28: =B28*C28 -> 0
A29: BƠ SÁP | D29: =B29*C29 -> 0
A30: ỚT CHUÔNG VÀNG(TRÁI) | D30: =B30*C30 -> 0
A31: ỚT CHUÔNG XANH | B31: =180+10+60 -> 250 | C31: 28000 | D31: =B31*C31 -> 7000000
A32: BÓ XÔI-HN KQ | D32: =B32*C32 -> 0
A33: BÓ XÔI-NA | D33: =B33*C33 -> 0
A34: BÔNG ATISO | D34: =B34*C34 -> 0
A35: BÔNG BÍ | D35: =B35*C35 -> 0
A36: BÔNG BÍ TÚI 300GR | D36: =B36*C36 -> 0
A37: ỚT CHUÔNG XANH(TRÁI) | D37: =B37*C37 -> 0
A38: CỦ DỀN | B38: =10+40+20+85 -> 155 | C38: 12000 | D38: =B38*C38 -> 1860000
A39: BÔNG CẢI XANH 10P | D39: =B39*C39 -> 0
A40: CỦ DỀN 600G | D40: =B40*C40 -> 0
...

Sheet 10.2
A1: hàng tồn cuối ngày 10/2
A2: TÊN SẢN PHẨM | B2: TỒN TRƯỚC | C2: GIÁ NHẬP | D2: THÀNH TIỀN
A4: CÀ CHUA SÔCOLA 250GR (HỘP) VR | D4: =B4*C4 -> 0
A5: CÀ CHUA SÔCOLA 250GR (KG) -NA | D5: =B5*C5 -> 0
A6: CÀ CHUA SÔCOLA 250GR (KG) VR | D6: =B6*C6 -> 0
A7: CÀ CHUA SÔCOLA 250GR(KG) KQ | D7: =B7*C7 -> 0
A8: CÀ CHUA SÔCOLA 300GR (HỘP) VR | D8: =B8*C8 -> 0
A9: CÀ CHUA SOCOLA XÁ | D9: =B9*C9 -> 0
A10: CÀ CHUA SÔCOLA(HỘP) KQ | D10: =B10*C10 -> 0
A11: CÀ RỐT BABY | D11: =B11*C11 -> 0
A12: CÀ RỐT BABY (KG) KQ | D12: =B12*C12 -> 0
A13: CÀ RỐT BABY 200GR | D13: =B13*C13 -> 0
A14: CẢI CẦU VỒNG | D14: =B14*C14 -> 0
A15: CẢI CẦU VỒNG 300GR | D15: =B15*C15 -> 0
... A19: CHANH VÀNG TRÁI 180UP | D19: =B19*C19 -> 0
A20: CẦN TÂY (KG) | B20: =44+35+10+20 -> 109 | C20: 9000 | D20: =B20*C20 -> 981000
A21: CẦN TÂY THUỶ CANH | D21: =B21*C21 -> 0
A22: CẦN TÂY(CÂY) | D22: =B22*C22 -> 0
A23: ỚT CHUÔNG 3 MÀU(KG)VR | D23: =B23*C23 -> 0
A24: ỚT CHUÔNG ĐỎ | B24: =150+40+65+20 -> 275 | C24: 35000 | D24: =B24*C24 -> 9625000
A25: ỚT CHUÔNG ĐỎ L1 | B25: 32 | C25: 30000 | D25: =B25*C25 -> 960000
A26: ỚT CHUÔNG ĐỎ(TRÁI) | D26: =B26*C26 -> 0
A27: ỚT CHUÔNG 3 MÀU 350G | D27: =B27*C27 -> 0
A28: ỚT CHUÔNG 3 MÀU KQ(KG) | D28: =B28*C28 -> 0
A29: ỚT CHUÔNG VÀNG | B29: =40+55 -> 95 | C29: 40000 | D29: =B29*C29 -> 3800000
A30: ỚT CHUÔNG VÀNG L1 | B30: 31 | C30: 35000 | D30: =B30*C30 -> 1085000
A31: ỚT CHUÔNG VÀNG(TRÁI) | D31: =B31*C31 -> 0
A32: ỚT CHUÔNG VÀNG+ XANH (VỈ) | D32: =B32*C32 -> 0
A33: ỚT CHUÔNG XANH | B33: =30+60+30+10 -> 130 | C33: 30000 | D33: =B33*C33 -> 3900000
A34: ỚT CHUÔNG XANH L1 | D34: =B34*C34 -> 0
A35: ỚT CHUÔNG XANH(TRÁI) | D35: =B35*C35 -> 0
A36: CỦ DỀN | B36: =50+30+30+40+35 -> 185 | C36: 12000 | D36: =B36*C36 -> 2220000
A37: CỦ DỀN 600G | D37: =B37*C37 -> 0
A38: GỪNG 250GR | D38: =B38*C38 -> 0
A39: HỒNG GIÒN | D39: =B39*C39 -> 0
A40: XÀ LÁCH MỸ | D40: =B40*C40 -> 0
A41: KHOAI TÂY HỒNG | B41: =20+20 -> 40 | C41: 19000 | D41: =B41*C41 -> 760000
A42: KHOAI TÂY HỒNG TÚI LƯỚI 500G | D42: =B42*C42 -> 0
A43: KHOAI TÂY VÀNG | D43: =B43*C43 -> 0
A44: KHOAI TÂY VÀNG ĐL | B44: =120+50+50+30 -> 250 | C44: 15000 | D44: =B44*C44 -> 3750000
...

Sheet 11.2
A1: hàng tồn cuối ngày 11/2
A2: TÊN SẢN PHẨM | B2: TỒN TRƯỚC | C2: GIÁ NHẬP | D2: THÀNH TIỀN
A3: BẮP CẢI TÍM | B3: 20 | C3: 17000 | D3: =B3*C3 -> 340000
A4: BẮP CẢI TÍM (BẮP) | D4: =B4*C4 -> 0
A5: BẮP CẢI TÍM SUSHI | D5: =B5*C5 -> 0
A6: BẮP CẢI TRẮNG | B6: 240 | C6: 6500 | D6: =B6*C6 -> 1560000
A7: BẮP CẢI TRẮNG (BẮP) | D7: =B7*C7 -> 0
A8: BẮP CẢI TRẮNG MỘC CHÂU | D8: =B8*C8 -> 0
A9: BẮP CẢI TRẮNG SUSHI | D9: =B9*C9 -> 0
A10: BẮP MỸ | D10: =B10*C10 -> 0
A11: BẦU | D11: =B11*C11 -> 0
A12: BÍ ĐAO XANH | B12: 140 | C12: 8000 | D12: =B12*C12 -> 1120000
A13: BÍ ĐAO XANH 400G | D13: =B13*C13 -> 0
A14: BÍ ĐỎ HỒ LÔ | B14: 13 | C14: 10000 | D14: =B14*C14 -> 130000
A15: BÍ ĐỎ MINI | D15: =B15*C15 -> 0
A16: BÍ ĐỎ NON (KG)KQ | D16: =B16*C16 -> 0
A17: BÍ ĐỎ NON TRÁI VR | B17: 40 | C17: 4000 | D17: =B17*C17 -> 160000
A18: BÍ ĐỎ NON( KG) VR | D18: =B18*C18 -> 0
A19: BÍ ĐỎ TRÒN | B19: 1250 | C19: 6000 | D19: =B19*C19 -> 7500000
A20: BÍ MINI VÀNG 300GR | D20: =B20*C20 -> 0
A21: BÍ MINI VÀNG KG | D21: =B21*C21 -> 0
A22: BÍ NGÒI VÀNG | D22: =B22*C22 -> 0
A23: BÍ NGÒI VÀNG (TRÁI) | D23: =B23*C23 -> 0
A24: BÍ NGÒI XANH | B24: 60 | C24: 10000 | D24: =B24*C24 -> 600000
A25: BÍ NGÒI XANH(TRÁI) | D25: =B25*C25 -> 0
A26: BÍ NHẬT | D26: =B26*C26 -> 0
A27: BƠ 034 | D27: =B27*C27 -> 0
A28: BƠ BOOTH | D28: =B28*C28 -> 0
A29: BƠ SÁP | D29: =B29*C29 -> 0
A30: BÓ XÔI | D30: =B30*C30 -> 0
A31: BÓ XÔI 300G VR | B31: 12 | C31: 4800 | D31: =B31*C31 -> 57600
A32: BÓ XÔI-HN KQ | D32: =B32*C32 -> 0
A33: BÓ XÔI-NA | D33: =B33*C33 -> 0
A34: BÔNG ATISO | D34: =B34*C34 -> 0
A35: BÔNG BÍ | D35: =B35*C35 -> 0
A36: BÔNG BÍ TÚI 300GR | D36: =B36*C36 -> 0
A37: BÔNG CẢI TRẮNG | D37: =B37*C37 -> 0
A38: BÔNG CẢI TRẮNG (CÂY) | D38: =B38*C38 -> 0
A39: BÔNG CẢI XANH 10P | D39: =B39*C39 -> 0
A40: BÔNG CẢI XANH AEON | B40: 25 | C40: 23000 | D40: =B40*C40 -> 575000
...

Sheet 12.2
A1: hàng tồn cuối ngày 12/2
A2: TÊN SẢN PHẨM | B2: TỒN TRƯỚC | C2: GIÁ NHẬP | D2: THÀNH TIỀN
A3: BẮP CẢI TÍM | B3: 20 | C3: 17000 | D3: =B3*C3 -> 340000
A4: BẮP CẢI TÍM (BẮP) | D4: =B4*C4 -> 0
A5: BẮP CẢI TÍM SUSHI | D5: =B5*C5 -> 0
A6: BẮP CẢI TRẮNG | B6: 135 | C6: 6500 | D6: =B6*C6 -> 877500
A7: BẮP CẢI TRẮNG (BẮP) | D7: =B7*C7 -> 0
A8: BẮP CẢI TRẮNG MỘC CHÂU | D8: =B8*C8 -> 0
A9: BẮP CẢI TRẮNG SUSHI | D9: =B9*C9 -> 0
A10: BẮP MỸ | D10: =B10*C10 -> 0
A11: BẦU | D11: =B11*C11 -> 0
A12: BÍ ĐAO XANH | B12: 120 | C12: 8000 | D12: =B12*C12 -> 960000
A13: BÍ ĐAO XANH 400G | D13: =B13*C13 -> 0
A14: BÍ ĐỎ HỒ LÔ | D14: =B14*C14 -> 0
A15: BÍ ĐỎ MINI | D15: =B15*C15 -> 0
A16: BÍ ĐỎ NON (KG)KQ | D16: =B16*C16 -> 0
A17: BÍ ĐỎ NON TRÁI VR | B17: 32 | C17: 4000 | D17: =B17*C17 -> 128000
A18: BÍ ĐỎ NON( KG) VR | B18: =40+10 -> 50 | C18: 12000 | D18: =B18*C18 -> 600000
A19: BÍ ĐỎ TRÒN | B19: 1030 | C19: 6000 | D19: =B19*C19 -> 6180000
A20: BÍ MINI VÀNG 300GR | D20: =B20*C20 -> 0
A21: BÍ MINI VÀNG KG | D21: =B21*C21 -> 0
A22: BÍ NGÒI VÀNG | D22: =B22*C22 -> 0
A23: BÍ NGÒI VÀNG (TRÁI) | D23: =B23*C23 -> 0
A24: BÍ NGÒI XANH | B24: =50+30 -> 80 | C24: 10000 | D24: =B24*C24 -> 800000
A25: BÍ NGÒI XANH(TRÁI) | D25: =B25*C25 -> 0
A26: BÍ NHẬT | D26: =B26*C26 -> 0
A27: BƠ 034 | D27: =B27*C27 -> 0
A28: BƠ BOOTH | D28: =B28*C28 -> 0
A29: BƠ SÁP | D29: =B29*C29 -> 0
A30: BÓ XÔI | D30: =B30*C30 -> 0
A31: BÓ XÔI 300G VR | D31: =B31*C31 -> 0
A32: BÓ XÔI-HN KQ | D32: =B32*C32 -> 0
A33: BÓ XÔI-NA | D33: =B33*C33 -> 0
A34: BÔNG ATISO | D34: =B34*C34 -> 0
A35: BÔNG BÍ | D35: =B35*C35 -> 0
A36: BÔNG BÍ TÚI 300GR | D36: =B36*C36 -> 0
... A43: BÔNG CẢI XANH BABY 200G | D43: =B43*C43 -> 0
A44: BÔNG CẢI XANH BIGC | B44: 22 | C44: 14000 | D44: =B44*C44 -> 308000
A45: BÔNG CẢI XANH CITI | D45: =B45*C45 -> 0
A46: CÀ CHUA | B46: =1040+460+50+160 -> 1710 | C46: 14000 | D46: =B46*C46 -> 23940000
...

Sheet 13.2
A1: hàng tồn cuối ngày 13/2
A2: TÊN SẢN PHẨM | B2: TỒN TRƯỚC | C2: GIÁ NHẬP | D2: THÀNH TIỀN
A3: BẮP CẢI TÍM | B3: 5 | C3: 17000 | D3: =B3*C3 -> 85000
A4: BẮP CẢI TÍM (BẮP) | D4: =B4*C4 -> 0
A5: BẮP CẢI TÍM SUSHI | D5: =B5*C5 -> 0
A6: BẮP CẢI TRẮNG | B6: 144 | C6: 6500 | D6: =B6*C6 -> 936000
A7: BẮP CẢI TRẮNG (BẮP) | D7: =B7*C7 -> 0
A8: BẮP CẢI TRẮNG MỘC CHÂU | D8: =B8*C8 -> 0
A9: BẮP CẢI TRẮNG SUSHI | D9: =B9*C9 -> 0
A10: BẮP MỸ | D10: =B10*C10 -> 0
A11: BẦU | D11: =B11*C11 -> 0
A12: BÍ ĐAO XANH | B12: 120 | C12: 8000 | D12: =B12*C12 -> 960000
A13: BÍ ĐAO XANH 400G | D13: =B13*C13 -> 0
A14: BÍ ĐỎ HỒ LÔ | B14: 16 | C14: 10000 | D14: =B14*C14 -> 160000
A15: BÍ ĐỎ MINI | D15: =B15*C15 -> 0
A16: BÍ ĐỎ NON (KG)KQ | D16: =B16*C16 -> 0
A17: BÍ ĐỎ NON TRÁI VR | D17: =B17*C17 -> 0
A18: BÍ ĐỎ NON( KG) VR | D18: =B18*C18 -> 0
A19: BÍ ĐỎ TRÒN | B19: =1200+2300 -> 3500 | C19: 6500 | D19: =B19*C19 -> 22750000
A20: BÍ MINI VÀNG 300GR | D20: =B20*C20 -> 0
A21: BÍ MINI VÀNG KG | D21: =B21*C21 -> 0
A22: BÍ NGÒI VÀNG | D22: =B22*C22 -> 0
A23: BÍ NGÒI VÀNG (TRÁI) | D23: =B23*C23 -> 0
A24: BÍ NGÒI XANH | B24: =60+20+82 -> 162 | C24: 10000 | D24: =B24*C24 -> 1620000
A25: BÍ NGÒI XANH(TRÁI) | D25: =B25*C25 -> 0
A26: BÍ NHẬT | D26: =B26*C26 -> 0
A27: BƠ 034 | D27: =B27*C27 -> 0
A28: BƠ BOOTH | D28: =B28*C28 -> 0
A29: BƠ SÁP | D29: =B29*C29 -> 0
A30: BÓ XÔI | B30: =4+10+1+4 -> 19 | C30: 16000 | D30: =B30*C30 -> 304000
A31: BÓ XÔI 300G VR | D31: =B31*C31 -> 0
A32: BÓ XÔI-HN KQ | D32: =B32*C32 -> 0
A33: BÓ XÔI-NA | D33: =B33*C33 -> 0
A34: BÔNG ATISO | D34: =B34*C34 -> 0
A35: BÔNG BÍ | D35: =B35*C35 -> 0
A36: BÔNG BÍ TÚI 300GR | D36: =B36*C36 -> 0
A37: BÔNG CẢI TRẮNG | D37: =B37*C37 -> 0
A38: BÔNG CẢI TRẮNG (CÂY) | D38: =B38*C38 -> 0
A39: BÔNG CẢI XANH 10P | D39: =B39*C39 -> 0
A40: BÔNG CẢI XANH AEON | B40: 24 | C40: 23000 | D40: =B40*C40 -> 552000
...

Sheet 14.2
A1: hàng tồn cuối ngày 14/2
A2: TÊN SẢN PHẨM | B2: TỒN TRƯỚC | C2: GIÁ NHẬP | D2: THÀNH TIỀN
A3: BẮP CẢI TÍM | D3: =B3*C3 -> 0
A4: BẮP CẢI TÍM (BẮP) | D4: =B4*C4 -> 0
A5: BẮP CẢI TÍM SUSHI | D5: =B5*C5 -> 0
A6: BẮP CẢI TRẮNG | B6: =72+200+12 -> 284 | C6: 6500 | D6: =B6*C6 -> 1846000
A7: BẮP CẢI TRẮNG (BẮP) | D7: =B7*C7 -> 0
A8: BẮP CẢI TRẮNG MỘC CHÂU | D8: =B8*C8 -> 0
A9: BẮP CẢI TRẮNG SUSHI | D9: =B9*C9 -> 0
A10: BẮP MỸ | D10: =B10*C10 -> 0
A11: BẦU | D11: =B11*C11 -> 0
A12: BÍ ĐAO XANH | B12: =10+6+40 -> 56 | C12: 8000 | D12: =B12*C12 -> 448000
A13: BÍ ĐAO XANH 400G | D13: =B13*C13 -> 0
A14: BÍ ĐỎ HỒ LÔ | D14: =B14*C14 -> 0
A15: BÍ ĐỎ MINI | D15: =B15*C15 -> 0
A16: BÍ ĐỎ NON (KG)KQ | D16: =B16*C16 -> 0
A17: BÍ ĐỎ NON TRÁI VR | D17: =B17*C17 -> 0
A18: BÍ ĐỎ NON( KG) VR | B18: =2+23+10+6 -> 41 | C18: 11000 | D18: =B18*C18 -> 451000
A19: BÍ ĐỎ TRÒN | B19: =1400+350+720 -> 2470 | C19: 6000 | D19: =B19*C19 -> 14820000
A20: BÍ MINI VÀNG 300GR | D20: =B20*C20 -> 0
A21: BÍ MINI VÀNG KG | D21: =B21*C21 -> 0
A22: BÍ NGÒI VÀNG | D22: =B22*C22 -> 0
A23: BÍ NGÒI VÀNG (TRÁI) | D23: =B23*C23 -> 0
A24: BÍ NGÒI XANH | B24: =55+35+12+25+5 -> 132 | C24: 9000 | D24: =B24*C24 -> 1188000
A25: BÍ NGÒI XANH(TRÁI) | D25: =B25*C25 -> 0
A26: BÍ NHẬT | D26: =B26*C26 -> 0
A27: BƠ 034 | D27: =B27*C27 -> 0
A28: BƠ BOOTH | D28: =B28*C28 -> 0
A29: BƠ SÁP | D29: =B29*C29 -> 0
A30: BÓ XÔI | D30: =B30*C30 -> 0
A31: BÓ XÔI 300G VR | B31: 2 | C31: 5300 | D31: =B31*C31 -> 10600
A32: BÓ XÔI-HN KQ | D32: =B32*C32 -> 0
A33: BÓ XÔI-NA | D33: =B33*C33 -> 0
A34: BÔNG ATISO | D34: =B34*C34 -> 0
A35: BÔNG BÍ | D35: =B35*C35 -> 0
A36: BÔNG BÍ TÚI 300GR | B36: 2 | C36: 5600 | D36: =B36*C36 -> 11200
A37: BÔNG CẢI TRẮNG | B37: 7 | C37: 11000 | D37: =B37*C37 -> 77000
A38: BÔNG CẢI TRẮNG (CÂY) | D38: =B38*C38 -> 0
A39: BÔNG CẢI XANH 10P | B39: =14+16 -> 30 | C39: 17000 | D39: =B39*C39 -> 510000
A40: BÔNG CẢI XANH AEON | D40: =B40*C40 -> 0
...

Sheet 15.2
A1: hàng tồn cuối ngày 15/2
A2: TÊN SẢN PHẨM | B2: TỒN TRƯỚC | C2: GIÁ NHẬP | D2: THÀNH TIỀN
A3: CÀ CHUA SÔCOLA 250GR (HỘP) VR | D3: =B3*C3 -> 0
A4: CÀ CHUA SÔCOLA 250GR (KG) -NA | D4: =B4*C4 -> 0
A5: CÀ CHUA SÔCOLA 250GR (KG) VR | D5: =B5*C5 -> 0
A6: CÀ CHUA SÔCOLA 250GR(KG) KQ | D6: =B6*C6 -> 0
A7: CÀ CHUA SÔCOLA 300GR (HỘP) VR | D7: =B7*C7 -> 0
A8: CÀ CHUA SOCOLA XÁ | D8: =B8*C8 -> 0
A9: CÀ CHUA SÔCOLA(HỘP) KQ | D9: =B9*C9 -> 0
A10: CÀ RỐT BABY | D10: =B10*C10 -> 0
A11: CÀ RỐT BABY (KG) KQ | D11: =B11*C11 -> 0
A12: CÀ RỐT BABY 200GR | D12: =B12*C12 -> 0
A13: CẢI CẦU VỒNG | D13: =B13*C13 -> 0
A14: CẢI CẦU VỒNG 300GR | D14: =B14*C14 -> 0
... A18: CHANH VÀNG TRÁI 180UP | D18: =B18*C18 -> 0
A19: CẦN TÂY (KG) | B19: =35+15 -> 50 | C19: 9000 | D19: =B19*C19 -> 450000
A20: CẦN TÂY THUỶ CANH | D20: =B20*C20 -> 0
A21: CẦN TÂY(CÂY) | D21: =B21*C21 -> 0
A22: ỚT CHUÔNG 3 MÀU(KG)VR | D22: =B22*C22 -> 0
A23: ỚT CHUÔNG ĐỎ | B23: =20+20+40 -> 80 | C23: 34000 | D23: =B23*C23 -> 2720000
A24: ỚT CHUÔNG ĐỎ L1 | D24: =B24*C24 -> 0
A25: ỚT CHUÔNG ĐỎ(TRÁI) | D25: =B25*C25 -> 0
A26: ỚT CHUÔNG 3 MÀU 350G | D26: =B26*C26 -> 0
A27: ỚT CHUÔNG 3 MÀU KQ(KG) | D27: =B27*C27 -> 0
A28: ỚT CHUÔNG VÀNG | B28: =22+12+20+10 -> 64 | C28: 34000 | D28: =B28*C28 -> 2176000
A29: ỚT CHUÔNG VÀNG L1 | D29: =B29*C29 -> 0
A30: ỚT CHUÔNG VÀNG(TRÁI) | D30: =B30*C30 -> 0
A31: ỚT CHUÔNG VÀNG+ XANH (VỈ) | D31: =B31*C31 -> 0
A32: ỚT CHUÔNG XANH | B32: =20+20+15 -> 55 | C32: 27000 | D32: =B32*C32 -> 1485000
A33: ỚT CHUÔNG XANH L1 | D33: =B33*C33 -> 0
A34: ỚT CHUÔNG XANH(TRÁI) | D34: =B34*C34 -> 0
A35: CỦ DỀN | B35: 25 | C35: 12000 | D35: =B35*C35 -> 300000
A36: CỦ DỀN 600G | D36: =B36*C36 -> 0
A37: GỪNG 250GR | D37: =B37*C37 -> 0
A38: HỒNG GIÒN | D38: =B38*C38 -> 0
A39: XÀ LÁCH MỸ | D39: =B39*C39 -> 0
A40: KHOAI TÂY HỒNG | D40: =B40*C40 -> 0
A41: KHOAI TÂY HỒNG TÚI LƯỚI 500G | D41: =B41*C41 -> 0
A42: KHOAI TÂY VÀNG | D42: =B42*C42 -> 0
A43: KHOAI TÂY VÀNG ĐL | B43: 225 | C43: 15000 | D43: =B43*C43 -> 3375000
...

Sheet 16.2
A1: hàng tồn cuối ngày 16/2
A2: TÊN SẢN PHẨM | B2: TỒN TRƯỚC | C2: GIÁ NHẬP | D2: THÀNH TIỀN
A3: CÀ CHUA SÔCOLA 250GR (HỘP) VR | B3: 16 | C3: 5000 | D3: =B3*C3 -> 80000
A4: CÀ CHUA SÔCOLA 250GR (KG) -NA | D4: =B4*C4 -> 0
A5: CÀ CHUA SÔCOLA 250GR (KG) VR | D5: =B5*C5 -> 0
A6: CÀ CHUA SÔCOLA 250GR(KG) KQ | D6: =B6*C6 -> 0
A7: CÀ CHUA SÔCOLA 300GR (HỘP) VR | D7: =B7*C7 -> 0
A8: CÀ CHUA SOCOLA XÁ | D8: =B8*C8 -> 0
A9: CÀ CHUA SÔCOLA(HỘP) KQ | D9: =B9*C9 -> 0
A10: CÀ RỐT BABY | D10: =B10*C10 -> 0
A11: CÀ RỐT BABY (KG) KQ | D11: =B11*C11 -> 0
A12: CÀ RỐT BABY 200GR | D12: =B12*C12 -> 0
A13: CẢI CẦU VỒNG | D13: =B13*C13 -> 0
A14: CẢI CẦU VỒNG 300GR | D14: =B14*C14 -> 0
A15: CẢI KALE | D15: =B15*C15 -> 0
... A22: ỚT CHUÔNG 3 MÀU(KG)VR | D22: =B22*C22 -> 0
A23: ỚT CHUÔNG ĐỎ | B23: =40+20+19+20 -> 99 | C23: 34000 | D23: =B23*C23 -> 3366000
A24: ỚT CHUÔNG ĐỎ L1 | D24: =B24*C24 -> 0
A25: ỚT CHUÔNG ĐỎ(TRÁI) | D25: =B25*C25 -> 0
A26: ỚT CHUÔNG 3 MÀU 350G | D26: =B26*C26 -> 0
A27: ỚT CHUÔNG 3 MÀU KQ(KG) | D27: =B27*C27 -> 0
A28: ỚT CHUÔNG VÀNG | D28: =B28*C28 -> 0
A29: ỚT CHUÔNG VÀNG L1 | D29: =B29*C29 -> 0
A30: ỚT CHUÔNG VÀNG(TRÁI) | D30: =B30*C30 -> 0
A31: ỚT CHUÔNG VÀNG+ XANH (VỈ) | D31: =B31*C31 -> 0
A32: ỚT CHUÔNG XANH | B32: =7+5+35 -> 47 | C32: 27000 | D32: =B32*C32 -> 1269000
A33: ỚT CHUÔNG XANH L1 | D33: =B33*C33 -> 0
A34: ỚT CHUÔNG XANH(TRÁI) | D34: =B34*C34 -> 0
A35: CỦ DỀN | B35: =6+5+35 -> 46 | C35: 12000 | D35: =B35*C35 -> 552000
A36: CỦ DỀN 600G | D36: =B36*C36 -> 0
A37: GỪNG 250GR | D37: =B37*C37 -> 0
A38: HỒNG GIÒN | D38: =B38*C38 -> 0
A39: XÀ LÁCH MỸ | D39: =B39*C39 -> 0
A40: KHOAI TÂY HỒNG | D40: =B40*C40 -> 0
A41: KHOAI TÂY HỒNG TÚI LƯỚI 500G | D41: =B41*C41 -> 0
A42: KHOAI TÂY VÀNG | D42: =B42*C42 -> 0
A43: KHOAI TÂY VÀNG ĐL | B43: =115+40 -> 155 | C43: 15000 | D43: =B43*C43 -> 2325000
A44: KHOAI TÂY VÀNG LỚN TÚI LƯỚI 500G | D44: =B44*C44 -> 0
A45: KHOAI TÂY VÀNG RỬA | D45: =B45*C45 -> 0
A46: KHOAI TÂY VÀNG TRUNG TÚI LƯỚI 500G | D46: =B46*C46 -> 0
...

Sheet 17.2
A1: hàng tồn cuối ngày 17/2
A2: TÊN SẢN PHẨM | B2: TỒN TRƯỚC | C2: GIÁ NHẬP | D2: THÀNH TIỀN
A3: BẮP CẢI TÍM | B3: =2+2+12+10 -> 26 | C3: 15000 | D3: =B3*C3 -> 390000
A4: BẮP CẢI TÍM (BẮP) | D4: =B4*C4 -> 0
A5: BẮP CẢI TÍM SUSHI | D5: =B5*C5 -> 0
A6: BẮP CẢI TRẮNG | B6: =10+60+70 -> 140 | C6: 6500 | D6: =B6*C6 -> 910000
A7: BẮP CẢI TRẮNG (BẮP) | D7: =B7*C7 -> 0
A8: BẮP CẢI TRẮNG MỘC CHÂU | D8: =B8*C8 -> 0
A9: BẮP CẢI TRẮNG SÓI BIỂN | D9: =B9*C9 -> 0
A10: BẮP CẢI TRẮNG SUSHI | D10: =B10*C10 -> 0
A11: BẮP MỸ | D11: =B11*C11 -> 0
A12: BẦU | D12: =B12*C12 -> 0
A13: BÍ ĐAO XANH | D13: =B13*C13 -> 0
A14: BÍ ĐAO XANH 400G | D14: =B14*C14 -> 0
A15: BÍ ĐỎ HỒ LÔ | B15: =8+12+20 -> 40 | C15: 9500 | D15: =B15*C15 -> 380000
A16: BÍ ĐỎ MINI | D16: =B16*C16 -> 0
A17: BÍ ĐỎ NON (KG)KQ | D17: =B17*C17 -> 0
A18: BÍ ĐỎ NON TRÁI VR | D18: =B18*C18 -> 0
A19: BÍ ĐỎ NON( KG) VR | D19: =B19*C19 -> 0
A20: BÍ ĐỎ TRÒN | B20: =3000+1510 -> 4510 | C20: 6000 | D20: =B20*C20 -> 27060000
A21: BÍ MINI VÀNG 300GR | B21: 6 | C21: 70000 | D21: =B21*C21 -> 420000
A22: BÍ MINI VÀNG KG | D22: =B22*C22 -> 0
A23: BÍ NGÒI VÀNG | D23: =B23*C23 -> 0
A24: BÍ NGÒI VÀNG (TRÁI) | D24: =B24*C24 -> 0
A25: BÍ NGÒI XANH | B25: 45 | C25: 9000 | D25: =B25*C25 -> 405000
A26: BÍ NGÒI XANH(TRÁI) | D26: =B26*C26 -> 0
A27: BÍ NHẬT | D27: =B27*C27 -> 0
A28: BƠ 034 | D28: =B28*C28 -> 0
A29: BƠ BOOTH | D29: =B29*C29 -> 0
A30: BƠ SÁP | D30: =B30*C30 -> 0
A31: BÓ XÔI | B31: 3 | C31: 15000 | D31: =B31*C31 -> 45000
A32: BÓ XÔI 300G VR | D32: =B32*C32 -> 0
A33: BÓ XÔI-HN KQ | D33: =B33*C33 -> 0
A34: BÓ XÔI-NA | D34: =B34*C34 -> 0
A35: BÔNG ATISO | D35: =B35*C35 -> 0
A36: BÔNG BÍ | D36: =B36*C36 -> 0
A37: BÔNG BÍ TÚI 300GR | D37: =B37*C37 -> 0
A38: BÔNG CẢI TRẮNG | D38: =B38*C38 -> 0
A39: BÔNG CẢI TRẮNG (CÂY) | D39: =B39*C39 -> 0
A40: BÔNG CẢI XANH 10P | D40: =B40*C40 -> 0
...

Sheet 18.2
A1: hàng tồn cuối ngày 18/2
A2: TÊN SẢN PHẨM | B2: TỒN TRƯỚC | C2: GIÁ NHẬP | D2: THÀNH TIỀN
A3: BẮP CẢI TÍM | B3: 20 | C3: 15000 | D3: =B3*C3 -> 300000
A4: BẮP CẢI TÍM (BẮP) | D4: =B4*C4 -> 0
A5: BẮP CẢI TÍM SUSHI | D5: =B5*C5 -> 0
A6: BẮP CẢI TRẮNG | B6: =20+50 -> 70 | C6: 6500 | D6: =B6*C6 -> 455000
A7: BẮP CẢI TRẮNG (BẮP) | D7: =B7*C7 -> 0
A8: BẮP CẢI TRẮNG MỘC CHÂU | D8: =B8*C8 -> 0
A9: BẮP CẢI TRẮNG SÓI BIỂN | D9: =B9*C9 -> 0
A10: BẮP CẢI TRẮNG SUSHI | D10: =B10*C10 -> 0
A11: BẮP MỸ | D11: =B11*C11 -> 0
A12: BẦU | D12: =B12*C12 -> 0
A13: BÍ ĐAO XANH | D13: =B13*C13 -> 0
A14: BÍ ĐAO XANH 400G | D14: =B14*C14 -> 0
A15: BÍ ĐỎ HỒ LÔ | B15: 10 | C15: 9500 | D15: =B15*C15 -> 95000
A16: BÍ ĐỎ MINI | D16: =B16*C16 -> 0
A17: BÍ ĐỎ NON (KG)KQ | D17: =B17*C17 -> 0
A18: BÍ ĐỎ NON TRÁI VR | D18: =B18*C18 -> 0
A19: BÍ ĐỎ NON( KG) VR | B19: 3 | C19: 4000 | D19: =B19*C19 -> 12000
A20: BÍ ĐỎ TRÒN | B20: =3000+1150 -> 4150 | C20: 6000 | D20: =B20*C20 -> 24900000
A21: BÍ MINI VÀNG 300GR | D21: =B21*C21 -> 0
A22: BÍ MINI VÀNG KG | D22: =B22*C22 -> 0
A23: BÍ NGÒI VÀNG | D23: =B23*C23 -> 0
A24: BÍ NGÒI VÀNG (TRÁI) | D24: =B24*C24 -> 0
A25: BÍ NGÒI XANH | B25: 30 | C25: 9000 | D25: =B25*C25 -> 270000
A26: BÍ NGÒI XANH(TRÁI) | D26: =B26*C26 -> 0
A27: BÍ NHẬT | D27: =B27*C27 -> 0
A28: BƠ 034 | D28: =B28*C28 -> 0
A29: BƠ BOOTH | D29: =B29*C29 -> 0
A30: BƠ SÁP | D30: =B30*C30 -> 0
A31: BÓ XÔI | D31: =B31*C31 -> 0
A32: BÓ XÔI 300G VR | B32: 40 | C32: 6000 | D32: =B32*C32 -> 240000
A33: BÓ XÔI-HN KQ | D33: =B33*C33 -> 0
A34: BÓ XÔI-NA | D34: =B34*C34 -> 0
A35: BÔNG ATISO | D35: =B35*C35 -> 0
A36: BÔNG BÍ | D36: =B36*C36 -> 0
A37: BÔNG BÍ TÚI 300GR | D37: =B37*C37 -> 0
A38: BÔNG CẢI TRẮNG | D38: =B38*C38 -> 0
A39: BÔNG CẢI TRẮNG (CÂY) | D39: =B39*C39 -> 0
A40: BÔNG CẢI XANH 10P | D40: =B40*C40 -> 0
...

Sheet 19.2
A1: hàng tồn cuối ngày 19/2 | B1: Stock | D1: Safety stock
A2: TÊN SẢN PHẨM | B2: TỒN TRƯỚC | C2: GIÁ NHẬP | D2: THÀNH TIỀN
A3: BẮP CẢI TÍM | B3: 16 | C3: 15000 | D3: =B3*C3 -> 240000
A4: BẮP CẢI TÍM (BẮP) | D4: =B4*C4 -> 0
A5: BẮP CẢI TÍM SUSHI | D5: =B5*C5 -> 0
A6: BẮP CẢI TRẮNG | B6: 250 | C6: 6500 | D6: =B6*C6 -> 1625000
A7: BẮP CẢI TRẮNG (BẮP) | D7: =B7*C7 -> 0
A8: BẮP CẢI TRẮNG MỘC CHÂU | D8: =B8*C8 -> 0
A9: BẮP CẢI TRẮNG SÓI BIỂN | D9: =B9*C9 -> 0
A10: BẮP CẢI TRẮNG SUSHI | D10: =B10*C10 -> 0
A11: BẮP MỸ | D11: =B11*C11 -> 0
A12: BẦU | D12: =B12*C12 -> 0
A13: BÍ ĐAO XANH | D13: =B13*C13 -> 0
A14: BÍ ĐAO XANH 400G | D14: =B14*C14 -> 0
A15: BÍ ĐỎ HỒ LÔ | D15: =B15*C15 -> 0
A16: BÍ ĐỎ MINI | D16: =B16*C16 -> 0
A17: BÍ ĐỎ NON (KG)KQ | D17: =B17*C17 -> 0
A18: BÍ ĐỎ NON TRÁI VR | B18: =16+10+9 -> 35 | C18: 4000 | D18: =B18*C18 -> 140000
A19: BÍ ĐỎ NON( KG) VR | D19: =B19*C19 -> 0
A20: BÍ ĐỎ TRÒN | B20: =70+1260 -> 1330 | C20: 6000 | D20: =B20*C20 -> 7980000
A21: BÍ MINI VÀNG 300GR | B21: 6 | C21: 70000 | D21: =B21*C21 -> 420000
A22: BÍ MINI VÀNG KG | D22: =B22*C22 -> 0
A23: BÍ NGÒI VÀNG | D23: =B23*C23 -> 0
A24: BÍ NGÒI VÀNG (TRÁI) | D24: =B24*C24 -> 0
A25: BÍ NGÒI XANH | B25: =10+12 -> 22 | C25: 9000 | D25: =B25*C25 -> 198000
A26: BÍ NGÒI XANH(TRÁI) | D26: =B26*C26 -> 0
A27: BÍ NHẬT | D27: =B27*C27 -> 0
A28: BƠ 034 | D28: =B28*C28 -> 0
A29: BƠ BOOTH | D29: =B29*C29 -> 0
A30: BƠ SÁP | D30: =B30*C30 -> 0
A31: BÓ XÔI | B31: 3 | C31: 15000 | D31: =B31*C31 -> 45000
A32: BÓ XÔI 300G VR | D32: =B32*C32 -> 0
A33: BÓ XÔI-HN KQ | D33: =B33*C33 -> 0
A34: BÓ XÔI-NA | D34: =B34*C34 -> 0
A35: BÔNG ATISO | D35: =B35*C35 -> 0
A36: BÔNG BÍ | D36: =B36*C36 -> 0
A37: BÔNG BÍ TÚI 300GR | D37: =B37*C37 -> 0
A38: BÔNG CẢI TRẮNG | D38: =B38*C38 -> 0
A39: BÔNG CẢI TRẮNG (CÂY) | D39: =B39*C39 -> 0
A40: BÔNG CẢI XANH 10P | D40: =B40*C40 -> 0
...

Sheet 20.2
A1: hàng tồn cuối ngày 20/2
A2: TÊN SẢN PHẨM | B2: TỒN TRƯỚC | C2: GIÁ NHẬP | D2: THÀNH TIỀN
A3: BẮP CẢI TÍM | B3: 2 | C3: 15000 | D3: =B3*C3 -> 30000
A4: BẮP CẢI TÍM (BẮP) | D4: =B4*C4 -> 0
A5: BẮP CẢI TÍM SUSHI | D5: =B5*C5 -> 0
A6: BẮP CẢI TRẮNG | B6: =12+12+12 -> 36 | C6: 6000 | D6: =B6*C6 -> 216000
A7: BẮP CẢI TRẮNG (BẮP) | D7: =B7*C7 -> 0
A8: BẮP CẢI TRẮNG MỘC CHÂU | D8: =B8*C8 -> 0
A9: BẮP CẢI TRẮNG SÓI BIỂN | D9: =B9*C9 -> 0
A10: BẮP CẢI TRẮNG SUSHI | D10: =B10*C10 -> 0
A11: BẮP MỸ | D11: =B11*C11 -> 0
A12: BẦU | D12: =B12*C12 -> 0
A13: BÍ ĐAO XANH | D13: =B13*C13 -> 0
A14: BÍ ĐAO XANH 400G | D14: =B14*C14 -> 0
A15: BÍ ĐỎ HỒ LÔ | D15: =B15*C15 -> 0
A16: BÍ ĐỎ MINI | D16: =B16*C16 -> 0
A17: BÍ ĐỎ NON (KG)KQ | D17: =B17*C17 -> 0
A18: BÍ ĐỎ NON TRÁI VR | B18: 11 | C18: 4000 | D18: =B18*C18 -> 44000
A19: BÍ ĐỎ NON( KG) VR | D19: =B19*C19 -> 0
A20: BÍ ĐỎ TRÒN | B20: =1350+1770 -> 3120 | C20: 6000 | D20: =B20*C20 -> 18720000
A21: BÍ MINI VÀNG 300GR | D21: =B21*C21 -> 0
A22: BÍ MINI VÀNG KG | D22: =B22*C22 -> 0
A23: BÍ NGÒI VÀNG | D23: =B23*C23 -> 0
A24: BÍ NGÒI VÀNG (TRÁI) | D24: =B24*C24 -> 0
A25: BÍ NGÒI XANH | B25: =25+20+30 -> 75 | C25: 8000 | D25: =B25*C25 -> 600000
A26: BÍ NGÒI XANH(TRÁI) | D26: =B26*C26 -> 0
A27: BÍ NHẬT | D27: =B27*C27 -> 0
A28: BƠ 034 | D28: =B28*C28 -> 0
A29: BƠ BOOTH | D29: =B29*C29 -> 0
A30: BƠ SÁP | D30: =B30*C30 -> 0
A31: BÓ XÔI | D31: =B31*C31 -> 0
A32: BÓ XÔI 300G VR | D32: =B32*C32 -> 0
A33: BÓ XÔI-HN KQ | D33: =B33*C33 -> 0
A34: BÓ XÔI-NA | D34: =B34*C34 -> 0
A35: BÔNG ATISO | D35: =B35*C35 -> 0
A36: BÔNG BÍ | D36: =B36*C36 -> 0
A37: BÔNG BÍ TÚI 300GR | D37: =B37*C37 -> 0
... A39: BÔNG CẢI TRẮNG (CÂY) | D39: =B39*C39 -> 0
A40: BÔNG CẢI XANH 10P | B40: 6 | C40: 17000 | D40: =B40*C40 -> 102000
A41: BÔNG CẢI XANH AEON | D41: =B41*C41 -> 0
...

Sheet 21.2
A1: hàng tồn cuối ngày 21/2
A2: TÊN SẢN PHẨM | B2: TỒN TRƯỚC | C2: GIÁ NHẬP | D2: THÀNH TIỀN
A3: BẮP CẢI TÍM | B3: 12 | C3: 15000 | D3: =B3*C3 -> 180000
A4: BẮP CẢI TÍM (BẮP) | D4: =B4*C4 -> 0
A5: BẮP CẢI TÍM SUSHI | D5: =B5*C5 -> 0
A6: BẮP CẢI TRẮNG | D6: =B6*C6 -> 0
A7: BẮP CẢI TRẮNG (BẮP) | D7: =B7*C7 -> 0
A8: BẮP CẢI TRẮNG MỘC CHÂU | D8: =B8*C8 -> 0
A9: BẮP CẢI TRẮNG SÓI BIỂN | D9: =B9*C9 -> 0
A10: BẮP CẢI TRẮNG SUSHI | D10: =B10*C10 -> 0
A11: BẮP MỸ | D11: =B11*C11 -> 0
A12: BẦU | D12: =B12*C12 -> 0
A13: BÍ ĐAO XANH | B13: =4+11 -> 15 | C13: 15000 | D13: =B13*C13 -> 225000
A14: BÍ ĐAO XANH 400G | D14: =B14*C14 -> 0
A15: BÍ ĐỎ HỒ LÔ | D15: =B15*C15 -> 0
A16: BÍ ĐỎ MINI | D16: =B16*C16 -> 0
A17: BÍ ĐỎ NON (KG)KQ | D17: =B17*C17 -> 0
A18: BÍ ĐỎ NON TRÁI VR | D18: =B18*C18 -> 0
A19: BÍ ĐỎ NON( KG) VR | D19: =B19*C19 -> 0
A20: BÍ ĐỎ TRÒN | B20: =1350+750 -> 2100 | C20: 6000 | D20: =B20*C20 -> 12600000
A21: BÍ MINI VÀNG 300GR | D21: =B21*C21 -> 0
A22: BÍ MINI VÀNG KG | D22: =B22*C22 -> 0
A23: BÍ NGÒI VÀNG | D23: =B23*C23 -> 0
A24: BÍ NGÒI VÀNG (TRÁI) | D24: =B24*C24 -> 0
A25: BÍ NGÒI XANH | B25: =10+15+25+65 -> 115 | C25: 7000 | D25: =B25*C25 -> 805000
A26: BÍ NGÒI XANH(TRÁI) | D26: =B26*C26 -> 0
A27: BÍ NHẬT | D27: =B27*C27 -> 0
A28: BƠ 034 | D28: =B28*C28 -> 0
A29: BƠ BOOTH | D29: =B29*C29 -> 0
A30: BƠ SÁP | D30: =B30*C30 -> 0
A31: BÓ XÔI | B31: 8 | C31: 15000 | D31: =B31*C31 -> 120000
A32: BÓ XÔI 300G VR | D32: =B32*C32 -> 0
A33: BÓ XÔI-HN KQ | D33: =B33*C33 -> 0
A34: BÓ XÔI-NA | D34: =B34*C34 -> 0
A35: BÔNG ATISO | D35: =B35*C35 -> 0
A36: BÔNG BÍ | D36: =B36*C36 -> 0
A37: BÔNG BÍ TÚI 300GR | D37: =B37*C37 -> 0
A38: BÔNG CẢI TRẮNG | B38: 4 | C38: 10000 | D38: =B38*C38 -> 40000
A39: BÔNG CẢI TRẮNG (CÂY) | D39: =B39*C39 -> 0
A40: BÔNG CẢI XANH 10P | D40: =B40*C40 -> 0
...

Sheet 22.2
A1: hàng tồn cuối ngày 22/2
A2: TÊN SẢN PHẨM | B2: TỒN TRƯỚC | C2: GIÁ NHẬP | D2: THÀNH TIỀN
A3: CÀ CHUA SÔCOLA 250GR (HỘP) VR | D3: =B3*C3 -> 0
A4: CÀ CHUA SÔCOLA 250GR (KG) -NA | D4: =B4*C4 -> 0
A5: CÀ CHUA SÔCOLA 250GR (KG) VR | D5: =B5*C5 -> 0
A6: CÀ CHUA SÔCOLA 250GR(KG) KQ | D6: =B6*C6 -> 0
A7: CÀ CHUA SÔCOLA 300GR (HỘP) VR | D7: =B7*C7 -> 0
A8: CÀ CHUA SOCOLA XÁ | D8: =B8*C8 -> 0
A9: CÀ CHUA SÔCOLA(HỘP) KQ | D9: =B9*C9 -> 0
A10: CÀ RỐT BABY | D10: =B10*C10 -> 0
A11: CÀ RỐT BABY (KG) KQ | D11: =B11*C11 -> 0
A12: CÀ RỐT BABY 200GR | D12: =B12*C12 -> 0
A13: CẢI CẦU VỒNG | D13: =B13*C13 -> 0
A14: CẢI CẦU VỒNG 300GR | D14: =B14*C14 -> 0
A15: CẢI KALE | D15: =B15*C15 -> 0
A16: CẢI KALE 300GR | B16: 15 | C16: 3000 | D16: =B16*C16 -> 45000
A17: CHANH VÀNG (KG) | D17: =B17*C17 -> 0
A18: CHANH VÀNG TRÁI 180UP | D18: =B18*C18 -> 0
A19: CẦN TÂY (KG) | D19: =B19*C19 -> 0
A20: CẦN TÂY THUỶ CANH | D20: =B20*C20 -> 0
A21: CẦN TÂY(CÂY) | D21: =B21*C21 -> 0
A22: ỚT CHUÔNG 3 MÀU(KG)VR | D22: =B22*C22 -> 0
A23: ỚT CHUÔNG ĐỎ | B23: =8+50+60 -> 118 | C23: 26000 | D23: =B23*C23 -> 3068000
A24: ỚT CHUÔNG ĐỎ L1 | B24: 2 | C24: 23000 | D24: =B24*C24 -> 46000
A25: ỚT CHUÔNG ĐỎ(TRÁI) | D25: =B25*C25 -> 0
A26: ỚT CHUÔNG 3 MÀU 350G | B26: 33 | C26: 9000 | D26: =B26*C26 -> 297000
A27: ỚT CHUÔNG 3 MÀU KQ(KG) | D27: =B27*C27 -> 0
A28: ỚT CHUÔNG VÀNG | B28: 20 | C28: 26000 | D28: =B28*C28 -> 520000
A29: ỚT CHUÔNG VÀNG L1 | D29: =B29*C29 -> 0
A30: ỚT CHUÔNG VÀNG(TRÁI) | D30: =B30*C30 -> 0
A31: ỚT CHUÔNG VÀNG+ XANH (VỈ) | D31: =B31*C31 -> 0
A32: ỚT CHUÔNG XANH | B32: =5+10+20+20+20 -> 75 | C32: 22000 | D32: =B32*C32 -> 1650000
A33: ỚT CHUÔNG XANH L1 | B33: 2 | C33: 18000 | D33: =B33*C33 -> 36000
A34: ỚT CHUÔNG XANH(TRÁI) | D34: =B34*C34 -> 0
A35: CỦ DỀN | B35: 96 | C35: 12000 | D35: =B35*C35 -> 1152000
A36: CỦ DỀN 600G | D36: =B36*C36 -> 0
A37: GỪNG 250GR | D37: =B37*C37 -> 0
A38: HỒNG GIÒN | D38: =B38*C38 -> 0
A39: XÀ LÁCH MỸ | D39: =B39*C39 -> 0
A40: KHOAI TÂY HỒNG | B40: 47 | C40: 18000 | D40: =B40*C40 -> 846000
...

Sheet 23.2
A1: hàng tồn cuối ngày 23/2
A2: TÊN SẢN PHẨM | B2: TỒN TRƯỚC | C2: GIÁ NHẬP | D2: THÀNH TIỀN
A3: CÀ CHUA SÔCOLA 250GR (HỘP) VR | B3: 22 | C3: 5000 | D3: =B3*C3 -> 110000
A4: CÀ CHUA SÔCOLA 250GR (KG) -NA | D4: =B4*C4 -> 0
A5: CÀ CHUA SÔCOLA 250GR (KG) VR | D5: =B5*C5 -> 0
A6: CÀ CHUA SÔCOLA 250GR(KG) KQ | D6: =B6*C6 -> 0
A7: CÀ CHUA SÔCOLA 300GR (HỘP) VR | D7: =B7*C7 -> 0
A8: CÀ CHUA SOCOLA XÁ | D8: =B8*C8 -> 0
A9: CÀ CHUA SÔCOLA(HỘP) KQ | D9: =B9*C9 -> 0
A10: CÀ RỐT BABY | D10: =B10*C10 -> 0
A11: CÀ RỐT BABY (KG) KQ | D11: =B11*C11 -> 0
A12: CÀ RỐT BABY 200GR | D12: =B12*C12 -> 0
A13: CẢI CẦU VỒNG | D13: =B13*C13 -> 0
A14: CẢI CẦU VỒNG 300GR | D14: =B14*C14 -> 0
A15: CẢI KALE | D15: =B15*C15 -> 0
... A18: CHANH VÀNG TRÁI 180UP | D18: =B18*C18 -> 0
A19: CẦN TÂY (KG) | B19: 8 | C19: 9000 | D19: =B19*C19 -> 72000
A20: CẦN TÂY THUỶ CANH | D20: =B20*C20 -> 0
A21: CẦN TÂY(CÂY) | D21: =B21*C21 -> 0
A22: ỚT CHUÔNG 3 MÀU(KG)VR | D22: =B22*C22 -> 0
A23: ỚT CHUÔNG ĐỎ | B23: =10+6+15+15+25+7 -> 78 | C23: 26000 | D23: =B23*C23 -> 2028000
A24: ỚT CHUÔNG ĐỎ L1 | D24: =B24*C24 -> 0
A25: ỚT CHUÔNG ĐỎ(TRÁI) | D25: =B25*C25 -> 0
A26: ỚT CHUÔNG 3 MÀU 350G | D26: =B26*C26 -> 0
A27: ỚT CHUÔNG 3 MÀU KQ(KG) | D27: =B27*C27 -> 0
A28: ỚT CHUÔNG VÀNG | B28: 32 | C28: 26000 | D28: =B28*C28 -> 832000
A29: ỚT CHUÔNG VÀNG L1 | D29: =B29*C29 -> 0
A30: ỚT CHUÔNG VÀNG(TRÁI) | D30: =B30*C30 -> 0
A31: ỚT CHUÔNG VÀNG+ XANH (VỈ) | D31: =B31*C31 -> 0
A32: ỚT CHUÔNG XANH | B32: =30+18+20+14 -> 82 | C32: 22000 | D32: =B32*C32 -> 1804000
A33: ỚT CHUÔNG XANH L1 | D33: =B33*C33 -> 0
A34: ỚT CHUÔNG XANH(TRÁI) | D34: =B34*C34 -> 0
A35: CỦ DỀN | B35: =10+10+34 -> 54 | C35: 12000 | D35: =B35*C35 -> 648000
A36: CỦ DỀN 600G | D36: =B36*C36 -> 0
A37: GỪNG 250GR | D37: =B37*C37 -> 0
A38: HỒNG GIÒN | D38: =B38*C38 -> 0
A39: XÀ LÁCH MỸ | D39: =B39*C39 -> 0
A40: KHOAI TÂY HỒNG | B40: 20 | C40: 18000 | D40: =B40*C40 -> 360000
A41: KHOAI TÂY HỒNG TÚI LƯỚI 500G | D41: =B41*C41 -> 0
A42: KHOAI TÂY VÀNG | D42: =B42*C42 -> 0
...

Sheet 24.2
A1: hàng tồn cuối ngày 24/2
A2: TÊN SẢN PHẨM | B2: TỒN TRƯỚC | C2: GIÁ NHẬP | D2: THÀNH TIỀN
A3: CÀ CHUA SÔCOLA 250GR (HỘP) VR | B3: 9 | C3: 5000 | D3: =B3*C3 -> 45000
A4: CÀ CHUA SÔCOLA 250GR (KG) -NA | D4: =B4*C4 -> 0
A5: CÀ CHUA SÔCOLA 250GR (KG) VR | D5: =B5*C5 -> 0
A6: CÀ CHUA SÔCOLA 250GR(KG) KQ | D6: =B6*C6 -> 0
A7: CÀ CHUA SÔCOLA 300GR (HỘP) VR | D7: =B7*C7 -> 0
A8: CÀ CHUA SOCOLA XÁ | D8: =B8*C8 -> 0
A9: CÀ CHUA SÔCOLA(HỘP) KQ | D9: =B9*C9 -> 0
A10: CÀ RỐT BABY | D10: =B10*C10 -> 0
A11: CÀ RỐT BABY (KG) KQ | D11: =B11*C11 -> 0
A12: CÀ RỐT BABY 200GR | B12: 12 | C12: 4000 | D12: =B12*C12 -> 48000
A13: CẢI CẦU VỒNG | D13: =B13*C13 -> 0
A14: CẢI CẦU VỒNG 300GR | D14: =B14*C14 -> 0
A15: CẢI KALE | D15: =B15*C15 -> 0
A16: CẢI KALE 300GR | B16: 10 | C16: 3000 | D16: =B16*C16 -> 30000
A17: CHANH VÀNG (KG) | D17: =B17*C17 -> 0
A18: CHANH VÀNG TRÁI 180UP | D18: =B18*C18 -> 0
A19: CẦN TÂY (KG) | B19: 22 | C19: 9000 | D19: =B19*C19 -> 198000
A20: CẦN TÂY THUỶ CANH | D20: =B20*C20 -> 0
A21: CẦN TÂY(CÂY) | D21: =B21*C21 -> 0
A22: ỚT CHUÔNG 3 MÀU(KG)VR | D22: =B22*C22 -> 0
A23: ỚT CHUÔNG ĐỎ | B23: =40+35+80+40 -> 195 | C23: 26000 | D23: =B23*C23 -> 5070000
A24: ỚT CHUÔNG ĐỎ L1 | D24: =B24*C24 -> 0
A25: ỚT CHUÔNG ĐỎ(TRÁI) | D25: =B25*C25 -> 0
A26: ỚT CHUÔNG 3 MÀU 350G | B26: =60+15+15 -> 90 | C26: 10000 | D26: =B26*C26 -> 900000
A27: ỚT CHUÔNG 3 MÀU KQ(KG) | D27: =B27*C27 -> 0
A28: ỚT CHUÔNG VÀNG | B28: =20+13+40+20+25 -> 118 | C28: 26000 | D28: =B28*C28 -> 3068000
A29: ỚT CHUÔNG VÀNG L1 | D29: =B29*C29 -> 0
A30: ỚT CHUÔNG VÀNG(TRÁI) | D30: =B30*C30 -> 0
A31: ỚT CHUÔNG VÀNG+ XANH (VỈ) | D31: =B31*C31 -> 0
A32: ỚT CHUÔNG XANH | B32: 15 | C32: 22000 | D32: =B32*C32 -> 330000
A33: ỚT CHUÔNG XANH L1 | D33: =B33*C33 -> 0
A34: ỚT CHUÔNG XANH(TRÁI) | D34: =B34*C34 -> 0
A35: CỦ DỀN | B35: 160 | C35: 12000 | D35: =B35*C35 -> 1920000
A36: CỦ DỀN 600G | D36: =B36*C36 -> 0
A37: GỪNG 250GR | D37: =B37*C37 -> 0
A38: HỒNG GIÒN | D38: =B38*C38 -> 0
A39: XÀ LÁCH MỸ | D39: =B39*C39 -> 0
A40: KHOAI TÂY HỒNG | B40: 12 | C40: 18000 | D40: =B40*C40 -> 216000
...

Sheet 25.2
A1: hàng tồn cuối ngày 25/2
A2: TÊN SẢN PHẨM | B2: TỒN TRƯỚC | C2: GIÁ NHẬP | D2: THÀNH TIỀN
A3: CÀ CHUA SÔCOLA 250GR (HỘP) VR | B3: 38 | C3: 5000 | D3: =B3*C3 -> 190000
A4: CÀ CHUA SÔCOLA 250GR (KG) -NA | D4: =B4*C4 -> 0
A5: CÀ CHUA SÔCOLA 250GR (KG) VR | D5: =B5*C5 -> 0
A6: CÀ CHUA SÔCOLA 250GR(KG) KQ | D6: =B6*C6 -> 0
A7: CÀ CHUA SÔCOLA 300GR (HỘP) VR | D7: =B7*C7 -> 0
A8: CÀ CHUA SOCOLA XÁ | D8: =B8*C8 -> 0
A9: CÀ CHUA SÔCOLA(HỘP) KQ | D9: =B9*C9 -> 0
A10: CÀ RỐT BABY | D10: =B10*C10 -> 0
A11: CÀ RỐT BABY (KG) KQ | D11: =B11*C11 -> 0
A12: CÀ RỐT BABY 200GR | D12: =B12*C12 -> 0
A13: CẢI CẦU VỒNG | D13: =B13*C13 -> 0
A14: CẢI CẦU VỒNG 300GR | D14: =B14*C14 -> 0
A15: CẢI KALE | D15: =B15*C15 -> 0
A16: CẢI KALE 300GR | B16: 3 | C16: 3000 | D16: =B16*C16 -> 9000
A17: CHANH VÀNG (KG) | D17: =B17*C17 -> 0
A18: CHANH VÀNG TRÁI 180UP | D18: =B18*C18 -> 0
A19: CẦN TÂY (KG) | B19: 20 | C19: 9000 | D19: =B19*C19 -> 180000
A20: CẦN TÂY THUỶ CANH | D20: =B20*C20 -> 0
A21: CẦN TÂY(CÂY) | D21: =B21*C21 -> 0
A22: ỚT CHUÔNG 3 MÀU(KG)VR | D22: =B22*C22 -> 0
A23: ỚT CHUÔNG ĐỎ | B23: =50+10+40 -> 100 | C23: 28000 | D23: =B23*C23 -> 2800000
A24: ỚT CHUÔNG ĐỎ L1 | D24: =B24*C24 -> 0
A25: ỚT CHUÔNG ĐỎ(TRÁI) | D25: =B25*C25 -> 0
A26: ỚT CHUÔNG 3 MÀU 350G | B26: 40 | C26: 11000 | D26: =B26*C26 -> 440000
A27: ỚT CHUÔNG 3 MÀU KQ(KG) | D27: =B27*C27 -> 0
A28: ỚT CHUÔNG VÀNG | B28: =8+10+20+5+10+15 -> 68 | C28: 28000 | D28: =B28*C28 -> 1904000
A29: ỚT CHUÔNG VÀNG L1 | D29: =B29*C29 -> 0
A30: ỚT CHUÔNG VÀNG(TRÁI) | D30: =B30*C30 -> 0
A31: ỚT CHUÔNG VÀNG+ XANH (VỈ) | D31: =B31*C31 -> 0
A32: ỚT CHUÔNG XANH | B32: =15+7+37 -> 59 | C32: 22000 | D32: =B32*C32 -> 1298000
A33: ỚT CHUÔNG XANH L1 | D33: =B33*C33 -> 0
A34: ỚT CHUÔNG XANH(TRÁI) | D34: =B34*C34 -> 0
A35: CỦ DỀN | B35: 45 | C35: 12000 | D35: =B35*C35 -> 540000
A36: CỦ DỀN 600G | D36: =B36*C36 -> 0
A37: GỪNG 250GR | D37: =B37*C37 -> 0
A38: HỒNG GIÒN | D38: =B38*C38 -> 0
A39: XÀ LÁCH MỸ | D39: =B39*C39 -> 0
A40: KHOAI TÂY HỒNG | D40: =B40*C40 -> 0
...

Sheet 26.2
A1: hàng tồn cuối ngày 26/2
A2: TÊN SẢN PHẨM | B2: TỒN TRƯỚC | C2: GIÁ NHẬP | D2: THÀNH TIỀN
A3: BẮP CẢI TÍM | B3: 6 | C3: 15000 | D3: =B3*C3 -> 90000
A4: BẮP CẢI TÍM (BẮP) | D4: =B4*C4 -> 0
A5: BẮP CẢI TÍM SUSHI | D5: =B5*C5 -> 0
A6: BẮP CẢI TRẮNG | D6: =B6*C6 -> 0
A7: BẮP CẢI TRẮNG (BẮP) | D7: =B7*C7 -> 0
A8: BẮP CẢI TRẮNG MỘC CHÂU | D8: =B8*C8 -> 0
A9: BẮP CẢI TRẮNG SÓI BIỂN | D9: =B9*C9 -> 0
A10: BẮP CẢI TRẮNG SUSHI | D10: =B10*C10 -> 0
A11: BẮP MỸ | D11: =B11*C11 -> 0
A12: BẦU | D12: =B12*C12 -> 0
A13: BÍ ĐAO XANH | D13: =B13*C13 -> 0
A14: BÍ ĐAO XANH 400G | D14: =B14*C14 -> 0
A15: BÍ ĐỎ HỒ LÔ | B15: 6 | C15: 9000 | D15: =B15*C15 -> 54000
A16: BÍ ĐỎ MINI | D16: =B16*C16 -> 0
A17: BÍ ĐỎ NON (KG)KQ | D17: =B17*C17 -> 0
A18: BÍ ĐỎ NON TRÁI VR | D18: =B18*C18 -> 0
A19: BÍ ĐỎ NON( KG) VR | D19: =B19*C19 -> 0
A20: BÍ ĐỎ TRÒN | B20: =45+300+60 -> 405 | C20: 6000 | D20: =B20*C20 -> 2430000
A21: BÍ MINI VÀNG 300GR | D21: =B21*C21 -> 0
A22: BÍ MINI VÀNG KG | D22: =B22*C22 -> 0
A23: BÍ NGÒI VÀNG | D23: =B23*C23 -> 0
A24: BÍ NGÒI VÀNG (TRÁI) | D24: =B24*C24 -> 0
A25: BÍ NGÒI XANH | B25: =10+30+15+15 -> 70 | C25: 8000 | D25: =B25*C25 -> 560000
A26: BÍ NGÒI XANH(TRÁI) | D26: =B26*C26 -> 0
A27: BÍ NHẬT | D27: =B27*C27 -> 0
A28: BƠ 034 | D28: =B28*C28 -> 0
A29: BƠ BOOTH | D29: =B29*C29 -> 0
A30: BƠ SÁP | D30: =B30*C30 -> 0
A31: BÓ XÔI | B31: 6 | C31: 15000 | D31: =B31*C31 -> 90000
A32: BÓ XÔI 300G VR | D32: =B32*C32 -> 0
A33: BÓ XÔI-HN KQ | D33: =B33*C33 -> 0
A34: BÓ XÔI-NA | D34: =B34*C34 -> 0
A35: BÔNG ATISO | D35: =B35*C35 -> 0
A36: BÔNG BÍ | D36: =B36*C36 -> 0
A37: BÔNG BÍ TÚI 300GR | D37: =B37*C37 -> 0
A38: BÔNG CẢI TRẮNG | B38: 4 | C38: 10000 | D38: =B38*C38 -> 40000
A39: BÔNG CẢI TRẮNG (CÂY) | D39: =B39*C39 -> 0
A40: BÔNG CẢI XANH 10P | B40: 50 | C40: 19000 | D40: =B40*C40 -> 950000
...

Sheet 27.2
A1: hàng tồn cuối ngày 27/2
A2: TÊN SẢN PHẨM | B2: TỒN TRƯỚC | C2: GIÁ NHẬP | D2: THÀNH TIỀN
A3: CÀ CHUA SÔCOLA 250GR (HỘP) VR | B3: 2 | C3: 5000 | D3: =B3*C3 -> 10000
A4: CÀ CHUA SÔCOLA 250GR (KG) -NA | D4: =B4*C4 -> 0
A5: CÀ CHUA SÔCOLA 250GR (KG) VR | D5: =B5*C5 -> 0
A6: CÀ CHUA SÔCOLA 250GR(KG) KQ | D6: =B6*C6 -> 0
A7: CÀ CHUA SÔCOLA 300GR (HỘP) VR | D7: =B7*C7 -> 0
A8: CÀ CHUA SOCOLA XÁ | D8: =B8*C8 -> 0
A9: CÀ CHUA SÔCOLA(HỘP) KQ | D9: =B9*C9 -> 0
A10: CÀ RỐT BABY | D10: =B10*C10 -> 0
A11: CÀ RỐT BABY (KG) KQ | D11: =B11*C11 -> 0
A12: CÀ RỐT BABY 200GR | D12: =B12*C12 -> 0
A13: CẢI CẦU VỒNG | D13: =B13*C13 -> 0
A14: CẢI CẦU VỒNG 300GR | B14: 5 | C14: 5500 | D14: =B14*C14 -> 27500
A15: CẢI KALE | D15: =B15*C15 -> 0
A16: CẢI KALE 300GR | D16: =B16*C16 -> 0
A17: CHANH VÀNG (KG) | D17: =B17*C17 -> 0
A18: CHANH VÀNG TRÁI 180UP | D18: =B18*C18 -> 0
A19: CẦN TÂY (KG) | B19: 40 | C19: 8000 | D19: =B19*C19 -> 320000
A20: CẦN TÂY THUỶ CANH | D20: =B20*C20 -> 0
A21: CẦN TÂY(CÂY) | D21: =B21*C21 -> 0
A22: ỚT CHUÔNG 3 MÀU(KG)VR | D22: =B22*C22 -> 0
A23: ỚT CHUÔNG ĐỎ | B23: =40+3+10+40+45 -> 138 | C23: 30000 | D23: =B23*C23 -> 4140000
A24: ỚT CHUÔNG ĐỎ L1 | D24: =B24*C24 -> 0
A25: ỚT CHUÔNG ĐỎ(TRÁI) | D25: =B25*C25 -> 0
A26: ỚT CHUÔNG 3 MÀU 350G | D26: =B26*C26 -> 0
A27: ỚT CHUÔNG 3 MÀU KQ(KG) | D27: =B27*C27 -> 0
A28: ỚT CHUÔNG VÀNG | B28: =20+25+20 -> 65 | C28: 28000 | D28: =B28*C28 -> 1820000
A29: ỚT CHUÔNG VÀNG L1 | D29: =B29*C29 -> 0
A30: ỚT CHUÔNG VÀNG(TRÁI) | D30: =B30*C30 -> 0
A31: ỚT CHUÔNG VÀNG+ XANH (VỈ) | D31: =B31*C31 -> 0
A32: ỚT CHUÔNG XANH | B32: =18+10+8 -> 36 | C32: 22000 | D32: =B32*C32 -> 792000
A33: ỚT CHUÔNG XANH L1 | D33: =B33*C33 -> 0
A34: ỚT CHUÔNG XANH(TRÁI) | D34: =B34*C34 -> 0
A35: CỦ DỀN | B35: =33+60 -> 93 | C35: 12000 | D35: =B35*C35 -> 1116000
A36: CỦ DỀN 600G | D36: =B36*C36 -> 0
A37: GỪNG 250GR | D37: =B37*C37 -> 0
A38: HỒNG GIÒN | D38: =B38*C38 -> 0
A39: XÀ LÁCH MỸ | D39: =B39*C39 -> 0
A40: KHOAI TÂY HỒNG | B40: 40 | C40: 18000 | D40: =B40*C40 -> 720000
...

Sheet 28.2
A1: hàng tồn cuối ngày 28/2
A2: TÊN SẢN PHẨM | B2: TỒN TRƯỚC | C2: GIÁ NHẬP | D2: THÀNH TIỀN
A3: CÀ CHUA SÔCOLA 250GR (HỘP) VR | D3: =B3*C3 -> 0
A4: CÀ CHUA SÔCOLA 250GR (KG) -NA | D4: =B4*C4 -> 0
A5: CÀ CHUA SÔCOLA 250GR (KG) VR | D5: =B5*C5 -> 0
A6: CÀ CHUA SÔCOLA 250GR(KG) KQ | D6: =B6*C6 -> 0
A7: CÀ CHUA SÔCOLA 300GR (HỘP) VR | D7: =B7*C7 -> 0
A8: CÀ CHUA SOCOLA XÁ | D8: =B8*C8 -> 0
A9: CÀ CHUA SÔCOLA(HỘP) KQ | D9: =B9*C9 -> 0
A10: CÀ RỐT BABY | D10: =B10*C10 -> 0
A11: CÀ RỐT BABY (KG) KQ | D11: =B11*C11 -> 0
A12: CÀ RỐT BABY 200GR | D12: =B12*C12 -> 0
A13: CẢI CẦU VỒNG | D13: =B13*C13 -> 0
A14: CẢI CẦU VỒNG 300GR | B14: 14 | C14: 6000 | D14: =B14*C14 -> 84000
A15: CẢI KALE | D15: =B15*C15 -> 0
A16: CẢI KALE 300GR | D16: =B16*C16 -> 0
A17: CHANH VÀNG (KG) | D17: =B17*C17 -> 0
A18: CHANH VÀNG TRÁI 180UP | D18: =B18*C18 -> 0
A19: CẦN TÂY (KG) | B19: 35 | C19: 9000 | D19: =B19*C19 -> 315000
A20: CẦN TÂY THUỶ CANH | D20: =B20*C20 -> 0
A21: CẦN TÂY(CÂY) | D21: =B21*C21 -> 0
A22: ỚT CHUÔNG 3 MÀU(KG)VR | D22: =B22*C22 -> 0
A23: ỚT CHUÔNG ĐỎ | B23: =10+45+15 -> 70 | C23: 34000 | D23: =B23*C23 -> 2380000
A24: ỚT CHUÔNG ĐỎ L1 | D24: =B24*C24 -> 0
A25: ỚT CHUÔNG ĐỎ(TRÁI) | D25: =B25*C25 -> 0
A26: ỚT CHUÔNG 3 MÀU 350G | B26: 15 | C26: 11000 | D26: =B26*C26 -> 165000
A27: ỚT CHUÔNG 3 MÀU KQ(KG) | D27: =B27*C27 -> 0
A28: ỚT CHUÔNG VÀNG | B28: =8+10+7 -> 25 | C28: 30000 | D28: =B28*C28 -> 750000
A29: ỚT CHUÔNG VÀNG L1 | D29: =B29*C29 -> 0
A30: ỚT CHUÔNG VÀNG(TRÁI) | D30: =B30*C30 -> 0
A31: ỚT CHUÔNG VÀNG+ XANH (VỈ) | D31: =B31*C31 -> 0
A32: ỚT CHUÔNG XANH | B32: =20+18+12 -> 50 | C32: 22000 | D32: =B32*C32 -> 1100000
A33: ỚT CHUÔNG XANH L1 | D33: =B33*C33 -> 0
A34: ỚT CHUÔNG XANH(TRÁI) | D34: =B34*C34 -> 0
A35: CỦ DỀN | B35: 70 | C35: 12000 | D35: =B35*C35 -> 840000
A36: CỦ DỀN 600G | D36: =B36*C36 -> 0
A37: GỪNG 250GR | D37: =B37*C37 -> 0
A38: HỒNG GIÒN | D38: =B38*C38 -> 0
A39: XÀ LÁCH MỸ | D39: =B39*C39 -> 0
A40: KHOAI TÂY HỒNG | B40: 18 | C40: 28000 | D40: =B40*C40 -> 504000
...

Sheet 29.2
A1: hàng tồn cuối ngày 29/2 | B1: Stock | D1: Safety stock
A2: TÊN SẢN PHẨM | B2: TỒN TRƯỚC | C2: GIÁ NHẬP | D2: THÀNH TIỀN
A3: CÀ CHUA SÔCOLA 250GR (HỘP) VR | B3: 3 | C3: 5000 | D3: =B3*C3 -> 15000
A4: CÀ CHUA SÔCOLA 250GR (KG) -NA | D4: =B4*C4 -> 0
A5: CÀ CHUA SÔCOLA 250GR (KG) VR | D5: =B5*C5 -> 0
A6: CÀ CHUA SÔCOLA 250GR(KG) KQ | D6: =B6*C6 -> 0
A7: CÀ CHUA SÔCOLA 300GR (HỘP) VR | D7: =B7*C7 -> 0
A8: CÀ CHUA SOCOLA XÁ | D8: =B8*C8 -> 0
A9: CÀ CHUA SÔCOLA(HỘP) KQ | D9: =B9*C9 -> 0
A10: CÀ RỐT BABY | D10: =B10*C10 -> 0
A11: CÀ RỐT BABY (KG) KQ | D11: =B11*C11 -> 0
A12: CÀ RỐT BABY 200GR | D12: =B12*C12 -> 0
A13: CẢI CẦU VỒNG | D13: =B13*C13 -> 0
A14: CẢI CẦU VỒNG 300GR | D14: =B14*C14 -> 0
A15: CẢI KALE | D15: =B15*C15 -> 0
A16: CẢI KALE 300GR | B16: 3 | C16: 4000 | D16: =B16*C16 -> 12000
A17: CHANH VÀNG (KG) | D17: =B17*C17 -> 0
A18: CHANH VÀNG TRÁI 180UP | D18: =B18*C18 -> 0
A19: CẦN TÂY (KG) | B19: 30 | C19: 9000 | D19: =B19*C19 -> 270000
A20: CẦN TÂY THUỶ CANH | D20: =B20*C20 -> 0
A21: CẦN TÂY(CÂY) | D21: =B21*C21 -> 0
A22: ỚT CHUÔNG 3 MÀU(KG)VR | D22: =B22*C22 -> 0
A23: ỚT CHUÔNG ĐỎ | B23: =37+38 -> 75 | C23: 34000 | D23: =B23*C23 -> 2550000
A24: ỚT CHUÔNG ĐỎ L1 | D24: =B24*C24 -> 0
A25: ỚT CHUÔNG ĐỎ(TRÁI) | D25: =B25*C25 -> 0
A26: ỚT CHUÔNG 3 MÀU 350G | D26: =B26*C26 -> 0
A27: ỚT CHUÔNG 3 MÀU KQ(KG) | D27: =B27*C27 -> 0
A28: ỚT CHUÔNG VÀNG | B28: =57+8-7 -> 58 | C28: 30000 | D28: =B28*C28 -> 1740000
A29: ỚT CHUÔNG VÀNG L1 | D29: =B29*C29 -> 0
A30: ỚT CHUÔNG VÀNG(TRÁI) | D30: =B30*C30 -> 0
A31: ỚT CHUÔNG VÀNG+ XANH (VỈ) | D31: =B31*C31 -> 0
A32: ỚT CHUÔNG XANH | B32: =10+18+20 -> 48 | C32: 25000 | D32: =B32*C32 -> 1200000
A33: ỚT CHUÔNG XANH L1 | D33: =B33*C33 -> 0
A34: ỚT CHUÔNG XANH(TRÁI) | D34: =B34*C34 -> 0
A35: CỦ DỀN | B35: 78 | C35: 11000 | D35: =B35*C35 -> 858000
A36: CỦ DỀN 600G | D36: =B36*C36 -> 0
A37: GỪNG 250GR | D37: =B37*C37 -> 0
A38: HỒNG GIÒN | D38: =B38*C38 -> 0
A39: XÀ LÁCH MỸ | D39: =B39*C39 -> 0
A40: KHOAI TÂY HỒNG | D40: =B40*C40 -> 0
...
