Workbook

Sheet 1.12
A1: hàng tồn cuối ngày 1/12
A2: Tên Sản phẩm | B2: ĐVT | C2: tồn | D2: giá | E2: thành tiền
A3: Cà Rốt | B3: Kg | C3: 315 | D3: 13500 | E3: =C3*D3 -> 4252500
A4: Cà Rốt | B4: Túi | C4: 0 | E4: =C4*D4 -> 0
A5: Cà Rốt Baby | B5: Kg | C5: 0 | E5: =C5*D5 -> 0
A6: Cà Rốt Baby | B6: Vỉ | C6: 19 | D6: 8000 | E6: =C6*D6 -> 152000
A7: Củ Cải Đỏ | B7: Hộp | C7: 3 | D7: 9500 | E7: =C7*D7 -> 28500
A8: Củ Cải Đỏ | B8: Kg | C8: 0 | E8: =C8*D8 -> 0
A9: Củ Dền | B9: Kg | C9: 0 | E9: =C9*D9 -> 0
A10: Củ Dền | B10: Túi | C10: 0 | E10: =C10*D10 -> 0
A11: Củ Hành Tây | B11: Kg | C11: 0 | E11: =C11*D11 -> 0
A12: Củ Hành Tây | B12: Túi 300gr | C12: 0 | E12: =C12*D12 -> 0
A13: Củ Hành Tây Trung | B13: Túi | C13: 430 | D13: 4500 | E13: =C13*D13 -> 1935000
A14: Củ Khoai Lang Mật Size 46 | B14: Kg | C14: 0 | E14: =C14*D14 -> 0
A15: Củ Khoai Lang Nhật | B15: Kg | C15: 0 | E15: =C15*D15 -> 0
A16: Củ Khoai Tây Vàng | B16: Kg | C16: 290 | D16: 15000 | E16: =C16*D16 -> 4350000
A17: Củ Khoai Tây Vàng | B17: Túi | C17: 0 | E17: =C17*D17 -> 0
A18: Bông Cải Xanh Baby | B18: Vỉ | C18: 0 | E18: =C18*D18 -> 0
A19: Bắp Cải Trắng | B19: Kg | C19: 450 | D19: 11000 | E19: =C19*D19 -> 4950000
A20: Cải Bó Xôi | B20: Kg | C20: 10 | D20: 14000 | E20: =C20*D20 -> 140000
A21: Cải Bó Xôi | B21: Túi | C21: 0 | E21: =C21*D21 -> 0
A22: Cải Kale | B22: Kg | C22: 0 | E22: =C22*D22 -> 0
A23: Cải Kale | B23: Túi | C23: 0 | E23: =C23*D23 -> 0
A24: Cải Thảo | B24: Kg | C24: 350 | D24: 6000 | E24: =C24*D24 -> 2100000
A25: Cần Tây | B25: Cây | C25: 0 | E25: =C25*D25 -> 0
A26: Cần Tây | B26: Kg | C26: 20 | D26: 17000 | E26: =C26*D26 -> 340000
A27: Xà Lách Lolo Xanh T.C | B27: Kg | C27: 6 | D27: 28000 | E27: =C27*D27 -> 168000
A28: Bí Đỏ Tròn | B28: Kg | C28: 720 | D28: 4300 | E28: =C28*D28 -> 3096000
A29: Bí Ngòi Xanh | B29: Kg | C29: 128 | D29: 8000 | E29: =C29*D29 -> 1024000
A30: Bí Ngòi Xanh | B30: Trái | C30: 0 | E30: =C30*D30 -> 0
A31: Bí Non Nhật | B31: Kg | C31: 98 | D31: 10000 | E31: =C31*D31 -> 980000
A32: Bí Non Nhật | B32: Trái | C32: 0 | E32: =C32*D32 -> 0
A33: Cà Chua Beef | B33: Kg | C33: 21 | D33: 21000 | E33: =C33*D33 -> 441000
A34: Cà Chua Beef | B34: Vỉ | C34: 0 | E34: =C34*D34 -> 0
A35: Cà Chua Beef | B35: Vỉ 650gr | C35: 0 | E35: =C35*D35 -> 0
A36: Cà Chua Thường | B36: Kg | C36: 120 | D36: 20000 | E36: =C36*D36 -> 2400000
A37: Cà Chua Thường | B37: Vỉ | C37: 0 | E37: =C37*D37 -> 0
A38: Cà Chua Thường Trung | B38: Túi | C38: 80 | D38: 16000 | E38: =C38*D38 -> 1280000
A39: Dưa Leo Baby | B39: Kg | C39: 31 | D39: 6000 | E39: =C39*D39 -> 186000
A40: Dưa Leo Baby | B40: Vỉ | C40: 383 | D40: 5000 | E40: =C40*D40 -> 1915000
...

Sheet 2.12
A1: hàng tồn cuối ngày 2/12
A2: Tên Sản phẩm | B2: ĐVT | C2: tồn | D2: giá | E2: thành tiền
A3: Cà Rốt | B3: Kg | C3: 320 | D3: 13500 | E3: =C3*D3 -> 4320000
A4: Cà Rốt | B4: Túi | C4: 0 | E4: =C4*D4 -> 0
A5: Cà Rốt Baby | B5: Vỉ | C5: 0 | E5: =C5*D5 -> 0
A6: Củ Cải Đỏ | B6: Hộp | C6: 23 | D6: 9500 | E6: =C6*D6 -> 218500
A7: Củ Dền | B7: Kg | C7: 0 | E7: =C7*D7 -> 0
A8: Củ Dền | B8: Túi | C8: 0 | E8: =C8*D8 -> 0
A9: Củ Hành Tây | B9: Kg | C9: 440 | D9: 22500 | E9: =C9*D9 -> 9900000
A10: Củ Hành Tây | B10: Túi 300gr | C10: 0 | E10: =C10*D10 -> 0
A11: Củ Hành Tây Trung | B11: Túi | C11: 360 | D11: 4500 | E11: =C11*D11 -> 1620000
A12: Củ Khoai Lang Mật Size 46 | B12: Kg | C12: 45 | D12: 31000 | E12: =C12*D12 -> 1395000
A13: Củ Khoai Lang Nhật | B13: Kg | C13: 0 | E13: =C13*D13 -> 0
A14: Củ Khoai Tây Vàng | B14: Kg | C14: 190 | D14: 15000 | E14: =C14*D14 -> 2850000
A15: Củ Khoai Tây Vàng | B15: Túi | C15: 0 | E15: =C15*D15 -> 0
A16: Bông Cải Xanh Baby | B16: Vỉ | C16: 0 | E16: =C16*D16 -> 0
A17: Bắp Cải Trắng | B17: Kg | C17: 1115 | D17: 11000 | E17: =C17*D17 -> 12265000
A18: Cải Bó Xôi | B18: Kg | C18: 0 | E18: =C18*D18 -> 0
A19: Cải Bó Xôi | B19: Túi | C19: 0 | E19: =C19*D19 -> 0
A20: Cải Kale | B20: Kg | C20: 1 | D20: 23000 | E20: =C20*D20 -> 23000
A21: Cải Kale | B21: Túi | C21: 0 | E21: =C21*D21 -> 0
A22: Cải Thảo | B22: Kg | C22: 400 | D22: 6000 | E22: =C22*D22 -> 2400000
A23: Cần Tây | B23: Cây | C23: 0 | E23: =C23*D23 -> 0
A24: Cần Tây | B24: Kg | C24: 80 | D24: 17000 | E24: =C24*D24 -> 1360000
A25: Xà Lách Lolo Xanh T.C | B25: Kg | C25: 0 | E25: =C25*D25 -> 0
A26: Bí Đỏ Tròn | B26: Kg | C26: 0 | E26: =C26*D26 -> 0
A27: Bí Ngòi Xanh | B27: Kg | C27: 45 | D27: 8000 | E27: =C27*D27 -> 360000
A28: Bí Ngòi Xanh | B28: Trái | C28: 0 | E28: =C28*D28 -> 0
A29: Bí Non Nhật | B29: Kg | C29: 73 | D29: 10000 | E29: =C29*D29 -> 730000
A30: Bí Non Nhật | B30: Trái | C30: 0 | E30: =C30*D30 -> 0
A31: Cà Chua Beef | B31: Kg | C31: 145 | D31: 21000 | E31: =C31*D31 -> 3045000
A32: Cà Chua Beef | B32: Vỉ | C32: 0 | E32: =C32*D32 -> 0
A33: Cà Chua Beef | B33: Vỉ 650gr | C33: 0 | E33: =C33*D33 -> 0
A34: Cà Chua Thường | B34: Kg | C34: 300 | D34: 20000 | E34: =C34*D34 -> 6000000
A35: Cà Chua Thường | B35: Vỉ | C35: 0 | E35: =C35*D35 -> 0
A36: Cà Chua Thường Trung | B36: Túi | C36: 40 | D36: 16000 | E36: =C36*D36 -> 640000
A37: Dưa Leo Baby | B37: Kg | C37: 45 | D37: 6000 | E37: =C37*D37 -> 270000
A38: Dưa Leo Baby | B38: Vỉ | C38: 227 | D38: 5000 | E38: =C38*D38 -> 1135000
A39: Dưa Leo Thường | B39: Kg | C39: 43 | D39: 5000 | E39: =C39*D39 -> 215000
A40: Ớt Chuông Đỏ | B40: Kg | C40: 35 | D40: 30000 | E40: =C40*D40 -> 1050000
...

Sheet 3.12
A1: hàng tồn cuối ngày 3/12 vr
A2: Tên Sản phẩm | B2: ĐVT | C2: tồn | D2: giá | E2: thành tiền
A3: Bắp Cải Tím | B3: Kg | C3: 25 | D3: 30000 | E3: =C3*D3 -> 750000
A4: Bắp Cải Trái Tim | B4: Kg | C4: 45 | D4: 10000 | E4: =C4*D4 -> 450000
A5: Bắp Cải Trắng | B5: Kg | C5: 645 | D5: 10000 | E5: =C5*D5 -> 6450000
A6: Bí Đỏ Hồ Lô | B6: Kg | C6: 0 | E6: =C6*D6 -> 0
A7: Bí Đỏ Tròn | B7: Kg | C7: 1100 | D7: 5500 | E7: =C7*D7 -> 6050000
A8: Bí Ngòi Vàng | B8: Kg | C8: 0 | E8: =C8*D8 -> 0
A9: Bí Ngòi Xanh | B9: Kg | C9: 138 | D9: 9000 | E9: =C9*D9 -> 1242000
A10: Bí Ngòi Xanh | B10: Trái | C10: 0 | E10: =C10*D10 -> 0
A11: Bí Non Nhật | B11: Kg | C11: 74 | D11: 10000 | E11: =C11*D11 -> 740000
A12: Bí Non Nhật | B12: Trái | C12: 0 | E12: =C12*D12 -> 0
A13: Bơ Booth | B13: Kg | C13: 0 | E13: =C13*D13 -> 0
A14: Bông Cải Trắng | B14: Kg | C14: 2 | D14: 15000 | E14: =C14*D14 -> 30000
A15: Bông Cải Xanh 10Cm | B15: Kg | C15: 76 | D15: 26000 | E15: =C15*D15 -> 1976000
A16: Bông Cải Xanh 7Cm | B16: Kg | C16: 3 | D16: 30000 | E16: =C16*D16 -> 90000
A17: Bông Cải Xanh Baby | B17: Vỉ | C17: 12 | D17: 7000 | E17: =C17*D17 -> 84000
A18: Cà Chua Beef | B18: Kg | C18: 30 | D18: 22000 | E18: =C18*D18 -> 660000
A19: Cà Chua Beef | B19: Vỉ | C19: 0 | E19: =C19*D19 -> 0
A20: Cà Chua Beef | B20: Vỉ 650gr | C20: 0 | E20: =C20*D20 -> 0
A21: Cà Chua Beef Trung | B21: Kg | C21: 0 | E21: =C21*D21 -> 0
A22: Cà Chua Beef Trung | B22: Vỉ 500gr | C22: 0 | E22: =C22*D22 -> 0
A23: Cà Chua Bi Đỏ | B23: Kg | C23: 15 | D23: 30000 | E23: =C23*D23 -> 450000
A24: Cà Chua Bi Đỏ | B24: Hộp 300gr | C24: 18 | D24: 9000 | E24: =C24*D24 -> 162000
A25: Cà Chua Bi Mix | B25: Hộp | C25: 5 | D25: 17000 | E25: =C25*D25 -> 85000
A26: Cà Chua Socola | B26: Kg | C26: 5 | D26: 34000 | E26: =C26*D26 -> 170000
A27: Cà Chua Socola | B27: Hộp 250GR | C27: 225 | D27: 10000 | E27: =C27*D27 -> 2250000
A28: Cà Chua Thường | B28: Kg | C28: 460 | D28: 22000 | E28: =C28*D28 -> 10120000
A29: Cà Chua Thường | B29: Vỉ | C29: 0 | E29: =C29*D29 -> 0
A30: Cà Chua Thường Trung | B30: Túi | C30: 110 | D30: 16000 | E30: =C30*D30 -> 1760000
A31: Cà Rốt | B31: Kg | C31: 85 | D31: 13500 | E31: =C31*D31 -> 1147500
A32: Cà Rốt | B32: Túi | C32: 0 | E32: =C32*D32 -> 0
A33: Cà Rốt Baby | B33: Vỉ | C33: 10 | D33: 10000 | E33: =C33*D33 -> 100000
A34: Cà Tím | B34: Kg | C34: 20 | D34: 6000 | E34: =C34*D34 -> 120000
A35: Cà Tím | B35: Cặp | C35: 0 | E35: =C35*D35 -> 0
A36: Cải Bó Xôi | B36: Kg | C36: 0 | E36: =C36*D36 -> 0
A37: Cải Bó Xôi | B37: Túi | C37: 43 | D37: 6000 | E37: =C37*D37 -> 258000
A38: Cải Cầu Vồng | B38: Kg | C38: 0 | E38: =C38*D38 -> 0
A39: Cải Cầu Vồng | B39: Túi | C39: 10 | D39: 6000 | E39: =C39*D39 -> 60000
A40: Cải Kale | B40: Kg | C40: 1 | D40: 23000 | E40: =C40*D40 -> 23000
...

Sheet 4.12
A2: hàng tồn cuối ngày 4/12 vr
A3: Tên Sản phẩm | B3: ĐVT | C3: tồn | D3: giá | E3: thành tiền
A4: Cà Rốt | B4: Kg | C4: 216 | D4: 13000 | E4: =C4*D4 -> 2808000
A5: Cà Rốt | B5: Túi | C5: 0 | E5: =C5*D5 -> 0
A6: Cà Rốt Baby | B6: Vỉ | C6: 0 | E6: =C6*D6 -> 0
A7: Củ Cải Đỏ | B7: Hộp | C7: 30 | D7: 8500 | E7: =C7*D7 -> 255000
A8: Củ Dền | B8: Kg | C8: 15 | D8: 17000 | E8: =C8*D8 -> 255000
A9: Củ Dền | B9: Túi | C9: 0 | E9: =C9*D9 -> 0
A10: Củ Hành Tây | B10: Kg | C10: 55 | D10: 22500 | E10: =C10*D10 -> 1237500
A11: Củ Hành Tây | B11: Túi 300gr | C11: 0 | E11: =C11*D11 -> 0
A12: Củ Hành Tây Trung | B12: Túi | C12: 250 | D12: 4500 | E12: =C12*D12 -> 1125000
A13: Củ Khoai Lang Mật Size 46 | B13: Kg | C13: 0 | E13: =C13*D13 -> 0
A14: Củ Khoai Lang Nhật | B14: Kg | C14: 50 | D14: 17000 | E14: =C14*D14 -> 850000
A15: Củ Khoai Tây Vàng | B15: Kg | C15: 190 | D15: 18000 | E15: =C15*D15 -> 3420000
A16: Củ Khoai Tây Vàng | B16: Túi | C16: 0 | E16: =C16*D16 -> 0
A17: Bông Cải Xanh Baby | B17: Vỉ | C17: 12 | D17: 8000 | E17: =C17*D17 -> 96000
A18: Bắp Cải Trắng | B18: Kg | C18: 1495 | D18: 8000 | E18: =C18*D18 -> 11960000
A19: Cải Bó Xôi | B19: Kg | C19: 0 | E19: =C19*D19 -> 0
A20: Cải Bó Xôi | B20: Túi | C20: 0 | E20: =C20*D20 -> 0
A21: Cải Kale | B21: Túi | C21: 11 | D21: 8000 | E21: =C21*D21 -> 88000
A22: Cải Thảo | B22: Kg | C22: 0 | E22: =C22*D22 -> 0
A23: Cần Tây | B23: Cây | C23: 0 | E23: =C23*D23 -> 0
A24: Cần Tây | B24: Kg | C24: 20 | D24: 16000 | E24: =C24*D24 -> 320000
A25: Xà Lách Lolo Xanh T.C | B25: Kg | C25: 0 | E25: =C25*D25 -> 0
A26: Bí Đỏ Tròn | B26: Kg | C26: 2000 | D26: 5500 | E26: =C26*D26 -> 11000000
A27: Bí Ngòi Xanh | B27: Kg | C27: 43 | D27: 10000 | E27: =C27*D27 -> 430000
A28: Bí Ngòi Xanh | B28: Trái | C28: 0 | E28: =C28*D28 -> 0
A29: Bí Non Nhật | B29: Kg | C29: 53 | D29: 10000 | E29: =C29*D29 -> 530000
A30: Bí Non Nhật | B30: Trái | C30: 0 | E30: =C30*D30 -> 0
A31: Cà Chua Beef | B31: Kg | C31: 7 | D31: 22000 | E31: =C31*D31 -> 154000
A32: Cà Chua Beef | B32: Vỉ | C32: 0 | E32: =C32*D32 -> 0
A33: Cà Chua Beef | B33: Vỉ 650gr | C33: 0 | E33: =C33*D33 -> 0
A34: Cà Chua Thường | B34: Kg | C34: 180 | D34: 22000 | E34: =C34*D34 -> 3960000
A35: Cà Chua Thường | B35: Vỉ | C35: 0 | E35: =C35*D35 -> 0
A36: Cà Chua Thường Trung | B36: Túi | C36: 0 | E36: =C36*D36 -> 0
A37: Dưa Leo Baby | B37: Kg | C37: 45 | D37: 10000 | E37: =C37*D37 -> 450000
A38: Dưa Leo Baby | B38: Vỉ | C38: 990 | D38: 5000 | E38: =C38*D38 -> 4950000
A39: Dưa Leo Thường | B39: Kg | C39: 17 | D39: 6000 | E39: =C39*D39 -> 102000
A40: Ớt Chuông Đỏ | B40: Kg | C40: 77 | D40: 27000 | E40: =C40*D40 -> 2079000
A41: Ớt Chuông Đỏ | B41: Trái | C41: 0 | E41: =C41*D41 -> 0
...

Sheet 5.12
A1: Tên Sản phẩm VR | B1: ĐVT | C1: Tồn ĐL 現在個 | D1: Gía nhập | E1: Thành tiền
A2: Bắp Cải Tím | B2: Kg | C2: 18 | D2: =VLOOKUP(A2,'4.12'!A4:D106,4,) -> 36000 | E2: =+D2*C2 -> 648000
A3: Bắp Cải Trái Tim | B3: Kg | C3: 0 | E3: =+D3*C3 -> 0
A4: Bắp Cải Trắng | B4: Kg | C4: 611 | D4: =VLOOKUP(A4,'4.12'!A6:D108,4,) -> 8000 | E4: =+D4*C4 -> 4888000
A5: Bí Đỏ Hồ Lô | B5: Kg | C5: 0 | E5: =+D5*C5 -> 0
A6: Bí Đỏ Tròn | B6: Kg | C6: 1905 | D6: =VLOOKUP(A6,'4.12'!A8:D110,4,) -> 5500 | E6: =+D6*C6 -> 10477500
A7: Bí Ngòi Vàng | B7: Kg | C7: 0 | E7: =+D7*C7 -> 0
A8: Bí Ngòi Xanh | B8: Kg | C8: 138 | D8: =VLOOKUP(A8,'4.12'!A10:D112,4,) -> 10000 | E8: =+D8*C8 -> 1380000
A9: Bí Ngòi Xanh | B9: Trái | C9: 0 | E9: =+D9*C9 -> 0
A10: Bí Non Nhật | B10: Kg | C10: 18 | D10: =VLOOKUP(A10,'4.12'!A12:D114,4,) -> 10000 | E10: =+D10*C10 -> 180000
A11: Bí Non Nhật | B11: Trái | C11: 0 | E11: =+D11*C11 -> 0
A12: Bơ Booth | B12: Kg | C12: 0 | E12: =+D12*C12 -> 0
A13: Bông Cải Trắng | B13: Kg | C13: 0 | E13: =+D13*C13 -> 0
A14: Bông Cải Xanh 10Cm | B14: Kg | C14: 17 | D14: =VLOOKUP(A14,'4.12'!A16:D118,4,) -> 26000 | E14: =+D14*C14 -> 442000
A15: Bông Cải Xanh 12Cm | B15: Kg | C15: 0 | E15: =+D15*C15 -> 0
A16: Bông Cải Xanh 7Cm | B16: Kg | C16: 50 | D16: 28000 | E16: =+D16*C16 -> 1400000
A17: Bông Cải Xanh Baby | B17: Vỉ | C17: 7 | D17: =40000/5 -> 8000 | E17: =+D17*C17 -> 56000
A18: Cà Chua Beef | B18: Kg | C18: 30 | D18: =VLOOKUP(A18,'4.12'!A20:D122,4,) -> 22000 | E18: =+D18*C18 -> 660000
A19: Cà Chua Beef | B19: Vỉ | C19: 0 | E19: =+D19*C19 -> 0
A20: Cà Chua Beef | B20: Vỉ 650gr | C20: 0 | E20: =+D20*C20 -> 0
A21: Cà Chua Beef Trung | B21: Kg | C21: 50 | D21: 18000 | E21: =+D21*C21 -> 900000
A22: Cà Chua Beef Trung | B22: Vỉ 500gr | C22: 0 | E22: =+D22*C22 -> 0
A23: Cà Chua Bi Đỏ | B23: Kg | C23: 16 | D23: =VLOOKUP(A23,'4.12'!A25:D127,4,) -> 30000 | E23: =+D23*C23 -> 480000
A24: Cà Chua Bi Đỏ | B24: Hộp 300gr | C24: 69 | D24: 9900 | E24: =+D24*C24 -> 683100
A25: Cà Chua Bi Mix | B25: Hộp | C25: 8 | D25: =54000/4 -> 13500 | E25: =+D25*C25 -> 108000
A26: Cà Chua Socola | B26: Kg | C26: 0 | E26: =+D26*C26 -> 0
A27: Cà Chua Socola | B27: Hộp 250GR | C27: 0 | E27: =+D27*C27 -> 0
A28: Cà Chua Thường | B28: Kg | C28: 370 | D28: =VLOOKUP(A28,'4.12'!A30:D132,4,) -> 22000 | E28: =+D28*C28 -> 8140000
A29: Cà Chua Thường | B29: Vỉ | C29: 0 | E29: =+D29*C29 -> 0
A30: Cà Chua Thường Trung | B30: Túi | C30: 50 | D30: 16000 | E30: =+D30*C30 -> 800000
A31: Cà Rốt | B31: Kg | C31: 144 | D31: =VLOOKUP(A31,'4.12'!A33:D135,4,) -> 13000 | E31: =+D31*C31 -> 1872000
A32: Cà Rốt | B32: Túi | C32: 0 | E32: =+D32*C32 -> 0
A33: Cà Rốt Baby | B33: Kg | C33: 0 | E33: =+D33*C33 -> 0
A34: Cà Rốt Baby | B34: Vỉ | C34: 17 | D34: 19400 | E34: =+D34*C34 -> 329800
A35: Cà Tím | B35: Kg | C35: 37 | D35: =VLOOKUP(A35,'4.12'!A37:D139,4,) -> 6500 | E35: =+D35*C35 -> 240500
A36: Cà Tím | B36: Cặp | C36: 0 | E36: =+D36*C36 -> 0
A37: Cải Bó Xôi | B37: Kg | C37: 50 | D37: 17000 | E37: =+D37*C37 -> 850000
A38: Cải Bó Xôi | B38: Túi | C38: 0 | E38: =+D38*C38 -> 0
A39: Cải Cầu Vồng | B39: Kg | C39: 0 | E39: =+D39*C39 -> 0
A40: Cải Cầu Vồng | B40: Túi | C40: 3 | D40: =VLOOKUP(A40,'4.12'!A42:D144,4,) -> 5000 | E40: =+D40*C40 -> 15000
...

Sheet 6.12
A1: Tên Sản phẩm VR | B1: ĐVT | C1: Tồn ĐL 現在個 | D1: Gía nhập | E1: Thành tiền
A2: Bắp Cải Tím | B2: Kg | C2: 25 | D2: 36000 | E2: 900000
A3: Bắp Cải Trái Tim | B3: Kg | C3: 40 | D3: 8000 | E3: 320000
A4: Bắp Cải Trắng | B4: Kg | C4: 615 | D4: 7500 | E4: 4612500
A5: Bí Đỏ Hồ Lô | B5: Kg | C5: 0
A6: Bí Đỏ Tròn | B6: Kg | C6: 1270 | D6: 5000 | E6: 6350000
A7: Bí Ngòi Vàng | B7: Kg | C7: 1 | D7: 35000 | E7: 35000
A8: Bí Ngòi Xanh | B8: Kg | C8: 93 | D8: 10000 | E8: 930000
A9: Bí Ngòi Xanh | B9: Trái | C9: 0
A10: Bí Non Nhật | B10: Kg | C10: 5 | D10: 10000 | E10: 50000
A11: Bí Non Nhật | B11: Trái | C11: 0
A12: Bơ Booth | B12: Kg | C12: 0
A13: Bông Cải Trắng | B13: Kg | C13: 0
A14: Bông Cải Xanh 12Cm | B14: Kg | C14: 5 | D14: 18000 | E14: 90000
A15: Bông Cải Xanh 7Cm | B15: Kg | C15: 0
A16: Bông Cải Xanh Baby | B16: Vỉ | C16: 0
A17: Cà Chua Beef | B17: Kg | C17: 105 | D17: 22000 | E17: 2310000
A18: Cà Chua Beef | B18: Vỉ | C18: 0
A19: Cà Chua Beef | B19: Vỉ 650gr | C19: 0
A20: Cà Chua Beef Trung | B20: Kg | C20: 99 | D20: 20000 | E20: 1980000
A21: Cà Chua Beef Trung | B21: Vỉ 500gr | C21: 0
A22: Cà Chua Bi Đỏ | B22: Kg | C22: 5 | D22: 9000 | E22: 45000
A23: Cà Chua Bi Đỏ | B23: Hộp 300gr | C23: 96 | D23: 9000 | E23: 864000
A24: Cà Chua Bi Mix | B24: Hộp | C24: 0
A25: Cà Chua Socola | B25: Kg | C25: 0
A26: Cà Chua Socola | B26: Hộp 250GR | C26: 45 | D26: =34000/4 -> 8500 | E26: =+D26*C26 -> 382500
A27: Cà Chua Thường | B27: Kg | C27: 170 | D27: 23000 | E27: 3910000
A28: Cà Chua Thường | B28: Vỉ | C28: 0
A29: Cà Chua Thường Trung | B29: Kg | C29: 50 | D29: 18000 | E29: 900000
A30: Cà Chua Thường Trung | B30: Túi | C30: 0
A31: Cà Rốt | B31: Kg | C31: 175 | D31: 12000 | E31: 2100000
A32: Cà Rốt | B32: Túi | C32: 0
A33: Cà Rốt Baby | B33: Vỉ | C33: 19 | D33: 8000 | E33: 152000
A34: Cà Tím | B34: Kg | C34: 48 | D34: 7000 | E34: 336000
A35: Cà Tím | B35: Cặp | C35: 0
A36: Cải Bó Xôi | B36: Kg | C36: 30 | D36: 14000 | E36: 420000
A37: Cải Bó Xôi | B37: Túi | C37: 0
A38: Cải Cầu Vồng | B38: Túi | C38: 14 | D38: 3900 | E38: 54600
A39: Cải Kale | B39: Túi | C39: 0
A40: Cải Thảo | B40: Kg | C40: 460 | D40: 6000 | E40: 2760000
...

Sheet 7.12
A1: Tên Sản phẩm VR | B1: ĐVT | C1: Tồn ĐL 現在個 | D1: Gía nhập | E1: Thành tiền
A2: Bắp Cải Tím | B2: Kg | C2: 20 | D2: 36000 | E2: 720000
A3: Bắp Cải Trái Tim | B3: Kg | C3: 0
A4: Bắp Cải Trắng | B4: Kg | C4: 226 | D4: 7500 | E4: 1695000
A5: Bí Đỏ Hồ Lô | B5: Kg | C5: 0
A6: Bí Đỏ Tròn | B6: Kg | C6: 710 | D6: 5000 | E6: 3550000
A7: Bí Ngòi Xanh | B7: Kg | C7: 150 | D7: 10000 | E7: 1500000
A8: Bí Ngòi Xanh | B8: Trái | C8: 0
A9: Bí Non Nhật | B9: Kg | C9: 38 | D9: 13000 | E9: 494000
A10: Bí Non Nhật | B10: Trái | C10: 0
A11: Bơ Booth | B11: Kg | C11: 0
A12: Bông Cải Trắng | B12: Kg | C12: 6 | D12: 15000 | E12: 90000
A13: Bông Cải Xanh 10Cm | B13: Kg | C13: 5 | D13: 20000 | E13: 100000
A14: Bông Cải Xanh 7Cm | B14: Kg | C14: 0
A15: Bông Cải Xanh Baby | B15: Vỉ | C15: 0
A16: Cà Chua Beef | B16: Kg | C16: 0
A17: Cà Chua Beef | B17: Vỉ | C17: 0
A18: Cà Chua Beef | B18: Vỉ 650gr | C18: 0
A19: Cà Chua Beef Trung | B19: Kg | C19: 75 | D19: 10000 | E19: 750000
A20: Cà Chua Beef Trung | B20: Vỉ 500gr | C20: 0
A21: Cà Chua Bi Đỏ | B21: Kg | C21: 10.5 | D21: 9000 | E21: 94500
A22: Cà Chua Bi Đỏ | B22: Hộp 300gr | C22: 65 | D22: 9000 | E22: 585000
A23: Cà Chua Bi Mix | B23: Hộp | C23: 0
A24: Cà Chua Socola | B24: Kg | C24: 0
A25: Cà Chua Socola | B25: Hộp 250GR | C25: 100 | D25: =34000/4 -> 8500 | E25: =+D25*C25 -> 850000
A26: Cà Chua Thường | B26: Kg | C26: 330 | D26: 19000 | E26: 6270000
A27: Cà Chua Thường | B27: Vỉ | C27: 0
A28: Cà Chua Thường Trung | B28: Túi | C28: 0
A29: Cà Rốt | B29: Kg | C29: 40 | D29: 13000 | E29: 520000
A30: Cà Rốt | B30: Túi | C30: 0
A31: Cà Rốt Baby | B31: Vỉ | C31: 18 | D31: 8000 | E31: 144000
A32: Cà Tím | B32: Kg | C32: 50 | D32: 6000 | E32: 300000
A33: Cà Tím | B33: Cặp | C33: 0
A34: Cải Bó Xôi | B34: Kg | C34: 10 | D34: 14000 | E34: 140000
A35: Cải Bó Xôi | B35: Túi | C35: 0
A36: Cải Cầu Vồng | B36: Túi | C36: 14 | D36: 3900 | E36: 54600
A37: Cải Kale | B37: Túi | C37: 0
A38: Cải Thảo | B38: Kg | C38: 170 | D38: 6000 | E38: 1020000
A39: Cần Tây | B39: Cây | C39: 0
A40: Cần Tây | B40: Kg | C40: 0
...

Sheet 8.12
A1: Tên Sản phẩm VR | B1: ĐVT | C1: Tồn ĐL 現在個 | D1: Gía nhập | E1: Thành tiền
A2: Bắp Cải Tím | B2: Kg | C2: 8 | D2: 36000 | E2: 288000
A3: Bắp Cải Trái Tim | B3: Kg | C3: 50 | D3: 5000 | E3: 250000
A4: Bắp Cải Trắng | B4: Kg | C4: 226 | D4: 7500 | E4: 1695000
A5: Bí Đao Xanh | B5: Kg | C5: 0
A6: Bí Đỏ Hồ Lô | B6: Kg | C6: 0
A7: Bí Đỏ Tròn | B7: Kg | C7: 700 | D7: 5000 | E7: 3500000
A8: Bí Ngòi Vàng | B8: Kg | C8: 0
A9: Bí Ngòi Xanh | B9: Kg | C9: 102 | D9: 8000 | E9: 816000
A10: Bí Ngòi Xanh | B10: Trái | C10: 0
A11: Bí Non Nhật | B11: Kg | C11: 20 | D11: 10000 | E11: 200000
A12: Bí Non Nhật | B12: Trái | C12: 0
A13: Bơ Booth | B13: Kg | C13: 0
A14: Bông Cải Trắng | B14: Kg | C14: 0
A15: Bông Cải Xanh 10Cm | B15: Kg | C15: 0
A16: Bông Cải Xanh 7Cm | B16: Kg | C16: 0
A17: Bông Cải Xanh Baby | B17: Vỉ | C17: 0
A18: Cà Chua Beef | B18: Kg | C18: 207 | D18: 23000 | E18: 4761000
A19: Cà Chua Beef | B19: Vỉ | C19: 0
A20: Cà Chua Beef | B20: Vỉ 650gr | C20: 0
A21: Cà Chua Beef Trung | B21: Kg | C21: 0
A22: Cà Chua Beef Trung | B22: Vỉ 500gr | C22: 22 | D22: 18000 | E22: 396000
A23: Cà Chua Bi Đỏ | B23: Kg | C23: 10.5 | D23: 9000 | E23: 94500
A24: Cà Chua Bi Đỏ | B24: Hộp 300gr | C24: 107 | D24: 9000 | E24: 963000
A25: Cà Chua Bi Mix | B25: Hộp | C25: 0
A26: Cà Chua Socola | B26: Kg | C26: 7 | D26: 38000 | E26: 266000
A27: Cà Chua Socola | B27: Hộp 250GR | C27: 272 | D27: =38000/4 -> 9500 | E27: =+D27*C27 -> 2584000
A28: Cà Chua Thường | B28: Kg | C28: 150 | D28: 22000 | E28: 3300000
A29: Cà Chua Thường | B29: Vỉ | C29: 0
A30: Cà Chua Thường Trung | B30: Túi | C30: 0
A31: Cà Rốt | B31: Kg | C31: 180 | D31: 13000 | E31: 2340000
A32: Cà Rốt | B32: Túi | C32: 0
A33: Cà Rốt Baby | B33: Kg | C33: 0
A34: Cà Rốt Baby | B34: Vỉ | C34: 14 | D34: 8400 | E34: 117600
A35: Cà Tím | B35: Kg | C35: 10 | D35: 6000 | E35: 60000
A36: Cà Tím | B36: Cặp | C36: 0
A37: Cải Bó Xôi | B37: Kg | C37: 20 | D37: 14000 | E37: 280000
A38: Cải Bó Xôi | B38: Túi | C38: 0
A39: Cải Cầu Vồng | B39: Kg | C39: 0
A40: Cải Cầu Vồng | B40: Túi | C40: 14 | D40: 3900 | E40: 54600
...

Sheet 9.12
A1: hàng tồn cuối ngày 9/12 vr
A2: Tên Sản phẩm | B2: ĐVT | C2: tồn | D2: giá | E2: thành tiền
A3: Cà Rốt | B3: Kg | C3: 0 | E3: =C3*D3 -> 0
A4: Cà Rốt | B4: Túi | C4: 0 | E4: =C4*D4 -> 0
A5: Cà Rốt Baby | B5: Vỉ | C5: 8 | D5: 8000 | E5: =C5*D5 -> 64000
A6: Củ Cải Đỏ | B6: Hộp | C6: 20 | D6: 7000 | E6: =C6*D6 -> 140000
A7: Củ Dền | B7: Kg | C7: 17 | D7: 14000 | E7: =C7*D7 -> 238000
A8: Củ Dền | B8: Túi | C8: 0 | E8: =C8*D8 -> 0
A9: Củ Hành Tây | B9: Kg | C9: 366 | D9: 20500 | E9: =C9*D9 -> 7503000
A10: Củ Hành Tây | B10: Túi 300gr | C10: 0 | E10: =C10*D10 -> 0
A11: Củ Hành Tây Trung | B11: Túi | C11: 133 | D11: 6000 | E11: =C11*D11 -> 798000
A12: Củ Khoai Lang Mật Size 46 | B12: Kg | C12: 975 | D12: 24000 | E12: =C12*D12 -> 23400000
A13: Củ Khoai Lang Mật Size 46 | B13: Túi | C13: 0 | E13: =C13*D13 -> 0
A14: Củ Khoai Lang Nhật | B14: Kg | C14: 60 | D14: 17000 | E14: =C14*D14 -> 1020000
A15: Củ Khoai Tây Vàng | B15: Kg | C15: 350 | D15: 17000 | E15: =C15*D15 -> 5950000
A16: Củ Khoai Tây Vàng | B16: Túi | C16: 0 | E16: =C16*D16 -> 0
A17: Bông Cải Xanh Baby | B17: Vỉ | C17: 0 | E17: =C17*D17 -> 0
A18: Bắp Cải Trắng | B18: Kg | C18: 250 | D18: 7500 | E18: =C18*D18 -> 1875000
A19: Cải Bó Xôi | B19: Kg | C19: 0 | E19: =C19*D19 -> 0
A20: Cải Bó Xôi | B20: Túi | C20: 0 | E20: =C20*D20 -> 0
A21: Cải Kale | B21: Túi | C21: 24 | D21: 5000 | E21: =C21*D21 -> 120000
A22: Cải Thảo | B22: Kg | C22: 0 | E22: =C22*D22 -> 0
A23: Cần Tây | B23: Cây | C23: 0 | E23: =C23*D23 -> 0
A24: Cần Tây | B24: Kg | C24: 0 | E24: =C24*D24 -> 0
A25: Xà Lách Lolo Xanh T.C | B25: Kg | C25: 27 | D25: 28000 | E25: =C25*D25 -> 756000
A26: Bí Đỏ Tròn | B26: Kg | C26: 520 | D26: 5000 | E26: =C26*D26 -> 2600000
A27: Bí Ngòi Xanh | B27: Kg | C27: 45 | D27: 10000 | E27: =C27*D27 -> 450000
A28: Bí Ngòi Xanh | B28: Trái | C28: 0 | E28: =C28*D28 -> 0
A29: Bí Non Nhật | B29: Kg | C29: 79 | D29: 10000 | E29: =C29*D29 -> 790000
A30: Bí Non Nhật | B30: Trái | C30: 0 | E30: =C30*D30 -> 0
A31: Cà Chua Beef | B31: Kg | C31: 140 | D31: 24000 | E31: =C31*D31 -> 3360000
A32: Cà Chua Beef | B32: Vỉ | C32: 0 | E32: =C32*D32 -> 0
A33: Cà Chua Beef | B33: Vỉ 650gr | C33: 0 | E33: =C33*D33 -> 0
A34: Cà Chua Thường | B34: Kg | C34: 650 | D34: 22000 | E34: =C34*D34 -> 14300000
A35: Cà Chua Thường | B35: Vỉ | C35: 0 | E35: =C35*D35 -> 0
A36: Cà Chua Thường Trung | B36: Túi | C36: 40 | D36: 16000 | E36: =C36*D36 -> 640000
A37: Dưa Leo Baby | B37: Kg | C37: 0 | E37: =C37*D37 -> 0
A38: Dưa Leo Baby | B38: Vỉ | C38: 462 | D38: 5000 | E38: =C38*D38 -> 2310000
A39: Dưa Leo Thường | B39: Kg | C39: 13 | D39: 6000 | E39: =C39*D39 -> 78000
A40: Ớt Chuông Đỏ | B40: Kg | C40: 95 | D40: 28000 | E40: =C40*D40 -> 2660000
...

Sheet 10.12
A1: hàng tồn cuối ngày 10/12 vr
A2: Tên Sản phẩm | B2: ĐVT | C2: tồn | D2: giá | E2: thành tiền
A3: Cà Rốt | B3: Kg | C3: 60 | D3: 13000 | E3: =C3*D3 -> 780000
A4: Cà Rốt | B4: Túi | C4: 0 | E4: =C4*D4 -> 0
A5: Cà Rốt Baby | B5: Kg | C5: 0 | E5: =C5*D5 -> 0
A6: Cà Rốt Baby | B6: Vỉ | C6: 15 | D6: 8000 | E6: =C6*D6 -> 120000
A7: Củ Cải Đỏ | B7: Hộp | C7: 13 | D7: 7000 | E7: =C7*D7 -> 91000
A8: Củ Cải Đỏ | B8: Kg | C8: 0 | E8: =C8*D8 -> 0
A9: Củ Dền | B9: Kg | C9: 35 | D9: 12000 | E9: =C9*D9 -> 420000
A10: Củ Dền | B10: Túi | C10: 0 | E10: =C10*D10 -> 0
A11: Củ Hành Tây | B11: Kg | C11: 185 | D11: 20500 | E11: =C11*D11 -> 3792500
A12: Củ Hành Tây | B12: Túi 300gr | C12: 0 | E12: =C12*D12 -> 0
A13: Củ Hành Tây Trung | B13: Túi | C13: 0 | E13: =C13*D13 -> 0
A14: Củ Khoai Lang Mật Size 46 | B14: Kg | C14: 930 | D14: 24000 | E14: =C14*D14 -> 22320000
A15: Củ Khoai Lang Nhật | B15: Kg | C15: 35 | D15: 16000 | E15: =C15*D15 -> 560000
A16: Củ Khoai Tây Vàng | B16: Kg | C16: 280 | D16: 17000 | E16: =C16*D16 -> 4760000
A17: Củ Khoai Tây Vàng | B17: Túi | C17: 0 | E17: =C17*D17 -> 0
A18: Bông Cải Xanh Baby | B18: Vỉ | C18: 15 | D18: 8000 | E18: =C18*D18 -> 120000
A19: Bắp Cải Trắng | B19: Kg | C19: 220 | D19: 7500 | E19: =C19*D19 -> 1650000
A20: Cải Bó Xôi | B20: Kg | C20: 0 | E20: =C20*D20 -> 0
A21: Cải Bó Xôi | B21: Túi | C21: 0 | E21: =C21*D21 -> 0
A22: Cải Kale | B22: Túi | C22: 11 | D22: 5000 | E22: =C22*D22 -> 55000
A23: Cải Thảo | B23: Kg | C23: 0 | E23: =C23*D23 -> 0
A24: Cần Tây | B24: Cây | C24: 0 | E24: =C24*D24 -> 0
A25: Cần Tây | B25: Kg | C25: 110 | D25: 16000 | E25: =C25*D25 -> 1760000
A26: Xà Lách Lolo Xanh T.C | B26: Kg | C26: 0 | E26: =C26*D26 -> 0
A27: Bí Đỏ Tròn | B27: Kg | C27: 405 | D27: 5000 | E27: =C27*D27 -> 2025000
A28: Bí Ngòi Xanh | B28: Kg | C28: 130 | D28: 11000 | E28: =C28*D28 -> 1430000
A29: Bí Ngòi Xanh | B29: Trái | C29: 0 | E29: =C29*D29 -> 0
A30: Bí Non Nhật | B30: Kg | C30: 55 | D30: 10000 | E30: =C30*D30 -> 550000
A31: Bí Non Nhật | B31: Trái | C31: 0 | E31: =C31*D31 -> 0
A32: Cà Chua Beef | B32: Kg | C32: 172 | D32: 24000 | E32: =C32*D32 -> 4128000
A33: Cà Chua Beef | B33: Vỉ | C33: 0 | E33: =C33*D33 -> 0
A34: Cà Chua Beef | B34: Vỉ 650gr | C34: 0 | E34: =C34*D34 -> 0
A35: Cà Chua Thường | B35: Kg | C35: 410 | D35: 24000 | E35: =C35*D35 -> 9840000
A36: Cà Chua Thường | B36: Vỉ | C36: 0 | E36: =C36*D36 -> 0
A37: Cà Chua Thường Trung | B37: Túi | C37: 70 | D37: 20000 | E37: =C37*D37 -> 1400000
A38: Dưa Leo Baby | B38: Kg | C38: 0 | E38: =C38*D38 -> 0
A39: Dưa Leo Baby | B39: Vỉ | C39: 434 | D39: 5000 | E39: =C39*D39 -> 2170000
A40: Dưa Leo Thường | B40: Kg | C40: 2 | D40: 7000 | E40: =C40*D40 -> 14000
...

Sheet 11.12
A1: hàng tồn cuối ngày 11/12 vr
A2: Tên Sản phẩm | B2: ĐVT | C2: tồn | D2: giá | E2: thành tiền
A3: Cà Rốt | B3: Kg | C3: 0 | E3: =C3*D3 -> 0
A4: Cà Rốt | B4: Túi | C4: 0 | E4: =C4*D4 -> 0
A5: Củ Cải Đỏ | B5: Hộp | C5: 9 | D5: 6500 | E5: =C5*D5 -> 58500
A6: Củ Dền | B6: Kg | C6: 30 | D6: 12000 | E6: =C6*D6 -> 360000
A7: Củ Dền | B7: Túi | C7: 0 | E7: =C7*D7 -> 0
A8: Củ Hành Tây | B8: Kg | C8: 290 | D8: 19000 | E8: =C8*D8 -> 5510000
A9: Củ Hành Tây | B9: Túi 300gr | C9: 0 | E9: =C9*D9 -> 0
A10: Củ Hành Tây Trung | B10: Túi | C10: 220 | D10: 6000 | E10: =C10*D10 -> 1320000
A11: Củ Khoai Lang Mật Size 46 | B11: Kg | C11: 690 | D11: 24000 | E11: =C11*D11 -> 16560000
A12: Củ Khoai Lang Nhật | B12: Kg | C12: 190 | D12: 16000 | E12: =C12*D12 -> 3040000
A13: Củ Khoai Tây Vàng | B13: Kg | C13: 390 | D13: 17000 | E13: =C13*D13 -> 6630000
A14: Củ Khoai Tây Vàng | B14: Túi | C14: 0 | E14: =C14*D14 -> 0
A15: Bông Cải Xanh Baby | B15: Vỉ | C15: 0 | E15: =C15*D15 -> 0
A16: Bắp Cải Trắng | B16: Kg | C16: 395 | D16: 7500 | E16: =C16*D16 -> 2962500
A17: Cải Bó Xôi | B17: Kg | C17: 0 | E17: =C17*D17 -> 0
A18: Cải Bó Xôi | B18: Túi | C18: 20 | D18: 6300 | E18: =C18*D18 -> 126000
A19: Cải Kale | B19: Túi | C19: 12 | D19: 5250 | E19: =C19*D19 -> 63000
A20: Cải Thảo | B20: Kg | C20: 0 | E20: =C20*D20 -> 0
A21: Cần Tây | B21: Cây | C21: 0 | E21: =C21*D21 -> 0
A22: Cần Tây | B22: Kg | C22: 60 | D22: 16000 | E22: =C22*D22 -> 960000
A23: Xà Lách Lolo Xanh T.C | B23: Kg | C23: 0 | E23: =C23*D23 -> 0
A24: Bí Đỏ Tròn | B24: Kg | C24: 350 | D24: 7000 | E24: =C24*D24 -> 2450000
A25: Bí Ngòi Xanh | B25: Kg | C25: 165 | D25: 11000 | E25: =C25*D25 -> 1815000
A26: Bí Ngòi Xanh | B26: Trái | C26: 0 | E26: =C26*D26 -> 0
A27: Bí Non Nhật | B27: Kg | C27: 138 | D27: 10000 | E27: =C27*D27 -> 1380000
A28: Bí Non Nhật | B28: Trái | C28: 0 | E28: =C28*D28 -> 0
A29: Cà Chua Beef | B29: Kg | C29: 143 | D29: 24000 | E29: =C29*D29 -> 3432000
A30: Cà Chua Beef | B30: Vỉ 650gr | C30: 0 | E30: =C30*D30 -> 0
A31: Cà Chua Thường | B31: Kg | C31: 120 | D31: 24000 | E31: =C31*D31 -> 2880000
A32: Cà Chua Thường | B32: Vỉ | C32: 0 | E32: =C32*D32 -> 0
A33: Cà Chua Thường Trung | B33: Túi | C33: 170 | D33: 18000 | E33: =C33*D33 -> 3060000
A34: Dưa Leo Baby | B34: Kg | C34: 0 | E34: =C34*D34 -> 0
A35: Dưa Leo Baby | B35: Vỉ | C35: 622 | D35: 5000 | E35: =C35*D35 -> 3110000
A36: Dưa Leo Thường | B36: Kg | C36: 0 | E36: =C36*D36 -> 0
A37: Ớt Chuông Đỏ | B37: Kg | C37: 95 | D37: 30000 | E37: =C37*D37 -> 2850000
A38: Ớt Chuông Đỏ | B38: Trái | C38: 0 | E38: =C38*D38 -> 0
A39: Ớt Chuông Vàng | B39: Kg | C39: 80 | D39: 15000 | E39: =C39*D39 -> 1200000
A40: Ớt Chuông Vàng | B40: Trái | C40: 0 | E40: =C40*D40 -> 0
...

Sheet 12.12
A1: hàng tồn cuối ngày 12/12 vr
A2: Tên Sản phẩm | B2: ĐVT | C2: tồn | D2: giá | E2: thành tiền
A3: Bắp Cải Tím | B3: Kg | C3: 55 | D3: 38000 | E3: =C3*D3 -> 2090000
A4: Bắp Cải Trái Tim | B4: Kg | C4: 150 | D4: 5000 | E4: =C4*D4 -> 750000
A5: Bắp Cải Trắng | B5: Kg | C5: 72 | D5: 5500 | E5: =C5*D5 -> 396000
A6: Bí Đao Xanh | B6: Kg | C6: 0 | E6: =C6*D6 -> 0
A7: Bí Đỏ Hồ Lô | B7: Kg | C7: 0 | E7: =C7*D7 -> 0
A8: Bí Đỏ Tròn | B8: Kg | C8: 460 | D8: 7000 | E8: =C8*D8 -> 3220000
A9: Bí Ngô Mini | B9: Kg | C9: 0 | E9: =C9*D9 -> 0
A10: Bí Ngòi Vàng | B10: Kg | C10: 0 | E10: =C10*D10 -> 0
A11: Bí Ngòi Xanh | B11: Kg | C11: 20 | D11: 11000 | E11: =C11*D11 -> 220000
A12: Bí Ngòi Xanh | B12: Trái | C12: 0 | E12: =C12*D12 -> 0
A13: Bí Non Nhật | B13: Kg | C13: 27 | D13: 13000 | E13: =C13*D13 -> 351000
A14: Bí Non Nhật | B14: Trái | C14: 0 | E14: =C14*D14 -> 0
A15: Bơ 034 L1 | B15: Kg | C15: 0 | E15: =C15*D15 -> 0
A16: Bơ Booth | B16: Kg | C16: 0 | E16: =C16*D16 -> 0
A17: Bông Cải Trắng | B17: Kg | C17: 20 | D17: 13000 | E17: =C17*D17 -> 260000
A18: Bông Cải Xanh 10Cm | B18: Kg | C18: 2 | D18: 19000 | E18: =C18*D18 -> 38000
A19: Bông Cải Xanh 12Cm | B19: Kg | C19: 0 | E19: =C19*D19 -> 0
A20: Bông Cải Xanh 7Cm | B20: Kg | C20: 0 | E20: =C20*D20 -> 0
A21: Bông Cải Xanh Baby | B21: Kg | C21: 0 | E21: =C21*D21 -> 0
A22: Bông Cải Xanh Baby | B22: Vỉ | C22: 24 | D22: 8000 | E22: =C22*D22 -> 192000
A23: Cà Chua Beef | B23: Kg | C23: 90 | D23: 24000 | E23: =C23*D23 -> 2160000
A24: Cà Chua Beef | B24: Vỉ | C24: 0 | E24: =C24*D24 -> 0
A25: Cà Chua Beef | B25: Vỉ 650gr | C25: 0 | E25: =C25*D25 -> 0
A26: Cà Chua Beef Trung | B26: Kg | C26: 45 | D26: 19000 | E26: =C26*D26 -> 855000
A27: Cà Chua Beef Trung | B27: Vỉ 500gr | C27: 0 | E27: =C27*D27 -> 0
A28: Cà Chua Bi Đỏ | B28: Kg | C28: 20 | D28: 30000 | E28: =C28*D28 -> 600000
A29: Cà Chua Bi Đỏ | B29: Hộp 300gr | C29: 64 | D29: 9000 | E29: =C29*D29 -> 576000
A30: Cà Chua Bi Mix | B30: Hộp | C30: 20 | D30: 16500 | E30: =C30*D30 -> 330000
A31: Cà Chua Socola | B31: Kg | C31: 0 | E31: =C31*D31 -> 0
A32: Cà Chua Socola | B32: Hộp 300gr | C32: 0 | E32: =C32*D32 -> 0
A33: Cà Chua Socola | B33: Hộp 250GR | C33: 0 | E33: =C33*D33 -> 0
A34: Cà Chua Thường | B34: Kg | C34: 210 | D34: 22000 | E34: =C34*D34 -> 4620000
A35: Cà Chua Thường | B35: Vỉ | C35: 0 | E35: =C35*D35 -> 0
A36: Cà Chua Thường Trung | B36: Túi | C36: 65 | D36: 18000 | E36: =C36*D36 -> 1170000
A37: Cà Rốt | B37: Kg | C37: 80 | D37: 12500 | E37: =C37*D37 -> 1000000
A38: Cà Rốt | B38: Túi | C38: 0 | E38: =C38*D38 -> 0
A39: Cà Rốt Baby | B39: Kg | C39: 0 | E39: =C39*D39 -> 0
A40: Cà Rốt Baby | B40: Vỉ | C40: 17 | D40: 9000 | E40: =C40*D40 -> 153000
...

Sheet 13.12
A1: hàng tồn cuối ngày 13/12 vr
A2: Tên Sản phẩm | B2: ĐVT | C2: tồn | D2: giá | E2: thành tiền
A3: Bắp Cải Tím | B3: Kg | C3: 20 | D3: 32000 | E3: =C3*D3 -> 640000
A4: Bắp Cải Trái Tim | B4: Kg | C4: 274 | D4: 6000 | E4: =C4*D4 -> 1644000
A5: Bắp Cải Trắng | B5: Kg | C5: 110 | D5: 5500 | E5: =C5*D5 -> 605000
A6: Bí Đỏ Hồ Lô | B6: Kg | C6: 0 | E6: =C6*D6 -> 0
A7: Bí Đỏ Tròn | B7: Kg | C7: 350 | D7: 7000 | E7: =C7*D7 -> 2450000
A8: Bí Ngòi Xanh | B8: Kg | C8: 165 | D8: 11000 | E8: =C8*D8 -> 1815000
A9: Bí Ngòi Xanh | B9: Trái | C9: 0 | E9: =C9*D9 -> 0
A10: Bí Non Nhật | B10: Kg | C10: 65 | D10: 13000 | E10: =C10*D10 -> 845000
A11: Bí Non Nhật | B11: Trái | C11: 0 | E11: =C11*D11 -> 0
A12: Bơ Booth | B12: Kg | C12: 0 | E12: =C12*D12 -> 0
A13: Bông Cải Trắng | B13: Kg | C13: 0 | E13: =C13*D13 -> 0
A14: Bông Cải Xanh 10Cm | B14: Kg | C14: 0 | E14: =C14*D14 -> 0
A15: Bông Cải Xanh 12Cm | B15: Kg | C15: 10 | D15: 16000 | E15: =C15*D15 -> 160000
A16: Bông Cải Xanh 7Cm | B16: Kg | C16: 35 | D16: 26000 | E16: =C16*D16 -> 910000
A17: Bông Cải Xanh Baby | B17: Vỉ | C17: 16 | D17: 8000 | E17: =C17*D17 -> 128000
A18: Cà Chua Beef | B18: Kg | C18: 110 | D18: 24000 | E18: =C18*D18 -> 2640000
A19: Cà Chua Beef | B19: Vỉ | C19: 0 | E19: =C19*D19 -> 0
A20: Cà Chua Beef | B20: Vỉ 650gr | C20: 0 | E20: =C20*D20 -> 0
A21: Cà Chua Beef Trung | B21: Kg | C21: 0 | E21: =C21*D21 -> 0
A22: Cà Chua Beef Trung | B22: Vỉ 500gr | C22: 0 | E22: =C22*D22 -> 0
A23: Cà Chua Bi Đỏ | B23: Kg | C23: 12 | D23: 30000 | E23: =C23*D23 -> 360000
A24: Cà Chua Bi Đỏ | B24: Hộp 300gr | C24: 97 | D24: 9000 | E24: =C24*D24 -> 873000
A25: Cà Chua Bi Mix | B25: Hộp | C25: 0 | E25: =C25*D25 -> 0
A26: Cà Chua Socola | B26: Kg | C26: 0 | E26: =C26*D26 -> 0
A27: Cà Chua Socola | B27: Hộp 250GR | C27: 0 | E27: =C27*D27 -> 0
A28: Cà Chua Thường | B28: Kg | C28: 85 | D28: 20000 | E28: =C28*D28 -> 1700000
A29: Cà Chua Thường | B29: Vỉ | C29: 0 | E29: =C29*D29 -> 0
A30: Cà Chua Thường Trung | B30: Túi | C30: 75 | D30: 18000 | E30: =C30*D30 -> 1350000
A31: Cà Rốt | B31: Kg | C31: 0 | E31: =C31*D31 -> 0
A32: Cà Rốt | B32: Túi | C32: 0 | E32: =C32*D32 -> 0
A33: Cà Rốt Baby | B33: Vỉ | C33: 0 | E33: =C33*D33 -> 0
A34: Cà Tím | B34: Kg | C34: 40 | D34: 7000 | E34: =C34*D34 -> 280000
A35: Cà Tím | B35: Cặp | C35: 0 | E35: =C35*D35 -> 0
A36: Cải Bó Xôi | B36: Kg | C36: 0 | E36: =C36*D36 -> 0
A37: Cải Bó Xôi | B37: Túi | C37: 0 | E37: =C37*D37 -> 0
A38: Cải Cầu Vồng | B38: Túi | C38: 10 | D38: 3900 | E38: =C38*D38 -> 39000
A39: Cải Kale | B39: Túi | C39: 10 | D39: 5250 | E39: =C39*D39 -> 52500
A40: Cải Thảo | B40: Kg | C40: 0 | E40: =C40*D40 -> 0
...

Sheet 14.12
A1: Tên Sản phẩm VR | B1: ĐVT | C1: Tồn ĐL 現在個 | D1: Gía nhập | E1: Thành tiền
A2: Bắp Cải Tím | B2: Kg | C2: 26 | D2: 32000 | E2: =+D2*C2 -> 832000
A3: Bắp Cải Trái Tim | B3: Kg | C3: 543 | D3: 6000 | E3: =+D3*C3 -> 3258000
A4: Bắp Cải Trắng | B4: Kg | C4: 335 | D4: 5500 | E4: =+D4*C4 -> 1842500
A5: Bí Đỏ Hồ Lô | B5: Kg | C5: 45 | D5: 11500 | E5: =+D5*C5 -> 517500
A6: Bí Đỏ Tròn | B6: Kg | C6: 195 | D6: 7000 | E6: =+D6*C6 -> 1365000
A7: Bí Ngòi Xanh | B7: Kg | C7: 100 | D7: 11000 | E7: =+D7*C7 -> 1100000
A8: Bí Ngòi Xanh | B8: Trái | C8: 0
A9: Bí Non Nhật | B9: Kg | C9: 25 | D9: 13000 | E9: =+D9*C9 -> 325000
A10: Bí Non Nhật | B10: Trái | C10: 0
A11: Bơ 034 L1 | B11: Kg | C11: 0
A12: Bơ Booth | B12: Kg | C12: 0
A13: Bông Cải Trắng | B13: Kg | C13: 33 | D13: 15000 | E13: =+D13*C13 -> 495000
A14: Bông Cải Xanh 10Cm | B14: Kg | C14: 0
A15: Bông Cải Xanh 12Cm | B15: Kg | C15: 50 | D15: 16000 | E15: =+D15*C15 -> 800000
A16: Bông Cải Xanh 7Cm | B16: Kg | C16: 0
A17: Bông Cải Xanh Baby | B17: Vỉ | C17: 0
A18: Cà Chua Beef | B18: Kg | C18: 125 | D18: 24000 | E18: =+D18*C18 -> 3000000
A19: Cà Chua Beef | B19: Vỉ | C19: 0
A20: Cà Chua Beef | B20: Vỉ 650gr | C20: 0
A21: Cà Chua Beef Trung | B21: Kg | C21: 8 | D21: 19000 | E21: =+D21*C21 -> 152000
A22: Cà Chua Beef Trung | B22: Vỉ 500gr | C22: 0
A23: Cà Chua Bi Đỏ | B23: Kg | C23: 8 | D23: 30000 | E23: =+D23*C23 -> 240000
A24: Cà Chua Bi Đỏ | B24: Hộp 300gr | C24: 60 | D24: 9000 | E24: =+D24*C24 -> 540000
A25: Cà Chua Bi Mix | B25: Hộp | C25: 12 | D25: 16500 | E25: =+D25*C25 -> 198000
A26: Cà Chua Socola | B26: Kg | C26: 10 | D26: 34000 | E26: =+D26*C26 -> 340000
A27: Cà Chua Socola | B27: Hộp 250GR | C27: 0
A28: Cà Chua Thường | B28: Kg | C28: 400 | D28: 20000 | E28: =+D28*C28 -> 8000000
A29: Cà Chua Thường | B29: Vỉ | C29: 0
A30: Cà Chua Thường Trung | B30: Túi | C30: 108 | D30: 18000 | E30: =+D30*C30 -> 1944000
A31: Cà Rốt | B31: Kg | C31: 0
A32: Cà Rốt | B32: Túi | C32: 0
A33: Cà Rốt Baby | B33: Vỉ | C33: 0
A34: Cà Tím | B34: Kg | C34: 0
A35: Cà Tím | B35: Cặp | C35: 0
A36: Cải Bó Xôi | B36: Kg | C36: 7 | D36: 14000 | E36: =+D36*C36 -> 98000
A37: Cải Bó Xôi | B37: Túi | C37: 0
A38: Cải Cầu Vồng | B38: Túi | C38: 0
A39: Cải Kale | B39: Túi | C39: 15 | D39: 5250 | E39: =+D39*C39 -> 78750
A40: Cải Thảo | B40: Kg | C40: 800 | D40: 5500 | E40: =+D40*C40 -> 4400000
...

Sheet 14.12.
A2: hàng tồn cuối ngày 14/12 vr
A3: Tên Sản phẩm | B3: ĐVT | C3: tồn | D3: giá | E3: thành tiền
A4: Cà Rốt | B4: Kg | C4: 0 | E4: =C4*D4 -> 0
A5: Cà Rốt | B5: Túi | C5: 0 | E5: =C5*D5 -> 0
A6: Cà Rốt Baby | B6: Vỉ | C6: 0 | E6: =C6*D6 -> 0
A7: Củ Cải Đỏ | B7: Hộp | C7: 13 | D7: 6500 | E7: =C7*D7 -> 84500
A8: Củ Cải Đỏ | B8: Kg | C8: 0 | E8: =C8*D8 -> 0
A9: Củ Dền | B9: Kg | C9: 10 | D9: 11000 | E9: =C9*D9 -> 110000
A10: Củ Dền | B10: Túi | C10: 0 | E10: =C10*D10 -> 0
A11: Củ Hành Tây | B11: Kg | C11: 463 | D11: 19000 | E11: =C11*D11 -> 8797000
A12: Củ Hành Tây | B12: Túi 300gr | C12: 0 | E12: =C12*D12 -> 0
A13: Củ Hành Tây Trung | B13: Túi | C13: 200 | D13: 4800 | E13: =C13*D13 -> 960000
A14: Củ Khoai Lang Mật Size 46 | B14: Kg | C14: 460 | D14: 24000 | E14: =C14*D14 -> 11040000
A15: Củ Khoai Lang Mật Size 46 | B15: Túi | C15: 0 | E15: =C15*D15 -> 0
A16: Củ Khoai Lang Nhật | B16: Kg | C16: 80 | D16: 16000 | E16: =C16*D16 -> 1280000
A17: Củ Khoai Tây Vàng | B17: Kg | C17: 50 | D17: 17000 | E17: =C17*D17 -> 850000
A18: Củ Khoai Tây Vàng | B18: Túi | C18: 0 | E18: =C18*D18 -> 0
A19: Bông Cải Xanh Baby | B19: Vỉ | C19: 0 | E19: =C19*D19 -> 0
A20: Bắp Cải Trắng | B20: Kg | C20: 335 | D20: 5500 | E20: =C20*D20 -> 1842500
A21: Cải Bó Xôi | B21: Kg | C21: 7 | D21: 16000 | E21: =C21*D21 -> 112000
A22: Cải Bó Xôi | B22: Túi | C22: 0 | E22: =C22*D22 -> 0
A23: Cải Kale | B23: Túi | C23: 15 | D23: 5250 | E23: =C23*D23 -> 78750
A24: Cải Thảo | B24: Kg | C24: 800 | D24: 5500 | E24: =C24*D24 -> 4400000
A25: Cần Tây | B25: Cây | C25: 0 | E25: =C25*D25 -> 0
A26: Cần Tây | B26: Kg | C26: 60 | D26: 13000 | E26: =C26*D26 -> 780000
A27: Xà Lách Lolo Xanh T.C | B27: Kg | C27: 8 | D27: 28000 | E27: =C27*D27 -> 224000
A28: Bí Đỏ Tròn | B28: Kg | C28: 195 | D28: 7000 | E28: =C28*D28 -> 1365000
A29: Bí Ngòi Xanh | B29: Kg | C29: 100 | D29: 13000 | E29: =C29*D29 -> 1300000
A30: Bí Ngòi Xanh | B30: Trái | C30: 0 | E30: =C30*D30 -> 0
A31: Bí Non Nhật | B31: Kg | C31: 25 | D31: 10000 | E31: =C31*D31 -> 250000
A32: Bí Non Nhật | B32: Trái | C32: 0 | E32: =C32*D32 -> 0
A33: Cà Chua Beef | B33: Kg | C33: 125 | D33: 24000 | E33: =C33*D33 -> 3000000
A34: Cà Chua Beef | B34: Vỉ 650gr | C34: 0 | E34: =C34*D34 -> 0
A35: Cà Chua Thường | B35: Kg | C35: 400 | D35: 20000 | E35: =C35*D35 -> 8000000
A36: Cà Chua Thường | B36: Vỉ | C36: 0 | E36: =C36*D36 -> 0
A37: Cà Chua Thường Trung | B37: Túi | C37: 108 | D37: 17000 | E37: =C37*D37 -> 1836000
A38: Dưa Leo Baby | B38: Kg | C38: 52 | D38: 7000 | E38: =C38*D38 -> 364000
A39: Dưa Leo Baby | B39: Vỉ | C39: 323 | D39: 5000 | E39: =C39*D39 -> 1615000
A40: Dưa Leo Thường | B40: Kg | C40: 30 | D40: 6000 | E40: =C40*D40 -> 180000
A41: Ớt Chuông Đỏ | B41: Kg | C41: 0 | E41: =C41*D41 -> 0
...

Sheet 15.12
A2: hàng tồn cuối ngày 15/12
A3: Tên Sản phẩm | B3: ĐVT | C3: tồn | D3: giá | E3: thành tiền
A4: Cà Rốt | B4: Kg | C4: 0 | E4: =C4*D4 -> 0
A5: Cà Rốt | B5: Túi | C5: 0 | E5: =C5*D5 -> 0
A6: Cà Rốt Baby | B6: Vỉ | C6: 0 | E6: =C6*D6 -> 0
A7: Củ Cải Đỏ | B7: Hộp | C7: 20 | D7: 6500 | E7: =C7*D7 -> 130000
A8: Củ Cải Đỏ | B8: Kg | C8: 0 | E8: =C8*D8 -> 0
A9: Củ Dền | B9: Kg | C9: 0 | E9: =C9*D9 -> 0
A10: Củ Dền | B10: Túi | C10: 0 | E10: =C10*D10 -> 0
A11: Củ Hành Tây | B11: Kg | C11: 250 | D11: 19000 | E11: =C11*D11 -> 4750000
A12: Củ Hành Tây | B12: Túi 300gr | C12: 0 | E12: =C12*D12 -> 0
A13: Củ Hành Tây Trung | B13: Túi | C13: 170 | D13: 4800 | E13: =C13*D13 -> 816000
A14: Củ Khoai Lang Mật Size 46 | B14: Kg | C14: 305 | D14: 24000 | E14: =C14*D14 -> 7320000
A15: Củ Khoai Lang Mật Size 46 | B15: Túi | C15: 0 | E15: =C15*D15 -> 0
A16: Củ Khoai Lang Nhật | B16: Kg | C16: 100 | D16: 16000 | E16: =C16*D16 -> 1600000
A17: Củ Khoai Tây Vàng | B17: Kg | C17: 440 | D17: 18000 | E17: =C17*D17 -> 7920000
A18: Củ Khoai Tây Vàng | B18: Túi | C18: 0 | E18: =C18*D18 -> 0
A19: Bông Cải Xanh Baby | B19: Vỉ | C19: 0 | E19: =C19*D19 -> 0
A20: Bắp Cải Trắng | B20: Kg | C20: 165 | D20: 5500 | E20: =C20*D20 -> 907500
A21: Cải Bó Xôi | B21: Kg | C21: 16 | D21: 16000 | E21: =C21*D21 -> 256000
A22: Cải Bó Xôi | B22: Túi | C22: 0 | E22: =C22*D22 -> 0
A23: Cải Kale | B23: Túi | C23: 16 | D23: 3900 | E23: =C23*D23 -> 62400
A24: Cải Thảo | B24: Kg | C24: 250 | D24: 5500 | E24: =C24*D24 -> 1375000
A25: Cần Tây | B25: Cây | C25: 0 | E25: =C25*D25 -> 0
A26: Cần Tây | B26: Kg | C26: 0 | E26: =C26*D26 -> 0
A27: Xà Lách Lolo Xanh T.C | B27: Kg | C27: 3 | D27: 28000 | E27: =C27*D27 -> 84000
A28: Bí Đỏ Tròn | B28: Kg | C28: 0 | E28: =C28*D28 -> 0
A29: Bí Ngòi Xanh | B29: Kg | C29: 80 | D29: 13000 | E29: =C29*D29 -> 1040000
A30: Bí Ngòi Xanh | B30: Trái | C30: 0 | E30: =C30*D30 -> 0
A31: Bí Non Nhật | B31: Kg | C31: 22 | D31: 13000 | E31: =C31*D31 -> 286000
A32: Bí Non Nhật | B32: Trái | C32: 0 | E32: =C32*D32 -> 0
A33: Cà Chua Beef | B33: Kg | C33: 185 | D33: 24000 | E33: =C33*D33 -> 4440000
A34: Cà Chua Beef | B34: Vỉ 650gr | C34: 0 | E34: =C34*D34 -> 0
A35: Cà Chua Thường | B35: Kg | C35: 260 | D35: 20000 | E35: =C35*D35 -> 5200000
A36: Cà Chua Thường | B36: Vỉ | C36: 0 | E36: =C36*D36 -> 0
A37: Cà Chua Thường Trung | B37: Túi | C37: 65 | D37: 17000 | E37: =C37*D37 -> 1105000
A38: Dưa Leo Baby | B38: Kg | C38: 0 | E38: =C38*D38 -> 0
A39: Dưa Leo Baby | B39: Vỉ | C39: 65 | D39: 5000 | E39: =C39*D39 -> 325000
A40: Dưa Leo Thường | B40: Kg | C40: 20 | D40: 6000 | E40: =C40*D40 -> 120000
A41: Ớt Chuông Đỏ | B41: Kg | C41: 105 | D41: 38000 | E41: =C41*D41 -> 3990000
...

Sheet 16.12
A1: hnagf tồn cuối ngày 16/12 vr
A2: Tên Sản phẩm | B2: ĐVT | C2: tồn | D2: giá | E2: thành tiền
A3: Bắp Cải Tím | B3: Kg | C3: 0 | E3: =C3*D3 -> 0
A4: Bắp Cải Trái Tim | B4: Kg | C4: 1124 | D4: 5500 | E4: =C4*D4 -> 6182000
A5: Bắp Cải Trắng | B5: Kg | C5: 180 | D5: 5500 | E5: =C5*D5 -> 990000
A6: Bí Đỏ Hồ Lô | B6: Kg | C6: 0 | E6: =C6*D6 -> 0
A7: Bí Đỏ Tròn | B7: Kg | C7: 2240 | D7: 7000 | E7: =C7*D7 -> 15680000
A8: Bí Ngòi Xanh | B8: Kg | C8: 20 | D8: 16000 | E8: =C8*D8 -> 320000
A9: Bí Ngòi Xanh | B9: Trái | C9: 0 | E9: =C9*D9 -> 0
A10: Bí Non Nhật | B10: Kg | C10: 0 | E10: =C10*D10 -> 0
A11: Bí Non Nhật | B11: Trái | C11: 0 | E11: =C11*D11 -> 0
A12: Bơ 034 L1 | B12: Kg | C12: 0 | E12: =C12*D12 -> 0
A13: Bơ Booth | B13: Kg | C13: 0 | E13: =C13*D13 -> 0
A14: Bông Cải Trắng | B14: Kg | C14: 20 | D14: 25000 | E14: =C14*D14 -> 500000
A15: Bông Cải Xanh 10Cm | B15: Kg | C15: 0 | E15: =C15*D15 -> 0
A16: Bông Cải Xanh 12Cm | B16: Kg | C16: 0 | E16: =C16*D16 -> 0
A17: Bông Cải Xanh 7Cm | B17: Kg | C17: 0 | E17: =C17*D17 -> 0
A18: Bông Cải Xanh Baby | B18: Vỉ | C18: 18 | D18: 7600 | E18: =C18*D18 -> 136800
A19: Cà Chua Beef | B19: Kg | C19: 262 | D19: 22000 | E19: =C19*D19 -> 5764000
A20: Cà Chua Beef | B20: Vỉ | C20: 0 | E20: =C20*D20 -> 0
A21: Cà Chua Beef | B21: Vỉ 650gr | C21: 0 | E21: =C21*D21 -> 0
A22: Cà Chua Beef Trung | B22: Kg | C22: 60 | D22: 20000 | E22: =C22*D22 -> 1200000
A23: Cà Chua Beef Trung | B23: Vỉ 500gr | C23: 0 | E23: =C23*D23 -> 0
A24: Cà Chua Bi Đỏ | B24: Kg | C24: 3 | D24: 30000 | E24: =C24*D24 -> 90000
A25: Cà Chua Bi Đỏ | B25: Hộp 300gr | C25: 171 | D25: 9000 | E25: =C25*D25 -> 1539000
A26: Cà Chua Bi Mix | B26: Hộp | C26: 5 | D26: 16500 | E26: =C26*D26 -> 82500
A27: Cà Chua Socola | B27: Kg | C27: 10 | D27: 38000 | E27: =C27*D27 -> 380000
A28: Cà Chua Socola | B28: Hộp 250GR | C28: 324 | D28: 12000 | E28: =C28*D28 -> 3888000
A29: Cà Chua Thường | B29: Kg | C29: 200 | D29: 20000 | E29: =C29*D29 -> 4000000
A30: Cà Chua Thường | B30: Vỉ | C30: 0 | E30: =C30*D30 -> 0
A31: Cà Chua Thường Trung | B31: Túi | C31: 63 | D31: 16000 | E31: =C31*D31 -> 1008000
A32: Cà Rốt | B32: Kg | C32: 400 | D32: 13000 | E32: =C32*D32 -> 5200000
A33: Cà Rốt | B33: Túi | C33: 0 | E33: =C33*D33 -> 0
A34: Cà Rốt Baby | B34: Vỉ | C34: 0 | E34: =C34*D34 -> 0
A35: Cà Tím | B35: Kg | C35: 70 | D35: 10000 | E35: =C35*D35 -> 700000
A36: Cà Tím | B36: Cặp | C36: 0 | E36: =C36*D36 -> 0
A37: Cải Bó Xôi | B37: Kg | C37: 10 | D37: 20000 | E37: =C37*D37 -> 200000
A38: Cải Bó Xôi | B38: Túi | C38: 0 | E38: =C38*D38 -> 0
A39: Cải Cầu Vồng | B39: Túi | C39: 14 | D39: 3900 | E39: =C39*D39 -> 54600
A40: Cải Kale | B40: Túi | C40: 14 | D40: 3900 | E40: =C40*D40 -> 54600
...

Sheet 17.12
A1: hàng tồn cuối ngày 17/12 vr
A2: Tên Sản phẩm | B2: ĐVT | C2: tồn | D2: giá | E2: thành tiền
A3: Bắp Cải Tím | B3: Kg | C3: 50 | D3: 36000 | E3: =C3*D3 -> 1800000
A4: Bắp Cải Trái Tim | B4: Kg | C4: 1850 | D4: 5500 | E4: =C4*D4 -> 10175000
A5: Bắp Cải Trắng | B5: Kg | C5: 120 | D5: 5500 | E5: =C5*D5 -> 660000
A6: Bí Đao Xanh | B6: Kg | C6: 0 | E6: =C6*D6 -> 0
A7: Bí Đỏ Hồ Lô | B7: Kg | C7: 0 | E7: =C7*D7 -> 0
A8: Bí Đỏ Tròn | B8: Kg | C8: 2000 | D8: 7000 | E8: =C8*D8 -> 14000000
A9: Bí Ngòi Xanh | B9: Kg | C9: 0 | E9: =C9*D9 -> 0
A10: Bí Ngòi Xanh | B10: Trái | C10: 0 | E10: =C10*D10 -> 0
A11: Bí Non Nhật | B11: Kg | C11: 28 | D11: 13000 | E11: =C11*D11 -> 364000
A12: Bí Non Nhật | B12: Trái | C12: 0 | E12: =C12*D12 -> 0
A13: Bơ 034 L1 | B13: Kg | C13: 0 | E13: =C13*D13 -> 0
A14: Bơ Booth | B14: Kg | C14: 0 | E14: =C14*D14 -> 0
A15: Bông Cải Trắng | B15: Kg | C15: 0 | E15: =C15*D15 -> 0
A16: Bông Cải Xanh 10Cm | B16: Kg | C16: 0 | E16: =C16*D16 -> 0
A17: Bông Cải Xanh 12Cm | B17: Kg | C17: 0 | E17: =C17*D17 -> 0
A18: Bông Cải Xanh 7Cm | B18: Kg | C18: 0 | E18: =C18*D18 -> 0
A19: Bông Cải Xanh Baby | B19: Vỉ | C19: 10 | D19: 7600 | E19: =C19*D19 -> 76000
A20: Cà Chua Beef | B20: Kg | C20: 115 | D20: 22000 | E20: =C20*D20 -> 2530000
A21: Cà Chua Beef | B21: Vỉ | C21: 0 | E21: =C21*D21 -> 0
A22: Cà Chua Beef | B22: Vỉ 650gr | C22: 0 | E22: =C22*D22 -> 0
A23: Cà Chua Beef Trung | B23: Kg | C23: 14 | D23: 21000 | E23: =C23*D23 -> 294000
A24: Cà Chua Beef Trung | B24: Vỉ 500gr | C24: 0 | E24: =C24*D24 -> 0
A25: Cà Chua Bi Đỏ | B25: Hộp 500gr | C25: 14 | D25: 15000 | E25: =C25*D25 -> 210000
A26: Cà Chua Bi Đỏ | B26: Hộp 300gr | C26: 69 | D26: 9000 | E26: =C26*D26 -> 621000
A27: Cà Chua Bi Mix | B27: Hộp | C27: 0 | E27: =C27*D27 -> 0
A28: Cà Chua Socola | B28: Kg | C28: 0 | E28: =C28*D28 -> 0
A29: Cà Chua Socola | B29: Hộp 250GR | C29: 265 | D29: 12000 | E29: =C29*D29 -> 3180000
A30: Cà Chua Thường | B30: Kg | C30: 0 | E30: =C30*D30 -> 0
A31: Cà Chua Thường | B31: Vỉ | C31: 0 | E31: =C31*D31 -> 0
A32: Cà Chua Thường Trung | B32: Túi | C32: 135 | D32: 14000 | E32: =C32*D32 -> 1890000
A33: Cà Rốt | B33: Kg | C33: 232 | D33: 13000 | E33: =C33*D33 -> 3016000
A34: Cà Rốt | B34: Túi | C34: 0 | E34: =C34*D34 -> 0
A35: Cà Rốt Baby | B35: Kg | C35: 0 | E35: =C35*D35 -> 0
A36: Cà Rốt Baby | B36: Vỉ | C36: 0 | E36: =C36*D36 -> 0
A37: Cà Tím | B37: Kg | C37: 0 | E37: =C37*D37 -> 0
A38: Cà Tím | B38: Cặp | C38: 0 | E38: =C38*D38 -> 0
A39: Cải Bó Xôi | B39: Kg | C39: 0 | E39: =C39*D39 -> 0
A40: Cải Bó Xôi | B40: Túi | C40: 0 | E40: =C40*D40 -> 0
...

Sheet 18.12
A1: hàng tồn cuối ngày 18/12 vr
A2: Tên Sản phẩm | B2: ĐVT | C2: tồn | D2: giá | E2: thành tiền
A3: Cà Rốt | B3: Kg | C3: 340 | D3: 13000 | E3: =C3*D3 -> 4420000
A4: Cà Rốt | B4: Túi | C4: 0 | E4: =C4*D4 -> 0
A5: Cà Rốt Baby | B5: Vỉ | C5: 0 | E5: =C5*D5 -> 0
A6: Củ Cải Đỏ | B6: Hộp | C6: 0 | E6: =C6*D6 -> 0
A7: Củ Dền | B7: Kg | C7: 0 | E7: =C7*D7 -> 0
A8: Củ Dền | B8: Túi | C8: 0 | E8: =C8*D8 -> 0
A9: Củ Hành Tây | B9: Kg | C9: 513 | D9: 19000 | E9: =C9*D9 -> 9747000
A10: Củ Hành Tây | B10: Túi 300gr | C10: 0 | E10: =C10*D10 -> 0
A11: Củ Hành Tây Trung | B11: Túi | C11: 583 | D11: 4500 | E11: =C11*D11 -> 2623500
A12: Củ Khoai Lang Mật Size 46 | B12: Kg | C12: 130 | D12: 24000 | E12: =C12*D12 -> 3120000
A13: Củ Khoai Lang Nhật | B13: Kg | C13: 80 | D13: 16000 | E13: =C13*D13 -> 1280000
A14: Củ Khoai Tây Vàng | B14: Kg | C14: 240 | D14: 18000 | E14: =C14*D14 -> 4320000
A15: Củ Khoai Tây Vàng | B15: Túi | C15: 0 | E15: =C15*D15 -> 0
A16: Bông Cải Xanh Baby | B16: Vỉ | C16: 7 | D16: 7600 | E16: =C16*D16 -> 53200
A17: Bắp Cải Trắng | B17: Kg | C17: 630 | D17: 5000 | E17: =C17*D17 -> 3150000
A18: Cải Bó Xôi | B18: Kg | C18: 12 | D18: 24000 | E18: =C18*D18 -> 288000
A19: Cải Bó Xôi | B19: Túi | C19: 0 | E19: =C19*D19 -> 0
A20: Cải Kale | B20: Túi | C20: 0 | E20: =C20*D20 -> 0
A21: Cải Thảo | B21: Kg | E21: =C21*D21 -> 0
A22: Cần Tây | B22: Cây | C22: 0 | E22: =C22*D22 -> 0
A23: Cần Tây | B23: Kg | C23: 30 | D23: 10000 | E23: =C23*D23 -> 300000
A24: Xà Lách Lolo Xanh T.C | B24: Kg | C24: 6 | D24: 28000 | E24: =C24*D24 -> 168000
A25: Bí Đỏ Tròn | B25: Kg | C25: 1600 | D25: 7000 | E25: =C25*D25 -> 11200000
A26: Bí Ngòi Xanh | B26: Kg | C26: 55 | D26: 22000 | E26: =C26*D26 -> 1210000
A27: Bí Ngòi Xanh | B27: Trái | C27: 0 | E27: =C27*D27 -> 0
A28: Bí Non Nhật | B28: Trái | C28: 0 | E28: =C28*D28 -> 0
A29: Cà Chua Beef | B29: Kg | C29: 280 | D29: 22000 | E29: =C29*D29 -> 6160000
A30: Cà Chua Beef | B30: Vỉ 650gr | C30: 0 | E30: =C30*D30 -> 0
A31: Cà Chua Thường | B31: Kg | C31: 310 | D31: 20000 | E31: =C31*D31 -> 6200000
A32: Cà Chua Thường | B32: Vỉ | C32: 0 | E32: =C32*D32 -> 0
A33: Cà Chua Thường Trung | B33: Túi | C33: 90 | D33: 14000 | E33: =C33*D33 -> 1260000
A34: Dưa Leo Baby | B34: Kg | C34: 0 | E34: =C34*D34 -> 0
A35: Dưa Leo Baby | B35: Vỉ | C35: 0 | E35: =C35*D35 -> 0
A36: Dưa Leo Thường | B36: Kg | C36: 21 | D36: 12000 | E36: =C36*D36 -> 252000
A37: Ớt Chuông Đỏ | B37: Kg | C37: 85 | D37: 35000 | E37: =C37*D37 -> 2975000
A38: Ớt Chuông Đỏ | B38: Trái | C38: 0 | E38: =C38*D38 -> 0
A39: Ớt Chuông Vàng | B39: Kg | C39: 40 | D39: 35000 | E39: =C39*D39 -> 1400000
A40: Ớt Chuông Vàng | B40: Trái | C40: 0 | E40: =C40*D40 -> 0
...

Sheet 19.12
A1: hàng tồn cuối ngày 19/12 vr
A2: Tên Sản phẩm | B2: ĐVT | C2: tồn | D2: giá | E2: thành tiền
A3: Bắp Cải Tím | B3: Kg | C3: 0 | E3: =C3*D3 -> 0
A4: Bắp Cải Trái Tim | B4: Kg | C4: 550 | D4: 5500 | E4: =C4*D4 -> 3025000
A5: Bắp Cải Trắng | B5: Kg | C5: 300 | D5: 5000 | E5: =C5*D5 -> 1500000
A6: Bí Đỏ Hồ Lô | B6: Kg | C6: 10 | D6: 11500 | E6: =C6*D6 -> 115000
A7: Bí Đỏ Tròn | B7: Kg | C7: 1338 | D7: 7000 | E7: =C7*D7 -> 9366000
A8: Bí Ngòi Vàng | B8: Kg | C8: 0 | E8: =C8*D8 -> 0
A9: Bí Ngòi Xanh | B9: Kg | C9: 20 | D9: 20500 | E9: =C9*D9 -> 410000
A10: Bí Ngòi Xanh | B10: Trái | C10: 0 | E10: =C10*D10 -> 0
A11: Bí Non Nhật | B11: Kg | C11: 0 | E11: =C11*D11 -> 0
A12: Bí Non Nhật | B12: Trái | C12: 0 | E12: =C12*D12 -> 0
A13: Bơ 034 L1 | B13: Kg | C13: 0 | E13: =C13*D13 -> 0
A14: Bơ Booth | B14: Kg | C14: 0 | E14: =C14*D14 -> 0
A15: Bông Cải Trắng | B15: Kg | C15: 50 | D15: 25000 | E15: =C15*D15 -> 1250000
A16: Bông Cải Xanh 10Cm | B16: Kg | C16: 0 | E16: =C16*D16 -> 0
A17: Bông Cải Xanh 12Cm | B17: Kg | C17: 0 | E17: =C17*D17 -> 0
A18: Bông Cải Xanh 7Cm | B18: Kg | C18: 0 | E18: =C18*D18 -> 0
A19: Bông Cải Xanh Baby | B19: Vỉ | C19: 0 | E19: =C19*D19 -> 0
A20: Cà Chua Beef | B20: Kg | C20: 365 | D20: 21000 | E20: =C20*D20 -> 7665000
A21: Cà Chua Beef | B21: Vỉ | C21: 0 | E21: =C21*D21 -> 0
A22: Cà Chua Beef | B22: Vỉ 650gr | C22: 0 | E22: =C22*D22 -> 0
A23: Cà Chua Beef Trung | B23: Kg | C23: 27 | D23: 19000 | E23: =C23*D23 -> 513000
A24: Cà Chua Beef Trung | B24: Vỉ 500gr | C24: 0 | E24: =C24*D24 -> 0
A25: Cà Chua Bi Đỏ | B25: Kg | C25: 8 | D25: 30000 | E25: =C25*D25 -> 240000
A26: Cà Chua Bi Đỏ | B26: Hộp 300gr | C26: 98 | D26: 9000 | E26: =C26*D26 -> 882000
A27: Cà Chua Bi Mix | B27: Hộp | C27: 9 | D27: 16500 | E27: =C27*D27 -> 148500
A28: Cà Chua Socola | B28: Kg | C28: 0 | E28: =C28*D28 -> 0
A29: Cà Chua Socola | B29: Hộp 250GR | C29: 178 | D29: 12000 | E29: =C29*D29 -> 2136000
A30: Cà Chua Thường | B30: Kg | C30: 360 | D30: 22000 | E30: =C30*D30 -> 7920000
A31: Cà Chua Thường | B31: Vỉ | C31: 0 | E31: =C31*D31 -> 0
A32: Cà Chua Thường Trung | B32: Túi | C32: 80 | D32: 16000 | E32: =C32*D32 -> 1280000
A33: Cà Rốt | B33: Kg | C33: 95 | D33: 13000 | E33: =C33*D33 -> 1235000
A34: Cà Rốt | B34: Túi | C34: 0 | E34: =C34*D34 -> 0
A35: Cà Rốt Baby | B35: Kg | C35: 0 | E35: =C35*D35 -> 0
A36: Cà Rốt Baby | B36: Vỉ | C36: 0 | E36: =C36*D36 -> 0
A37: Cà Tím | B37: Kg | C37: 70 | D37: 10000 | E37: =C37*D37 -> 700000
A38: Cà Tím | B38: Cặp | C38: 0 | E38: =C38*D38 -> 0
A39: Cải Bó Xôi | B39: Kg | C39: 0 | E39: =C39*D39 -> 0
A40: Cải Bó Xôi | B40: Túi | C40: 0 | E40: =C40*D40 -> 0
...

Sheet 20.12
A2: Tên Sản phẩm | B2: ĐVT | C2: tồn | D2: giá | E2: thành tiền
A3: Bắp Cải Tím | B3: Kg | C3: 20 | D3: 36000 | E3: =C3*D3 -> 720000
A4: Bắp Cải Trái Tim | B4: Kg | C4: 778 | D4: 7000 | E4: =C4*D4 -> 5446000
A5: Bắp Cải Trắng | B5: Kg | C5: 440 | D5: 5000 | E5: =C5*D5 -> 2200000
A6: Bí Đỏ Hồ Lô | B6: Kg | C6: 0 | E6: =C6*D6 -> 0
A7: Bí Đỏ Tròn | B7: Kg | C7: 978 | D7: 7000 | E7: =C7*D7 -> 6846000
A8: Bí Ngòi Xanh | B8: Kg | C8: 18 | D8: 23000 | E8: =C8*D8 -> 414000
A9: Bí Ngòi Xanh | B9: Trái | C9: 0 | E9: =C9*D9 -> 0
A10: Bí Non Nhật | B10: Kg | C10: 40 | D10: 13000 | E10: =C10*D10 -> 520000
A11: Bí Non Nhật | B11: Trái | C11: 0 | E11: =C11*D11 -> 0
A12: Bơ Booth | B12: Kg | C12: 0 | E12: =C12*D12 -> 0
A13: Bông Cải Trắng | B13: Kg | C13: 0 | E13: =C13*D13 -> 0
A14: Bông Cải Xanh 10Cm | B14: Kg | C14: 0 | E14: =C14*D14 -> 0
A15: Bông Cải Xanh 12Cm | B15: Kg | C15: 0 | E15: =C15*D15 -> 0
A16: Bông Cải Xanh 7Cm | B16: Kg | C16: 0 | E16: =C16*D16 -> 0
A17: Bông Cải Xanh Baby | B17: Vỉ | C17: 3 | D17: 7600 | E17: =C17*D17 -> 22800
A18: Cà Chua Beef | B18: Kg | C18: 90 | D18: 21000 | E18: =C18*D18 -> 1890000
A19: Cà Chua Beef | B19: Vỉ | C19: 0 | E19: =C19*D19 -> 0
A20: Cà Chua Beef | B20: Vỉ 650gr | C20: 0 | E20: =C20*D20 -> 0
A21: Cà Chua Beef Trung | B21: Kg | C21: 271 | D21: 19000 | E21: =C21*D21 -> 5149000
A22: Cà Chua Beef Trung | B22: Vỉ 500gr | C22: 0 | E22: =C22*D22 -> 0
A23: Cà Chua Bi Đỏ | B23: Hộp 500gr | C23: 8 | D23: 15000 | E23: =C23*D23 -> 120000
A24: Cà Chua Bi Đỏ | B24: Hộp 300gr | C24: 72 | D24: 9000 | E24: =C24*D24 -> 648000
A25: Cà Chua Bi Mix | B25: Hộp | C25: 6 | D25: 16500 | E25: =C25*D25 -> 99000
A26: Cà Chua Socola | B26: Kg | C26: 4.8 | D26: 35000 | E26: =C26*D26 -> 168000
A27: Cà Chua Socola | B27: Hộp 250GR | C27: 154 | D27: 12000 | E27: =C27*D27 -> 1848000
A28: Cà Chua Thường | B28: Kg | C28: 420 | D28: 20000 | E28: =C28*D28 -> 8400000
A29: Cà Chua Thường | B29: Vỉ | C29: 0 | E29: =C29*D29 -> 0
A30: Cà Chua Thường Trung | B30: Túi | C30: 80 | D30: 16000 | E30: =C30*D30 -> 1280000
A31: Cà Rốt | B31: Kg | C31: 75 | D31: 13000 | E31: =C31*D31 -> 975000
A32: Cà Rốt | B32: Túi | C32: 0 | E32: =C32*D32 -> 0
A33: Cà Rốt Baby | B33: Vỉ | C33: 10 | D33: 10000 | E33: =C33*D33 -> 100000
A34: Cà Tím | B34: Kg | C34: 15 | D34: 10000 | E34: =C34*D34 -> 150000
A35: Cà Tím | B35: Cặp | C35: 0 | E35: =C35*D35 -> 0
A36: Cải Bó Xôi | B36: Kg | C36: 0 | E36: =C36*D36 -> 0
A37: Cải Bó Xôi | B37: Túi | C37: 0 | E37: =C37*D37 -> 0
A38: Cải Cầu Vồng | B38: Túi | C38: 7 | D38: 3900 | E38: =C38*D38 -> 27300
A39: Cải Kale | B39: Túi | C39: 22 | D39: 3900 | E39: =C39*D39 -> 85800
A40: Cải Thảo | B40: Kg | C40: 0 | E40: =C40*D40 -> 0
A41: Cải Thảo Hỏa Tiễn | B41: Kg | C41: 0 | E41: =C41*D41 -> 0
...

Sheet 21.12
A2: hàng tồn cuối ngày 21/12 vr
A3: Tên Sản phẩm | B3: ĐVT | C3: tồn | D3: giá | E3: thành tiền
A4: Cà Rốt | B4: Kg | C4: 260 | D4: 13000 | E4: =C4*D4 -> 3380000
A5: Cà Rốt | B5: Túi | E5: =C5*D5 -> 0
A6: Cà Rốt Baby | B6: Vỉ | C6: 10 | D6: 10000 | E6: =C6*D6 -> 100000
A7: Củ Cải Đỏ | B7: Hộp | C7: 6 | D7: 9000 | E7: =C7*D7 -> 54000
A8: Củ Dền | B8: Kg | C8: 30 | D8: 11000 | E8: =C8*D8 -> 330000
A9: Củ Hành Tây | B9: Kg | C9: 360 | D9: 19000 | E9: =C9*D9 -> 6840000
A10: Củ Hành Tây Trung | B10: Túi | C10: 173.33333 | D10: 4500 | E10: =C10*D10 -> 780000
A11: Củ Khoai Lang Mật Size 46 | B11: Kg | C11: 40 | D11: 24000 | E11: =C11*D11 -> 960000
A12: Củ Khoai Lang Nhật | B12: Kg | C12: 340 | D12: 17000 | E12: =C12*D12 -> 5780000
A13: Củ Khoai Tây Vàng | B13: Kg | C13: 400 | D13: 18000 | E13: =C13*D13 -> 7200000
A14: Củ Khoai Tây Vàng | B14: Túi | C14: 36 | D14: 8000 | E14: =C14*D14 -> 288000
A15: Bông Cải Xanh Baby | B15: Vỉ | E15: =C15*D15 -> 0
A16: Bắp Cải Trắng | B16: Kg | C16: 380 | D16: 5500 | E16: =C16*D16 -> 2090000
A17: Cải Bó Xôi | B17: Kg | C17: 8 | D17: 32000 | E17: =C17*D17 -> 256000
A18: Cải Bó Xôi | B18: Túi | E18: =C18*D18 -> 0
A19: Cải Kale | B19: Túi | C19: 9 | D19: 3900 | E19: =C19*D19 -> 35100
A20: Cải Thảo | B20: Kg | E20: =C20*D20 -> 0
A21: Cần Tây | B21: Cây | E21: =C21*D21 -> 0
A22: Cần Tây | B22: Kg | C22: 55 | D22: 10000 | E22: =C22*D22 -> 550000
A23: Xà Lách Lolo Xanh T.C | B23: Kg | C23: 5 | D23: 28000 | E23: =C23*D23 -> 140000
A24: Bí Đỏ Tròn | B24: Kg | C24: 1060 | D24: 7000 | E24: =C24*D24 -> 7420000
A25: Bí Ngòi Xanh | B25: Kg | C25: 70 | D25: 21000 | E25: =C25*D25 -> 1470000
A26: Bí Ngòi Xanh | B26: Trái | E26: =C26*D26 -> 0
A27: Bí Non Nhật | B27: Kg | E27: =C27*D27 -> 0
A28: Bí Non Nhật | B28: Trái | E28: =C28*D28 -> 0
A29: Cà Chua Beef | B29: Kg | C29: 155 | D29: 17000 | E29: =C29*D29 -> 2635000
A30: Cà Chua Beef | B30: Vỉ 650gr | E30: =C30*D30 -> 0
A31: Cà Chua Thường | B31: Kg | C31: 343 | D31: 18000 | E31: =C31*D31 -> 6174000
A32: Cà Chua Thường | B32: Vỉ | E32: =C32*D32 -> 0
A33: Cà Chua Thường Trung | B33: Túi | C33: 100 | D33: 13000 | E33: =C33*D33 -> 1300000
A34: Dưa Leo Baby | B34: Kg | E34: =C34*D34 -> 0
A35: Dưa Leo Baby | B35: Vỉ | E35: =C35*D35 -> 0
A36: Dưa Leo Thường | B36: Kg | C36: 40 | D36: 15000 | E36: =C36*D36 -> 600000
A37: Ớt Chuông Đỏ | B37: Kg | C37: 185 | D37: 32000 | E37: =C37*D37 -> 5920000
A38: Ớt Chuông Đỏ | B38: Trái | E38: =C38*D38 -> 0
A39: Ớt Chuông Vàng | B39: Kg | C39: 8 | D39: 35000 | E39: =C39*D39 -> 280000
A40: Ớt Chuông Vàng | B40: Trái | E40: =C40*D40 -> 0
A41: Ớt Chuông Xanh | B41: Kg | E41: =C41*D41 -> 0
...

Sheet 22.12
A1: hàng tồn cuối ngày 22/12 vr
A2: Tên Sản phẩm | B2: ĐVT | C2: tồn | D2: giá | E2: thành tiền
A3: Bắp Cải Tím | B3: Kg | C3: 30 | D3: 36000 | E3: =C3*D3 -> 1080000
A4: Bắp Cải Trái Tim | B4: Kg | C4: 1475 | D4: 5500 | E4: =C4*D4 -> 8112500
A5: Bắp Cải Trắng | B5: Kg | C5: 352 | D5: 5000 | E5: =C5*D5 -> 1760000
A6: Bí Đao Xanh | B6: Kg | C6: 0 | E6: =C6*D6 -> 0
A7: Bí Đỏ Hồ Lô | B7: Kg | C7: 4 | D7: 11500 | E7: =C7*D7 -> 46000
A8: Bí Đỏ Tròn | B8: Kg | C8: 930 | D8: 7000 | E8: =C8*D8 -> 6510000
A9: Bí Ngòi Vàng | B9: Kg | C9: 0 | E9: =C9*D9 -> 0
A10: Bí Ngòi Xanh | B10: Kg | C10: 128 | D10: 21000 | E10: =C10*D10 -> 2688000
A11: Bí Ngòi Xanh | B11: Trái | C11: 0 | E11: =C11*D11 -> 0
A12: Bí Non Nhật | B12: Kg | C12: 4 | D12: 14000 | E12: =C12*D12 -> 56000
A13: Bí Non Nhật | B13: Trái | C13: 0 | E13: =C13*D13 -> 0
A14: Bơ Booth | B14: Kg | C14: 0 | E14: =C14*D14 -> 0
A15: Bông Cải Trắng | B15: Kg | C15: 0 | E15: =C15*D15 -> 0
A16: Bông Cải Xanh 10Cm | B16: Kg | C16: 0 | E16: =C16*D16 -> 0
A17: Bông Cải Xanh 12Cm | B17: Kg | C17: 0 | E17: =C17*D17 -> 0
A18: Bông Cải Xanh 7Cm | B18: Kg | C18: 0 | E18: =C18*D18 -> 0
A19: Bông Cải Xanh Baby | B19: Vỉ | C19: 14 | D19: 8500 | E19: =C19*D19 -> 119000
A20: Cà Chua Beef | B20: Kg | C20: 20 | D20: 17000 | E20: =C20*D20 -> 340000
A21: Cà Chua Beef | B21: Vỉ | C21: 0 | E21: =C21*D21 -> 0
A22: Cà Chua Beef | B22: Vỉ 650gr | C22: 0 | E22: =C22*D22 -> 0
A23: Cà Chua Beef Trung | B23: Kg | C23: 25 | D23: 17000 | E23: =C23*D23 -> 425000
A24: Cà Chua Beef Trung | B24: Vỉ 500gr | C24: 0 | E24: =C24*D24 -> 0
A25: Cà Chua Bi Đỏ | B25: Kg | C25: 12 | D25: 30000 | E25: =C25*D25 -> 360000
A26: Cà Chua Bi Đỏ | B26: Hộp 300gr | C26: 81 | D26: 9000 | E26: =C26*D26 -> 729000
A27: Cà Chua Bi Mix | B27: Hộp | C27: 19 | D27: 14400 | E27: =C27*D27 -> 273600
A28: Cà Chua Socola | B28: Kg | C28: 0 | E28: =C28*D28 -> 0
A29: Cà Chua Socola | B29: Hộp 250GR | C29: 532 | D29: 12000 | E29: =C29*D29 -> 6384000
A30: Cà Chua Thường | B30: Kg | C30: 40 | D30: 14000 | E30: =C30*D30 -> 560000
A31: Cà Chua Thường | B31: Vỉ | C31: 0 | E31: =C31*D31 -> 0
A32: Cà Chua Thường Trung | B32: Túi | C32: 206 | D32: 13000 | E32: =C32*D32 -> 2678000
A33: Cà Rốt | B33: Kg | C33: 320 | D33: 13000 | E33: =C33*D33 -> 4160000
A34: Cà Rốt | B34: Túi | C34: 0 | E34: =C34*D34 -> 0
