Workbook

Sheet 1.12
A1: hàng tồn cuối ngày 1/12
A2: TÊN SẢN PHẨM | B2: TỒN TRƯỚC | C2: GIÁ NHẬP | D2: THÀNH TIỀN
A3: CÀ CHUA SÔCOLA 250GR (HỘP) VR | D3: =B3*C3 -> 0
A4: CÀ CHUA SÔCOLA 250GR (KG) -NA | D4: =B4*C4 -> 0
A5: CÀ CHUA SÔCOLA 250GR (KG) VR | D5: =B5*C5 -> 0
A6: CÀ CHUA SÔCOLA 250GR(KG) KQ | D6: =B6*C6 -> 0
A7: CÀ CHUA SÔCOLA 300GR (HỘP) VR | D7: =B7*C7 -> 0
A8: CÀ CHUA SOCOLA XÁ | D8: =B8*C8 -> 0
A9: CÀ CHUA SÔCOLA(HỘP) KQ | D9: =B9*C9 -> 0
A10: CÀ RỐT BABY | D10: =B10*C10 -> 0
A11: CÀ RỐT BABY (KG) KQ | D11: =B11*C11 -> 0
A12: CÀ RỐT BABY 200GR | D12: =B12*C12 -> 0
A13: CẢI CẦU VỒNG | D13: =B13*C13 -> 0
A14: CẢI CẦU VỒNG 300GR | D14: =B14*C14 -> 0
... A22: ỚT CHUÔNG 3 MÀU(KG)VR | D22: =B22*C22 -> 0
A23: ỚT CHUÔNG ĐỎ | B23: =20+39+75+50+50 -> 234 | C23: 27000 | D23: =B23*C23 -> 6318000
A24: ỚT CHUÔNG ĐỎ L1 | D24: =B24*C24 -> 0
A25: ỚT CHUÔNG ĐỎ(TRÁI) | D25: =B25*C25 -> 0
A26: ỚT CHUÔNG 3 MÀU 350G | B26: 30 | C26: 12000 | D26: =B26*C26 -> 360000
A27: ỚT CHUÔNG 3 MÀU KQ(KG) | D27: =B27*C27 -> 0
A28: ỚT CHUÔNG VÀNG | B28: =60+20 -> 80 | C28: 35000 | D28: =B28*C28 -> 2800000
A29: ỚT CHUÔNG VÀNG L1 | D29: =B29*C29 -> 0
A30: ỚT CHUÔNG VÀNG(TRÁI) | D30: =B30*C30 -> 0
A31: ỚT CHUÔNG VÀNG+ XANH (VỈ) | D31: =B31*C31 -> 0
A32: ỚT CHUÔNG XANH | B32: =40+5+12 -> 57 | C32: 35000 | D32: =B32*C32 -> 1995000
A33: ỚT CHUÔNG XANH L1 | B33: 20 | C33: 29000 | D33: =B33*C33 -> 580000
A34: ỚT CHUÔNG XANH(TRÁI) | D34: =B34*C34 -> 0
A35: CỦ DỀN | B35: 22 | C35: 13000 | D35: =B35*C35 -> 286000
A36: CỦ DỀN 600G | D36: =B36*C36 -> 0
A37: GỪNG 250GR | D37: =B37*C37 -> 0
A38: HỒNG GIÒN | D38: =B38*C38 -> 0
A39: XÀ LÁCH MỸ | D39: =B39*C39 -> 0
A40: KHOAI TÂY HỒNG | D40: =B40*C40 -> 0
A41: KHOAI TÂY HỒNG TÚI LƯỚI 500G | D41: =B41*C41 -> 0
A42: KHOAI TÂY VÀNG | B42: =60+40+15 -> 115 | C42: 12000 | D42: =B42*C42 -> 1380000
A43: KHOAI TÂY VÀNG ĐL | B43: =80+20+300+20+10+40+30 -> 500 | C43: 18000 | D43: =B43*C43 -> 9000000
A44: KHOAI TÂY VÀNG LỚN TÚI LƯỚI 500G | B44: 110 | C44: 15000 | D44: =B44*C44 -> 1650000
A45: KHOAI TÂY VÀNG RỬA | D45: =B45*C45 -> 0
A46: KHOAI TÂY VÀNG TRUNG TÚI LƯỚI 500G | D46: =B46*C46 -> 0
A47: CẢI THẢO DL | B47: 80 | C47: 9000 | D47: =B47*C47 -> 720000
...

Sheet 2.12
A1: hàng tồn cuối ngày 2/12
A2: TÊN SẢN PHẨM | B2: TỒN TRƯỚC | C2: GIÁ NHẬP | D2: THÀNH TIỀN
A3: CÀ CHUA SÔCOLA 250GR (HỘP) VR | D3: =B3*C3 -> 0
A4: CÀ CHUA SÔCOLA 250GR (KG) -NA | D4: =B4*C4 -> 0
A5: CÀ CHUA SÔCOLA 250GR (KG) VR | D5: =B5*C5 -> 0
A6: CÀ CHUA SÔCOLA 250GR(KG) KQ | D6: =B6*C6 -> 0
A7: CÀ CHUA SÔCOLA 300GR (HỘP) VR | D7: =B7*C7 -> 0
A8: CÀ CHUA SOCOLA XÁ | D8: =B8*C8 -> 0
A9: CÀ CHUA SÔCOLA(HỘP) KQ | D9: =B9*C9 -> 0
A10: CÀ RỐT BABY | D10: =B10*C10 -> 0
A11: CÀ RỐT BABY (KG) KQ | D11: =B11*C11 -> 0
A12: CÀ RỐT BABY 200GR | D12: =B12*C12 -> 0
A13: CẢI CẦU VỒNG | D13: =B13*C13 -> 0
A14: CẢI CẦU VỒNG 300GR | D14: =B14*C14 -> 0
... A22: ỚT CHUÔNG 3 MÀU(KG)VR | D22: =B22*C22 -> 0
A23: ỚT CHUÔNG ĐỎ | B23: 100 | C23: 26000 | D23: =B23*C23 -> 2600000
A24: ỚT CHUÔNG ĐỎ L1 | B24: 5 | C24: 24000 | D24: =B24*C24 -> 120000
A25: ỚT CHUÔNG ĐỎ(TRÁI) | D25: =B25*C25 -> 0
A26: ỚT CHUÔNG 3 MÀU 350G | B26: 18 | C26: 11000 | D26: =B26*C26 -> 198000
A27: ỚT CHUÔNG 3 MÀU KQ(KG) | D27: =B27*C27 -> 0
A28: ỚT CHUÔNG VÀNG | B28: 40 | C28: 32000 | D28: =B28*C28 -> 1280000
A29: ỚT CHUÔNG VÀNG L1 | D29: =B29*C29 -> 0
A30: ỚT CHUÔNG VÀNG(TRÁI) | D30: =B30*C30 -> 0
A31: ỚT CHUÔNG VÀNG+ XANH (VỈ) | D31: =B31*C31 -> 0
A32: ỚT CHUÔNG XANH | B32: 60 | C32: 32000 | D32: =B32*C32 -> 1920000
A33: ỚT CHUÔNG XANH L1 | B33: 25 | C33: 27000 | D33: =B33*C33 -> 675000
A34: ỚT CHUÔNG XANH(TRÁI) | D34: =B34*C34 -> 0
A35: CỦ DỀN | B35: =60+27+20+5 -> 112 | C35: 14000 | D35: =B35*C35 -> 1568000
A36: CỦ DỀN 600G | D36: =B36*C36 -> 0
A37: GỪNG 250GR | D37: =B37*C37 -> 0
A38: HỒNG GIÒN | D38: =B38*C38 -> 0
A39: XÀ LÁCH MỸ | D39: =B39*C39 -> 0
A40: KHOAI TÂY HỒNG | B40: 18 | C40: 25000 | D40: =B40*C40 -> 450000
A41: KHOAI TÂY HỒNG TÚI LƯỚI 500G | D41: =B41*C41 -> 0
A42: KHOAI TÂY VÀNG | B42: 27 | C42: 18000 | D42: =B42*C42 -> 486000
A43: KHOAI TÂY VÀNG ĐL | D43: =B43*C43 -> 0
A44: KHOAI TÂY VÀNG LỚN TÚI LƯỚI 500G | B44: 80 | C44: 15000 | D44: =B44*C44 -> 1200000
A45: KHOAI TÂY VÀNG RỬA | D45: =B45*C45 -> 0
A46: KHOAI TÂY VÀNG TRUNG TÚI LƯỚI 500G | D46: =B46*C46 -> 0
A47: CẢI THẢO DL | D47: =B47*C47 -> 0
...

Sheet 3.12
A1: hàng tồn cuối ngày 3/12
A2: TÊN SẢN PHẨM | B2: TỒN TRƯỚC | C2: GIÁ NHẬP | D2: THÀNH TIỀN
A3: BẮP CẢI TÍM | B3: 10 | C3: 22000 | D3: =B3*C3 -> 220000
A4: BẮP CẢI TÍM (BẮP) | D4: =B4*C4 -> 0
A5: BẮP CẢI TÍM SUSHI | D5: =B5*C5 -> 0
A6: BẮP CẢI TRẮNG | D6: =B6*C6 -> 0
A7: BẮP CẢI TRẮNG (BẮP) | D7: =B7*C7 -> 0
A8: BẮP CẢI TRẮNG MỘC CHÂU | D8: =B8*C8 -> 0
A9: BẮP CẢI TRẮNG SUSHI | D9: =B9*C9 -> 0
A10: BẮP MỸ | D10: =B10*C10 -> 0
A11: BẦU | D11: =B11*C11 -> 0
A12: BÍ ĐAO XANH | D12: =B12*C12 -> 0
A13: BÍ ĐAO XANH 400G | D13: =B13*C13 -> 0
A14: BÍ ĐỎ HỒ LÔ | D14: =B14*C14 -> 0
A15: BÍ ĐỎ MINI | D15: =B15*C15 -> 0
... A18: BÍ ĐỎ NON( KG) VR | D18: =B18*C18 -> 0
A19: BÍ ĐỎ TRÒN | B19: =2555+240 -> 2795 | C19: 5000 | D19: =B19*C19 -> 13975000
A20: BÍ MINI VÀNG 300GR | D20: =B20*C20 -> 0
A21: BÍ MINI VÀNG KG | D21: =B21*C21 -> 0
A22: BÍ NGÒI VÀNG | D22: =B22*C22 -> 0
A23: BÍ NGÒI VÀNG (TRÁI) | D23: =B23*C23 -> 0
A24: BÍ NGÒI XANH | B24: =40+10+30+45+10+10 -> 145 | C24: 12000 | D24: =B24*C24 -> 1740000
A25: BÍ NGÒI XANH(TRÁI) | D25: =B25*C25 -> 0
A26: BÍ NHẬT | D26: =B26*C26 -> 0
A27: BƠ 034 | D27: =B27*C27 -> 0
A28: BƠ BOOTH | D28: =B28*C28 -> 0
A29: BƠ SÁP | D29: =B29*C29 -> 0
A30: BÓ XÔI | D30: =B30*C30 -> 0
A31: BÓ XÔI 300G VR | D31: =B31*C31 -> 0
A32: BÓ XÔI-HN KQ | D32: =B32*C32 -> 0
A33: BÓ XÔI-NA | D33: =B33*C33 -> 0
A34: BÔNG ATISO | D34: =B34*C34 -> 0
A35: BÔNG BÍ | D35: =B35*C35 -> 0
A36: BÔNG BÍ TÚI 300GR | D36: =B36*C36 -> 0
A37: BÔNG CẢI TRẮNG | B37: 7 | C37: 29000 | D37: =B37*C37 -> 203000
A38: BÔNG CẢI TRẮNG (CÂY) | D38: =B38*C38 -> 0
A39: BÔNG CẢI XANH 10P | D39: =B39*C39 -> 0
A40: BÔNG CẢI XANH AEON | B40: 10 | C40: 28000 | D40: =B40*C40 -> 280000
A41: BÔNG CẢI XANH AEON (CÂY) | D41: =B41*C41 -> 0
A42: BÔNG CẢI XANH BABY (KG) | D42: =B42*C42 -> 0
...

Sheet 4.12
A1: hàng tồn cuối ngày 4/12
A2: TÊN SẢN PHẨM | B2: TỒN TRƯỚC | C2: GIÁ NHẬP | D2: THÀNH TIỀN
A3: CÀ CHUA SÔCOLA 250GR (HỘP) VR | D3: =B3*C3 -> 0
A4: CÀ CHUA SÔCOLA 250GR (KG) -NA | D4: =B4*C4 -> 0
A5: CÀ CHUA SÔCOLA 250GR (KG) VR | D5: =B5*C5 -> 0
A6: CÀ CHUA SÔCOLA 250GR(KG) KQ | D6: =B6*C6 -> 0
A7: CÀ CHUA SÔCOLA 300GR (HỘP) VR | D7: =B7*C7 -> 0
A8: CÀ CHUA SOCOLA XÁ | D8: =B8*C8 -> 0
A9: CÀ CHUA SÔCOLA(HỘP) KQ | D9: =B9*C9 -> 0
A10: CÀ RỐT BABY | D10: =B10*C10 -> 0
A11: CÀ RỐT BABY (KG) KQ | D11: =B11*C11 -> 0
A12: CÀ RỐT BABY 200GR | D12: =B12*C12 -> 0
A13: CẢI CẦU VỒNG | D13: =B13*C13 -> 0
A14: CẢI CẦU VỒNG 300GR | D14: =B14*C14 -> 0
... A22: ỚT CHUÔNG 3 MÀU(KG)VR | D22: =B22*C22 -> 0
A23: ỚT CHUÔNG ĐỎ | B23: 50 | C23: 24000 | D23: =B23*C23 -> 1200000
A24: ỚT CHUÔNG ĐỎ L1 | B24: 14 | C24: 22000 | D24: =B24*C24 -> 308000
A25: ỚT CHUÔNG ĐỎ(TRÁI) | D25: =B25*C25 -> 0
A26: ỚT CHUÔNG 3 MÀU 350G | D26: =B26*C26 -> 0
A27: ỚT CHUÔNG 3 MÀU KQ(KG) | D27: =B27*C27 -> 0
A28: ỚT CHUÔNG VÀNG | B28: 70 | C28: 30000 | D28: =B28*C28 -> 2100000
A29: ỚT CHUÔNG VÀNG L1 | B29: 8 | C29: 28000 | D29: =B29*C29 -> 224000
A30: ỚT CHUÔNG VÀNG(TRÁI) | D30: =B30*C30 -> 0
A31: ỚT CHUÔNG VÀNG+ XANH (VỈ) | D31: =B31*C31 -> 0
A32: ỚT CHUÔNG XANH | B32: =8+54 -> 62 | C32: 27000 | D32: =B32*C32 -> 1674000
A33: ỚT CHUÔNG XANH L1 | B33: =5+24+5 -> 34 | C33: 22000 | D33: =B33*C33 -> 748000
A34: ỚT CHUÔNG XANH(TRÁI) | D34: =B34*C34 -> 0
A35: CỦ DỀN | B35: 110 | C35: 14000 | D35: =B35*C35 -> 1540000
A36: CỦ DỀN 600G | D36: =B36*C36 -> 0
A37: GỪNG 250GR | D37: =B37*C37 -> 0
A38: HỒNG GIÒN | D38: =B38*C38 -> 0
A39: XÀ LÁCH MỸ | D39: =B39*C39 -> 0
A40: KHOAI TÂY HỒNG | B40: 20 | C40: 24000 | D40: =B40*C40 -> 480000
A41: KHOAI TÂY HỒNG TÚI LƯỚI 500G | D41: =B41*C41 -> 0
A42: KHOAI TÂY VÀNG | B42: 76 | C42: 12000 | D42: =B42*C42 -> 912000
A43: KHOAI TÂY VÀNG ĐL | B43: 260 | C43: 18000 | D43: =B43*C43 -> 4680000
A44: KHOAI TÂY VÀNG LỚN TÚI LƯỚI 500G | B44: 106 | C44: 15000 | D44: =B44*C44 -> 1590000
A45: KHOAI TÂY VÀNG RỬA | D45: =B45*C45 -> 0
A46: KHOAI TÂY VÀNG TRUNG TÚI LƯỚI 500G | D46: =B46*C46 -> 0
A47: CẢI THẢO DL | D47: =B47*C47 -> 0
...

Sheet 5.12
A1: hàng tồn cuối ngày 5/12
A2: TÊN SẢN PHẨM | B2: TỒN TRƯỚC | C2: GIÁ NHẬP | D2: THÀNH TIỀN
A3: CÀ CHUA SÔCOLA 250GR (HỘP) VR | B3: =7+9 -> 16 | C3: 7500 | D3: =B3*C3 -> 120000
A4: CÀ CHUA SÔCOLA 250GR (KG) -NA | D4: =B4*C4 -> 0
A5: CÀ CHUA SÔCOLA 250GR (KG) VR | D5: =B5*C5 -> 0
A6: CÀ CHUA SÔCOLA 250GR(KG) KQ | D6: =B6*C6 -> 0
A7: CÀ CHUA SÔCOLA 300GR (HỘP) VR | D7: =B7*C7 -> 0
A8: CÀ CHUA SOCOLA XÁ | D8: =B8*C8 -> 0
A9: CÀ CHUA SÔCOLA(HỘP) KQ | D9: =B9*C9 -> 0
A10: CÀ RỐT BABY | D10: =B10*C10 -> 0
A11: CÀ RỐT BABY (KG) KQ | D11: =B11*C11 -> 0
A12: CÀ RỐT BABY 200GR | D12: =B12*C12 -> 0
A13: CẢI CẦU VỒNG | D13: =B13*C13 -> 0
A14: CẢI CẦU VỒNG 300GR | D14: =B14*C14 -> 0
A15: CẢI KALE | D15: =B15*C15 -> 0
... A18: CHANH VÀNG TRÁI 180UP | D18: =B18*C18 -> 0
A19: CẦN TÂY (KG) | B19: 5 | C19: 21000 | D19: =B19*C19 -> 105000
A20: CẦN TÂY VR | D20: =B20*C20 -> 0
A21: CẦN TÂY(CÂY) | D21: =B21*C21 -> 0
A22: ỚT CHUÔNG 3 MÀU(KG)VR | D22: =B22*C22 -> 0
A23: ỚT CHUÔNG ĐỎ | B23: =20+15+127 -> 162 | C23: 22000 | D23: =B23*C23 -> 3564000
A24: ỚT CHUÔNG ĐỎ L1 | B24: 12 | C24: 19000 | D24: =B24*C24 -> 228000
A25: ỚT CHUÔNG ĐỎ(TRÁI) | D25: =B25*C25 -> 0
A26: ỚT CHUÔNG 3 MÀU 350G | B26: =39+30+12 -> 81 | C26: 10000 | D26: =B26*C26 -> 810000
A27: ỚT CHUÔNG 3 MÀU KQ(KG) | D27: =B27*C27 -> 0
A28: ỚT CHUÔNG VÀNG | B28: =10+100 -> 110 | C28: 29000 | D28: =B28*C28 -> 3190000
A29: ỚT CHUÔNG VÀNG L1 | D29: =B29*C29 -> 0
A30: ỚT CHUÔNG VÀNG(TRÁI) | D30: =B30*C30 -> 0
A31: ỚT CHUÔNG VÀNG+ XANH (VỈ) | D31: =B31*C31 -> 0
A32: ỚT CHUÔNG XANH | B32: =10+30+20 -> 60 | C32: 27000 | D32: =B32*C32 -> 1620000
A33: ỚT CHUÔNG XANH L1 | B33: 15 | C33: 21000 | D33: =B33*C33 -> 315000
A34: ỚT CHUÔNG XANH(TRÁI) | D34: =B34*C34 -> 0
A35: CỦ DỀN | B35: =20+20+10+26 -> 76 | C35: 13500 | D35: =B35*C35 -> 1026000
A36: CỦ DỀN 600G | D36: =B36*C36 -> 0
A37: GỪNG 250GR | D37: =B37*C37 -> 0
A38: HỒNG GIÒN | B38: 3 | C38: 27000 | D38: =B38*C38 -> 81000
A39: XÀ LÁCH MỸ | D39: =B39*C39 -> 0
A40: KHOAI TÂY HỒNG | D40: =B40*C40 -> 0
A41: KHOAI TÂY HỒNG TÚI LƯỚI 500G | D41: =B41*C41 -> 0
A42: KHOAI TÂY VÀNG | D42: =B42*C42 -> 0
...

Sheet 6.12
A1: hàng tồn cuối ngày 6/12
A2: TÊN SẢN PHẨM | B2: TỒN TRƯỚC | C2: GIÁ NHẬP | D2: THÀNH TIỀN
A3: CÀ CHUA SÔCOLA 250GR (HỘP) VR | B3: 13 | C3: 8500 | D3: =B3*C3 -> 110500
A4: CÀ CHUA SÔCOLA 250GR (KG) -NA | D4: =B4*C4 -> 0
A5: CÀ CHUA SÔCOLA 250GR (KG) VR | D5: =B5*C5 -> 0
A6: CÀ CHUA SÔCOLA 250GR(KG) KQ | D6: =B6*C6 -> 0
A7: CÀ CHUA SÔCOLA 300GR (HỘP) VR | D7: =B7*C7 -> 0
A8: CÀ CHUA SOCOLA XÁ | D8: =B8*C8 -> 0
A9: CÀ CHUA SÔCOLA(HỘP) KQ | D9: =B9*C9 -> 0
A10: CÀ RỐT BABY | D10: =B10*C10 -> 0
A11: CÀ RỐT BABY (KG) KQ | D11: =B11*C11 -> 0
A12: CÀ RỐT BABY 200GR | D12: =B12*C12 -> 0
A13: CẢI CẦU VỒNG | D13: =B13*C13 -> 0
A14: CẢI CẦU VỒNG 300GR | D14: =B14*C14 -> 0
A15: CẢI KALE | D15: =B15*C15 -> 0
... A22: ỚT CHUÔNG 3 MÀU(KG)VR | D22: =B22*C22 -> 0
A23: ỚT CHUÔNG ĐỎ | B23: =10+6+20+30 -> 66 | C23: 21000 | D23: =B23*C23 -> 1386000
A24: ỚT CHUÔNG ĐỎ L1 | B24: 10 | C24: 18000 | D24: =B24*C24 -> 180000
A25: ỚT CHUÔNG ĐỎ(TRÁI) | D25: =B25*C25 -> 0
A26: ỚT CHUÔNG 3 MÀU 350G | B26: 145 | C26: 10000 | D26: =B26*C26 -> 1450000
A27: ỚT CHUÔNG 3 MÀU KQ(KG) | D27: =B27*C27 -> 0
A28: ỚT CHUÔNG VÀNG | B28: =20+10+15 -> 45 | C28: 28000 | D28: =B28*C28 -> 1260000
A29: ỚT CHUÔNG VÀNG L1 | D29: =B29*C29 -> 0
A30: ỚT CHUÔNG VÀNG(TRÁI) | D30: =B30*C30 -> 0
A31: ỚT CHUÔNG VÀNG+ XANH (VỈ) | D31: =B31*C31 -> 0
A32: ỚT CHUÔNG XANH | B32: =5+25 -> 30 | C32: 26000 | D32: =B32*C32 -> 780000
A33: ỚT CHUÔNG XANH L1 | B33: =9+8+6 -> 23 | C33: 21000 | D33: =B33*C33 -> 483000
A34: ỚT CHUÔNG XANH(TRÁI) | D34: =B34*C34 -> 0
A35: CỦ DỀN | B35: 110 | C35: 13500 | D35: =B35*C35 -> 1485000
A36: CỦ DỀN 600G | D36: =B36*C36 -> 0
A37: GỪNG 250GR | D37: =B37*C37 -> 0
A38: HỒNG GIÒN | D38: =B38*C38 -> 0
A39: XÀ LÁCH MỸ | D39: =B39*C39 -> 0
A40: KHOAI TÂY HỒNG | B40: 12 | C40: 24000 | D40: =B40*C40 -> 288000
A41: KHOAI TÂY HỒNG TÚI LƯỚI 500G | D41: =B41*C41 -> 0
A42: KHOAI TÂY VÀNG | B42: =30+10 -> 40 | C42: 12000 | D42: =B42*C42 -> 480000
A43: KHOAI TÂY VÀNG ĐL | B43: =25+30+220 -> 275 | C43: 17000 | D43: =B43*C43 -> 4675000
A44: KHOAI TÂY VÀNG LỚN TÚI LƯỚI 500G | B44: 60 | C44: 15000 | D44: =B44*C44 -> 900000
A45: KHOAI TÂY VÀNG RỬA | D45: =B45*C45 -> 0
A46: KHOAI TÂY VÀNG TRUNG TÚI LƯỚI 500G | D46: =B46*C46 -> 0
...

Sheet 7.12
A1: hàng tồn cuối ngày 7/12
A2: TÊN SẢN PHẨM | B2: TỒN TRƯỚC | C2: GIÁ NHẬP | D2: THÀNH TIỀN
A3: CÀ CHUA SÔCOLA 250GR (HỘP) VR | D3: =B3*C3 -> 0
A4: CÀ CHUA SÔCOLA 250GR (KG) -NA | D4: =B4*C4 -> 0
A5: CÀ CHUA SÔCOLA 250GR (KG) VR | D5: =B5*C5 -> 0
A6: CÀ CHUA SÔCOLA 250GR(KG) KQ | D6: =B6*C6 -> 0
A7: CÀ CHUA SÔCOLA 300GR (HỘP) VR | D7: =B7*C7 -> 0
A8: CÀ CHUA SOCOLA XÁ | D8: =B8*C8 -> 0
A9: CÀ CHUA SÔCOLA(HỘP) KQ | D9: =B9*C9 -> 0
A10: CÀ RỐT BABY | D10: =B10*C10 -> 0
A11: CÀ RỐT BABY (KG) KQ | D11: =B11*C11 -> 0
A12: CÀ RỐT BABY 200GR | B12: 1.6 | C12: 60000 | D12: =B12*C12 -> 96000
A13: CẢI CẦU VỒNG | B13: 8 | C13: 22000 | D13: =B13*C13 -> 176000
A14: CẢI CẦU VỒNG 300GR | D14: =B14*C14 -> 0
A15: CẢI KALE | D15: =B15*C15 -> 0
A16: CẢI KALE 300GR | D16: =B16*C16 -> 0
A17: CHANH VÀNG (KG) | D17: =B17*C17 -> 0
A18: CHANH VÀNG TRÁI 180UP | D18: =B18*C18 -> 0
A19: CẦN TÂY (KG) | B19: 30 | C19: 20000 | D19: =B19*C19 -> 600000
A20: CẦN TÂY VR | D20: =B20*C20 -> 0
A21: CẦN TÂY(CÂY) | D21: =B21*C21 -> 0
A22: ỚT CHUÔNG 3 MÀU(KG)VR | D22: =B22*C22 -> 0
A23: ỚT CHUÔNG ĐỎ | B23: 100 | C23: 22000 | D23: =B23*C23 -> 2200000
A24: ỚT CHUÔNG ĐỎ L1 | B24: 11 | C24: 18000 | D24: =B24*C24 -> 198000
A25: ỚT CHUÔNG ĐỎ(TRÁI) | D25: =B25*C25 -> 0
A26: ỚT CHUÔNG 3 MÀU 350G | B26: =20+12+50 -> 82 | C26: 10000 | D26: =B26*C26 -> 820000
A27: ỚT CHUÔNG 3 MÀU KQ(KG) | D27: =B27*C27 -> 0
A28: ỚT CHUÔNG VÀNG | B28: 80 | C28: 28000 | D28: =B28*C28 -> 2240000
A29: ỚT CHUÔNG VÀNG L1 | B29: =16+5 -> 21 | C29: 23000 | D29: =B29*C29 -> 483000
A30: ỚT CHUÔNG VÀNG(TRÁI) | D30: =B30*C30 -> 0
A31: ỚT CHUÔNG VÀNG+ XANH (VỈ) | D31: =B31*C31 -> 0
A32: ỚT CHUÔNG XANH | B32: =10+4+20+10 -> 44 | C32: 26000 | D32: =B32*C32 -> 1144000
A33: ỚT CHUÔNG XANH L1 | B33: =20+6+15 -> 41 | C33: 22000 | D33: =B33*C33 -> 902000
A34: ỚT CHUÔNG XANH(TRÁI) | D34: =B34*C34 -> 0
A35: CỦ DỀN | B35: =27+20 -> 47 | C35: 13500 | D35: =B35*C35 -> 634500
A36: CỦ DỀN 600G | D36: =B36*C36 -> 0
A37: GỪNG 250GR | D37: =B37*C37 -> 0
A38: HỒNG GIÒN | D38: =B38*C38 -> 0
A39: XÀ LÁCH MỸ | D39: =B39*C39 -> 0
A40: KHOAI TÂY HỒNG | B40: 6 | C40: 24000 | D40: =B40*C40 -> 144000
...

Sheet 8.12
A1: hàng tồn cuối ngày 8/12
A2: TÊN SẢN PHẨM | B2: TỒN TRƯỚC | C2: GIÁ NHẬP | D2: THÀNH TIỀN
A3: CÀ CHUA SÔCOLA 250GR (HỘP) VR | D3: =B3*C3 -> 0
A4: CÀ CHUA SÔCOLA 250GR (KG) -NA | D4: =B4*C4 -> 0
A5: CÀ CHUA SÔCOLA 250GR (KG) VR | D5: =B5*C5 -> 0
A6: CÀ CHUA SÔCOLA 250GR(KG) KQ | D6: =B6*C6 -> 0
A7: CÀ CHUA SÔCOLA 300GR (HỘP) VR | D7: =B7*C7 -> 0
A8: CÀ CHUA SOCOLA XÁ | D8: =B8*C8 -> 0
A9: CÀ CHUA SÔCOLA(HỘP) KQ | D9: =B9*C9 -> 0
A10: CÀ RỐT BABY | D10: =B10*C10 -> 0
A11: CÀ RỐT BABY (KG) KQ | D11: =B11*C11 -> 0
A12: CÀ RỐT BABY 200GR | B12: 1.6 | C12: 60000 | D12: =B12*C12 -> 96000
A13: CẢI CẦU VỒNG | D13: =B13*C13 -> 0
A14: CẢI CẦU VỒNG 300GR | D14: =B14*C14 -> 0
A15: CẢI KALE | D15: =B15*C15 -> 0
A16: CẢI KALE 300GR | D16: =B16*C16 -> 0
A17: CHANH VÀNG (KG) | D17: =B17*C17 -> 0
A18: CHANH VÀNG TRÁI 180UP | D18: =B18*C18 -> 0
A19: CẦN TÂY (KG) | D19: =B19*C19 -> 0
A20: CẦN TÂY VR | D20: =B20*C20 -> 0
A21: CẦN TÂY(CÂY) | D21: =B21*C21 -> 0
A22: ỚT CHUÔNG 3 MÀU(KG)VR | D22: =B22*C22 -> 0
A23: ỚT CHUÔNG ĐỎ | B23: =47+10+3 -> 60 | C23: 20000 | D23: =B23*C23 -> 1200000
A24: ỚT CHUÔNG ĐỎ L1 | B24: 5 | C24: 18000 | D24: =B24*C24 -> 90000
A25: ỚT CHUÔNG ĐỎ(TRÁI) | D25: =B25*C25 -> 0
A26: ỚT CHUÔNG 3 MÀU 350G | B26: 17 | C26: 10000 | D26: =B26*C26 -> 170000
A27: ỚT CHUÔNG 3 MÀU KQ(KG) | D27: =B27*C27 -> 0
A28: ỚT CHUÔNG VÀNG | B28: =40+20+16 -> 76 | C28: 28000 | D28: =B28*C28 -> 2128000
A29: ỚT CHUÔNG VÀNG L1 | D29: =B29*C29 -> 0
A30: ỚT CHUÔNG VÀNG(TRÁI) | D30: =B30*C30 -> 0
A31: ỚT CHUÔNG VÀNG+ XANH (VỈ) | D31: =B31*C31 -> 0
A32: ỚT CHUÔNG XANH | B32: =28+8+7+7+16 -> 66 | C32: 26000 | D32: =B32*C32 -> 1716000
A33: ỚT CHUÔNG XANH L1 | B33: 17 | C33: 22000 | D33: =B33*C33 -> 374000
A34: ỚT CHUÔNG XANH(TRÁI) | D34: =B34*C34 -> 0
A35: CỦ DỀN | B35: =25+12 -> 37 | C35: 13500 | D35: =B35*C35 -> 499500
A36: CỦ DỀN 600G | D36: =B36*C36 -> 0
A37: GỪNG 250GR | D37: =B37*C37 -> 0
A38: HỒNG GIÒN | D38: =B38*C38 -> 0
A39: XÀ LÁCH MỸ | D39: =B39*C39 -> 0
A40: KHOAI TÂY HỒNG | B40: =15+20 -> 35 | C40: 24000 | D40: =B40*C40 -> 840000
...

Sheet 9.12
A1: hàng tồn cuối ngày 9/12
A2: TÊN SẢN PHẨM | B2: TỒN TRƯỚC | C2: GIÁ NHẬP | D2: THÀNH TIỀN
A3: BẮP CẢI TÍM | B3: 10 | C3: 26000 | D3: =B3*C3 -> 260000
A4: CÀ CHUA SÔCOLA 250GR (KG) -NA | D4: =B4*C4 -> 0
A5: CÀ CHUA SÔCOLA 250GR (KG) VR | D5: =B5*C5 -> 0
A6: CÀ CHUA SÔCOLA 250GR(KG) KQ | D6: =B6*C6 -> 0
A7: CÀ CHUA SÔCOLA 300GR (HỘP) VR | D7: =B7*C7 -> 0
A8: CÀ CHUA SOCOLA XÁ | D8: =B8*C8 -> 0
A9: CÀ CHUA SÔCOLA(HỘP) KQ | D9: =B9*C9 -> 0
A10: CÀ RỐT BABY | D10: =B10*C10 -> 0
A11: CÀ RỐT BABY (KG) KQ | D11: =B11*C11 -> 0
A12: CÀ RỐT BABY 200GR | D12: =B12*C12 -> 0
A13: CẢI CẦU VỒNG | D13: =B13*C13 -> 0
A14: CẢI CẦU VỒNG 300GR | D14: =B14*C14 -> 0
A15: CẢI KALE | D15: =B15*C15 -> 0
... A22: ỚT CHUÔNG 3 MÀU(KG)VR | D22: =B22*C22 -> 0
A23: BÍ ĐỎ NON TRÁI VR | B23: 10 | C23: 4200 | D23: =B23*C23 -> 42000
A24: ỚT CHUÔNG ĐỎ L1 | D24: =B24*C24 -> 0
A25: ỚT CHUÔNG ĐỎ(TRÁI) | D25: =B25*C25 -> 0
A26: BÍ ĐỎ TRÒN | B26: =1645+150+30+30 -> 1855 | C26: 4000 | D26: =B26*C26 -> 7420000
A27: ỚT CHUÔNG 3 MÀU KQ(KG) | D27: =B27*C27 -> 0
A28: BÍ NGÒI VÀNG | B28: 3.5 | C28: 25000 | D28: =B28*C28 -> 87500
A29: ỚT CHUÔNG VÀNG L1 | D29: =B29*C29 -> 0
A30: ỚT CHUÔNG VÀNG(TRÁI) | D30: =B30*C30 -> 0
A31: ỚT CHUÔNG VÀNG+ XANH (VỈ) | D31: =B31*C31 -> 0
A32: BÍ NGÒI XANH | B32: =25+10+20 -> 55 | C32: 12000 | D32: =B32*C32 -> 660000
A33: ỚT CHUÔNG XANH L1 | D33: =B33*C33 -> 0
A34: ỚT CHUÔNG XANH(TRÁI) | D34: =B34*C34 -> 0
A35: BƠ BOOTH | B35: 16 | C35: 45000 | D35: =B35*C35 -> 720000
A36: CỦ DỀN 600G | D36: =B36*C36 -> 0
A37: GỪNG 250GR | D37: =B37*C37 -> 0
A38: HỒNG GIÒN | D38: =B38*C38 -> 0
A39: XÀ LÁCH MỸ | D39: =B39*C39 -> 0
A40: KHOAI TÂY HỒNG | D40: =B40*C40 -> 0
A41: KHOAI TÂY HỒNG TÚI LƯỚI 500G | D41: =B41*C41 -> 0
A42: BÔNG BÍ | B42: 0.5 | C42: 55000 | D42: =B42*C42 -> 27500
A43: BÔNG CẢI TRẮNG | B43: 4 | C43: 22000 | D43: =B43*C43 -> 88000
A44: CÀ CHUA | B44: =240+200+10 -> 450 | C44: 23000 | D44: =B44*C44 -> 10350000
A45: KHOAI TÂY VÀNG RỬA | D45: =B45*C45 -> 0
A46: KHOAI TÂY VÀNG TRUNG TÚI LƯỚI 500G | D46: =B46*C46 -> 0
...

Sheet 10.12
A1: Hàng tồn cuối ngày 10/12 | C1: Stock
A2: TÊN SẢN PHẨM | B2: ĐVT | C2: TỒN TRƯỚC | D2: GIÁ NHẬP | E2: THÀNH TIỀN
A4: BẮP CẢI TÍM | B4: Kg | C4: 20 | D4: =_xlfn.IFNA(VLOOKUP(A4,'9.12'!A3:C303,3,),) -> 26000 | E4: =+D4*C4 -> 520000
A5: BẮP CẢI TÍM (BẮP) | B5: BẮP
A6: BẮP CẢI TÍM SUSHI | B6: Kg
A7: BẮP CẢI TRẮNG | B7: Kg
A8: BẮP CẢI TRẮNG (BẮP) | B8: BẮP
A9: BẮP CẢI TRẮNG MỘC CHÂU | B9: Kg
A10: BẮP CẢI TRẮNG SUSHI | B10: Kg
A11: BẮP MỸ | B11: Kg
A12: BẦU | B12: Kg
A13: BÍ ĐAO XANH | B13: Kg
A14: BÍ ĐAO XANH 400G | B14: TRÁI
A15: BÍ ĐỎ HỒ LÔ | B15: Kg
A16: BÍ ĐỎ MINI | B16: Kg
... A19: BÍ ĐỎ NON( KG) VR | B19: Kg
A20: BÍ ĐỎ TRÒN | B20: Kg | C20: 1715 | D20: =_xlfn.IFNA(VLOOKUP(A20,'9.12'!A19:C319,3,),) -> 4000 | E20: =+D20*C20 -> 6860000
A21: BÍ MINI VÀNG 300GR | B21: TRÁI
A22: BÍ MINI VÀNG KG | B22: Kg
A23: BÍ NGÒI VÀNG | B23: Kg | C23: 7 | D23: =_xlfn.IFNA(VLOOKUP(A23,'9.12'!A22:C322,3,),) -> 25000 | E23: =+D23*C23 -> 175000
A24: BÍ NGÒI VÀNG (TRÁI) | B24: TRÁI
A25: BÍ NGÒI XANH | B25: Kg | C25: 94 | D25: =_xlfn.IFNA(VLOOKUP(A25,'9.12'!A24:C324,3,),) -> 12000 | E25: =+D25*C25 -> 1128000
A26: BÍ NGÒI XANH(TRÁI) | B26: TRÁI
A27: BÍ NHẬT | B27: Kg
A28: BƠ 034 | B28: Kg
A29: BƠ BOOTH | B29: Kg
A30: BƠ SÁP | B30: Kg
A31: BÓ XÔI | B31: Kg | C31: 2 | D31: 30000 | E31: =+D31*C31 -> 60000
A32: BÓ XÔI 300G VR | B32: TÚI
A33: BÓ XÔI-HN KQ | B33: Kg
A34: BÓ XÔI-NA | B34: Kg
A35: BÔNG ATISO | B35: Kg
A36: BÔNG BÍ | B36: Kg
A37: BÔNG BÍ TÚI 300GR | B37: VỈ
A38: BÔNG CẢI TRẮNG | B38: Kg | C38: 8 | D38: =_xlfn.IFNA(VLOOKUP(A38,'9.12'!A37:C337,3,),) -> 22000 | E38: =+D38*C38 -> 176000
A39: BÔNG CẢI TRẮNG (CÂY) | B39: CÂY
A40: BÔNG CẢI XANH 10P | B40: Kg
A41: BÔNG CẢI XANH AEON | B41: Kg
A42: BÔNG CẢI XANH AEON (CÂY) | B42: CÂY
A43: BÔNG CẢI XANH BABY (KG) | B43: Kg
...

Sheet 11.12
A1: Hàng tồn cuối ngày 11/12 | C1: Stock
A2: TÊN SẢN PHẨM | B2: ĐVT | C2: TỒN TRƯỚC | D2: GIÁ NHẬP | E2: THÀNH TIỀN
A4: BẮP CẢI TÍM | B4: Kg
A5: BẮP CẢI TÍM (BẮP) | B5: BẮP
A6: BẮP CẢI TÍM SUSHI | B6: Kg
A7: BẮP CẢI TRẮNG | B7: Kg
A8: BẮP CẢI TRẮNG (BẮP) | B8: BẮP
A9: BẮP CẢI TRẮNG MỘC CHÂU | B9: Kg
A10: BẮP CẢI TRẮNG SUSHI | B10: Kg
A11: BẮP MỸ | B11: Kg
A12: BẦU | B12: Kg
A13: BÍ ĐAO XANH | B13: Kg
A14: BÍ ĐAO XANH 400G | B14: TRÁI
A15: BÍ ĐỎ HỒ LÔ | B15: Kg | C15: 5 | D15: 8500 | E15: =+D15*C15 -> 42500
A16: BÍ ĐỎ MINI | B16: Kg
A17: BÍ ĐỎ NON (KG)KQ | B17: Kg
A18: BÍ ĐỎ NON TRÁI VR | B18: TRÁI | C18: 10 | D18: =12000*0.3 -> 3600 | E18: =+D18*C18 -> 36000
A19: BÍ ĐỎ NON( KG) VR | B19: Kg
A20: BÍ ĐỎ TRÒN | B20: Kg | C20: 270 | D20: =_xlfn.IFNA(VLOOKUP(A20,'10.12'!A9:D303,4,),) -> 4000 | E20: =+D20*C20 -> 1080000
A21: BÍ MINI VÀNG 300GR | B21: TRÁI
A22: BÍ MINI VÀNG KG | B22: Kg
A23: BÍ NGÒI VÀNG | B23: Kg | C23: 2 | D23: =_xlfn.IFNA(VLOOKUP(A23,'10.12'!A12:D306,4,),) -> 25000 | E23: =+D23*C23 -> 50000
A24: BÍ NGÒI VÀNG (TRÁI) | B24: TRÁI
A25: BÍ NGÒI XANH | B25: Kg | C25: 65 | D25: =_xlfn.IFNA(VLOOKUP(A25,'10.12'!A14:D308,4,),) -> 12000 | E25: =+D25*C25 -> 780000
A26: BÍ NGÒI XANH(TRÁI) | B26: TRÁI
A27: BÍ NHẬT | B27: Kg
A28: BƠ 034 | B28: Kg
A29: BƠ BOOTH | B29: Kg | C29: 2 | D29: 55000 | E29: =+D29*C29 -> 110000
A30: BƠ SÁP | B30: Kg
A31: BÓ XÔI | B31: Kg
A32: BÓ XÔI 300G VR | B32: TÚI
A33: BÓ XÔI-HN KQ | B33: Kg
A34: BÓ XÔI-NA | B34: Kg
A35: BÔNG ATISO | B35: Kg
A36: BÔNG BÍ | B36: Kg
A37: BÔNG BÍ TÚI 300GR | B37: VỈ
A38: BÔNG CẢI TRẮNG | B38: Kg
A39: BÔNG CẢI TRẮNG (CÂY) | B39: CÂY
A40: BÔNG CẢI XANH 10P | B40: Kg
A41: BÔNG CẢI XANH AEON | B41: Kg
...

Sheet 12.12
A1: hàng tồn cuối ngày 12/12
A2: TÊN SẢN PHẨM | B2: TỒN TRƯỚC | C2: GIÁ NHẬP | D2: THÀNH TIỀN
A3: BẮP CẢI TÍM | B3: 92 | C3: 26000 | D3: =B3*C3 -> 2392000
A4: CÀ CHUA SÔCOLA 250GR (KG) -NA | D4: =B4*C4 -> 0
A5: CÀ CHUA SÔCOLA 250GR (KG) VR | D5: =B5*C5 -> 0
A6: CÀ CHUA SÔCOLA 250GR(KG) KQ | D6: =B6*C6 -> 0
A7: CÀ CHUA SÔCOLA 300GR (HỘP) VR | D7: =B7*C7 -> 0
A8: CÀ CHUA SOCOLA XÁ | D8: =B8*C8 -> 0
A9: CÀ CHUA SÔCOLA(HỘP) KQ | D9: =B9*C9 -> 0
A10: CÀ RỐT BABY | D10: =B10*C10 -> 0
A11: CÀ RỐT BABY (KG) KQ | D11: =B11*C11 -> 0
A12: CÀ RỐT BABY 200GR | D12: =B12*C12 -> 0
A13: CẢI CẦU VỒNG | D13: =B13*C13 -> 0
A14: CẢI CẦU VỒNG 300GR | D14: =B14*C14 -> 0
A15: CẢI KALE | D15: =B15*C15 -> 0
... A22: ỚT CHUÔNG 3 MÀU(KG)VR | D22: =B22*C22 -> 0
A23: BẮP CẢI TRẮNG | B23: 80 | C23: 6500 | D23: =B23*C23 -> 520000
A24: BÍ ĐỎ TRÒN | B24: =1500+30+30+90 -> 1650 | C24: 4000 | D24: =B24*C24 -> 6600000
A25: ỚT CHUÔNG ĐỎ(TRÁI) | D25: =B25*C25 -> 0
A26: BÍ NGÒI XANH | B26: =75+20+15 -> 110 | C26: 12000 | D26: =B26*C26 -> 1320000
A27: ỚT CHUÔNG 3 MÀU KQ(KG) | D27: =B27*C27 -> 0
A28: BÔNG CẢI XANH AEON | B28: =6+5+5+30 -> 46 | C28: 25000 | D28: =B28*C28 -> 1150000
A29: ỚT CHUÔNG VÀNG L1 | D29: =B29*C29 -> 0
A30: ỚT CHUÔNG VÀNG(TRÁI) | D30: =B30*C30 -> 0
A31: ỚT CHUÔNG VÀNG+ XANH (VỈ) | D31: =B31*C31 -> 0
A32: BÔNG CẢI XANH BIGC | B32: 15 | C32: 16000 | D32: =B32*C32 -> 240000
A33: CÀ CHUA | B33: =60+40+100+40+100+120 -> 460 | C33: 22000 | D33: =B33*C33 -> 10120000
A34: ỚT CHUÔNG XANH(TRÁI) | D34: =B34*C34 -> 0
A35: CÀ CHUA BI COOP | B35: 5 | C35: 13500 | D35: =B35*C35 -> 67500
A36: CỦ DỀN 600G | D36: =B36*C36 -> 0
A37: GỪNG 250GR | D37: =B37*C37 -> 0
A38: HỒNG GIÒN | D38: =B38*C38 -> 0
A39: XÀ LÁCH MỸ | D39: =B39*C39 -> 0
A40: CÀ CHUA L1 | B40: 40 | C40: 19000 | D40: =B40*C40 -> 760000
A41: KHOAI TÂY HỒNG TÚI LƯỚI 500G | D41: =B41*C41 -> 0
A42: CÀ CHUA SÔCOLA 250GR (HỘP) VR | B42: 13 | C42: 8000 | D42: =B42*C42 -> 104000
A43: CÀ CHUA Ý | B43: =135+15+15 -> 165 | C43: 26500 | D43: =B43*C43 -> 4372500
A44: CÀ RỐT DL L1 | B44: 45 | C44: 10000 | D44: =B44*C44 -> 450000
A45: KHOAI TÂY VÀNG RỬA | D45: =B45*C45 -> 0
A46: KHOAI TÂY VÀNG TRUNG TÚI LƯỚI 500G | D46: =B46*C46 -> 0
...

Sheet 13.12
A1: Hàng tồn cuối ngày 13/12
A2: TÊN SẢN PHẨM | B2: ĐVT | C2: TỒN TRƯỚC | D2: GIÁ | E2: THÀNH TIỀN
A4: CÀ CHUA SÔCOLA 250GR (HỘP) VR | B4: HỘP
A5: CÀ CHUA SÔCOLA 250GR (KG) -NA | B5: Kg
A6: CÀ CHUA SÔCOLA 250GR (KG) VR | B6: Kg
A7: CÀ CHUA SÔCOLA 250GR(KG) KQ | B7: Kg
A8: CÀ CHUA SÔCOLA 300GR (HỘP) VR | B8: HỘP
A9: CÀ CHUA SOCOLA XÁ | B9: Kg
A10: CÀ CHUA SÔCOLA(HỘP) KQ | B10: HỘP
A11: CÀ RỐT BABY | B11: Kg
A12: CÀ RỐT BABY (KG) KQ | B12: Kg
A13: CÀ RỐT BABY 200GR | B13: VỈ
A14: CẢI CẦU VỒNG | B14: Kg
A15: CẢI CẦU VỒNG 300GR | B15: TÚI
... A19: CHANH VÀNG TRÁI 180UP | B19: TRÁI
A20: BÍ ĐỎ TRÒN | B20: Kg | C20: 1260 | D20: =_xlfn.IFNA(VLOOKUP(A20,'12.12'!A3:C292,3,),) -> 4000 | E20: =+D20*C20 -> 5040000
A21: CẦN TÂY VR | B21: Kg
A22: CẦN TÂY(CÂY) | B22: CÂY
A23: ỚT CHUÔNG 3 MÀU(KG)VR | B23: VỈ
A24: BÍ NGÒI VÀNG | B24: Kg | C24: 2 | D24: 25000 | E24: =+D24*C24 -> 50000
A25: BÍ NGÒI XANH | B25: Kg | C25: 120 | D25: =_xlfn.IFNA(VLOOKUP(A25,'12.12'!A8:C297,3,),) -> 12000 | E25: =+D25*C25 -> 1440000
A26: ỚT CHUÔNG ĐỎ(TRÁI) | B26: TRÁI
A27: ỚT CHUÔNG 3 MÀU 350G | B27: VỈ
A28: ỚT CHUÔNG 3 MÀU KQ(KG) | B28: Kg
A29: BÔNG CẢI TRẮNG | B29: Kg | C29: 8 | D29: 28000 | E29: =+D29*C29 -> 224000
A30: ỚT CHUÔNG VÀNG L1 | B30: Kg
A31: ỚT CHUÔNG VÀNG(TRÁI) | B31: TRÁI
A32: ỚT CHUÔNG VÀNG+ XANH (VỈ) | B32: VỈ
A33: BÔNG CẢI XANH BIGC | B33: Kg | C33: 8 | D33: =_xlfn.IFNA(VLOOKUP(A33,'12.12'!A16:C305,3,),) -> 16000 | E33: =+D33*C33 -> 128000
A34: CÀ CHUA | B34: Kg | C34: 190 | D34: =_xlfn.IFNA(VLOOKUP(A34,'12.12'!A17:C306,3,),) -> 22000 | E34: =+D34*C34 -> 4180000
A35: ỚT CHUÔNG XANH(TRÁI) | B35: TRÁI
A36: CÀ CHUA Ý | B36: Kg | C36: 202 | D36: =_xlfn.IFNA(VLOOKUP(A36,'12.12'!A19:C308,3,),) -> 26500 | E36: =+D36*C36 -> 5353000
A37: CỦ DỀN 600G | B37: TÚI
A38: GỪNG 250GR | B38: Kg
A39: HỒNG GIÒN | B39: Kg
A40: XÀ LÁCH MỸ | B40: Kg
A41: CÀ CHUA Ý CHÙM | B41: KG | C41: 85 | D41: 28000 | E41: =+D41*C41 -> 2380000
A42: KHOAI TÂY HỒNG TÚI LƯỚI 500G | B42: TÚI
A43: CÀ CHUA Ý(VỈ) KG | B43: Kg | C43: 7 | D43: 20000 | E43: =+D43*C43 -> 140000
A44: CÀ TÍM | B44: Kg | C44: 38 | D44: 9000 | E44: =+D44*C44 -> 342000
...

Sheet 14.12
A1: hàng tồn cuối ngày 14/12
A2: TÊN SẢN PHẨM | B2: TỒN TRƯỚC | C2: GIÁ NHẬP | D2: THÀNH TIỀN
A3: CÀ CHUA SÔCOLA 250GR (HỘP) VR | D3: =B3*C3 -> 0
A4: CÀ CHUA SÔCOLA 250GR (KG) -NA | D4: =B4*C4 -> 0
A5: CÀ CHUA SÔCOLA 250GR (KG) VR | D5: =B5*C5 -> 0
A6: CÀ CHUA SÔCOLA 250GR(KG) KQ | D6: =B6*C6 -> 0
A7: CÀ CHUA SÔCOLA 300GR (HỘP) VR | D7: =B7*C7 -> 0
A8: CÀ CHUA SOCOLA XÁ | D8: =B8*C8 -> 0
A9: CÀ CHUA SÔCOLA(HỘP) KQ | D9: =B9*C9 -> 0
A10: CÀ RỐT BABY | D10: =B10*C10 -> 0
A11: CÀ RỐT BABY (KG) KQ | D11: =B11*C11 -> 0
A12: CÀ RỐT BABY 200GR | D12: =B12*C12 -> 0
A13: CẢI CẦU VỒNG | D13: =B13*C13 -> 0
A14: CẢI CẦU VỒNG 300GR | D14: =B14*C14 -> 0
... A22: ỚT CHUÔNG 3 MÀU(KG)VR | D22: =B22*C22 -> 0
A23: ỚT CHUÔNG ĐỎ | B23: =5+80+10+7 -> 102 | C23: 22000 | D23: =B23*C23 -> 2244000
A24: ỚT CHUÔNG ĐỎ L1 | B24: 19 | C24: 19000 | D24: =B24*C24 -> 361000
A25: ỚT CHUÔNG ĐỎ(TRÁI) | D25: =B25*C25 -> 0
A26: ỚT CHUÔNG 3 MÀU 350G | D26: =B26*C26 -> 0
A27: ỚT CHUÔNG 3 MÀU KQ(KG) | D27: =B27*C27 -> 0
A28: ỚT CHUÔNG VÀNG | D28: =B28*C28 -> 0
A29: ỚT CHUÔNG VÀNG L1 | D29: =B29*C29 -> 0
A30: ỚT CHUÔNG VÀNG(TRÁI) | D30: =B30*C30 -> 0
A31: ỚT CHUÔNG VÀNG+ XANH (VỈ) | D31: =B31*C31 -> 0
A32: ỚT CHUÔNG XANH | B32: 115 | C32: 26000 | D32: =B32*C32 -> 2990000
A33: ỚT CHUÔNG XANH L1 | B33: 2 | C33: 23000 | D33: =B33*C33 -> 46000
A34: ỚT CHUÔNG XANH(TRÁI) | D34: =B34*C34 -> 0
A35: CỦ DỀN | B35: =20+28+40+7 -> 95 | C35: 14000 | D35: =B35*C35 -> 1330000
A36: CỦ DỀN 600G | D36: =B36*C36 -> 0
A37: GỪNG 250GR | D37: =B37*C37 -> 0
A38: HỒNG GIÒN | D38: =B38*C38 -> 0
A39: XÀ LÁCH MỸ | D39: =B39*C39 -> 0
A40: KHOAI TÂY HỒNG | D40: =B40*C40 -> 0
A41: KHOAI TÂY HỒNG TÚI LƯỚI 500G | D41: =B41*C41 -> 0
A42: KHOAI TÂY VÀNG | D42: =B42*C42 -> 0
A43: KHOAI TÂY VÀNG ĐL | B43: =60+30+140 -> 230 | C43: 16000 | D43: =B43*C43 -> 3680000
A44: KHOAI TÂY VÀNG LỚN TÚI LƯỚI 500G | B44: =77+20 -> 97 | C44: 15000 | D44: =B44*C44 -> 1455000
A45: KHOAI TÂY VÀNG RỬA | D45: =B45*C45 -> 0
A46: KHOAI TÂY VÀNG TRUNG TÚI LƯỚI 500G | D46: =B46*C46 -> 0
A47: CẢI THẢO DL | B47: 40 | C47: 7000 | D47: =B47*C47 -> 280000
...

Sheet 15.12
A1: hàng tồn cuối ngày 15/12
A2: TÊN SẢN PHẨM | B2: TỒN TRƯỚC | C2: GIÁ NHẬP | D2: THÀNH TIỀN
A3: CÀ CHUA SOCOLA XÁ | D3: =B3*C3 -> 0
A4: CÀ CHUA SÔCOLA 250GR (HỘP) VR | D4: =B4*C4 -> 0
A5: CÀ CHUA SÔCOLA 250GR (KG) -NA | D5: =B5*C5 -> 0
A6: CÀ CHUA SÔCOLA 250GR (KG) VR | D6: =B6*C6 -> 0
A7: CÀ CHUA SÔCOLA 250GR(KG) KQ | D7: =B7*C7 -> 0
A8: CÀ CHUA SÔCOLA 300GR (HỘP) VR | D8: =B8*C8 -> 0
A9: CÀ CHUA SÔCOLA(HỘP) KQ | D9: =B9*C9 -> 0
A10: CÀ RỐT BABY | D10: =B10*C10 -> 0
A11: CÀ RỐT BABY (KG) KQ | D11: =B11*C11 -> 0
A12: CÀ RỐT BABY 200GR | D12: =B12*C12 -> 0
A13: CẢI CẦU VỒNG | D13: =B13*C13 -> 0
A14: CẢI CẦU VỒNG 300GR | D14: =B14*C14 -> 0
... A21: CẦN TÂY(CÂY) | D21: =B21*C21 -> 0
A22: ỚT CHUÔNG 3 MÀU(KG)VR | B22: 9 | C22: 9000 | D22: =B22*C22 -> 81000
A23: ỚT CHUÔNG ĐỎ | B23: =25+8+80+40+20 -> 173 | C23: 22000 | D23: =B23*C23 -> 3806000
A24: ỚT CHUÔNG ĐỎ L1 | B24: 17 | C24: 20000 | D24: =B24*C24 -> 340000
A25: ỚT CHUÔNG ĐỎ(TRÁI) | D25: =B25*C25 -> 0
A26: ỚT CHUÔNG 3 MÀU 350G | D26: =B26*C26 -> 0
A27: ỚT CHUÔNG 3 MÀU KQ(KG) | D27: =B27*C27 -> 0
A28: ỚT CHUÔNG VÀNG | B28: =7+15+20+20+20+23 -> 105 | C28: 30000 | D28: =B28*C28 -> 3150000
A29: ỚT CHUÔNG VÀNG L1 | B29: 16 | C29: 24000 | D29: =B29*C29 -> 384000
A30: ỚT CHUÔNG VÀNG(TRÁI) | D30: =B30*C30 -> 0
A31: ỚT CHUÔNG VÀNG+ XANH (VỈ) | D31: =B31*C31 -> 0
A32: ỚT CHUÔNG XANH | B32: =8+5+26 -> 39 | C32: 26000 | D32: =B32*C32 -> 1014000
A33: ỚT CHUÔNG XANH L1 | D33: =B33*C33 -> 0
A34: ỚT CHUÔNG XANH(TRÁI) | D34: =B34*C34 -> 0
A35: CỦ DỀN | B35: =20+12+10 -> 42 | C35: 14000 | D35: =B35*C35 -> 588000
A36: CỦ DỀN 600G | D36: =B36*C36 -> 0
A37: GỪNG 250GR | D37: =B37*C37 -> 0
A38: HỒNG GIÒN | D38: =B38*C38 -> 0
A39: XÀ LÁCH MỸ | D39: =B39*C39 -> 0
A40: KHOAI TÂY HỒNG | B40: 20 | C40: 25000 | D40: =B40*C40 -> 500000
A41: KHOAI TÂY HỒNG TÚI LƯỚI 500G | D41: =B41*C41 -> 0
A42: KHOAI TÂY VÀNG | B42: 25 | C42: 12000 | D42: =B42*C42 -> 300000
A43: KHOAI TÂY VÀNG ĐL | B43: =50+170+25 -> 245 | C43: 16000 | D43: =B43*C43 -> 3920000
A44: KHOAI TÂY VÀNG LỚN TÚI LƯỚI 500G | D44: =B44*C44 -> 0
A45: KHOAI TÂY VÀNG RỬA | D45: =B45*C45 -> 0
A46: KHOAI TÂY VÀNG TRUNG TÚI LƯỚI 500G | D46: =B46*C46 -> 0
...

Sheet 16.12
A1: hàng tồn cuối ngày 16/12
A2: TÊN SẢN PHẨM | B2: TỒN TRƯỚC | C2: GIÁ NHẬP | D2: THÀNH TIỀN
A3: CÀ CHUA SÔCOLA 250GR (HỘP) VR | D3: =B3*C3 -> 0
A4: CÀ CHUA SÔCOLA 250GR (KG) -NA | D4: =B4*C4 -> 0
A5: CÀ CHUA SÔCOLA 250GR (KG) VR | D5: =B5*C5 -> 0
A6: CÀ CHUA SÔCOLA 250GR(KG) KQ | D6: =B6*C6 -> 0
A7: CÀ CHUA SÔCOLA 300GR (HỘP) VR | D7: =B7*C7 -> 0
A8: CÀ CHUA SOCOLA XÁ | D8: =B8*C8 -> 0
A9: CÀ CHUA SÔCOLA(HỘP) KQ | D9: =B9*C9 -> 0
A10: CÀ RỐT BABY | D10: =B10*C10 -> 0
A11: CÀ RỐT BABY (KG) KQ | D11: =B11*C11 -> 0
A12: CÀ RỐT BABY 200GR | D12: =B12*C12 -> 0
A13: CẢI CẦU VỒNG | D13: =B13*C13 -> 0
A14: CẢI CẦU VỒNG 300GR | D14: =B14*C14 -> 0
... A18: CHANH VÀNG TRÁI 180UP | D18: =B18*C18 -> 0
A19: CẦN TÂY (KG) | B19: 60 | C19: 22000 | D19: =B19*C19 -> 1320000
A20: CẦN TÂY VR | D20: =B20*C20 -> 0
A21: CẦN TÂY(CÂY) | D21: =B21*C21 -> 0
A22: ỚT CHUÔNG 3 MÀU(KG)VR | D22: =B22*C22 -> 0
A23: ỚT CHUÔNG ĐỎ | B23: =40+152 -> 192 | C23: 24000 | D23: =B23*C23 -> 4608000
A24: ỚT CHUÔNG ĐỎ L1 | B24: 6 | C24: 22000 | D24: =B24*C24 -> 132000
A25: ỚT CHUÔNG ĐỎ(TRÁI) | D25: =B25*C25 -> 0
A26: ỚT CHUÔNG 3 MÀU 350G | D26: =B26*C26 -> 0
A27: ỚT CHUÔNG 3 MÀU KQ(KG) | D27: =B27*C27 -> 0
A28: ỚT CHUÔNG VÀNG | D28: =B28*C28 -> 0
A29: ỚT CHUÔNG VÀNG L1 | D29: =B29*C29 -> 0
A30: ỚT CHUÔNG VÀNG(TRÁI) | D30: =B30*C30 -> 0
A31: ỚT CHUÔNG VÀNG+ XANH (VỈ) | D31: =B31*C31 -> 0
A32: ỚT CHUÔNG XANH | B32: =40+50 -> 90 | C32: 27000 | D32: =B32*C32 -> 2430000
A33: ỚT CHUÔNG XANH L1 | D33: =B33*C33 -> 0
A34: ỚT CHUÔNG XANH(TRÁI) | D34: =B34*C34 -> 0
A35: CỦ DỀN | B35: =13+20+80 -> 113 | C35: 14250 | D35: =B35*C35 -> 1610250
A36: CỦ DỀN 600G | D36: =B36*C36 -> 0
A37: GỪNG 250GR | D37: =B37*C37 -> 0
A38: HỒNG GIÒN | D38: =B38*C38 -> 0
A39: XÀ LÁCH MỸ | D39: =B39*C39 -> 0
A40: KHOAI TÂY HỒNG | B40: 13 | C40: 24000 | D40: =B40*C40 -> 312000
A41: KHOAI TÂY HỒNG TÚI LƯỚI 500G | D41: =B41*C41 -> 0
A42: KHOAI TÂY VÀNG | B42: 60 | C42: 12000 | D42: =B42*C42 -> 720000
A43: KHOAI TÂY VÀNG ĐL | B43: =50+80+30 -> 160 | C43: 16000 | D43: =B43*C43 -> 2560000
...

Sheet 17.12
A1: Hàng tồn cuối ngày 17/12
A2: TÊN SẢN PHẨM | B2: TỒN TRƯỚC | C2: GIÁ NHẬP | D2: THÀNH TIỀN
A5: BẮP CẢI TÍM | B5: 10 | C5: 26000 | D5: =B5*C5 -> 260000
A6: BẮP CẢI TÍM (BẮP) | D6: =B6*C6 -> 0
A7: BẮP CẢI TÍM SUSHI | D7: =B7*C7 -> 0
A8: BẮP CẢI TRẮNG | D8: =B8*C8 -> 0
A9: BẮP CẢI TRẮNG (BẮP) | D9: =B9*C9 -> 0
A10: BẮP CẢI TRẮNG MỘC CHÂU | D10: =B10*C10 -> 0
A11: BẮP CẢI TRẮNG SUSHI | D11: =B11*C11 -> 0
A12: BẮP MỸ | D12: =B12*C12 -> 0
A13: BẦU | D13: =B13*C13 -> 0
A14: BÍ ĐAO XANH | D14: =B14*C14 -> 0
A15: BÍ ĐAO XANH 400G | D15: =B15*C15 -> 0
A16: BÍ ĐỎ HỒ LÔ | D16: =B16*C16 -> 0
A17: BÍ ĐỎ MINI | D17: =B17*C17 -> 0
A18: BÍ ĐỎ NON (KG)KQ | D18: =B18*C18 -> 0
A19: BÍ ĐỎ NON TRÁI VR | B19: 27 | C19: 4000 | D19: =B19*C19 -> 108000
A20: BÍ ĐỎ NON( KG) VR | D20: =B20*C20 -> 0
A21: BÍ ĐỎ TRÒN | B21: =210+150 -> 360 | C21: 4000 | D21: =B21*C21 -> 1440000
A22: BÍ MINI VÀNG 300GR | D22: =B22*C22 -> 0
A23: BÍ MINI VÀNG KG | D23: =B23*C23 -> 0
A24: BÍ NGÒI VÀNG | D24: =B24*C24 -> 0
A25: BÍ NGÒI VÀNG (TRÁI) | D25: =B25*C25 -> 0
A26: BÍ NGÒI XANH | B26: 100 | C26: 12000 | D26: =B26*C26 -> 1200000
A27: BÍ NGÒI XANH(TRÁI) | D27: =B27*C27 -> 0
A28: BÍ NHẬT | D28: =B28*C28 -> 0
A29: BƠ 034 | D29: =B29*C29 -> 0
A30: BƠ BOOTH | D30: =B30*C30 -> 0
A31: BƠ SÁP | D31: =B31*C31 -> 0
A32: BÓ XÔI | D32: =B32*C32 -> 0
A33: BÓ XÔI 300G VR | D33: =B33*C33 -> 0
A34: BÓ XÔI-HN KQ | D34: =B34*C34 -> 0
A35: BÓ XÔI-NA | D35: =B35*C35 -> 0
A36: BÔNG ATISO | D36: =B36*C36 -> 0
A37: BÔNG BÍ | D37: =B37*C37 -> 0
A38: BÔNG BÍ TÚI 300GR | D38: =B38*C38 -> 0
A39: BÔNG CẢI TRẮNG | B39: 2 | C39: 16000 | D39: =B39*C39 -> 32000
A40: BÔNG CẢI TRẮNG (CÂY) | D40: =B40*C40 -> 0
A41: BÔNG CẢI XANH 10P | D41: =B41*C41 -> 0
A42: BÔNG CẢI XANH AEON | B42: =15+25 -> 40 | C42: 25000 | D42: =B42*C42 -> 1000000
...

Sheet 18.12
A1: hàng tồn cuối ngày 18/12
A2: TÊN SẢN PHẨM | B2: TỒN TRƯỚC | C2: GIÁ NHẬP | D2: THÀNH TIỀN
A4: CÀ CHUA SÔCOLA 250GR (HỘP) VR | D4: =B4*C4 -> 0
A5: CÀ CHUA SÔCOLA 250GR (KG) -NA | D5: =B5*C5 -> 0
A6: CÀ CHUA SÔCOLA 250GR (KG) VR | D6: =B6*C6 -> 0
A7: CÀ CHUA SÔCOLA 250GR(KG) KQ | D7: =B7*C7 -> 0
A8: CÀ CHUA SÔCOLA 300GR (HỘP) VR | D8: =B8*C8 -> 0
A9: CÀ CHUA SOCOLA XÁ | D9: =B9*C9 -> 0
A10: CÀ CHUA SÔCOLA(HỘP) KQ | D10: =B10*C10 -> 0
A11: CÀ RỐT BABY | D11: =B11*C11 -> 0
A12: CÀ RỐT BABY (KG) KQ | D12: =B12*C12 -> 0
A13: CÀ RỐT BABY 200GR | D13: =B13*C13 -> 0
A14: CẢI CẦU VỒNG | D14: =B14*C14 -> 0
A15: CẢI CẦU VỒNG 300GR | D15: =B15*C15 -> 0
... A23: ỚT CHUÔNG 3 MÀU(KG)VR | D23: =B23*C23 -> 0
A24: ỚT CHUÔNG ĐỎ | B24: =88+40 -> 128 | C24: 27000 | D24: =B24*C24 -> 3456000
A25: ỚT CHUÔNG ĐỎ L1 | B25: 3 | C25: 22000 | D25: =B25*C25 -> 66000
A26: ỚT CHUÔNG ĐỎ(TRÁI) | B26: 280 | C26: 7000 | D26: =B26*C26 -> 1960000
A27: ỚT CHUÔNG 3 MÀU 350G | D27: =B27*C27 -> 0
A28: ỚT CHUÔNG 3 MÀU KQ(KG) | D28: =B28*C28 -> 0
A29: ỚT CHUÔNG VÀNG | B29: =15+40 -> 55 | C29: 35000 | D29: =B29*C29 -> 1925000
A30: ỚT CHUÔNG VÀNG L1 | D30: =B30*C30 -> 0
A31: ỚT CHUÔNG VÀNG(TRÁI) | D31: =B31*C31 -> 0
A32: ỚT CHUÔNG VÀNG+ XANH (VỈ) | D32: =B32*C32 -> 0
A33: ỚT CHUÔNG XANH | B33: 40 | C33: 27000 | D33: =B33*C33 -> 1080000
A34: ỚT CHUÔNG XANH L1 | D34: =B34*C34 -> 0
A35: ỚT CHUÔNG XANH(TRÁI) | D35: =B35*C35 -> 0
A36: CỦ DỀN | B36: =13+30 -> 43 | C36: 14000 | D36: =B36*C36 -> 602000
A37: CỦ DỀN 600G | D37: =B37*C37 -> 0
A38: GỪNG 250GR | D38: =B38*C38 -> 0
A39: HỒNG GIÒN | D39: =B39*C39 -> 0
A40: XÀ LÁCH MỸ | D40: =B40*C40 -> 0
A41: KHOAI TÂY HỒNG | B41: 15 | C41: 24000 | D41: =B41*C41 -> 360000
A42: KHOAI TÂY HỒNG TÚI LƯỚI 500G | D42: =B42*C42 -> 0
A43: KHOAI TÂY VÀNG | B43: 10 | C43: 12000 | D43: =B43*C43 -> 120000
A44: KHOAI TÂY VÀNG ĐL | B44: =340+290 -> 630 | C44: 16000 | D44: =B44*C44 -> 10080000
A45: KHOAI TÂY VÀNG LỚN TÚI LƯỚI 500G | B45: 40 | C45: 15000 | D45: =B45*C45 -> 600000
A46: KHOAI TÂY VÀNG RỬA | D46: =B46*C46 -> 0
A47: KHOAI TÂY VÀNG TRUNG TÚI LƯỚI 500G | D47: =B47*C47 -> 0
A48: CẢI THẢO DL | D48: =B48*C48 -> 0
...

Sheet 19.12
A1: hàng tồn cuối ngày 19/12
A2: TÊN SẢN PHẨM | B2: TỒN TRƯỚC | C2: GIÁ NHẬP | D2: THÀNH TIỀN
A3: CÀ CHUA SÔCOLA 250GR (HỘP) VR | B3: 13 | C3: 7000 | D3: =B3*C3 -> 91000
A4: CÀ CHUA SÔCOLA 250GR (KG) -NA | D4: =B4*C4 -> 0
A5: CÀ CHUA SÔCOLA 250GR (KG) VR | D5: =B5*C5 -> 0
A6: CÀ CHUA SÔCOLA 250GR(KG) KQ | D6: =B6*C6 -> 0
A7: CÀ CHUA SÔCOLA 300GR (HỘP) VR | D7: =B7*C7 -> 0
A8: CÀ CHUA SOCOLA XÁ | D8: =B8*C8 -> 0
A9: CÀ CHUA SÔCOLA(HỘP) KQ | D9: =B9*C9 -> 0
A10: CÀ RỐT BABY | D10: =B10*C10 -> 0
A11: CÀ RỐT BABY (KG) KQ | D11: =B11*C11 -> 0
A12: CÀ RỐT BABY 200GR | D12: =B12*C12 -> 0
A13: CẢI CẦU VỒNG | D13: =B13*C13 -> 0
A14: CẢI CẦU VỒNG 300GR | D14: =B14*C14 -> 0
A15: CẢI KALE | D15: =B15*C15 -> 0
... A22: ỚT CHUÔNG 3 MÀU(KG)VR | D22: =B22*C22 -> 0
A23: ỚT CHUÔNG ĐỎ | B23: =40+20+40+20 -> 120 | C23: 28000 | D23: =B23*C23 -> 3360000
A24: ỚT CHUÔNG ĐỎ L1 | D24: =B24*C24 -> 0
A25: ỚT CHUÔNG ĐỎ(TRÁI) | D25: =B25*C25 -> 0
A26: ỚT CHUÔNG 3 MÀU 350G | D26: =B26*C26 -> 0
A27: ỚT CHUÔNG 3 MÀU KQ(KG) | D27: =B27*C27 -> 0
A28: ỚT CHUÔNG VÀNG | D28: =B28*C28 -> 0
A29: ỚT CHUÔNG VÀNG L1 | D29: =B29*C29 -> 0
A30: ỚT CHUÔNG VÀNG(TRÁI) | D30: =B30*C30 -> 0
A31: ỚT CHUÔNG VÀNG+ XANH (VỈ) | D31: =B31*C31 -> 0
A32: ỚT CHUÔNG XANH | B32: 52 | C32: 35000 | D32: =B32*C32 -> 1820000
A33: ỚT CHUÔNG XANH L1 | D33: =B33*C33 -> 0
A34: ỚT CHUÔNG XANH(TRÁI) | D34: =B34*C34 -> 0
A35: CỦ DỀN | B35: 115 | C35: 14000 | D35: =B35*C35 -> 1610000
A36: CỦ DỀN 600G | D36: =B36*C36 -> 0
A37: GỪNG 250GR | D37: =B37*C37 -> 0
A38: HỒNG GIÒN | D38: =B38*C38 -> 0
A39: XÀ LÁCH MỸ | D39: =B39*C39 -> 0
A40: KHOAI TÂY HỒNG | B40: =15+20 -> 35 | C40: 25000 | D40: =B40*C40 -> 875000
A41: KHOAI TÂY HỒNG TÚI LƯỚI 500G | D41: =B41*C41 -> 0
A42: KHOAI TÂY VÀNG | B42: 180 | C42: 12000 | D42: =B42*C42 -> 2160000
A43: KHOAI TÂY VÀNG ĐL | B43: 100 | C43: 15000 | D43: =B43*C43 -> 1500000
A44: KHOAI TÂY VÀNG LỚN TÚI LƯỚI 500G | B44: 120 | C44: 15000 | D44: =B44*C44 -> 1800000
A45: KHOAI TÂY VÀNG RỬA | D45: =B45*C45 -> 0
A46: KHOAI TÂY VÀNG TRUNG TÚI LƯỚI 500G | D46: =B46*C46 -> 0
...

Sheet 20.12
A1: hàng tồn cuối ngày 20/12
A2: TÊN SẢN PHẨM | B2: TỒN TRƯỚC | C2: GIÁ NHẬP | D2: THÀNH TIỀN
A3: CÀ CHUA SÔCOLA 250GR (HỘP) VR | B3: 27 | C3: 7000 | D3: =B3*C3 -> 189000
A4: CÀ CHUA SÔCOLA 250GR (KG) -NA | D4: =B4*C4 -> 0
A5: CÀ CHUA SÔCOLA 250GR (KG) VR | D5: =B5*C5 -> 0
A6: CÀ CHUA SÔCOLA 250GR(KG) KQ | D6: =B6*C6 -> 0
A7: CÀ CHUA SÔCOLA 300GR (HỘP) VR | D7: =B7*C7 -> 0
A8: CÀ CHUA SOCOLA XÁ | D8: =B8*C8 -> 0
A9: CÀ CHUA SÔCOLA(HỘP) KQ | D9: =B9*C9 -> 0
A10: CÀ RỐT BABY | D10: =B10*C10 -> 0
A11: CÀ RỐT BABY (KG) KQ | D11: =B11*C11 -> 0
A12: CÀ RỐT BABY 200GR | D12: =B12*C12 -> 0
A13: CẢI CẦU VỒNG | D13: =B13*C13 -> 0
A14: CẢI CẦU VỒNG 300GR | D14: =B14*C14 -> 0
A15: CẢI KALE | D15: =B15*C15 -> 0
... A18: CHANH VÀNG TRÁI 180UP | D18: =B18*C18 -> 0
A19: CẦN TÂY (KG) | B19: 10 | C19: 22000 | D19: =B19*C19 -> 220000
A20: CẦN TÂY VR | D20: =B20*C20 -> 0
A21: CẦN TÂY(CÂY) | D21: =B21*C21 -> 0
A22: ỚT CHUÔNG 3 MÀU(KG)VR | D22: =B22*C22 -> 0
A23: ỚT CHUÔNG ĐỎ | B23: =22+40+65 -> 127 | C23: 28000 | D23: =B23*C23 -> 3556000
A24: ỚT CHUÔNG ĐỎ L1 | D24: =B24*C24 -> 0
A25: ỚT CHUÔNG ĐỎ(TRÁI) | D25: =B25*C25 -> 0
A26: ỚT CHUÔNG 3 MÀU 350G | B26: 5 | C26: 12000 | D26: =B26*C26 -> 60000
A27: ỚT CHUÔNG 3 MÀU KQ(KG) | D27: =B27*C27 -> 0
A28: ỚT CHUÔNG VÀNG | B28: =20+80+6 -> 106 | C28: 36000 | D28: =B28*C28 -> 3816000
A29: ỚT CHUÔNG VÀNG L1 | D29: =B29*C29 -> 0
A30: ỚT CHUÔNG VÀNG(TRÁI) | D30: =B30*C30 -> 0
A31: ỚT CHUÔNG VÀNG+ XANH (VỈ) | D31: =B31*C31 -> 0
A32: ỚT CHUÔNG XANH | B32: =20+10+5 -> 35 | C32: 35000 | D32: =B32*C32 -> 1225000
A33: ỚT CHUÔNG XANH L1 | D33: =B33*C33 -> 0
A34: ỚT CHUÔNG XANH(TRÁI) | D34: =B34*C34 -> 0
A35: CỦ DỀN | B35: =10+20+15+15 -> 60 | C35: 14000 | D35: =B35*C35 -> 840000
A36: CỦ DỀN 600G | D36: =B36*C36 -> 0
A37: GỪNG 250GR | D37: =B37*C37 -> 0
A38: HỒNG GIÒN | D38: =B38*C38 -> 0
A39: XÀ LÁCH MỸ | D39: =B39*C39 -> 0
A40: KHOAI TÂY HỒNG | B40: 17 | C40: 25000 | D40: =B40*C40 -> 425000
A41: KHOAI TÂY HỒNG TÚI LƯỚI 500G | D41: =B41*C41 -> 0
A42: KHOAI TÂY VÀNG | B42: 80 | C42: 12000 | D42: =B42*C42 -> 960000
...

Sheet 21.12
A1: hàng tồn cuối ngày 21/12
A2: TÊN SẢN PHẨM | B2: TỒN TRƯỚC | C2: GIÁ NHẬP | D2: THÀNH TIỀN
A3: BẮP CẢI TÍM | B3: 6 | C3: 26000 | D3: =B3*C3 -> 156000
A4: CÀ CHUA SÔCOLA 250GR (KG) -NA | D4: =B4*C4 -> 0
A5: CÀ CHUA SÔCOLA 250GR (KG) VR | D5: =B5*C5 -> 0
A6: CÀ CHUA SÔCOLA 250GR(KG) KQ | D6: =B6*C6 -> 0
A7: CÀ CHUA SÔCOLA 300GR (HỘP) VR | D7: =B7*C7 -> 0
A8: CÀ CHUA SOCOLA XÁ | D8: =B8*C8 -> 0
A9: CÀ CHUA SÔCOLA(HỘP) KQ | D9: =B9*C9 -> 0
A10: CÀ RỐT BABY | D10: =B10*C10 -> 0
A11: CÀ RỐT BABY (KG) KQ | D11: =B11*C11 -> 0
A12: CÀ RỐT BABY 200GR | D12: =B12*C12 -> 0
A13: CẢI CẦU VỒNG | D13: =B13*C13 -> 0
A14: CẢI CẦU VỒNG 300GR | D14: =B14*C14 -> 0
A15: CẢI KALE | D15: =B15*C15 -> 0
... A22: ỚT CHUÔNG 3 MÀU(KG)VR | D22: =B22*C22 -> 0
A23: BẮP CẢI TRẮNG | B23: 160 | C23: 6500 | D23: =B23*C23 -> 1040000
A24: ỚT CHUÔNG ĐỎ L1 | D24: =B24*C24 -> 0
A25: ỚT CHUÔNG ĐỎ(TRÁI) | D25: =B25*C25 -> 0
A26: BÍ ĐỎ NON TRÁI VR | B26: 18 | C26: 4000 | D26: =B26*C26 -> 72000
A27: ỚT CHUÔNG 3 MÀU KQ(KG) | D27: =B27*C27 -> 0
A28: BÍ ĐỎ TRÒN | B28: =420+90+660+390+390+1270 -> 3220 | C28: 5000 | D28: =B28*C28 -> 16100000
A29: ỚT CHUÔNG VÀNG L1 | D29: =B29*C29 -> 0
A30: ỚT CHUÔNG VÀNG(TRÁI) | D30: =B30*C30 -> 0
A31: ỚT CHUÔNG VÀNG+ XANH (VỈ) | D31: =B31*C31 -> 0
A32: BÍ NGÒI XANH | B32: 30 | C32: 10000 | D32: =B32*C32 -> 300000
A33: ỚT CHUÔNG XANH L1 | D33: =B33*C33 -> 0
A34: ỚT CHUÔNG XANH(TRÁI) | D34: =B34*C34 -> 0
A35: BÔNG CẢI TRẮNG | B35: 10 | C35: 13000 | D35: =B35*C35 -> 130000
A36: CỦ DỀN 600G | D36: =B36*C36 -> 0
A37: GỪNG 250GR | D37: =B37*C37 -> 0
A38: HỒNG GIÒN | D38: =B38*C38 -> 0
A39: XÀ LÁCH MỸ | D39: =B39*C39 -> 0
A40: CÀ CHUA | B40: =380+20 -> 400 | C40: 19000 | D40: =B40*C40 -> 7600000
A41: KHOAI TÂY HỒNG TÚI LƯỚI 500G | D41: =B41*C41 -> 0
A42: CÀ CHUA BI COOP | B42: 2 | C42: 10000 | D42: =B42*C42 -> 20000
A43: CÀ CHUA SÔCOLA 250GR (HỘP) VR | B43: 20 | C43: 7000 | D43: =B43*C43 -> 140000
A44: CÀ CHUA Ý | B44: =80+60+95+60+40 -> 335 | C44: 25000 | D44: =B44*C44 -> 8375000
A45: KHOAI TÂY VÀNG RỬA | D45: =B45*C45 -> 0
A46: KHOAI TÂY VÀNG TRUNG TÚI LƯỚI 500G | D46: =B46*C46 -> 0
...

Sheet 22.12
A1: hàng tồn cuối ngày 22/12
A2: TÊN SẢN PHẨM | B2: TỒN TRƯỚC | C2: GIÁ NHẬP | D2: THÀNH TIỀN
A3: BẮP CẢI TÍM | B3: 5 | C3: 26000 | D3: =B3*C3 -> 130000
A4: BẮP CẢI TÍM (BẮP) | D4: =B4*C4 -> 0
A5: BẮP CẢI TÍM SUSHI | D5: =B5*C5 -> 0
A6: BẮP CẢI TRẮNG | D6: =B6*C6 -> 0
A7: BẮP CẢI TRẮNG (BẮP) | D7: =B7*C7 -> 0
A8: BẮP CẢI TRẮNG MỘC CHÂU | D8: =B8*C8 -> 0
A9: BẮP CẢI TRẮNG SUSHI | D9: =B9*C9 -> 0
A10: BẮP MỸ | D10: =B10*C10 -> 0
A11: BẦU | D11: =B11*C11 -> 0
A12: BÍ ĐAO XANH | B12: 2 | C12: 9000 | D12: =B12*C12 -> 18000
A13: BÍ ĐAO XANH 400G | D13: =B13*C13 -> 0
A14: BÍ ĐỎ HỒ LÔ | B14: 3 | C14: 9500 | D14: =B14*C14 -> 28500
A15: BÍ ĐỎ MINI | D15: =B15*C15 -> 0
A16: BÍ ĐỎ NON (KG)KQ | D16: =B16*C16 -> 0
A17: BÍ ĐỎ NON TRÁI VR | B17: 76 | C17: 4000 | D17: =B17*C17 -> 304000
A18: BÍ ĐỎ NON( KG) VR | D18: =B18*C18 -> 0
A19: BÍ ĐỎ TRÒN | B19: =1187+1830 -> 3017 | C19: 5000 | D19: =B19*C19 -> 15085000
A20: BÍ MINI VÀNG 300GR | D20: =B20*C20 -> 0
A21: BÍ MINI VÀNG KG | D21: =B21*C21 -> 0
A22: BÍ NGÒI VÀNG | D22: =B22*C22 -> 0
A23: BÍ NGÒI VÀNG (TRÁI) | D23: =B23*C23 -> 0
A24: BÍ NGÒI XANH | B24: =15+35+10+35 -> 95 | C24: 10000 | D24: =B24*C24 -> 950000
A25: BÍ NGÒI XANH(TRÁI) | D25: =B25*C25 -> 0
A26: BÍ NHẬT | D26: =B26*C26 -> 0
A27: BƠ 034 | D27: =B27*C27 -> 0
A28: BƠ BOOTH | D28: =B28*C28 -> 0
A29: BƠ SÁP | D29: =B29*C29 -> 0
A30: BÓ XÔI | D30: =B30*C30 -> 0
A31: BÓ XÔI 300G VR | D31: =B31*C31 -> 0
A32: BÓ XÔI-HN KQ | D32: =B32*C32 -> 0
A33: BÓ XÔI-NA | D33: =B33*C33 -> 0
A34: BÔNG ATISO | D34: =B34*C34 -> 0
A35: BÔNG BÍ | D35: =B35*C35 -> 0
A36: BÔNG BÍ TÚI 300GR | D36: =B36*C36 -> 0
A37: BÔNG CẢI TRẮNG | B37: 15 | C37: 13000 | D37: =B37*C37 -> 195000
A38: BÔNG CẢI TRẮNG (CÂY) | D38: =B38*C38 -> 0
A39: BÔNG CẢI XANH 10P | D39: =B39*C39 -> 0
A40: BÔNG CẢI XANH AEON | D40: =B40*C40 -> 0
...

Sheet 23.12
A1: hàng tồn cuối ngày 23/12
A2: TÊN SẢN PHẨM | B2: TỒN TRƯỚC | C2: GIÁ NHẬP | D2: THÀNH TIỀN
A3: CÀ CHUA SÔCOLA 250GR (HỘP) VR | D3: =B3*C3 -> 0
A4: CÀ CHUA SÔCOLA 250GR (KG) -NA | D4: =B4*C4 -> 0
A5: CÀ CHUA SÔCOLA 250GR (KG) VR | D5: =B5*C5 -> 0
A6: CÀ CHUA SÔCOLA 250GR(KG) KQ | D6: =B6*C6 -> 0
A7: CÀ CHUA SÔCOLA 300GR (HỘP) VR | D7: =B7*C7 -> 0
A8: CÀ CHUA SOCOLA XÁ | D8: =B8*C8 -> 0
A9: CÀ CHUA SÔCOLA(HỘP) KQ | D9: =B9*C9 -> 0
A10: CÀ RỐT BABY | D10: =B10*C10 -> 0
A11: CÀ RỐT BABY (KG) KQ | D11: =B11*C11 -> 0
A12: BÍ ĐỎ TRÒN | B12: =1187+890 -> 2077 | C12: 5000 | D12: =B12*C12 -> 10385000
A13: CẢI CẦU VỒNG | D13: =B13*C13 -> 0
A14: CẢI CẦU VỒNG 300GR | D14: =B14*C14 -> 0
A15: CẢI KALE | D15: =B15*C15 -> 0
A16: CẢI KALE 300GR | D16: =B16*C16 -> 0
A17: CHANH VÀNG (KG) | D17: =B17*C17 -> 0
A18: CHANH VÀNG TRÁI 180UP | D18: =B18*C18 -> 0
A19: CẦN TÂY (KG) | D19: =B19*C19 -> 0
A20: CẦN TÂY VR | D20: =B20*C20 -> 0
A21: CẦN TÂY(CÂY) | D21: =B21*C21 -> 0
A22: ỚT CHUÔNG 3 MÀU(KG)VR | D22: =B22*C22 -> 0
A23: BÍ NGÒI VÀNG | B23: 3 | C23: 30000 | D23: =B23*C23 -> 90000
A24: ỚT CHUÔNG ĐỎ L1 | D24: =B24*C24 -> 0
A25: ỚT CHUÔNG ĐỎ(TRÁI) | D25: =B25*C25 -> 0
A26: ỚT CHUÔNG 3 MÀU 350G | D26: =B26*C26 -> 0
A27: ỚT CHUÔNG 3 MÀU KQ(KG) | D27: =B27*C27 -> 0
A28: BÍ NGÒI XANH | B28: 35 | C28: 10000 | D28: =B28*C28 -> 350000
A29: ỚT CHUÔNG VÀNG L1 | D29: =B29*C29 -> 0
A30: ỚT CHUÔNG VÀNG(TRÁI) | D30: =B30*C30 -> 0
A31: ỚT CHUÔNG VÀNG+ XANH (VỈ) | D31: =B31*C31 -> 0
A32: ỚT CHUÔNG XANH | D32: =B32*C32 -> 0
A33: ỚT CHUÔNG XANH L1 | D33: =B33*C33 -> 0
A34: ỚT CHUÔNG XANH(TRÁI) | D34: =B34*C34 -> 0
A35: BÔNG CẢI XANH BIGC | B35: 40 | C35: 16000 | D35: =B35*C35 -> 640000
A36: CỦ DỀN 600G | D36: =B36*C36 -> 0
A37: GỪNG 250GR | D37: =B37*C37 -> 0
A38: HỒNG GIÒN | D38: =B38*C38 -> 0
A39: XÀ LÁCH MỸ | D39: =B39*C39 -> 0
A40: CÀ CHUA | B40: =120+100+40+20+20+100+50 -> 450 | C40: 21000 | D40: =B40*C40 -> 9450000
...

Sheet 24.12
A1: 45284
A2: TÊN SẢN PHẨM | B2: ĐVT | C2: TỒN TRƯỚC | D2: GIÁ NHẬP | E2: THÀNH TIỀN
A4: BẮP CẢI TÍM | B4: Kg | E4: =+D4*C4 -> 0
A5: BẮP CẢI TÍM (BẮP) | B5: BẮP | E5: =+D5*C5 -> 0
A6: BẮP CẢI TÍM SUSHI | B6: Kg | E6: =+D6*C6 -> 0
A7: BẮP CẢI TRẮNG | B7: Kg | E7: =+D7*C7 -> 0
A8: BẮP CẢI TRẮNG (BẮP) | B8: BẮP | E8: =+D8*C8 -> 0
A9: BẮP CẢI TRẮNG MỘC CHÂU | B9: Kg | E9: =+D9*C9 -> 0
A10: BẮP CẢI TRẮNG SUSHI | B10: Kg | E10: =+D10*C10 -> 0
A11: BẮP MỸ | B11: Kg | E11: =+D11*C11 -> 0
A12: BẦU | B12: Kg | C12: 15 | D12: 12000 | E12: =+D12*C12 -> 180000
A13: BÍ ĐAO XANH | B13: Kg | E13: =+D13*C13 -> 0
A14: BÍ ĐAO XANH 400G | B14: TRÁI | E14: =+D14*C14 -> 0
A15: BÍ ĐỎ HỒ LÔ | B15: Kg | C15: 5 | D15: 10000 | E15: =+D15*C15 -> 50000
A16: BÍ ĐỎ MINI | B16: Kg | E16: =+D16*C16 -> 0
A17: BÍ ĐỎ NON (KG)KQ | B17: Kg | E17: =+D17*C17 -> 0
A18: BÍ ĐỎ NON TRÁI VR | B18: TRÁI | E18: =+D18*C18 -> 0
A19: BÍ ĐỎ NON( KG) VR | B19: Kg | E19: =+D19*C19 -> 0
A20: BÍ ĐỎ TRÒN | B20: Kg | C20: 1782 | D20: 5000 | E20: =+D20*C20 -> 8910000
A21: BÍ MINI VÀNG 300GR | B21: TRÁI | E21: =+D21*C21 -> 0
A22: BÍ MINI VÀNG KG | B22: Kg | E22: =+D22*C22 -> 0
A23: BÍ NGÒI VÀNG | B23: Kg | C23: 5 | D23: =IFERROR(VLOOKUP(A23,'23.12'!A23:C315,3,),) -> 30000 | E23: =+D23*C23 -> 150000
A24: BÍ NGÒI VÀNG (TRÁI) | B24: TRÁI | E24: =+D24*C24 -> 0
A25: BÍ NGÒI XANH | B25: Kg | C25: 55 | D25: =IFERROR(VLOOKUP(A25,'23.12'!A25:C317,3,),) -> 10000 | E25: =+D25*C25 -> 550000
A26: BÍ NGÒI XANH(TRÁI) | B26: TRÁI | E26: =+D26*C26 -> 0
A27: BÍ NHẬT | B27: Kg | E27: =+D27*C27 -> 0
A28: BƠ 034 | B28: Kg | E28: =+D28*C28 -> 0
A29: BƠ BOOTH | B29: Kg | E29: =+D29*C29 -> 0
A30: BƠ SÁP | B30: Kg | E30: =+D30*C30 -> 0
A31: BÓ XÔI | B31: Kg | E31: =+D31*C31 -> 0
A32: BÓ XÔI 300G VR | B32: TÚI | E32: =+D32*C32 -> 0
A33: BÓ XÔI-HN KQ | B33: Kg | E33: =+D33*C33 -> 0
A34: BÓ XÔI-NA | B34: Kg | E34: =+D34*C34 -> 0
A35: BÔNG ATISO | B35: Kg | E35: =+D35*C35 -> 0
A36: BÔNG BÍ | B36: Kg | E36: =+D36*C36 -> 0
A37: BÔNG BÍ TÚI 300GR | B37: VỈ | E37: =+D37*C37 -> 0
... A46: BÔNG CẢI XANH CITI | B46: Kg | E46: =+D46*C46 -> 0
A47: CÀ CHUA | B47: Kg | C47: 443 | D47: 20000 | E47: =+D47*C47 -> 8860000
A48: CÀ CHUA BI | B48: Kg | E48: =+D48*C48 -> 0
A49: CÀ CHUA BI (HỘP) 300GR KQ | B49: HỘP | E49: =+D49*C49 -> 0
...

Sheet 25.12
A1: 45285
A2: TÊN SẢN PHẨM | B2: ĐVT | C2: QUY CÁCH | D2: TỒN TRƯỚC | E2: GHI CHÚ | F2: GIÁ NHẬP | G2: THÀNH TIỀN
A4: CÀ CHUA SÔCOLA 250GR (HỘP) VR | B4: HỘP | G4: =+F4*D4 -> 0
A5: CÀ CHUA SÔCOLA 250GR (KG) -NA | B5: Kg | G5: =+F5*D5 -> 0
A6: CÀ CHUA SÔCOLA 250GR (KG) VR | B6: Kg | G6: =+F6*D6 -> 0
A7: CÀ CHUA SÔCOLA 250GR(KG) KQ | B7: Kg | G7: =+F7*D7 -> 0
A8: CÀ CHUA SÔCOLA 300GR (HỘP) VR | B8: HỘP | G8: =+F8*D8 -> 0
A9: CÀ CHUA SOCOLA XÁ | B9: Kg | G9: =+F9*D9 -> 0
A10: CÀ CHUA SÔCOLA(HỘP) KQ | B10: HỘP | G10: =+F10*D10 -> 0
A11: CÀ RỐT BABY | B11: Kg | C11: 40-60GR | G11: =+F11*D11 -> 0
A12: CÀ RỐT BABY (KG) KQ | B12: Kg | C12: 40-60GR | G12: =+F12*D12 -> 0
A13: CÀ RỐT BABY 200GR | B13: VỈ | C13: 40-60GR | G13: =+F13*D13 -> 0
A14: CẢI CẦU VỒNG | B14: Kg | G14: =+F14*D14 -> 0
A15: BẮP CẢI TÍM | B15: Kg | C15: 300GR | D15: 7 | F15: 26000 | G15: =+F15*D15 -> 182000
A16: CẢI KALE | B16: Kg | G16: =+F16*D16 -> 0
A17: CẢI KALE 300GR | B17: TÚI | G17: =+F17*D17 -> 0
A18: CHANH VÀNG (KG) | B18: Kg | G18: =+F18*D18 -> 0
A19: CHANH VÀNG TRÁI 180UP | B19: TRÁI | G19: =+F19*D19 -> 0
A20: CẦN TÂY (KG) | B20: Kg | C20: 250GR | G20: =+F20*D20 -> 0
A21: CẦN TÂY VR | B21: Kg | G21: =+F21*D21 -> 0
A22: CẦN TÂY(CÂY) | B22: CÂY | C22: 500GR | G22: =+F22*D22 -> 0
A23: ỚT CHUÔNG 3 MÀU(KG)VR | B23: VỈ | G23: =+F23*D23 -> 0
A24: BÍ ĐAO XANH | B24: Kg | C24: 350GR | D24: 17 | F24: 10000 | G24: =+F24*D24 -> 170000
A25: ỚT CHUÔNG ĐỎ L1 | B25: Kg | G25: =+F25*D25 -> 0
A26: ỚT CHUÔNG ĐỎ(TRÁI) | B26: TRÁI | C26: 150GR | G26: =+F26*D26 -> 0
A27: ỚT CHUÔNG 3 MÀU 350G | B27: VỈ | G27: =+F27*D27 -> 0
A28: ỚT CHUÔNG 3 MÀU KQ(KG) | B28: Kg | G28: =+F28*D28 -> 0
A29: BÍ ĐỎ NON TRÁI VR | B29: TRÁI | C29: 300GR | D29: 27 | F29: =10000*0.3 -> 3000 | G29: =+F29*D29 -> 81000
A30: ỚT CHUÔNG VÀNG L1 | B30: Kg | G30: =+F30*D30 -> 0
A31: ỚT CHUÔNG VÀNG(TRÁI) | B31: TRÁI | C31: 150GR | G31: =+F31*D31 -> 0
A32: ỚT CHUÔNG VÀNG+ XANH (VỈ) | B32: VỈ | G32: =+F32*D32 -> 0
A33: BÍ ĐỎ TRÒN | B33: Kg | C33: 1KG | D33: 3325 | E33: TỒN MNN 2040KG | F33: 5000 | G33: =+F33*D33 -> 16625000
A34: ỚT CHUÔNG XANH L1 | B34: Kg | G34: =+F34*D34 -> 0
A35: ỚT CHUÔNG XANH(TRÁI) | B35: TRÁI | C35: 150GR | G35: =+F35*D35 -> 0
A36: BÍ NGÒI VÀNG | B36: Kg | C36: 250GR | D36: 4 | F36: 30000 | G36: =+F36*D36 -> 120000
A37: CỦ DỀN 600G | B37: TÚI | C37: 200GR | G37: =+F37*D37 -> 0
A38: GỪNG 250GR | B38: Kg | G38: =+F38*D38 -> 0
A39: HỒNG GIÒN | B39: Kg | C39: 12-14 TRÁI/KG | G39: =+F39*D39 -> 0
A40: XÀ LÁCH MỸ | B40: Kg | G40: =+F40*D40 -> 0
A41: BÍ NGÒI XANH | B41: Kg | C41: 250GR | D41: 93 | F41: 11000 | G41: =+F41*D41 -> 1023000
...

Sheet 26.12
A1: hàng tồn cuối ngày 26/12
A2: TÊN SẢN PHẨM | B2: TỒN TRƯỚC | C2: GIÁ NHẬP | D2: THÀNH TIỀN
A3: BẮP CẢI TÍM | D3: =B3*C3 -> 0
A4: BẮP CẢI TÍM (BẮP) | D4: =B4*C4 -> 0
A5: BẮP CẢI TÍM SUSHI | D5: =B5*C5 -> 0
A6: BẮP CẢI TRẮNG | D6: =B6*C6 -> 0
A7: BẮP CẢI TRẮNG (BẮP) | D7: =B7*C7 -> 0
A8: BẮP CẢI TRẮNG MỘC CHÂU | D8: =B8*C8 -> 0
A9: BẮP CẢI TRẮNG SUSHI | D9: =B9*C9 -> 0
A10: BẮP MỸ | D10: =B10*C10 -> 0
A11: BẦU | D11: =B11*C11 -> 0
A12: BÍ ĐAO XANH | B12: 15 | C12: 9000 | D12: =B12*C12 -> 135000
A13: BÍ ĐAO XANH 400G | D13: =B13*C13 -> 0
A14: BÍ ĐỎ HỒ LÔ | D14: =B14*C14 -> 0
A15: BÍ ĐỎ MINI | D15: =B15*C15 -> 0
A16: BÍ ĐỎ NON (KG)KQ | D16: =B16*C16 -> 0
A17: BÍ ĐỎ NON TRÁI VR | B17: =20+14 -> 34 | C17: 4000 | D17: =B17*C17 -> 136000
A18: BÍ ĐỎ NON( KG) VR | D18: =B18*C18 -> 0
A19: BÍ ĐỎ TRÒN | B19: =1240+540+270+45+735 -> 2830 | C19: 5000 | D19: =B19*C19 -> 14150000
A20: BÍ MINI VÀNG 300GR | D20: =B20*C20 -> 0
A21: BÍ MINI VÀNG KG | D21: =B21*C21 -> 0
A22: BÍ NGÒI VÀNG | B22: 1 | C22: 28000 | D22: =B22*C22 -> 28000
A23: BÍ NGÒI VÀNG (TRÁI) | D23: =B23*C23 -> 0
A24: BÍ NGÒI XANH | B24: =20+15+12 -> 47 | C24: 11000 | D24: =B24*C24 -> 517000
A25: BÍ NGÒI XANH(TRÁI) | D25: =B25*C25 -> 0
A26: BÍ NHẬT | D26: =B26*C26 -> 0
A27: BƠ 034 | D27: =B27*C27 -> 0
A28: BƠ BOOTH | D28: =B28*C28 -> 0
A29: BƠ SÁP | D29: =B29*C29 -> 0
A30: BÓ XÔI | B30: 1 | C30: 16000 | D30: =B30*C30 -> 16000
A31: BÓ XÔI 300G VR | D31: =B31*C31 -> 0
A32: BÓ XÔI-HN KQ | D32: =B32*C32 -> 0
A33: BÓ XÔI-NA | D33: =B33*C33 -> 0
A34: BÔNG ATISO | D34: =B34*C34 -> 0
A35: BÔNG BÍ | D35: =B35*C35 -> 0
A36: BÔNG BÍ TÚI 300GR | D36: =B36*C36 -> 0
A37: BÔNG CẢI TRẮNG | B37: 12 | C37: 13000 | D37: =B37*C37 -> 156000
A38: BÔNG CẢI TRẮNG (CÂY) | D38: =B38*C38 -> 0
A39: BÔNG CẢI XANH 10P | B39: 3 | C39: 22000 | D39: =B39*C39 -> 66000
A40: BÔNG CẢI XANH AEON | D40: =B40*C40 -> 0
...

Sheet 27.12
A1: hàng tồn cuối ngày 27/12
A2: TÊN SẢN PHẨM | B2: TỒN TRƯỚC | C2: GIÁ NHẬP | D2: THÀNH TIỀN
A3: CÀ CHUA SÔCOLA 250GR (HỘP) VR | B3: 8 | C3: 8000 | D3: =B3*C3 -> 64000
A4: CÀ CHUA SÔCOLA 250GR (KG) -NA | D4: =B4*C4 -> 0
A5: CÀ CHUA SÔCOLA 250GR (KG) VR | D5: =B5*C5 -> 0
A6: CÀ CHUA SÔCOLA 250GR(KG) KQ | D6: =B6*C6 -> 0
A7: CÀ CHUA SÔCOLA 300GR (HỘP) VR | D7: =B7*C7 -> 0
A8: CÀ CHUA SOCOLA XÁ | D8: =B8*C8 -> 0
A9: CÀ CHUA SÔCOLA(HỘP) KQ | D9: =B9*C9 -> 0
A10: CÀ RỐT BABY | D10: =B10*C10 -> 0
A11: CÀ RỐT BABY (KG) KQ | D11: =B11*C11 -> 0
A12: CÀ RỐT BABY 200GR | D12: =B12*C12 -> 0
A13: CẢI CẦU VỒNG | D13: =B13*C13 -> 0
A14: CẢI CẦU VỒNG 300GR | B14: 8 | C14: 6000 | D14: =B14*C14 -> 48000
A15: CẢI KALE | D15: =B15*C15 -> 0
A16: CẢI KALE 300GR | B16: 9 | C16: 4000 | D16: =B16*C16 -> 36000
A17: CHANH VÀNG (KG) | D17: =B17*C17 -> 0
A18: CHANH VÀNG TRÁI 180UP | D18: =B18*C18 -> 0
A19: CẦN TÂY (KG) | B19: =19+26 -> 45 | C19: 18000 | D19: =B19*C19 -> 810000
A20: CẦN TÂY THUỶ CANH | D20: =B20*C20 -> 0
A21: CẦN TÂY(CÂY) | D21: =B21*C21 -> 0
A22: ỚT CHUÔNG 3 MÀU(KG)VR | D22: =B22*C22 -> 0
A23: ỚT CHUÔNG ĐỎ | B23: =60+10+25 -> 95 | C23: 30000 | D23: =B23*C23 -> 2850000
A24: ỚT CHUÔNG ĐỎ L1 | B24: 32 | C24: 25000 | D24: =B24*C24 -> 800000
A25: ỚT CHUÔNG ĐỎ(TRÁI) | D25: =B25*C25 -> 0
A26: ỚT CHUÔNG 3 MÀU 350G | D26: =B26*C26 -> 0
A27: ỚT CHUÔNG 3 MÀU KQ(KG) | D27: =B27*C27 -> 0
A28: ỚT CHUÔNG VÀNG | B28: =10+20+20 -> 50 | C28: 30000 | D28: =B28*C28 -> 1500000
A29: ỚT CHUÔNG VÀNG L1 | B29: 16 | C29: 25000 | D29: =B29*C29 -> 400000
A30: ỚT CHUÔNG VÀNG(TRÁI) | D30: =B30*C30 -> 0
A31: ỚT CHUÔNG VÀNG+ XANH (VỈ) | D31: =B31*C31 -> 0
A32: ỚT CHUÔNG XANH | B32: 5 | C32: 38000 | D32: =B32*C32 -> 190000
A33: ỚT CHUÔNG XANH L1 | B33: 15 | C33: 25000 | D33: =B33*C33 -> 375000
A34: ỚT CHUÔNG XANH(TRÁI) | D34: =B34*C34 -> 0
A35: CỦ DỀN | B35: 40 | C35: 11000 | D35: =B35*C35 -> 440000
A36: CỦ DỀN 600G | D36: =B36*C36 -> 0
A37: GỪNG 250GR | D37: =B37*C37 -> 0
A38: HỒNG GIÒN | D38: =B38*C38 -> 0
A39: XÀ LÁCH MỸ | D39: =B39*C39 -> 0
A40: KHOAI TÂY HỒNG | B40: 15 | C40: 24000 | D40: =B40*C40 -> 360000
...

Sheet 28.12
A1: hàng tồn cuối ngày 28/12
A2: TÊN SẢN PHẨM | B2: TỒN TRƯỚC | C2: GIÁ NHẬP | D2: THÀNH TIỀN
A3: CÀ CHUA SÔCOLA 250GR (HỘP) VR | D3: =B3*C3 -> 0
A4: CÀ CHUA SÔCOLA 250GR (KG) -NA | D4: =B4*C4 -> 0
A5: CÀ CHUA SÔCOLA 250GR (KG) VR | D5: =B5*C5 -> 0
A6: CÀ CHUA SÔCOLA 250GR(KG) KQ | D6: =B6*C6 -> 0
A7: CÀ CHUA SÔCOLA 300GR (HỘP) VR | D7: =B7*C7 -> 0
A8: CÀ CHUA SOCOLA XÁ | D8: =B8*C8 -> 0
A9: CÀ CHUA SÔCOLA(HỘP) KQ | D9: =B9*C9 -> 0
A10: CÀ RỐT BABY | D10: =B10*C10 -> 0
A11: CÀ RỐT BABY (KG) KQ | D11: =B11*C11 -> 0
A12: CÀ RỐT BABY 200GR | D12: =B12*C12 -> 0
A13: CẢI CẦU VỒNG | D13: =B13*C13 -> 0
A14: CẢI CẦU VỒNG 300GR | D14: =B14*C14 -> 0
... A22: ỚT CHUÔNG 3 MÀU(KG)VR | D22: =B22*C22 -> 0
A23: ỚT CHUÔNG ĐỎ | B23: =20+20+80+30+20+12 -> 182 | C23: 30000 | D23: =B23*C23 -> 5460000
A24: ỚT CHUÔNG ĐỎ L1 | B24: 12 | C24: 25000 | D24: =B24*C24 -> 300000
A25: ỚT CHUÔNG ĐỎ(TRÁI) | D25: =B25*C25 -> 0
A26: ỚT CHUÔNG 3 MÀU 350G | D26: =B26*C26 -> 0
A27: ỚT CHUÔNG 3 MÀU KQ(KG) | D27: =B27*C27 -> 0
A28: ỚT CHUÔNG VÀNG | B28: =26+20+20+5+22 -> 93 | C28: 38000 | D28: =B28*C28 -> 3534000
A29: ỚT CHUÔNG VÀNG L1 | B29: 7 | C29: 33000 | D29: =B29*C29 -> 231000
A30: ỚT CHUÔNG VÀNG(TRÁI) | D30: =B30*C30 -> 0
A31: ỚT CHUÔNG VÀNG+ XANH (VỈ) | D31: =B31*C31 -> 0
A32: ỚT CHUÔNG XANH | B32: 28 | C32: 27000 | D32: =B32*C32 -> 756000
A33: ỚT CHUÔNG XANH L1 | D33: =B33*C33 -> 0
A34: ỚT CHUÔNG XANH(TRÁI) | D34: =B34*C34 -> 0
A35: CỦ DỀN | B35: =47+6+10+40 -> 103 | C35: 11000 | D35: =B35*C35 -> 1133000
A36: CỦ DỀN 600G | D36: =B36*C36 -> 0
A37: GỪNG 250GR | D37: =B37*C37 -> 0
A38: HỒNG GIÒN | D38: =B38*C38 -> 0
A39: XÀ LÁCH MỸ | D39: =B39*C39 -> 0
A40: KHOAI TÂY HỒNG | B40: 5 | C40: 24000 | D40: =B40*C40 -> 120000
A41: KHOAI TÂY HỒNG TÚI LƯỚI 500G | D41: =B41*C41 -> 0
A42: KHOAI TÂY VÀNG | B42: 160 | C42: 12000 | D42: =B42*C42 -> 1920000
A43: KHOAI TÂY VÀNG ĐL | B43: =100+20+120+100 -> 340 | C43: 15000 | D43: =B43*C43 -> 5100000
A44: KHOAI TÂY VÀNG LỚN TÚI LƯỚI 500G | B44: 94 | C44: 15000 | D44: =B44*C44 -> 1410000
A45: KHOAI TÂY VÀNG RỬA | D45: =B45*C45 -> 0
A46: KHOAI TÂY VÀNG TRUNG TÚI LƯỚI 500G | D46: =B46*C46 -> 0
A47: CẢI THẢO DL | D47: =B47*C47 -> 0
...

Sheet 29.12
A1: Hàng tồn cuối ngày 29/12/2023 | B1: Stock | D1: Safety stock
A2: TÊN SẢN PHẨM | B2: Tồn trước | C2: Gía nhập | D2: Thành tiền
A3: CÀ CHUA SÔCOLA 250GR (HỘP) VR | D3: =B3*C3 -> 0
A4: CÀ CHUA SÔCOLA 250GR (KG) -NA | D4: =B4*C4 -> 0
A5: CÀ CHUA SÔCOLA 250GR (KG) VR | D5: =B5*C5 -> 0
A6: CÀ CHUA SÔCOLA 250GR(KG) KQ | D6: =B6*C6 -> 0
A7: CÀ CHUA SÔCOLA 300GR (HỘP) VR | D7: =B7*C7 -> 0
A8: CÀ CHUA SOCOLA XÁ | D8: =B8*C8 -> 0
A9: CÀ CHUA SÔCOLA(HỘP) KQ | D9: =B9*C9 -> 0
A10: CÀ RỐT BABY | D10: =B10*C10 -> 0
A11: CÀ RỐT BABY (KG) KQ | D11: =B11*C11 -> 0
A12: CÀ RỐT BABY 200GR | D12: =B12*C12 -> 0
A13: CẢI CẦU VỒNG | D13: =B13*C13 -> 0
A14: CẢI CẦU VỒNG 300GR | D14: =B14*C14 -> 0
... A18: CHANH VÀNG TRÁI 180UP | D18: =B18*C18 -> 0
A19: CẦN TÂY (KG) | B19: 15 | C19: 18000 | D19: =B19*C19 -> 270000
A20: CẦN TÂY THUỶ CANH | D20: =B20*C20 -> 0
A21: CẦN TÂY(CÂY) | D21: =B21*C21 -> 0
A22: ỚT CHUÔNG 3 MÀU(KG)VR | D22: =B22*C22 -> 0
A23: ỚT CHUÔNG ĐỎ | B23: 24 | C23: 30000 | D23: =B23*C23 -> 720000
A24: ỚT CHUÔNG ĐỎ L1 | D24: =B24*C24 -> 0
A25: ỚT CHUÔNG ĐỎ(TRÁI) | D25: =B25*C25 -> 0
A26: ỚT CHUÔNG 3 MÀU 350G | D26: =B26*C26 -> 0
A27: ỚT CHUÔNG 3 MÀU KQ(KG) | D27: =B27*C27 -> 0
A28: ỚT CHUÔNG VÀNG | B28: =18+10 -> 28 | C28: 38000 | D28: =B28*C28 -> 1064000
A29: ỚT CHUÔNG VÀNG L1 | D29: =B29*C29 -> 0
A30: ỚT CHUÔNG VÀNG(TRÁI) | D30: =B30*C30 -> 0
A31: ỚT CHUÔNG VÀNG+ XANH (VỈ) | D31: =B31*C31 -> 0
A32: ỚT CHUÔNG XANH | B32: =10+18+2 -> 30 | C32: 27000 | D32: =B32*C32 -> 810000
A33: ỚT CHUÔNG XANH L1 | D33: =B33*C33 -> 0
A34: ỚT CHUÔNG XANH(TRÁI) | D34: =B34*C34 -> 0
A35: CỦ DỀN | B35: =100+10 -> 110 | C35: 11000 | D35: =B35*C35 -> 1210000
A36: CỦ DỀN 600G | D36: =B36*C36 -> 0
A37: GỪNG 250GR | D37: =B37*C37 -> 0
A38: HỒNG GIÒN | D38: =B38*C38 -> 0
A39: XÀ LÁCH MỸ | D39: =B39*C39 -> 0
A40: KHOAI TÂY HỒNG | D40: =B40*C40 -> 0
