Workbook

Sheet 3011
A1: Tên Sản phẩm | B1: ĐVT | C1: SL | E1: Tên Sản phẩm | H1: =SUM(H3:H103) -> 63750350
A2: Hạt Dẻ Ngố | B2: KG | C2: 0
A3: Củ Dền | B3: KG | C3: 40 | D3: 45626 | E3: Củ Dền 30/11/2024 | F3: =VLOOKUP(E3,'[1]TIỀN MUA PHỤ'!$A:$B,2,0) -> 18000 | G3: 18000 | H3: =C3*G3 -> 720000
A4: Củ Hành Tây | B4: KG | C4: 50 | D4: 45626 | E4: Củ Hành Tây 30/11/2024 | F4: =VLOOKUP(E4,'[1]TIỀN MUA PHỤ'!$A:$B,2,0) -> 29000 | G4: 29000 | H4: =C4*G4 -> 1450000
A5: Củ Hành Tây | B5: Túi 300gr | C5: 0
A6: Củ Khoai Mỡ | B6: KG | C6: 0
A7: Cà Chua Beef | B7: KG | C7: 200 | D7: 45626 | E7: Cà Chua Beef 30/11/2024 | F7: =VLOOKUP(E7,'[1]TIỀN MUA PHỤ'!$A:$B,2,0) -> 22000 | G7: 22000 | H7: =C7*G7 -> 4400000
A8: Củ Khoai Lang Mật Size 46 | B8: KG | C8: 160 | D8: 45626 | E8: Củ Khoai Lang Mật Size 46 30/11/2024 | F8: =VLOOKUP(E8,'[1]TIỀN MUA PHỤ'!$A:$B,2,0) -> 31000 | G8: 31000 | H8: =C8*G8 -> 4960000
A9: Củ Khoai Lang Mật Size 46 | B9: Túi | C9: 0
A10: Củ Cải Đỏ | B10: KG | C10: 0
A11: Củ Cải Đỏ | B11: Hộp | C11: 30 | D11: 45626 | E11: Củ Cải Đỏ 30/11/2024 | F11: =VLOOKUP(E11,'[1]TIỀN MUA PHỤ'!$A:$B,2,0) -> 9500 | G11: 9500 | H11: =C11*G11 -> 285000
A12: Đậu Cove Trắng | B12: KG | C12: 0
A13: Đậu Cove Trắng | B13: Túi 300gr | C13: 100 | D13: 45626 | E13: Đậu Cove Trắng 30/11/2024 | F13: =VLOOKUP(E13,'[1]TIỀN MUA PHỤ'!$A:$B,2,0) -> 6500 | G13: 6500 | H13: =C13*G13 -> 650000
A14: Cà Chua Thường | B14: KG | C14: 100 | D14: 45626 | E14: Cà Chua Thường 30/11/2024 | F14: =VLOOKUP(E14,'[1]TIỀN MUA PHỤ'!$A:$B,2,0) -> 20000 | G14: 20000 | H14: =C14*G14 -> 2000000
A15: Cà Chua Thường | B15: Vỉ | C15: 0
A16: Bí Ngòi Xanh | B16: KG | C16: 0
A17: Bí Ngòi Xanh | B17: Trái 280gr | C17: 250 | D17: 45626 | E17: Bí Ngòi Xanh 30/11/2024 | F17: =VLOOKUP(E17,'[1]TIỀN MUA PHỤ'!$A:$B,2,0)*0.3 -> 2400 | G17: 2400 | H17: =C17*G17 -> 600000
A18: Cà Tím Sọc Pha Lê | B18: Hộp | C18: 0
A19: Hành Paro | B19: KG | C19: 15 | D19: 45626 | E19: Hành Paro 30/11/2024 | F19: =VLOOKUP(E19,'[1]TIỀN MUA PHỤ'!$A:$B,2,0) -> 28000 | G19: 28000 | H19: =C19*G19 -> 420000
A20: Hành Paro | B20: Cây | C20: 200 | D20: 45626 | E20: Hành Paro 30/11/2024 | F20: =VLOOKUP(E20,'[1]TIỀN MUA PHỤ'!$A:$B,2,0)/5 -> 5600 | G20: 5600 | H20: =C20*G20 -> 1120000
A21: Cải Bó Xôi | B21: KG | C21: 90 | D21: 45626 | E21: Cải Bó Xôi 30/11/2024 | F21: =VLOOKUP(E21,'[1]TIỀN MUA PHỤ'!$A:$B,2,0) -> 16000 | G21: 16000 | H21: =C21*G21 -> 1440000
A22: Cải Bó Xôi | B22: Túi | C22: 0
A23: Ớt Chuông Đỏ | B23: KG | C23: 0
A24: Ớt Chuông Đỏ | B24: Trái 180gr | C24: 800 | D24: 45626 | E24: Ớt Chuông Đỏ 30/11/2024 | F24: =VLOOKUP(E24,'[1]TIỀN MUA PHỤ'!$A:$B,2,0)/4 -> 7500 | G24: 7500 | H24: =C24*G24 -> 6000000
A25: Ớt Chuông Baby | B25: KG | C25: 20 | D25: 45626 | E25: Ớt Chuông Baby 30/11/2024 | F25: =VLOOKUP(E25,'[1]TIỀN MUA PHỤ'!$A:$B,2,0) -> 44000 | G25: 44000 | H25: =C25*G25 -> 880000
A26: Ớt Chuông Baby | B26: Hộp | C26: 0
A27: Cà Chua Bi Mix | B27: KG | C27: 0
A28: Cà Chua Bi Mix | B28: Hộp | C28: 59 | D28: 45626 | E28: Cà Chua Bi Mix 30/11/2024 | F28: =VLOOKUP(E28,'[1]TIỀN MUA PHỤ'!$A:$B,2,0)*0.3 -> 15450 | G28: 15450 | H28: =C28*G28 -> 911550
A29: Cà Chua Socola | B29: KG | C29: 0
A30: Cà Chua Socola | B30: Hộp 300gr | C30: 245 | D30: 45626 | E30: Cà Chua Socola 30/11/2024 | F30: =VLOOKUP(E30,'[1]TIỀN MUA PHỤ'!$A:$B,2,0) -> 14000 | G30: 14000 | H30: =C30*G30 -> 3430000
A31: Bí Đao Xanh | B31: KG | C31: 0
A32: Bí Đao Xanh | B32: Trái | C32: 50 | D32: 45626 | E32: Bí Đao Xanh 30/11/2024 | F32: =VLOOKUP(E32,'[1]TIỀN MUA PHỤ'!$A:$B,2,0)*0.4 -> 2600 | G32: 2600 | H32: =C32*G32 -> 130000
A33: Bí Non Nhật | B33: KG | C33: 0
A34: Bí Non Nhật | B34: Trái | C34: 200 | D34: 45626 | E34: Bí Non Nhật 30/11/2024 | F34: =VLOOKUP(E34,'[1]TIỀN MUA PHỤ'!$A:$B,2,0)*0.3 -> 3000 | G34: 3000 | H34: =C34*G34 -> 600000
A35: Xà Lách Lolo Tím | B35: KG | C35: 17 | D35: 45626 | E35: Xà Lách Lolo Tím 30/11/2024 | F35: =VLOOKUP(E35,'[1]TIỀN MUA PHỤ'!$A:$B,2,0) -> 35000 | G35: 35000 | H35: =C35*G35 -> 595000
A36: Xà Lách Lolo Tím | B36: Túi | C36: 0
A37: Ớt Sweet Palemo | B37: KG | C37: 0
A38: Ớt Sweet Palemo | B38: Túi | C38: 200 | D38: 45626 | E38: Ớt Sweet Palemo 30/11/2024 | F38: 18000 | G38: 18000 | H38: =C38*G38 -> 3600000
A39: Củ Khoai Lang Nhật | B39: KG | C39: 50 | D39: 45626 | E39: Củ Khoai Lang Nhật 30/11/2024 | F39: =VLOOKUP(E39,'[1]TIỀN MUA PHỤ'!$A:$B,2,0) -> 17500 | G39: 17500 | H39: =C39*G39 -> 875000
A40: Củ Khoai Lang Nhật | B40: Túi | C40: 0
...

Sheet 2911
A1: Tên Sản phẩm | B1: ĐVT | C1: SL | E1: Tên Sản phẩm | H1: =SUM(H2:H97) -> 59956550
A2: Dưa Leo Thường | B2: KG | C2: 40 | D2: 45625 | E2: Dưa Leo Thường 29/11/2024 | F2: =VLOOKUP(E2,'[1]TIỀN MUA PHỤ'!$A:$B,2,0) -> 4000 | G2: 4000 | H2: =C2*G2 -> 160000
A3: Hạt Dẻ Ngố | B3: KG | C3: 0 | D3: 45625
A4: Cà Chua Beef | B4: KG | C4: 140 | D4: 45625 | E4: Cà Chua Beef 29/11/2024 | F4: =VLOOKUP(E4,'[1]TIỀN MUA PHỤ'!$A:$B,2,0) -> 19000 | G4: 19000 | H4: =C4*G4 -> 2660000
A5: Cà Chua Thường | B5: KG | C5: 100 | D5: 45625 | E5: Cà Chua Thường 29/11/2024 | F5: =VLOOKUP(E5,'[1]TIỀN MUA PHỤ'!$A:$B,2,0) -> 18000 | G5: 18000 | H5: =C5*G5 -> 1800000
A6: Cà Chua Thường | B6: Vỉ | C6: 0 | D6: 45625
A7: Cần Tây | B7: KG | C7: 0 | D7: 45625
A8: Cần Tây | B8: Cây | C8: 200 | D8: 45625 | E8: Cần Tây 29/11/2024 | F8: 10000 | G8: 10000 | H8: =C8*G8 -> 2000000
A9: Cần Tây | B9: Túi | C9: 0 | D9: 45625
A10: Bí Ngòi Xanh | B10: KG | C10: 0 | D10: 45625
A11: Bí Ngòi Xanh | B11: Trái 280gr | C11: 400 | D11: 45625 | E11: Bí Ngòi Xanh 29/11/2024 | F11: =VLOOKUP(E11,'[1]TIỀN MUA PHỤ'!$A:$B,2,0)*0.3 -> 2400 | G11: 2400 | H11: =C11*G11 -> 960000
A12: Hành Paro | B12: KG | C12: 0 | D12: 45625
A13: Hành Paro | B13: Cây | C13: 300 | D13: 45625 | E13: Hành Paro 29/11/2024 | F13: =VLOOKUP(E13,'[1]TIỀN MUA PHỤ'!$A:$B,2,0)/5 -> 5800 | G13: 5800 | H13: =C13*G13 -> 1740000
A14: Cải Bó Xôi | B14: KG | C14: 60 | D14: 45625 | E14: Cải Bó Xôi 29/11/2024 | F14: =VLOOKUP(E14,'[1]TIỀN MUA PHỤ'!$A:$B,2,0) -> 16000 | G14: 16000 | H14: =C14*G14 -> 960000
A15: Cải Bó Xôi | B15: Túi | C15: 0 | D15: 45625
A16: Bông Cải Xanh Baby | B16: KG | C16: 0 | D16: 45625
A17: Bông Cải Xanh Baby | B17: Vỉ | C17: 55 | D17: 45625 | E17: Bông Cải Xanh Baby 29/11/2024 | F17: =VLOOKUP(E17,'[1]TIỀN MUA PHỤ'!$A:$B,2,0)/5 -> 9400 | G17: 9400 | H17: =C17*G17 -> 517000
A18: Cà Chua Socola | B18: KG | C18: 0 | D18: 45625
A19: Cà Chua Socola | B19: Hộp 300gr | C19: 0 | D19: 45625
A20: Ớt Sweet Palemo | B20: KG | C20: 0 | D20: 45625
A21: Ớt Sweet Palemo | B21: Túi | C21: 443 | D21: 45625 | E21: Ớt Sweet Palemo 29/11/2024 | F21: 18000 | G21: 18000 | H21: =C21*G21 -> 7974000
A22: Xà Lách Lolo Xanh | B22: KG | C22: 140 | D22: 45625 | E22: Xà Lách Lolo Xanh 29/11/2024 | F22: =VLOOKUP(E22,'[1]TIỀN MUA PHỤ'!$A:$B,2,0) -> 14000 | G22: 14000 | H22: =C22*G22 -> 1960000
A23: Xà Lách Lolo Xanh | B23: Túi | C23: 0 | D23: 45625
A24: Cải Kale | B24: KG | C24: 0 | D24: 45625
A25: Cải Kale | B25: Túi | C25: 50 | D25: 45625 | E25: Cải Kale 29/11/2024 | F25: =VLOOKUP(E25,'[1]TIỀN MUA PHỤ'!$A:$B,2,0)*0.3 -> 7350 | G25: 7350 | H25: =C25*G25 -> 367500
A26: Cải Kale | B26: Túi 150gr | C26: 20 | D26: 45625 | E26: Cải Kale 29/11/2024 | F26: =F25/2 -> 3675 | G26: 3675 | H26: =C26*G26 -> 73500
A27: Bí Đao Xanh | B27: KG | C27: 0 | D27: 45625
A28: Bí Đao Xanh | B28: Trái | C28: 20 | D28: 45625 | E28: Bí Đao Xanh 29/11/2024 | F28: =VLOOKUP(E28,'[1]TIỀN MUA PHỤ'!$A:$B,2,0)*0.4 -> 2600 | G28: 2600 | H28: =C28*G28 -> 52000
A29: Xà Lách Lolo Tím | B29: KG | C29: 5 | D29: 45625 | E29: Xà Lách Lolo Tím 29/11/2024 | F29: =VLOOKUP(E29,'[1]TIỀN MUA PHỤ'!$A:$B,2,0) -> 35000 | G29: 35000 | H29: =C29*G29 -> 175000
A30: Xà Lách Lolo Tím | B30: Túi | C30: 0 | D30: 45625
A31: Lá Mè | B31: KG | C31: 0 | D31: 45625
A32: Lá Mè | B32: Túi | C32: 800 | D32: 45625 | E32: Lá Mè 29/11/2024 | F32: =VLOOKUP(E32,'[1]TIỀN MUA PHỤ'!$A:$B,2,0)/20 -> 1800 | G32: 1800 | H32: =C32*G32 -> 1440000
A33: Củ Dền | B33: KG | C33: 20 | D33: 45625 | E33: Củ Dền 29/11/2024 | F33: =VLOOKUP(E33,'[1]TIỀN MUA PHỤ'!$A:$B,2,0) -> 18000 | G33: 18000 | H33: =C33*G33 -> 360000
A34: Củ Hành Tây | B34: KG | C34: 0 | D34: 45625
A35: Củ Hành Tây | B35: Túi 300gr | C35: 0 | D35: 45625
A36: Củ Khoai Lang Nhật | B36: KG | C36: 100 | D36: 45625 | E36: Củ Khoai Lang Nhật 29/11/2024 | F36: =VLOOKUP(E36,'[1]TIỀN MUA PHỤ'!$A:$B,2,0) -> 17500 | G36: 17500 | H36: =C36*G36 -> 1750000
A37: Củ Khoai Lang Nhật | B37: Túi | C37: 0 | D37: 45625
A38: Bí Đỏ Tròn | B38: KG | C38: 0 | D38: 45625
A39: Xà Lách Mỡ | B39: KG | C39: 50 | D39: 45625 | E39: Xà Lách Mỡ 29/11/2024 | F39: 25000 | G39: 25000 | H39: =C39*G39 -> 1250000
A40: Củ Khoai Mỡ | B40: KG | C40: 0 | D40: 45625
...

Sheet 2811
A1: Tên Sản phẩm | B1: ĐVT | C1: SL | D1: NGÀY | H1: =SUM(H2:H102) -> 74548500
A2: Dưa Leo Thường | B2: KG | C2: 20 | D2: 45624 | E2: Dưa Leo Thường 28/11/2024 | F2: =VLOOKUP(E2,'[1]TIỀN MUA PHỤ'!$A:$B,2,0) -> 4000 | G2: 4000 | H2: =C2*G2 -> 80000
A3: Ớt Chuông Đỏ | B3: KG | C3: 0 | D3: 45624 | E3: Ớt Chuông Đỏ 28/11/2024 | F3: =VLOOKUP(E3,'[1]TIỀN MUA PHỤ'!$A:$B,2,0) -> 32000 | G3: 32000
A4: Ớt Chuông Đỏ | B4: Trái 180gr | C4: 800 | D4: 45624 | E4: Ớt Chuông Đỏ 28/11/2024 | F4: =VLOOKUP(E4,'[1]TIỀN MUA PHỤ'!$A:$B,2,0)/4 -> 8000 | G4: 8000 | H4: =C4*G4 -> 6400000
A5: Hạt Dẻ Ngố | B5: KG | C5: 0 | D5: 45624 | E5: Hạt Dẻ Ngố 28/11/2024 | F5: =VLOOKUP(E5,'[1]TIỀN MUA PHỤ'!$A:$B,2,0) -> #N/A | G5: #N/A
A6: Xà Lách Lolo Xanh | B6: KG | C6: 100 | D6: 45624 | E6: Xà Lách Lolo Xanh 28/11/2024 | F6: =VLOOKUP(E6,'[1]TIỀN MUA PHỤ'!$A:$B,2,0) -> 14000 | G6: 14000 | H6: =C6*G6 -> 1400000
A7: Xà Lách Lolo Xanh | B7: Túi | C7: 0 | D7: 45624 | E7: Xà Lách Lolo Xanh 28/11/2024 | F7: =VLOOKUP(E7,'[1]TIỀN MUA PHỤ'!$A:$B,2,0) -> 14000 | G7: 14000
A8: Cà Chua Beef | B8: KG | C8: 300 | D8: 45624 | E8: Cà Chua Beef 28/11/2024 | F8: =VLOOKUP(E8,'[1]TIỀN MUA PHỤ'!$A:$B,2,0) -> 16000 | G8: 16000 | H8: =C8*G8 -> 4800000
A9: Dưa Leo Baby | B9: KG | C9: 0 | D9: 45624 | E9: Dưa Leo Baby 28/11/2024 | F9: =VLOOKUP(E9,'[1]TIỀN MUA PHỤ'!$A:$B,2,0) -> 6000 | G9: 6000
A10: Dưa Leo Baby | B10: Vỉ | C10: 840 | D10: 45624 | E10: Dưa Leo Baby 28/11/2024 | F10: =VLOOKUP(E10,'[1]TIỀN MUA PHỤ'!$A:$B,2,0) -> 6000 | G10: 6000 | H10: =C10*G10 -> 5040000
A11: Cà Chua Thường | B11: KG | C11: 100 | D11: 45624 | E11: Cà Chua Thường 28/11/2024 | F11: =VLOOKUP(E11,'[1]TIỀN MUA PHỤ'!$A:$B,2,0) -> 18000 | G11: 18000 | H11: =C11*G11 -> 1800000
A12: Cà Chua Thường | B12: Vỉ | C12: 0 | D12: 45624 | E12: Cà Chua Thường 28/11/2024 | F12: =VLOOKUP(E12,'[1]TIỀN MUA PHỤ'!$A:$B,2,0) -> 18000 | G12: 18000
A13: Cần Tây | B13: KG | C13: 0 | D13: 45624 | E13: Cần Tây 28/11/2024 | F13: =VLOOKUP(E13,'[1]TIỀN MUA PHỤ'!$A:$B,2,0) -> 20000 | G13: 20000
A14: Cần Tây | B14: Cây | C14: 300 | D14: 45624 | E14: Cần Tây 28/11/2024 | F14: 10000 | G14: 10000 | H14: =C14*G14 -> 3000000
A15: Cần Tây | B15: Túi | C15: 0 | D15: 45624 | E15: Cần Tây 28/11/2024 | F15: =VLOOKUP(E15,'[1]TIỀN MUA PHỤ'!$A:$B,2,0) -> 20000 | G15: 20000
A16: Cải Bó Xôi | B16: KG | C16: 40 | D16: 45624 | E16: Cải Bó Xôi 28/11/2024 | F16: =VLOOKUP(E16,'[1]TIỀN MUA PHỤ'!$A:$B,2,0) -> 16000 | G16: 16000 | H16: =C16*G16 -> 640000
A17: Cải Bó Xôi | B17: Túi | C17: 0 | D17: 45624 | E17: Cải Bó Xôi 28/11/2024 | F17: =VLOOKUP(E17,'[1]TIỀN MUA PHỤ'!$A:$B,2,0) -> 16000 | G17: 16000
A18: Bông Cải Xanh Baby | B18: KG | C18: 5 | D18: 45624 | E18: Bông Cải Xanh Baby 28/11/2024 | F18: =VLOOKUP(E18,'[1]TIỀN MUA PHỤ'!$A:$B,2,0) -> 47000 | G18: 47000 | H18: =C18*G18 -> 235000
A19: Bông Cải Xanh Baby | B19: Vỉ | C19: 70 | D19: 45624 | E19: Bông Cải Xanh Baby 28/11/2024 | F19: =VLOOKUP(E19,'[1]TIỀN MUA PHỤ'!$A:$B,2,0)/5 -> 9400 | G19: 9400 | H19: =C19*G19 -> 658000
A20: Cà Chua Socola | B20: KG | C20: 0 | D20: 45624 | E20: Cà Chua Socola 28/11/2024 | F20: =VLOOKUP(E20,'[1]TIỀN MUA PHỤ'!$A:$B,2,0) -> 10000 | G20: 10000
A21: Cà Chua Socola | B21: Hộp 300gr | C21: 200 | D21: 45624 | E21: Cà Chua Socola 28/11/2024 | F21: 12450 | G21: 12450 | H21: =C21*G21 -> 2490000
A22: Ớt Sweet Palemo | B22: KG | C22: 0 | D22: 45624 | E22: Ớt Sweet Palemo 28/11/2024 | F22: =VLOOKUP(E22,'[1]TIỀN MUA PHỤ'!$A:$B,2,0) -> 55000 | G22: 55000
A23: Ớt Sweet Palemo | B23: Túi | C23: 300 | D23: 45624 | E23: Ớt Sweet Palemo 28/11/2024 | F23: 20000 | G23: 20000 | H23: =C23*G23 -> 6000000
A24: Bí Ngòi Xanh | B24: KG | C24: 0 | D24: 45624 | E24: Bí Ngòi Xanh 28/11/2024 | F24: =VLOOKUP(E24,'[1]TIỀN MUA PHỤ'!$A:$B,2,0) -> 9000 | G24: 9000
A25: Bí Ngòi Xanh | B25: Trái 280gr | C25: 500 | D25: 45624 | E25: Bí Ngòi Xanh 28/11/2024 | F25: =VLOOKUP(E25,'[1]TIỀN MUA PHỤ'!$A:$B,2,0)*0.3 -> 2700 | G25: 2700 | H25: =C25*G25 -> 1350000
A26: Bí Non Nhật | B26: KG | C26: 0 | D26: 45624 | E26: Bí Non Nhật 28/11/2024 | F26: =VLOOKUP(E26,'[1]TIỀN MUA PHỤ'!$A:$B,2,0) -> 10000 | G26: 10000
A27: Bí Non Nhật | B27: Trái | C27: 460 | D27: 45624 | E27: Bí Non Nhật 28/11/2024 | F27: =VLOOKUP(E27,'[1]TIỀN MUA PHỤ'!$A:$B,2,0)*0.3 -> 3000 | G27: 3000 | H27: =C27*G27 -> 1380000
A28: Xà Lách Lolo Tím | B28: KG | C28: 10 | D28: 45624 | E28: Xà Lách Lolo Tím 28/11/2024 | F28: =VLOOKUP(E28,'[1]TIỀN MUA PHỤ'!$A:$B,2,0) -> 35000 | G28: 35000 | H28: =C28*G28 -> 350000
A29: Xà Lách Lolo Tím | B29: Túi | C29: 0 | D29: 45624 | E29: Xà Lách Lolo Tím 28/11/2024 | F29: =VLOOKUP(E29,'[1]TIỀN MUA PHỤ'!$A:$B,2,0) -> 35000 | G29: 35000
A30: Lá Mè | B30: KG | C30: 0 | D30: 45624 | E30: Lá Mè 28/11/2024 | F30: =VLOOKUP(E30,'[1]TIỀN MUA PHỤ'!$A:$B,2,0) -> 38000 | G30: 38000
A31: Lá Mè | B31: Túi | C31: 400 | D31: 45624 | E31: Lá Mè 28/11/2024 | F31: =VLOOKUP(E31,'[1]TIỀN MUA PHỤ'!$A:$B,2,0)/20 -> 1900 | G31: 1900 | H31: =C31*G31 -> 760000
A32: Cà Chua Bi Đỏ | B32: KG | C32: 0 | D32: 45624 | E32: Cà Chua Bi Đỏ 28/11/2024 | F32: =VLOOKUP(E32,'[1]TIỀN MUA PHỤ'!$A:$B,2,0) -> 8700 | G32: 8700
A33: Cà Chua Bi Đỏ | B33: Hộp 300gr | C33: 150 | D33: 45624 | E33: Cà Chua Bi Đỏ 28/11/2024 | F33: =VLOOKUP(E33,'[1]TIỀN MUA PHỤ'!$A:$B,2,0) -> 8700 | G33: 8700 | H33: =C33*G33 -> 1305000
A34: Xà Lách Lolo Xanh Sushi | B34: KG | C34: 40 | D34: 45624 | E34: Xà Lách Lolo Xanh Sushi 28/11/2024 | F34: 14000 | G34: 14000 | H34: =C34*G34 -> 560000
A35: Củ Dền | B35: KG | C35: 30 | D35: 45624 | E35: Củ Dền 28/11/2024 | F35: =VLOOKUP(E35,'[1]TIỀN MUA PHỤ'!$A:$B,2,0) -> 18000 | G35: 18000 | H35: =C35*G35 -> 540000
A36: Củ Hành Tây | B36: KG | C36: 110 | D36: 45624 | E36: Củ Hành Tây 28/11/2024 | F36: 21000 | G36: 21000 | H36: =C36*G36 -> 2310000
A37: Củ Hành Tây | B37: Túi 300gr | C37: 0 | D37: 45624 | E37: Củ Hành Tây 28/11/2024 | F37: =VLOOKUP(E37,'[1]TIỀN MUA PHỤ'!$A:$B,2,0) -> #N/A | G37: #N/A
A38: Củ Khoai Lang Nhật | B38: KG | C38: 150 | D38: 45624 | E38: Củ Khoai Lang Nhật 28/11/2024 | F38: =VLOOKUP(E38,'[1]TIỀN MUA PHỤ'!$A:$B,2,0) -> 17000 | G38: 17000 | H38: =C38*G38 -> 2550000
A39: Củ Khoai Lang Nhật | B39: Túi | C39: 0 | D39: 45624 | E39: Củ Khoai Lang Nhật 28/11/2024 | F39: =VLOOKUP(E39,'[1]TIỀN MUA PHỤ'!$A:$B,2,0) -> 17000 | G39: 17000
A40: Xà Lách Mỡ | B40: KG | C40: 30 | D40: 45624 | E40: Xà Lách Mỡ 28/11/2024 | F40: 26000 | G40: 26000 | H40: =C40*G40 -> 780000
...

Sheet 2711
H1: =SUM(H2:H132) -> 48280500
A2: Bắp Cải Tím | B2: KG | C2: 20 | D2: 45623 | E2: Bắp Cải Tím 27/11/2024 | F2: =VLOOKUP(E2,'[1]TIỀN MUA PHỤ'!$A:$B,2,0) -> 30000 | G2: 30000 | H2: =C2*G2 -> 600000
A3: Bắp Cải Trái Tim | B3: KG | C3: 20 | D3: 45623 | E3: Bắp Cải Trái Tim 27/11/2024 | F3: =VLOOKUP(E3,'[1]TIỀN MUA PHỤ'!$A:$B,2,0) -> 10000 | G3: 10000 | H3: =C3*G3 -> 200000
A4: Bắp Cải Trắng | B4: KG | C4: 0
A5: Bí Đao Xanh | B5: KG | C5: 0
A6: Bí Đao Xanh | B6: Trái | C6: 30 | D6: 45623 | E6: Bí Đao Xanh 27/11/2024 | F6: =VLOOKUP(E6,'[1]TIỀN MUA PHỤ'!$A:$B,2,0)*0.4 -> 3000 | G6: 3000 | H6: =C6*G6 -> 90000
A7: Bí Đỏ Tròn | B7: KG | C7: 0
A8: Bí Ngô Mini | B8: KG | C8: 0
A9: Bí Ngòi Xanh | B9: Trái 280gr | C9: 300 | D9: 45623 | E9: Bí Ngòi Xanh 27/11/2024 | F9: =VLOOKUP(E9,'[1]TIỀN MUA PHỤ'!$A:$B,2,0)*0.3 -> 2700 | G9: 2700 | H9: =C9*G9 -> 810000
A10: Bí Ngòi Xanh | B10: KG | C10: 0
A11: Bí Non Nhật | B11: KG | C11: 20 | D11: 45623 | E11: Bí Non Nhật 27/11/2024 | F11: =VLOOKUP(E11,'[1]TIỀN MUA PHỤ'!$A:$B,2,0) -> 10000 | G11: 10000 | H11: =C11*G11 -> 200000
A12: Bí Non Nhật | B12: Trái | C12: 187 | D12: 45623 | E12: Bí Non Nhật 27/11/2024 | F12: =VLOOKUP(E12,'[1]TIỀN MUA PHỤ'!$A:$B,2,0)*0.3 -> 3000 | G12: 3000 | H12: =C12*G12 -> 561000
A13: Bơ Booth | B13: KG | C13: 80 | D13: 45623 | E13: Bơ Booth 27/11/2024 | F13: =VLOOKUP(E13,'[1]TIỀN MUA PHỤ'!$A:$B,2,0) -> 41000 | G13: 41000 | H13: =C13*G13 -> 3280000
A14: Bông Bí Nụ | B14: KG | C14: 0
A15: Bông Cải Xanh 7Cm | B15: KG | C15: 25 | D15: 45623 | E15: Bông Cải Xanh 7Cm 27/11/2024 | F15: =VLOOKUP(E15,'[1]TIỀN MUA PHỤ'!$A:$B,2,0) -> 32000 | G15: 32000 | H15: =C15*G15 -> 800000
A16: Bông Cải Xanh Baby | B16: KG | C16: 0
A17: Bông Cải Xanh Baby | B17: vỉ | C17: 15 | D17: 45623 | E17: Bông Cải Xanh Baby 27/11/2024 | F17: =VLOOKUP(E17,'[1]TIỀN MUA PHỤ'!$A:$B,2,0)/10 -> 4700 | G17: 4700 | H17: =C17*G17 -> 70500
A18: Cà Chua Beef | B18: KG | C18: 220 | D18: 45623 | E18: Cà Chua Beef 27/11/2024 | F18: =VLOOKUP(E18,'[1]TIỀN MUA PHỤ'!$A:$B,2,0) -> 16000 | G18: 16000 | H18: =C18*G18 -> 3520000
A19: Cà Chua Beef Trung | B19: KG | C19: 0
A20: Cà Chua Beef Trung | B20: Vỉ 500gr | C20: 160 | D20: 45623 | E20: Cà Chua Beef Trung 27/11/2024 | F20: =VLOOKUP(E20,'[1]TIỀN MUA PHỤ'!$A:$B,2,0)/2 -> 7500 | G20: 7500 | H20: =C20*G20 -> 1200000
A21: Cà Chua Bi Đỏ | B21: KG | C21: 0
A22: Cà Chua Bi Đỏ | B22: Hộp 300gr | C22: 150 | D22: 45623 | E22: Cà Chua Bi Đỏ 27/11/2024 | F22: =VLOOKUP(E22,'[1]TIỀN MUA PHỤ'!$A:$B,2,0) -> 8700 | G22: 8700 | H22: =C22*G22 -> 1305000
A23: Cà Chua Bi Mix | B23: KG | C23: 0
A24: Cà Chua Bi Mix | B24: hộp | C24: 50 | D24: 45623 | E24: Cà Chua Bi Mix 27/11/2024 | F24: =VLOOKUP(E24,'[1]TIỀN MUA PHỤ'!$A:$B,2,0)*0.3 -> 15450 | G24: 15450 | H24: =C24*G24 -> 772500
A25: Cà Chua Socola | B25: KG | C25: 0
A26: Cà Chua Socola | B26: Hộp 300gr | C26: 120 | D26: 45623 | E26: Cà Chua Socola 27/11/2024 | F26: =VLOOKUP(E26,'[1]TIỀN MUA PHỤ'!$A:$B,2,0)*0.3 -> 12450 | G26: 12450 | H26: =C26*G26 -> 1494000
A27: Cà Chua Thường | B27: KG | C27: 80 | D27: 45623 | E27: Cà Chua Thường 27/11/2024 | F27: =VLOOKUP(E27,'[1]TIỀN MUA PHỤ'!$A:$B,2,0) -> 17000 | G27: 17000 | H27: =C27*G27 -> 1360000
A28: Cà Chua Thường | B28: vỉ | C28: 0
A29: Cà Rốt | B29: KG | C29: 40 | D29: 45623 | E29: Cà Rốt 27/11/2024 | F29: =VLOOKUP(E29,'[1]TIỀN MUA PHỤ'!$A:$B,2,0) -> 14000 | G29: 14000 | H29: =C29*G29 -> 560000
A30: Cà Rốt | B30: túi | C30: 0
A31: Cà Rốt Baby | B31: KG | C31: 0
A32: Cà Rốt Baby | B32: vỉ | C32: 80 | D32: 45623 | E32: Cà Rốt Baby 27/11/2024 | F32: =VLOOKUP(E32,'[1]TIỀN MUA PHỤ'!$A:$B,2,0)/5 -> 8000 | G32: 8000 | H32: =C32*G32 -> 640000
A33: Cà Tím Sọc Pha Lê | B33: hộp | C33: 0
A34: Cải Bó Xôi | B34: KG | C34: 40 | D34: 45623 | E34: Cải Bó Xôi 27/11/2024 | F34: =VLOOKUP(E34,'[1]TIỀN MUA PHỤ'!$A:$B,2,0) -> 16000 | G34: 16000 | H34: =C34*G34 -> 640000
A35: Cải Bó Xôi | B35: túi | C35: 0
A36: Cải Cầu Vồng | B36: KG | C36: 0
A37: Cải Kale | B37: KG | C37: 0
A38: Cải Kale | B38: túi | C38: 150 | D38: 45623 | E38: Cải Kale 27/11/2024 | F38: =VLOOKUP(E38,'[1]TIỀN MUA PHỤ'!$A:$B,2,0)*0.3 -> 6900 | G38: 6900 | H38: =C38*G38 -> 1035000
A39: Cải Kale | B39: Túi 150gr | C39: 0
A40: Cải Thảo | B40: KG | C40: 0
...

Sheet 2611
A1: TÊN | B1: ĐVT | C1: SL | D1: NGÀY | H1: =SUM(H6:H137) -> 42283350
A2: Bắp Cải Tím | B2: KG | C2: 0
A3: Bắp Cải Trái Tim | B3: KG | C3: 0
A4: Bắp Cải Trắng | B4: KG | C4: 0
A5: Bí Đao Xanh | B5: KG | C5: 0
A6: Bí Đao Xanh | B6: Trái | C6: 40 | D6: 45622 | E6: Bí Đao Xanh 26/11/2024 | F6: =VLOOKUP(E6,'[1]TIỀN MUA PHỤ'!$A:$B,2,0)*0.4 -> 3600 | G6: 3600 | H6: =C6*G6 -> 144000
A7: Bí Ngô Mini | B7: KG | C7: 0
A8: Bí Ngòi Xanh | B8: KG | C8: 70 | D8: 45622 | E8: Bí Ngòi Xanh 26/11/2024 | F8: =VLOOKUP(E8,'[1]TIỀN MUA PHỤ'!$A:$B,2,0) -> 10000 | G8: 10000 | H8: =C8*G8 -> 700000
A9: Bí Ngòi Xanh | B9: Trái 280gr | C9: 240 | D9: 45622 | E9: Bí Ngòi Xanh 26/11/2024 | F9: =VLOOKUP(E9,'[1]TIỀN MUA PHỤ'!$A:$B,2,0)*0.3 -> 3000 | G9: 3000 | H9: =C9*G9 -> 720000
A10: Bí Non Nhật | B10: KG | C10: 0
A11: Bí Non Nhật | B11: Trái | C11: 160 | D11: 45622 | E11: Bí Non Nhật 26/11/2024 | F11: =VLOOKUP(E11,'[1]TIỀN MUA PHỤ'!$A:$B,2,0)*0.3 -> 3000 | G11: 3000 | H11: =C11*G11 -> 480000
A12: Bơ Booth | B12: KG | C12: 0
A13: Bông Bí Nụ | B13: KG | C13: 0
A14: Bông Cải Trắng | B14: KG | C14: 0
A15: Bông Cải Xanh 7Cm | B15: KG | C15: 65 | D15: 45622 | E15: Bông Cải Xanh 7Cm 26/11/2024 | F15: =VLOOKUP(E15,'[1]TIỀN MUA PHỤ'!$A:$B,2,0) -> 32000 | G15: 32000 | H15: =C15*G15 -> 2080000
A16: Bông Cải Xanh Baby | B16: KG | C16: 8 | D16: 45622 | E16: Bông Cải Xanh Baby 26/11/2024 | F16: =VLOOKUP(E16,'[1]TIỀN MUA PHỤ'!$A:$B,2,0) -> 47000 | G16: 47000 | H16: =C16*G16 -> 376000
A17: Bông Cải Xanh Baby | B17: Vỉ | C17: 0
A18: Cà Chua Beef | B18: KG | C18: 80 | D18: 45622 | E18: Cà Chua Beef 26/11/2024 | F18: =VLOOKUP(E18,'[1]TIỀN MUA PHỤ'!$A:$B,2,0) -> 16000 | G18: 16000 | H18: =C18*G18 -> 1280000
A19: Cà Chua Beef Trung | B19: KG | C19: 50 | D19: 45622 | E19: Cà Chua Beef Trung 26/11/2024 | F19: =VLOOKUP(E19,'[1]TIỀN MUA PHỤ'!$A:$B,2,0) -> 16000 | G19: 16000 | H19: =C19*G19 -> 800000
A20: Cà Chua Beef Trung | B20: Vỉ 500gr | C20: 200 | D20: 45622 | E20: Cà Chua Beef Trung 26/11/2024 | F20: =VLOOKUP(E20,'[1]TIỀN MUA PHỤ'!$A:$B,2,0)/2 -> 8000 | G20: 8000 | H20: =C20*G20 -> 1600000
A21: Cà Chua Bi Đỏ | B21: KG | C21: 0
A22: Cà Chua Bi Đỏ | B22: Hộp 300gr | C22: 240 | D22: 45622 | E22: Cà Chua Bi Đỏ 26/11/2024 | F22: =VLOOKUP(E22,'[1]TIỀN MUA PHỤ'!$A:$B,2,0) -> 8700 | G22: 8700 | H22: =C22*G22 -> 2088000
A23: Cà Chua Bi Mix | B23: KG | C23: 0
A24: Cà Chua Bi Mix | B24: Hộp | C24: 50 | D24: 45622 | E24: Cà Chua Bi Mix 26/11/2024 | F24: =VLOOKUP(E24,'[1]TIỀN MUA PHỤ'!$A:$B,2,0)*0.3 -> 14250 | G24: 14250 | H24: =C24*G24 -> 712500
A25: Cà Chua Socola | B25: KG | C25: 0
A26: Cà Chua Socola | B26: Hộp 300gr | C26: 20 | D26: 45622 | E26: Cà Chua Socola 26/11/2024 | F26: =VLOOKUP(E26,'[1]TIỀN MUA PHỤ'!$A:$B,2,0)*0.3 -> 11400 | G26: 11400 | H26: =C26*G26 -> 228000
A27: Cà Chua Thường | B27: KG | C27: 100 | D27: 45622 | E27: Cà Chua Thường 26/11/2024 | F27: =VLOOKUP(E27,'[1]TIỀN MUA PHỤ'!$A:$B,2,0) -> 21000 | G27: 21000 | H27: =C27*G27 -> 2100000
A28: Cà Chua Thường | B28: Vỉ | C28: 0
A29: Cà Rốt | B29: KG | C29: 20 | D29: 45622 | E29: Cà Rốt 26/11/2024 | F29: =VLOOKUP(E29,'[1]TIỀN MUA PHỤ'!$A:$B,2,0) -> 13500 | G29: 13500 | H29: =C29*G29 -> 270000
A30: Cà Rốt | B30: Túi | C30: 0
A31: Cà Rốt Baby | B31: KG | C31: 0
A32: Cà Rốt Baby | B32: Vỉ | C32: 120 | D32: 45622 | E32: Cà Rốt Baby 26/11/2024 | F32: =VLOOKUP(E32,'[1]TIỀN MUA PHỤ'!$A:$B,2,0)/5 -> 8000 | G32: 8000 | H32: =C32*G32 -> 960000
A33: Cà Rốt Trung | B33: KG | C33: 40 | D33: 45622 | E33: Cà Rốt Trung 26/11/2024 | F33: =VLOOKUP(E33,'[1]TIỀN MUA PHỤ'!$A:$B,2,0) -> 11000 | G33: 11000 | H33: =C33*G33 -> 440000
A34: Cà Tím | B34: KG | C34: 0
A35: Cà Tím Sọc Pha Lê | B35: Hộp | C35: 0
A36: Cải Bó Xôi | B36: KG | C36: 40 | D36: 45622 | E36: Cải Bó Xôi 26/11/2024 | F36: =VLOOKUP(E36,'[1]TIỀN MUA PHỤ'!$A:$B,2,0) -> 17000 | G36: 17000 | H36: =C36*G36 -> 680000
A37: Cải Bó Xôi | B37: Túi | C37: 0
A38: Cải Cầu Vồng | B38: KG | C38: 0
A39: Cải Kale | B39: KG | C39: 0
A40: Cải Kale | B40: Túi | C40: 105 | D40: 45622 | E40: Cải Kale 26/11/2024 | F40: =VLOOKUP(E40,'[1]TIỀN MUA PHỤ'!$A:$B,2,0)*0.3 -> 6900 | G40: 6900 | H40: =C40*G40 -> 724500
...

Sheet 2511
A1: Dưa Leo Thường | B1: KG | C1: 20 | D1: 45621 | E1: Dưa Leo Thường 25/11/2024 | F1: =VLOOKUP(E1,'[1]TIỀN MUA PHỤ'!$A:$B,2,0) -> 3000 | G1: =C1*F1 -> 60000
A2: Cần Tây | B2: Cây | C2: 200 | D2: 45621 | E2: Cần Tây 25/11/2024 | F2: 10000 | G2: =C2*F2 -> 2000000
A3: Bí Ngòi Xanh | B3: Trái 280gr | C3: 500 | D3: 45621 | E3: Bí Ngòi Xanh 25/11/2024 | F3: =VLOOKUP(E3,'[1]TIỀN MUA PHỤ'!$A:$B,2,0)*0.3 -> 3000 | G3: =C3*F3 -> 1500000
A4: Cải Bó Xôi | B4: KG | C4: 80 | D4: 45621 | E4: Cải Bó Xôi 25/11/2024 | F4: =VLOOKUP(E4,'[1]TIỀN MUA PHỤ'!$A:$B,2,0)*0.3 -> 5100 | G4: =C4*F4 -> 408000
A5: Cà Chua Socola | B5: KG | C5: 6 | D5: 45621 | E5: Cà Chua Socola 25/11/2024 | F5: =VLOOKUP(E5,'[1]TIỀN MUA PHỤ'!$A:$B,2,0) -> 38500 | G5: =C5*F5 -> 231000
A6: Cà Chua Socola | B6: Hộp 300gr | C6: 172 | D6: 45621 | E6: Cà Chua Socola 25/11/2024 | F6: =40000*0.3 -> 12000 | G6: =C6*F6 -> 2064000
A7: Bí Đao Xanh | B7: Trái | C7: 20 | D7: 45621 | E7: Bí Đao Xanh 25/11/2024 | F7: 4000 | G7: =C7*F7 -> 80000
A8: Bí Non Nhật | B8: Trái | C8: 200 | D8: 45621 | E8: Bí Non Nhật 25/11/2024 | F8: =VLOOKUP(E8,'[1]TIỀN MUA PHỤ'!$A:$B,2,0)*0.3 -> 3000 | G8: =C8*F8 -> 600000
A9: Ớt Sweet Palemo | B9: Túi | C9: 200 | D9: 45621 | E9: Ớt Sweet Palemo 25/11/2024 | F9: 20000 | G9: =C9*F9 -> 4000000
A10: Bông Cải Xanh Baby | B10: Vỉ | C10: 70 | D10: 45621 | E10: Bông Cải Xanh Baby 25/11/2024 | F10: =VLOOKUP(E10,'[1]TIỀN MUA PHỤ'!$A:$B,2,0)/5 -> 10600 | G10: =C10*F10 -> 742000
A11: Xà Lách Lolo Tím | B11: KG | C11: 10 | D11: 45621 | E11: Xà Lách Lolo Tím 25/11/2024 | F11: =VLOOKUP(E11,'[1]TIỀN MUA PHỤ'!$A:$B,2,0) -> 35000 | G11: =C11*F11 -> 350000
A12: Lá Mè | B12: Túi | C12: 300 | D12: 45621 | E12: Lá Mè 25/11/2024 | F12: =VLOOKUP(E12,'[1]TIỀN MUA PHỤ'!$A:$B,2,0)/20 -> 1800 | G12: =C12*F12 -> 540000
A13: Xà Lách Mỡ | B13: KG | C13: 20 | D13: 45621 | E13: Xà Lách Mỡ 25/11/2024 | F13: 28000 | G13: =C13*F13 -> 560000
A14: Măng Tây | B14: KG | C14: 40 | D14: 45621 | E14: Măng Tây 25/11/2024 | F14: =VLOOKUP(E14,'[1]TIỀN MUA PHỤ'!$A:$B,2,0) -> 62000 | G14: =C14*F14 -> 2480000
A15: Đậu Cove Trắng | B15: Túi 300gr | C15: 20 | D15: 45621 | E15: Đậu Cove Trắng 25/11/2024 | F15: =VLOOKUP(E15,'[1]TIỀN MUA PHỤ'!$A:$B,2,0)*3 -> 19500 | G15: =C15*F15 -> 390000
A16: Củ Khoai Lang Mật Size 46 | B16: KG | C16: 100 | D16: 45621 | E16: Củ Khoai Lang Mật Size 46 25/11/2024 | F16: 26000 | G16: =C16*F16 -> 2600000
A17: Hành Paro | B17: Cây | C17: 100 | D17: 45621 | E17: Hành Paro 25/11/2024 | F17: =VLOOKUP(E17,'[1]TIỀN MUA PHỤ'!$A:$B,2,0)/5 -> 6000 | G17: =C17*F17 -> 600000
A18: Ớt Chuông Vàng | B18: Trái 180gr | C18: 250 | D18: 45621 | E18: Ớt Chuông Vàng 25/11/2024 | F18: =VLOOKUP(E18,'[1]TIỀN MUA PHỤ'!$A:$B,2,0)/4 -> 4500 | G18: =C18*F18 -> 1125000
A19: Ớt Chuông Xanh | B19: Trái 180gr | C19: 150 | D19: 45621 | E19: Ớt Chuông Xanh 25/11/2024 | F19: =VLOOKUP(E19,'[1]TIỀN MUA PHỤ'!$A:$B,2,0)/4 -> 7000 | G19: =C19*F19 -> 1050000
A20: Ớt Chuông Baby | B20: KG | C20: 25 | D20: 45621 | E20: Ớt Chuông Baby 25/11/2024 | F20: =VLOOKUP(E20,'[1]TIỀN MUA PHỤ'!$A:$B,2,0) -> 44000 | G20: =C20*F20 -> 1100000
A21: Cà Chua Bi Mix | B21: Hộp | C21: 90 | D21: 45621 | E21: Cà Chua Bi Mix 25/11/2024 | F21: =VLOOKUP(E21,'[1]TIỀN MUA PHỤ'!$A:$B,2,0)*0.3 -> 14100 | G21: =C21*F21 -> 1269000
A22: Cải Kale | B22: KG | C22: 15 | D22: 45621 | E22: Cải Kale 25/11/2024 | F22: 27000 | G22: =C22*F22 -> 405000
A23: Cải Kale | B23: Túi | C23: 131 | D23: 45621 | E23: Cải Kale 25/11/2024 | F23: 9000 | G23: =C23*F23 -> 1179000
A24: Cải Kale | B24: Túi 150gr | C24: 15 | D24: 45621 | E24: Cải Kale 25/11/2024 | F24: 4500 | G24: =C24*F24 -> 67500
A25: Cà Rốt | B25: KG | C25: 108 | D25: 45621 | E25: Cà Rốt 25/11/2024 | F25: =VLOOKUP(E25,'[1]TIỀN MUA PHỤ'!$A:$B,2,0) -> 12500 | G25: =C25*F25 -> 1350000
A26: Cà Chua Bi Đỏ | B26: Hộp 300gr | C26: 100 | D26: 45621 | E26: Cà Chua Bi Đỏ 25/11/2024 | F26: =VLOOKUP(E26,'[1]TIỀN MUA PHỤ'!$A:$B,2,0) -> 8700 | G26: =C26*F26 -> 870000
A27: Lá É | B27: KG | C27: 5 | D27: 45621 | E27: Lá É 25/11/2024 | F27: =VLOOKUP(E27,'[1]TIỀN MUA PHỤ'!$A:$B,2,0) -> 27000 | G27: =C27*F27 -> 135000
A28: Xà Lách Lolo Xanh | B28: KG | C28: 100 | D28: 45621 | E28: Xà Lách Lolo Xanh 25/11/2024 | F28: =VLOOKUP(E28,'[1]TIỀN MUA PHỤ'!$A:$B,2,0) -> 14000 | G28: =C28*F28 -> 1400000
A29: Dưa Leo Baby | B29: Vỉ | C29: 820 | D29: 45621 | E29: Dưa Leo Baby 25/11/2024 | F29: =VLOOKUP(E29,'[1]TIỀN MUA PHỤ'!$A:$B,2,0) -> 4000 | G29: =C29*F29 -> 3280000
A30: Ớt Chuông Đỏ | B30: Trái 180gr | C30: 100 | D30: 45621 | E30: Ớt Chuông Đỏ 25/11/2024 | F30: =VLOOKUP(E30,'[1]TIỀN MUA PHỤ'!$A:$B,2,0)/4 -> 8750 | G30: =C30*F30 -> 875000
A31: Đậu Cove Nhật | B31: Túi | C31: 15 | D31: 45621 | E31: Đậu Cove Nhật 25/11/2024 | F31: =VLOOKUP(E31,'[1]TIỀN MUA PHỤ'!$A:$B,2,0) -> 6000 | G31: =C31*F31 -> 90000
A32: Củ Khoai Tây Vàng | B32: KG | C32: 50 | D32: 45621 | E32: Củ Khoai Tây Vàng 25/11/2024 | F32: 18000 | G32: =C32*F32 -> 900000
A33: Ớt Chuông Ba Màu | B33: Vỉ | C33: 20 | D33: 45621 | E33: Ớt Chuông Ba Màu 25/11/2024 | F33: 22000 | G33: =C33*F33 -> 440000
A34: Bông Cải Xanh 7Cm | B34: KG | C34: 20 | D34: 45621 | E34: Bông Cải Xanh 7Cm 25/11/2024 | F34: =VLOOKUP(E34,'[1]TIỀN MUA PHỤ'!$A:$B,2,0) -> 36000 | G34: =C34*F34 -> 720000
A35: Củ Hành Tây | B35: KG | C35: 100 | D35: 45621 | E35: Củ Hành Tây 25/11/2024 | F35: =VLOOKUP(E35,'[1]TIỀN MUA PHỤ'!$A:$B,2,0) -> 21000 | G35: =C35*F35 -> 2100000
A36: Cà Chua Beef Trung | B36: Vỉ 500gr | C36: 242 | D36: 45621 | E36: Cà Chua Beef Trung 25/11/2024 | F36: 9000 | G36: =C36*F36 -> 2178000
A37: Cà Rốt Baby | B37: Vỉ | C37: 60 | D37: 45621 | E37: Cà Rốt Baby 25/11/2024 | F37: =VLOOKUP(E37,'[1]TIỀN MUA PHỤ'!$A:$B,2,0)/5 -> 8400 | G37: =C37*F37 -> 504000
A38: Bắp Cải Tím | B38: KG | C38: 15 | D38: 45621 | E38: Bắp Cải Tím 25/11/2024 | F38: =VLOOKUP(E38,'[1]TIỀN MUA PHỤ'!$A:$B,2,0) -> 30000 | G38: =C38*F38 -> 450000
A39: Dưa Leo Nhật | B39: Túi | C39: 25 | D39: 45621 | E39: Dưa Leo Nhật 25/11/2024 | F39: 6000 | G39: =C39*F39 -> 150000
A40: Xà Lách Lolo Xanh T.C Cây | B40: Cây | C40: 50 | D40: 45621 | E40: Xà Lách Lolo Xanh T.C Cây 25/11/2024 | F40: =VLOOKUP(E40,'[1]TIỀN MUA PHỤ'!$A:$B,2,0) -> 6800 | G40: =C40*F40 -> 340000
...

Sheet 2411
H1: =SUM(H2:H49) -> 47592450
A2: Bí Ngòi Xanh | B2: Trái 280gr | C2: 376 | D2: 45620 | E2: Bí Ngòi Xanh Trái 280gr 24/11/2024 | F2: 3000 | G2: 3000 | H2: =C2*G2 -> 1128000
A3: Bí Non Nhật | B3: Trái | C3: 250 | D3: 45620 | E3: Bí Non Nhật Trái 24/11/2024 | F3: 3000 | G3: 3000 | H3: =C3*G3 -> 750000
A4: Bông Cải Xanh Baby | B4: Vỉ | C4: 50 | D4: 45620 | E4: Bông Cải Xanh Baby Vỉ 24/11/2024 | F4: 10600 | G4: 10600 | H4: =C4*G4 -> 530000
A5: Cà Chua Beef Trung | B5: KG | C5: 110 | D5: 45620 | E5: Cà Chua Beef Trung KG 24/11/2024 | F5: =VLOOKUP(E5,'[2]SỔ CHI TIẾT MUA HÀNG'!$I:$K,3,0) -> 15000 | G5: 15000 | H5: =C5*G5 -> 1650000
A6: Cà Chua Beef Trung | B6: Vỉ 500gr | C6: 200 | D6: 45620 | E6: Cà Chua Beef Trung Vỉ 500gr 24/11/2024 | F6: =16500/2 -> 8250 | G6: 8250 | H6: =C6*G6 -> 1650000
A7: Cà Chua Bi Đỏ | B7: KG | C7: 5 | D7: 45620 | E7: Cà Chua Bi Đỏ KG 24/11/2024 | F7: 33000 | G7: 33000 | H7: =C7*G7 -> 165000
A8: Cà Chua Bi Đỏ | B8: Hộp 300gr | C8: 100 | D8: 45620 | E8: Cà Chua Bi Đỏ Hộp 300gr 24/11/2024 | F8: =VLOOKUP(E8,'[2]SỔ CHI TIẾT MUA HÀNG'!$I:$K,3,0) -> 10500 | G8: 10500 | H8: =C8*G8 -> 1050000
A9: Cà Chua Bi Mix | B9: Hộp | C9: 69 | D9: 45620 | E9: Cà Chua Bi Mix Hộp 24/11/2024 | F9: ='2111'!H10 -> 15450 | G9: 15450 | H9: =C9*G9 -> 1066050
A10: Cà Chua Socola | B10: Hộp 300gr | C10: 96 | D10: 45620 | E10: Cà Chua Socola Hộp 300gr 24/11/2024 | F10: 11550 | G10: 11550 | H10: =C10*G10 -> 1108800
A11: Cà Chua Thường | B11: KG | C11: 100 | D11: 45620 | E11: Cà Chua Thường KG 24/11/2024 | F11: =VLOOKUP(E11,'[2]SỔ CHI TIẾT MUA HÀNG'!$I:$K,3,0) -> 14000 | G11: 14000 | H11: =C11*G11 -> 1400000
A12: Cà Rốt | B12: KG | C12: 60 | D12: 45620 | E12: Cà Rốt KG 24/11/2024 | F12: 12500 | G12: 12500 | H12: =C12*G12 -> 750000
A13: Cà Rốt Baby | B13: KG | C13: 5 | D13: 45620 | E13: Cà Rốt Baby KG 24/11/2024 | F13: =VLOOKUP(E13,'[2]SỔ CHI TIẾT MUA HÀNG'!$I:$K,3,0) -> 42000 | G13: 42000 | H13: =C13*G13 -> 210000
A14: Cà Rốt Baby | B14: Vỉ | C14: 100 | D14: 45620 | E14: Cà Rốt Baby Vỉ 24/11/2024 | F14: 8400 | G14: 8400 | H14: =C14*G14 -> 840000
A15: Cải Bó Xôi | B15: KG | C15: 20 | D15: 45620 | E15: Cải Bó Xôi KG 24/11/2024 | F15: =VLOOKUP(E15,'[2]SỔ CHI TIẾT MUA HÀNG'!$I:$K,3,0) -> 20000 | G15: 20000 | H15: =C15*G15 -> 400000
A16: Cải Kale | B16: Túi | C16: 50 | D16: 45620 | E16: Cải Kale Túi 24/11/2024 | F16: 8400 | G16: 8400 | H16: =C16*G16 -> 420000
A17: Cải Kale | B17: Túi 150gr | C17: 15 | D17: 45620 | E17: Cải Kale Túi 150gr 24/11/2024 | F17: 4200 | G17: 4200 | H17: =C17*G17 -> 63000
A18: Cần Tây | B18: Cây | C18: 180 | D18: 45620 | E18: Cần Tây Cây 24/11/2024 | F18: 10000 | G18: 10000 | H18: =C18*G18 -> 1800000
A19: Củ Cải Đỏ | B19: Hộp | C19: 17 | D19: 45620 | E19: Củ Cải Đỏ Hộp 24/11/2024 | F19: =VLOOKUP(E19,'[2]SỔ CHI TIẾT MUA HÀNG'!$I:$K,3,0) -> 11000 | G19: 11000 | H19: =C19*G19 -> 187000
A20: Củ Hành Tây | B20: KG | C20: 45 | D20: 45620 | E20: Củ Hành Tây KG 24/11/2024 | F20: 20000 | G20: 20000 | H20: =C20*G20 -> 900000
A21: Củ Khoai Lang Mật Size 46 | B21: KG | C21: 100 | D21: 45620 | E21: Củ Khoai Lang Mật Size 46 KG 24/11/2024 | F21: 26000 | G21: 26000 | H21: =C21*G21 -> 2600000
A22: Củ Khoai Lang Nhật | B22: KG | C22: 100 | D22: 45620 | E22: Củ Khoai Lang Nhật KG 24/11/2024 | F22: =VLOOKUP(E22,'[2]SỔ CHI TIẾT MUA HÀNG'!$I:$K,3,0) -> 17000 | G22: 17000 | H22: =C22*G22 -> 1700000
A23: Củ Khoai Mỡ | B23: KG | C23: 20 | D23: 45620 | E23: Củ Khoai Mỡ KG 24/11/2024 | F23: =VLOOKUP(E23,'[2]SỔ CHI TIẾT MUA HÀNG'!$I:$K,3,0) -> 30000 | G23: 30000 | H23: =C23*G23 -> 600000
A24: Củ Khoai Tây Vàng | B24: KG | C24: 30 | D24: 45620 | E24: Củ Khoai Tây Vàng KG 24/11/2024 | F24: =VLOOKUP(E24,'[2]SỔ CHI TIẾT MUA HÀNG'!$I:$K,3,0) -> 15000 | G24: 15000 | H24: =C24*G24 -> 450000
A25: Dưa Leo Baby | B25: Vỉ | C25: 700 | D25: 45620 | E25: Dưa Leo Baby Vỉ 24/11/2024 | F25: =VLOOKUP(E25,'[2]SỔ CHI TIẾT MUA HÀNG'!$I:$K,3,0) -> 6000 | G25: 6000 | H25: =C25*G25 -> 4200000
A26: Dưa Leo Nhật | B26: Túi | C26: 30 | D26: 45620 | E26: Dưa Leo Nhật Túi 24/11/2024 | F26: 6000 | G26: 6000 | H26: =C26*G26 -> 180000
A27: Dưa Leo Thường | B27: KG | C27: 40 | D27: 45620 | E27: Dưa Leo Thường KG 24/11/2024 | F27: =VLOOKUP(E27,'[2]SỔ CHI TIẾT MUA HÀNG'!$I:$K,3,0) -> 3000 | G27: 3000 | H27: =C27*G27 -> 120000
A28: Hành Paro | B28: Cây | C28: 100 | D28: 45620 | E28: Hành Paro Cây 24/11/2024 | F28: =33000/5 -> 6600 | G28: 6600 | H28: =C28*G28 -> 660000
A29: Lá É | B29: Gói | C29: 10 | D29: 45620 | E29: Lá É Gói 24/11/2024 | F29: 7800 | G29: 7800 | H29: =C29*G29 -> 78000
A30: Lá Mè | B30: KG | C30: 16 | D30: 45620 | E30: Lá Mè KG 24/11/2024 | F30: =VLOOKUP(E30,'[2]SỔ CHI TIẾT MUA HÀNG'!$I:$K,3,0) -> 36000 | G30: 36000 | H30: =C30*G30 -> 576000
A31: Lá Mè | B31: Túi | C31: 514 | D31: 45620 | E31: Lá Mè Túi 24/11/2024 | F31: 1900 | G31: 1900 | H31: =C31*G31 -> 976600
A32: Măng Tây | B32: KG | C32: 30 | D32: 45620 | E32: Măng Tây KG 24/11/2024 | F32: =VLOOKUP(E32,'[2]SỔ CHI TIẾT MUA HÀNG'!$I:$K,3,0) -> 62000 | G32: 62000 | H32: =C32*G32 -> 1860000
A33: Ớt Chuông Baby | B33: KG | C33: 40 | D33: 45620 | E33: Ớt Chuông Baby KG 24/11/2024 | F33: =VLOOKUP(E33,'[2]SỔ CHI TIẾT MUA HÀNG'!$I:$K,3,0) -> 44000 | G33: 44000 | H33: =C33*G33 -> 1760000
A34: Ớt Chuông Đỏ | B34: Trái 180gr | C34: 200 | D34: 45620 | E34: Ớt Chuông Đỏ Trái 180gr 24/11/2024 | F34: =35000/4 -> 8750 | G34: 8750 | H34: =C34*G34 -> 1750000
A35: Ớt Chuông Vàng | B35: Trái 180gr | C35: 200 | D35: 45620 | E35: Ớt Chuông Vàng Trái 180gr 24/11/2024 | F35: =18000/4 -> 4500 | G35: 4500 | H35: =C35*G35 -> 900000
A36: Ớt Chuông Xanh | B36: Trái 180gr | C36: 100 | D36: 45620 | E36: Ớt Chuông Xanh Trái 180gr 24/11/2024 | F36: =28000/4 -> 7000 | G36: 7000 | H36: =C36*G36 -> 700000
A37: Ớt Sweet Palemo | B37: KG | C37: 30 | D37: 45620 | E37: Ớt Sweet Palemo KG 24/11/2024 | F37: =VLOOKUP(E37,'[2]SỔ CHI TIẾT MUA HÀNG'!$I:$K,3,0) -> 55000 | G37: 55000 | H37: =C37*G37 -> 1650000
A38: Ớt Sweet Palemo | B38: Túi | C38: 150 | D38: 45620 | E38: Ớt Sweet Palemo Túi 24/11/2024 | F38: =VLOOKUP(E38,'[2]SỔ CHI TIẾT MUA HÀNG'!$I:$K,3,0) -> 20000 | G38: 20000 | H38: =C38*G38 -> 3000000
A39: Rau Ngò Rí | B39: KG | C39: 6 | D39: 45620 | E39: Rau Ngò Rí KG 24/11/2024 | F39: =VLOOKUP(E39,'[2]SỔ CHI TIẾT MUA HÀNG'!$I:$K,3,0) -> 35000 | G39: 35000 | H39: =C39*G39 -> 210000
A40: Xà Lách Lolo Tím | B40: Túi | C40: 20 | D40: 45620 | E40: Xà Lách Lolo Tím Túi 24/11/2024 | F40: =35000*0.3 -> 10500 | G40: 10500 | H40: =C40*G40 -> 210000
...

Sheet 2311
H1: =SUM(H2:H47) -> 42164950
A2: Bắp Cải Trái Tim | B2: KG | C2: 25 | D2: 45619 | E2: Bắp Cải Trái Tim KG 23/11/2024 | F2: 12000 | G2: 12000 | H2: =C2*G2 -> 300000
A3: Bí Đao Xanh | B3: Trái | C3: 30 | D3: 45619 | E3: Bí Đao Xanh Trái 23/11/2024 | F3: 4000 | G3: 4000 | H3: =C3*G3 -> 120000
A4: Bí Ngòi Xanh | B4: Trái 280gr | C4: 250 | D4: 45619 | E4: Bí Ngòi Xanh Trái 280gr 23/11/2024 | F4: 3000 | G4: 3000 | H4: =C4*G4 -> 750000
A5: Bí Non Nhật | B5: Trái | C5: 150 | D5: 45619 | E5: Bí Non Nhật Trái 23/11/2024 | F5: 3000 | G5: 3000 | H5: =C5*G5 -> 450000
A6: Bông Cải Xanh Baby | B6: Vỉ | C6: 50 | D6: 45619 | E6: Bông Cải Xanh Baby Vỉ 23/11/2024 | F6: 11200 | G6: 11200 | H6: =C6*G6 -> 560000
A7: Cà Chua Beef | B7: KG | C7: 150 | D7: 45619 | E7: Cà Chua Beef KG 23/11/2024 | F7: =VLOOKUP(E7,'[2]SỔ CHI TIẾT MUA HÀNG'!$I:$K,3,0) -> 18000 | G7: 18000 | H7: =C7*G7 -> 2700000
A8: Cà Chua Beef Trung | B8: Vỉ 500gr | C8: 100 | D8: 45619 | E8: Cà Chua Beef Trung Vỉ 500gr 23/11/2024 | F8: =16500/2 -> 8250 | G8: 8250 | H8: =C8*G8 -> 825000
A9: Cà Chua Bi Mix | B9: Hộp | C9: 55 | D9: 45619 | E9: Cà Chua Bi Mix Hộp 23/11/2024 | F9: 12450 | G9: 12450 | H9: =C9*G9 -> 684750
A10: Cà Chua Socola | B10: Hộp 300gr | C10: 100 | D10: 45619 | E10: Cà Chua Socola Hộp 300gr 23/11/2024 | F10: 11550 | G10: 11550 | H10: =C10*G10 -> 1155000
A11: Cà Chua Thường | B11: KG | C11: 100 | D11: 45619 | E11: Cà Chua Thường KG 23/11/2024 | F11: 17000 | G11: 17000 | H11: =C11*G11 -> 1700000
A12: Cà Rốt | B12: KG | C12: 100 | D12: 45619 | E12: Cà Rốt KG 23/11/2024 | F12: =VLOOKUP(E12,'[2]SỔ CHI TIẾT MUA HÀNG'!$I:$K,3,0) -> 14000 | G12: 14000 | H12: =C12*G12 -> 1400000
A13: Cà Rốt Baby | B13: Vỉ | C13: 60 | D13: 45619 | E13: Cà Rốt Baby Vỉ 23/11/2024 | F13: 9600 | G13: 9600 | H13: =C13*G13 -> 576000
A14: Cải Bó Xôi | B14: KG | C14: 60 | D14: 45619 | E14: Cải Bó Xôi KG 23/11/2024 | F14: =VLOOKUP(E14,'[2]SỔ CHI TIẾT MUA HÀNG'!$I:$K,3,0) -> 20000 | G14: 20000 | H14: =C14*G14 -> 1200000
A15: Cải Kale | B15: Túi | C15: 123 | D15: 45619 | E15: Cải Kale Túi 23/11/2024 | F15: =28000*0.3 -> 8400 | G15: 8400 | H15: =C15*G15 -> 1033200
A16: Cải Kale | B16: Túi 150gr | C16: 10 | D16: 45619 | E16: Cải Kale Túi 150gr 23/11/2024 | F16: =F15/2 -> 4200 | G16: 4200 | H16: =C16*G16 -> 42000
A17: Cần Tây | B17: Cây | C17: 100 | D17: 45619 | E17: Cần Tây Cây 23/11/2024 | F17: 10000 | G17: 10000 | H17: =C17*G17 -> 1000000
A18: Chanh Không Hạt | B18: Vỉ | C18: 30 | D18: 45619 | E18: Chanh Không Hạt Vỉ 23/11/2024 | F18: 6500 | G18: 6500 | H18: =C18*G18 -> 195000
A19: Củ Cải Trắng | B19: KG | C19: 20 | D19: 45619 | E19: Củ Cải Trắng KG 23/11/2024 | F19: =VLOOKUP(E19,'[2]SỔ CHI TIẾT MUA HÀNG'!$I:$K,3,0) -> 5000 | G19: 5000 | H19: =C19*G19 -> 100000
A20: Củ Dền | B20: KG | C20: 20 | D20: 45619 | E20: Củ Dền KG 23/11/2024 | F20: =VLOOKUP(E20,'[2]SỔ CHI TIẾT MUA HÀNG'!$I:$K,3,0) -> 18000 | G20: 18000 | H20: =C20*G20 -> 360000
A21: Củ Hành Tây | B21: KG | C21: 50 | D21: 45619 | E21: Củ Hành Tây KG 23/11/2024 | F21: =VLOOKUP(E21,'[2]SỔ CHI TIẾT MUA HÀNG'!$I:$K,3,0) -> 28000 | G21: 28000 | H21: =C21*G21 -> 1400000
A22: Củ Khoai Lang Mật Size 46 | B22: KG | C22: 80 | D22: 45619 | E22: Củ Khoai Lang Mật Size 46 KG 23/11/2024 | F22: 23000 | G22: 23000 | H22: =C22*G22 -> 1840000
A23: Củ Khoai Lang Nhật | B23: KG | C23: 80 | D23: 45619 | E23: Củ Khoai Lang Nhật KG 23/11/2024 | F23: =VLOOKUP(E23,'[2]SỔ CHI TIẾT MUA HÀNG'!$I:$K,3,0) -> 17000 | G23: 17000 | H23: =C23*G23 -> 1360000
A24: Củ Khoai Tây Vàng | B24: KG | C24: 40 | D24: 45619 | E24: Củ Khoai Tây Vàng KG 23/11/2024 | F24: =VLOOKUP(E24,'[2]SỔ CHI TIẾT MUA HÀNG'!$I:$K,3,0) -> 15000 | G24: 15000 | H24: =C24*G24 -> 600000
A25: Đậu Cove Nhật | B25: Túi | C25: 15 | D25: 45619 | E25: Đậu Cove Nhật Túi 23/11/2024 | F25: =VLOOKUP(E25,'[2]SỔ CHI TIẾT MUA HÀNG'!$I:$K,3,0) -> 6000 | G25: 6000 | H25: =C25*G25 -> 90000
A26: Đậu Đỏ | B26: KG | C26: 3 | D26: 45619 | E26: Đậu Đỏ KG 23/11/2024 | F26: =VLOOKUP(E26,'[2]SỔ CHI TIẾT MUA HÀNG'!$I:$K,3,0) -> 80000 | G26: 80000 | H26: =C26*G26 -> 240000
A27: Dưa Leo Baby | B27: Vỉ | C27: 450 | D27: 45619 | E27: Dưa Leo Baby Vỉ 23/11/2024 | F27: =VLOOKUP(E27,'[2]SỔ CHI TIẾT MUA HÀNG'!$I:$K,3,0) -> 6000 | G27: 6000 | H27: =C27*G27 -> 2700000
A28: Dưa Leo Nhật | B28: Túi | C28: 20 | D28: 45619 | E28: Dưa Leo Nhật Túi 23/11/2024 | F28: 6000 | G28: 6000 | H28: =C28*G28 -> 120000
A29: Hành Paro | B29: KG | C29: 20 | D29: 45619 | E29: Hành Paro KG 23/11/2024 | F29: =VLOOKUP(E29,'[2]SỔ CHI TIẾT MUA HÀNG'!$I:$K,3,0) -> 30000 | G29: 30000 | H29: =C29*G29 -> 600000
A30: Hành Paro | B30: Cây | C30: 100 | D30: 45619 | E30: Hành Paro Cây 23/11/2024 | F30: 6600 | G30: 6600 | H30: =C30*G30 -> 660000
A31: Hồng Treo Gió | B31: Hộp | C31: 20 | D31: 45619 | E31: Hồng Treo Gió Hộp 23/11/2024 | F31: 100000 | G31: 100000 | H31: =C31*G31 -> 2000000
A32: Lá É | B32: Gói | C32: 25 | D32: 45619 | E32: Lá É Gói 23/11/2024 | F32: =26000*0.3 -> 7800 | G32: 7800 | H32: =C32*G32 -> 195000
A33: Lá Mè | B33: Túi | C33: 300 | D33: 45619 | E33: Lá Mè Túi 23/11/2024 | F33: 1900 | G33: 1900 | H33: =C33*G33 -> 570000
A34: Măng Tây | B34: KG | C34: 35 | D34: 45619 | E34: Măng Tây KG 23/11/2024 | F34: =VLOOKUP(E34,'[2]SỔ CHI TIẾT MUA HÀNG'!$I:$K,3,0) -> 62000 | G34: 62000 | H34: =C34*G34 -> 2170000
A35: Ớt Chuông Baby | B35: KG | C35: 24 | D35: 45619 | E35: Ớt Chuông Baby KG 23/11/2024 | F35: =VLOOKUP(E35,'[2]SỔ CHI TIẾT MUA HÀNG'!$I:$K,3,0) -> 44000 | G35: 44000 | H35: =C35*G35 -> 1056000
A36: Ớt Chuông Đỏ | B36: Trái 180gr | C36: 150 | D36: 45619 | E36: Ớt Chuông Đỏ Trái 180gr 23/11/2024 | F36: =35000/4 -> 8750 | G36: 8750 | H36: =C36*G36 -> 1312500
A37: Ớt Chuông Vàng | B37: Trái 180gr | C37: 150 | D37: 45619 | E37: Ớt Chuông Vàng Trái 180gr 23/11/2024 | F37: =18000/4 -> 4500 | G37: 4500 | H37: =C37*G37 -> 675000
A38: Ớt Chuông Xanh | B38: Trái 180gr | C38: 60 | D38: 45619 | E38: Ớt Chuông Xanh Trái 180gr 23/11/2024 | F38: =28000/4 -> 7000 | G38: 7000 | H38: =C38*G38 -> 420000
A39: Ớt Sweet Palemo | B39: Túi | C39: 200 | D39: 45619 | E39: Ớt Sweet Palemo Túi 23/11/2024 | F39: =VLOOKUP(E39,'[2]SỔ CHI TIẾT MUA HÀNG'!$I:$K,3,0) -> 22000 | G39: 22000 | H39: =C39*G39 -> 4400000
A40: Rau Ngò Rí | B40: KG | C40: 8 | D40: 45619 | E40: Rau Ngò Rí KG 23/11/2024 | F40: =VLOOKUP(E40,'[2]SỔ CHI TIẾT MUA HÀNG'!$I:$K,3,0) -> 35000 | G40: 35000 | H40: =C40*G40 -> 280000
...

Sheet 2211
H1: =SUM(H2:H50) -> 44752500
A2: Bí Đao Xanh | B2: Trái | C2: 20 | D2: 45618 | E2: Bí Đao Xanh Trái 22/11/2024 | F2: 4000 | G2: 4000 | H2: =C2*G2 -> 80000
A3: Bí Đỏ Tròn | B3: KG | C3: 30 | D3: 45618 | E3: Bí Đỏ Tròn KG 22/11/2024 | F3: 5000 | G3: 5000 | H3: =C3*G3 -> 150000
A4: Bí Ngòi Xanh | B4: KG | C4: 30 | D4: 45618 | E4: Bí Ngòi Xanh KG 22/11/2024 | F4: =VLOOKUP(E4,'[2]SỔ CHI TIẾT MUA HÀNG'!$I:$K,3,0) -> 11000 | G4: 11000 | H4: =C4*G4 -> 330000
A5: Bí Ngòi Xanh | B5: Trái 280gr | C5: 200 | D5: 45618 | E5: Bí Ngòi Xanh Trái 280gr 22/11/2024 | F5: =11000*0.3 -> 3300 | G5: 3300 | H5: =C5*G5 -> 660000
A6: Bí Non Nhật | B6: Trái | C6: 140 | D6: 45618 | E6: Bí Non Nhật Trái 22/11/2024 | F6: 3000 | G6: 3000 | H6: =C6*G6 -> 420000
A7: Bơ Booth | B7: KG | C7: 20 | D7: 45618 | E7: Bơ Booth KG 22/11/2024 | F7: =VLOOKUP(E7,'[2]SỔ CHI TIẾT MUA HÀNG'!$I:$K,3,0) -> 39000 | G7: 39000 | H7: =C7*G7 -> 780000
A8: Bông Cải Xanh Baby | B8: Vỉ | C8: 10 | D8: 45618 | E8: Bông Cải Xanh Baby Vỉ 22/11/2024 | F8: 11200 | G8: 11200 | H8: =C8*G8 -> 112000
A9: Cà Chua Beef | B9: KG | C9: 200 | D9: 45618 | E9: Cà Chua Beef KG 22/11/2024 | F9: =VLOOKUP(E9,'[2]SỔ CHI TIẾT MUA HÀNG'!$I:$K,3,0) -> 18000 | G9: 18000 | H9: =C9*G9 -> 3600000
A10: Cà Chua Beef Trung | B10: Vỉ 500gr | C10: 200 | D10: 45618 | E10: Cà Chua Beef Trung Vỉ 500gr 22/11/2024 | F10: =17000/2 -> 8500 | G10: 8500 | H10: =C10*G10 -> 1700000
A11: Cà Chua Bi Mix | B11: Hộp | C11: 60 | D11: 45618 | E11: Cà Chua Bi Mix Hộp 22/11/2024 | F11: ='2111'!H12 -> 17000 | G11: 17000 | H11: =C11*G11 -> 1020000
A12: Cà Chua Socola | B12: Hộp 300gr | C12: 50 | D12: 45618 | E12: Cà Chua Socola Hộp 300gr 22/11/2024 | F12: 12450 | G12: 12450 | H12: =C12*G12 -> 622500
A13: Cà Chua Thường | B13: KG | C13: 140 | D13: 45618 | E13: Cà Chua Thường KG 22/11/2024 | F13: =VLOOKUP(E13,'[2]SỔ CHI TIẾT MUA HÀNG'!$I:$K,3,0) -> 17000 | G13: 17000 | H13: =C13*G13 -> 2380000
A14: Cà Rốt | B14: KG | C14: 40 | D14: 45618 | E14: Cà Rốt KG 22/11/2024 | F14: =VLOOKUP(E14,'[2]SỔ CHI TIẾT MUA HÀNG'!$I:$K,3,0) -> 14000 | G14: 14000 | H14: =C14*G14 -> 560000
A15: Cà Rốt Baby | B15: Vỉ | C15: 80 | D15: 45618 | E15: Cà Rốt Baby Vỉ 22/11/2024 | F15: 9600 | G15: 9600 | H15: =C15*G15 -> 768000
A16: Cải Kale | B16: Túi | C16: 100 | D16: 45618 | E16: Cải Kale Túi 22/11/2024 | F16: =28000*0.3 -> 8400 | G16: 8400 | H16: =C16*G16 -> 840000
A17: Cần Tây | B17: Cây | C17: 100 | D17: 45618 | E17: Cần Tây Cây 22/11/2024 | F17: 10000 | G17: 10000 | H17: =C17*G17 -> 1000000
A18: Chanh Không Hạt | B18: Vỉ | C18: 50 | D18: 45618 | E18: Chanh Không Hạt Vỉ 22/11/2024 | F18: =VLOOKUP(A18,'2111'!A:I,8,0) -> 6500 | G18: 6500 | H18: =C18*G18 -> 325000
A19: Củ Cải Trắng | B19: KG | C19: 20 | D19: 45618 | E19: Củ Cải Trắng KG 22/11/2024 | F19: =VLOOKUP(E19,'[2]SỔ CHI TIẾT MUA HÀNG'!$I:$K,3,0) -> 6000 | G19: 6000 | H19: =C19*G19 -> 120000
A20: Củ Dền | B20: KG | C20: 20 | D20: 45618 | E20: Củ Dền KG 22/11/2024 | F20: =VLOOKUP(E20,'[2]SỔ CHI TIẾT MUA HÀNG'!$I:$K,3,0) -> 18000 | G20: 18000 | H20: =C20*G20 -> 360000
A21: Củ Hành Tây | B21: KG | C21: 60 | D21: 45618 | E21: Củ Hành Tây KG 22/11/2024 | F21: 20000 | G21: 20000 | H21: =C21*G21 -> 1200000
A22: Củ Khoai Lang Mật Size 46 | B22: KG | C22: 140 | D22: 45618 | E22: Củ Khoai Lang Mật Size 46 KG 22/11/2024 | F22: =VLOOKUP(A22,'2111'!A:I,8,0) -> 26000 | G22: 26000 | H22: =C22*G22 -> 3640000
A23: Củ Khoai Lang Nhật | B23: KG | C23: 120 | D23: 45618 | E23: Củ Khoai Lang Nhật KG 22/11/2024 | F23: =VLOOKUP(E23,'[2]SỔ CHI TIẾT MUA HÀNG'!$I:$K,3,0) -> 17000 | G23: 17000 | H23: =C23*G23 -> 2040000
A24: Củ Khoai Mỡ | B24: KG | C24: 10 | D24: 45618 | E24: Củ Khoai Mỡ KG 22/11/2024 | F24: =VLOOKUP(E24,'[2]SỔ CHI TIẾT MUA HÀNG'!$I:$K,3,0) -> 25000 | G24: 25000 | H24: =C24*G24 -> 250000
A25: Củ Khoai Tây Vàng | B25: KG | C25: 40 | D25: 45618 | E25: Củ Khoai Tây Vàng KG 22/11/2024 | F25: =VLOOKUP(E25,'[2]SỔ CHI TIẾT MUA HÀNG'!$I:$K,3,0) -> 15000 | G25: 15000 | H25: =C25*G25 -> 600000
A26: Đậu Cove Nhật | B26: Túi | C26: 15 | D26: 45618 | E26: Đậu Cove Nhật Túi 22/11/2024 | F26: =VLOOKUP(E26,'[2]SỔ CHI TIẾT MUA HÀNG'!$I:$K,3,0) -> 6000 | G26: 6000 | H26: =C26*G26 -> 90000
A27: Đậu Cove Trắng | B27: Túi 300gr | C27: 20 | D27: 45618 | E27: Đậu Cove Trắng Túi 300gr 22/11/2024 | F27: =VLOOKUP(E27,'[2]SỔ CHI TIẾT MUA HÀNG'!$I:$K,3,0) -> 8000 | G27: 8000 | H27: =C27*G27 -> 160000
A28: Dưa Leo Baby | B28: Vỉ | C28: 500 | D28: 45618 | E28: Dưa Leo Baby Vỉ 22/11/2024 | F28: =VLOOKUP(A28,'2111'!A:I,8,0) -> 5000 | G28: 5000 | H28: =C28*G28 -> 2500000
A29: Dưa Leo Thường | B29: KG | C29: 20 | D29: 45618 | E29: Dưa Leo Thường KG 22/11/2024 | F29: =VLOOKUP(E29,'[2]SỔ CHI TIẾT MUA HÀNG'!$I:$K,3,0) -> 3000 | G29: 3000 | H29: =C29*G29 -> 60000
A30: Hành Paro | B30: KG | C30: 15 | D30: 45618 | E30: Hành Paro KG 22/11/2024 | F30: =VLOOKUP(A30,'2111'!A:I,8,0) -> 33000 | G30: 33000 | H30: =C30*G30 -> 495000
A31: Hành Paro | B31: Cây | C31: 80 | D31: 45618 | E31: Hành Paro Cây 22/11/2024 | F31: =F30/5 -> 6600 | G31: 6600 | H31: =C31*G31 -> 528000
A32: Hồng Treo Gió | B32: Hộp | C32: 15 | D32: 45618 | E32: Hồng Treo Gió Hộp 22/11/2024 | F32: =VLOOKUP(A32,'2111'!A:I,8,0) -> 100000 | G32: 100000 | H32: =C32*G32 -> 1500000
A33: Lá É | B33: Gói | C33: 30 | D33: 45618 | E33: Lá É Gói 22/11/2024 | F33: =VLOOKUP(A33,'2111'!A:I,8,0)*0.3 -> 7800 | G33: 7800 | H33: =C33*G33 -> 234000
A34: Lá Hương Thảo | B34: Túi | C34: 10 | D34: 45618 | E34: Lá Hương Thảo Túi 22/11/2024 | F34: =VLOOKUP(A34,'2111'!A:I,8,0)/20 -> 5000 | G34: 5000 | H34: =C34*G34 -> 50000
A35: Lá Nha Đam | B35: KG | C35: 10 | D35: 45618 | E35: Lá Nha Đam KG 22/11/2024 | F35: =VLOOKUP(E35,'[2]SỔ CHI TIẾT MUA HÀNG'!$I:$K,3,0) -> 14000 | G35: 14000 | H35: =C35*G35 -> 140000
A36: Măng Tây | B36: KG | C36: 20 | D36: 45618 | E36: Măng Tây KG 22/11/2024 | F36: =VLOOKUP(E36,'[2]SỔ CHI TIẾT MUA HÀNG'!$I:$K,3,0) -> 63000 | G36: 63000 | H36: =C36*G36 -> 1260000
A37: Ớt Chuông Baby | B37: KG | C37: 30 | D37: 45618 | E37: Ớt Chuông Baby KG 22/11/2024 | F37: =VLOOKUP(E37,'[2]SỔ CHI TIẾT MUA HÀNG'!$I:$K,3,0) -> 44000 | G37: 44000 | H37: =C37*G37 -> 1320000
A38: Ớt Chuông Đỏ | B38: Trái 180gr | C38: 200 | D38: 45618 | E38: Ớt Chuông Đỏ Trái 180gr 22/11/2024 | F38: =VLOOKUP(A38,'2111'!A:I,8,0)/4 -> 8750 | G38: 8750 | H38: =C38*G38 -> 1750000
A39: Ớt Chuông Vàng | B39: Trái 180gr | C39: 160 | D39: 45618 | E39: Ớt Chuông Vàng Trái 180gr 22/11/2024 | F39: =VLOOKUP(A39,'2111'!A:I,8,0)/4 -> 4500 | G39: 4500 | H39: =C39*G39 -> 720000
A40: Ớt Chuông Xanh | B40: Trái 180gr | C40: 80 | D40: 45618 | E40: Ớt Chuông Xanh Trái 180gr 22/11/2024 | F40: =VLOOKUP(A40,'2111'!A:I,8,0)/4 -> 7000 | G40: 7000 | H40: =C40*G40 -> 560000
...

Sheet 2111
I1: =SUM(I2:I48) -> 43308150
A2: Bắp Cải Trái Tim | B2: Bắp Cải Trái Tim 21/11/2024 | C2: KG | D2: 20 | E2: 45617 | F2: Bắp Cải Trái Tim KG 21/11/2024 | G2: 12000 | H2: 12000 | I2: =D2*H2 -> 240000
A3: Bí Đỏ Tròn | B3: Bí Đỏ Tròn 21/11/2024 | C3: KG | D3: 40 | E3: 45617 | F3: Bí Đỏ Tròn KG 21/11/2024 | G3: 5000 | H3: 5000 | I3: =D3*H3 -> 200000
A4: Bí Ngòi Xanh | B4: Bí Ngòi Xanh 21/11/2024 | C4: Trái 280gr | D4: 350 | E4: 45617 | F4: Bí Ngòi Xanh Trái 280gr 21/11/2024 | G4: =VLOOKUP(B4,[2]Sheet1!$K:$N,4,0) -> 3000 | H4: 3000 | I4: =D4*H4 -> 1050000
A5: Bí Non Nhật | B5: Bí Non Nhật 20/11/2024 | C5: Trái | D5: 136 | E5: 45617 | F5: Bí Non Nhật Trái 21/11/2024 | G5: =VLOOKUP(B5,[2]Sheet1!$K:$N,4,0) -> 3000 | H5: 3000 | I5: =D5*H5 -> 408000
A6: Bông Cải Xanh 7Cm | B6: Bông Cải Xanh 7Cm 21/11/2024 | C6: KG | D6: 20 | E6: 45617 | F6: Bông Cải Xanh 7Cm KG 21/11/2024 | G6: 30000 | H6: 30000 | I6: =D6*H6 -> 600000
A7: Bông Cải Xanh Baby | C7: KG | D7: 7 | E7: 45617 | F7: Bông Cải Xanh Baby KG 21/11/2024 | G7: =VLOOKUP(F7,'[2]SỔ CHI TIẾT MUA HÀNG'!$I:$K,3,0) -> 56000 | H7: 56000 | I7: =D7*H7 -> 392000
A8: Bông Cải Xanh Baby | B8: Bông Cải Xanh Baby 21/11/2024 | C8: Vỉ | D8: 12 | E8: 45617 | F8: Bông Cải Xanh Baby Vỉ 21/11/2024 | G8: =VLOOKUP(B8,[2]Sheet1!$K:$N,4,0) -> 11200 | H8: 11200 | I8: =D8*H8 -> 134400
A9: Cà Chua Beef | C9: KG | D9: 190 | E9: 45617 | F9: Cà Chua Beef KG 21/11/2024 | G9: =VLOOKUP(F9,'[2]SỔ CHI TIẾT MUA HÀNG'!$I:$K,3,0) -> 19000 | H9: 19000 | I9: =D9*H9 -> 3610000
A10: Cà Chua Bi Mix | B10: Cà Chua Bi Mix 21/11/2024 | C10: Hộp | D10: 65 | E10: 45617 | F10: Cà Chua Bi Mix Hộp 21/11/2024 | G10: ='1911'!F16 -> 15450 | H10: 15450 | I10: =D10*H10 -> 1004250
A11: Cà Chua Socola | B11: Cà Chua Socola Hộp 21/11/2024 | C11: Hộp 300gr | D11: 95 | E11: 45617 | F11: Cà Chua Socola Hộp 300gr 21/11/2024 | G11: 15000 | H11: 15000 | I11: =D11*H11 -> 1425000
A12: Cà Chua Thường | C12: KG | D12: 25 | E12: 45617 | F12: Cà Chua Thường KG 21/11/2024 | G12: =VLOOKUP(F12,'[2]SỔ CHI TIẾT MUA HÀNG'!$I:$K,3,0) -> 17000 | H12: 17000 | I12: =D12*H12 -> 425000
A13: Cà Rốt | C13: KG | D13: 24 | E13: 45617 | F13: Cà Rốt KG 21/11/2024 | G13: =VLOOKUP(F13,'[2]SỔ CHI TIẾT MUA HÀNG'!$I:$K,3,0) -> 15000 | H13: 15000 | I13: =D13*H13 -> 360000
A14: Cà Rốt Baby | B14: Cà Rốt Baby 21/11/2024 | C14: Vỉ | D14: 60 | E14: 45617 | F14: Cà Rốt Baby Vỉ 21/11/2024 | G14: =VLOOKUP(B14,[2]Sheet1!$K:$N,4,0) -> 9600 | H14: 9600 | I14: =D14*H14 -> 576000
A15: Cải Kale | B15: Cải Kale 21/11/2024 | C15: Túi | D15: 150 | E15: 45617 | F15: Cải Kale Túi 21/11/2024 | G15: =VLOOKUP(B15,[2]Sheet1!$K:$N,4,0) -> 8700 | H15: 8700 | I15: =D15*H15 -> 1305000
A16: Cải Kale | B16: Cải Kale Túi 21/11/2024 | C16: Túi 150gr | D16: 6 | E16: 45617 | F16: Cải Kale Túi 150gr 21/11/2024 | G16: =G15/2 -> 4350 | H16: 4350 | I16: =D16*H16 -> 26100
A17: Cần Tây | B17: Cần Tây 21/11/2024 | C17: Cây | D17: 200 | E17: 45617 | F17: Cần Tây Cây 21/11/2024 | G17: =VLOOKUP(B17,[2]Sheet1!$K:$N,4,0) -> 10000 | H17: 10000 | I17: =D17*H17 -> 2000000
A18: Chanh Không Hạt | B18: Chanh Không Hạt 21/11/2024 | C18: Vỉ | D18: 48 | E18: 45617 | F18: Chanh Không Hạt Vỉ 21/11/2024 | G18: =VLOOKUP(B18,[2]Sheet1!$K:$N,4,0) -> 6500 | H18: 6500 | I18: =D18*H18 -> 312000
A19: Củ Cải Trắng | C19: KG | D19: 15 | E19: 45617 | F19: Củ Cải Trắng KG 21/11/2024 | G19: =VLOOKUP(F19,'[2]SỔ CHI TIẾT MUA HÀNG'!$I:$K,3,0) -> 6000 | H19: 6000 | I19: =D19*H19 -> 90000
A20: Củ Hành Tây | B20: Củ Hành Tây 21/11/2024 | C20: KG | D20: 120 | E20: 45617 | F20: Củ Hành Tây KG 21/11/2024 | G20: 21000 | H20: 21000 | I20: =D20*H20 -> 2520000
A21: Củ Khoai Lang Mật Size 46 | B21: Củ Khoai Lang Mật Size 46 21/11/2024 | C21: KG | D21: 100 | E21: 45617 | F21: Củ Khoai Lang Mật Size 46 KG 21/11/2024 | G21: 26000 | H21: 26000 | I21: =D21*H21 -> 2600000
A22: Củ Khoai Lang Nhật | C22: KG | D22: 55 | E22: 45617 | F22: Củ Khoai Lang Nhật KG 21/11/2024 | G22: =VLOOKUP(F22,'[2]SỔ CHI TIẾT MUA HÀNG'!$I:$K,3,0) -> 17000 | H22: 17000 | I22: =D22*H22 -> 935000
A23: Dưa Leo Baby | B23: Dưa Leo Baby 21/11/2024 | C23: Vỉ | D23: 200 | E23: 45617 | F23: Dưa Leo Baby Vỉ 21/11/2024 | G23: 5000 | H23: 5000 | I23: =D23*H23 -> 1000000
A24: Dưa Leo Thường | B24: Dưa Leo Thường 21/11/2024 | C24: KG | D24: 60 | E24: 45617 | F24: Dưa Leo Thường KG 21/11/2024 | G24: 3000 | H24: 3000 | I24: =D24*H24 -> 180000
A25: Hành Paro | B25: Hành Paro 21/11/2024 | C25: KG | D25: 10 | E25: 45617 | F25: Hành Paro KG 21/11/2024 | G25: 33000 | H25: 33000 | I25: =D25*H25 -> 330000
A26: Hành Paro | B26: Hành Paro 21/11/2024 | C26: Cây | D26: 120 | E26: 45617 | F26: Hành Paro Cây 21/11/2024 | G26: =33000/5 -> 6600 | H26: 6600 | I26: =D26*H26 -> 792000
A27: Hồng Treo Gió | B27: Hồng Treo Gió 21/11/2024 | C27: Hộp | D27: 39 | E27: 45617 | F27: Hồng Treo Gió Hộp 21/11/2024 | G27: 100000 | H27: 100000 | I27: =D27*H27 -> 3900000
A28: Lá É | C28: KG | D28: 10 | E28: 45617 | F28: Lá É KG 21/11/2024 | G28: =VLOOKUP(F28,'[2]SỔ CHI TIẾT MUA HÀNG'!$I:$K,3,0) -> 26000 | H28: 26000 | I28: =D28*H28 -> 260000
A29: Lá Hương Thảo | C29: KG | D29: 1 | E29: 45617 | F29: Lá Hương Thảo KG 21/11/2024 | G29: =VLOOKUP(F29,'[2]SỔ CHI TIẾT MUA HÀNG'!$I:$K,3,0) -> 100000 | H29: 100000 | I29: =D29*H29 -> 100000
A30: Lá Mè | B30: Lá Mè 21/11/2024 | C30: Túi | D30: 290 | E30: 45617 | F30: Lá Mè Túi 21/11/2024 | G30: 2000 | H30: 2000 | I30: =D30*H30 -> 580000
A31: Lá Nha Đam | C31: KG | D31: 2 | E31: 45617 | F31: Lá Nha Đam KG 21/11/2024 | G31: =VLOOKUP(F31,'[2]SỔ CHI TIẾT MUA HÀNG'!$I:$K,3,0) -> 14000 | H31: 14000 | I31: =D31*H31 -> 28000
A32: Lá Tía Tô | B32: Lá Tía Tô 21/11/2024 | C32: KG | D32: 3 | E32: 45617 | F32: Lá Tía Tô KG 21/11/2024 | G32: 32000 | H32: 32000 | I32: =D32*H32 -> 96000
A33: Măng Tây | C33: KG | D33: 40 | E33: 45617 | F33: Măng Tây KG 21/11/2024 | G33: =VLOOKUP(F33,'[2]SỔ CHI TIẾT MUA HÀNG'!$I:$K,3,0) -> 62000 | H33: 62000 | I33: =D33*H33 -> 2480000
A34: Ớt Chuông Baby | B34: Ớt Chuông Baby 21/11/2024 | C34: KG | D34: 34 | E34: 45617 | F34: Ớt Chuông Baby KG 21/11/2024 | G34: 44000 | H34: 44000 | I34: =D34*H34 -> 1496000
A35: Ớt Chuông Đỏ | C35: KG | D35: 25 | E35: 45617 | F35: Ớt Chuông Đỏ KG 21/11/2024 | G35: =VLOOKUP(F35,'[2]SỔ CHI TIẾT MUA HÀNG'!$I:$K,3,0) -> 35000 | H35: 35000 | I35: =D35*H35 -> 875000
A36: Ớt Chuông Snack | C36: KG | D36: 13 | E36: 45617 | F36: Ớt Chuông Snack KG 21/11/2024 | G36: =VLOOKUP(F36,'[2]SỔ CHI TIẾT MUA HÀNG'!$I:$K,3,0) -> 49000 | H36: 49000 | I36: =D36*H36 -> 637000
A37: Ớt Chuông Vàng | C37: KG | D37: 40 | E37: 45617 | F37: Ớt Chuông Vàng KG 21/11/2024 | G37: =VLOOKUP(F37,'[2]SỔ CHI TIẾT MUA HÀNG'!$I:$K,3,0) -> 18000 | H37: 18000 | I37: =D37*H37 -> 720000
A38: Ớt Chuông Xanh | C38: KG | D38: 30 | E38: 45617 | F38: Ớt Chuông Xanh KG 21/11/2024 | G38: =VLOOKUP(F38,'[2]SỔ CHI TIẾT MUA HÀNG'!$I:$K,3,0) -> 28000 | H38: 28000 | I38: =D38*H38 -> 840000
A39: Ớt Sweet Palemo | B39: Ớt Sweet Palemo 21/11/2024 | C39: KG | D39: 20 | E39: 45617 | F39: Ớt Sweet Palemo KG 21/11/2024 | G39: 66000 | H39: 66000 | I39: =D39*H39 -> 1320000
A40: Ớt Sweet Palemo | B40: Ớt Sweet Palemo 21/11/2024 | C40: Túi | D40: 163 | E40: 45617 | F40: Ớt Sweet Palemo Túi 21/11/2024 | G40: 23000 | H40: 23000 | I40: =D40*H40 -> 3749000
...

Sheet 2011
A1: Tên hàng | B1: ĐVT | C1: Số lượng | D1: NGÀY NHẬP | H1: =SUM(H2:H53) -> 42153500
A2: Bắp Cải Tím | B2: KG | C2: 20 | D2: 45616 | E2: Bắp Cải Tím KG 20/11/2024 | F2: =VLOOKUP(E2,'[2]SỔ CHI TIẾT MUA HÀNG'!$I:$K,3,0) -> 30000 | G2: 30000 | H2: =C2*G2 -> 600000
A3: Bí Đao Xanh | B3: Trái | C3: 10 | D3: 45616 | E3: Bí Đao Xanh Trái 20/11/2024 | F3: 3000 | G3: 3000 | H3: =C3*G3 -> 30000
A4: Bí Đỏ Tròn | B4: KG | C4: 40 | D4: 45616 | E4: Bí Đỏ Tròn KG 20/11/2024 | F4: =VLOOKUP(E4,'[2]SỔ CHI TIẾT MUA HÀNG'!$I:$K,3,0) -> 5000 | G4: 5000 | H4: =C4*G4 -> 200000
A5: Bí Ngô Mini | B5: KG | C5: 10 | D5: 45616 | E5: Bí Ngô Mini KG 20/11/2024 | F5: =VLOOKUP(E5,'[2]SỔ CHI TIẾT MUA HÀNG'!$I:$K,3,0) -> 48000 | G5: 48000 | H5: =C5*G5 -> 480000
A6: Bí Ngòi Xanh | B6: Trái 280gr | C6: 260 | D6: 45616 | E6: Bí Ngòi Xanh Trái 280gr 20/11/2024 | F6: =VLOOKUP(A6,[2]Sheet1!$G:$N,7,0) -> 0.3 | G6: 3000 | H6: =C6*G6 -> 780000
A7: Bí Non Nhật | B7: KG | C7: 10 | D7: 45616 | E7: Bí Non Nhật KG 20/11/2024 | F7: =VLOOKUP(E7,'[2]SỔ CHI TIẾT MUA HÀNG'!$I:$K,3,0) -> 10000 | G7: 10000 | H7: =C7*G7 -> 100000
A8: Bí Non Nhật | B8: Trái | C8: 140 | D8: 45616 | E8: Bí Non Nhật Trái 20/11/2024 | F8: =VLOOKUP(A8,[2]Sheet1!$G:$N,7,0) -> 0.3 | G8: 3300 | H8: =C8*G8 -> 462000
A9: Bông Cải Xanh Baby | B9: Vỉ | C9: 39 | D9: 45616 | E9: Bông Cải Xanh Baby Vỉ 20/11/2024 | F9: =VLOOKUP(A9,[2]Sheet1!$G:$N,7,0) -> 0.2 | G9: 11400 | H9: =C9*G9 -> 444600
A10: Cà Chua Beef | B10: KG | C10: 140 | D10: 45616 | E10: Cà Chua Beef KG 20/11/2024 | F10: =VLOOKUP(E10,'[2]SỔ CHI TIẾT MUA HÀNG'!$I:$K,3,0) -> 20000 | G10: 20000 | H10: =C10*G10 -> 2800000
A11: Cà Chua Beef Trung | B11: Vỉ 500gr | C11: 100 | D11: 45616 | E11: Cà Chua Beef Trung Vỉ 500gr 20/11/2024 | F11: =VLOOKUP(A11,[2]Sheet1!$G:$N,7,0) -> 0.5 | G11: 9500 | H11: =C11*G11 -> 950000
A12: Cà Chua Bi Đỏ | B12: Hộp 300gr | C12: 90 | D12: 45616 | E12: Cà Chua Bi Đỏ Hộp 300gr 20/11/2024 | F12: =VLOOKUP(E12,'[2]SỔ CHI TIẾT MUA HÀNG'!$I:$K,3,0) -> 10500 | G12: 10500 | H12: =C12*G12 -> 945000
A13: Cà Chua Socola | B13: Hộp 300gr | C13: 120 | D13: 45616 | E13: Cà Chua Socola Hộp 300gr 20/11/2024 | F13: =51500*0.3 -> 15450 | G13: 15450 | H13: =C13*G13 -> 1854000
A14: Cà Chua Thường | B14: KG | C14: 40 | D14: 45616 | E14: Cà Chua Thường KG 20/11/2024 | F14: =VLOOKUP(E14,'[2]SỔ CHI TIẾT MUA HÀNG'!$I:$K,3,0) -> 14000 | G14: 14000 | H14: =C14*G14 -> 560000
A15: Cà Rốt Baby | B15: Vỉ | C15: 65 | D15: 45616 | E15: Cà Rốt Baby Vỉ 20/11/2024 | F15: =52000/5 -> 10400 | G15: 10400 | H15: =C15*G15 -> 676000
A16: Cải Bó Xôi | B16: KG | C16: 40 | D16: 45616 | E16: Cải Bó Xôi KG 20/11/2024 | F16: =VLOOKUP(E16,'[2]SỔ CHI TIẾT MUA HÀNG'!$I:$K,3,0) -> 25000 | G16: 25000 | H16: =C16*G16 -> 1000000
A17: Cải Kale | B17: Túi | C17: 40 | D17: 45616 | E17: Cải Kale Túi 20/11/2024 | F17: =VLOOKUP(A17,[2]Sheet1!$G:$N,7,0) -> 0.3 | G17: 9150 | H17: =C17*G17 -> 366000
A18: Cải Kale | B18: Túi 150gr | C18: 10 | D18: 45616 | E18: Cải Kale Túi 150gr 20/11/2024 | F18: =VLOOKUP(A18,[2]Sheet1!$G:$N,7,0) -> 0.3 | G18: 9150 | H18: =C18*G18 -> 91500
A19: Cải Thảo | B19: KG | C19: 30 | D19: 45616 | E19: Cải Thảo KG 20/11/2024 | F19: 7000 | G19: 7000 | H19: =C19*G19 -> 210000
A20: Cần Tây | B20: Cây | C20: 200 | D20: 45616 | E20: Cần Tây Cây 20/11/2024 | F20: =VLOOKUP(A20,[2]Sheet1!$G:$N,7,0) -> 0.5 | G20: 8500 | H20: =C20*G20 -> 1700000
A21: Chanh Không Hạt | B21: Vỉ | C21: 40 | D21: 45616 | E21: Chanh Không Hạt Vỉ 20/11/2024 | F21: =VLOOKUP(A21,[2]Sheet1!$G:$N,7,0) -> 0.25 | G21: 6500 | H21: =C21*G21 -> 260000
A22: Củ Cải Đỏ | B22: Hộp | C22: 30 | D22: 45616 | E22: Củ Cải Đỏ Hộp 20/11/2024 | F22: =VLOOKUP(E22,'[2]SỔ CHI TIẾT MUA HÀNG'!$I:$K,3,0) -> 14000 | G22: 14000 | H22: =C22*G22 -> 420000
