Workbook

Sheet 1.1
A1: hàng tồn cuối ngày 1/1 vr
A2: Tên Sản phẩm | B2: ĐVT | C2: tồn | D2: giá | E2: thành tiền
A3: Bắp Cải Tím | B3: Kg | C3: 0 | E3: =C3*D3 -> 0
A4: Bắp Cải Trái Tim | B4: Kg | C4: 310 | D4: 7500 | E4: =C4*D4 -> 2325000
A5: Bắp Cải Trắng | B5: Kg | C5: 462 | D5: 5500 | E5: =C5*D5 -> 2541000
A6: Bí Đỏ Hồ Lô | B6: Kg | C6: 3 | D6: 11500 | E6: =C6*D6 -> 34500
A7: Bí Đỏ Tròn | B7: Kg | C7: 108 | D7: 11000 | E7: =C7*D7 -> 1188000
A8: Bí Ngòi Xanh | B8: Kg | C8: 465 | D8: 10000 | E8: =C8*D8 -> 4650000
A9: Bí Ngòi Xanh | B9: Trái | C9: 0 | E9: =C9*D9 -> 0
A10: Bí Non Nhật | B10: Kg | C10: 0 | E10: =C10*D10 -> 0
A11: Bí Non Nhật | B11: Trái | C11: 0 | E11: =C11*D11 -> 0
A12: Bơ Booth | B12: Kg | C12: 0 | E12: =C12*D12 -> 0
A13: Bông Cải Trắng | B13: Kg | C13: 12 | D13: 15000 | E13: =C13*D13 -> 180000
A14: Bông Cải Xanh 10Cm | B14: Kg | C14: 24 | D14: 20000 | E14: =C14*D14 -> 480000
A15: Bông Cải Xanh 12Cm | B15: Kg | C15: 0 | E15: =C15*D15 -> 0
A16: Bông Cải Xanh 7Cm | B16: Kg | C16: 34 | D16: 33000 | E16: =C16*D16 -> 1122000
A17: Bông Cải Xanh Baby | B17: Vỉ | C17: 22 | D17: 8000 | E17: =C17*D17 -> 176000
A18: Cà Chua Beef | B18: Kg | C18: 85 | D18: 15000 | E18: =C18*D18 -> 1275000
A19: Cà Chua Beef | B19: Vỉ | C19: 0 | E19: =C19*D19 -> 0
A20: Cà Chua Beef | B20: Vỉ 650gr | C20: 0 | E20: =C20*D20 -> 0
A21: Cà Chua Beef Trung | B21: Kg | C21: 13 | D21: 14000 | E21: =C21*D21 -> 182000
A22: Cà Chua Beef Trung | B22: Vỉ 500gr | C22: 95 | D22: 7000 | E22: =C22*D22 -> 665000
A23: Cà Chua Bi Đỏ | B23: Kg | C23: 5 | D23: 24000 | E23: =C23*D23 -> 120000
A24: Cà Chua Bi Đỏ | B24: Hộp 300gr | C24: 73 | D24: 7200 | E24: =C24*D24 -> 525600
A25: Cà Chua Bi Mix | B25: Hộp | C25: 5 | D25: 12000 | E25: =C25*D25 -> 60000
A26: Cà Chua Socola | B26: Kg | C26: 5 | D26: 28000 | E26: =C26*D26 -> 140000
A27: Cà Chua Socola | B27: Hộp 250GR | C27: 370 | D27: 9000 | E27: =C27*D27 -> 3330000
A28: Cà Chua Thường | B28: Kg | C28: 532 | D28: 16000 | E28: =C28*D28 -> 8512000
A29: Cà Chua Thường | B29: Vỉ | C29: 0 | E29: =C29*D29 -> 0
A30: Cà Chua Thường Trung | B30: Túi | C30: 140 | D30: 14000 | E30: =C30*D30 -> 1960000
A31: Cà Rốt | B31: Kg | C31: 67 | D31: 11000 | E31: =C31*D31 -> 737000
A32: Cà Rốt | B32: Túi | C32: 0 | E32: =C32*D32 -> 0
A33: Cà Rốt Baby | B33: Vỉ | C33: 7 | D33: 10000 | E33: =C33*D33 -> 70000
A34: Cà Tím | B34: Kg | C34: 69 | D34: 8000 | E34: =C34*D34 -> 552000
A35: Cà Tím | B35: Cặp | C35: 0 | E35: =C35*D35 -> 0
A36: Cải Bó Xôi | B36: Kg | C36: 20 | D36: 28000 | E36: =C36*D36 -> 560000
A37: Cải Bó Xôi | B37: Túi | C37: 0 | E37: =C37*D37 -> 0
A38: Cải Cầu Vồng | B38: Túi | C38: 11 | D38: 5000 | E38: =C38*D38 -> 55000
A39: Cải Kale | B39: Túi | C39: 12 | D39: 4000 | E39: =C39*D39 -> 48000
A40: Cải Thảo | B40: Kg | C40: 717 | D40: 7500 | E40: =C40*D40 -> 5377500
...

Sheet 2.1
A1: hàng tồn cuối ngày 2.1 vr
A2: Tên Sản phẩm | B2: ĐVT | C2: tồn | D2: giá | E2: thành tiền
A3: Bắp Cải Tím | B3: Kg | C3: 14 | D3: 17000 | E3: =C3*D3 -> 238000
A4: Bắp Cải Trái Tim | B4: Kg | C4: 213 | D4: 7500 | E4: =C4*D4 -> 1597500
A5: Bắp Cải Trắng | B5: Kg | C5: 84 | D5: 5500 | E5: =C5*D5 -> 462000
A6: Bí Đỏ Hồ Lô | B6: Kg | C6: 3 | D6: 11500 | E6: =C6*D6 -> 34500
A7: Bí Đỏ Tròn | B7: Kg | C7: 130 | D7: 10000 | E7: =C7*D7 -> 1300000
A8: Bí Ngòi Vàng | B8: Kg | C8: 0 | E8: =C8*D8 -> 0
A9: Bí Ngòi Xanh | B9: Kg | C9: 120 | D9: 10000 | E9: =C9*D9 -> 1200000
A10: Bí Ngòi Xanh | B10: Trái | C10: 0 | E10: =C10*D10 -> 0
A11: Bí Non Nhật | B11: Kg | C11: 60 | D11: 19000 | E11: =C11*D11 -> 1140000
A12: Bí Non Nhật | B12: Trái | C12: 0 | E12: =C12*D12 -> 0
A13: Bơ Booth | B13: Kg | C13: 0 | E13: =C13*D13 -> 0
A14: Bông Cải Trắng | B14: Kg | C14: 20 | D14: 16000 | E14: =C14*D14 -> 320000
A15: Bông Cải Xanh 10Cm | B15: Kg | C15: 27 | D15: 20000 | E15: =C15*D15 -> 540000
A16: Bông Cải Xanh 12Cm | B16: Kg | C16: 0 | E16: =C16*D16 -> 0
A17: Bông Cải Xanh 7Cm | B17: Kg | C17: 0 | E17: =C17*D17 -> 0
A18: Bông Cải Xanh Baby | B18: Vỉ | C18: 0 | E18: =C18*D18 -> 0
A19: Cà Chua Beef | B19: Kg | C19: 697 | D19: 15000 | E19: =C19*D19 -> 10455000
A20: Cà Chua Beef | B20: Vỉ | C20: 0 | E20: =C20*D20 -> 0
A21: Cà Chua Beef | B21: Vỉ 650gr | C21: 0 | E21: =C21*D21 -> 0
A22: Cà Chua Beef Trung | B22: Kg | C22: 0 | E22: =C22*D22 -> 0
A23: Cà Chua Beef Trung | B23: Vỉ 500gr | C23: 50 | D23: 7000 | E23: =C23*D23 -> 350000
A24: Cà Chua Bi Đỏ | B24: Kg | C24: 6 | D24: 24000 | E24: =C24*D24 -> 144000
A25: Cà Chua Bi Đỏ | B25: Hộp 300gr | C25: 83 | D25: 7200 | E25: =C25*D25 -> 597600
A26: Cà Chua Bi Mix | B26: Hộp | C26: 5 | D26: 12000 | E26: =C26*D26 -> 60000
A27: Cà Chua Socola | B27: Kg | C27: 0 | E27: =C27*D27 -> 0
A28: Cà Chua Socola | B28: Hộp 250GR | C28: 310 | D28: 9000 | E28: =C28*D28 -> 2790000
A29: Cà Chua Thường | B29: Kg | C29: 212 | D29: 18000 | E29: =C29*D29 -> 3816000
A30: Cà Chua Thường | B30: Vỉ | C30: 0 | E30: =C30*D30 -> 0
A31: Cà Chua Thường Trung | B31: Túi | C31: 110 | D31: 14000 | E31: =C31*D31 -> 1540000
A32: Cà Rốt | B32: Kg | C32: 118 | D32: 11500 | E32: =C32*D32 -> 1357000
A33: Cà Rốt | B33: Túi | C33: 0 | E33: =C33*D33 -> 0
A34: Cà Rốt Baby | B34: Kg | C34: 0 | E34: =C34*D34 -> 0
A35: Cà Rốt Baby | B35: Vỉ | C35: 7 | D35: 9500 | E35: =C35*D35 -> 66500
A36: Cà Tím | B36: Kg | C36: 0 | E36: =C36*D36 -> 0
A37: Cà Tím | B37: Cặp | C37: 0 | E37: =C37*D37 -> 0
A38: Cải Bó Xôi | B38: Kg | C38: 5 | D38: 28000 | E38: =C38*D38 -> 140000
A39: Cải Bó Xôi | B39: Túi | C39: 7 | D39: 9000 | E39: =C39*D39 -> 63000
A40: Cải Cầu Vồng | B40: Kg | C40: 0 | E40: =C40*D40 -> 0
...

Sheet 3.1
A1: hàng tồn cuối ngày 3/1 vr
A2: Tên Sản phẩm | B2: ĐVT | C2: tồn | D2: giá | E2: thành tiền
A3: Bắp Cải Tím | B3: Kg | C3: 10 | D3: 15000 | E3: =C3*D3 -> 150000
A4: Bắp Cải Trái Tim | B4: Kg | C4: 105 | D4: 7500 | E4: =C4*D4 -> 787500
A5: Bắp Cải Trắng | B5: Kg | C5: 420 | D5: 5500 | E5: =C5*D5 -> 2310000
A6: Bí Đỏ Hồ Lô | B6: Kg | C6: 0 | E6: =C6*D6 -> 0
A7: Bí Đỏ Tròn | B7: Kg | C7: 15 | D7: 10000 | E7: =C7*D7 -> 150000
A8: Bí Ngòi Xanh | B8: Kg | C8: 201 | D8: 10000 | E8: =C8*D8 -> 2010000
A9: Bí Ngòi Xanh | B9: Trái | C9: 0 | E9: =C9*D9 -> 0
A10: Bí Non Nhật | B10: Kg | C10: 72 | D10: 19000 | E10: =C10*D10 -> 1368000
A11: Bí Non Nhật | B11: Trái | C11: 0 | E11: =C11*D11 -> 0
A12: Bơ Booth | B12: Kg | C12: 0 | E12: =C12*D12 -> 0
A13: Bông Cải Trắng | B13: Kg | C13: 0 | E13: =C13*D13 -> 0
A14: Bông Cải Xanh 10Cm | B14: Kg | C14: 0 | E14: =C14*D14 -> 0
A15: Bông Cải Xanh 12Cm | B15: Kg | C15: 0 | E15: =C15*D15 -> 0
A16: Bông Cải Xanh 7Cm | B16: Kg | C16: 0 | E16: =C16*D16 -> 0
A17: Bông Cải Xanh Baby | B17: Vỉ | C17: 0 | E17: =C17*D17 -> 0
A18: Cà Chua Beef | B18: Kg | C18: 43 | D18: 15000 | E18: =C18*D18 -> 645000
A19: Cà Chua Beef | B19: Vỉ | C19: 0 | E19: =C19*D19 -> 0
A20: Cà Chua Beef | B20: Vỉ 650gr | C20: 0 | E20: =C20*D20 -> 0
A21: Cà Chua Beef Trung | B21: Kg | C21: 29 | D21: 14000 | E21: =C21*D21 -> 406000
A22: Cà Chua Beef Trung | B22: Vỉ 500gr | C22: 15 | D22: 7000 | E22: =C22*D22 -> 105000
A23: Cà Chua Bi Đỏ | B23: Kg | C23: 5 | D23: 24000 | E23: =C23*D23 -> 120000
A24: Cà Chua Bi Đỏ | B24: Hộp 300gr | C24: 35 | D24: 7200 | E24: =C24*D24 -> 252000
A25: Cà Chua Bi Mix | B25: Hộp | C25: 5 | D25: 12000 | E25: =C25*D25 -> 60000
A26: Cà Chua Socola | B26: Kg | C26: 0 | E26: =C26*D26 -> 0
A27: Cà Chua Socola | B27: Hộp 250GR | C27: 0 | E27: =C27*D27 -> 0
A28: Cà Chua Thường | B28: Kg | C28: 660 | D28: 16000 | E28: =C28*D28 -> 10560000
A29: Cà Chua Thường | B29: Vỉ | C29: 0 | E29: =C29*D29 -> 0
A30: Cà Chua Thường Trung | B30: Túi | C30: 20 | D30: 14000 | E30: =C30*D30 -> 280000
A31: Cà Rốt | B31: Kg | C31: 90 | D31: 11500 | E31: =C31*D31 -> 1035000
A32: Cà Rốt | B32: Túi | C32: 0 | E32: =C32*D32 -> 0
A33: Cà Rốt Baby | B33: Vỉ | C33: 0 | E33: =C33*D33 -> 0
A34: Cà Tím | B34: Kg | C34: 0 | E34: =C34*D34 -> 0
A35: Cà Tím | B35: Cặp | C35: 0 | E35: =C35*D35 -> 0
A36: Cải Bó Xôi | B36: Kg | C36: 8 | D36: 26000 | E36: =C36*D36 -> 208000
A37: Cải Bó Xôi | B37: Túi | C37: 0 | E37: =C37*D37 -> 0
A38: Cải Cầu Vồng | B38: Túi | C38: 11 | D38: 5000 | E38: =C38*D38 -> 55000
A39: Cải Kale | B39: Túi | C39: 0 | E39: =C39*D39 -> 0
A40: Cải Thảo | B40: Kg | C40: 1110 | D40: 6500 | E40: =C40*D40 -> 7215000
...

Sheet 4.1
A2: hàng tồn cuối ngày 4/1 vr
A3: Tên Sản phẩm | B3: ĐVT | C3: tồn | D3: giá | E3: thành tiền
A4: Cà Rốt | B4: Kg | C4: 205 | D4: 11500 | E4: =C4*D4 -> 2357500
A5: Cà Rốt | B5: Túi | C5: 0 | E5: =C5*D5 -> 0
A6: Cà Rốt Baby | B6: Vỉ | C6: 9 | D6: 9500 | E6: =C6*D6 -> 85500
A7: Củ Cải Đỏ | B7: Hộp | C7: 0 | E7: =C7*D7 -> 0
A8: Củ Cải Đỏ | B8: Kg | C8: 0 | E8: =C8*D8 -> 0
A9: Củ Dền | B9: Kg | C9: 53 | D9: 10000 | E9: =C9*D9 -> 530000
A10: Củ Dền | B10: Túi | C10: 0 | E10: =C10*D10 -> 0
A11: Củ Hành Tây | B11: Kg | C11: 348 | D11: 12500 | E11: =C11*D11 -> 4350000
A12: Củ Hành Tây | B12: Túi 300gr | C12: 0 | E12: =C12*D12 -> 0
A13: Củ Hành Tây Trung | B13: Túi | C13: 133 | D13: 3000 | E13: =C13*D13 -> 399000
A14: Củ Khoai Lang Mật Size 46 | B14: Kg | C14: 1085 | D14: 28000 | E14: =C14*D14 -> 30380000
A15: Củ Khoai Lang Mật Size 46 | B15: Túi | C15: 0 | E15: =C15*D15 -> 0
A16: Củ Khoai Lang Nhật | B16: Kg | C16: 216 | D16: 16000 | E16: =C16*D16 -> 3456000
A17: Củ Khoai Tây Vàng | B17: Kg | C17: 217 | D17: 17000 | E17: =C17*D17 -> 3689000
A18: Củ Khoai Tây Vàng | B18: Túi | C18: 0 | E18: =C18*D18 -> 0
A19: Bông Cải Xanh Baby | B19: Vỉ | C19: 7 | D19: 8000 | E19: =C19*D19 -> 56000
A20: Bắp Cải Trắng | B20: Kg | C20: 79 | D20: 5500 | E20: =C20*D20 -> 434500
A21: Cải Bó Xôi | B21: Kg | C21: 8 | D21: 28000 | E21: =C21*D21 -> 224000
A22: Cải Bó Xôi | B22: Túi | C22: 13 | D22: 9000 | E22: =C22*D22 -> 117000
A23: Cải Kale | B23: Túi | C23: 21 | D23: 4300 | E23: =C23*D23 -> 90300
A24: Cải Thảo | B24: Kg | C24: 1523 | D24: 6500 | E24: =C24*D24 -> 9899500
A25: Cần Tây | B25: Cây | C25: 0 | E25: =C25*D25 -> 0
A26: Cần Tây | B26: Kg | C26: 30 | D26: 9000 | E26: =C26*D26 -> 270000
A27: Xà Lách Lolo Xanh T.C | B27: Kg | C27: 0 | E27: =C27*D27 -> 0
A28: Bí Đỏ Tròn | B28: Kg | C28: 0 | E28: =C28*D28 -> 0
A29: Bí Ngòi Xanh | B29: Kg | C29: 69 | D29: 8000 | E29: =C29*D29 -> 552000
A30: Bí Ngòi Xanh | B30: Trái | C30: 0 | E30: =C30*D30 -> 0
A31: Bí Non Nhật | B31: Kg | C31: 100 | D31: 19000 | E31: =C31*D31 -> 1900000
A32: Bí Non Nhật | B32: Trái | C32: 0 | E32: =C32*D32 -> 0
A33: Cà Chua Beef | B33: Kg | C33: 59 | D33: 17000 | E33: =C33*D33 -> 1003000
A34: Cà Chua Beef | B34: Vỉ | C34: 0 | E34: =C34*D34 -> 0
A35: Cà Chua Beef | B35: Vỉ 650gr | C35: 0 | E35: =C35*D35 -> 0
A36: Cà Chua Thường | B36: Kg | C36: 446 | D36: 16000 | E36: =C36*D36 -> 7136000
A37: Cà Chua Thường | B37: Vỉ | C37: 0 | E37: =C37*D37 -> 0
A38: Cà Chua Thường Trung | B38: Túi | C38: 80 | D38: 11000 | E38: =C38*D38 -> 880000
A39: Dưa Leo Baby | B39: Kg | C39: 0 | E39: =C39*D39 -> 0
A40: Dưa Leo Baby | B40: Vỉ | C40: 165 | D40: 6000 | E40: =C40*D40 -> 990000
A41: Dưa Leo Thường | B41: Kg | C41: 20 | D41: 12000 | E41: =C41*D41 -> 240000
...

Sheet 5.1
A1: hàng tồn cuối ngày 5/1 vr
A2: Tên Sản phẩm | B2: ĐVT | C2: tồn | D2: giá | E2: thành tiền
A3: Cà Rốt | B3: Kg | C3: 159 | D3: 11500 | E3: =C3*D3 -> 1828500
A4: Cà Rốt | B4: Túi | C4: 0 | E4: =C4*D4 -> 0
A5: Cà Rốt Baby | B5: Kg | C5: 0 | E5: =C5*D5 -> 0
A6: Cà Rốt Baby | B6: Vỉ | C6: 0 | E6: =C6*D6 -> 0
A7: Củ Cải Đỏ | B7: Hộp | C7: 0 | E7: =C7*D7 -> 0
A8: Củ Cải Đỏ | B8: Kg | C8: 0 | E8: =C8*D8 -> 0
A9: Củ Dền | B9: Kg | C9: 10 | D9: 10000 | E9: =C9*D9 -> 100000
A10: Củ Dền | B10: Túi | C10: 0 | E10: =C10*D10 -> 0
A11: Củ Hành Tây | B11: Kg | C11: 240 | D11: 12500 | E11: =C11*D11 -> 3000000
A12: Củ Hành Tây | B12: Túi 300gr | C12: 0 | E12: =C12*D12 -> 0
A13: Củ Hành Tây Trung | B13: Túi | C13: 123 | D13: 3000 | E13: =C13*D13 -> 369000
A14: Củ Khoai Lang Mật Size 46 | B14: Kg | C14: 965 | D14: 28000 | E14: =C14*D14 -> 27020000
A15: Củ Khoai Lang Mật Size 46 | B15: Túi | C15: 0 | E15: =C15*D15 -> 0
A16: Củ Khoai Lang Nhật | B16: Kg | C16: 191 | D16: 16000 | E16: =C16*D16 -> 3056000
A17: Củ Khoai Tây Vàng | B17: Kg | C17: 350 | D17: 17000 | E17: =C17*D17 -> 5950000
A18: Củ Khoai Tây Vàng | B18: Túi | C18: 0 | E18: =C18*D18 -> 0
A19: Bông Cải Xanh Baby | B19: Vỉ | C19: 0 | E19: =C19*D19 -> 0
A20: Bắp Cải Trắng | B20: Kg | C20: 40 | D20: 5500 | E20: =C20*D20 -> 220000
A21: Cải Bó Xôi | B21: Kg | C21: 3 | D21: 28000 | E21: =C21*D21 -> 84000
A22: Cải Bó Xôi | B22: Túi | C22: 10 | D22: 9000 | E22: =C22*D22 -> 90000
A23: Cải Kale | B23: Túi | C23: 12 | D23: 4300 | E23: =C23*D23 -> 51600
A24: Cải Thảo | B24: Kg | C24: 960 | D24: 6000 | E24: =C24*D24 -> 5760000
A25: Cần Tây | B25: Cây | C25: 0 | E25: =C25*D25 -> 0
A26: Cần Tây | B26: Kg | C26: 40 | D26: 9000 | E26: =C26*D26 -> 360000
A27: Xà Lách Lolo Xanh T.C | B27: Kg | C27: 0 | E27: =C27*D27 -> 0
A28: Bí Đỏ Tròn | B28: Kg | C28: 120 | D28: 10000 | E28: =C28*D28 -> 1200000
A29: Bí Ngòi Xanh | B29: Kg | C29: 83 | D29: 8000 | E29: =C29*D29 -> 664000
A30: Bí Ngòi Xanh | B30: Trái | C30: 0 | E30: =C30*D30 -> 0
A31: Bí Non Nhật | B31: Kg | C31: 70 | D31: 19000 | E31: =C31*D31 -> 1330000
A32: Bí Non Nhật | B32: Trái | C32: 0 | E32: =C32*D32 -> 0
A33: Cà Chua Beef | B33: Kg | C33: 195 | D33: 17000 | E33: =C33*D33 -> 3315000
A34: Cà Chua Beef | B34: Vỉ 650gr | C34: 0 | E34: =C34*D34 -> 0
A35: Cà Chua Thường | B35: Kg | C35: 199 | D35: 12000 | E35: =C35*D35 -> 2388000
A36: Cà Chua Thường | B36: Vỉ | C36: 0 | E36: =C36*D36 -> 0
A37: Cà Chua Thường Trung | B37: Túi | C37: 130 | D37: 9000 | E37: =C37*D37 -> 1170000
A38: Dưa Leo Baby | B38: Kg | C38: 0 | E38: =C38*D38 -> 0
A39: Dưa Leo Baby | B39: Vỉ | C39: 0 | E39: =C39*D39 -> 0
A40: Dưa Leo Thường | B40: Kg | C40: 10 | D40: 10000 | E40: =C40*D40 -> 100000
...

Sheet 6.1
A1: hàng tồn cuối ngày 6/1 vr
A2: Tên Sản phẩm VR | B2: ĐVT | C2: tồn | D2: giá | E2: thành tiền
A3: Bắp Cải Trái Tim | B3: Kg | C3: 271 | D3: 7000 | E3: =C3*D3 -> 1897000
A4: Bắp Cải Trắng | B4: Kg | C4: 380 | D4: 5500 | E4: =C4*D4 -> 2090000
A5: Bí Đỏ Hồ Lô | B5: Kg | C5: 0 | E5: =C5*D5 -> 0
A6: Bí Đỏ Tròn | B6: Kg | C6: 25 | D6: 10000 | E6: =C6*D6 -> 250000
A7: Bí Ngòi Xanh | B7: Kg | C7: 354 | D7: 8000 | E7: =C7*D7 -> 2832000
A8: Bí Ngòi Xanh | B8: Trái | C8: 0 | E8: =C8*D8 -> 0
A9: Bí Non Nhật | B9: Kg | C9: 55 | D9: 15000 | E9: =C9*D9 -> 825000
A10: Bí Non Nhật | B10: Trái | C10: 0 | E10: =C10*D10 -> 0
A11: Bông Cải Trắng | B11: Kg | C11: 0 | E11: =C11*D11 -> 0
A12: Bông Cải Xanh 12Cm | B12: Kg | C12: 40 | D12: 20000 | E12: =C12*D12 -> 800000
A13: Bông Cải Xanh 7Cm | B13: Kg | C13: 15 | D13: 31000 | E13: =C13*D13 -> 465000
A14: Bông Cải Xanh Baby | B14: Vỉ | C14: 0 | E14: =C14*D14 -> 0
A15: Bông Cải Xanh Gốc Dài | B15: Kg | C15: 20 | D15: 20000 | E15: =C15*D15 -> 400000
A16: Cà Chua Beef | B16: Kg | C16: 358 | D16: 17000 | E16: =C16*D16 -> 6086000
A17: Cà Chua Beef | B17: Vỉ 650gr | C17: 0 | E17: =C17*D17 -> 0
A18: Cà Chua Beef Trung | B18: Kg | C18: 25 | D18: 8000 | E18: =C18*D18 -> 200000
A19: Cà Chua Beef Trung | B19: Vỉ 500gr | C19: 0 | E19: =C19*D19 -> 0
A20: Cà Chua Bi Đỏ | B20: Kg | C20: 2 | D20: 24000 | E20: =C20*D20 -> 48000
A21: Cà Chua Bi Đỏ | B21: Hộp 300gr | C21: 118 | D21: 7200 | E21: =C21*D21 -> 849600
A22: Cà Chua Socola | B22: Kg | C22: 0 | E22: =C22*D22 -> 0
A23: Cà Chua Socola | B23: Hộp 250GR | C23: 322 | D23: 11000 | E23: =C23*D23 -> 3542000
A24: Cà Chua Thường | B24: Kg | C24: 312 | D24: 11000 | E24: =C24*D24 -> 3432000
A25: Cà Chua Thường | B25: Vỉ | C25: 0 | E25: =C25*D25 -> 0
A26: Cà Chua Thường Trung | B26: Túi | C26: 141 | D26: 9000 | E26: =C26*D26 -> 1269000
A27: Cà Rốt | B27: Kg | C27: 154 | D27: 11000 | E27: =C27*D27 -> 1694000
A28: Cà Rốt | B28: Túi | C28: 0 | E28: =C28*D28 -> 0
A29: Cà Rốt Baby | B29: Vỉ | C29: 7 | D29: 9500 | E29: =C29*D29 -> 66500
A30: Cà Tím | B30: Kg | C30: 69 | D30: 8000 | E30: =C30*D30 -> 552000
A31: Cà Tím | B31: Cặp | C31: 0 | E31: =C31*D31 -> 0
A32: Cải Bó Xôi | B32: Kg | C32: 7 | D32: 28000 | E32: =C32*D32 -> 196000
A33: Cải Bó Xôi | B33: Túi | C33: 6 | D33: 9000 | E33: =C33*D33 -> 54000
A34: Cải Cầu Vồng | B34: Túi | C34: 2 | D34: 6000 | E34: =C34*D34 -> 12000
A35: Cải Kale | B35: Túi | C35: 0 | E35: =C35*D35 -> 0
A36: Cải Thảo | B36: Kg | C36: 1541 | D36: 6000 | E36: =C36*D36 -> 9246000
A37: Cải Thảo Hỏa Tiễn | B37: Kg | C37: 4 | D37: 14000 | E37: =C37*D37 -> 56000
A38: Cần Tây | B38: Cây | C38: 0 | E38: =C38*D38 -> 0
A39: Cần Tây | B39: Kg | C39: 73 | D39: 9000 | E39: =C39*D39 -> 657000
A40: Chanh Dây Tím | B40: Kg | C40: 20 | D40: 27000 | E40: =C40*D40 -> 540000
...

Sheet 7.1
A1: hàng tồn cuối ngày 7/1 vr
A2: Tên Sản phẩm | B2: ĐVT | C2: tồn | D2: giá | E2: thành tiền
A3: Cà Rốt | B3: Kg | C3: 296 | D3: 11000 | E3: =C3*D3 -> 3256000
A4: Cà Rốt | B4: Túi | C4: 0 | E4: =C4*D4 -> 0
A5: Cà Rốt Baby | B5: Vỉ | C5: 0 | E5: =C5*D5 -> 0
A6: Củ Cải Đỏ | B6: Hộp | C6: 0 | E6: =C6*D6 -> 0
A7: Củ Cải Đỏ | B7: Kg | C7: 0 | E7: =C7*D7 -> 0
A8: Củ Dền | B8: Kg | C8: 45 | D8: 10000 | E8: =C8*D8 -> 450000
A9: Củ Dền | B9: Túi | C9: 0 | E9: =C9*D9 -> 0
A10: Củ Hành Tây | B10: Kg | C10: 345 | D10: 12500 | E10: =C10*D10 -> 4312500
A11: Củ Hành Tây | B11: Túi 300gr | C11: 0 | E11: =C11*D11 -> 0
A12: Củ Hành Tây Trung | B12: Túi | C12: 0 | E12: =C12*D12 -> 0
A13: Củ Khoai Lang Mật Size 46 | B13: Kg | C13: 860 | D13: 28000 | E13: =C13*D13 -> 24080000
A14: Củ Khoai Lang Mật Size 46 | B14: Túi | C14: 0 | E14: =C14*D14 -> 0
A15: Củ Khoai Lang Nhật | B15: Kg | C15: 275 | D15: 29000 | E15: =C15*D15 -> 7975000
A16: Củ Khoai Tây Vàng | B16: Kg | C16: 425 | D16: 17000 | E16: =C16*D16 -> 7225000
A17: Củ Khoai Tây Vàng | B17: Túi | C17: 0 | E17: =C17*D17 -> 0
A18: Bông Cải Xanh Baby | B18: Vỉ | C18: 0 | E18: =C18*D18 -> 0
A19: Bắp Cải Trắng | B19: Kg | C19: 632 | D19: 5000 | E19: =C19*D19 -> 3160000
A20: Cải Bó Xôi | B20: Kg | C20: 15 | D20: 28000 | E20: =C20*D20 -> 420000
A21: Cải Bó Xôi | B21: Túi | C21: 0 | E21: =C21*D21 -> 0
A22: Cải Kale | B22: Túi | C22: 0 | E22: =C22*D22 -> 0
A23: Cải Thảo | B23: Kg | C23: 910 | D23: 6000 | E23: =C23*D23 -> 5460000
A24: Cần Tây | B24: Cây | C24: 0 | E24: =C24*D24 -> 0
A25: Cần Tây | B25: Kg | C25: 65 | D25: 9000 | E25: =C25*D25 -> 585000
A26: Xà Lách Lolo Xanh T.C | B26: Kg | C26: 0 | E26: =C26*D26 -> 0
A27: Bí Đỏ Tròn | B27: Kg | C27: 85 | D27: 10000 | E27: =C27*D27 -> 850000
A28: Bí Ngòi Xanh | B28: Kg | C28: 180 | D28: 8000 | E28: =C28*D28 -> 1440000
A29: Bí Ngòi Xanh | B29: Trái | C29: 0 | E29: =C29*D29 -> 0
A30: Bí Non Nhật | B30: Kg | C30: 0 | E30: =C30*D30 -> 0
A31: Bí Non Nhật | B31: Trái | C31: 0 | E31: =C31*D31 -> 0
A32: Cà Chua Beef | B32: Kg | C32: 560 | D32: 17000 | E32: =C32*D32 -> 9520000
A33: Cà Chua Beef | B33: Vỉ | C33: 0 | E33: =C33*D33 -> 0
A34: Cà Chua Beef | B34: Vỉ 650gr | C34: 0 | E34: =C34*D34 -> 0
A35: Cà Chua Thường | B35: Kg | C35: 450 | D35: 11000 | E35: =C35*D35 -> 4950000
A36: Cà Chua Thường | B36: Vỉ | C36: 0 | E36: =C36*D36 -> 0
A37: Cà Chua Thường Trung | B37: Túi | C37: 80 | D37: 9000 | E37: =C37*D37 -> 720000
A38: Dưa Leo Baby | B38: Kg | C38: 0 | E38: =C38*D38 -> 0
A39: Dưa Leo Baby | B39: Vỉ | C39: 650 | D39: 6000 | E39: =C39*D39 -> 3900000
A40: Dưa Leo Thường | B40: Kg | C40: 30 | D40: 13000 | E40: =C40*D40 -> 390000
...

Sheet 8.1
A1: hàng tồn cuối ngày 8/1 vr
A2: Tên Sản phẩm | B2: ĐVT | C2: tồn | D2: giá | E2: thành tiền
A3: Cà Rốt | B3: Kg | C3: 85 | D3: 10500 | E3: =C3*D3 -> 892500
A4: Cà Rốt | B4: Túi | C4: 0 | E4: =C4*D4 -> 0
A5: Cà Rốt Baby | B5: Vỉ | C5: 19 | D5: 8000 | E5: =C5*D5 -> 152000
A6: Củ Dền | B6: Kg | C6: 0 | E6: =C6*D6 -> 0
A7: Củ Dền | B7: Túi | C7: 0 | E7: =C7*D7 -> 0
A8: Củ Hành Tây | B8: Kg | C8: 235 | D8: 12500 | E8: =C8*D8 -> 2937500
A9: Củ Hành Tây | B9: Túi 300gr | C9: 0 | E9: =C9*D9 -> 0
A10: Củ Hành Tây Trung | B10: Túi | C10: 183 | D10: 2400 | E10: =C10*D10 -> 439200
A11: Củ Khoai Lang Mật Size 46 | B11: Kg | C11: 1180 | D11: 29000 | E11: =C11*D11 -> 34220000
A12: Củ Khoai Lang Mật Size 46 | B12: Túi | C12: 0 | E12: =C12*D12 -> 0
A13: Củ Khoai Lang Nhật | B13: Kg | C13: 240 | D13: 16000 | E13: =C13*D13 -> 3840000
A14: Củ Khoai Tây Vàng | B14: Kg | C14: 380 | D14: 17000 | E14: =C14*D14 -> 6460000
A15: Củ Khoai Tây Vàng | B15: Túi | C15: 0 | E15: =C15*D15 -> 0
A16: Bông Cải Xanh Baby | B16: Vỉ | C16: 26 | D16: 7000 | E16: =C16*D16 -> 182000
A17: Bắp Cải Trắng | B17: Kg | C17: 664 | D17: 5000 | E17: =C17*D17 -> 3320000
A18: Cải Bó Xôi | B18: Kg | C18: 3 | D18: 15000 | E18: =C18*D18 -> 45000
A19: Cải Bó Xôi | B19: Túi | C19: 0 | E19: =C19*D19 -> 0
A20: Cải Kale | B20: Túi | C20: 13 | D20: 4300 | E20: =C20*D20 -> 55900
A21: Cải Thảo | B21: Kg | C21: 720 | D21: 6000 | E21: =C21*D21 -> 4320000
A22: Cần Tây | B22: Cây | C22: 0 | E22: =C22*D22 -> 0
A23: Cần Tây | B23: Kg | C23: 37 | D23: 9000 | E23: =C23*D23 -> 333000
A24: Xà Lách Lolo Xanh T.C | B24: Kg | C24: 0 | E24: =C24*D24 -> 0
A25: Bí Đỏ Tròn | B25: Kg | C25: 167 | D25: 10500 | E25: =C25*D25 -> 1753500
A26: Bí Ngòi Xanh | B26: Kg | C26: 169 | D26: 8000 | E26: =C26*D26 -> 1352000
A27: Bí Ngòi Xanh | B27: Trái | C27: 0 | E27: =C27*D27 -> 0
A28: Bí Non Nhật | B28: Kg | C28: 50 | D28: 13000 | E28: =C28*D28 -> 650000
A29: Bí Non Nhật | B29: Trái | C29: 0 | E29: =C29*D29 -> 0
A30: Cà Chua Beef | B30: Kg | C30: 423 | D30: 17000 | E30: =C30*D30 -> 7191000
A31: Cà Chua Beef | B31: Vỉ 650gr | C31: 0 | E31: =C31*D31 -> 0
A32: Cà Chua Thường | B32: Kg | C32: 280 | D32: 11000 | E32: =C32*D32 -> 3080000
A33: Cà Chua Thường | B33: Vỉ | C33: 0 | E33: =C33*D33 -> 0
A34: Cà Chua Thường Trung | B34: Túi | C34: 100 | D34: 9000 | E34: =C34*D34 -> 900000
A35: Dưa Leo Baby | B35: Kg | C35: 0 | E35: =C35*D35 -> 0
A36: Dưa Leo Baby | B36: Vỉ | C36: 1028 | D36: 6000 | E36: =C36*D36 -> 6168000
A37: Dưa Leo Thường | B37: Kg | C37: 0 | E37: =C37*D37 -> 0
A38: Ớt Chuông Đỏ | B38: Kg | C38: 70 | D38: 25000 | E38: =C38*D38 -> 1750000
A39: Ớt Chuông Đỏ | B39: Trái | C39: 0 | E39: =C39*D39 -> 0
A40: Ớt Chuông Vàng | B40: Kg | C40: 118 | D40: 22000 | E40: =C40*D40 -> 2596000
...

Sheet 9.1
A2: hàng tồn cuối ngày 9/1 vr
A3: Tên Sản phẩm | B3: ĐVT | C3: tồn | D3: giá | E3: thành tiền
A4: Cà Rốt | B4: Kg | C4: 129 | D4: 10000 | E4: =C4*D4 -> 1290000
A5: Cà Rốt Baby | B5: Vỉ | C5: 18 | D5: 9000 | E5: =C5*D5 -> 162000
A6: Củ Dền | B6: Kg | C6: 60 | D6: 11000 | E6: =C6*D6 -> 660000
A7: Củ Hành Tây | B7: Kg | C7: 337 | D7: 12000 | E7: =C7*D7 -> 4044000
A8: Củ Hành Tây Trung | B8: Túi | C8: 15 | D8: 2400 | E8: =C8*D8 -> 36000
A9: Củ Khoai Lang Mật Size 46 | B9: Kg | C9: 1240 | D9: 28000 | E9: =C9*D9 -> 34720000
A10: Củ Khoai Lang Nhật | B10: Kg | C10: 190 | D10: 16000 | E10: =C10*D10 -> 3040000
A11: Củ Khoai Tây Vàng | B11: Kg | C11: 300 | D11: 17000 | E11: =C11*D11 -> 5100000
A12: Bắp Cải Trắng | B12: Kg | C12: 630 | D12: 5000 | E12: =C12*D12 -> 3150000
A13: Cải Bó Xôi | B13: Kg | C13: 20 | D13: 15000 | E13: =C13*D13 -> 300000
A14: Cải Kale | B14: Túi | C14: 2 | D14: 4300 | E14: =C14*D14 -> 8600
A15: Cải Thảo | B15: Kg | C15: 1185 | D15: 6000 | E15: =C15*D15 -> 7110000
... A65: Trái Bưởi Đường | B65: Trái | C65: 996 | D65: 11361 | E65: =C65*D65 -> 11315556
E66: =SUM(E4:E65) -> 158949756
A67: kq
A68: Tên Sản phẩm | B68: ĐVT | C68: tồn | D68: giá | E68: thành tiền
A69: Cà Rốt | B69: Kg | C69: 121 | D69: 10000 | E69: =C69*D69 -> 1210000
A70: Củ Cải Trắng | B70: Kg | C70: 20 | D70: 6500 | E70: =C70*D70 -> 130000
A71: Củ Dền | B71: Kg | C71: 5 | D71: 11000 | E71: =C71*D71 -> 55000
A72: Củ Hành Tây | B72: Kg | C72: 33 | D72: 12000 | E72: =C72*D72 -> 396000
A73: Củ Khoai Lang Nhật | B73: Kg | C73: 30 | D73: 16000 | E73: =C73*D73 -> 480000
A74: Củ Khoai Tây Vàng | B74: Kg | C74: 30 | D74: 18000 | E74: =C74*D74 -> 540000
A75: Củ Su Hào | B75: Kg | C75: 5 | D75: 11000 | E75: =C75*D75 -> 55000
A76: Bông Cải Trắng | B76: Kg | C76: 4 | D76: 16000 | E76: =C76*D76 -> 64000
A77: Bắp Cải Trái Tim | B77: Kg | C77: 290 | D77: 7000 | E77: =C77*D77 -> 2030000
A78: Bắp Cải Trắng | B78: Kg | C78: 110 | D78: 5500 | E78: =C78*D78 -> 605000
A79: Cải Thảo | B79: Kg | C79: 55 | D79: 6000 | E79: =C79*D79 -> 330000
A80: Cần Tây | B80: Kg | C80: 17 | D80: 9000 | E80: =C80*D80 -> 153000
... A94: Cải Thảo Kim Chi | B94: Kg | C94: 650 | D94: 6000 | E94: =C94*D94 -> 3900000
E95: =SUM(E69:E94) -> 17754000
E96: =E95+E66 -> 176703756

Sheet 10.1
A1: hàng tồn cuối ngày 10/1 vr
A2: Tên Sản phẩm | B2: ĐVT | C2: tồn | D2: giá | E2: thành tiền
A3: Bắp Cải Tím | B3: Kg | C3: 0 | E3: =C3*D3 -> 0
A4: Bắp Cải Trái Tim | B4: Kg | C4: 0 | E4: =C4*D4 -> 0
A5: Bắp Cải Trắng | B5: Kg | C5: 369 | D5: 5000 | E5: =C5*D5 -> 1845000
A6: Bí Đỏ Hồ Lô | B6: Kg | C6: 0 | E6: =C6*D6 -> 0
A7: Bí Đỏ Tròn | B7: Kg | C7: 0 | E7: =C7*D7 -> 0
A8: Bí Ngòi Xanh | B8: Kg | C8: 208 | D8: 8000 | E8: =C8*D8 -> 1664000
A9: Bí Ngòi Xanh | B9: Trái | C9: 0 | E9: =C9*D9 -> 0
A10: Bí Non Nhật | B10: Kg | C10: 50 | D10: 13000 | E10: =C10*D10 -> 650000
A11: Bí Non Nhật | B11: Trái | C11: 0 | E11: =C11*D11 -> 0
A12: Bơ Booth | B12: Kg | C12: 0 | E12: =C12*D12 -> 0
A13: Bông Cải Trắng | B13: Kg | C13: 26 | D13: 13000 | E13: =C13*D13 -> 338000
A14: Bông Cải Xanh 10Cm | B14: Kg | C14: 5 | D14: 14000 | E14: =C14*D14 -> 70000
A15: Bông Cải Xanh 12Cm | B15: Kg | C15: 0 | E15: =C15*D15 -> 0
A16: Bông Cải Xanh 7Cm | B16: Kg | C16: 0 | E16: =C16*D16 -> 0
A17: Bông Cải Xanh Baby | B17: Vỉ | C17: 20 | D17: 7000 | E17: =C17*D17 -> 140000
A18: Cà Chua Beef | B18: Kg | C18: 270 | D18: 19500 | E18: =C18*D18 -> 5265000
A19: Cà Chua Beef | B19: Vỉ | C19: 0 | E19: =C19*D19 -> 0
A20: Cà Chua Beef | B20: Vỉ 650gr | C20: 0 | E20: =C20*D20 -> 0
A21: Cà Chua Beef Trung | B21: Kg | C21: 40 | D21: 16000 | E21: =C21*D21 -> 640000
A22: Cà Chua Beef Trung | B22: Vỉ 500gr | C22: 0 | E22: =C22*D22 -> 0
A23: Cà Chua Bi Đỏ | B23: Kg | C23: 17 | D23: 24000 | E23: =C23*D23 -> 408000
A24: Cà Chua Bi Đỏ | B24: Hộp 300gr | C24: 70 | D24: 7200 | E24: =C24*D24 -> 504000
A25: Cà Chua Bi Mix | B25: Hộp | C25: 5 | D25: 12000 | E25: =C25*D25 -> 60000
A26: Cà Chua Socola | B26: Kg | C26: 0 | E26: =C26*D26 -> 0
A27: Cà Chua Socola | B27: Hộp 300gr | C27: 230 | D27: 8400 | E27: =C27*D27 -> 1932000
A28: Cà Chua Socola | B28: Hộp 250GR | C28: 270 | D28: 7000 | E28: =C28*D28 -> 1890000
A29: Cà Chua Thường | B29: Kg | C29: 190 | D29: 14000 | E29: =C29*D29 -> 2660000
A30: Cà Chua Thường | B30: Vỉ | C30: 0 | E30: =C30*D30 -> 0
A31: Cà Chua Thường Trung | B31: Túi | C31: 0 | E31: =C31*D31 -> 0
A32: Cà Rốt | B32: Kg | C32: 220 | D32: 10000 | E32: =C32*D32 -> 2200000
A33: Cà Rốt | B33: Túi | C33: 0 | E33: =C33*D33 -> 0
A34: Cà Rốt Baby | B34: Vỉ | C34: 0 | E34: =C34*D34 -> 0
A35: Cà Tím | B35: Kg | C35: 45 | D35: 8000 | E35: =C35*D35 -> 360000
A36: Cà Tím | B36: Cặp | C36: 0 | E36: =C36*D36 -> 0
A37: Cải Bó Xôi | B37: Kg | C37: 0 | E37: =C37*D37 -> 0
A38: Cải Bó Xôi | B38: Túi | C38: 0 | E38: =C38*D38 -> 0
A39: Cải Cầu Vồng | B39: Túi | C39: 8 | D39: 6000 | E39: =C39*D39 -> 48000
A40: Cải Kale | B40: Túi | C40: 9 | D40: 4300 | E40: =C40*D40 -> 38700
...

Sheet 11.11
A1: Tên Sản phẩm | B1: ĐVT | C1: Tồn ĐL 現在個 | D1: Gía nhập | E1: Thành tiền
A2: Bắp Cải Tím | B2: Kg | C2: 10 | D2: 11000 | E2: =+D2*C2 -> 110000
A3: Bắp Cải Trái Tim | B3: Kg | C3: 0
A4: Bắp Cải Trắng | B4: Kg | C4: 246 | D4: 5000 | E4: =+D4*C4 -> 1230000
A5: Bí Đỏ Hồ Lô | B5: Kg | C5: 3 | D5: 11000 | E5: =+D5*C5 -> 33000
A6: Bí Đỏ Tròn | B6: Kg | C6: 0
A7: Bí Ngòi Xanh | B7: Kg | C7: 135 | D7: 8000 | E7: =+D7*C7 -> 1080000
A8: Bí Ngòi Xanh | B8: Trái | C8: 0
A9: Bí Non Nhật | B9: Kg | C9: 50 | D9: 10000 | E9: =+D9*C9 -> 500000
A10: Bí Non Nhật | B10: Trái | C10: 0
A11: Bơ Booth | B11: Kg | C11: 0
A12: Bông Cải Trắng | B12: Kg | C12: 2 | D12: 13000 | E12: =+D12*C12 -> 26000
A13: Bông Cải Xanh 10Cm | B13: Kg | C13: 0
A14: Bông Cải Xanh 12Cm | B14: Kg | C14: 0
A15: Bông Cải Xanh 7Cm | B15: Kg | C15: 0
A16: Bông Cải Xanh Baby | B16: Vỉ | C16: 0
A17: Cà Chua Beef | B17: Kg | C17: 350 | D17: 20000 | E17: =+D17*C17 -> 7000000
A18: Cà Chua Beef | B18: Vỉ | C18: 0
A19: Cà Chua Beef | B19: Vỉ 650gr | C19: 0
A20: Cà Chua Beef Trung | B20: Kg | C20: 4 | D20: 15000 | E20: =+D20*C20 -> 60000
A21: Cà Chua Beef Trung | B21: Vỉ 500gr | C21: 85 | D21: 8500 | E21: =+D21*C21 -> 722500
A22: Cà Chua Bi Đỏ | B22: Kg | C22: 5 | D22: 24000 | E22: =+D22*C22 -> 120000
A23: Cà Chua Bi Đỏ | B23: Hộp 300gr | C23: 85 | D23: 7200 | E23: =+D23*C23 -> 612000
A24: Cà Chua Bi Mix | B24: Hộp | C24: 21 | D24: 11100 | E24: =+D24*C24 -> 233100
A25: Cà Chua Socola | B25: Kg | C25: 0
A26: Cà Chua Socola | B26: Hộp 300gr | C26: 180 | D26: 8400 | E26: =+D26*C26 -> 1512000
A27: Cà Chua Socola | B27: Hộp 250GR | C27: 110 | D27: 7000 | E27: =+D27*C27 -> 770000
A28: Cà Chua Thường | B28: Kg | C28: 340 | D28: 12000 | E28: =+D28*C28 -> 4080000
A29: Cà Chua Thường | B29: Vỉ | C29: 0
A30: Cà Chua Thường Trung | B30: Túi | C30: 120 | D30: 9000 | E30: =+D30*C30 -> 1080000
A31: Cà Rốt | B31: Kg | C31: 40 | D31: 10000 | E31: =+D31*C31 -> 400000
A32: Cà Rốt | B32: Túi | C32: 0
A33: Cà Rốt Baby | B33: Vỉ | C33: 12 | D33: 7800 | E33: =+D33*C33 -> 93600
A34: Cà Tím | B34: Kg | C34: 27 | D34: 8000 | E34: =+D34*C34 -> 216000
A35: Cà Tím | B35: Cặp | C35: 0
A36: Cải Bó Xôi | B36: Kg | C36: 40 | D36: 15000 | E36: =+D36*C36 -> 600000
A37: Cải Bó Xôi | B37: Túi | C37: 0
A38: Cải Cầu Vồng | B38: Túi | C38: 11 | D38: 6000 | E38: =+D38*C38 -> 66000
A39: Cải Kale | B39: Túi | C39: 2 | D39: 4500 | E39: =+D39*C39 -> 9000
A40: Cải Thảo | B40: Kg | C40: 880 | D40: 7000 | E40: =+D40*C40 -> 6160000
...

Sheet 12.1
A1: hàng tồn cuối ngày 12/1 vr
A2: Tên Sản phẩm | B2: ĐVT | C2: tồn | D2: giá | E2: thành tiền
A3: Bắp Cải Tím | B3: Kg | C3: 11 | D3: 11000 | E3: =C3*D3 -> 121000
A4: Bắp Cải Trái Tim | B4: Kg | C4: 0 | E4: =C4*D4 -> 0
A5: Bắp Cải Trắng | B5: Kg | C5: 210 | D5: 5000 | E5: =C5*D5 -> 1050000
A6: Bí Đao Xanh | B6: Kg | C6: 0 | E6: =C6*D6 -> 0
A7: Bí Đỏ Hồ Lô | B7: Kg | C7: 0 | E7: =C7*D7 -> 0
A8: Bí Đỏ Tròn | B8: Kg | C8: 125 | D8: 9000 | E8: =C8*D8 -> 1125000
A9: Bí Ngòi Vàng | B9: Kg | C9: 0 | E9: =C9*D9 -> 0
A10: Bí Ngòi Xanh | B10: Kg | C10: 125 | D10: 8000 | E10: =C10*D10 -> 1000000
A11: Bí Ngòi Xanh | B11: Trái | C11: 0 | E11: =C11*D11 -> 0
A12: Bí Non Nhật | B12: Kg | C12: 28 | D12: 14000 | E12: =C12*D12 -> 392000
A13: Bí Non Nhật | B13: Trái | C13: 0 | E13: =C13*D13 -> 0
A14: Bơ Booth | B14: Kg | C14: 0 | E14: =C14*D14 -> 0
A15: Bông Cải Trắng | B15: Kg | C15: 10 | D15: 13000 | E15: =C15*D15 -> 130000
A16: Bông Cải Xanh 10Cm | B16: Kg | C16: 0 | E16: =C16*D16 -> 0
A17: Bông Cải Xanh 12Cm | B17: Kg | C17: 0 | E17: =C17*D17 -> 0
A18: Bông Cải Xanh 7Cm | B18: Kg | C18: 0 | E18: =C18*D18 -> 0
A19: Bông Cải Xanh Baby | B19: Vỉ | C19: 0 | E19: =C19*D19 -> 0
A20: Cà Chua Beef | B20: Kg | C20: 218 | D20: 18000 | E20: =C20*D20 -> 3924000
A21: Cà Chua Beef | B21: Vỉ | C21: 0 | E21: =C21*D21 -> 0
A22: Cà Chua Beef | B22: Vỉ 650gr | C22: 0 | E22: =C22*D22 -> 0
A23: Cà Chua Beef Trung | B23: Kg | C23: 15 | D23: 16000 | E23: =C23*D23 -> 240000
A24: Cà Chua Beef Trung | B24: Vỉ 500gr | C24: 40 | D24: 8500 | E24: =C24*D24 -> 340000
A25: Cà Chua Bi Đỏ | B25: Kg | C25: 0 | E25: =C25*D25 -> 0
A26: Cà Chua Bi Đỏ | B26: Hộp 300gr | C26: 111 | D26: 7200 | E26: =C26*D26 -> 799200
A27: Cà Chua Bi Mix | B27: Hộp | C27: 11 | D27: 12000 | E27: =C27*D27 -> 132000
A28: Cà Chua Socola | B28: Kg | C28: 0 | E28: =C28*D28 -> 0
A29: Cà Chua Socola | B29: Hộp 300gr | C29: 200 | D29: 8400 | E29: =C29*D29 -> 1680000
A30: Cà Chua Socola | B30: Hộp 250GR | C30: 350 | D30: 7000 | E30: =C30*D30 -> 2450000
A31: Cà Chua Thường | B31: Kg | C31: 235 | D31: 11000 | E31: =C31*D31 -> 2585000
A32: Cà Chua Thường | B32: Vỉ | C32: 0 | E32: =C32*D32 -> 0
A33: Cà Chua Thường Trung | B33: Túi | C33: 90 | D33: 9000 | E33: =C33*D33 -> 810000
A34: Cà Rốt | B34: Kg | C34: 116 | D34: 10000 | E34: =C34*D34 -> 1160000
A35: Cà Rốt | B35: Túi | C35: 0 | E35: =C35*D35 -> 0
A36: Cà Rốt Baby | B36: Kg | C36: 0 | E36: =C36*D36 -> 0
A37: Cà Rốt Baby | B37: Vỉ | C37: 2 | D37: 7800 | E37: =C37*D37 -> 15600
A38: Cà Tím | B38: Kg | C38: 62 | D38: 8000 | E38: =C38*D38 -> 496000
A39: Cà Tím | B39: Cặp | C39: 0 | E39: =C39*D39 -> 0
A40: Cải Bó Xôi | B40: Kg | C40: 36 | D40: 15000 | E40: =C40*D40 -> 540000
...

Sheet 13.1
A1: hàng tồn cuối ngày 13/1 vr
A2: Tên Sản phẩm VR | B2: ĐVT | C2: tồn | D2: giá | E2: thành tiền
A3: Bắp Cải Tím | B3: Kg | C3: 20 | D3: 12000 | E3: =C3*D3 -> 240000
A4: Bắp Cải Trái Tim | B4: Kg | C4: 0 | E4: =C4*D4 -> 0
A5: Bắp Cải Trắng | B5: Kg | C5: 185 | D5: 5000 | E5: =C5*D5 -> 925000
A6: Bí Đỏ Hồ Lô | B6: Kg | C6: 28 | D6: 9500 | E6: =C6*D6 -> 266000
A7: Bí Đỏ Tròn | B7: Kg | C7: 0 | E7: =C7*D7 -> 0
A8: Bí Ngòi Xanh | B8: Kg | C8: 120 | D8: 8000 | E8: =C8*D8 -> 960000
A9: Bí Ngòi Xanh | B9: Trái | C9: 0 | E9: =C9*D9 -> 0
A10: Bí Non Nhật | B10: Kg | C10: 40 | D10: 14000 | E10: =C10*D10 -> 560000
A11: Bí Non Nhật | B11: Trái | C11: 0 | E11: =C11*D11 -> 0
A12: Bông Cải Trắng | B12: Kg | C12: 7 | D12: 12000 | E12: =C12*D12 -> 84000
A13: Bông Cải Xanh 10Cm | B13: Kg | C13: 50 | D13: 12000 | E13: =C13*D13 -> 600000
A14: Bông Cải Xanh 12Cm | B14: Kg | C14: 0 | E14: =C14*D14 -> 0
A15: Bông Cải Xanh 7Cm | B15: Kg | C15: 0 | E15: =C15*D15 -> 0
A16: Bông Cải Xanh Baby | B16: Vỉ | C16: 10 | D16: 7000 | E16: =C16*D16 -> 70000
A17: Cà Chua Beef | B17: Kg | C17: 505 | D17: 19000 | E17: =C17*D17 -> 9595000
A18: Cà Chua Beef | B18: Vỉ 650gr | C18: 0 | E18: =C18*D18 -> 0
A19: Cà Chua Beef Trung | B19: Kg | C19: 42 | D19: 16000 | E19: =C19*D19 -> 672000
A20: Cà Chua Beef Trung | B20: Vỉ 500gr | C20: 0 | E20: =C20*D20 -> 0
A21: Cà Chua Bi Đỏ | B21: Kg | C21: 6 | D21: 21000 | E21: =C21*D21 -> 126000
A22: Cà Chua Bi Đỏ | B22: Hộp 300gr | C22: 75 | D22: 6300 | E22: =C22*D22 -> 472500
A23: Cà Chua Bi Mix | B23: Hộp | C23: 3 | D23: 11200 | E23: =C23*D23 -> 33600
A24: Cà Chua Socola | B24: Kg | C24: 0 | E24: =C24*D24 -> 0
A25: Cà Chua Socola | B25: Hộp 300gr | C25: 110 | D25: 8400 | E25: =C25*D25 -> 924000
A26: Cà Chua Socola | B26: Hộp 250GR | C26: 190 | D26: 7000 | E26: =C26*D26 -> 1330000
A27: Cà Chua Thường | B27: Kg | C27: 365 | D27: 11000 | E27: =C27*D27 -> 4015000
A28: Cà Chua Thường | B28: Vỉ | C28: 0 | E28: =C28*D28 -> 0
A29: Cà Chua Thường Trung | B29: Túi | C29: 90 | D29: 6000 | E29: =C29*D29 -> 540000
A30: Cà Rốt | B30: Kg | C30: 97 | D30: 10000 | E30: =C30*D30 -> 970000
A31: Cà Rốt | B31: Túi | C31: 0 | E31: =C31*D31 -> 0
A32: Cà Rốt Baby | B32: Vỉ | C32: 8 | D32: 7800 | E32: =C32*D32 -> 62400
A33: Cà Tím | B33: Kg | C33: 83 | D33: 8000 | E33: =C33*D33 -> 664000
A34: Cà Tím | B34: Cặp | C34: 0 | E34: =C34*D34 -> 0
A35: Cải Bó Xôi | B35: Kg | C35: 8 | D35: 15000 | E35: =C35*D35 -> 120000
A36: Cải Bó Xôi | B36: Túi | C36: 0 | E36: =C36*D36 -> 0
A37: Cải Cầu Vồng | B37: Túi | C37: 8 | D37: 6000 | E37: =C37*D37 -> 48000
A38: Cải Kale | B38: Túi | C38: 6 | D38: 4300 | E38: =C38*D38 -> 25800
A39: Cải Thảo | B39: Kg | C39: 465 | D39: 5500 | E39: =C39*D39 -> 2557500
A40: Cải Thảo Hỏa Tiễn | B40: Kg | C40: 9 | D40: 14000 | E40: =C40*D40 -> 126000
...

Sheet 14.1
A1: hàng tồn cuối ngày 14/1 vr
A2: tên sản phẩm | B2: dvt | C2: tồn | D2: giá | E2: thành tiền
A3: Bắp Cải Tím | B3: Kg | C3: 0 | E3: =C3*D3 -> 0
A4: Bắp Cải Trái Tim | B4: Kg | C4: 0 | E4: =C4*D4 -> 0
A5: Bắp Cải Trắng | B5: Kg | C5: 476 | D5: 5000 | E5: =C5*D5 -> 2380000
A6: Bí Đao Xanh | B6: Kg | C6: 0 | E6: =C6*D6 -> 0
A7: Bí Đỏ Hồ Lô | B7: Kg | C7: 12 | D7: 9500 | E7: =C7*D7 -> 114000
A8: Bí Đỏ Tròn | B8: Kg | C8: 255 | D8: 9000 | E8: =C8*D8 -> 2295000
A9: Bí Ngòi Vàng | B9: Kg | C9: 0 | E9: =C9*D9 -> 0
A10: Bí Ngòi Xanh | B10: Kg | C10: 115 | D10: 8000 | E10: =C10*D10 -> 920000
A11: Bí Ngòi Xanh | B11: Trái | C11: 0 | E11: =C11*D11 -> 0
A12: Bí Non Nhật | B12: Kg | C12: 100 | D12: 16000 | E12: =C12*D12 -> 1600000
A13: Bí Non Nhật | B13: Trái | C13: 0 | E13: =C13*D13 -> 0
A14: Bơ Booth | B14: Kg | C14: 0 | E14: =C14*D14 -> 0
A15: Bông Cải Trắng | B15: Kg | C15: 0 | E15: =C15*D15 -> 0
A16: Bông Cải Xanh 10Cm | B16: Kg | C16: 5 | D16: 12000 | E16: =C16*D16 -> 60000
A17: Bông Cải Xanh 12Cm | B17: Kg | C17: 0 | E17: =C17*D17 -> 0
A18: Bông Cải Xanh 7Cm | B18: Kg | C18: 52 | D18: 23000 | E18: =C18*D18 -> 1196000
A19: Bông Cải Xanh Baby | B19: Vỉ | C19: 12 | D19: 7000 | E19: =C19*D19 -> 84000
A20: Cà Chua Beef | B20: Kg | C20: 435 | D20: 19000 | E20: =C20*D20 -> 8265000
A21: Cà Chua Beef | B21: Vỉ | C21: 0 | E21: =C21*D21 -> 0
A22: Cà Chua Beef | B22: Vỉ 650gr | C22: 0 | E22: =C22*D22 -> 0
A23: Cà Chua Beef Trung | B23: Kg | C23: 14 | D23: 16000 | E23: =C23*D23 -> 224000
A24: Cà Chua Beef Trung | B24: Vỉ 500gr | C24: 0 | E24: =C24*D24 -> 0
A25: Cà Chua Bi Đỏ | B25: Kg | C25: 24 | D25: 21000 | E25: =C25*D25 -> 504000
A26: Cà Chua Bi Đỏ | B26: Hộp 300gr | C26: 62 | D26: 6300 | E26: =C26*D26 -> 390600
A27: Cà Chua Bi Mix | B27: Hộp | C27: 4 | D27: 11100 | E27: =C27*D27 -> 44400
A28: Cà Chua Socola | B28: Kg | C28: 0 | E28: =C28*D28 -> 0
A29: Cà Chua Socola | B29: Hộp 300gr | C29: 85 | D29: 8400 | E29: =C29*D29 -> 714000
A30: Cà Chua Socola | B30: Hộp 250GR | C30: 108 | D30: 7000 | E30: =C30*D30 -> 756000
A31: Cà Chua Thường | B31: Kg | C31: 175 | D31: 10000 | E31: =C31*D31 -> 1750000
A32: Cà Chua Thường | B32: Vỉ | C32: 0 | E32: =C32*D32 -> 0
A33: Cà Chua Thường Trung | B33: Túi | C33: 135 | D33: 6000 | E33: =C33*D33 -> 810000
A34: Cà Rốt | B34: Kg | C34: 305 | D34: 9500 | E34: =C34*D34 -> 2897500
A35: Cà Rốt | B35: Túi | C35: 0 | E35: =C35*D35 -> 0
A36: Cà Rốt Baby | B36: Kg | C36: 0 | E36: =C36*D36 -> 0
A37: Cà Rốt Baby | B37: Vỉ | C37: 0 | E37: =C37*D37 -> 0
A38: Cà Tím | B38: Kg | C38: 0 | E38: =C38*D38 -> 0
A39: Cà Tím | B39: Cặp | C39: 0 | E39: =C39*D39 -> 0
A40: Cải Bó Xôi | B40: Kg | C40: 25 | D40: 15000 | E40: =C40*D40 -> 375000
...

Sheet 15.1
A1: hàng tồn cuối ngày 15/1 vr
A2: Tên Sản phẩm | B2: ĐVT | C2: tồn | D2: giá | E2: thành tiền
A3: Cà Rốt | B3: Kg | C3: 380 | D3: 9500 | E3: =C3*D3 -> 3610000
A4: Cà Rốt | B4: Túi | C4: 0 | E4: =C4*D4 -> 0
A5: Cà Rốt Baby | B5: Vỉ | C5: 0 | E5: =C5*D5 -> 0
A6: Củ Cải Đỏ | B6: Hộp | C6: 6 | D6: 11000 | E6: =C6*D6 -> 66000
A7: Củ Cải Đỏ | B7: Kg | C7: 0 | E7: =C7*D7 -> 0
A8: Củ Dền | B8: Kg | C8: 30 | D8: 11000 | E8: =C8*D8 -> 330000
A9: Củ Dền | B9: Túi | C9: 0 | E9: =C9*D9 -> 0
A10: Củ Hành Tây | B10: Kg | C10: 200 | D10: 10000 | E10: =C10*D10 -> 2000000
A11: Củ Hành Tây | B11: Túi 300gr | C11: 0 | E11: =C11*D11 -> 0
A12: Củ Hành Tây Trung | B12: Túi | C12: 230 | D12: 2400 | E12: =C12*D12 -> 552000
A13: Củ Khoai Lang Mật Size 46 | B13: Kg | C13: 1737 | D13: 27000 | E13: =C13*D13 -> 46899000
A14: Củ Khoai Lang Mật Size 46 | B14: Túi | C14: 0 | E14: =C14*D14 -> 0
A15: Củ Khoai Lang Nhật | B15: Kg | C15: 415 | D15: 15500 | E15: =C15*D15 -> 6432500
A16: Củ Khoai Tây Vàng | B16: Kg | C16: 160 | D16: 18000 | E16: =C16*D16 -> 2880000
A17: Củ Khoai Tây Vàng | B17: Túi | C17: 0 | E17: =C17*D17 -> 0
A18: Bông Cải Xanh Baby | B18: Vỉ | C18: 5 | D18: 7000 | E18: =C18*D18 -> 35000
A19: Bắp Cải Trắng | B19: Kg | C19: 457 | D19: 5000 | E19: =C19*D19 -> 2285000
A20: Cải Bó Xôi | B20: Kg | C20: 12 | D20: 15000 | E20: =C20*D20 -> 180000
A21: Cải Bó Xôi | B21: Túi | C21: 0 | E21: =C21*D21 -> 0
A22: Cải Kale | B22: Túi | C22: 8 | D22: 4300 | E22: =C22*D22 -> 34400
A23: Cải Thảo | B23: Kg | C23: 1190 | D23: 5000 | E23: =C23*D23 -> 5950000
A24: Cần Tây | B24: Cây | C24: 0 | E24: =C24*D24 -> 0
A25: Cần Tây | B25: Kg | C25: 79 | D25: 9000 | E25: =C25*D25 -> 711000
A26: Xà Lách Lolo Xanh T.C | B26: Kg | C26: 0 | E26: =C26*D26 -> 0
A27: Bí Đỏ Tròn | B27: Kg | C27: 46 | D27: 12000 | E27: =C27*D27 -> 552000
A28: Bí Ngòi Xanh | B28: Kg | C28: 420 | D28: 8500 | E28: =C28*D28 -> 3570000
A29: Bí Ngòi Xanh | B29: Trái | C29: 0 | E29: =C29*D29 -> 0
A30: Bí Non Nhật | B30: Kg | C30: 42 | D30: 14000 | E30: =C30*D30 -> 588000
A31: Bí Non Nhật | B31: Trái | C31: 0 | E31: =C31*D31 -> 0
A32: Cà Chua Beef | B32: Kg | C32: 460 | D32: 19000 | E32: =C32*D32 -> 8740000
A33: Cà Chua Beef | B33: Vỉ 650gr | C33: 0 | E33: =C33*D33 -> 0
A34: Cà Chua Thường | B34: Kg | C34: 430 | D34: 11000 | E34: =C34*D34 -> 4730000
A35: Cà Chua Thường | B35: Vỉ | C35: 0 | E35: =C35*D35 -> 0
A36: Cà Chua Thường Trung | B36: Túi | C36: 90 | D36: 6000 | E36: =C36*D36 -> 540000
A37: Dưa Leo Baby | B37: Kg | C37: 0 | E37: =C37*D37 -> 0
A38: Dưa Leo Baby | B38: Vỉ | C38: 539 | D38: 6000 | E38: =C38*D38 -> 3234000
A39: Dưa Leo Thường | B39: Kg | C39: 7 | D39: 8000 | E39: =C39*D39 -> 56000
A40: Ớt Chuông Đỏ | B40: Kg | C40: 125 | D40: 28000 | E40: =C40*D40 -> 3500000
...

Sheet 16.1
A1: Tên Sản phẩm VR | B1: ĐVT | C1: Tồn ĐL 現在個 | D1: Gía nhập | E1: Thành tiền
A2: Bắp Cải Tím | B2: Kg | C2: 23 | D2: 10000 | E2: =+D2*C2 -> 230000
A3: Bắp Cải Trái Tim | B3: Kg | C3: 0
A4: Bắp Cải Trắng | B4: Kg | C4: 505 | D4: 5500 | E4: =+D4*C4 -> 2777500
A5: Bí Đao Xanh | B5: Kg | C5: 0
A6: Bí Đỏ Hồ Lô | B6: Kg | C6: 0
A7: Bí Đỏ Tròn | B7: Kg | C7: 1825 | D7: 8000 | E7: =+D7*C7 -> 14600000
A8: Bí Ngòi Vàng | B8: Kg | C8: 0
A9: Bí Ngòi Xanh | B9: Kg | C9: 239 | D9: 8500 | E9: =+D9*C9 -> 2031500
A10: Bí Ngòi Xanh | B10: Trái | C10: 0
A11: Bí Non Nhật | B11: Kg | C11: 67 | D11: 10000 | E11: =+D11*C11 -> 670000
A12: Bí Non Nhật | B12: Trái | C12: 0
A13: Bơ 034 L1 | B13: Kg | C13: 0
A14: Bơ Booth | B14: Kg | C14: 0
A15: Bông Cải Trắng | B15: Kg | C15: 0
A16: Bông Cải Xanh 10Cm | B16: Kg | C16: 0
A17: Bông Cải Xanh 12Cm | B17: Kg | C17: 10 | D17: 10000 | E17: =+D17*C17 -> 100000
A18: Bông Cải Xanh 7Cm | B18: Kg | C18: 37 | D18: 21000 | E18: =+D18*C18 -> 777000
A19: Bông Cải Xanh Baby | B19: Vỉ | C19: 18 | D19: 7000 | E19: =+D19*C19 -> 126000
A20: Cà Chua Beef | B20: Kg | C20: 335 | D20: 18000 | E20: =+D20*C20 -> 6030000
A21: Cà Chua Beef | B21: Vỉ | C21: 0
A22: Cà Chua Beef | B22: Vỉ 650gr | C22: 70 | D22: 13650 | E22: =+D22*C22 -> 955500
A23: Cà Chua Beef Trung | B23: Kg | C23: 5 | D23: 14000 | E23: =+D23*C23 -> 70000
A24: Cà Chua Beef Trung | B24: Vỉ 500gr | C24: 70 | D24: 8000 | E24: =+D24*C24 -> 560000
A25: Cà Chua Bi Đỏ | B25: Kg | C25: 13 | D25: 21000 | E25: =+D25*C25 -> 273000
A26: Cà Chua Bi Đỏ | B26: Hộp 300gr | C26: 94 | D26: 6300 | E26: =+D26*C26 -> 592200
A27: Cà Chua Bi Mix | B27: Hộp | C27: 18 | D27: 11100 | E27: =+D27*C27 -> 199800
A28: Cà Chua Socola | B28: Kg | C28: 0
A29: Cà Chua Socola | B29: Hộp 300gr | C29: 60 | D29: 9750 | E29: =+D29*C29 -> 585000
A30: Cà Chua Socola | B30: Hộp 250GR | C30: 40 | D30: 7000 | E30: =+D30*C30 -> 280000
A31: Cà Chua Thường | B31: Kg | C31: 290 | D31: 10000 | E31: =+D31*C31 -> 2900000
A32: Cà Chua Thường | B32: Vỉ | C32: 0
A33: Cà Chua Thường Trung | B33: Túi | C33: 90 | D33: 6000 | E33: =+D33*C33 -> 540000
A34: Cà Rốt | B34: Kg | C34: 455 | D34: 8500 | E34: =+D34*C34 -> 3867500
A35: Cà Rốt | B35: Túi | C35: 0
A36: Cà Rốt Baby | B36: Kg | C36: 0
A37: Cà Rốt Baby | B37: Vỉ | C37: 0
A38: Cà Tím | B38: Kg | C38: 84 | D38: 8000 | E38: =+D38*C38 -> 672000
A39: Cà Tím | B39: Cặp | C39: 0
A40: Cải Bó Xôi | B40: Kg | C40: 3 | D40: 26000 | E40: =+D40*C40 -> 78000
...

Sheet 17.1
A1: hàng tồn cuối ngày 17/1 vr
A2: Tên Sản phẩm | B2: ĐVT | C2: tồn | D2: giá | E2: thành tiền
A3: Bắp Cải Tím | B3: Kg | C3: 10 | D3: 10000 | E3: =C3*D3 -> 100000
A4: Bắp Cải Trái Tim | B4: Kg | C4: 150 | D4: 6000 | E4: =C4*D4 -> 900000 | F4: hùng báo sáng 18/1
A5: Bắp Cải Trắng | B5: Kg | C5: 150 | D5: 5000 | E5: =C5*D5 -> 750000 | F5: hùng báo sáng 18/1
A6: Bí Đỏ Hồ Lô | B6: Kg | C6: 0 | E6: =C6*D6 -> 0
A7: Bí Đỏ Tròn | B7: Kg | C7: 1505 | D7: 8000 | E7: =C7*D7 -> 12040000
A8: Bí Ngòi Vàng | B8: Kg | C8: 2 | D8: 9000 | E8: =C8*D8 -> 18000
A9: Bí Ngòi Xanh | B9: Kg | C9: 225 | D9: 8500 | E9: =C9*D9 -> 1912500
A10: Bí Ngòi Xanh | B10: Trái | C10: 0 | E10: =C10*D10 -> 0
A11: Bí Non Nhật | B11: Kg | C11: 52 | D11: 10000 | E11: =C11*D11 -> 520000
A12: Bí Non Nhật | B12: Trái | C12: 0 | E12: =C12*D12 -> 0
A13: Bơ Booth | B13: Kg | C13: 0 | E13: =C13*D13 -> 0
A14: Bông Cải Trắng | B14: Kg | C14: 16 | D14: 12000 | E14: =C14*D14 -> 192000
A15: Bông Cải Xanh 10Cm | B15: Kg | C15: 10 | D15: 12000 | E15: =C15*D15 -> 120000
A16: Bông Cải Xanh 12Cm | B16: Kg | C16: 25 | D16: 10000 | E16: =C16*D16 -> 250000
A17: Bông Cải Xanh 7Cm | B17: Kg | C17: 43 | D17: 21000 | E17: =C17*D17 -> 903000
A18: Bông Cải Xanh Baby | B18: Vỉ | C18: 9 | D18: 7000 | E18: =C18*D18 -> 63000
A19: Cà Chua Beef | B19: Kg | C19: 265 | D19: 19000 | E19: =C19*D19 -> 5035000
A20: Cà Chua Beef | B20: Vỉ | C20: 0 | E20: =C20*D20 -> 0
A21: Cà Chua Beef | B21: Vỉ 650gr | C21: 0 | E21: =C21*D21 -> 0
A22: Cà Chua Beef Trung | B22: Kg | C22: 15 | D22: 16000 | E22: =C22*D22 -> 240000
A23: Cà Chua Beef Trung | B23: Vỉ 500gr | C23: 45 | D23: 8500 | E23: =C23*D23 -> 382500
A24: Cà Chua Bi Đỏ | B24: Kg | C24: 4 | D24: 21000 | E24: =C24*D24 -> 84000
A25: Cà Chua Bi Đỏ | B25: Hộp 300gr | C25: 70 | D25: 6300 | E25: =C25*D25 -> 441000
A26: Cà Chua Bi Mix | B26: Hộp | C26: 5 | D26: 11100 | E26: =C26*D26 -> 55500
A27: Cà Chua Socola | B27: Kg | C27: 0 | E27: =C27*D27 -> 0
A28: Cà Chua Socola | B28: Hộp 300gr | C28: 141 | D28: 8400 | E28: =C28*D28 -> 1184400
A29: Cà Chua Socola | B29: Hộp 250GR | C29: 28 | D29: 7000 | E29: =C29*D29 -> 196000
A30: Cà Chua Thường | B30: Kg | C30: 0 | E30: =C30*D30 -> 0
A31: Cà Chua Thường | B31: Vỉ | C31: 0 | E31: =C31*D31 -> 0
A32: Cà Chua Thường Trung | B32: Túi | C32: 70 | D32: 6000 | E32: =C32*D32 -> 420000
A33: Cà Rốt | B33: Kg | C33: 120 | D33: 10000 | E33: =C33*D33 -> 1200000
A34: Cà Rốt | B34: Túi | C34: 0 | E34: =C34*D34 -> 0
A35: Cà Rốt Baby | B35: Vỉ | C35: 0 | E35: =C35*D35 -> 0
A36: Cà Tím | B36: Kg | C36: 57 | D36: 8000 | E36: =C36*D36 -> 456000
A37: Cà Tím | B37: Cặp | C37: 0 | E37: =C37*D37 -> 0
A38: Cải Bó Xôi | B38: Kg | C38: 0 | E38: =C38*D38 -> 0
A39: Cải Bó Xôi | B39: Túi | C39: 0 | E39: =C39*D39 -> 0
A40: Cải Cầu Vồng | B40: Túi | C40: 8 | D40: 6000 | E40: =C40*D40 -> 48000
...

Sheet 18.1
A1: hàng tồn cuối ngày 18/1 vr
A2: Tên Sản phẩm VR | B2: ĐVT | C2: tồn | D2: giá | E2: thành tiền
A3: Bắp Cải Tím | B3: Kg | C3: 24 | D3: 10000 | E3: =C3*D3 -> 240000
A4: Bắp Cải Trái Tim | B4: Kg | C4: 624 | D4: 6000 | E4: =C4*D4 -> 3744000
A5: Bắp Cải Trắng | B5: Kg | C5: 255 | D5: 5500 | E5: =C5*D5 -> 1402500
A6: Bí Đỏ Hồ Lô | B6: Kg | C6: 0 | E6: =C6*D6 -> 0
A7: Bí Đỏ Tròn | B7: Kg | C7: 1235 | D7: 8000 | E7: =C7*D7 -> 9880000
A8: Bí Ngòi Vàng | B8: Kg | C8: 2 | D8: 9000 | E8: =C8*D8 -> 18000
A9: Bí Ngòi Xanh | B9: Kg | C9: 154 | D9: 8500 | E9: =C9*D9 -> 1309000
A10: Bí Ngòi Xanh | B10: Trái | C10: 0 | E10: =C10*D10 -> 0
A11: Bí Non Nhật | B11: Kg | C11: 65 | D11: 14000 | E11: =C11*D11 -> 910000
A12: Bí Non Nhật | B12: Trái | C12: 0 | E12: =C12*D12 -> 0
A13: Bơ Booth | B13: Kg | C13: 0 | E13: =C13*D13 -> 0
A14: Bông Cải Trắng | B14: Kg | C14: 0 | E14: =C14*D14 -> 0
A15: Bông Cải Xanh 10Cm | B15: Kg | C15: 35 | D15: 12000 | E15: =C15*D15 -> 420000
A16: Bông Cải Xanh 12Cm | B16: Kg | C16: 0 | E16: =C16*D16 -> 0
A17: Bông Cải Xanh 7Cm | B17: Kg | C17: 40 | D17: 21000 | E17: =C17*D17 -> 840000
A18: Bông Cải Xanh Baby | B18: Vỉ | C18: 10 | D18: 7000 | E18: =C18*D18 -> 70000
A19: Cà Chua Beef | B19: Kg | C19: 195 | D19: 19000 | E19: =C19*D19 -> 3705000
A20: Cà Chua Beef | B20: Vỉ | C20: 0 | E20: =C20*D20 -> 0
A21: Cà Chua Beef | B21: Vỉ 650gr | C21: 0 | E21: =C21*D21 -> 0
A22: Cà Chua Beef Trung | B22: Kg | C22: 20 | D22: 14000 | E22: =C22*D22 -> 280000
A23: Cà Chua Beef Trung | B23: Vỉ 500gr | C23: 33 | D23: 8000 | E23: =C23*D23 -> 264000
A24: Cà Chua Bi Đỏ | B24: Kg | C24: 0 | E24: =C24*D24 -> 0
A25: Cà Chua Bi Đỏ | B25: Hộp 300gr | C25: 89 | D25: 6300 | E25: =C25*D25 -> 560700
A26: Cà Chua Bi Mix | B26: Hộp | C26: 10 | D26: 11100 | E26: =C26*D26 -> 111000
A27: Cà Chua Socola | B27: Kg | C27: 0 | E27: =C27*D27 -> 0
A28: Cà Chua Socola | B28: Hộp 250GR | C28: 60 | D28: 7000 | E28: =C28*D28 -> 420000
A29: Cà Chua Thường | B29: Kg | C29: 470 | D29: 10000 | E29: =C29*D29 -> 4700000
A30: Cà Chua Thường | B30: Vỉ | C30: 0 | E30: =C30*D30 -> 0
A31: Cà Chua Thường Trung | B31: Túi | C31: 130 | D31: 6000 | E31: =C31*D31 -> 780000
A32: Cà Rốt | B32: Kg | C32: 143 | D32: 8500 | E32: =C32*D32 -> 1215500
A33: Cà Rốt | B33: Túi | C33: 0 | E33: =C33*D33 -> 0
A34: Cà Rốt Baby | B34: Vỉ | C34: 16 | D34: 7000 | E34: =C34*D34 -> 112000
A35: Cà Tím | B35: Kg | C35: 89 | D35: 8000 | E35: =C35*D35 -> 712000
A36: Cà Tím | B36: Cặp | C36: 0 | E36: =C36*D36 -> 0
A37: Cải Bó Xôi | B37: Kg | C37: 0 | E37: =C37*D37 -> 0
A38: Cải Bó Xôi | B38: Túi | C38: 0 | E38: =C38*D38 -> 0
A39: Cải Cầu Vồng | B39: Túi | C39: 6 | D39: 6000 | E39: =C39*D39 -> 36000
A40: Cải Kale | B40: Túi | C40: 15 | D40: 4300 | E40: =C40*D40 -> 64500
...

Sheet 19.1
A1: Tên Sản phẩm VR | B1: ĐVT | C1: Tồn ĐL 現在個 | D1: Gía nhập | E1: Thành tiền
A2: Bắp Cải Tím | B2: Kg | C2: 27 | D2: 11000 | E2: =+D2*C2 -> 297000
A3: Bắp Cải Trái Tim | B3: Kg | C3: 0
A4: Bắp Cải Trắng | B4: Kg | C4: 354 | D4: 5500 | E4: =+D4*C4 -> 1947000
A5: Bí Đao Xanh | B5: Kg | C5: 0
A6: Bí Đỏ Hồ Lô | B6: Kg | C6: 0
A7: Bí Đỏ Tròn | B7: Kg | C7: 996 | D7: 8000 | E7: =+D7*C7 -> 7968000
A8: Bí Ngòi Vàng | B8: Kg | C8: 2.5 | D8: 9000 | E8: =+D8*C8 -> 22500
A9: Bí Ngòi Xanh | B9: Kg | C9: 87 | D9: 10000 | E9: =+D9*C9 -> 870000
A10: Bí Ngòi Xanh | B10: Trái | C10: 0
A11: Bí Non Nhật | B11: Kg | C11: 33 | D11: 10000 | E11: =+D11*C11 -> 330000
A12: Bí Non Nhật | B12: Trái | C12: 0
A13: Bơ Booth | B13: Kg | C13: 0
A14: Bông Cải Trắng | B14: Kg | C14: 10 | D14: 12000 | E14: =+D14*C14 -> 120000
A15: Bông Cải Xanh 10Cm | B15: Kg | C15: 10 | D15: 12000 | E15: =+D15*C15 -> 120000
A16: Bông Cải Xanh 12Cm | B16: Kg | C16: 0
A17: Bông Cải Xanh 7Cm | B17: Kg | C17: 12 | D17: 17000 | E17: =+D17*C17 -> 204000
A18: Bông Cải Xanh Baby | B18: Vỉ | C18: 7 | D18: 7000 | E18: =+D18*C18 -> 49000
A19: Cà Chua Beef | B19: Kg | C19: 297 | D19: 15000 | E19: =+D19*C19 -> 4455000
A20: Cà Chua Beef | B20: Vỉ | C20: 0
A21: Cà Chua Beef | B21: Vỉ 650gr | C21: 0
A22: Cà Chua Beef Trung | B22: Kg | C22: 10 | D22: 8000 | E22: =+D22*C22 -> 80000
A23: Cà Chua Beef Trung | B23: Vỉ 500gr | C23: 0
A24: Cà Chua Bi Đỏ | B24: Kg | C24: 5 | D24: 6300 | E24: =+D24*C24 -> 31500
A25: Cà Chua Bi Đỏ | B25: Hộp 300gr | C25: 116 | D25: 6300 | E25: =+D25*C25 -> 730800
A26: Cà Chua Bi Mix | B26: Hộp | C26: 4 | D26: 10500 | E26: =+D26*C26 -> 42000
A27: Cà Chua Socola | B27: Kg | C27: 0
A28: Cà Chua Socola | B28: Hộp 250GR | C28: 0
A29: Cà Chua Thường | B29: Kg | C29: 200 | D29: 10000 | E29: =+D29*C29 -> 2000000
A30: Cà Chua Thường | B30: Vỉ | C30: 0
A31: Cà Chua Thường Trung | B31: Túi | C31: 100 | D31: 7000 | E31: =+D31*C31 -> 700000
A32: Cà Rốt | B32: Kg | C32: 191 | D32: 8500 | E32: =+D32*C32 -> 1623500
A33: Cà Rốt | B33: Túi | C33: 0
A34: Cà Rốt Baby | B34: Kg | C34: 0
A35: Cà Rốt Baby | B35: Vỉ | C35: 0
A36: Cà Tím | B36: Kg | C36: 32 | D36: 8000 | E36: =+D36*C36 -> 256000
A37: Cà Tím | B37: Cặp | C37: 0
A38: Cải Bó Xôi | B38: Kg | C38: 27 | D38: 26000 | E38: =+D38*C38 -> 702000
A39: Cải Bó Xôi | B39: Túi | C39: 0
A40: Cải Cầu Vồng | B40: Kg | C40: 0
...

Sheet 20.1
A1: Tên Sản phẩm VR | B1: ĐVT | C1: Tồn ĐL 現在個 | D1: Gía nhập | E1: Thành tiền
A2: Bắp Cải Tím | B2: Kg | C2: 10 | D2: 10000 | E2: =+D2*C2 -> 100000
A3: Bắp Cải Trái Tim | B3: Kg | C3: 315 | D3: 4000 | E3: =+D3*C3 -> 1260000
A4: Bắp Cải Trắng | B4: Kg | C4: 569 | D4: 5500 | E4: =+D4*C4 -> 3129500
A5: Bí Đao Xanh | B5: Kg | C5: 12 | D5: 10000 | E5: =+D5*C5 -> 120000
A6: Bí Đỏ Hồ Lô | B6: Kg | C6: 0 | E6: =+D6*C6 -> 0
A7: Bí Đỏ Tròn | B7: Kg | C7: 665 | D7: 8000 | E7: =+D7*C7 -> 5320000
A8: Bí Ngòi Xanh | B8: Kg | C8: 92 | D8: 8000 | E8: =+D8*C8 -> 736000
A9: Bí Ngòi Xanh | B9: Trái | C9: 0 | E9: =+D9*C9 -> 0
A10: Bí Non Nhật | B10: Kg | C10: 72 | D10: 10000 | E10: =+D10*C10 -> 720000
A11: Bí Non Nhật | B11: Trái | C11: 0 | E11: =+D11*C11 -> 0
A12: Bơ Booth | B12: Kg | C12: 0 | E12: =+D12*C12 -> 0
A13: Bông Cải Trắng | B13: Kg | C13: 0 | E13: =+D13*C13 -> 0
A14: Bông Cải Xanh 10Cm | B14: Kg | C14: 45 | D14: 12000 | E14: =+D14*C14 -> 540000
A15: Bông Cải Xanh 12Cm | B15: Kg | C15: 0 | E15: =+D15*C15 -> 0
A16: Bông Cải Xanh 7Cm | B16: Kg | C16: 45 | D16: 21000 | E16: =+D16*C16 -> 945000
A17: Bông Cải Xanh Baby | B17: Vỉ | C17: 0 | E17: =+D17*C17 -> 0
A18: Cà Chua Beef | B18: Kg | C18: 200 | D18: 15000 | E18: =+D18*C18 -> 3000000
A19: Cà Chua Beef | B19: Vỉ | C19: 0 | E19: =+D19*C19 -> 0
A20: Cà Chua Beef | B20: Vỉ 650gr | C20: 0 | E20: =+D20*C20 -> 0
A21: Cà Chua Beef Trung | B21: Kg | C21: 15 | D21: 8000 | E21: =+D21*C21 -> 120000
A22: Cà Chua Beef Trung | B22: Vỉ 500gr | C22: 0 | E22: =+D22*C22 -> 0
A23: Cà Chua Bi Đỏ | B23: Kg | C23: 0 | E23: =+D23*C23 -> 0
A24: Cà Chua Bi Đỏ | B24: Hộp 300gr | C24: 74 | D24: 5400 | E24: =+D24*C24 -> 399600
A25: Cà Chua Bi Mix | B25: Hộp | C25: 5 | D25: 10500 | E25: =+D25*C25 -> 52500
A26: Cà Chua Socola | B26: Kg | C26: 0 | E26: =+D26*C26 -> 0
A27: Cà Chua Socola | B27: Hộp 250GR | C27: 250 | D27: 10000 | E27: =+D27*C27 -> 2500000
A28: Cà Chua Thường | B28: Kg | C28: 145 | D28: 10000 | E28: =+D28*C28 -> 1450000
A29: Cà Chua Thường | B29: Vỉ | C29: 0 | E29: =+D29*C29 -> 0
A30: Cà Chua Thường Trung | B30: Túi | C30: 60 | D30: 7000 | E30: =+D30*C30 -> 420000
A31: Cà Rốt | B31: Kg | C31: 115 | D31: 9000 | E31: =+D31*C31 -> 1035000
A32: Cà Rốt | B32: Túi | C32: 0 | E32: =+D32*C32 -> 0
A33: Cà Rốt Baby | B33: Vỉ | C33: 27 | D33: 6000 | E33: =+D33*C33 -> 162000
A34: Cà Tím | B34: Kg | C34: 75 | D34: 8000 | E34: =+D34*C34 -> 600000
A35: Cà Tím | B35: Cặp | C35: 0 | E35: =+D35*C35 -> 0
A36: Cải Bó Xôi | B36: Kg | C36: 23 | D36: 25000 | E36: =+D36*C36 -> 575000
A37: Cải Bó Xôi | B37: Túi | C37: 0 | E37: =+D37*C37 -> 0
A38: Cải Cầu Vồng | B38: Túi | C38: 0 | E38: =+D38*C38 -> 0
A39: Cải Kale | B39: Túi | C39: 12 | D39: 4200 | E39: =+D39*C39 -> 50400
A40: Cải Thảo | B40: Kg | C40: 220 | D40: 6500 | E40: =+D40*C40 -> 1430000
...

Sheet 21.1
A1: hàng tồn cuối ngày 21/1 vr
A2: Tên Sản phẩm | B2: ĐVT | C2: tồn | D2: giá | E2: thành tiền
A3: Bắp Cải Tím | B3: Kg | C3: 12 | D3: 10000 | E3: =C3*D3 -> 120000
A4: Bắp Cải Trái Tim | B4: Kg | C4: 0 | E4: =C4*D4 -> 0
A5: Bắp Cải Trắng | B5: Kg | C5: 779 | D5: 5500 | E5: =C5*D5 -> 4284500
A6: Bí Đao Xanh | B6: Kg | C6: 15 | D6: 10000 | E6: =C6*D6 -> 150000
A7: Bí Đỏ Hồ Lô | B7: Kg | C7: 0 | E7: =C7*D7 -> 0
A8: Bí Đỏ Tròn | B8: Kg | C8: 457 | D8: 8000 | E8: =C8*D8 -> 3656000
A9: Bí Ngòi Vàng | B9: Kg | C9: 0 | E9: =C9*D9 -> 0
A10: Bí Ngòi Xanh | B10: Kg | C10: 109 | D10: 10000 | E10: =C10*D10 -> 1090000
A11: Bí Ngòi Xanh | B11: Trái | C11: 0 | E11: =C11*D11 -> 0
A12: Bí Non Nhật | B12: Kg | C12: 68 | D12: 14000 | E12: =C12*D12 -> 952000
A13: Bí Non Nhật | B13: Trái | C13: 0 | E13: =C13*D13 -> 0
A14: Bơ Booth | B14: Kg | C14: 0 | E14: =C14*D14 -> 0
A15: Bông Cải Trắng | B15: Kg | C15: 4 | D15: 12000 | E15: =C15*D15 -> 48000
A16: Bông Cải Xanh 10Cm | B16: Kg | C16: 8 | D16: 10000 | E16: =C16*D16 -> 80000
A17: Bông Cải Xanh 12Cm | B17: Kg | C17: 0 | E17: =C17*D17 -> 0
A18: Bông Cải Xanh 7Cm | B18: Kg | C18: 0 | E18: =C18*D18 -> 0
A19: Bông Cải Xanh Baby | B19: Vỉ | C19: 20 | D19: 7000 | E19: =C19*D19 -> 140000
A20: Cà Chua Beef | B20: Kg | C20: 102 | D20: 17000 | E20: =C20*D20 -> 1734000
A21: Cà Chua Beef | B21: Vỉ | C21: 0 | E21: =C21*D21 -> 0
A22: Cà Chua Beef | B22: Vỉ 650gr | C22: 0 | E22: =C22*D22 -> 0
A23: Cà Chua Beef Trung | B23: Kg | C23: 24 | D23: 14000 | E23: =C23*D23 -> 336000
A24: Cà Chua Beef Trung | B24: Vỉ 500gr | C24: 0 | E24: =C24*D24 -> 0
A25: Cà Chua Bi Đỏ | B25: Kg | C25: 5 | D25: 18000 | E25: =C25*D25 -> 90000
A26: Cà Chua Bi Đỏ | B26: Hộp 300gr | C26: 87 | D26: 5400 | E26: =C26*D26 -> 469800
A27: Cà Chua Bi Mix | B27: Hộp | C27: 5 | D27: 11100 | E27: =C27*D27 -> 55500
A28: Cà Chua Socola | B28: Kg | C28: 0 | E28: =C28*D28 -> 0
A29: Cà Chua Socola | B29: Hộp 250GR | C29: 7 | D29: 10000 | E29: =C29*D29 -> 70000
A30: Cà Chua Thường | B30: Kg | C30: 57 | D30: 11000 | E30: =C30*D30 -> 627000
A31: Cà Chua Thường | B31: Vỉ | C31: 0 | E31: =C31*D31 -> 0
A32: Cà Chua Thường Trung | B32: Túi | C32: 80 | D32: 8000 | E32: =C32*D32 -> 640000
A33: Cà Rốt | B33: Kg | C33: 540 | D33: 9000 | E33: =C33*D33 -> 4860000
A34: Cà Rốt | B34: Túi | C34: 0 | E34: =C34*D34 -> 0
A35: Cà Rốt Baby | B35: Vỉ | C35: 3 | D35: 7000 | E35: =C35*D35 -> 21000
A36: Cà Tím | B36: Kg | C36: 98 | D36: 8000 | E36: =C36*D36 -> 784000
A37: Cà Tím | B37: Cặp | C37: 0 | E37: =C37*D37 -> 0
A38: Cải Bó Xôi | B38: Kg | C38: 0 | E38: =C38*D38 -> 0
A39: Cải Bó Xôi | B39: Túi | C39: 0 | E39: =C39*D39 -> 0
A40: Cải Cầu Vồng | B40: Kg | C40: 0 | E40: =C40*D40 -> 0
...

Sheet 22.1
A1: hàng tồn cuối ngày 22/1 vr
A2: Tên Sản phẩm | B2: ĐVT | C2: tồn | D2: giá | E2: thành tiền
A3: Bắp Cải Tím | B3: Kg | C3: 20 | D3: 8000 | E3: =C3*D3 -> 160000
A4: Bắp Cải Trái Tim | B4: Kg | C4: 205 | D4: 4000 | E4: =C4*D4 -> 820000
A5: Bắp Cải Trắng | B5: Kg | C5: 586 | D5: 6000 | E5: =C5*D5 -> 3516000
A6: Bí Đỏ Hồ Lô | B6: Kg | C6: 0 | E6: =C6*D6 -> 0
A7: Bí Đỏ Tròn | B7: Kg | C7: 269 | D7: 7800 | E7: =C7*D7 -> 2098200
A8: Bí Ngòi Vàng | B8: Kg | C8: 1 | D8: 12000 | E8: =C8*D8 -> 12000
A9: Bí Ngòi Xanh | B9: Kg | C9: 109 | D9: 10000 | E9: =C9*D9 -> 1090000
A10: Bí Ngòi Xanh | B10: Trái | C10: 0 | E10: =C10*D10 -> 0
A11: Bí Non Nhật | B11: Kg | C11: 45 | D11: 14000 | E11: =C11*D11 -> 630000
A12: Bí Non Nhật | B12: Trái | C12: 0 | E12: =C12*D12 -> 0
A13: Bơ Booth | B13: Kg | C13: 0 | E13: =C13*D13 -> 0
A14: Bông Cải Trắng | B14: Kg | C14: 17 | D14: 12000 | E14: =C14*D14 -> 204000
A15: Bông Cải Xanh 10Cm | B15: Kg | C15: 0 | E15: =C15*D15 -> 0
A16: Bông Cải Xanh 12Cm | B16: Kg | C16: 25 | D16: 10000 | E16: =C16*D16 -> 250000
A17: Bông Cải Xanh 7Cm | B17: Kg | C17: 35 | D17: 21000 | E17: =C17*D17 -> 735000
A18: Bông Cải Xanh Baby | B18: Vỉ | C18: 0 | E18: =C18*D18 -> 0
A19: Cà Chua Beef | B19: Kg | C19: 127 | D19: 17000 | E19: =C19*D19 -> 2159000
A20: Cà Chua Beef | B20: Vỉ | C20: 0 | E20: =C20*D20 -> 0
A21: Cà Chua Beef | B21: Vỉ 650gr | C21: 0 | E21: =C21*D21 -> 0
A22: Cà Chua Beef Trung | B22: Kg | C22: 0 | E22: =C22*D22 -> 0
A23: Cà Chua Beef Trung | B23: Vỉ 500gr | C23: 70 | D23: 8000 | E23: =C23*D23 -> 560000
A24: Cà Chua Bi Đỏ | B24: Kg | C24: 0 | E24: =C24*D24 -> 0
A25: Cà Chua Bi Đỏ | B25: Hộp 300gr | C25: 68 | D25: 5400 | E25: =C25*D25 -> 367200
A26: Cà Chua Bi Mix | B26: Hộp | C26: 3 | D26: 11100 | E26: =C26*D26 -> 33300
A27: Cà Chua Socola | B27: Kg | C27: 0 | E27: =C27*D27 -> 0
A28: Cà Chua Socola | B28: Hộp 250GR | C28: 0 | E28: =C28*D28 -> 0
A29: Cà Chua Thường | B29: Kg | C29: 0 | E29: =C29*D29 -> 0
A30: Cà Chua Thường | B30: Vỉ | C30: 0 | E30: =C30*D30 -> 0
A31: Cà Chua Thường Trung | B31: Túi | C31: 60 | D31: 8000 | E31: =C31*D31 -> 480000
A32: Cà Rốt | B32: Kg | C32: 145 | D32: 9000 | E32: =C32*D32 -> 1305000
A33: Cà Rốt | B33: Túi | C33: 0 | E33: =C33*D33 -> 0
A34: Cà Rốt Baby | B34: Vỉ | C34: 12 | D34: 6000 | E34: =C34*D34 -> 72000
A35: Cà Tím | B35: Kg | C35: 116 | D35: 8000 | E35: =C35*D35 -> 928000
A36: Cà Tím | B36: Cặp | C36: 0 | E36: =C36*D36 -> 0
A37: Cải Bó Xôi | B37: Kg | C37: 25 | D37: 22000 | E37: =C37*D37 -> 550000
A38: Cải Bó Xôi | B38: Túi | C38: 0 | E38: =C38*D38 -> 0
A39: Cải Cầu Vồng | B39: Túi | C39: 4 | D39: 5000 | E39: =C39*D39 -> 20000
A40: Cải Kale | B40: Túi | C40: 25 | D40: 3500 | E40: =C40*D40 -> 87500
...

Sheet 23.1
A1: hàng tồn cuối ngày 23/1 vr
A2: Tên Sản phẩm | B2: ĐVT | C2: tồn | D2: giá | E2: thành tiền
A3: Cà Rốt | B3: Kg | C3: 80 | D3: 9500 | E3: =C3*D3 -> 760000
A4: Cà Rốt | B4: Túi | C4: 0 | E4: =C4*D4 -> 0
A5: Cà Rốt Baby | B5: Vỉ | C5: 15 | D5: 6000 | E5: =C5*D5 -> 90000
A6: Củ Cải Đỏ | B6: Hộp | C6: 0 | E6: =C6*D6 -> 0
A7: Củ Dền | B7: Kg | C7: 35 | D7: 11000 | E7: =C7*D7 -> 385000
A8: Củ Dền | B8: Túi | C8: 0 | E8: =C8*D8 -> 0
A9: Củ Hành Tây | B9: Kg | C9: 236 | D9: 10000 | E9: =C9*D9 -> 2360000
A10: Củ Hành Tây | B10: Túi 300gr | C10: 0 | E10: =C10*D10 -> 0
A11: Củ Hành Tây Trung | B11: Túi | C11: 100 | D11: 2400 | E11: =C11*D11 -> 240000
A12: Củ Khoai Lang Mật Size 46 | B12: Kg | C12: 2860 | D12: 27000 | E12: =C12*D12 -> 77220000
A13: Củ Khoai Lang Mật Size 46 | B13: Túi | C13: 0 | E13: =C13*D13 -> 0
A14: Củ Khoai Lang Nhật | B14: Kg | C14: 120 | D14: 15000 | E14: =C14*D14 -> 1800000
A15: Củ Khoai Tây Vàng | B15: Kg | C15: 640 | D15: 16000 | E15: =C15*D15 -> 10240000
A16: Củ Khoai Tây Vàng | B16: Túi | C16: 0 | E16: =C16*D16 -> 0
